
# Created by Ruins mod version 15.3 Ingame Parser
# authoring Player: Mensrea

weight=25
embed_into_distance=2
acceptable_target_blocks=
unacceptable_target_blocks=flowing_water,water,flowing_lava,lava
dimensions=7,8,14
allowable_overhang=0
max_leveling=2
leveling_buffer=0
preserve_water=0
preserve_lava=0

rule1=0,100,PFAAChemica:pollutedSoil-0
rule2=0,100,IW:boneblock-0
rule3=0,100,PFAAGeologica:weakOreSand-5

layer
1,1,1,1,1,1,1,1,1,1,1,1,1,1
1,1,1,1,1,1,1,1,1,1,1,1,1,1
1,1,1,1,1,1,1,1,1,1,1,1,1,1
1,1,1,1,1,1,1,1,1,1,1,1,1,1
1,1,1,1,1,1,1,1,1,1,1,1,1,1
1,1,1,1,1,1,1,1,1,1,1,1,1,1
1,1,1,1,1,1,1,1,1,1,2,1,1,1
1,1,1,1,1,1,1,1,1,1,1,1,1,1
endlayer

layer
3,3,3,3,3,3,3,3,3,3,3,3,3,3
3,3,3,3,3,3,2,3,2,3,2,3,2,3
3,3,2,3,2,3,3,3,3,3,3,3,3,3
3,3,3,3,3,3,3,3,3,3,3,3,3,3
3,3,3,3,3,3,3,3,3,3,3,3,3,3
3,3,3,3,3,3,3,3,3,3,3,3,3,3
3,3,3,3,3,3,3,3,3,3,2,3,3,3
3,3,3,3,3,3,3,3,3,3,3,3,3,3
endlayer

layer
0,0,0,0,0,0,0,0,3,0,3,0,3,0
0,0,0,0,3,0,2,3,2,3,2,3,2,3
0,0,2,3,2,0,0,0,0,0,0,0,0,0
0,0,0,0,0,0,3,0,0,0,0,0,0,3
0,0,0,0,0,3,3,3,0,0,0,0,3,3
0,0,0,3,3,3,3,3,3,0,2,0,3,3
0,0,0,0,3,3,3,3,3,0,2,0,0,3
0,0,0,0,0,3,3,3,0,0,0,0,0,0
endlayer

layer
0,0,0,0,0,0,0,0,0,0,0,0,0,0
0,0,0,0,0,0,2,0,2,0,2,0,2,0
0,0,2,0,2,0,0,0,0,0,0,0,0,0
0,0,2,0,2,0,0,0,0,0,0,0,0,0
0,0,0,0,0,0,0,0,0,0,2,0,0,0
0,0,0,0,0,0,0,0,0,0,2,0,0,0
0,0,0,0,0,0,0,0,0,0,0,0,0,0
0,0,0,0,0,0,0,0,0,0,0,0,0,0
endlayer

layer
0,0,0,0,0,0,0,0,0,0,0,0,0,0
0,0,0,0,0,0,2,0,2,0,2,0,2,0
0,0,0,0,0,0,2,0,2,0,2,0,2,0
0,0,2,0,2,0,0,0,0,0,0,0,0,0
0,0,2,0,2,0,0,0,0,0,0,0,0,0
0,0,0,0,0,0,0,0,0,0,0,0,0,0
0,0,0,0,0,0,0,0,0,0,0,0,0,0
0,0,0,0,0,0,0,0,0,0,0,0,0,0
endlayer

layer
0,0,0,0,0,0,0,0,0,0,0,0,0,0
0,0,0,0,0,0,0,0,0,0,0,0,0,0
0,0,0,0,0,0,2,0,2,0,0,0,2,0
0,0,0,0,0,0,2,0,2,0,0,0,2,0
0,0,2,0,2,0,0,0,0,0,0,0,0,0
0,0,2,0,2,0,0,0,0,0,0,0,0,0
0,0,2,0,2,0,0,0,0,0,0,0,0,0
0,0,0,0,0,0,0,0,0,0,0,0,0,0
endlayer

layer
0,0,0,0,0,0,0,0,0,0,0,0,0,0
0,0,0,0,0,0,0,0,0,0,0,0,0,0
0,0,0,0,0,0,0,0,0,0,0,0,0,0
0,0,0,0,0,0,2,0,2,0,0,0,2,0
0,0,0,0,0,0,2,0,2,0,0,0,2,0
0,0,0,0,0,0,2,0,2,0,0,0,2,0
0,0,0,0,0,0,0,0,0,0,0,0,0,0
0,0,0,0,0,0,0,0,0,0,0,0,0,0
endlayer

