
# Created by Ruins mod version 15.3 Ingame Parser
# authoring Player: Mensrea

weight=3
embed_into_distance=6
acceptable_target_blocks=
unacceptable_target_blocks=flowing_water,water,flowing_lava,lava
dimensions=11,14,16
allowable_overhang=0
max_leveling=2
leveling_buffer=0
preserve_water=0
preserve_lava=0
preventRotation=1

rule1=0,100,minecraft:stonebrick-0
rule2=0,100,MobSpawner:desertmobs.cryptzombie
rule3=0,100,minecraft:stone_slab-0
rule4=0,100,minecraft:stone_brick_stairs-1
rule5=0,100,ChestGenHook:pyramidJungleChest:5-5
rule6=0,100,ChestGenHook:pyramidJungleChest:5-3
rule7=0,100,minecraft:stone_brick_stairs-0
rule8=0,100,minecraft:sand-1
rule9=0,100,minecraft:deadbush-0
rule10=0,100,minecraft:stonebrick-2

layer
1,1,1,1,1,1,1,1,1,1,1,1,1,1,1,1
1,1,1,1,1,1,1,1,1,1,1,1,1,1,1,1
1,1,1,1,1,1,1,1,1,1,1,1,1,1,1,1
1,1,1,1,1,1,1,1,1,1,1,1,1,1,1,1
1,1,1,1,1,1,1,1,1,1,1,1,1,1,1,1
1,1,1,1,1,1,1,1,1,1,1,1,1,1,1,1
1,1,1,1,1,1,1,1,1,1,1,1,1,1,1,1
1,1,1,1,1,1,1,1,1,1,1,1,1,1,1,1
1,1,1,1,1,1,1,1,1,1,1,1,1,1,1,1
1,1,1,1,1,1,1,1,1,1,1,1,1,1,1,1
1,1,1,1,1,1,1,1,1,1,1,1,1,1,1,1
1,1,1,1,1,1,1,1,1,1,1,1,1,1,1,1
1,1,1,1,1,1,1,1,1,1,1,1,1,1,1,1
1,1,1,1,1,1,1,1,1,1,1,1,1,1,1,1
endlayer

layer
1,1,1,1,1,1,1,1,1,1,1,1,1,1,1,1
1,1,1,1,1,1,1,1,1,1,1,1,1,1,1,1
1,1,1,1,1,1,1,1,1,1,1,1,1,1,1,1
1,1,1,1,2,1,1,2,1,2,1,1,2,1,1,1
1,1,1,1,1,1,1,1,1,1,1,1,1,1,1,1
1,1,1,1,1,1,1,1,1,1,1,1,1,1,1,1
1,1,1,1,1,1,1,1,1,1,1,1,1,1,1,1
1,1,1,1,1,1,1,1,1,1,1,1,1,1,1,1
1,1,1,1,1,1,1,1,1,1,1,1,1,1,1,1
1,1,1,1,1,1,1,1,1,1,1,1,1,1,1,1
1,1,1,1,2,1,1,2,1,2,1,1,2,1,1,1
1,1,1,1,1,1,1,1,1,1,1,1,1,1,1,1
1,1,1,1,1,1,1,1,1,1,1,1,1,1,1,1
1,1,1,1,1,1,1,1,1,1,1,1,1,1,1,1
endlayer

layer
1,1,1,1,1,1,1,1,1,1,1,1,1,1,1,1
1,1,1,1,3,0,0,3,1,3,0,0,3,1,1,1
1,1,1,1,3,0,0,3,1,3,0,0,3,1,1,1
1,1,1,1,3,0,0,3,1,3,0,0,3,1,1,1
1,1,1,1,1,0,0,1,1,1,0,0,1,1,1,1
1,1,6,5,1,0,0,0,0,0,0,0,0,0,4,1
1,1,0,0,0,0,0,0,0,0,0,0,0,0,0,1
1,1,0,0,0,0,0,0,0,0,0,0,0,0,0,1
1,1,6,5,1,0,0,0,0,0,0,0,0,0,7,1
1,1,1,1,1,0,0,1,1,1,0,0,1,1,1,1
1,1,1,1,3,0,0,3,1,3,0,0,3,1,1,1
1,1,1,1,3,0,0,3,1,3,0,0,3,1,1,1
1,1,1,1,3,0,0,3,1,3,0,0,3,1,1,1
1,1,1,1,1,1,1,1,1,1,1,1,1,1,1,1
endlayer

layer
1,1,1,1,1,1,1,1,1,1,1,1,1,1,1,1
1,1,1,1,0,0,0,0,1,0,0,0,0,1,1,1
1,1,1,1,0,0,0,0,1,0,0,0,0,1,1,1
1,1,1,1,0,0,0,0,1,0,0,0,0,1,1,1
1,1,1,1,1,0,0,1,1,1,0,0,1,1,4,1
1,1,0,0,1,0,0,0,0,0,0,0,0,0,0,1
1,1,0,0,0,0,0,0,0,0,0,0,0,0,0,1
1,1,0,0,0,0,0,0,0,0,0,0,0,0,0,1
1,1,0,0,1,0,0,0,0,0,0,0,0,0,0,1
1,1,1,1,1,0,0,1,1,1,0,0,1,1,7,1
1,1,1,1,0,0,0,0,1,0,0,0,0,1,1,1
1,1,1,1,0,0,0,0,1,0,0,0,0,1,1,1
1,1,1,1,0,0,0,0,1,0,0,0,0,1,1,1
1,1,1,1,1,1,1,1,1,1,1,1,1,1,1,1
endlayer

layer
1,1,1,1,1,1,1,1,1,1,1,1,1,1,1,1
1,1,1,1,0,0,0,0,1,0,0,0,0,1,1,1
1,1,1,1,0,0,0,0,1,0,0,0,0,1,1,1
1,1,1,1,0,0,0,0,1,0,0,0,0,1,4,1
1,1,1,1,1,1,1,1,1,1,1,1,1,1,0,1
1,1,0,0,1,0,0,0,0,0,0,0,0,0,0,1
1,1,0,0,1,0,0,0,0,0,0,0,0,0,0,1
1,1,0,0,1,0,0,0,0,0,0,0,0,0,0,1
1,1,0,0,1,0,0,0,0,0,0,0,0,0,0,1
1,1,1,1,1,1,1,1,1,1,1,1,1,1,0,1
1,1,1,1,0,0,0,0,1,0,0,0,0,1,7,1
1,1,1,1,0,0,0,0,1,0,0,0,0,1,1,1
1,1,1,1,0,0,0,0,1,0,0,0,0,1,1,1
1,1,1,1,1,1,1,1,1,1,1,1,1,1,1,1
endlayer

layer
8,8,8,8,8,8,8,8,8,8,8,8,8,8,8,8
8,8,8,8,1,1,1,1,1,1,1,1,1,8,8,8
8,8,8,8,1,0,0,1,1,0,0,0,1,8,8,8
8,8,8,1,1,0,0,1,1,0,0,0,1,8,0,8
8,1,1,1,1,1,1,1,1,1,1,1,1,8,0,8
8,1,0,0,1,0,0,0,0,0,0,0,1,1,0,8
8,1,0,0,1,0,0,0,0,0,0,0,0,1,0,8
8,1,0,0,1,0,0,0,0,0,0,0,0,1,0,8
8,1,0,0,1,0,0,0,0,0,0,0,1,1,0,8
8,1,1,1,1,1,1,1,1,1,1,1,1,8,0,8
8,8,8,1,1,0,0,0,1,0,0,0,1,8,0,8
8,8,8,8,1,0,0,0,1,0,0,0,1,8,8,8
8,8,8,8,1,1,1,1,1,1,1,1,1,8,8,8
8,8,8,8,8,8,8,8,8,8,8,8,8,8,8,8
endlayer

layer
0,0,0,0,0,0,0,0,0,0,0,0,0,0,9,0
0,0,0,0,8,8,8,8,8,8,8,8,8,0,0,0
0,0,9,8,8,1,1,1,8,1,1,1,8,0,0,0
0,0,8,1,1,1,1,1,1,1,1,1,1,8,0,0
0,8,8,1,1,1,1,1,1,1,1,1,1,8,0,0
0,8,1,1,1,0,0,0,0,0,0,1,1,1,10,0
0,8,1,1,1,0,0,0,0,0,0,1,1,1,10,0
0,8,1,1,1,0,0,0,0,0,0,1,1,1,10,0
0,8,1,1,1,0,0,0,0,0,0,1,1,1,10,0
0,8,8,1,1,1,1,1,1,1,1,1,1,8,0,0
0,0,8,1,1,1,1,1,1,1,1,1,1,8,0,0
0,9,0,8,8,1,1,1,8,1,1,1,8,0,0,0
0,0,0,0,8,8,8,8,8,8,8,8,8,0,9,0
0,0,0,0,0,0,0,0,0,0,0,0,0,0,0,0
endlayer

layer
0,0,0,0,0,0,0,0,0,0,0,0,0,0,0,0
0,0,0,0,0,0,0,0,0,0,0,0,0,0,0,0
0,0,0,0,0,8,8,8,8,8,8,8,0,0,0,0
0,0,0,8,8,8,8,8,8,8,8,8,8,0,0,0
0,0,0,8,8,8,8,8,8,8,8,8,8,0,0,0
0,0,8,1,1,1,1,1,1,1,1,1,1,8,0,0
0,0,8,1,1,1,1,1,1,1,1,1,1,8,0,0
0,8,8,1,1,1,1,1,1,1,1,1,1,8,0,0
0,0,8,1,1,1,1,1,1,1,1,1,1,8,0,0
0,0,0,8,8,8,8,8,8,8,8,8,8,0,0,0
0,0,0,8,8,8,8,8,8,8,8,8,8,0,0,0
0,0,0,0,0,8,8,8,0,8,8,8,0,0,0,0
0,0,0,0,0,0,0,0,0,0,0,0,0,0,0,0
0,0,0,0,0,0,0,0,0,0,0,0,0,0,0,0
endlayer

layer
0,0,0,0,0,0,0,0,0,0,0,0,0,0,0,0
0,0,0,0,0,0,0,0,0,0,0,0,0,0,0,0
0,0,0,0,0,0,9,0,0,0,0,0,0,0,0,0
0,0,0,0,0,0,0,0,0,0,0,0,0,0,0,0
0,0,0,0,8,8,0,8,8,8,0,0,0,0,0,0
0,0,0,8,8,8,8,8,8,8,8,8,8,0,0,0
0,0,0,8,8,8,8,8,8,8,8,8,8,0,0,0
0,0,8,8,8,8,8,8,8,8,8,8,8,0,0,0
0,0,0,8,8,8,8,8,8,8,8,8,8,0,0,0
0,0,0,0,0,0,0,0,0,0,0,0,0,0,0,0
0,0,0,0,0,0,0,0,0,0,0,0,0,0,0,0
0,0,0,0,0,0,0,9,0,0,0,0,0,0,0,0
0,0,0,0,0,0,0,0,0,0,0,0,0,0,0,0
0,0,0,0,0,0,0,0,0,0,0,0,0,0,0,0
endlayer

layer
0,0,0,0,0,0,0,0,0,0,0,0,0,0,0,0
0,0,0,0,0,0,0,0,0,0,0,0,0,0,0,0
0,0,0,0,0,0,0,0,0,0,0,0,0,0,0,0
0,0,0,0,0,0,0,0,0,0,0,0,0,0,0,0
0,0,0,0,0,0,0,0,0,0,0,0,0,0,0,0
0,0,0,0,0,0,0,0,8,0,0,0,0,0,0,0
0,0,0,0,0,0,0,0,0,0,0,0,0,0,0,0
0,0,0,0,0,0,0,0,0,0,0,9,0,0,0,0
0,0,0,0,0,0,0,0,0,0,0,0,0,0,0,0
0,0,0,0,0,0,0,0,0,0,0,0,0,0,0,0
0,0,0,0,0,0,0,0,0,0,0,0,0,0,0,0
0,0,0,0,0,0,0,0,0,0,0,0,0,0,0,0
0,0,0,0,0,0,0,0,0,0,0,0,0,0,0,0
0,0,0,0,0,0,0,0,0,0,0,0,0,0,0,0
endlayer

layer
0,0,0,0,0,0,0,0,0,0,0,0,0,0,0,0
0,0,0,0,0,0,0,0,0,0,0,0,0,0,0,0
0,0,0,0,0,0,0,0,0,0,0,0,0,0,0,0
0,0,0,0,0,0,0,0,0,0,0,0,0,0,0,0
0,0,0,0,0,0,0,0,0,0,0,0,0,0,0,0
0,0,0,0,0,0,0,0,9,0,0,0,0,0,0,0
0,0,0,0,0,0,0,0,0,0,0,0,0,0,0,0
0,0,0,0,0,0,0,0,0,0,0,0,0,0,0,0
0,0,0,0,0,0,0,0,0,0,0,0,0,0,0,0
0,0,0,0,0,0,0,0,0,0,0,0,0,0,0,0
0,0,0,0,0,0,0,0,0,0,0,0,0,0,0,0
0,0,0,0,0,0,0,0,0,0,0,0,0,0,0,0
0,0,0,0,0,0,0,0,0,0,0,0,0,0,0,0
0,0,0,0,0,0,0,0,0,0,0,0,0,0,0,0
endlayer

