
# Created by Ruins mod version 15.3 Ingame Parser
# authoring Player: Mensrea

weight=2
embed_into_distance=7
acceptable_target_blocks=
unacceptable_target_blocks=flowing_water,water,flowing_lava,lava
dimensions=12,16,19
allowable_overhang=0
max_leveling=2
leveling_buffer=0
preserve_water=0
preserve_lava=0
preventRotation=1

rule1=0,100,PFAAGeologica:strongStone-7
rule2=0,100,PFAAGeologica:mediumStone-3
rule3=0,100,IW:concrete-0
rule4=0,100,IW:concretestairs-2
rule5=0,100,IW:steelsiding-0
rule6=0,100,IW:steelblock-0
rule7=0,100,IC2:blockDoorAlloy-3
rule8=0,100,IInventory;ThermalExpansion:Strongbox:2;IC2:reactorUraniumSimpledepleted#3#0#0-6
rule9=0,100,ChestGenHook:mineshaftCorridor:5-2
rule10=0,100,ChestGenHook:mineshaftCorridor:5-3
rule11=0,100,IInventory;ThermalExpansion:Strongbox:2;IC2:reactorUraniumSimple#2#1#0-6
rule12=0,100,minecraft:sand-1
rule13=0,100,PFAAGeologica:weakStone-1
rule14=0,100,IW:concretestairs-0
rule15=0,100,IW:metalbutton-1
rule16=0,100,IC2:blockDoorAlloy-8
rule17=0,100,IW:machinery2-0
rule18=0,100,IW:smalllightwhite-2
rule19=0,100,minecraft:gravel-0
rule20=0,100,IW:smalllightwhite-1
rule21=0,100,IW:concretestairs-3
rule22=0,100,IW:smalllightwhite-3
rule23=0,100,IW:smalllightwhite-4
rule24=2,100,WallSign:NOTICE::as per mgmt:stools no :longer provided-4
rule25=2,100,WallSign:NOTICE::due to cutbacks:store will:no longer-4
rule26=2,100,WallSign:be providing:hazmat suits.:keep fuel-rod:handling to min-4
rule27=0,100,minecraft:brick_block-0
rule28=0,100,IW:concreteslab-0
rule29=0,100,minecraft:trapdoor-2
rule30=0,100,IW:computer1-0
rule31=0,100,minecraft:fence_gate-3
rule32=0,100,IW:metaldoor-1
rule33=0,100,IW:glassclear-0
rule34=2,100,WallSign:SPENT FUEL:DISPOSAL:null:null-3
rule35=0,100,minecraft:stained_glass-15
rule36=0,100,IW:metaldoor-9
rule37=0,100,IW:metaldoor-8
rule38=2,100,WallSign:FUEL ROD:DISPENSER:null:null-3
rule39=0,100,IW:lightwhite-0
rule40=2,100,WallSign:Always wear a:haz-mat suit:when handling:fuel rods.-3
rule41=2,100,WallSign:BEAR:MART:null:null-2
rule42=2,100,WallSign:HONEY:MINI:null:null-2
rule43=2,100,WallSign:Please do:not leave:spent fuel rods:on the pads. mg-3
rule44=0,100,IW:scrapmetalsheet-0
rule45=0,100,IW:machinery1-0
rule46=0,100,IC2:blockGenerator-3

layer
1,1,1,1,1,1,1,1,1,1,1,1,1,1,1,1,1,1,1
1,1,1,1,1,1,1,1,1,1,1,1,1,1,1,1,1,1,1
1,1,1,1,1,1,1,1,1,1,1,1,1,1,1,1,1,1,1
1,1,1,1,1,1,1,1,1,1,1,1,1,1,1,1,1,1,1
1,1,1,1,1,1,1,1,1,1,1,1,1,1,1,1,1,1,1
1,1,1,1,1,1,1,1,1,1,1,1,1,1,1,1,1,1,1
1,1,1,1,1,1,1,1,1,1,1,1,1,1,1,1,1,1,1
1,1,1,1,1,1,1,1,1,1,1,1,1,1,1,1,1,1,1
1,1,1,1,1,1,1,1,1,1,1,1,1,1,1,1,1,1,1
1,1,1,1,1,1,1,1,1,1,1,1,1,1,1,1,1,1,1
1,1,1,1,1,1,1,1,1,1,1,1,1,1,1,1,1,1,1
1,1,1,1,1,1,1,1,1,1,1,1,1,1,1,1,1,1,1
1,1,1,1,1,1,1,1,1,1,1,1,1,1,1,1,1,1,1
1,1,1,1,1,1,1,1,1,1,1,1,1,1,1,1,1,1,1
1,1,1,1,1,1,1,1,1,1,1,1,1,1,1,1,1,1,1
1,1,1,1,1,1,1,1,1,1,1,1,1,1,1,1,1,1,1
endlayer

layer
1,1,1,1,1,1,1,1,1,1,1,1,1,1,1,1,1,1,1
1,1,1,1,1,1,1,1,1,1,1,1,1,1,1,1,1,1,1
1,1,1,1,1,1,1,1,1,1,1,1,1,1,1,1,1,1,1
1,1,1,1,1,1,1,1,1,1,1,1,1,1,1,1,1,1,1
1,1,1,1,1,1,1,1,1,1,1,1,1,1,1,1,1,1,1
1,1,1,1,1,1,1,1,1,1,1,1,1,1,1,1,1,1,1
1,1,1,1,1,1,1,1,1,1,1,1,1,1,1,1,1,1,1
1,1,1,1,1,1,1,1,1,1,1,1,1,1,1,1,1,1,1
1,1,1,1,1,1,1,1,1,1,1,1,1,1,1,1,1,1,1
1,1,1,1,1,1,1,1,1,1,1,1,1,1,1,1,1,1,1
1,1,1,1,1,1,1,1,1,1,1,1,1,1,1,1,1,1,1
1,1,1,1,1,1,1,1,1,1,1,1,1,1,1,1,1,1,1
1,1,1,1,1,1,1,1,1,1,1,1,1,1,1,1,1,1,1
1,1,1,1,1,1,1,1,1,1,1,1,1,1,1,1,1,1,1
1,1,1,1,1,1,1,1,1,1,1,1,1,1,1,1,1,1,1
1,1,1,1,1,1,1,1,1,1,1,1,1,1,1,1,1,1,1
endlayer

layer
2,2,2,2,2,2,2,2,2,2,2,2,2,2,2,2,2,2,2
2,2,2,2,2,2,2,2,2,2,2,2,2,2,2,2,2,2,2
2,2,2,2,2,2,2,2,2,2,2,2,2,2,2,2,2,2,2
2,2,2,2,2,2,2,2,2,2,2,2,2,2,2,2,2,2,2
2,2,2,2,2,2,2,2,2,2,2,2,2,2,2,2,2,2,2
2,2,2,2,2,2,2,2,3,3,3,3,3,3,2,2,2,2,2
2,2,2,2,2,2,2,2,2,2,2,2,2,3,3,3,2,2,2
2,2,2,2,2,2,2,2,2,2,2,2,2,3,2,2,2,2,2
2,2,2,2,2,2,2,2,2,2,2,2,2,3,2,2,2,2,2
2,2,2,2,2,2,2,2,2,2,2,2,2,3,3,3,2,2,2
2,2,2,2,2,2,2,2,2,2,2,2,2,3,2,2,2,2,2
2,2,2,2,2,2,2,2,2,2,2,2,2,2,2,2,2,2,2
2,2,2,2,2,2,2,2,2,2,2,2,2,2,2,2,2,2,2
2,2,2,2,2,2,2,2,2,2,2,2,2,2,2,2,2,2,2
2,2,2,2,2,2,2,2,2,2,2,2,2,2,2,2,2,2,2
2,2,2,2,2,2,2,2,2,2,2,2,2,2,2,2,2,2,2
endlayer

layer
2,2,2,2,2,2,2,2,2,2,2,2,2,2,2,2,2,2,2
2,2,3,3,3,3,3,3,3,2,2,2,2,2,2,2,2,2,2
2,2,3,4,0,0,0,0,0,3,2,2,2,2,2,2,2,2,2
2,2,2,3,5,0,0,0,5,3,2,2,2,2,2,2,2,2,2
2,2,2,3,5,0,5,0,5,3,3,3,3,3,2,2,2,2,2
2,2,2,3,0,0,5,0,0,0,0,0,7,0,6,2,2,2,2
2,2,2,3,0,0,5,0,0,3,3,3,3,0,8,3,2,2,2
2,2,2,3,0,0,0,0,0,3,2,2,3,0,3,2,2,2,2
2,2,2,3,10,9,0,10,9,3,2,2,3,0,3,2,2,2,2
2,2,2,12,3,3,3,3,3,2,2,2,3,0,11,3,2,2,2
2,2,2,2,0,2,2,2,2,0,0,0,3,0,6,2,2,2,2
2,2,2,2,2,2,2,2,2,2,2,2,3,3,3,2,2,2,2
2,2,2,2,2,2,2,2,2,2,2,2,2,2,2,2,2,2,2
2,2,2,2,2,2,2,2,2,2,2,2,2,2,2,2,2,2,2
2,2,2,2,2,2,2,2,2,2,2,2,2,2,2,2,2,2,2
2,2,2,2,2,2,2,2,2,2,2,2,2,2,2,2,2,2,2
endlayer

layer
13,13,13,13,13,13,13,13,13,13,13,13,13,13,13,13,13,13,13
13,3,3,3,3,3,3,3,3,3,13,13,13,13,13,13,13,13,13
13,3,0,0,0,0,0,0,0,3,13,13,13,13,13,13,13,13,13
13,3,14,3,5,0,0,0,5,3,13,13,13,13,13,13,13,13,13
13,3,3,3,5,0,5,0,5,3,3,3,3,3,13,13,13,13,13
13,13,13,3,0,0,5,0,0,0,0,15,16,15,6,13,13,13,13
13,13,13,3,0,0,5,0,0,3,3,3,3,0,17,3,13,13,13
13,13,13,3,0,0,0,0,0,3,13,13,3,0,3,13,13,13,13
13,13,13,3,0,0,0,0,0,3,13,13,3,0,3,13,13,13,13
13,13,13,0,3,3,3,3,3,12,13,13,3,0,17,3,13,13,13
13,13,13,13,13,13,13,13,13,13,13,13,3,18,6,13,13,13,13
13,13,13,13,13,13,13,13,13,13,13,13,3,3,3,13,13,13,13
13,13,13,13,13,13,13,13,13,13,13,13,13,13,13,13,13,13,13
13,13,13,13,13,13,13,13,13,13,13,13,13,13,13,13,13,13,13
13,13,13,13,13,13,13,13,13,13,13,13,13,13,13,13,13,13,13
13,13,13,13,13,13,13,13,13,13,13,13,13,13,13,13,13,13,13
endlayer

layer
12,12,12,12,12,12,12,12,12,12,12,12,12,12,12,12,12,12,12
12,3,3,3,3,3,3,3,3,3,19,12,12,12,12,12,12,12,12
12,3,0,0,0,0,20,0,0,3,19,12,12,12,12,12,12,12,12
12,3,0,3,0,0,0,0,0,3,19,12,12,12,6,12,12,12,12
12,3,0,21,0,0,0,0,0,3,3,3,3,3,12,12,12,12,12
12,3,3,3,23,0,0,0,22,3,3,3,3,3,6,12,12,12,12
12,12,12,3,0,0,0,0,0,3,3,3,3,3,3,3,12,12,12
12,12,12,3,0,0,0,0,0,3,19,12,3,3,3,12,12,12,12
12,12,12,3,26,25,18,0,24,3,19,12,3,3,3,12,12,12,12
12,12,12,0,3,3,3,3,3,0,12,12,3,3,3,3,12,12,12
12,12,12,12,12,12,12,12,12,12,12,12,3,3,6,12,12,12,12
12,12,12,12,12,12,12,12,12,12,12,12,3,3,3,12,12,12,12
12,12,12,12,12,12,12,12,12,12,12,12,12,12,6,12,12,12,12
12,12,12,12,12,12,12,12,12,12,12,12,12,12,12,12,12,12,12
12,12,12,12,12,12,12,12,12,12,12,12,12,12,12,12,12,12,12
12,12,12,12,12,12,12,12,12,12,12,12,12,12,12,12,12,12,12
endlayer

layer
12,12,12,12,12,12,12,12,12,12,12,12,12,12,12,12,12,12,12
12,3,3,3,3,3,3,3,3,3,19,19,19,19,19,19,19,19,12
12,3,0,3,3,3,3,3,3,3,19,19,19,19,19,19,19,19,12
12,3,0,3,3,3,3,3,3,3,19,19,19,19,6,19,19,19,12
12,3,0,0,21,3,3,3,3,3,19,19,19,19,19,19,19,19,12
12,3,3,3,3,3,3,3,3,3,19,19,19,19,6,19,19,19,12
12,3,3,3,3,3,3,3,3,3,19,19,19,19,19,19,19,19,12
12,3,3,3,3,3,3,3,3,3,19,19,19,19,19,19,19,19,12
12,3,3,3,3,3,3,3,3,3,19,19,19,19,19,19,19,19,12
12,3,3,3,3,3,3,3,3,3,19,19,19,19,19,19,19,19,12
12,3,3,3,3,3,3,3,3,3,19,19,19,19,6,19,19,19,12
12,3,3,3,3,3,3,3,3,3,19,19,19,19,19,19,19,19,12
12,3,3,3,3,3,3,3,3,3,19,19,19,19,6,19,19,19,12
12,3,3,3,3,3,3,3,3,3,19,19,19,19,19,19,19,19,12
12,3,3,3,3,3,3,3,3,3,19,19,19,19,19,19,19,19,12
12,12,12,12,12,12,12,12,12,12,19,19,19,12,12,12,12,12,12
endlayer

layer
0,0,0,0,0,0,0,0,0,0,0,0,0,0,0,0,0,0,0
0,6,27,27,27,27,27,27,27,6,0,0,0,0,0,0,0,0,0
0,27,28,5,5,0,5,5,0,27,0,0,0,0,0,0,0,0,0
0,27,28,0,0,0,0,0,0,27,0,0,0,0,6,0,0,0,0
0,27,29,29,29,0,0,0,0,27,0,0,0,0,0,0,0,0,0
0,27,6,6,6,31,6,30,6,27,0,0,0,0,6,0,0,0,0
0,27,0,0,0,0,0,0,0,6,0,0,0,0,5,0,0,0,0
0,27,0,0,0,0,0,0,0,32,0,0,0,0,0,0,0,0,0
0,27,0,5,0,5,0,5,0,32,0,0,0,0,0,0,0,0,0
0,27,0,5,0,5,0,5,0,6,0,0,0,0,5,0,0,0,0
0,27,0,5,0,5,0,5,0,27,0,0,0,0,6,0,0,0,0
0,27,0,5,0,5,0,5,0,27,0,0,0,0,0,0,0,0,0
0,27,0,5,0,5,0,5,0,27,0,0,0,0,6,0,0,0,0
0,27,0,0,0,0,0,0,0,27,0,0,0,0,0,0,0,0,0
0,6,27,27,27,27,27,27,27,6,0,0,0,0,0,0,0,0,0
0,0,0,0,0,0,0,0,0,6,4,0,0,0,0,0,0,0,0
endlayer

layer
0,0,0,0,0,0,0,0,0,0,0,0,0,0,0,0,0,0,0
0,6,33,33,33,33,33,33,33,6,0,0,0,0,0,0,0,0,0
0,33,0,5,5,0,5,5,0,33,0,0,0,0,0,0,0,0,0
0,33,0,0,0,0,0,0,0,33,0,0,0,0,6,0,0,0,0
0,33,0,0,0,0,0,0,0,33,0,0,0,0,0,0,0,0,0
0,33,0,0,0,0,0,35,0,33,0,0,0,34,6,0,0,0,0
0,33,0,0,0,0,0,0,0,6,0,0,0,0,5,0,0,0,0
0,33,0,0,0,0,0,0,0,36,0,0,0,0,0,0,0,0,0
0,33,0,5,0,5,0,5,0,37,0,0,0,0,0,0,0,0,0
0,33,0,5,0,5,0,5,0,6,0,0,0,0,5,0,0,0,0
0,33,0,5,0,5,0,5,0,33,0,0,0,38,6,0,0,0,0
0,33,0,5,0,5,0,5,0,33,0,0,0,0,0,0,0,0,0
0,33,0,5,0,5,0,5,0,33,0,0,0,0,6,0,0,0,0
0,33,0,0,0,0,0,0,0,33,0,0,0,0,0,0,0,0,0
0,6,33,33,33,33,33,33,33,6,0,0,0,0,0,0,0,0,0
0,0,0,0,0,0,0,0,6,4,0,0,0,0,0,0,0,0,0
endlayer

layer
0,0,0,0,0,0,0,0,0,0,0,0,0,0,0,0,0,0,0
0,6,33,33,33,33,33,33,33,6,0,0,0,0,0,0,0,0,0
0,33,0,0,0,0,0,0,0,33,0,0,0,0,39,0,0,0,0
0,33,0,0,0,0,0,0,0,33,0,0,0,40,6,0,0,0,0
0,33,0,0,0,0,0,0,0,33,0,0,0,0,39,0,0,0,0
0,33,0,0,0,0,0,0,0,33,0,0,0,0,0,0,0,0,0
0,33,0,0,0,0,0,0,0,6,0,0,0,0,0,0,0,0,0
0,33,0,0,0,0,0,0,0,6,41,0,0,0,0,0,0,0,0
0,33,0,0,0,0,0,0,0,6,42,0,0,0,0,0,0,0,0
0,33,0,0,0,0,0,0,0,6,0,0,0,0,0,0,0,0,0
0,33,0,0,0,0,0,0,0,33,0,0,0,0,0,0,0,0,0
0,33,0,0,0,0,0,0,0,33,0,0,0,0,39,0,0,0,0
0,33,0,0,0,0,0,0,0,33,0,0,0,43,6,0,0,0,0
0,33,0,0,0,0,0,0,0,33,0,0,0,0,39,0,0,0,0
0,6,33,33,33,33,33,33,33,6,0,0,0,0,0,0,0,0,0
0,0,0,0,0,0,0,6,4,0,0,0,0,0,0,0,0,0,0
endlayer

layer
0,0,0,0,0,0,0,0,0,0,0,0,0,0,0,0,0,0,0
0,6,6,6,6,6,6,6,6,6,0,0,0,0,0,0,0,0,0
0,6,5,5,5,5,5,5,5,6,0,6,6,6,6,6,6,6,0
0,6,5,5,5,39,5,5,5,6,0,6,44,44,6,44,44,6,0
0,6,5,5,5,45,5,5,5,6,0,6,44,44,6,44,44,6,0
0,6,5,5,5,5,5,5,5,6,0,6,44,44,6,44,44,6,0
0,6,5,5,5,5,5,5,5,6,6,6,44,44,6,44,44,6,0
0,6,5,5,5,39,5,5,5,6,5,6,44,44,6,44,44,6,0
0,6,5,5,5,39,5,5,5,6,5,6,44,44,6,44,44,6,0
0,6,5,5,5,5,5,5,5,6,6,6,44,44,6,44,44,6,0
0,6,5,5,5,5,5,5,5,6,0,6,44,44,6,44,44,6,0
0,6,5,5,5,45,5,5,5,6,0,6,44,44,6,44,44,6,0
0,6,5,5,5,39,5,5,5,6,0,6,44,44,6,44,44,6,0
0,6,5,5,5,5,5,5,5,6,0,6,6,6,6,6,6,6,0
0,6,6,6,6,6,6,6,6,6,0,0,0,0,0,0,0,0,0
0,0,0,0,0,0,6,4,0,0,0,0,0,0,0,0,0,0,0
endlayer

layer
0,0,0,0,0,0,0,0,0,0,0,0,0,0,0,0,0,0,0
0,0,0,0,0,0,0,0,0,0,0,0,0,0,0,0,0,0,0
0,0,0,0,0,0,0,0,0,0,0,0,0,0,0,0,0,0,0
0,0,0,0,0,0,0,0,0,0,0,0,0,0,0,0,0,0,0
0,0,0,0,0,0,0,0,0,0,0,0,0,0,0,0,0,0,0
0,0,0,0,0,0,0,0,0,0,0,0,0,0,46,0,0,0,0
0,0,0,0,0,0,0,0,0,0,0,0,0,0,0,0,0,0,0
0,0,0,0,0,0,0,0,0,0,0,0,0,0,0,0,0,0,0
0,0,0,0,0,0,0,0,0,0,0,0,0,0,0,0,0,0,0
0,0,0,0,0,0,0,0,0,0,0,0,0,0,0,0,0,0,0
0,0,0,0,0,0,0,0,0,0,0,0,0,0,46,0,0,0,0
0,0,0,0,0,0,0,0,0,0,0,0,0,0,0,0,0,0,0
0,0,0,0,0,0,0,0,0,0,0,0,0,0,0,0,0,0,0
0,0,0,0,0,0,0,0,0,0,0,0,0,0,0,0,0,0,0
0,0,0,0,0,0,0,0,0,0,0,0,0,0,0,0,0,0,0
0,0,0,0,0,0,0,0,0,0,0,0,0,0,0,0,0,0,0
endlayer

