
# Created by Ruins mod version 15.3 Ingame Parser
# authoring Player: Mensrea

weight=10
embed_into_distance=7
acceptable_target_blocks=
unacceptable_target_blocks=flowing_water,water,flowing_lava,lava
dimensions=11,12,12
allowable_overhang=0
max_leveling=2
leveling_buffer=0
preserve_water=0
preserve_lava=0
preventRotation=1

rule1=0,100,PFAAGeologica:strongStone-7
rule2=0,100,PFAAGeologica:mediumStone-3
rule3=0,100,IW:concrete-0
rule4=0,100,PFAAGeologica:weakStone-1
rule5=0,100,MobSpawner:demonmobs.belph
rule6=0,100,MobSpawner:demonmobs.pinky
rule7=0,100,minecraft:sand-1
rule8=0,100,IW:concreteslab-0
rule9=0,100,IW:bush-0

layer
1,1,1,1,1,1,1,1,1,1,1,1
1,1,1,1,1,1,1,1,1,1,1,1
1,1,1,1,1,1,1,1,1,1,1,1
1,1,1,1,1,1,1,1,1,1,1,1
1,1,1,1,1,1,1,1,1,1,1,1
1,1,1,1,1,1,1,1,1,1,1,1
1,1,1,1,1,1,1,1,1,1,1,1
1,1,1,1,1,1,1,1,1,1,1,1
1,1,1,1,1,1,1,1,1,1,1,1
1,1,1,1,1,1,1,1,1,1,1,1
1,1,1,1,1,1,1,1,1,1,1,1
1,1,1,1,1,1,1,1,1,1,1,1
endlayer

layer
1,1,1,1,1,1,1,1,1,1,1,1
1,1,1,1,1,1,1,1,1,1,1,1
1,1,1,1,1,1,1,1,1,1,1,1
1,1,1,1,1,1,1,1,1,1,1,1
1,1,1,1,1,1,1,1,1,1,1,1
1,1,1,1,1,1,1,1,1,1,1,1
1,1,1,1,1,1,1,1,1,1,1,1
1,1,1,1,1,1,1,1,1,1,1,1
1,1,1,1,1,1,1,1,1,1,1,1
1,1,1,1,1,1,1,1,1,1,1,1
1,1,1,1,1,1,1,1,1,1,1,1
1,1,1,1,1,1,1,1,1,1,1,1
endlayer

layer
2,2,2,2,2,2,2,2,2,2,2,2
2,2,2,2,2,2,2,2,2,2,2,2
2,2,2,2,2,2,2,2,2,2,2,2
2,2,2,2,2,2,2,2,2,2,2,2
2,2,2,2,2,2,2,2,2,2,2,2
2,2,2,2,2,3,2,2,2,2,2,2
2,2,2,2,2,2,2,2,2,2,2,2
2,2,2,2,2,2,2,2,2,2,2,2
2,2,2,2,2,3,2,2,2,2,2,2
2,2,2,2,2,2,2,2,2,2,2,2
2,2,2,2,2,2,2,2,2,2,2,2
2,2,2,2,2,2,2,2,2,2,2,2
endlayer

layer
2,2,2,2,2,2,2,2,2,2,2,2
2,2,2,2,2,2,2,2,2,2,2,2
2,2,2,2,2,2,2,2,2,2,2,2
2,2,2,2,2,2,2,2,2,2,2,2
2,2,2,2,2,3,2,2,2,2,2,2
2,2,2,2,3,3,3,2,2,2,2,2
2,2,2,2,0,3,2,2,2,2,2,2
2,2,2,2,3,2,3,2,2,2,2,2
2,2,2,2,2,3,2,2,2,2,2,2
2,2,2,2,2,2,2,2,2,2,2,2
2,2,2,2,2,2,2,2,2,2,2,2
2,2,2,2,2,2,2,2,2,2,2,2
endlayer

layer
4,4,4,4,4,4,4,4,4,4,4,4
4,4,4,4,4,4,4,4,4,4,4,4
4,4,4,4,4,4,4,4,4,4,4,4
4,4,4,4,4,4,4,4,4,4,4,4
4,4,4,4,4,3,4,4,4,4,4,4
4,4,4,4,3,5,3,4,4,4,4,4
4,4,4,4,3,3,3,4,4,4,4,4
4,4,4,3,6,3,6,3,4,4,4,4
4,4,4,4,3,3,3,4,4,4,4,4
4,4,4,4,3,3,3,4,4,4,4,4
4,4,4,4,4,4,4,4,4,4,4,4
4,4,4,4,4,4,4,4,4,4,4,4
endlayer

layer
7,7,7,7,7,7,7,7,7,7,7,7
7,7,7,7,7,7,7,7,7,7,7,7
7,7,7,7,7,7,7,7,7,7,7,7
7,7,7,7,7,7,7,7,7,7,7,7
7,7,7,3,3,3,3,3,7,7,7,7
7,7,7,3,8,8,8,3,7,7,7,7
7,7,7,3,8,8,8,3,7,7,7,7
7,7,7,3,8,8,8,3,7,7,7,7
7,7,7,3,8,8,8,3,7,7,7,7
7,7,7,3,8,8,8,3,7,7,7,7
7,7,7,7,7,7,7,7,7,7,7,7
7,7,7,7,7,7,7,7,7,7,7,7
endlayer

layer
9,0,7,7,7,7,0,0,7,7,7,7
0,0,0,7,7,7,7,7,7,7,7,7
7,0,7,7,7,7,7,7,7,7,7,7
7,7,7,7,7,7,7,7,7,7,7,7
7,7,7,3,3,3,3,3,7,7,7,7
7,7,7,3,0,0,0,3,7,7,7,0
7,7,7,3,0,0,0,3,7,7,7,0
7,7,7,3,0,0,0,3,7,7,7,0
7,7,7,3,0,0,0,3,7,7,7,7
7,7,7,3,0,0,0,3,7,7,7,7
7,7,7,7,0,0,0,7,7,7,7,0
7,7,7,7,0,0,0,7,7,7,0,0
endlayer

layer
0,0,0,7,7,0,0,0,0,0,0,0
0,0,0,0,0,0,0,0,0,7,7,7
0,0,0,0,7,7,7,0,0,7,7,0
0,0,0,7,7,7,7,7,0,0,7,0
0,0,7,3,3,3,3,3,7,0,0,0
0,7,7,3,0,0,0,3,7,7,0,0
0,7,7,3,0,0,0,3,7,7,0,0
0,7,7,3,0,0,0,3,7,7,0,0
0,7,7,3,0,0,0,3,7,0,0,0
0,7,7,3,0,0,0,3,7,7,0,0
0,0,7,7,0,0,0,7,7,0,9,0
7,7,0,0,0,0,0,0,0,0,0,0
endlayer

layer
0,0,0,0,0,0,0,0,0,0,0,0
0,0,0,0,0,0,0,0,0,0,0,0
0,0,0,0,0,0,0,0,0,0,7,0
0,0,0,0,7,7,7,0,0,0,0,0
0,0,0,7,7,3,7,7,0,0,0,0
0,0,7,7,3,3,3,7,7,0,0,0
0,0,7,3,3,3,3,3,7,0,0,0
0,0,7,7,3,3,3,7,7,0,0,0
0,0,7,7,3,3,3,7,0,0,0,0
0,0,7,3,3,3,3,3,7,0,0,0
0,0,0,0,0,0,0,0,0,0,0,0
0,9,0,0,0,0,0,0,0,0,0,0
endlayer

layer
0,0,0,0,0,0,0,0,0,0,0,0
0,0,0,0,0,0,0,0,0,0,0,0
0,0,0,0,0,0,0,0,0,0,9,0
0,0,0,0,0,0,0,0,0,0,0,0
0,0,0,0,0,7,0,0,0,0,0,0
0,0,0,0,7,7,7,0,0,0,0,0
0,0,0,7,7,7,7,7,0,0,0,0
0,0,0,7,7,7,7,0,0,0,0,0
0,0,0,7,7,7,7,0,0,0,0,0
0,0,0,7,7,7,7,7,0,0,0,0
0,0,0,0,0,0,0,0,0,0,0,0
0,0,0,0,0,0,0,0,0,0,0,0
endlayer

layer
0,0,0,0,0,0,0,0,0,0,0,0
0,0,0,0,0,0,0,0,0,0,0,0
0,0,0,0,0,0,0,0,0,0,0,0
0,0,0,0,0,0,0,0,0,0,0,0
0,0,0,0,0,0,0,0,0,0,0,0
0,0,0,0,0,0,0,0,0,0,0,0
0,0,0,0,0,9,0,0,0,0,0,0
0,0,0,9,0,7,0,0,0,0,0,0
0,0,0,0,7,7,7,0,0,0,0,0
0,0,0,0,0,7,0,0,0,0,0,0
0,0,0,0,0,0,0,0,0,0,0,0
0,0,0,0,0,0,0,0,0,0,0,0
endlayer

