
# Created by Ruins mod version 15.3 Ingame Parser
# authoring Player: Mensrea

weight=8
embed_into_distance=7
acceptable_target_blocks=
unacceptable_target_blocks=flowing_water,water,flowing_lava,lava
dimensions=12,22,20
allowable_overhang=0
max_leveling=2
leveling_buffer=0
preserve_water=0
preserve_lava=0
preventRotation=1

rule1=0,100,PFAAGeologica:strongStone-7
rule2=0,100,IW:metalladder-3
rule3=0,100,IW:metaldoor-1
rule4=0,100,IW:steelsiding-0
rule5=0,100,minecraft:sandstone_stairs-0
rule6=0,100,minecraft:sandstone_stairs-3
rule7=0,100,PFAAGeologica:strongStoneBrick-9
rule8=0,100,minecraft:farmland-7
rule9=0,100,minecraft:sandstone_stairs-2
rule10=0,100,minecraft:bed-3
rule11=0,100,minecraft:oak_stairs-1
rule12=0,100,minecraft:bed-11
rule13=0,100,minecraft:log-3
rule14=0,100,minecraft:water-0
rule15=0,100,PFAAGeologica:mediumStone-3
rule16=0,100,ChestGenHook:strongholdCorridor:5-2
rule17=0,100,IW:metaldoor-8
rule18=0,100,ChestGenHook:strongholdCorridor:5-2
rule19=0,100,IC2:blockGenerator-0
rule20=0,100,minecraft:wheat-7
rule21=0,100,minecraft:potatoes-7
rule22=0,100,minecraft:planks-0
rule23=0,100,minecraft:wheat-3
rule24=0,100,minecraft:wheat-5
rule25=0,100,PFAAGeologica:strongStone-9
rule26=0,100,IW:smalllightwhite-3
rule27=0,100,IW:lightwhite-0
rule28=0,100,IW:smalllightwhite-4
rule29=0,100,PFAAGeologica:weakStone-1
rule30=0,100,PFAAGeologica:strongStoneBrickStairs.marble-3
rule31=0,100,minecraft:fence-0
rule32=0,100,minecraft:spruce_stairs-2
rule33=0,100,minecraft:bookshelf-0
rule34=0,100,IW:metaldoor-2
rule35=0,100,IW:metalhatch-3
rule36=0,100,ThermalExpansion:Workbench-1
rule37=0,100,enviromine:freezer-5
rule38=0,100,minecraft:cauldron-3
rule39=0,100,PFAAGeologica:strongStone-5
rule40=0,100,minecraft:furnace-2
rule41=0,100,IW:machinery2-0
rule42=0,100,IW:metaldoor-0
rule43=0,100,minecraft:spruce_stairs-1
rule44=0,100,ChestGenHook:mineshaftCorridor:5-2
rule45=0,100,minecraft:spruce_stairs-3
rule46=0,100,ChestGenHook:mineshaftCorridor:5-2
rule47=0,100,IW:computer1-0
rule48=0,100,minecraft:spruce_stairs-0
rule49=0,100,minecraft:sand-1
rule50=0,100,minecraft:wooden_pressure_plate-0
rule51=0,100,minecraft:flower_pot-7
rule52=0,100,minecraft:stained_glass-15
rule53=0,100,minecraft:flower_pot-2
rule54=0,100,minecraft:flower_pot-0
rule55=0,100,IW:bush-0
rule56=0,100,IW:smalllightwhite-2
rule57=0,100,IW:smalllightwhite-1

layer
1,1,1,1,1,1,1,1,1,1,1,1,1,1,1,1,1,1,1,1
1,1,1,1,1,1,1,1,1,1,1,1,1,1,1,1,1,1,1,1
1,1,1,1,1,1,1,1,1,1,1,1,1,1,1,1,1,1,1,1
1,1,1,1,1,1,1,1,1,1,1,1,1,1,1,1,1,1,1,1
1,1,1,1,1,1,1,1,1,1,1,1,1,1,1,1,1,1,1,1
1,1,1,1,1,1,1,1,1,1,1,1,1,1,1,1,1,1,1,1
1,1,1,1,1,1,1,1,1,1,1,1,1,1,1,1,1,1,1,1
1,1,1,1,1,1,1,1,1,1,1,1,1,1,1,1,1,1,1,1
1,1,1,1,1,1,1,1,1,1,1,1,1,1,1,1,1,1,1,1
1,1,1,1,1,1,1,1,1,1,1,1,1,1,1,1,1,1,1,1
1,1,1,1,1,1,1,1,1,1,1,1,1,1,1,1,1,1,1,1
1,1,1,1,1,1,1,1,1,1,1,1,1,1,1,1,1,1,1,1
1,1,1,1,1,1,1,1,1,1,1,1,1,1,1,1,1,1,1,1
1,1,1,1,1,1,1,1,1,1,1,1,1,1,1,1,1,1,1,1
1,1,1,1,1,1,1,1,1,1,1,1,1,1,1,1,1,1,1,1
1,1,1,1,1,1,1,1,1,1,1,1,1,1,1,1,1,1,1,1
1,1,1,1,1,1,1,1,1,1,1,1,1,1,1,1,1,1,1,1
1,1,1,1,1,1,1,1,1,1,1,1,1,1,1,1,1,1,1,1
1,1,1,1,1,1,1,1,1,1,1,1,1,1,1,1,1,1,1,1
1,1,1,1,1,1,1,1,1,1,1,1,1,1,1,1,1,1,1,1
1,1,1,1,1,1,1,1,1,1,1,1,1,1,1,1,1,1,1,1
1,1,1,1,1,1,1,1,1,1,1,1,1,1,1,1,1,1,1,1
endlayer

layer
1,1,1,1,1,1,1,1,1,1,1,1,1,1,1,1,1,1,1,1
1,1,1,1,1,1,1,1,1,1,1,1,1,1,1,1,1,1,1,1
1,1,1,1,1,1,1,1,1,1,1,1,1,1,1,1,1,1,1,1
1,1,1,1,1,1,1,1,1,1,1,1,1,1,1,1,1,1,1,1
1,1,1,1,1,1,1,1,1,1,1,1,1,1,1,1,1,1,1,1
1,1,1,1,1,1,1,1,1,1,1,1,1,1,1,1,1,1,1,1
1,1,1,1,1,1,1,1,1,1,1,1,1,1,1,1,1,1,1,1
1,1,1,1,1,1,1,1,1,1,1,1,1,1,1,1,1,1,1,1
1,1,1,1,1,1,1,1,1,1,1,1,1,1,1,1,1,1,1,1
1,1,1,1,1,1,1,4,0,3,0,0,0,0,2,1,1,1,1,1
1,1,1,1,1,1,1,0,0,7,5,5,0,6,5,1,1,1,1,1
1,1,1,1,1,1,1,11,10,7,8,9,0,6,8,1,1,1,1,1
1,1,1,1,1,1,1,13,12,7,8,9,0,6,8,1,1,1,1,1
1,1,1,1,1,1,1,7,7,7,8,9,0,6,8,1,1,1,1,1
1,1,1,1,1,1,1,1,1,7,14,9,0,6,14,1,1,1,1,1
1,1,1,1,1,1,1,1,1,7,8,9,0,6,8,1,1,1,1,1
1,1,1,1,1,1,1,1,1,7,8,9,0,6,8,1,1,1,1,1
1,1,1,1,1,1,1,1,1,7,8,9,4,6,8,1,1,1,1,1
1,1,1,1,1,1,1,1,1,1,7,7,7,7,7,1,1,1,1,1
1,1,1,1,1,1,1,1,1,1,1,1,1,1,1,1,1,1,1,1
1,1,1,1,1,1,1,1,1,1,1,1,1,1,1,1,1,1,1,1
1,1,1,1,1,1,1,1,1,1,1,1,1,1,1,1,1,1,1,1
endlayer

layer
15,15,15,15,15,15,15,15,15,15,15,15,15,15,15,15,15,15,15,15
15,15,15,15,15,15,15,15,15,15,15,15,15,15,15,15,15,15,15,15
15,15,15,15,15,15,15,15,15,15,15,15,15,15,15,15,15,15,15,15
15,15,15,15,15,15,15,15,15,15,15,15,15,15,15,15,15,15,15,15
15,15,15,15,15,15,15,15,15,15,15,15,15,15,15,15,15,15,15,15
15,15,15,7,7,7,7,15,15,15,15,15,15,15,15,15,15,15,15,15
15,15,15,7,0,0,6,15,15,15,15,15,15,15,15,15,15,15,15,15
15,15,15,7,0,0,6,15,15,15,15,15,15,15,15,15,15,15,15,15
15,15,15,7,16,0,7,15,7,7,7,7,7,7,7,7,15,15,15,15
15,15,15,7,18,0,7,4,0,17,0,0,0,0,2,7,15,15,15,15
15,15,15,19,0,0,7,0,0,7,0,0,0,0,0,7,15,15,15,15
15,15,15,7,22,0,7,0,0,7,21,0,0,0,20,7,15,15,15,15
15,15,15,7,22,0,7,0,0,7,21,0,0,0,23,7,15,15,15,15
15,15,15,15,0,0,15,7,7,7,21,0,0,0,24,7,15,15,15,15
15,15,15,15,0,22,15,15,15,7,0,0,0,0,0,7,15,15,15,15
15,15,15,15,0,22,15,15,15,7,21,0,0,0,20,7,15,15,15,15
15,15,15,15,0,0,15,15,15,7,21,0,0,0,20,7,15,15,15,15
15,15,15,15,0,22,15,15,15,7,21,0,4,0,20,7,15,15,15,15
15,15,15,15,0,22,15,15,15,15,7,7,7,7,7,7,15,15,15,15
15,15,15,15,2,25,15,15,15,15,15,15,15,15,15,15,15,15,15,15
15,15,15,15,15,15,15,15,15,15,15,15,15,15,15,15,15,15,15,15
15,15,15,15,15,15,15,15,15,15,15,15,15,15,15,15,15,15,15,15
endlayer

layer
15,15,15,15,15,15,15,15,15,15,15,15,15,15,15,15,15,15,15,15
15,15,15,15,15,15,15,15,15,15,15,15,15,15,15,15,15,15,15,15
15,15,15,15,15,15,15,15,15,15,15,15,15,15,15,15,15,15,15,15
15,15,15,15,15,15,15,15,15,15,15,15,15,15,15,15,15,15,15,15
15,15,15,15,15,15,15,15,15,15,15,15,15,15,15,15,15,15,15,15
15,15,15,7,7,7,7,15,15,15,15,15,15,15,15,15,15,15,15,15
15,15,15,7,0,0,0,6,15,15,15,15,15,15,15,15,15,15,15,15
15,15,15,7,0,0,0,6,15,15,15,15,15,15,15,15,15,15,15,15
15,15,15,7,0,26,7,7,7,7,7,7,7,7,7,7,15,15,15,15
15,15,15,7,0,0,7,0,0,0,0,0,0,0,2,7,15,15,15,15
15,15,15,4,0,0,7,0,0,7,0,0,0,0,0,7,15,15,15,15
15,15,15,7,0,0,7,0,0,7,27,0,0,0,27,7,15,15,15,15
15,15,15,7,0,0,7,28,0,7,0,0,0,0,0,7,15,15,15,15
15,15,15,15,0,26,15,7,7,7,27,0,0,0,27,7,15,15,15,15
15,15,15,15,0,0,15,15,15,7,0,0,0,0,0,7,15,15,15,15
15,15,15,15,0,0,15,15,15,7,27,0,0,0,27,7,15,15,15,15
15,15,15,15,0,0,15,15,15,7,0,0,0,0,0,7,15,15,15,15
15,15,15,15,0,0,15,15,15,7,27,0,0,0,27,7,15,15,15,15
15,15,15,15,0,26,15,15,15,15,7,7,7,7,7,7,15,15,15,15
15,15,15,15,2,25,15,15,15,15,15,15,15,15,15,15,15,15,15,15
15,15,15,15,15,15,15,15,15,15,15,15,15,15,15,15,15,15,15,15
15,15,15,15,15,15,15,15,15,15,15,15,15,15,15,15,15,15,15,15
endlayer

layer
29,29,29,29,29,29,29,29,29,29,29,29,29,29,29,29,29,29,29,29
29,29,29,29,29,29,29,29,29,29,29,29,29,29,29,29,29,29,29,29
29,29,29,29,29,29,29,29,29,29,29,29,29,29,29,29,29,29,29,29
29,29,29,29,29,29,29,29,29,29,29,29,29,29,29,29,29,29,29,29
29,29,29,29,29,29,29,29,29,29,29,29,29,29,29,29,29,29,29,29
29,29,29,25,25,25,25,25,25,25,25,25,25,25,25,25,29,29,29,29
29,29,29,25,0,0,0,0,6,25,25,25,25,25,25,25,29,29,29,29
29,29,29,25,0,0,0,0,6,25,25,25,25,25,25,25,29,29,29,29
29,29,29,25,25,25,25,25,25,25,25,25,25,25,25,25,29,29,29,29
29,29,29,25,25,25,25,25,25,25,25,25,25,25,2,25,29,29,29,29
29,29,29,4,25,25,25,25,25,25,25,25,25,25,25,25,29,29,29,29
29,29,29,25,25,25,25,25,25,25,25,25,25,25,25,25,29,29,29,29
29,29,29,25,25,25,25,25,25,25,25,25,25,25,25,25,29,29,29,29
29,29,29,25,25,25,25,25,25,25,25,25,25,25,25,25,29,29,29,29
29,29,29,25,25,25,25,25,25,25,25,25,25,25,25,25,29,29,29,29
29,29,29,25,25,25,25,25,25,25,25,25,25,25,25,25,29,29,29,29
29,29,29,25,25,25,25,25,25,25,25,25,25,25,25,25,29,29,29,29
29,29,29,25,25,25,25,25,25,25,25,25,25,25,25,25,29,29,29,29
29,29,29,25,25,25,25,25,25,25,25,25,25,25,25,25,29,29,29,29
29,29,29,29,2,25,29,29,29,29,29,29,29,29,29,29,29,29,29,29
29,29,29,29,29,29,29,29,29,29,29,29,29,29,29,29,29,29,29,29
29,29,29,29,29,29,29,29,29,29,29,29,29,29,29,29,29,29,29,29
endlayer

layer
29,29,29,29,29,29,29,29,29,29,29,29,29,29,29,29,29,29,29,29
29,29,29,29,29,29,29,29,29,29,29,29,29,29,29,29,29,29,29,29
29,29,29,29,29,29,29,29,29,29,29,29,29,29,29,29,29,29,29,29
29,29,29,29,29,29,29,29,29,29,29,29,29,29,29,29,29,29,29,29
29,29,29,29,29,29,29,29,29,29,29,29,29,29,29,29,29,29,29,29
29,29,29,7,7,7,7,7,7,7,7,7,7,7,7,7,29,29,29,29
29,29,29,7,0,0,0,0,0,33,32,31,7,0,30,7,29,29,29,29
29,29,29,7,0,0,0,0,0,33,0,0,7,0,4,7,29,29,29,29
29,29,29,7,7,7,7,7,7,7,7,34,7,34,7,7,29,29,29,29
29,29,29,7,39,38,37,36,4,4,0,0,0,0,35,7,29,29,29,29
29,29,29,41,40,0,0,0,0,0,0,0,0,0,6,7,29,29,29,29
29,29,29,7,39,0,0,0,0,0,0,0,0,0,4,7,29,29,29,29
29,29,29,7,0,0,43,0,0,33,7,42,7,7,7,7,29,29,29,29
29,29,29,7,4,0,13,13,0,45,7,0,43,0,44,7,29,29,29,29
29,29,29,7,47,0,13,13,0,45,7,0,31,0,46,7,29,29,29,29
29,29,29,7,4,0,13,13,0,45,7,0,0,0,0,7,29,29,29,29
29,29,29,7,0,0,0,48,0,45,7,0,10,10,0,7,29,29,29,29
29,29,29,7,33,48,48,48,48,13,7,4,12,12,4,7,29,29,29,29
29,29,29,7,7,7,7,7,7,7,7,7,7,7,7,7,29,29,29,29
29,29,29,29,2,25,29,29,29,29,29,29,29,29,29,29,29,29,29,29
29,29,29,29,29,29,29,29,29,29,29,29,29,29,29,29,29,29,29,29
49,29,29,29,29,29,29,29,29,29,29,29,29,29,29,29,29,29,29,29
endlayer

layer
49,49,49,49,49,49,49,49,49,49,49,49,49,49,49,49,49,49,49,49
49,49,49,49,49,49,49,49,49,49,49,49,49,49,49,49,49,49,49,49
49,49,49,49,49,49,49,49,49,49,49,49,49,49,49,49,49,49,49,49
49,49,49,49,49,49,49,49,49,49,49,49,49,49,49,49,49,49,49,49
49,49,49,49,49,49,49,49,49,49,49,49,49,49,49,49,49,49,49,49
49,49,49,7,7,7,7,7,7,7,7,7,7,7,7,7,49,49,49,49
49,49,49,7,0,0,0,0,0,33,0,50,7,0,0,7,49,49,49,49
49,49,49,7,0,0,0,0,0,33,0,0,7,0,0,7,49,49,49,49
49,49,49,7,7,7,7,7,7,7,7,17,7,17,7,7,49,49,49,49
49,49,49,7,0,0,0,0,4,4,0,0,0,0,0,7,25,25,25,25
49,49,49,4,0,0,0,0,0,0,0,0,0,0,0,6,25,25,25,25
49,49,49,7,0,0,0,0,0,0,0,0,0,0,4,7,25,25,25,25
49,49,49,7,0,0,0,0,0,51,7,17,7,7,7,7,49,49,49,49
49,49,49,7,52,0,0,0,0,0,7,0,0,0,0,7,49,49,49,49
49,49,49,7,52,0,0,0,0,0,7,0,50,0,0,7,49,49,49,49
49,49,49,7,52,0,0,0,0,0,7,0,0,0,0,7,49,49,49,49
49,49,49,7,0,0,0,0,0,0,7,0,0,0,0,7,49,49,49,49
49,49,49,7,54,0,0,0,0,53,7,4,0,0,4,7,49,49,49,49
49,49,49,7,7,7,7,7,7,7,7,7,7,7,7,7,49,49,49,49
49,49,49,49,2,25,49,49,49,49,49,49,49,49,49,49,49,49,0,49
49,49,49,49,49,49,49,49,49,49,49,49,49,49,49,49,49,0,0,49
0,49,49,49,49,49,49,49,49,49,49,49,49,49,49,49,49,49,49,49
endlayer

layer
49,49,49,0,0,0,49,0,0,0,49,49,0,0,0,0,0,0,49,0
49,49,55,0,0,49,49,49,0,0,0,0,0,0,49,0,0,55,49,49
49,0,0,0,49,49,49,49,49,0,55,0,0,49,49,49,0,0,0,49
0,0,0,49,49,49,49,49,49,49,49,49,49,49,49,49,49,0,0,49
0,0,49,49,49,49,49,49,49,49,49,49,49,49,49,49,49,49,0,0
0,49,49,7,7,7,7,7,7,7,7,7,7,7,7,7,49,49,49,55
0,49,49,7,0,0,0,0,0,33,0,0,7,0,0,7,49,49,49,0
0,49,49,7,0,0,0,0,0,33,56,0,7,0,56,7,49,49,49,0
0,49,49,7,7,7,7,7,7,7,7,31,7,31,7,7,49,49,49,0
0,49,49,7,28,0,0,0,0,0,57,0,0,0,26,7,25,7,7,0
0,49,49,4,0,0,0,0,0,0,0,0,0,0,0,0,3,0,0,0
0,49,49,7,0,0,0,0,0,0,56,0,0,0,26,7,25,7,7,0
0,49,49,7,0,0,0,0,0,26,7,31,7,7,7,7,49,49,49,49
0,49,49,7,52,0,0,0,0,0,7,0,0,0,57,7,49,49,49,49
0,49,49,7,52,0,0,0,0,0,7,0,0,0,0,7,49,49,49,49
0,49,49,7,52,0,0,0,0,0,7,0,0,0,0,7,49,49,49,0
0,49,49,7,0,0,0,0,0,0,7,0,0,0,0,7,49,49,0,0
0,49,49,7,28,0,0,0,0,26,7,56,0,0,56,7,49,49,0,0
0,49,49,7,7,7,7,7,7,7,7,7,7,7,7,7,49,49,0,0
0,0,49,49,2,25,49,49,49,49,49,49,49,49,49,49,49,0,0,0
0,0,0,49,49,49,49,49,49,49,49,49,49,49,49,49,0,0,0,0
0,0,0,0,0,0,0,0,0,0,0,0,0,0,0,0,0,0,0,0
endlayer

layer
0,0,0,0,0,0,0,0,0,0,0,0,0,0,0,0,0,0,0,0
0,0,0,0,0,0,49,0,0,0,0,0,0,0,0,0,0,0,0,0
0,0,0,0,0,49,49,49,0,0,0,0,0,0,49,0,0,0,0,0
0,0,0,0,49,49,49,49,49,0,0,0,0,49,49,49,0,0,0,0
0,0,0,49,49,49,49,49,49,49,49,49,49,49,49,49,49,0,0,0
0,0,49,49,7,7,7,7,7,7,7,7,7,7,7,49,49,49,0,0
0,0,49,7,4,4,4,4,4,4,4,4,7,4,4,7,49,49,0,0
0,0,49,7,4,4,4,4,4,4,4,4,7,4,4,7,49,49,0,0
0,0,49,7,7,7,7,7,7,7,25,25,25,25,25,7,49,49,0,0
0,0,49,7,4,4,4,4,4,4,4,4,4,4,4,7,25,7,7,0
0,0,49,4,4,4,4,4,4,4,4,4,4,4,0,0,17,0,0,0
0,0,49,7,4,4,4,4,4,4,4,4,4,4,4,7,25,7,7,0
0,0,49,7,4,4,4,4,4,4,25,25,25,7,7,7,49,49,49,0
0,0,49,7,4,4,4,4,4,4,7,4,4,4,4,7,49,49,49,0
0,0,49,7,4,4,4,4,4,4,7,4,4,4,4,7,49,49,49,0
0,0,49,7,4,4,4,4,4,4,7,4,4,4,4,7,49,49,0,0
0,55,49,7,4,4,4,4,4,4,7,4,4,4,4,7,49,0,0,0
0,0,49,7,4,4,4,4,4,4,7,4,4,4,4,7,49,55,0,0
0,0,49,49,7,7,7,7,7,7,7,7,7,7,7,49,49,0,0,0
0,0,0,49,25,49,49,49,49,49,49,49,49,49,49,49,0,0,0,0
0,0,0,0,0,0,0,0,55,0,0,0,0,0,0,0,0,0,0,0
0,0,0,0,0,0,0,0,0,0,0,0,0,0,0,0,0,0,0,0
endlayer

layer
0,0,0,0,0,0,0,0,0,0,0,0,0,0,0,0,0,0,0,0
0,0,0,0,0,0,0,0,0,0,0,0,0,0,0,0,0,0,0,0
0,0,0,0,0,0,49,0,0,0,0,0,0,0,0,0,0,0,0,0
0,0,0,0,0,49,49,49,0,0,0,0,0,0,49,0,0,0,0,0
0,0,0,0,49,49,49,49,49,0,0,0,0,49,49,49,0,0,0,0
0,0,0,49,49,49,49,49,49,49,49,49,49,49,49,49,0,0,0,0
0,0,0,49,49,49,49,49,49,49,49,49,49,49,49,49,49,0,0,0
0,0,0,49,49,49,49,49,49,49,49,49,49,49,49,49,49,0,0,0
0,0,0,49,49,49,49,49,49,49,49,49,49,49,49,49,49,0,0,0
0,0,55,49,49,49,49,49,49,49,49,49,49,49,49,25,25,25,25,0
0,0,49,4,49,49,49,49,49,49,49,49,49,49,4,25,25,25,25,0
0,0,0,49,49,49,49,49,49,49,49,49,49,49,49,25,25,25,25,0
0,0,0,49,49,49,49,49,49,49,49,49,49,49,49,49,49,49,0,0
0,0,0,49,49,49,49,49,49,49,49,49,49,49,49,49,49,49,0,0
0,0,0,49,49,49,49,49,49,49,49,49,49,49,49,49,49,49,0,0
0,0,0,49,49,49,49,49,49,49,49,49,49,49,49,49,49,0,0,0
0,0,0,49,49,49,49,49,49,49,49,49,49,49,49,49,0,0,0,0
0,0,0,49,49,49,49,49,49,49,49,49,49,49,49,49,0,0,0,0
0,0,0,49,49,49,49,49,49,49,49,49,49,49,49,49,0,0,0,0
0,0,0,0,0,0,0,0,0,0,0,0,0,0,0,0,0,0,0,0
0,0,0,0,0,0,0,0,0,0,0,0,0,0,0,0,0,0,0,0
0,0,0,0,0,0,0,0,0,0,0,0,0,0,0,0,0,0,0,0
endlayer

layer
0,0,0,0,0,0,0,0,0,0,0,0,0,0,0,0,0,0,0,0
0,0,0,0,0,0,0,0,0,0,0,0,0,0,0,0,0,0,0,0
0,0,0,0,0,0,0,0,0,0,0,0,0,0,0,0,0,0,0,0
0,0,0,0,0,0,0,0,0,0,0,0,0,0,0,0,0,0,0,0
0,0,0,0,0,0,49,0,0,0,0,0,0,0,0,0,0,0,0,0
0,0,0,0,0,49,49,49,0,0,0,0,0,0,0,0,0,0,0,0
0,0,0,0,49,49,49,49,49,0,0,0,0,55,0,0,0,0,0,0
0,0,0,0,49,49,49,49,0,0,0,0,0,0,0,0,0,0,0,0
0,0,0,0,49,49,49,0,0,0,0,49,49,49,49,49,0,0,0,0
0,0,0,49,0,49,0,0,0,0,49,49,49,49,49,49,49,0,0,0
0,0,0,4,49,0,0,0,0,0,49,49,49,49,49,49,49,0,0,0
0,0,0,49,0,0,0,55,0,0,49,49,49,49,49,49,49,0,0,0
0,0,0,0,0,0,0,0,0,0,0,49,49,49,49,49,0,0,0,0
0,0,0,0,0,49,0,0,0,0,0,0,0,0,49,0,0,0,0,0
0,0,0,0,49,49,49,49,0,0,0,0,49,0,0,0,55,0,0,0
0,0,0,0,0,49,49,49,49,0,0,49,49,49,0,0,0,0,0,0
0,0,0,0,0,0,49,49,0,0,0,0,49,49,49,0,0,0,0,0
0,0,0,0,0,0,0,0,0,0,0,0,0,49,0,0,0,0,0,0
0,0,0,55,0,0,0,0,0,0,55,0,0,0,0,55,0,0,0,0
0,0,0,0,0,0,0,0,0,0,0,0,0,0,0,0,0,0,0,0
0,0,0,0,0,0,0,0,0,0,0,0,0,0,0,0,0,0,0,0
0,0,0,0,0,0,0,0,0,0,0,0,0,0,0,0,0,0,0,0
endlayer

layer
0,0,0,0,0,0,0,0,0,0,0,0,0,0,0,0,0,0,0,0
0,0,0,0,0,0,0,0,0,0,0,0,0,0,0,0,0,0,0,0
0,0,0,0,0,0,0,0,0,0,0,0,0,0,0,0,0,0,0,0
0,0,0,0,0,0,0,0,0,0,0,0,0,0,0,0,0,0,0,0
0,0,0,0,0,0,0,0,0,0,0,0,0,0,0,0,0,0,0,0
0,0,0,0,0,0,0,0,0,0,0,0,0,0,0,0,0,0,0,0
0,0,0,0,0,0,0,0,0,0,0,0,0,0,0,0,0,0,0,0
0,0,0,0,0,55,0,0,0,0,0,0,0,0,0,0,0,0,0,0
0,0,0,0,0,0,0,0,0,0,0,0,0,0,0,0,0,0,0,0
0,0,0,0,0,0,0,0,0,0,0,0,0,0,0,0,0,0,0,0
0,0,0,4,0,0,0,0,0,0,0,0,55,0,0,0,0,0,0,0
0,0,0,0,0,0,0,0,0,0,0,0,0,0,0,0,0,0,0,0
0,0,0,0,0,0,0,0,0,0,0,0,0,0,0,0,0,0,0,0
0,0,0,0,0,0,0,0,0,0,0,0,0,0,0,0,0,0,0,0
0,0,0,0,0,0,0,0,0,0,0,0,0,0,0,0,0,0,0,0
0,0,0,0,0,0,0,55,0,0,0,0,0,0,0,0,0,0,0,0
0,0,0,0,0,0,0,0,0,0,0,0,0,55,0,0,0,0,0,0
0,0,0,0,0,0,0,0,0,0,0,0,0,0,0,0,0,0,0,0
0,0,0,0,0,0,0,0,0,0,0,0,0,0,0,0,0,0,0,0
0,0,0,0,0,0,0,0,0,0,0,0,0,0,0,0,0,0,0,0
0,0,0,0,0,0,0,0,0,0,0,0,0,0,0,0,0,0,0,0
0,0,0,0,0,0,0,0,0,0,0,0,0,0,0,0,0,0,0,0
endlayer

