
# Created by Ruins mod version 15.3 Ingame Parser
# authoring Player: Mensrea

weight=5
embed_into_distance=7
acceptable_target_blocks=
unacceptable_target_blocks=flowing_water,water,flowing_lava,lava
dimensions=20,19,18
allowable_overhang=0
max_leveling=2
leveling_buffer=0
preserve_water=0
preserve_lava=0
preventRotation=1

rule1=0,100,PFAAGeologica:strongStone-7
rule2=0,100,minecraft:planks-0
rule3=0,100,minecraft:bed-9
rule4=0,100,ChestGenHook:mineshaftCorridor:5-2
rule5=0,100,minecraft:bed-1
rule6=0,100,IW:steelblock-0
rule7=0,100,IW:metalladder-5
rule8=0,100,ThermalExpansion:Workbench-1
rule9=0,100,minecraft:furnace-5
rule10=0,100,IW:metaldoor-0
rule11=0,100,IW:computer1-0
rule12=0,100,minecraft:bed-3
rule13=0,100,ChestGenHook:strongholdCorridor:5-2
rule14=0,100,minecraft:bed-11
rule15=0,100,ChestGenHook:strongholdCorridor:5-2
rule16=0,100,PFAAGeologica:mediumStone-3
rule17=0,100,IW:metaldoor-9
rule18=0,100,minecraft:stained_glass-15
rule19=0,100,IW:smalllightwhite-1
rule20=0,100,IW:smalllightwhite-4
rule21=0,100,IW:machinery1-0
rule22=0,100,IW:smalllightwhite-2
rule23=0,100,PFAAGeologica:weakStone-1
rule24=0,100,minecraft:sand-1
rule25=0,100,minecraft:stonebrick-0
rule26=0,100,ImmersiveEngineering:metalDecoration-0
rule27=0,100,IW:metaldoor-8
rule28=0,100,IW:steelsiding-0
rule29=0,100,AdvancedRepulsionSystems:DeFenceBW-0
rule30=2,100,minecraft:piston_head-12
rule31=0,100,IW:fiberboard-0
rule32=0,100,minecraft:sticky_piston-12
rule33=0,100,minecraft:lever-9
rule34=0,100,IW:metalhatch-2
rule35=0,100,minecraft:ladder-2
rule36=0,100,minecraft:ladder-4
rule37=0,100,minecraft:wool-0

layer
1,1,1,1,1,1,1,1,1,1,1,1,1,1,1,1,1,1
1,1,1,1,1,1,1,1,1,1,1,1,1,1,1,1,1,1
1,1,1,1,1,1,1,1,1,1,1,1,1,1,1,1,1,1
1,1,1,1,1,1,1,1,1,1,1,1,1,1,1,1,1,1
1,1,1,1,1,1,1,1,1,1,1,1,1,1,1,1,1,1
1,1,1,1,1,1,1,1,1,1,1,1,1,1,1,1,1,1
1,1,1,1,1,1,1,1,1,1,1,1,1,1,1,1,1,1
1,1,1,1,1,1,1,1,1,1,1,1,1,1,1,1,1,1
1,1,1,1,1,1,1,1,1,1,1,1,1,1,1,1,1,1
1,1,1,1,1,1,1,1,1,1,1,1,1,1,1,1,1,1
1,1,1,1,1,1,1,1,1,1,1,1,1,1,1,1,1,1
1,1,1,1,1,1,1,1,1,1,1,1,1,1,1,1,1,1
1,1,1,1,1,1,1,1,1,1,1,1,1,1,1,1,1,1
1,1,1,1,1,1,1,1,1,1,1,1,1,1,1,1,1,1
1,1,1,1,1,1,1,1,1,1,1,1,1,1,1,1,1,1
1,1,1,1,1,1,1,1,1,1,1,1,1,1,1,1,1,1
1,1,1,1,1,1,1,1,1,1,1,1,1,1,1,1,1,1
1,1,1,1,1,1,1,1,1,1,1,1,1,1,1,1,1,1
1,1,1,1,1,1,1,1,1,1,1,1,1,1,1,1,1,1
endlayer

layer
1,1,1,1,1,1,1,1,1,1,1,1,1,1,1,1,1,1
1,1,1,1,1,1,1,1,1,1,1,1,1,1,1,1,1,1
1,1,1,1,1,1,1,1,1,1,1,1,1,1,1,1,1,1
1,1,1,1,1,1,1,1,1,1,1,1,1,1,1,1,1,1
1,1,1,1,1,1,1,1,1,1,1,1,1,1,1,1,1,1
1,1,1,1,1,1,1,1,1,1,1,1,1,1,1,1,1,1
1,1,1,1,1,1,1,1,1,1,1,1,1,1,1,1,1,1
1,1,1,1,1,1,1,1,1,1,1,1,1,1,1,1,1,1
1,1,1,1,1,1,1,1,1,1,1,1,1,1,1,1,1,1
1,1,1,1,1,1,1,1,1,1,1,1,1,1,1,1,1,1
1,1,1,1,1,1,1,1,1,1,1,1,1,1,1,1,1,1
1,1,1,1,1,1,4,0,3,2,1,1,1,1,1,1,1,1
1,1,1,1,7,1,6,0,5,0,1,1,1,1,1,1,1,1
1,1,1,1,10,9,8,0,0,0,1,1,1,1,1,1,1,1
1,1,1,1,0,0,0,0,0,11,1,1,1,1,1,1,1,1
1,1,1,1,0,0,0,0,0,0,1,1,1,1,1,1,1,1
1,1,1,1,13,0,12,0,12,0,1,1,1,1,1,1,1,1
1,1,1,1,15,0,14,2,14,2,1,1,1,1,1,1,1,1
1,1,1,1,1,1,1,1,1,1,1,1,1,1,1,1,1,1
endlayer

layer
16,16,16,16,16,16,16,16,16,16,16,16,16,16,16,16,16,16
16,16,16,16,16,16,16,16,16,16,16,16,16,16,16,16,16,16
16,16,16,16,16,16,16,16,16,16,16,16,16,16,16,16,16,16
16,16,16,16,16,16,16,16,16,16,16,16,16,16,16,16,16,16
16,16,16,16,16,16,16,16,16,16,16,16,16,16,16,16,16,16
16,16,16,16,16,16,16,16,16,16,16,16,16,16,16,16,16,16
16,16,16,16,16,16,16,16,16,16,16,16,16,16,16,16,16,16
16,16,16,16,16,16,16,16,16,16,16,16,16,16,16,16,16,16
16,16,16,16,16,16,16,16,16,16,16,16,16,16,16,16,16,16
16,16,16,16,16,16,16,16,16,16,16,16,16,16,16,16,16,16
16,16,16,16,16,16,16,16,16,16,16,16,16,16,16,16,16,16
16,16,16,16,16,16,0,0,0,0,16,16,16,16,16,16,16,16
16,16,16,16,7,16,6,0,0,0,16,16,16,16,16,16,16,16
16,16,16,16,17,0,0,0,0,0,16,16,16,16,16,16,16,16
16,16,16,16,0,0,0,0,0,18,16,16,16,16,16,16,16,16
16,16,16,16,0,0,0,0,0,0,16,16,16,16,16,16,16,16
16,16,16,16,0,0,0,0,0,0,16,16,16,16,16,16,16,16
16,16,16,16,0,0,0,0,0,0,16,16,16,16,16,16,16,16
16,16,16,16,16,16,16,16,16,16,16,16,16,16,16,16,16,16
endlayer

layer
16,16,16,16,16,16,16,16,16,16,16,16,16,16,16,16,16,16
16,16,16,16,16,16,16,16,16,16,16,16,16,16,16,16,16,16
16,16,16,16,16,16,16,16,16,16,16,16,16,16,16,16,16,16
16,16,16,16,16,16,16,16,16,16,16,16,16,16,16,16,16,16
16,16,16,16,16,16,16,16,16,16,16,16,16,16,16,16,16,16
16,16,16,16,16,16,16,16,16,16,16,16,16,16,16,16,16,16
16,16,16,16,16,16,16,16,16,16,16,16,16,16,16,16,16,16
16,16,16,16,16,16,16,16,16,16,16,16,16,16,16,16,16,16
16,16,16,16,16,16,16,16,16,16,16,16,16,16,16,16,16,16
16,16,16,16,16,16,16,16,16,16,16,16,16,16,16,16,16,16
16,16,16,16,16,16,16,16,16,16,16,16,16,16,16,16,16,16
16,16,16,16,16,16,20,0,0,19,16,16,16,16,16,16,16,16
16,16,16,16,7,16,6,0,0,0,16,16,16,16,16,16,16,16
16,16,16,16,21,0,0,0,0,0,16,16,16,16,16,16,16,16
16,16,16,16,0,0,0,0,0,0,16,16,16,16,16,16,16,16
16,16,16,16,0,0,0,0,0,0,16,16,16,16,16,16,16,16
16,16,16,16,0,0,0,0,0,0,16,16,16,16,16,16,16,16
16,16,16,16,22,0,0,0,0,22,16,16,16,16,16,16,16,16
16,16,16,16,16,16,16,16,16,16,16,16,16,16,16,16,16,16
endlayer

layer
23,23,23,23,23,23,23,23,23,23,23,23,23,23,23,23,23,23
23,23,23,23,23,23,23,23,23,23,23,23,23,23,23,23,23,23
23,23,23,23,23,23,23,23,23,23,23,23,23,23,23,23,23,23
23,23,23,23,23,23,23,23,23,23,23,23,23,23,23,23,23,23
23,23,23,23,23,23,23,23,23,23,23,23,23,23,23,23,23,23
23,23,23,23,23,23,23,23,23,23,23,23,23,23,23,23,23,23
23,23,23,23,23,23,23,23,23,23,23,23,23,23,23,23,23,23
23,23,23,23,23,23,23,23,23,23,23,23,23,23,23,23,23,23
23,23,23,23,23,23,23,23,23,23,23,23,23,23,23,23,23,23
23,23,23,23,23,23,23,23,23,23,23,23,23,23,23,23,23,23
23,23,23,23,23,23,23,23,23,23,23,23,23,23,23,23,23,23
23,23,23,23,23,23,23,23,23,23,23,23,23,23,23,23,23,23
23,23,23,23,7,23,6,23,23,23,23,23,23,23,23,23,23,23
23,23,23,23,23,23,23,23,23,23,23,23,23,23,23,23,23,23
23,23,23,23,23,23,23,23,23,23,23,23,23,23,23,23,23,23
23,23,23,23,23,23,23,23,23,23,23,23,23,23,23,23,23,23
23,23,23,23,23,23,23,23,23,23,23,23,23,23,23,23,23,23
23,23,23,23,23,23,23,23,23,23,23,23,23,23,23,23,23,23
23,23,23,23,23,23,23,23,23,23,23,23,23,23,23,23,23,23
endlayer

layer
24,24,24,24,24,24,24,24,24,24,24,24,24,24,24,24,24,24
24,6,24,24,24,24,24,24,24,24,6,25,25,6,24,24,6,24
24,24,24,24,24,24,24,24,24,24,24,24,24,24,24,24,24,24
24,24,24,24,24,24,24,24,24,24,24,24,24,24,24,24,24,24
24,24,24,24,24,24,24,24,24,24,24,24,24,24,24,24,24,24
24,24,24,24,24,24,24,24,24,24,24,24,24,24,24,24,24,24
24,24,24,24,24,24,24,24,24,24,24,24,24,24,24,24,24,24
24,24,24,24,24,24,24,24,24,24,24,24,24,24,24,24,24,24
24,6,6,24,24,24,24,24,24,24,24,24,24,24,24,24,24,24
24,24,24,24,24,24,24,24,24,24,24,24,24,24,24,24,24,24
24,24,24,24,24,24,24,24,24,24,24,24,24,24,24,24,24,24
24,24,24,25,25,25,24,24,24,24,24,24,24,24,24,24,24,24
24,24,24,25,7,25,6,24,24,24,24,24,24,24,24,24,24,24
24,24,24,25,25,25,24,24,24,24,24,24,24,24,24,24,24,24
24,24,24,24,6,24,24,24,24,24,24,24,24,24,24,24,24,24
24,24,24,24,24,24,24,24,24,24,24,24,24,24,24,24,24,24
24,24,6,24,24,24,24,24,24,6,24,24,24,24,24,24,24,24
24,24,24,24,24,24,24,24,24,6,24,24,24,24,24,24,6,24
24,24,24,24,24,24,24,24,24,24,24,24,24,24,24,24,24,24
endlayer

layer
24,24,24,24,24,24,24,24,24,24,24,24,24,24,24,24,24,24
24,6,24,24,24,24,24,24,24,24,6,25,25,6,24,24,6,24
24,24,24,24,0,0,0,0,0,24,24,24,24,24,24,24,24,24
24,24,24,0,0,0,0,0,0,0,24,24,24,24,24,24,24,24
24,24,0,0,0,24,24,24,0,0,0,24,24,24,24,24,24,24
24,24,0,0,24,24,24,24,24,0,0,0,24,24,24,24,24,24
24,24,0,24,24,24,24,24,24,24,0,0,0,24,24,24,24,24
24,24,24,24,24,24,6,24,24,24,24,0,0,0,24,24,24,24
24,6,6,24,24,24,24,24,24,6,24,24,0,0,0,24,24,24
24,24,24,24,24,24,24,24,24,24,24,24,24,0,0,24,24,24
24,24,24,24,24,24,24,24,24,24,24,24,24,0,0,24,24,24
24,24,24,25,25,25,24,24,24,24,24,24,24,0,0,24,24,24
24,24,24,25,7,25,6,24,24,24,24,24,24,0,0,24,24,24
24,24,24,25,25,25,24,24,24,24,24,24,24,0,0,24,24,24
24,24,24,24,6,24,24,24,24,24,24,24,0,0,0,24,24,24
24,24,24,24,24,24,24,24,24,24,24,24,0,0,24,24,24,24
24,24,6,24,24,24,24,24,24,6,24,24,0,0,24,24,24,24
24,24,24,24,24,24,24,24,24,6,24,24,24,24,24,24,6,24
24,24,24,24,24,24,24,24,24,24,24,24,24,24,24,24,24,24
endlayer

layer
0,0,0,0,0,0,0,0,0,0,0,0,0,0,0,0,0,0
0,6,26,26,26,26,26,26,26,26,6,10,10,6,26,26,6,0
0,26,0,0,0,0,0,0,0,0,0,0,0,0,0,0,26,0
0,26,0,0,0,0,0,0,0,0,0,0,0,0,0,0,26,0
0,26,0,0,0,0,0,0,0,0,0,0,0,0,0,0,26,0
0,26,0,0,0,24,24,24,0,0,0,0,0,0,0,0,26,0
0,26,0,0,24,24,24,24,24,0,0,0,0,0,0,0,26,0
0,26,0,24,24,24,6,24,24,24,0,0,0,0,0,0,26,0
24,6,6,24,24,24,24,24,24,6,24,0,0,0,0,0,26,0
24,24,24,24,24,24,24,24,24,24,24,24,0,0,0,0,26,0
0,24,24,24,24,24,24,24,24,24,24,24,0,0,0,0,26,0
0,24,24,25,25,25,24,24,24,24,24,24,0,0,0,0,26,0
0,24,24,25,7,25,6,24,24,24,24,24,0,0,0,0,26,0
24,24,24,25,25,25,24,24,24,6,24,24,0,0,0,0,26,0
24,24,24,24,6,24,24,24,24,24,24,0,0,0,0,0,26,0
0,24,24,24,24,24,24,24,24,24,24,0,0,0,0,0,26,0
0,0,6,24,24,24,24,24,24,6,0,0,0,0,0,0,26,0
0,0,0,24,24,24,24,24,24,6,26,26,26,26,26,26,6,0
0,0,0,0,24,24,24,24,0,0,0,0,0,0,0,0,0,0
endlayer

layer
0,0,0,0,0,0,0,0,0,0,0,0,0,0,0,0,0,0
0,6,26,26,26,26,26,26,26,26,6,17,27,6,26,26,6,0
0,26,0,0,0,0,0,0,0,0,0,0,0,0,0,0,26,0
0,26,0,0,0,0,0,0,0,0,0,0,0,0,0,0,26,0
0,26,0,0,0,0,0,0,0,0,0,0,0,0,0,0,26,0
0,26,0,0,0,0,0,0,0,0,0,0,0,0,0,0,26,0
0,26,0,0,0,24,0,0,0,0,0,0,0,0,0,0,26,0
0,26,0,0,6,24,6,24,24,0,0,0,0,0,0,0,26,0
0,6,6,28,24,24,24,24,28,6,0,0,0,0,0,0,26,0
0,24,24,24,24,24,24,24,24,24,24,0,0,0,0,0,26,0
0,0,28,24,24,24,24,24,24,24,24,0,0,0,0,0,26,0
0,0,28,25,25,25,24,24,24,24,24,0,0,0,0,0,26,0
0,0,28,25,7,25,6,24,24,24,24,0,0,0,0,0,26,0
0,24,24,25,25,25,24,24,24,6,24,0,0,0,0,0,26,0
0,24,24,24,6,24,24,24,24,28,0,0,0,0,0,0,26,0
0,0,28,24,24,24,24,24,24,28,0,0,0,0,0,0,26,0
0,0,6,28,24,24,24,24,28,6,0,0,0,0,0,0,26,0
0,0,0,0,24,24,24,24,0,6,26,26,26,26,26,26,6,0
0,0,0,0,0,0,0,0,0,0,0,0,0,0,0,0,0,0
endlayer

layer
0,0,0,0,0,0,0,0,0,0,0,0,0,0,0,0,0,0
0,6,29,0,29,0,29,0,29,0,6,0,0,6,29,0,6,0
0,0,0,0,0,0,0,0,0,0,0,0,0,0,0,0,0,0
0,0,0,0,0,0,0,0,0,0,0,0,0,0,0,0,29,0
0,0,0,0,0,0,0,0,0,0,0,0,0,0,0,0,0,0
0,0,0,0,0,0,0,0,0,0,0,0,0,0,0,0,0,0
0,0,0,0,0,0,0,0,0,0,0,0,0,0,0,0,29,0
0,0,0,0,6,28,6,0,0,0,0,0,0,0,0,0,0,0
0,6,6,28,28,28,28,28,28,6,0,0,0,0,0,0,29,0
0,0,28,24,24,24,24,24,24,28,0,0,0,0,0,0,0,0
0,0,28,24,24,24,24,24,24,28,0,0,0,0,0,0,29,0
0,0,28,25,25,25,24,24,24,28,0,0,0,0,0,0,0,0
0,0,28,25,7,25,6,24,24,28,0,0,0,0,0,0,29,0
0,0,28,25,25,25,24,24,24,6,0,0,0,0,0,0,0,0
0,0,28,24,6,24,24,24,24,28,0,0,0,0,0,0,29,0
0,0,28,24,24,24,24,24,24,28,0,0,0,0,0,0,0,0
0,0,6,28,28,28,28,28,28,6,0,0,0,0,0,0,0,0
0,0,0,0,0,0,0,0,0,6,0,0,29,0,29,0,6,0
0,0,0,0,0,0,0,0,0,0,0,0,0,0,0,0,0,0
endlayer

layer
0,0,0,0,0,0,0,0,0,0,0,0,0,0,0,0,0,0
0,0,0,0,0,0,0,0,0,0,0,0,0,0,0,0,0,0
0,0,0,0,0,0,0,0,0,0,0,0,0,0,0,0,0,0
0,0,0,0,0,0,0,0,0,0,0,0,0,0,0,0,0,0
0,0,0,0,0,0,0,0,0,0,0,0,0,0,0,0,0,0
0,0,0,0,0,0,0,0,0,0,0,0,0,0,0,0,0,0
0,0,0,0,0,0,0,0,0,0,0,0,0,0,0,0,0,0
0,0,0,0,6,28,6,0,0,0,0,0,0,0,0,0,0,0
0,0,6,28,28,30,28,28,28,6,0,0,0,0,0,0,0,0
0,0,28,31,33,32,31,31,31,28,0,0,0,0,0,0,0,0
0,0,28,31,31,31,31,24,31,28,0,0,0,0,0,0,0,0
0,0,28,25,25,25,24,24,31,28,0,0,0,0,0,0,0,0
0,0,28,25,7,25,6,24,31,28,0,0,0,0,0,0,0,0
0,0,28,25,25,25,24,24,31,6,0,0,0,0,0,0,0,0
0,0,28,31,6,24,24,24,31,28,0,0,0,0,0,0,0,0
0,0,28,31,31,31,31,31,31,28,0,0,0,0,0,0,0,0
0,0,6,28,28,28,28,28,28,6,0,0,0,0,0,0,0,0
0,0,0,0,0,0,0,0,0,0,0,0,0,0,0,0,0,0
0,0,0,0,0,0,0,0,0,0,0,0,0,0,0,0,0,0
endlayer

layer
0,0,0,0,0,0,0,0,0,0,0,0,0,0,0,0,0,0
0,0,0,0,0,0,0,0,0,0,0,0,0,0,0,0,0,0
0,0,0,0,0,0,0,0,0,0,0,0,0,0,0,0,0,0
0,0,0,0,0,0,0,0,0,0,0,0,0,0,0,0,0,0
0,0,0,0,0,0,0,0,0,0,0,0,0,0,0,0,0,0
0,0,0,0,0,0,0,0,0,0,0,0,0,0,0,0,0,0
0,0,0,0,0,0,0,0,0,0,0,0,0,0,0,0,0,0
0,0,29,29,0,0,0,29,29,29,0,0,0,0,0,0,0,0
0,29,6,28,28,0,28,28,28,6,29,0,0,0,0,0,0,0
0,29,28,0,26,0,0,0,0,28,29,0,0,0,0,0,0,0
0,29,28,0,0,0,0,0,0,28,29,0,0,0,0,0,0,0
0,29,28,0,0,0,0,0,0,28,29,0,0,0,0,0,0,0
0,29,28,0,34,0,6,0,0,28,29,0,0,0,0,0,0,0
0,29,28,0,25,35,0,0,0,6,29,0,0,0,0,0,0,0
0,29,28,0,6,0,0,0,0,28,29,0,0,0,0,0,0,0
0,29,28,0,0,0,0,0,0,28,29,0,0,0,0,0,0,0
0,29,6,28,28,28,28,28,28,6,29,0,0,0,0,0,0,0
0,0,29,29,29,29,29,29,29,29,0,0,0,0,0,0,0,0
0,0,0,0,0,0,0,0,0,0,0,0,0,0,0,0,0,0
endlayer

layer
0,0,0,0,0,0,0,0,0,0,0,0,0,0,0,0,0,0
0,0,0,0,0,0,0,0,0,0,0,0,0,0,0,0,0,0
0,0,0,0,0,0,0,0,0,0,0,0,0,0,0,0,0,0
0,0,0,0,0,0,0,0,0,0,0,0,0,0,0,0,0,0
0,0,0,0,0,0,0,0,0,0,0,0,0,0,0,0,0,0
0,0,0,0,0,0,0,0,0,0,0,0,0,0,0,0,0,0
0,0,0,0,0,0,0,0,0,0,0,0,0,0,0,0,0,0
0,0,0,0,0,0,0,0,0,0,0,0,0,0,0,0,0,0
0,0,0,0,0,0,0,0,0,0,0,0,0,0,0,0,0,0
0,0,0,0,0,0,0,0,0,0,0,0,0,0,0,0,0,0
0,0,0,0,0,0,0,0,0,0,0,0,0,0,0,0,0,0
0,0,0,0,0,0,0,0,0,0,0,0,0,0,0,0,0,0
0,0,0,0,0,0,6,0,0,0,0,0,0,0,0,0,0,0
0,0,0,0,36,0,0,0,0,0,0,0,0,0,0,0,0,0
0,0,0,0,6,0,0,0,0,0,0,0,0,0,0,0,0,0
0,0,0,0,0,0,0,0,0,0,0,0,0,0,0,0,0,0
0,0,0,0,0,0,0,0,0,0,0,0,0,0,0,0,0,0
0,0,0,0,0,0,0,0,0,0,0,0,0,0,0,0,0,0
0,0,0,0,0,0,0,0,0,0,0,0,0,0,0,0,0,0
endlayer

layer
0,0,0,0,0,0,0,0,0,0,0,0,0,0,0,0,0,0
0,0,0,0,0,0,0,0,0,0,0,0,0,0,0,0,0,0
0,0,0,0,0,0,0,0,0,0,0,0,0,0,0,0,0,0
0,0,0,0,0,0,0,0,0,0,0,0,0,0,0,0,0,0
0,0,0,0,0,0,0,0,0,0,0,0,0,0,0,0,0,0
0,0,0,0,0,0,0,0,0,0,0,0,0,0,0,0,0,0
0,0,0,0,0,0,0,0,0,0,0,0,0,0,0,0,0,0
0,0,0,0,0,0,0,0,0,0,0,0,0,0,0,0,0,0
0,0,0,0,0,0,0,0,0,0,0,0,0,0,0,0,0,0
0,0,0,0,0,0,0,0,0,0,0,0,0,0,0,0,0,0
0,0,0,0,0,0,0,0,0,0,0,0,0,0,0,0,0,0
0,0,0,0,0,0,0,0,0,0,0,0,0,0,0,0,0,0
0,0,0,0,0,0,6,0,0,0,0,0,0,0,0,0,0,0
0,0,0,0,36,0,0,0,0,0,0,0,0,0,0,0,0,0
0,0,0,0,6,0,0,0,0,0,0,0,0,0,0,0,0,0
0,0,0,0,0,0,0,0,0,0,0,0,0,0,0,0,0,0
0,0,0,0,0,0,0,0,0,0,0,0,0,0,0,0,0,0
0,0,0,0,0,0,0,0,0,0,0,0,0,0,0,0,0,0
0,0,0,0,0,0,0,0,0,0,0,0,0,0,0,0,0,0
endlayer

layer
0,0,0,0,0,0,0,0,0,0,0,0,0,0,0,0,0,0
0,0,0,0,0,0,0,0,0,0,0,0,0,0,0,0,0,0
0,0,0,0,0,0,0,0,0,0,0,0,0,0,0,0,0,0
0,0,0,0,0,0,0,0,0,0,0,0,0,0,0,0,0,0
0,0,0,0,0,0,0,0,0,0,0,0,0,0,0,0,0,0
0,0,0,0,0,0,0,0,0,0,0,0,0,0,0,0,0,0
0,0,0,0,0,0,0,0,0,0,0,0,0,0,0,0,0,0
0,0,0,0,0,0,0,0,0,0,0,0,0,0,0,0,0,0
0,0,0,0,0,0,0,0,0,0,0,0,0,0,0,0,0,0
0,0,0,0,0,0,0,0,0,0,0,0,0,0,0,0,0,0
0,0,0,0,0,0,0,0,0,0,0,0,0,0,0,0,0,0
0,0,0,0,0,0,0,0,0,0,0,0,0,0,0,0,0,0
0,0,0,0,0,0,6,0,0,0,0,0,0,0,0,0,0,0
0,0,0,0,36,0,0,0,0,0,0,0,0,0,0,0,0,0
0,0,0,0,6,0,0,0,0,0,0,0,0,0,0,0,0,0
0,0,0,0,0,0,0,0,0,0,0,0,0,0,0,0,0,0
0,0,0,0,0,0,0,0,0,0,0,0,0,0,0,0,0,0
0,0,0,0,0,0,0,0,0,0,0,0,0,0,0,0,0,0
0,0,0,0,0,0,0,0,0,0,0,0,0,0,0,0,0,0
endlayer

layer
0,0,0,0,0,0,0,0,0,0,0,0,0,0,0,0,0,0
0,0,0,0,0,0,0,0,0,0,0,0,0,0,0,0,0,0
0,0,0,0,0,0,0,0,0,0,0,0,0,0,0,0,0,0
0,0,0,0,0,0,0,0,0,0,0,0,0,0,0,0,0,0
0,0,0,0,0,0,0,0,0,0,0,0,0,0,0,0,0,0
0,0,0,0,0,0,0,0,0,0,0,0,0,0,0,0,0,0
0,0,0,0,0,0,0,0,0,0,0,0,0,0,0,0,0,0
0,0,0,0,0,0,0,0,0,0,0,0,0,0,0,0,0,0
0,0,0,0,0,0,0,0,0,0,0,0,0,0,0,0,0,0
0,0,0,0,0,0,0,0,0,0,0,0,0,0,0,0,0,0
0,0,0,0,0,0,0,0,0,0,0,0,0,0,0,0,0,0
0,0,0,0,0,0,0,0,0,0,0,0,0,0,0,0,0,0
0,0,0,0,0,0,6,0,0,0,0,0,0,0,0,0,0,0
0,0,0,0,36,0,0,0,0,0,0,0,0,0,0,0,0,0
0,0,0,0,6,0,0,0,0,0,0,0,0,0,0,0,0,0
0,0,0,0,0,0,0,0,0,0,0,0,0,0,0,0,0,0
0,0,0,0,0,0,0,0,0,0,0,0,0,0,0,0,0,0
0,0,0,0,0,0,0,0,0,0,0,0,0,0,0,0,0,0
0,0,0,0,0,0,0,0,0,0,0,0,0,0,0,0,0,0
endlayer

layer
0,0,0,0,0,0,0,0,0,0,0,0,0,0,0,0,0,0
0,0,0,0,0,0,0,0,0,0,0,0,0,0,0,0,0,0
0,0,0,0,0,0,0,0,0,0,0,0,0,0,0,0,0,0
0,0,0,0,0,0,0,0,0,0,0,0,0,0,0,0,0,0
0,0,0,0,0,0,0,0,0,0,0,0,0,0,0,0,0,0
0,0,0,0,0,0,0,0,0,0,0,0,0,0,0,0,0,0
0,0,0,0,0,0,0,0,0,0,0,0,0,0,0,0,0,0
0,0,0,0,0,0,0,0,0,0,0,0,0,0,0,0,0,0
0,0,0,0,0,0,0,0,0,0,0,0,0,0,0,0,0,0
0,0,0,0,0,0,0,0,0,0,0,0,0,0,0,0,0,0
0,0,0,0,0,0,0,0,0,0,0,0,0,0,0,0,0,0
0,0,0,0,0,0,0,0,0,0,0,0,0,0,0,0,0,0
0,0,6,28,28,6,6,0,0,0,0,0,0,0,0,0,0,0
0,0,28,6,36,6,6,0,0,0,0,0,0,0,0,0,0,0
0,0,28,6,6,6,28,0,0,0,0,0,0,0,0,0,0,0
0,0,28,6,6,6,28,0,0,0,0,0,0,0,0,0,0,0
0,0,6,28,28,28,6,0,0,0,0,0,0,0,0,0,0,0
0,0,0,0,0,0,0,0,0,0,0,0,0,0,0,0,0,0
0,0,0,0,0,0,0,0,0,0,0,0,0,0,0,0,0,0
endlayer

layer
0,0,0,0,0,0,0,0,0,0,0,0,0,0,0,0,0,0
0,0,0,0,0,0,0,0,0,0,0,0,0,0,0,0,0,0
0,0,0,0,0,0,0,0,0,0,0,0,0,0,0,0,0,0
0,0,0,0,0,0,0,0,0,0,0,0,0,0,0,0,0,0
0,0,0,0,0,0,0,0,0,0,0,0,0,0,0,0,0,0
0,0,0,0,0,0,0,0,0,0,0,0,0,0,0,0,0,0
0,0,0,0,0,0,0,0,0,0,0,0,0,0,0,0,0,0
0,0,0,0,0,0,0,0,0,0,0,0,0,0,0,0,0,0
0,0,0,0,0,0,0,0,0,0,0,0,0,0,0,0,0,0
0,0,0,0,0,0,0,0,0,0,0,0,0,0,0,0,0,0
0,0,0,0,0,0,0,0,0,0,0,0,0,0,0,0,0,0
0,0,0,0,0,0,0,0,0,0,0,0,0,0,0,0,0,0
0,0,6,28,28,28,6,0,0,0,0,0,0,0,0,0,0,0
0,0,28,0,0,0,28,0,0,0,0,0,0,0,0,0,0,0
0,0,28,0,0,0,28,0,0,0,0,0,0,0,0,0,0,0
0,0,28,0,0,0,28,0,0,0,0,0,0,0,0,0,0,0
0,0,6,28,28,28,6,0,0,0,0,0,0,0,0,0,0,0
0,0,0,0,0,0,0,0,0,0,0,0,0,0,0,0,0,0
0,0,0,0,0,0,0,0,0,0,0,0,0,0,0,0,0,0
endlayer

layer
0,0,0,0,0,0,0,0,0,0,0,0,0,0,0,0,0,0
0,0,0,0,0,0,0,0,0,0,0,0,0,0,0,0,0,0
0,0,0,0,0,0,0,0,0,0,0,0,0,0,0,0,0,0
0,0,0,0,0,0,0,0,0,0,0,0,0,0,0,0,0,0
0,0,0,0,0,0,0,0,0,0,0,0,0,0,0,0,0,0
0,0,0,0,0,0,0,0,0,0,0,0,0,0,0,0,0,0
0,0,0,0,0,0,0,0,0,0,0,0,0,0,0,0,0,0
0,0,0,0,0,0,0,0,0,0,0,0,0,0,0,0,0,0
0,0,0,0,0,0,0,0,0,0,0,0,0,0,0,0,0,0
0,0,0,0,0,0,0,0,0,0,0,0,0,0,0,0,0,0
0,0,0,0,0,0,0,0,0,0,0,0,0,0,0,0,0,0
0,0,0,0,0,0,0,0,0,0,0,0,0,0,0,0,0,0
0,0,0,0,0,0,6,0,0,0,0,0,0,0,0,0,0,0
0,0,0,0,0,0,0,0,0,0,0,0,0,0,0,0,0,0
0,0,0,0,0,0,0,0,0,0,0,0,0,0,0,0,0,0
0,0,0,0,0,0,0,0,0,0,0,0,0,0,0,0,0,0
0,0,0,0,0,0,0,0,0,0,0,0,0,0,0,0,0,0
0,0,0,0,0,0,0,0,0,0,0,0,0,0,0,0,0,0
0,0,0,0,0,0,0,0,0,0,0,0,0,0,0,0,0,0
endlayer

layer
0,0,0,0,0,0,0,0,0,0,0,0,0,0,0,0,0,0
0,0,0,0,0,0,0,0,0,0,0,0,0,0,0,0,0,0
0,0,0,0,0,0,0,0,0,0,0,0,0,0,0,0,0,0
0,0,0,0,0,0,0,0,0,0,0,0,0,0,0,0,0,0
0,0,0,0,0,0,0,0,0,0,0,0,0,0,0,0,0,0
0,0,0,0,0,0,0,0,0,0,0,0,0,0,0,0,0,0
0,0,0,0,0,0,0,0,0,0,0,0,0,0,0,0,0,0
0,0,0,0,0,0,0,0,0,0,0,0,0,0,0,0,0,0
0,0,0,0,0,0,0,0,0,0,0,0,0,0,0,0,0,0
0,0,0,0,0,0,0,0,0,0,0,0,0,0,0,0,0,0
0,0,0,0,0,0,0,0,0,0,0,0,0,0,0,0,0,0
0,0,0,0,0,0,0,0,0,0,0,0,0,0,0,0,0,0
0,0,31,31,31,31,6,0,0,0,0,0,0,0,0,0,0,0
0,0,37,37,37,37,31,0,0,0,0,0,0,0,0,0,0,0
0,0,37,37,37,37,31,0,0,0,0,0,0,0,0,0,0,0
0,0,37,37,37,37,31,0,0,0,0,0,0,0,0,0,0,0
0,0,37,37,37,37,31,0,0,0,0,0,0,0,0,0,0,0
0,0,0,0,0,0,0,0,0,0,0,0,0,0,0,0,0,0
0,0,0,0,0,0,0,0,0,0,0,0,0,0,0,0,0,0
endlayer

