
# Created by Ruins mod version 15.3 Ingame Parser
# authoring Player: Mensrea

weight=4
embed_into_distance=12
acceptable_target_blocks=
unacceptable_target_blocks=flowing_water,water,flowing_lava,lava
dimensions=16,19,19
allowable_overhang=0
max_leveling=2
leveling_buffer=0
preserve_water=0
preserve_lava=0
preventRotation=1

rule1=0,100,PFAAGeologica:strongStone-3
rule2=0,100,minecraft:obsidian-0
rule3=0,100,PFAAGeologica:strongStone-7
rule4=0,100,minecraft:gold_block-0
rule5=0,100,minecraft:nether_brick-0
rule6=0,100,ChestGenHook:pyramidDesertyChest:5-2
rule7=0,100,ChestGenHook:pyramidDesertyChest:5-2
rule8=0,100,MobSpawner:demonmobs.trite
rule9=0,100,ChestGenHook:dungeonChest:5-2
rule10=0,100,ChestGenHook:dungeonChest:5-2
rule11=0,100,minecraft:nether_brick_stairs-0
rule12=0,100,minecraft:nether_brick_stairs-2
rule13=0,100,minecraft:nether_brick_stairs-3
rule14=0,100,minecraft:dirt-0
rule15=0,100,ChestGenHook:pyramidJungleChest:5-2
rule16=0,100,minecraft:cauldron-0
rule17=0,100,minecraft:nether_brick_stairs-1
rule18=0,100,ChestGenHook:dungeonChest:5-2
rule19=0,100,ChestGenHook:dungeonChest:5-2
rule20=0,100,ChestGenHook:pyramidDesertyChest:5-2
rule21=0,100,ChestGenHook:pyramidDesertyChest:5-2
rule22=0,100,ImmersiveEngineering:storageSlab-7
rule23=0,100,Skull:0:5-1
rule24=0,100,Skull:0:3-1
rule25=0,100,Skull:0:11-1
rule26=0,100,Skull:0:12-1
rule27=0,100,Skull:0:13-1
rule28=0,100,PFAAGeologica:mediumStone-3
rule29=0,100,PFAAGeologica:weakStone-1
rule30=0,100,minecraft:sand-1
rule31=0,100,IW:bush-0

layer
1,1,1,1,1,1,1,1,1,1,1,1,1,1,1,1,1,1,1
1,1,1,1,1,1,1,1,1,1,1,1,1,1,1,1,1,1,1
1,1,1,1,1,1,1,1,1,1,1,1,1,1,1,1,1,1,1
1,1,1,1,1,1,1,1,1,1,1,1,1,1,1,1,1,1,1
1,1,1,1,1,1,1,1,1,1,1,1,1,1,1,1,1,1,1
1,1,1,1,1,1,1,1,1,1,1,1,1,1,1,1,1,1,1
1,1,1,1,1,1,1,1,1,1,1,1,1,1,1,1,1,1,1
1,1,1,1,1,1,1,1,1,1,1,1,1,1,1,1,1,1,1
1,1,1,1,1,1,1,1,1,1,1,1,1,1,1,1,1,1,1
1,1,1,1,1,1,1,1,1,1,1,1,1,1,1,1,1,1,1
1,1,1,1,1,1,1,1,1,1,1,1,1,1,1,1,1,1,1
1,1,1,1,1,1,1,1,1,1,1,1,1,1,1,1,1,1,1
1,1,1,1,1,1,1,1,1,1,1,1,1,1,1,1,1,1,1
1,1,1,1,1,1,1,1,1,1,1,1,1,1,1,1,1,1,1
1,1,1,1,1,1,1,1,1,1,1,1,1,1,1,1,1,1,1
1,1,1,1,1,1,1,1,1,1,1,1,1,1,1,1,1,1,1
1,1,1,1,1,1,1,1,1,1,1,1,1,1,1,1,1,1,1
1,1,1,1,1,1,1,1,1,1,1,1,1,1,1,1,1,1,1
1,1,1,1,1,1,1,1,1,1,1,1,1,1,1,1,1,1,1
endlayer

layer
1,1,1,1,1,1,1,1,1,1,1,1,1,1,1,1,1,1,1
1,1,1,1,1,1,1,1,1,1,1,1,1,1,1,1,1,1,1
1,1,1,1,1,1,1,1,1,1,1,1,1,1,1,1,1,1,1
1,1,1,1,1,1,1,1,1,1,1,1,1,1,1,1,1,1,1
1,1,1,1,1,1,1,1,1,1,1,1,1,1,1,1,1,1,1
1,1,1,1,1,1,1,1,1,1,1,1,1,1,1,1,1,1,1
1,1,1,1,1,1,1,1,1,1,1,1,1,1,1,1,1,1,1
1,1,1,1,1,1,1,1,1,1,1,1,1,1,1,1,1,1,1
1,1,1,1,1,1,1,1,1,1,1,1,1,1,1,1,1,1,1
1,1,1,1,1,1,1,1,1,1,1,1,1,1,1,1,1,1,1
1,1,1,1,1,1,1,1,1,1,1,1,1,1,1,1,1,1,1
1,1,1,1,1,1,1,1,1,1,1,1,1,1,1,1,1,1,1
1,1,1,1,1,1,1,1,1,1,1,1,1,1,1,1,1,1,1
1,1,1,1,1,1,1,1,1,1,1,1,1,1,1,1,1,1,1
1,1,1,1,1,1,1,1,1,1,1,1,1,1,1,1,1,1,1
1,1,1,1,1,1,1,1,1,1,1,1,1,1,1,1,1,1,1
1,1,1,1,1,1,1,1,1,1,1,1,1,1,1,1,1,1,1
1,1,1,1,1,1,1,1,1,1,1,1,1,1,1,1,1,1,1
1,1,1,1,1,1,1,1,1,1,1,1,1,1,1,1,1,1,1
endlayer

layer
1,1,1,1,1,1,1,1,1,1,1,1,1,1,1,1,1,1,1
1,2,2,2,2,2,2,2,2,2,2,2,2,2,2,2,2,2,1
1,2,2,2,2,2,2,2,2,2,2,2,2,2,2,2,2,2,1
1,2,2,2,2,2,2,2,2,2,2,2,2,2,2,2,2,2,1
1,2,2,2,2,2,2,2,2,2,2,2,2,2,2,2,2,2,1
1,2,2,2,2,2,2,2,2,2,2,2,2,2,2,2,2,2,1
1,2,2,2,2,2,2,2,2,2,2,2,2,2,2,2,2,2,1
1,2,2,2,2,2,2,2,2,2,2,2,2,2,2,2,2,2,1
1,2,2,2,2,2,2,2,2,2,2,2,2,2,2,2,2,2,1
1,2,2,2,2,2,2,2,2,2,2,2,2,2,2,2,2,2,1
1,2,2,2,2,2,2,2,2,2,2,2,2,2,2,2,2,2,1
1,2,2,2,2,2,2,2,2,2,2,2,2,2,2,2,2,2,1
1,2,2,2,2,2,2,2,2,2,2,2,2,2,2,2,2,2,1
1,2,2,2,2,2,2,2,2,2,2,2,2,2,2,2,2,2,1
1,2,2,2,2,2,2,2,2,2,2,2,2,2,2,2,2,2,1
1,2,2,2,2,2,2,2,2,2,2,2,2,2,2,2,2,2,1
1,2,2,2,2,2,2,2,2,2,2,2,2,2,2,2,2,2,1
1,2,2,2,2,2,2,2,2,2,2,2,2,2,2,2,2,2,1
1,1,1,1,1,1,1,1,1,1,1,1,1,1,1,1,1,1,1
endlayer

layer
3,3,3,3,3,3,3,3,3,3,3,3,3,3,3,3,3,3,3
3,2,2,2,2,2,2,2,2,2,2,2,2,2,2,2,2,2,3
3,2,4,0,0,0,0,0,0,0,0,0,0,0,0,0,4,2,3
3,2,0,0,5,5,0,5,5,5,5,0,0,5,5,0,0,2,3
3,2,0,0,10,9,0,5,8,8,5,0,0,7,6,0,0,2,3
3,2,0,0,0,0,0,5,5,5,5,0,0,0,0,0,0,2,3
3,2,0,0,0,0,0,0,0,0,0,0,0,0,0,0,0,2,3
3,2,0,0,0,0,0,0,11,11,11,11,11,11,11,0,0,2,3
3,2,3,0,0,0,0,0,13,5,5,5,5,5,12,0,0,2,3
3,3,3,3,0,16,0,0,13,5,15,14,14,5,12,0,0,2,3
3,2,3,0,0,0,0,0,13,5,5,5,5,5,12,0,0,2,3
3,2,0,0,0,0,0,0,17,17,17,17,17,17,12,0,0,2,3
3,2,0,0,0,0,0,0,0,0,0,0,0,0,0,0,0,2,3
3,2,0,0,0,0,0,5,5,5,5,0,0,0,0,0,0,2,3
3,2,0,0,21,20,0,5,8,8,5,0,19,18,0,0,0,2,3
3,2,0,0,5,5,0,5,5,5,5,0,5,5,0,0,0,2,3
3,2,4,0,0,0,0,0,0,0,0,0,0,0,0,0,4,2,3
3,2,2,2,2,2,2,2,2,2,2,2,2,2,2,2,2,2,3
3,3,3,3,3,3,3,3,3,3,3,3,3,3,3,3,3,3,3
endlayer

layer
3,3,3,3,3,3,3,3,3,3,3,3,3,3,3,3,3,3,3
3,2,2,2,2,2,2,2,2,2,2,2,2,2,2,2,2,2,3
3,2,4,0,0,0,0,0,0,0,0,0,0,0,0,0,4,2,3
3,2,0,0,5,5,0,0,0,0,0,0,0,5,5,0,0,2,3
3,2,0,0,0,0,0,0,22,22,0,0,0,0,0,0,0,2,3
3,2,0,0,0,0,0,0,0,0,0,0,0,0,0,0,0,2,3
3,2,0,0,0,0,0,0,0,0,0,0,0,0,0,0,0,2,3
3,2,0,0,0,0,0,0,0,0,0,0,0,0,0,0,0,2,3
3,2,0,0,0,0,0,0,0,5,0,0,0,5,0,0,0,2,3
3,3,3,0,0,0,0,0,0,0,22,22,22,0,0,0,0,2,3
3,2,0,0,0,0,0,0,0,5,0,0,0,5,0,0,0,2,3
3,2,0,0,0,0,0,0,0,0,0,0,0,0,0,0,0,2,3
3,2,0,0,0,0,0,0,0,0,0,0,0,0,0,0,0,2,3
3,2,0,0,0,0,0,0,0,0,0,0,0,0,0,0,0,2,3
3,2,0,0,0,0,0,0,22,22,0,0,0,0,0,0,0,2,3
3,2,0,0,5,5,0,0,0,0,0,0,5,5,0,0,0,2,3
3,2,4,0,0,0,0,0,0,0,0,0,0,0,0,0,4,2,3
3,2,2,2,2,2,2,2,2,2,2,2,2,2,2,2,2,2,3
3,3,3,3,3,3,3,3,3,3,3,3,3,3,3,3,3,3,3
endlayer

layer
3,3,3,3,3,3,3,3,3,3,3,3,3,3,3,3,3,3,3
3,2,3,3,3,3,3,3,3,3,3,3,3,3,3,3,3,2,3
3,3,2,2,2,2,2,2,2,2,2,2,2,2,2,2,2,3,3
3,3,2,4,24,24,0,0,0,0,0,0,0,23,23,4,2,3,3
3,3,2,0,0,0,0,0,0,0,0,0,0,0,0,0,2,3,3
3,3,2,0,0,0,0,0,0,0,0,0,0,0,0,0,2,3,3
3,3,2,0,0,0,0,0,0,0,0,0,0,0,0,0,2,3,3
3,3,2,0,0,0,0,0,0,0,0,0,0,0,0,0,2,3,3
3,2,2,0,0,0,0,0,0,0,0,0,0,0,0,0,2,3,3
3,2,0,0,0,0,0,0,0,0,0,0,0,0,0,0,2,3,3
3,2,2,0,0,0,0,0,0,0,0,0,0,0,0,0,2,3,3
3,3,2,0,0,0,0,0,0,0,0,0,0,0,0,0,2,3,3
3,3,2,0,0,0,0,0,0,0,0,0,0,0,0,0,2,3,3
3,3,2,0,0,0,0,0,0,0,0,0,0,0,0,0,2,3,3
3,3,2,0,0,0,0,0,0,0,0,0,0,0,0,0,2,3,3
3,3,2,4,26,27,0,0,0,0,0,0,26,25,0,4,2,3,3
3,3,2,2,2,2,2,2,2,2,2,2,2,2,2,2,2,3,3
3,2,3,3,3,3,3,3,3,3,3,3,3,3,3,3,3,2,3
3,3,3,3,3,3,3,3,3,3,3,3,3,3,3,3,3,3,3
endlayer

layer
3,3,3,3,3,3,3,3,3,3,3,3,3,3,3,3,3,3,3
3,2,3,3,3,3,3,3,3,3,3,3,3,3,3,3,3,2,3
3,3,2,3,3,3,3,3,3,3,3,3,3,3,3,3,2,3,3
3,3,3,2,2,2,2,2,2,2,2,2,2,2,2,2,3,3,3
3,3,3,2,4,0,0,0,0,0,0,0,0,0,4,2,3,3,3
3,3,3,2,0,0,0,0,0,0,0,0,0,0,0,2,3,3,3
3,3,3,2,0,0,0,0,0,0,0,0,0,0,0,2,3,3,3
3,3,3,2,0,0,0,0,0,0,0,0,0,0,0,2,3,3,3
3,3,2,2,0,0,0,0,0,0,0,0,0,0,0,2,3,3,3
3,2,2,2,0,0,0,0,0,0,0,0,0,0,0,2,3,3,3
3,3,2,2,0,0,0,0,0,0,0,0,0,0,0,2,3,3,3
3,3,3,2,0,0,0,0,0,0,0,0,0,0,0,2,3,3,3
3,3,3,2,0,0,0,0,0,0,0,0,0,0,0,2,3,3,3
3,3,3,2,0,0,0,0,0,0,0,0,0,0,0,2,3,3,3
3,3,3,2,4,0,0,0,0,0,0,0,0,0,4,2,3,3,3
3,3,3,2,2,2,2,2,2,2,2,2,2,2,2,2,3,3,3
3,3,2,3,3,3,3,3,3,3,3,3,3,3,3,3,2,3,3
3,2,3,3,3,3,3,3,3,3,3,3,3,3,3,3,3,2,3
3,3,3,3,3,3,3,3,3,3,3,3,3,3,3,3,3,3,3
endlayer

layer
28,28,28,28,28,28,28,28,28,28,28,28,28,28,28,28,28,28,28
28,2,28,28,28,28,28,28,28,28,28,28,28,28,28,28,28,2,28
28,28,2,28,28,28,28,28,28,28,28,28,28,28,28,28,2,28,28
28,28,28,28,28,28,28,28,28,28,28,28,28,28,28,28,28,28,28
28,28,28,28,2,2,2,2,2,2,2,2,2,2,2,28,28,28,28
28,28,28,28,2,4,0,0,0,0,0,0,0,4,2,28,28,28,28
28,28,28,28,2,0,0,0,0,0,0,0,0,0,2,28,28,28,28
28,28,28,28,2,0,0,0,0,0,0,0,0,0,2,28,28,28,28
28,28,28,28,2,0,0,0,0,0,0,0,0,0,2,28,28,28,28
28,28,28,28,2,0,0,0,0,0,0,0,0,0,2,28,28,28,28
28,28,28,28,2,0,0,0,0,0,0,0,0,0,2,28,28,28,28
28,28,28,28,2,0,0,0,0,0,0,0,0,0,2,28,28,28,28
28,28,28,28,2,0,0,0,0,0,0,0,0,0,2,28,28,28,28
28,28,28,28,2,4,0,0,0,0,0,0,0,4,2,28,28,28,28
28,28,28,28,2,2,2,2,2,2,2,2,2,2,2,28,28,28,28
28,28,28,28,28,28,28,28,28,28,28,28,28,28,28,28,28,28,28
28,28,2,28,28,28,28,28,28,28,28,28,28,28,28,28,2,28,28
28,2,28,28,28,28,28,28,28,28,28,28,28,28,28,28,28,2,28
28,28,28,28,28,28,28,28,28,28,28,28,28,28,28,28,28,28,28
endlayer

layer
28,28,28,28,28,28,28,28,28,28,28,28,28,28,28,28,28,28,28
28,2,28,28,28,28,28,28,28,28,28,28,28,28,28,28,28,2,28
28,28,2,28,28,28,28,28,28,28,28,28,28,28,28,28,2,28,28
28,28,28,28,28,28,28,28,28,28,28,28,28,28,28,28,28,28,28
28,28,28,28,28,28,28,28,28,28,28,28,28,28,28,28,28,28,28
28,28,28,28,28,2,2,2,2,2,2,2,2,2,28,28,28,28,28
28,28,28,28,28,2,4,0,0,0,0,0,4,2,28,28,28,28,28
28,28,28,28,28,2,0,0,0,0,0,0,0,2,28,28,28,28,28
28,28,28,28,28,2,0,0,0,0,0,0,0,2,28,28,28,28,28
28,28,28,28,28,2,0,0,0,0,0,0,0,2,28,28,28,28,28
28,28,28,28,28,2,0,0,0,0,0,0,0,2,28,28,28,28,28
28,28,28,28,28,2,0,0,0,0,0,0,0,2,28,28,28,28,28
28,28,28,28,28,2,4,0,0,0,0,0,4,2,28,28,28,28,28
28,28,28,28,28,2,2,2,2,2,2,2,2,2,28,28,28,28,28
28,28,28,28,28,28,28,28,28,28,28,28,28,28,28,28,28,28,28
28,28,28,28,28,28,28,28,28,28,28,28,28,28,28,28,28,28,28
28,28,2,28,28,28,28,28,28,28,28,28,28,28,28,28,2,28,28
28,2,28,28,28,28,28,28,28,28,28,28,28,28,28,28,28,2,28
28,28,28,28,28,28,28,28,28,28,28,28,28,28,28,28,28,28,28
endlayer

layer
29,29,29,29,29,29,29,29,29,29,29,29,29,29,29,29,29,29,29
29,2,28,28,28,28,28,28,28,28,28,28,28,28,28,28,28,2,29
29,28,2,28,28,28,28,28,28,28,28,28,28,28,28,28,2,28,29
29,28,28,28,28,28,28,28,28,28,28,28,28,28,28,28,28,28,29
29,28,28,28,28,28,28,28,28,28,28,28,28,28,28,28,28,28,29
29,28,28,28,28,28,28,28,28,28,28,28,28,28,28,28,28,28,29
29,28,28,28,28,28,2,2,2,2,2,2,2,28,28,28,28,28,29
29,28,28,28,28,28,2,4,0,0,0,4,2,28,28,28,28,28,29
29,28,28,28,28,28,2,0,0,0,0,0,2,28,28,28,28,28,29
29,28,28,28,28,28,2,0,0,0,0,0,2,28,28,28,28,28,29
29,28,28,28,28,28,2,0,0,0,0,0,2,28,28,28,28,28,29
29,28,28,28,28,28,2,4,0,0,0,4,2,28,28,28,28,28,29
29,28,28,28,28,28,2,2,2,2,2,2,2,28,28,28,28,28,29
29,28,28,28,28,28,28,28,28,28,28,28,28,28,28,28,28,28,29
29,28,28,28,28,28,28,28,28,28,28,28,28,28,28,28,28,28,29
29,28,28,28,28,28,28,28,28,28,28,28,28,28,28,28,28,28,29
29,28,2,28,28,28,28,28,28,28,28,28,28,28,28,28,2,28,29
29,2,28,28,28,28,28,28,28,28,28,28,28,28,28,28,28,2,29
29,29,29,29,29,29,29,29,29,29,29,29,29,29,29,29,29,29,29
endlayer

layer
30,30,30,30,30,30,30,30,30,30,30,30,30,30,30,30,30,30,30
30,2,30,30,30,30,30,30,30,30,30,30,30,30,30,30,30,2,30
30,30,2,30,30,30,30,30,30,30,30,30,30,30,30,30,2,30,30
30,30,30,30,30,30,30,30,30,30,30,30,30,30,30,30,30,30,30
30,30,30,30,30,30,30,30,30,30,30,30,30,30,30,30,30,30,30
30,30,30,30,30,30,30,30,30,30,30,30,30,30,30,30,30,30,30
30,30,30,30,30,30,30,30,30,30,30,30,30,30,30,30,30,30,30
30,30,30,30,30,30,30,2,2,2,2,2,30,30,30,30,30,30,30
30,30,30,30,30,30,30,2,4,0,4,2,30,30,30,30,30,30,30
30,30,30,30,30,30,30,2,0,0,0,2,30,30,30,30,30,30,30
30,30,30,30,30,30,30,2,4,0,4,2,30,30,30,30,30,30,30
30,30,30,30,30,30,30,2,2,2,2,2,30,30,30,30,30,30,30
30,30,30,30,30,30,30,30,30,30,30,30,30,30,30,30,30,30,30
30,30,30,30,30,30,30,30,30,30,30,30,30,30,30,30,30,30,30
30,30,30,30,30,30,30,30,30,30,30,30,30,30,30,30,30,30,30
30,30,30,30,30,30,30,30,30,30,30,30,30,30,30,30,30,30,30
30,30,2,30,30,30,30,30,30,30,30,30,30,30,30,30,2,30,30
30,2,30,30,30,30,30,30,30,30,30,30,30,30,30,30,30,2,30
30,30,30,30,30,30,30,30,30,30,30,30,30,30,30,30,30,30,30
endlayer

layer
0,30,30,30,30,30,30,30,0,0,0,30,30,30,30,30,30,30,30
30,2,30,30,30,30,30,30,30,0,0,0,30,30,30,30,30,2,30
30,30,2,30,30,30,30,30,30,0,0,0,0,30,30,30,2,30,30
30,30,30,30,30,30,30,30,30,0,0,0,0,30,30,30,30,30,30
30,30,30,30,30,30,30,30,30,30,0,0,0,30,30,30,30,30,30
0,30,30,30,30,30,30,30,30,30,0,0,0,0,30,30,30,30,30
0,0,30,30,30,30,30,30,30,30,30,0,31,0,30,30,30,30,30
0,0,30,30,30,30,30,30,30,30,30,30,0,0,30,30,30,30,30
30,0,30,30,30,30,30,30,2,2,2,30,30,30,30,30,30,30,30
30,30,30,30,30,30,30,30,2,4,2,30,30,30,30,30,30,30,0
30,30,30,30,30,30,30,30,2,2,2,30,30,30,30,30,30,0,0
0,30,30,30,30,30,30,30,30,30,30,30,30,30,30,30,30,30,0
0,30,30,30,30,30,30,30,30,30,30,30,30,30,30,30,30,30,30
30,30,30,30,30,30,30,30,30,30,30,30,30,30,30,30,30,30,30
30,30,30,30,30,30,30,30,30,30,30,30,30,30,30,30,30,30,30
30,30,30,30,30,30,30,30,30,30,30,30,30,30,30,30,30,30,30
30,30,2,30,30,30,30,30,30,30,30,30,30,30,30,30,2,30,30
30,2,30,30,30,30,30,30,30,30,30,30,30,30,30,30,30,2,30
0,30,30,30,30,30,30,0,0,0,30,30,30,30,30,30,30,30,30
endlayer

layer
0,30,0,0,0,0,0,0,0,0,0,0,0,0,0,0,30,30,0
30,2,30,30,0,0,0,0,0,0,0,0,0,0,0,30,30,30,30
0,30,2,30,30,0,0,31,0,0,0,0,0,0,30,30,2,30,30
0,30,30,30,30,30,0,0,0,0,0,0,0,0,30,30,30,30,0
0,0,30,30,30,30,0,30,0,0,0,0,0,0,30,30,30,0,0
0,0,30,30,30,0,0,30,30,0,0,0,0,0,0,0,0,0,0
0,0,0,30,0,0,0,30,30,0,0,0,0,0,0,0,0,0,0
0,0,0,0,0,0,30,30,30,30,0,0,0,0,0,0,31,0,0
0,0,0,30,30,30,30,30,30,2,30,30,0,0,0,0,0,0,0
0,0,0,30,30,30,30,30,2,2,2,30,30,30,0,0,0,0,0
0,0,30,30,30,30,30,30,30,2,30,30,30,30,30,0,0,0,0
0,0,30,30,30,30,30,30,30,30,30,30,30,30,30,0,0,0,0
0,0,30,30,30,30,30,30,30,30,30,30,30,30,0,0,31,0,0
0,30,30,30,30,30,30,30,30,30,30,30,30,30,0,0,0,0,0
0,30,30,30,30,30,30,30,30,30,30,30,30,0,0,0,0,0,0
0,30,30,30,30,30,30,30,30,30,0,0,0,0,0,0,30,0,0
0,0,30,30,30,30,30,0,0,0,0,31,0,0,0,30,2,30,0
0,0,0,0,0,0,0,0,0,0,0,0,0,0,30,30,30,30,0
0,0,0,0,0,0,0,0,0,0,0,0,0,0,0,0,30,0,0
endlayer

layer
0,0,0,0,0,0,0,0,0,0,0,0,0,0,0,0,0,0,0
0,4,30,0,0,0,0,0,0,0,0,0,0,0,0,0,30,30,0
0,30,2,30,0,0,0,0,0,0,0,0,0,0,0,0,2,30,0
0,0,30,0,0,0,0,0,0,0,0,0,0,0,0,31,0,0,0
0,0,0,0,0,0,0,0,0,0,0,0,0,0,0,0,0,0,0
0,0,0,0,0,0,0,0,0,0,0,0,0,0,0,0,0,0,0
0,0,0,31,0,0,0,0,0,0,0,0,0,0,0,0,0,0,0
0,0,0,0,0,0,0,0,0,0,0,0,0,0,0,0,0,0,0
0,0,0,0,0,0,0,30,30,0,0,0,0,0,0,0,0,0,0
0,0,0,0,0,0,30,30,30,2,0,0,0,0,0,0,0,0,0
0,0,0,0,30,30,30,30,30,30,30,30,0,0,0,0,0,0,0
0,0,0,30,30,30,30,30,30,30,30,30,30,0,0,0,0,0,0
0,0,0,30,30,30,30,30,30,30,30,30,30,0,0,0,0,0,0
0,0,0,30,30,30,30,30,30,30,30,30,0,0,0,0,0,0,0
0,0,30,30,30,30,30,30,30,0,0,0,0,0,0,0,0,0,0
0,0,0,30,30,30,0,0,0,0,0,0,0,0,0,0,0,0,0
0,0,0,0,0,0,0,0,0,0,0,0,0,0,0,0,30,0,0
0,0,0,0,0,0,0,0,0,0,0,0,0,0,0,0,0,0,0
0,0,0,0,0,0,0,0,0,0,0,0,0,0,0,0,0,0,0
endlayer

layer
0,0,0,0,0,0,0,0,0,0,0,0,0,0,0,0,0,0,0
0,0,0,0,0,0,0,0,0,0,0,0,0,0,0,0,0,0,0
0,0,2,0,0,0,0,0,0,0,0,0,0,0,0,0,2,0,0
0,0,0,0,0,0,0,0,0,0,0,0,0,0,0,0,0,0,0
0,0,0,0,0,0,0,0,0,0,0,0,0,0,0,0,0,0,0
0,0,0,0,0,0,0,0,0,0,0,0,0,0,0,0,0,0,0
0,0,0,0,0,0,0,0,0,0,0,0,0,0,0,0,0,0,0
0,0,0,0,0,0,0,0,0,0,0,0,0,0,0,0,0,0,0
0,0,0,0,0,0,0,0,0,0,0,0,0,0,0,0,0,0,0
0,0,0,0,0,0,0,0,0,0,0,0,0,0,0,0,0,0,0
0,0,0,0,0,0,0,30,0,0,0,31,0,0,0,0,0,0,0
0,0,0,0,0,30,30,30,30,30,0,0,0,0,0,0,0,0,0
0,0,0,0,30,30,30,30,30,30,30,0,0,0,0,0,0,0,0
0,0,0,0,0,30,30,30,0,0,0,0,0,0,0,0,0,0,0
0,0,0,0,0,0,0,0,0,0,0,0,0,0,0,0,0,0,0
0,0,0,31,0,0,0,0,0,0,0,0,0,0,0,0,0,0,0
0,0,0,0,0,0,0,0,0,0,0,0,0,0,0,0,31,0,0
0,0,0,0,0,0,0,0,0,0,0,0,0,0,0,0,0,0,0
0,0,0,0,0,0,0,0,0,0,0,0,0,0,0,0,0,0,0
endlayer

layer
0,0,0,0,0,0,0,0,0,0,0,0,0,0,0,0,0,0,0
0,0,0,0,0,0,0,0,0,0,0,0,0,0,0,0,0,0,0
0,0,4,0,0,0,0,0,0,0,0,0,0,0,0,0,4,0,0
0,0,0,0,0,0,0,0,0,0,0,0,0,0,0,0,0,0,0
0,0,0,0,0,0,0,0,0,0,0,0,0,0,0,0,0,0,0
0,0,0,0,0,0,0,0,0,0,0,0,0,0,0,0,0,0,0
0,0,0,0,0,0,0,0,0,0,0,0,0,0,0,0,0,0,0
0,0,0,0,0,0,0,0,0,0,0,0,0,0,0,0,0,0,0
0,0,0,0,0,0,0,0,0,0,0,0,0,0,0,0,0,0,0
0,0,0,0,0,0,0,0,0,0,0,0,0,0,0,0,0,0,0
0,0,0,0,0,0,0,0,0,0,0,0,0,0,0,0,0,0,0
0,0,0,0,0,0,0,0,0,0,0,0,0,0,0,0,0,0,0
0,0,0,0,0,0,31,0,0,0,0,0,0,0,0,0,0,0,0
0,0,0,0,0,0,0,0,0,0,0,0,0,0,0,0,0,0,0
0,0,0,0,0,0,0,0,0,0,0,0,0,0,0,0,0,0,0
0,0,0,0,0,0,0,0,0,0,0,0,0,0,0,0,0,0,0
0,0,0,0,0,0,0,0,0,0,0,0,0,0,0,0,0,0,0
0,0,0,0,0,0,0,0,0,0,0,0,0,0,0,0,0,0,0
0,0,0,0,0,0,0,0,0,0,0,0,0,0,0,0,0,0,0
endlayer

