
# Created by Ruins mod version 15.3 Ingame Parser
# authoring Player: Mensrea

weight=8
embed_into_distance=6
acceptable_target_blocks=
unacceptable_target_blocks=flowing_water,water,flowing_lava,lava
dimensions=14,22,27
allowable_overhang=0
max_leveling=2
leveling_buffer=0
preserve_water=0
preserve_lava=0
preventRotation=1

rule1=0,100,PFAAGeologica:strongStone-7
rule2=0,100,PFAAGeologica:mediumStone-3
rule3=0,100,minecraft:stonebrick-0
rule4=0,100,minecraft:water-0
rule5=0,100,PFAAGeologica:weakStone-1
rule6=0,100,minecraft:sand-1
rule7=0,100,minecraft:dirt-0
rule8=0,100,minecraft:planks-0
rule9=0,100,minecraft:oak_stairs-0
rule10=0,100,minecraft:gravel-0
rule11=0,100,minecraft:stone-0
rule12=0,100,minecraft:log-0
rule13=0,100,minecraft:stone_brick_stairs-1
rule14=0,100,minecraft:stone_brick_stairs-2
rule15=0,100,minecraft:stone_brick_stairs-3
rule16=0,100,IInventory;minecraft:furnace;minecraft:coal#7#0#1-2
rule17=0,100,IW:steelblock-0
rule18=0,100,minecraft:farmland-7
rule19=0,100,IW:steelsiding-0
rule20=0,100,minecraft:glass-0
rule21=0,100,IW:fiberboard-0
rule22=0,100,minecraft:potatoes-7
rule23=0,100,minecraft:potatoes-6
rule24=0,100,minecraft:bed-10
rule25=0,100,minecraft:bed-2
rule26=0,100,minecraft:bookshelf-0
rule27=0,100,ChestGenHook:mineshaftCorridor:5-2
rule28=0,100,minecraft:jungle_stairs-1
rule29=0,100,IW:metaldoor-2
rule30=0,100,IW:metaldoor-3
rule31=0,100,minecraft:potatoes-5
rule32=0,100,minecraft:bed-0
rule33=0,100,minecraft:bed-8
rule34=0,100,ChestGenHook:mineshaftCorridor:5-2
rule35=0,100,IW:computer1-0
rule36=0,100,minecraft:jungle_stairs-3
rule37=0,100,minecraft:potatoes-4
rule38=0,100,minecraft:fence-0
rule39=0,100,minecraft:cauldron-3
rule40=0,100,ThermalExpansion:Workbench-1
rule41=0,100,minecraft:wooden_door-2
rule42=0,100,IInventory;minecraft:chest;enviromine:rottenFood#16#0#0+enviromine:rottenFood#16#0#1+enviromine:rottenFood#16#0#2+enviromine:rottenFood#16#0#3+enviromine:rottenFood#16#0#4+minecraft:dye#58#15#5+minecraft:sapling#5#0#6+IC2:itemCellEmpty#49#1#7+ThermalFoundation:tool.hoePlatinum#1#0#8+ThermalFoundation:tool.sicklePlatinum#1#0#9-3
rule43=0,100,IW:smalllightwhite-3
rule44=0,100,minecraft:leaves-4
rule45=0,100,minecraft:leaves-12
rule46=0,100,IW:smalllightwhite-4
rule47=0,100,IW:metaldoor-8
rule48=0,100,minecraft:stained_glass-15
rule49=0,100,minecraft:wooden_pressure_plate-0
rule50=0,100,minecraft:wooden_door-8
rule51=0,100,IW:scrapmetalsheet-0
rule52=0,100,IW:machinery1-0
rule53=0,100,IC2:blockGenerator-3
rule54=0,100,IW:smalllightwhite-1
rule55=0,100,minecraft:leaves-0

layer
1,1,1,1,1,1,1,1,1,1,1,1,1,1,1,1,1,1,1,1,1,1,1,1,1,1,1
1,1,1,1,1,1,1,1,1,1,1,1,1,1,1,1,1,1,1,1,1,1,1,1,1,1,1
1,1,1,1,1,1,1,1,1,1,1,1,1,1,1,1,1,1,1,1,1,1,1,1,1,1,1
1,1,1,1,1,1,1,1,1,1,1,1,1,1,1,1,1,1,1,1,1,1,1,1,1,1,1
1,1,1,1,1,1,1,1,1,1,1,1,1,1,1,1,1,1,1,1,1,1,1,1,1,1,1
1,1,1,1,1,1,1,1,1,1,1,1,1,1,1,1,1,1,1,1,1,1,1,1,1,1,1
1,1,1,1,1,1,1,1,1,1,1,1,1,1,1,1,1,1,1,1,1,1,1,1,1,1,1
1,1,1,1,1,1,1,1,1,1,1,1,1,1,1,1,1,1,1,1,1,1,1,1,1,1,1
1,1,1,1,1,1,1,1,1,1,1,1,1,1,1,1,1,1,1,1,1,1,1,1,1,1,1
1,1,1,1,1,1,1,1,1,1,1,1,1,1,1,1,1,1,1,1,1,1,1,1,1,1,1
1,1,1,1,1,1,1,1,1,1,1,1,1,1,1,1,1,1,1,1,1,1,1,1,1,1,1
1,1,1,1,1,1,1,1,1,1,1,1,1,1,1,1,1,1,1,1,1,1,1,1,1,1,1
1,1,1,1,1,1,1,1,1,1,1,1,1,1,1,1,1,1,1,1,1,1,1,1,1,1,1
1,1,1,1,1,1,1,1,1,1,1,1,1,1,1,1,1,1,1,1,1,1,1,1,1,1,1
1,1,1,1,1,1,1,1,1,1,1,1,1,1,1,1,1,1,1,1,1,1,1,1,1,1,1
1,1,1,1,1,1,1,1,1,1,1,1,1,1,1,1,1,1,1,1,1,1,1,1,1,1,1
1,1,1,1,1,1,1,1,1,1,1,1,1,1,1,1,1,1,1,1,1,1,1,1,1,1,1
1,1,1,1,1,1,1,1,1,1,1,1,1,1,1,1,1,1,1,1,1,1,1,1,1,1,1
1,1,1,1,1,1,1,1,1,1,1,1,1,1,1,1,1,1,1,1,1,1,1,1,1,1,1
1,1,1,1,1,1,1,1,1,1,1,1,1,1,1,1,1,1,1,1,1,1,1,1,1,1,1
1,1,1,1,1,1,1,1,1,1,1,1,1,1,1,1,1,1,1,1,1,1,1,1,1,1,1
1,1,1,1,1,1,1,1,1,1,1,1,1,1,1,1,1,1,1,1,1,1,1,1,1,1,1
endlayer

layer
2,2,2,2,2,2,2,2,2,2,2,2,2,2,2,2,2,2,2,2,2,2,2,2,2,2,2
2,2,2,2,2,2,2,2,2,2,2,2,2,2,2,2,2,2,2,2,2,2,2,2,2,2,2
2,2,2,2,2,2,2,2,2,2,2,2,2,2,2,2,2,2,2,2,2,2,2,2,2,2,2
2,2,2,2,2,2,2,2,2,2,2,2,2,2,2,2,2,2,2,2,2,2,2,2,2,2,2
2,2,2,2,2,2,2,2,2,2,2,2,2,2,2,2,2,2,2,2,2,2,2,2,2,2,2
2,2,2,2,2,2,2,2,2,2,2,2,2,2,2,2,2,2,2,2,2,2,2,2,2,2,2
2,2,2,2,2,2,2,2,2,2,2,2,2,2,2,2,2,2,2,2,2,2,2,2,2,2,2
2,2,2,2,2,2,2,2,2,2,2,2,2,2,2,2,2,2,2,2,2,2,2,2,2,2,2
2,2,2,2,2,2,2,2,2,2,2,2,2,2,2,2,2,2,2,2,2,2,2,2,2,2,2
2,2,2,2,2,2,2,2,2,2,2,2,2,2,2,2,2,3,3,3,3,3,3,3,3,2,2
2,2,2,2,2,2,2,2,2,2,2,2,2,2,2,2,2,3,3,3,3,3,3,3,3,2,2
2,2,2,2,2,2,2,2,2,2,2,2,2,2,2,2,2,3,3,3,3,3,3,3,3,2,2
2,2,2,2,2,2,2,2,2,2,2,2,2,2,2,2,2,3,3,3,3,3,3,3,3,2,2
2,2,2,2,2,2,2,2,2,2,2,2,2,2,2,2,2,3,3,3,3,3,3,3,3,2,2
2,2,2,2,2,2,2,2,2,2,2,2,2,2,2,2,2,3,3,3,3,3,3,3,3,2,2
2,2,2,2,2,2,2,2,2,2,2,2,2,2,2,2,2,3,3,3,3,3,3,3,3,2,2
2,2,2,2,2,2,2,2,2,2,2,2,2,2,2,2,2,3,3,3,3,3,3,3,3,2,2
2,2,2,2,2,2,2,2,2,2,2,2,2,2,2,2,2,2,2,2,2,2,3,3,3,2,2
2,2,2,2,2,2,2,2,2,2,2,2,2,2,2,2,2,2,2,2,2,2,3,3,3,2,2
2,2,2,2,2,2,2,2,2,2,2,2,2,2,2,2,2,2,2,2,2,2,3,3,3,2,2
2,2,2,2,2,2,2,2,2,2,2,2,2,2,2,2,2,2,2,2,2,2,2,2,2,2,2
2,2,2,2,2,2,2,2,2,2,2,2,2,2,2,2,2,2,2,2,2,2,2,2,2,2,2
endlayer

layer
2,2,2,2,2,2,2,2,2,2,2,2,2,2,2,2,2,2,2,2,2,2,2,2,2,2,2
2,2,2,2,2,2,2,2,2,2,2,2,2,2,2,2,2,2,2,2,2,2,2,2,2,2,2
2,2,2,2,2,2,2,2,2,2,2,2,2,2,2,2,2,2,2,2,2,2,2,2,2,2,2
2,2,2,2,2,2,2,2,2,2,2,2,2,2,2,2,2,2,2,2,2,2,2,2,2,2,2
2,2,2,2,2,2,2,2,2,2,2,2,2,2,2,2,2,2,2,2,2,2,2,2,2,2,2
2,2,2,2,2,2,2,2,2,2,2,2,2,2,2,2,2,2,2,2,2,2,2,2,2,2,2
2,2,2,2,2,2,2,2,2,2,2,2,2,2,2,2,2,2,2,2,2,2,2,2,2,2,2
2,2,2,2,2,2,2,2,2,2,2,2,2,2,2,2,2,2,2,2,2,2,2,2,2,2,2
2,2,2,2,2,2,2,2,2,2,2,2,2,2,2,2,2,2,2,2,2,2,2,2,2,2,2
2,2,2,2,2,2,2,2,2,2,2,2,2,2,2,2,2,3,3,3,3,3,3,3,3,2,2
2,2,2,2,2,2,2,2,2,2,2,2,2,2,2,2,2,3,4,4,4,4,4,4,3,2,2
2,2,2,2,2,2,2,2,2,2,2,2,2,2,2,2,2,3,4,4,4,4,4,4,3,2,2
2,2,2,2,2,2,2,2,2,2,2,2,2,2,2,2,2,3,4,4,4,4,4,4,3,2,2
2,2,2,2,2,2,2,2,2,2,2,2,2,2,2,2,2,3,4,4,4,4,4,4,3,2,2
2,2,2,2,2,2,2,2,2,2,2,2,2,2,2,2,2,3,4,4,4,4,4,4,3,2,2
2,2,2,2,2,2,2,2,2,2,2,2,2,2,2,2,2,3,4,4,4,4,4,4,3,2,2
2,2,2,2,2,2,2,2,2,2,2,2,2,2,2,2,2,3,3,3,3,3,3,4,3,2,2
2,2,2,2,2,2,2,2,2,2,2,2,2,2,2,2,2,2,2,2,2,2,3,4,3,2,2
2,2,2,2,2,2,2,2,2,2,2,2,2,2,2,2,2,2,2,2,2,2,3,2,3,2,2
2,2,2,2,2,2,2,2,2,2,2,2,2,2,2,2,2,2,2,2,2,2,3,3,3,2,2
2,2,2,2,2,2,2,2,2,2,2,2,2,2,2,2,2,2,2,2,2,2,2,2,2,2,2
2,2,2,2,2,2,2,2,2,2,2,2,2,2,2,2,2,2,2,2,2,2,2,2,2,2,2
endlayer

layer
5,5,5,5,5,5,5,5,5,5,5,5,5,5,5,5,5,5,5,5,5,5,5,5,5,5,5
5,5,5,5,5,5,5,5,5,5,5,5,5,5,5,5,5,5,5,5,5,5,5,5,5,5,5
5,5,5,5,5,5,5,5,5,5,5,5,5,5,5,5,5,5,5,5,5,5,5,5,5,5,5
5,5,5,5,5,5,5,5,5,5,5,5,5,5,5,5,5,5,5,5,5,5,5,5,5,5,5
5,5,5,5,5,5,5,5,5,5,5,5,5,5,5,5,5,5,5,5,5,5,5,5,5,5,5
5,5,5,5,5,5,5,5,5,5,5,5,5,5,5,5,5,5,5,5,5,5,5,5,5,5,5
5,5,5,5,5,5,5,5,5,5,5,5,5,5,5,5,5,5,5,5,5,5,5,5,5,5,5
5,5,5,5,5,5,5,5,5,5,5,5,5,5,5,5,5,5,5,5,5,5,5,5,5,5,5
5,5,5,5,5,5,5,5,5,5,5,5,5,5,5,5,5,5,5,5,5,5,5,5,5,5,5
5,5,5,5,5,5,5,5,5,5,5,5,5,5,5,5,5,3,3,3,3,3,3,3,3,5,5
5,5,5,5,5,5,5,5,5,5,5,5,5,5,5,5,5,3,4,4,4,4,4,4,3,5,5
5,5,5,5,5,5,5,5,5,5,5,5,5,5,5,5,5,3,4,4,4,4,4,4,3,5,5
5,5,5,5,5,5,5,5,5,5,5,5,5,5,5,5,5,3,4,4,4,4,4,4,3,5,5
5,5,5,5,5,5,5,5,5,5,5,5,5,5,5,5,5,3,4,4,4,4,4,4,3,5,5
5,5,5,5,5,5,5,5,5,5,5,5,5,5,5,5,5,3,4,4,4,4,4,4,3,5,5
5,5,5,5,5,5,5,5,5,5,5,5,5,5,5,5,5,3,4,4,4,4,4,4,3,5,5
5,5,5,5,5,5,5,5,5,5,5,5,5,5,5,5,5,3,3,3,3,3,3,4,3,5,5
5,5,5,5,5,5,5,5,5,5,5,5,5,5,5,5,5,5,5,5,5,5,3,4,3,5,5
5,5,5,5,5,5,5,5,5,5,5,5,5,5,5,5,5,5,5,5,5,5,3,5,3,5,5
5,5,5,5,5,5,5,5,5,5,5,5,5,5,5,5,5,5,5,5,5,5,3,3,3,5,5
5,5,5,5,5,5,5,5,5,5,5,5,5,5,5,5,5,5,5,5,5,5,5,5,5,5,5
5,5,5,5,5,5,5,5,5,5,5,5,5,5,5,5,5,5,5,5,5,5,5,5,5,5,5
endlayer

layer
5,5,5,5,5,5,5,5,5,5,5,5,5,5,5,5,5,5,5,5,5,5,5,5,5,5,5
5,5,5,5,5,5,5,5,5,5,5,5,5,5,5,5,5,5,5,5,5,5,5,5,5,5,5
5,5,5,5,5,5,5,5,5,5,5,5,5,5,5,5,5,5,5,5,5,5,5,5,5,5,5
5,5,5,5,5,5,5,5,5,5,5,5,5,5,5,5,5,5,5,5,5,5,5,5,5,5,5
5,5,5,5,5,5,5,5,5,5,5,5,5,5,5,5,5,5,5,5,5,5,5,5,5,5,5
5,5,5,5,5,5,5,5,5,5,5,5,5,5,5,5,5,5,5,5,5,5,5,5,5,5,5
5,5,5,5,5,5,5,5,5,5,5,5,5,5,5,5,5,5,5,5,5,5,5,5,5,5,5
5,5,5,5,5,5,5,5,5,5,5,5,5,5,5,5,5,5,5,5,5,5,5,5,5,5,5
5,5,5,5,5,5,5,5,5,5,5,5,5,5,5,5,5,5,5,5,5,5,5,5,5,5,5
5,5,5,5,5,5,5,5,5,5,5,5,5,5,5,5,5,3,3,3,3,3,3,3,3,5,5
5,5,5,5,5,5,5,5,5,5,5,5,5,5,5,5,5,3,4,4,4,4,4,4,3,5,5
5,5,5,5,5,5,5,5,5,5,5,5,5,5,5,5,5,3,4,4,4,4,4,4,3,5,5
5,5,5,5,5,5,5,5,5,5,5,5,5,5,5,5,5,3,4,4,4,4,4,4,3,5,5
5,5,5,5,5,5,5,5,5,5,5,5,5,5,5,5,5,3,4,4,4,4,4,4,3,5,5
5,5,5,5,5,5,5,5,5,5,5,5,5,5,5,5,5,3,4,4,4,4,4,4,3,5,5
5,5,5,5,5,5,5,5,5,5,5,5,5,5,5,5,5,3,4,4,4,4,4,4,3,5,5
5,5,5,5,5,5,5,5,5,5,5,5,5,5,5,5,5,3,3,3,3,3,3,4,3,5,5
5,5,5,5,5,5,5,5,5,5,5,5,5,5,5,5,5,5,5,5,5,5,3,4,3,5,5
5,5,5,5,5,5,5,5,5,5,5,5,5,5,5,5,5,5,5,5,5,5,3,4,3,5,5
5,5,5,5,5,5,5,5,5,5,5,5,5,5,5,5,5,5,5,5,5,5,3,3,3,5,5
5,5,5,5,5,5,5,5,5,5,5,5,5,5,5,5,5,5,5,5,5,5,5,5,5,5,5
5,5,5,5,5,5,5,5,5,5,5,5,5,5,5,5,5,5,5,5,5,5,5,5,5,5,5
endlayer

layer
6,6,6,6,6,6,6,6,6,6,6,6,6,6,6,6,6,6,6,6,6,6,6,6,6,6,6
6,6,6,6,6,6,6,6,6,6,6,6,6,6,6,6,6,6,6,6,6,6,6,6,6,6,6
6,6,6,6,6,6,6,6,6,6,6,6,6,6,6,6,6,6,6,6,6,6,6,6,6,6,6
6,6,6,6,6,6,6,6,6,6,6,6,6,6,6,6,6,6,6,6,6,6,6,6,6,6,6
6,6,6,6,6,6,6,6,6,6,6,6,6,6,6,6,6,6,6,6,6,6,6,6,6,6,6
6,6,6,6,6,6,6,6,6,6,6,6,6,6,6,6,6,6,6,6,6,6,6,6,6,6,6
6,6,6,6,6,6,6,6,6,6,6,6,6,6,6,6,6,6,6,6,6,6,6,6,6,6,6
6,6,6,6,6,6,6,6,6,6,6,6,6,6,6,6,6,6,6,6,6,6,6,6,6,6,6
6,6,6,6,6,6,6,6,6,6,6,6,6,6,6,6,6,6,6,6,6,6,6,6,6,6,6
6,6,6,6,6,6,6,6,6,6,6,6,6,6,6,6,6,3,3,3,3,3,3,3,3,6,6
6,6,6,6,6,6,6,6,6,6,6,6,6,6,6,6,6,3,3,3,3,3,3,3,3,6,6
6,6,6,6,6,6,6,6,6,6,6,6,6,6,6,6,6,3,3,3,3,3,3,3,3,6,6
6,6,6,6,6,6,6,6,6,6,6,6,6,6,6,6,6,3,3,3,3,3,3,3,3,6,6
6,6,6,6,6,6,6,6,6,6,6,6,6,6,6,6,6,3,3,3,3,3,3,3,3,6,6
6,6,6,6,6,6,6,6,6,6,6,6,6,6,6,6,6,3,3,3,3,3,3,3,3,6,6
6,6,6,6,6,6,6,6,6,6,6,6,6,6,6,6,6,3,3,3,3,3,3,3,3,6,6
6,6,6,6,6,6,6,6,6,6,6,6,6,6,6,6,6,3,3,3,3,3,3,3,3,6,6
6,6,6,6,6,6,6,6,6,6,6,6,6,6,6,6,6,6,6,6,6,6,3,3,3,6,6
6,6,6,6,6,6,6,6,6,6,6,6,6,6,6,6,6,6,6,6,6,6,3,0,3,6,6
6,6,6,6,6,6,6,6,6,6,6,6,6,6,6,6,6,6,6,6,6,6,3,3,3,6,6
6,6,6,6,6,6,6,6,6,6,6,6,6,6,6,6,6,6,6,6,6,6,6,6,6,6,6
6,6,6,6,6,6,6,6,6,6,6,6,6,6,6,6,6,6,6,6,6,6,6,6,6,6,6
endlayer

layer
0,6,6,6,6,6,6,6,6,6,6,6,6,6,6,6,6,6,6,6,6,6,6,6,6,0,0
0,6,6,6,6,6,6,6,6,6,6,6,6,6,6,6,6,6,6,6,6,6,6,6,6,6,0
0,6,6,6,6,6,6,6,6,6,6,6,6,3,6,6,6,6,6,3,6,6,3,3,3,6,0
6,6,6,6,6,6,6,6,6,6,6,6,6,6,6,6,6,6,6,6,6,6,3,7,3,6,6
6,6,6,6,6,6,6,6,6,6,6,6,6,6,6,8,0,8,6,6,6,6,3,3,3,6,6
6,6,6,6,6,6,6,6,6,6,6,6,6,6,6,8,0,8,6,6,6,6,6,6,6,6,6
6,6,6,6,6,6,6,6,6,6,6,6,6,6,6,0,0,0,6,6,6,6,3,3,3,6,6
6,6,6,6,6,6,6,6,6,6,6,6,6,6,6,0,0,0,6,6,6,6,3,7,3,6,0
6,6,6,6,6,6,6,6,6,6,6,6,6,6,6,8,0,0,0,0,0,6,3,3,3,6,0
6,6,6,6,6,6,6,6,6,6,6,6,6,6,6,8,0,8,6,6,9,6,6,6,6,6,6
6,6,6,6,6,6,6,6,6,6,6,6,6,6,6,0,0,8,6,6,6,6,6,6,6,6,6
6,6,6,6,6,6,6,6,6,6,6,6,6,6,6,8,0,0,6,6,6,6,6,6,6,6,6
6,6,6,6,6,6,6,6,6,6,6,6,6,6,6,8,0,8,6,6,6,6,6,6,6,6,6
6,6,6,6,6,6,6,6,6,6,6,6,6,6,6,6,6,6,6,6,6,6,6,6,6,6,6
6,6,6,6,6,6,6,6,6,6,6,6,6,3,6,6,6,6,6,3,6,6,6,6,6,6,6
6,6,6,6,6,6,6,6,6,6,6,6,6,6,6,6,6,6,6,6,6,6,6,6,6,6,6
6,6,6,6,6,6,6,6,6,6,6,6,6,6,6,10,10,10,6,6,6,6,6,6,6,6,6
6,6,6,6,6,6,6,6,6,6,6,6,6,6,10,10,10,10,10,6,6,6,3,3,3,6,6
6,6,6,6,6,6,6,6,6,6,6,6,6,6,10,10,10,10,10,10,10,10,3,0,3,6,6
6,6,6,6,6,10,10,10,6,6,6,6,6,10,10,10,10,10,10,10,6,6,3,3,3,6,6
6,6,6,6,6,10,10,10,10,10,10,10,10,10,10,10,10,10,10,6,6,6,6,6,6,6,0
6,6,6,0,0,6,6,6,6,6,6,6,6,6,10,10,10,10,6,6,6,6,6,6,6,0,0
endlayer

layer
0,0,0,0,0,0,0,6,6,6,0,0,0,0,0,0,0,0,0,0,0,0,0,0,0,0,0
0,11,11,11,11,11,11,11,11,11,11,11,0,0,6,6,0,0,0,6,0,0,0,0,0,0,0
0,11,11,11,11,11,11,11,11,11,11,11,0,3,0,0,0,0,0,3,0,0,0,0,0,0,0
0,11,11,11,11,11,11,11,11,11,11,11,0,0,0,0,0,0,0,0,0,0,0,12,0,0,0
0,11,11,11,11,11,11,11,11,11,11,11,0,0,0,0,0,0,0,0,0,0,0,0,0,0,0
0,11,11,11,11,11,11,11,11,11,11,11,0,0,0,0,0,0,0,0,0,0,0,0,0,0,0
0,11,11,11,11,11,11,11,11,11,11,11,0,0,0,0,0,0,0,0,0,0,0,0,0,0,0
0,11,11,11,11,11,11,11,11,11,11,11,0,0,0,0,0,0,0,0,0,0,0,12,0,0,0
0,11,11,11,11,11,11,11,11,11,11,11,0,0,0,0,0,0,0,0,0,0,0,0,0,0,0
0,11,11,11,11,11,11,11,11,11,11,11,0,0,0,0,0,0,0,0,0,0,0,0,0,0,0
0,11,11,11,11,11,11,11,11,11,11,11,0,0,0,0,0,0,0,0,0,0,0,6,0,0,0
0,11,11,11,11,11,11,11,11,11,11,11,0,0,0,8,0,0,0,0,0,0,6,6,6,0,0
0,11,11,11,11,11,11,11,11,11,11,11,0,0,0,8,0,0,0,0,0,0,0,6,6,6,0
0,11,11,11,11,11,11,11,11,11,11,11,0,0,0,0,0,0,0,0,0,0,6,6,6,0,0
6,11,11,11,11,11,11,11,11,11,11,11,0,3,0,0,0,0,0,3,0,0,6,6,6,0,0
6,11,11,11,11,11,11,11,11,11,11,11,0,0,0,0,3,0,0,0,0,0,6,0,0,0,0
6,11,11,11,11,11,11,11,11,11,11,11,0,0,0,0,13,0,0,0,0,0,0,0,0,0,0
6,11,11,11,11,11,11,11,11,11,11,11,0,0,0,0,0,0,0,0,0,0,15,3,14,0,0
6,11,11,11,11,11,11,11,11,11,11,11,0,0,16,0,0,0,0,0,0,0,15,0,14,0,0
6,6,0,0,0,13,13,13,0,0,0,0,0,0,0,0,0,0,0,0,0,0,15,3,14,0,0
0,0,0,0,0,0,0,0,0,0,0,0,0,0,0,0,0,0,0,0,0,0,0,0,0,0,0
0,0,0,0,0,0,0,0,0,0,0,0,0,0,0,0,0,0,0,0,0,6,6,0,0,0,0
endlayer

layer
0,0,0,0,0,0,0,0,0,0,0,0,0,0,0,0,0,0,0,0,0,0,0,0,0,0,0
0,11,11,11,11,11,11,11,11,11,11,11,0,0,0,0,0,0,0,0,0,0,0,0,0,0,0
0,11,18,18,18,18,18,18,18,18,18,11,0,17,17,17,17,17,17,17,0,0,0,0,0,0,0
0,11,18,18,18,18,18,18,18,18,18,11,0,17,19,19,19,19,19,17,0,0,0,12,0,0,0
0,11,18,18,18,18,18,18,18,18,18,11,0,17,19,19,19,19,19,17,0,0,0,0,0,0,0
0,11,18,18,18,18,3,18,18,18,18,11,0,17,19,19,19,19,19,17,0,0,0,0,0,0,0
0,11,18,18,18,18,4,18,18,18,18,11,0,17,19,19,19,19,19,17,0,0,0,0,0,0,0
0,11,18,18,18,18,4,18,18,18,18,11,0,17,19,19,19,19,19,17,0,0,0,12,0,0,0
0,11,18,18,18,18,4,18,18,18,18,11,0,17,19,19,19,19,19,17,0,0,0,0,0,0,0
0,11,18,18,18,18,4,18,18,18,18,11,0,17,19,19,19,19,19,17,0,0,0,0,0,0,0
0,11,18,18,18,18,4,18,18,18,18,11,0,17,19,19,19,19,19,17,0,0,0,0,0,0,0
0,11,18,18,18,18,4,18,18,18,18,11,0,17,19,19,19,19,19,17,0,0,0,0,0,0,0
0,11,18,18,18,18,4,18,18,18,18,11,0,17,19,19,19,19,19,17,0,0,0,0,0,0,0
0,11,18,18,18,18,4,18,18,18,18,11,0,17,19,19,19,19,19,17,0,0,0,6,0,0,0
0,11,18,18,18,18,3,18,18,18,18,11,0,17,17,17,17,17,17,17,0,0,0,0,0,0,0
0,11,18,18,18,18,18,18,18,18,18,11,0,0,0,0,13,0,0,0,0,0,0,0,0,0,0
0,11,3,3,3,3,3,3,3,3,3,11,0,0,0,0,0,0,0,0,0,0,0,0,0,0,0
0,11,3,14,0,0,0,0,0,15,3,11,0,0,0,0,0,0,0,0,0,0,0,17,0,0,0
0,11,11,11,11,0,0,0,11,11,11,11,0,0,0,0,0,0,0,0,0,0,0,0,0,0,0
0,0,0,0,0,0,0,0,0,0,0,0,0,0,0,0,0,0,0,0,0,0,0,17,0,0,0
0,0,0,0,0,0,0,0,0,0,0,0,0,0,0,0,0,0,0,0,0,0,0,0,0,0,0
0,0,0,0,0,0,0,0,0,0,0,0,0,0,0,0,0,0,0,0,0,0,0,0,0,0,0
endlayer

layer
0,0,0,0,0,0,0,0,0,0,0,0,0,0,0,0,0,0,0,0,0,0,0,0,0,0,0
0,11,11,20,20,20,20,20,20,20,11,11,0,0,0,0,0,0,0,0,0,0,0,0,0,0,0
0,20,22,23,22,22,22,22,22,22,22,20,0,17,21,21,21,21,21,17,0,0,0,0,0,0,0
0,20,22,22,22,22,22,22,22,22,22,20,0,21,28,27,26,25,24,21,0,0,0,12,0,0,0
0,20,22,22,22,22,23,22,23,22,22,20,0,21,0,0,0,0,0,21,0,0,0,0,0,0,0
0,20,22,22,22,22,19,22,22,22,22,20,0,21,29,21,21,21,21,21,0,0,0,0,0,0,0
0,20,22,22,22,22,19,22,22,22,22,20,0,21,0,30,0,28,26,21,0,0,0,0,0,0,0
0,20,22,22,31,22,19,22,31,22,22,20,0,21,0,21,0,0,0,21,0,0,0,12,0,0,0
0,20,22,22,22,22,19,22,22,22,22,20,0,21,0,21,34,33,32,21,0,0,0,0,0,0,0
0,20,22,22,22,23,19,22,22,22,22,20,0,21,0,21,21,21,21,21,0,0,0,0,0,0,0
0,20,22,22,22,22,19,22,22,22,22,20,0,21,0,35,28,28,28,21,0,0,0,0,0,0,0
0,20,37,31,22,22,19,22,23,22,22,20,0,21,0,0,0,0,36,21,0,0,0,0,0,0,0
0,20,22,22,22,22,19,22,23,22,31,20,0,21,39,0,38,0,36,21,0,0,0,0,0,0,0
0,20,22,22,22,23,19,22,22,22,22,20,0,21,40,0,0,0,26,21,0,0,0,0,0,0,0
0,20,22,22,22,22,19,22,22,22,22,20,0,17,21,21,41,21,21,17,0,0,0,0,0,0,0
0,20,31,22,31,22,31,22,22,22,22,20,0,0,0,0,0,0,0,0,0,0,0,0,0,0,0
0,20,0,0,0,0,0,0,0,0,0,20,0,0,0,0,0,0,0,0,0,0,0,0,0,0,0
0,20,0,0,0,0,0,0,0,0,42,20,0,0,0,0,0,0,0,0,0,0,0,17,0,0,0
0,11,20,20,11,0,0,0,11,20,20,11,0,0,0,0,0,0,0,0,0,0,43,19,0,0,0
0,0,0,0,0,0,0,0,0,0,0,0,0,0,0,0,0,0,0,0,0,0,0,17,0,0,0
0,0,0,0,0,0,0,0,0,0,0,0,0,0,0,0,0,0,0,0,0,0,0,0,0,0,0
0,0,0,0,0,0,0,0,0,0,0,0,0,0,0,0,0,0,0,0,0,0,0,0,0,0,0
endlayer

layer
0,0,0,0,0,0,0,0,0,0,0,0,0,0,0,0,0,0,0,0,0,0,0,0,0,0,0
0,11,11,20,20,20,20,20,20,20,11,11,0,0,0,0,0,0,0,0,0,0,0,0,0,0,0
0,20,0,0,0,0,0,0,0,0,0,20,0,17,21,21,20,21,21,17,0,0,0,44,0,0,0
0,20,0,0,0,0,0,0,0,0,0,20,0,21,46,0,0,0,43,21,0,0,45,12,44,0,0
0,20,0,0,0,0,0,0,0,0,0,20,0,20,0,0,0,0,0,21,0,0,0,44,0,0,0
0,20,0,0,0,0,0,0,0,0,0,20,0,21,47,21,21,21,21,21,0,0,0,0,0,0,0
0,20,0,0,0,0,0,0,0,0,0,20,0,21,0,47,0,0,43,21,0,0,0,44,0,0,0
0,20,0,0,0,0,0,0,0,0,0,20,0,21,0,21,0,0,0,20,0,0,44,12,44,0,0
0,20,0,0,0,0,0,0,0,0,0,20,0,20,0,21,46,0,0,21,0,0,0,44,0,0,0
0,20,0,0,0,0,0,0,0,0,0,20,0,21,0,21,21,21,21,21,0,0,0,0,0,0,0
0,20,0,0,0,0,0,0,0,0,0,20,0,21,0,48,0,0,43,21,0,0,0,0,0,0,0
0,20,0,0,0,0,0,0,0,0,0,20,0,21,0,0,0,0,0,21,0,0,0,0,0,0,0
0,20,0,0,0,0,0,0,0,0,0,20,0,20,0,0,49,0,0,21,0,0,0,0,0,0,0
0,20,0,0,0,0,0,0,0,0,0,20,0,21,46,0,0,0,43,21,0,0,0,0,0,0,0
0,20,0,0,0,0,0,0,0,0,0,20,0,17,20,21,50,21,20,17,0,0,0,0,0,0,0
0,20,0,0,0,0,0,0,0,0,0,20,0,0,0,0,0,0,0,0,0,0,0,0,0,0,0
0,20,0,0,0,0,0,0,0,0,0,20,0,0,0,0,0,0,0,0,0,0,0,0,0,0,0
0,20,0,0,0,0,0,0,0,0,0,20,0,0,0,0,0,0,0,0,0,0,0,0,0,0,0
0,11,11,20,11,0,0,0,11,20,11,11,0,0,0,0,0,0,0,0,0,0,0,0,0,0,0
0,0,0,0,0,0,0,0,0,0,0,0,0,0,0,0,0,0,0,0,0,0,0,0,0,0,0
0,0,0,0,0,0,0,0,0,0,0,0,0,0,0,0,0,0,0,0,0,0,0,0,0,0,0
0,0,0,0,0,0,0,0,0,0,0,0,0,0,0,0,0,0,0,0,0,0,0,0,0,0,0
endlayer

layer
0,0,0,0,0,0,0,0,0,0,0,0,0,0,0,0,0,0,0,0,0,0,0,0,0,0,0
0,0,11,11,20,20,20,20,20,11,11,0,0,0,0,0,0,0,0,0,0,0,0,0,0,0,0
0,0,20,0,0,0,0,0,0,0,20,0,0,17,17,17,17,17,17,17,0,0,44,45,44,0,0
0,0,20,0,0,0,0,0,0,0,20,0,0,17,51,51,51,51,51,17,0,0,45,12,44,0,0
0,0,20,0,0,0,0,0,0,0,20,0,0,17,51,51,52,51,51,17,0,0,44,44,44,0,0
0,0,20,0,0,0,0,0,0,0,20,0,0,17,51,51,51,51,51,17,0,0,0,0,0,0,0
0,0,20,0,0,0,0,0,0,0,20,0,0,17,51,51,51,51,51,17,0,0,44,44,44,0,0
0,0,20,0,0,0,0,0,0,0,20,0,0,17,51,51,51,51,51,17,0,0,44,12,44,0,0
0,0,20,0,0,0,0,0,0,0,20,0,0,17,51,51,53,51,51,17,0,0,44,44,44,0,0
0,0,20,0,0,0,0,0,0,0,20,0,0,17,51,51,51,51,51,17,0,0,0,0,0,0,0
0,0,20,0,0,0,0,0,0,0,20,0,0,17,51,51,51,51,51,17,0,0,0,0,0,0,0
0,0,20,0,0,0,0,0,0,0,20,0,0,17,51,51,51,51,51,17,0,0,0,0,0,0,0
0,0,20,0,0,0,0,0,0,0,20,0,0,17,51,51,52,51,51,17,0,0,0,0,0,0,0
0,0,20,0,0,0,0,0,0,0,20,0,0,17,51,51,51,51,51,17,0,0,0,0,0,0,0
0,0,20,0,0,0,0,0,0,0,20,0,0,17,17,17,17,17,17,17,0,0,0,0,0,0,0
0,0,20,0,0,0,0,0,0,0,20,0,0,54,0,0,0,0,0,54,0,0,0,0,0,0,0
0,0,20,0,0,0,0,0,0,0,20,0,0,0,0,0,0,0,0,0,0,0,0,0,0,0,0
0,0,20,0,0,0,0,0,0,0,20,0,0,0,0,0,0,0,0,0,0,0,0,0,0,0,0
0,0,11,11,11,11,11,11,11,11,11,0,0,0,0,0,0,0,0,0,0,0,0,0,0,0,0
0,0,0,0,0,0,0,0,0,0,0,0,0,0,0,0,0,0,0,0,0,0,0,0,0,0,0
0,0,0,0,0,0,0,0,0,0,0,0,0,0,0,0,0,0,0,0,0,0,0,0,0,0,0
0,0,0,0,0,0,0,0,0,0,0,0,0,0,0,0,0,0,0,0,0,0,0,0,0,0,0
endlayer

layer
0,0,0,0,0,0,0,0,0,0,0,0,0,0,0,0,0,0,0,0,0,0,0,0,0,0,0
0,0,0,11,11,11,11,11,11,11,0,0,0,0,0,0,0,0,0,0,0,0,0,0,0,0,0
0,0,0,20,20,20,20,20,20,20,0,0,0,0,0,0,0,0,0,0,0,0,0,55,0,0,0
0,0,0,20,20,20,20,20,20,20,0,0,0,0,0,0,0,0,0,0,0,0,55,12,55,0,0
0,0,0,20,20,20,20,20,20,20,0,0,0,0,0,0,0,0,0,0,0,0,0,55,0,0,0
0,0,0,20,20,20,20,20,20,20,0,0,0,0,0,0,0,0,0,0,0,0,0,0,0,0,0
0,0,0,20,20,20,20,20,20,20,0,0,0,0,0,0,0,0,0,0,0,0,0,55,0,0,0
0,0,0,20,20,20,20,20,20,20,0,0,0,0,0,0,0,0,0,0,0,0,55,12,55,0,0
0,0,0,20,20,20,20,20,20,20,0,0,0,0,0,0,0,0,0,0,0,0,0,55,0,0,0
0,0,0,20,20,20,20,20,20,20,0,0,0,0,0,0,0,0,0,0,0,0,0,0,0,0,0
0,0,0,20,20,20,20,20,20,20,0,0,0,0,0,0,0,0,0,0,0,0,0,0,0,0,0
0,0,0,20,20,20,20,20,20,20,0,0,0,0,0,0,0,0,0,0,0,0,0,0,0,0,0
0,0,0,20,20,20,20,20,20,20,0,0,0,0,0,0,0,0,0,0,0,0,0,0,0,0,0
0,0,0,20,20,20,20,20,20,20,0,0,0,0,0,0,0,0,0,0,0,0,0,0,0,0,0
0,0,0,20,20,20,20,20,20,20,0,0,0,0,0,0,0,0,0,0,0,0,0,0,0,0,0
0,0,0,20,20,20,20,20,20,20,0,0,0,0,0,0,0,0,0,0,0,0,0,0,0,0,0
0,0,0,20,20,20,20,20,20,20,0,0,0,0,0,0,0,0,0,0,0,0,0,0,0,0,0
0,0,0,20,20,20,20,20,20,20,0,0,0,0,0,0,0,0,0,0,0,0,0,0,0,0,0
0,0,0,11,11,11,11,11,11,11,0,0,0,0,0,0,0,0,0,0,0,0,0,0,0,0,0
0,0,0,0,0,0,0,0,0,0,0,0,0,0,0,0,0,0,0,0,0,0,0,0,0,0,0
0,0,0,0,0,0,0,0,0,0,0,0,0,0,0,0,0,0,0,0,0,0,0,0,0,0,0
0,0,0,0,0,0,0,0,0,0,0,0,0,0,0,0,0,0,0,0,0,0,0,0,0,0,0
endlayer

layer
0,0,0,0,0,0,0,0,0,0,0,0,0,0,0,0,0,0,0,0,0,0,0,0,0,0,0
0,0,0,0,0,0,0,0,0,0,0,0,0,0,0,0,0,0,0,0,0,0,0,0,0,0,0
0,0,0,0,0,0,0,0,0,0,0,0,0,0,0,0,0,0,0,0,0,0,0,0,0,0,0
0,0,0,0,0,0,0,0,0,0,0,0,0,0,0,0,0,0,0,0,0,0,0,55,0,0,0
0,0,0,0,0,0,0,0,0,0,0,0,0,0,0,0,0,0,0,0,0,0,0,0,0,0,0
0,0,0,0,0,0,0,0,0,0,0,0,0,0,0,0,0,0,0,0,0,0,0,0,0,0,0
0,0,0,0,0,0,0,0,0,0,0,0,0,0,0,0,0,0,0,0,0,0,0,0,0,0,0
0,0,0,0,0,0,0,0,0,0,0,0,0,0,0,0,0,0,0,0,0,0,0,55,0,0,0
0,0,0,0,0,0,0,0,0,0,0,0,0,0,0,0,0,0,0,0,0,0,0,0,0,0,0
0,0,0,0,0,0,0,0,0,0,0,0,0,0,0,0,0,0,0,0,0,0,0,0,0,0,0
0,0,0,0,0,0,0,0,0,0,0,0,0,0,0,0,0,0,0,0,0,0,0,0,0,0,0
0,0,0,0,0,0,0,0,0,0,0,0,0,0,0,0,0,0,0,0,0,0,0,0,0,0,0
0,0,0,0,0,0,0,0,0,0,0,0,0,0,0,0,0,0,0,0,0,0,0,0,0,0,0
0,0,0,0,0,0,0,0,0,0,0,0,0,0,0,0,0,0,0,0,0,0,0,0,0,0,0
0,0,0,0,0,0,0,0,0,0,0,0,0,0,0,0,0,0,0,0,0,0,0,0,0,0,0
0,0,0,0,0,0,0,0,0,0,0,0,0,0,0,0,0,0,0,0,0,0,0,0,0,0,0
0,0,0,0,0,0,0,0,0,0,0,0,0,0,0,0,0,0,0,0,0,0,0,0,0,0,0
0,0,0,0,0,0,0,0,0,0,0,0,0,0,0,0,0,0,0,0,0,0,0,0,0,0,0
0,0,0,0,0,0,0,0,0,0,0,0,0,0,0,0,0,0,0,0,0,0,0,0,0,0,0
0,0,0,0,0,0,0,0,0,0,0,0,0,0,0,0,0,0,0,0,0,0,0,0,0,0,0
0,0,0,0,0,0,0,0,0,0,0,0,0,0,0,0,0,0,0,0,0,0,0,0,0,0,0
0,0,0,0,0,0,0,0,0,0,0,0,0,0,0,0,0,0,0,0,0,0,0,0,0,0,0
endlayer

