
# Created by Ruins mod version 15.3 Ingame Parser
# authoring Player: Mensrea

weight=3
embed_into_distance=8
acceptable_target_blocks=
unacceptable_target_blocks=flowing_water,water,flowing_lava,lava
dimensions=10,9,9
allowable_overhang=0
max_leveling=2
leveling_buffer=0
preserve_water=0
preserve_lava=0
preventRotation=1

rule1=0,100,PFAAGeologica:strongStone-7
rule2=0,100,minecraft:stonebrick-0
rule3=0,100,MobSpawner:desertmobs.cryptzombie
rule4=0,100,minecraft:dirt-0
rule5=0,100,ChestGenHook:pyramidJungleChest:5-2
rule6=0,100,minecraft:jukebox-0
rule7=0,100,ChestGenHook:pyramidDesertyChest:5-2
rule8=0,100,ImmersiveEngineering:storageSlab-7
rule9=0,100,ChestGenHook:dungeonChest:5-2
rule10=0,100,minecraft:bookshelf-0
rule11=0,100,PFAAGeologica:mediumStone-3
rule12=0,100,minecraft:obsidian-0
rule13=0,100,PFAAGeologica:weakStone-1
rule14=0,100,minecraft:sand-1
rule15=0,100,minecraft:gold_block-0
rule16=0,100,IW:bush-0

layer
1,1,1,1,1,1,1,1,1
1,2,2,2,2,2,2,2,1
1,2,2,2,2,2,2,2,1
1,2,2,2,2,2,2,2,1
1,2,5,4,2,4,3,2,1
1,2,2,2,2,2,2,2,1
1,2,2,2,2,2,2,2,1
1,2,2,2,2,2,2,2,1
1,1,1,1,1,1,1,1,1
endlayer

layer
1,1,1,1,1,1,1,1,1
1,2,2,2,2,2,2,2,1
1,2,2,2,2,2,2,2,1
1,2,7,0,0,0,6,2,1
1,2,8,8,0,8,8,2,1
1,2,10,0,0,0,9,2,1
1,2,2,2,2,2,2,2,1
1,2,2,2,2,2,2,2,1
1,1,1,1,1,1,1,1,1
endlayer

layer
1,1,1,1,1,1,1,1,1
1,2,2,2,2,2,2,2,1
1,2,2,2,2,2,2,2,1
1,2,0,0,0,0,0,2,1
1,2,0,0,0,0,0,2,1
1,2,0,0,0,0,0,2,1
1,2,2,2,2,2,2,2,1
1,2,2,2,2,2,2,2,1
1,1,1,1,1,1,1,1,1
endlayer

layer
11,11,11,11,11,11,11,11,11
11,2,2,2,2,2,2,2,11
11,2,2,2,2,2,2,2,11
11,2,2,0,0,0,2,2,11
11,2,2,0,0,0,2,2,11
11,2,2,0,0,0,2,2,11
11,2,2,2,2,2,2,2,11
11,2,2,2,2,2,2,2,11
11,11,11,11,11,11,11,11,11
endlayer

layer
11,11,11,11,11,11,11,11,11
11,12,11,11,11,11,11,12,11
11,11,2,2,2,2,2,11,11
11,11,2,2,2,2,2,11,11
11,11,2,2,0,2,2,11,11
11,11,2,2,2,2,2,11,11
11,11,2,2,2,2,2,11,11
11,12,11,11,11,11,11,12,11
11,11,11,11,11,11,11,11,11
endlayer

layer
13,13,13,13,13,13,13,13,13
13,13,13,13,13,13,13,13,13
13,13,12,13,13,13,12,13,13
13,13,13,2,2,2,13,13,13
13,13,13,2,0,2,13,13,13
13,13,13,2,2,2,13,13,13
13,13,12,13,13,13,12,13,13
13,13,13,13,13,13,13,13,13
13,13,13,13,13,13,13,13,13
endlayer

layer
14,14,14,14,14,14,14,14,14
14,14,14,14,14,14,14,14,14
14,14,14,14,14,14,14,14,14
14,14,14,12,2,12,14,14,14
14,14,14,2,15,2,14,14,14
14,14,14,12,2,12,14,14,14
14,14,14,14,14,14,14,14,14
14,14,14,14,14,14,14,14,14
14,14,14,14,14,14,14,14,14
endlayer

layer
14,14,14,14,0,0,0,14,14
14,14,14,0,0,0,14,14,14
14,14,0,0,14,14,14,14,0
0,14,0,12,14,12,14,14,14
14,14,14,14,12,14,14,14,14
14,14,14,12,14,12,14,14,0
0,14,14,14,14,14,14,14,14
0,14,14,14,14,14,14,14,0
14,14,14,14,14,14,0,0,14
endlayer

layer
0,0,16,0,0,0,0,0,0
0,14,0,0,0,0,0,0,0
0,0,0,0,0,0,0,16,0
0,0,0,12,0,12,0,0,0
0,0,0,0,0,14,14,0,0
0,0,0,12,14,12,14,0,0
0,0,0,0,14,14,0,0,0
0,0,0,0,0,0,0,0,0
0,0,0,0,0,0,0,0,0
endlayer

layer
0,0,0,0,0,0,0,0,0
0,0,0,0,0,0,0,0,0
0,0,0,0,0,0,0,0,0
0,0,0,0,0,0,0,0,0
0,0,0,0,0,0,0,0,0
0,0,0,0,0,0,0,0,0
0,0,0,0,0,16,0,0,0
0,0,0,0,0,0,0,0,0
0,0,0,0,0,0,0,0,0
endlayer

