
# Created by Ruins mod version 15.3 Ingame Parser
# authoring Player: Mensrea

weight=4
embed_into_distance=9
acceptable_target_blocks=
unacceptable_target_blocks=flowing_water,water,flowing_lava,lava
dimensions=12,16,19
allowable_overhang=0
max_leveling=2
leveling_buffer=0
preserve_water=0
preserve_lava=0
preventRotation=1

rule1=0,100,PFAAGeologica:strongStone-7
rule2=0,100,minecraft:stone-0
rule3=0,100,minecraft:lapis_block-0
rule4=0,100,minecraft:stonebrick-0
rule5=0,100,minecraft:stonebrick-2
rule6=0,100,minecraft:bookshelf-0
rule7=0,100,minecraft:oak_stairs-1
rule8=0,100,minecraft:oak_stairs-3
rule9=0,100,minecraft:oak_stairs-2
rule10=0,100,minecraft:fence-0
rule11=0,100,minecraft:oak_stairs-0
rule12=0,100,PFAAGeologica:strongStone-5
rule13=0,100,minecraft:furnace-3
rule14=0,100,minecraft:cauldron-0
rule15=0,100,ChestGenHook:pyramidJungleChest:5-2
rule16=0,100,minecraft:iron_bars-0
rule17=0,100,minecraft:wooden_pressure_plate-0
rule18=0,100,enviromine:offtorch-1
rule19=0,100,enviromine:offtorch-2
rule20=0,100,PFAAGeologica:mediumStone-3
rule21=0,100,minecraft:sand-1
rule22=0,100,minecraft:wooden_slab-0
rule23=0,100,PFAAGeologica:strongStoneBrickStairs.marble-3
rule24=0,100,ChestGenHook:pyramidDesertyChest:5-2
rule25=0,100,PFAAGeologica:strongStoneBrickStairs.marble-1
rule26=0,100,ChestGenHook:pyramidDesertyChest:5-2
rule27=0,100,PFAAGeologica:strongStoneBrickStairs.marble-2
rule28=0,100,ChestGenHook:pyramidDesertyChest:5-2
rule29=0,100,minecraft:wooden_slab-3
rule30=0,100,PFAAGeologica:weakStone-1
rule31=0,100,enviromine:offtorch-3
rule32=0,100,IW:bush-0

layer
1,1,1,1,1,1,1,1,1,1,1,1,1,1,1,1,1,1,1
1,1,1,1,1,1,1,1,1,1,1,1,1,1,1,1,1,1,1
1,1,2,2,2,2,2,2,2,2,2,2,2,2,2,2,2,1,1
1,1,2,2,2,2,2,2,2,2,2,2,2,2,2,2,2,1,1
1,1,2,2,2,2,3,3,3,3,3,3,3,2,2,2,2,1,1
1,1,2,2,2,2,3,2,2,2,2,2,3,2,2,2,2,1,1
1,1,2,2,2,2,3,2,3,3,3,2,3,2,2,2,2,1,1
1,1,2,2,2,2,3,2,3,2,3,2,3,3,3,3,3,1,1
1,1,2,2,2,2,3,2,3,2,3,2,3,3,3,3,3,1,1
1,1,2,2,2,2,3,2,3,3,3,2,3,2,2,2,2,1,1
1,1,2,2,2,2,3,2,2,2,2,2,3,2,2,2,2,1,1
1,1,2,2,2,2,3,3,3,3,3,3,3,2,2,2,2,1,1
1,1,2,2,2,2,2,2,2,2,2,2,2,2,2,2,2,1,1
1,1,2,2,2,2,2,2,2,2,2,2,2,2,2,2,2,1,1
1,1,1,1,1,1,1,1,1,1,1,1,1,1,1,1,1,1,1
1,1,1,1,1,1,1,1,1,1,1,1,1,1,1,1,1,1,1
endlayer

layer
1,1,1,1,1,1,1,1,1,1,1,1,1,1,1,1,1,1,1
1,1,1,1,1,1,1,1,1,1,1,1,1,1,1,1,1,1,1
1,1,2,4,4,5,4,4,4,5,4,4,4,4,5,4,2,1,1
1,1,5,0,0,0,0,0,0,0,0,0,1,1,0,0,4,1,1
1,1,5,0,0,0,0,0,0,0,0,0,0,0,6,0,4,1,1
1,1,4,0,0,0,0,7,7,0,0,6,0,0,6,0,5,1,1
1,1,4,0,0,0,0,9,0,0,0,8,0,0,0,1,4,1,1
1,1,4,0,0,0,0,0,0,10,0,8,0,0,1,1,1,1,1
1,1,4,11,11,0,0,0,0,10,0,8,0,0,0,1,1,1,1
1,1,4,2,2,0,0,9,0,0,0,8,0,12,12,1,4,1,1
1,1,4,0,0,0,0,11,11,0,0,6,0,12,0,0,5,1,1
1,1,4,0,0,0,0,0,0,0,0,0,0,12,0,13,4,1,1
1,1,4,15,0,0,0,0,0,0,0,0,0,0,0,14,4,1,1
1,1,2,4,4,5,4,4,4,5,5,4,4,4,4,4,2,1,1
1,1,1,1,1,1,1,1,1,1,1,1,1,1,1,1,1,1,1
1,1,1,1,1,1,1,1,1,1,1,1,1,1,1,1,1,1,1
endlayer

layer
1,1,1,1,1,1,1,1,1,1,1,1,1,1,1,1,1,1,1
1,1,1,1,1,1,1,1,1,1,1,1,1,1,1,1,1,1,1
1,1,2,5,16,16,5,4,16,16,16,5,4,1,16,4,2,1,1
1,1,4,0,0,0,0,0,0,0,0,0,0,0,0,0,5,1,1
1,1,16,0,0,0,0,0,0,0,0,0,0,0,6,0,16,1,1
1,1,16,0,0,0,0,0,0,0,0,0,0,0,6,0,16,1,1
1,1,5,0,0,0,0,0,0,0,0,0,0,0,0,0,5,1,1
1,1,5,0,0,0,0,0,0,17,0,0,0,0,0,0,1,1,1
1,1,4,0,0,0,0,0,0,17,0,0,0,0,0,0,1,1,1
1,1,4,11,11,0,0,0,0,0,0,0,0,0,0,0,5,1,1
1,1,16,2,2,0,0,0,0,0,0,0,0,0,0,0,16,1,1
1,1,16,0,0,0,0,0,0,0,0,0,0,0,0,0,16,1,1
1,1,4,0,0,0,0,0,0,0,0,0,0,0,0,0,4,1,1
1,1,2,4,16,16,5,4,16,16,16,5,4,16,16,5,2,1,1
1,1,1,1,1,1,1,1,1,1,1,1,1,1,1,1,1,1,1
1,1,1,1,1,1,1,1,1,1,1,1,1,1,1,1,1,1,1
endlayer

layer
1,1,1,1,1,1,1,1,1,1,1,1,1,1,1,1,1,1,1
1,1,1,1,1,1,1,1,1,1,1,1,1,1,1,1,1,1,1
1,1,2,4,16,16,4,4,16,16,16,4,5,16,16,4,2,1,1
1,1,4,0,0,0,18,0,0,0,0,0,18,0,0,0,4,1,1
1,1,16,0,0,0,0,0,0,0,0,0,0,0,0,0,16,1,1
1,1,16,0,0,0,0,0,0,0,0,0,0,0,0,0,16,1,1
1,1,4,0,0,0,0,0,0,0,0,0,0,0,0,0,2,1,1
1,1,4,0,0,0,0,0,0,0,0,0,0,0,0,0,2,1,1
1,1,4,0,0,0,0,0,0,0,0,0,0,0,0,0,2,1,1
1,1,4,0,0,0,0,0,0,0,0,0,0,0,0,0,2,1,1
1,1,16,11,11,0,0,0,0,0,0,0,0,0,0,0,16,1,1
1,1,16,2,2,0,0,0,0,0,0,0,0,0,0,0,16,1,1
1,1,4,0,0,0,19,0,0,0,0,0,19,0,0,0,4,1,1
1,1,2,4,16,16,5,4,16,16,16,4,4,16,16,4,2,1,1
1,1,1,1,1,1,1,1,1,1,1,1,1,1,1,1,1,1,1
1,1,1,1,1,1,1,1,1,1,1,1,1,1,1,1,1,1,1
endlayer

layer
20,20,20,20,20,20,20,20,20,20,20,20,20,20,20,20,20,20,20
20,20,20,20,20,20,20,20,20,20,20,20,20,20,20,20,20,20,20
20,20,2,2,2,2,2,2,2,2,2,2,2,2,2,2,2,20,20
20,20,2,2,2,2,2,2,2,2,2,2,2,2,2,2,2,20,20
20,20,2,2,2,2,2,2,2,2,2,2,2,2,2,2,2,20,20
20,20,2,2,2,2,2,2,2,2,2,2,2,2,2,2,2,20,20
20,20,2,2,2,2,2,2,2,2,2,2,2,2,2,2,2,20,20
20,20,2,2,2,2,2,2,2,2,2,2,2,2,2,2,2,20,20
20,20,2,0,0,2,2,2,2,2,2,2,2,2,2,2,2,20,20
20,20,2,0,0,2,2,2,2,2,2,2,2,2,2,2,2,20,20
20,20,2,0,0,2,2,2,2,2,2,2,2,2,2,2,2,20,20
20,20,2,11,11,2,2,2,2,2,2,2,2,2,2,2,2,20,20
20,20,2,2,2,2,2,2,2,2,2,2,2,2,2,2,2,20,20
20,20,2,2,2,2,2,2,2,2,2,2,2,2,2,2,2,20,20
20,20,20,20,20,20,20,20,20,20,20,20,20,20,20,20,20,20,20
20,20,20,20,20,20,20,20,20,20,20,20,20,20,20,20,20,20,20
endlayer

layer
20,20,20,20,20,20,20,20,20,20,20,20,20,20,20,20,20,20,20
20,20,20,20,20,20,20,20,20,20,20,20,20,20,20,20,20,20,20
20,20,2,4,4,4,4,4,4,4,4,4,4,4,2,20,12,20,20
20,20,4,12,21,23,0,0,4,6,0,0,22,22,4,21,20,20,20
20,20,4,21,21,23,25,25,4,0,0,0,0,24,4,0,12,20,20
20,20,4,27,21,21,0,0,4,0,0,0,0,26,4,21,20,20,20
20,20,4,4,5,5,4,0,4,0,4,4,5,4,4,21,12,20,20
20,20,4,0,0,16,0,0,0,0,0,0,0,0,21,21,20,20,20
20,20,4,0,0,16,0,0,0,0,0,0,0,21,21,21,20,20,20
20,20,4,0,0,16,0,6,4,0,4,4,5,4,4,0,12,20,20
20,20,4,0,0,16,0,8,5,0,0,6,6,6,4,21,20,20,20
20,20,4,0,0,16,0,8,4,0,0,0,0,0,4,21,12,20,20
20,20,4,0,0,0,0,6,4,29,29,0,0,28,4,21,20,20,20
20,20,2,4,4,4,4,4,4,4,4,4,4,4,2,20,12,20,20
20,20,20,20,20,20,20,20,20,20,20,20,20,0,20,20,20,20,20
20,20,20,20,20,20,20,20,20,20,20,20,20,20,20,20,20,20,20
endlayer

layer
30,30,30,30,30,30,30,30,30,30,30,30,30,30,30,30,30,30,30
30,30,30,30,30,30,30,30,30,30,30,30,30,30,30,30,30,30,30
30,30,2,4,16,16,5,4,4,4,5,16,16,4,2,21,12,30,30
30,30,5,21,0,0,0,0,5,6,0,0,0,0,4,0,21,30,30
30,30,16,21,21,0,0,0,4,0,0,0,0,0,16,0,12,30,30
30,30,5,21,0,0,0,0,5,0,0,0,0,0,5,0,0,30,30
30,30,4,5,4,4,5,0,5,0,4,5,5,4,4,0,12,30,30
30,30,4,0,0,0,0,0,0,0,0,0,0,0,0,21,21,30,30
30,30,4,0,0,0,0,0,0,0,0,0,0,0,0,21,21,30,30
30,30,4,0,0,0,0,0,4,0,5,4,4,5,5,0,12,30,30
30,30,16,0,0,0,0,0,4,0,0,6,6,6,4,0,21,30,30
30,30,16,0,0,0,0,0,5,0,0,0,0,0,16,0,12,30,30
30,30,4,0,0,0,0,0,4,0,0,0,0,0,4,0,0,30,30
30,30,2,4,16,16,4,4,4,5,4,16,16,4,2,21,12,30,30
30,30,30,30,30,30,30,30,30,30,30,30,30,30,30,30,30,30,30
30,30,30,30,30,30,30,30,30,30,30,30,30,30,30,30,30,30,30
endlayer

layer
21,21,21,21,21,21,21,21,21,21,21,21,21,21,21,21,21,21,21
21,21,21,21,21,21,21,21,21,21,21,21,21,21,21,21,21,21,21
21,21,2,5,16,16,4,4,4,4,4,16,16,4,2,0,12,21,21
21,21,4,0,0,0,0,0,4,0,0,0,0,0,4,0,0,21,21
21,21,16,0,0,0,0,0,5,0,0,0,0,0,16,0,12,21,21
21,21,4,0,0,0,0,19,4,19,0,0,0,0,4,0,0,21,21
21,21,4,4,4,4,2,2,2,2,2,4,4,4,2,0,12,21,21
21,21,4,0,0,0,0,18,0,0,0,0,0,31,2,0,0,21,21
21,21,4,0,0,0,0,0,0,0,0,0,0,0,2,0,0,21,21
21,21,4,0,0,0,0,0,2,2,2,4,4,4,2,0,12,21,21
21,21,16,0,0,0,0,0,4,18,0,0,0,0,4,0,0,21,21
21,21,16,0,0,0,0,0,4,0,0,0,0,0,16,0,12,21,21
21,21,4,0,0,0,0,0,4,0,0,0,0,0,5,0,0,21,21
21,21,2,4,16,16,4,4,4,4,5,16,16,4,2,0,12,21,21
21,21,21,21,21,21,21,21,21,21,21,21,21,21,21,21,21,21,21
21,21,21,21,21,21,21,21,21,21,21,21,21,21,21,21,21,21,21
endlayer

layer
21,21,21,21,21,21,0,0,0,0,0,0,21,21,21,21,0,0,0
21,21,21,21,21,21,21,0,0,21,21,21,21,21,21,21,21,21,0
21,21,2,2,2,2,2,2,2,2,2,2,2,2,2,2,2,21,21
21,21,2,2,2,2,2,2,2,2,2,2,2,2,2,2,2,21,21
21,21,2,0,2,2,2,2,2,2,2,2,2,2,2,2,2,21,21
21,21,2,2,2,2,2,2,2,2,2,2,2,2,2,2,2,21,21
21,21,2,2,2,2,2,2,2,2,2,2,2,2,2,2,2,21,21
21,21,21,2,2,2,2,2,2,2,2,2,2,2,2,2,2,21,21
21,21,2,2,2,2,2,2,2,2,2,2,2,2,2,2,2,21,0
21,21,2,2,2,2,2,2,2,2,2,2,2,2,2,2,2,21,0
21,21,2,2,2,2,2,2,2,2,2,2,2,2,2,2,2,21,21
21,21,2,2,2,2,2,2,2,2,2,2,2,2,2,2,2,21,21
21,21,2,2,2,2,2,2,2,2,2,2,2,2,2,2,2,21,21
21,21,2,2,2,2,2,2,2,2,2,2,2,2,2,2,2,21,21
21,21,21,21,21,21,21,0,0,0,21,21,21,21,21,21,21,21,0
21,21,21,21,21,0,0,0,0,0,0,21,21,21,21,21,21,0,0
endlayer

layer
0,21,21,0,0,0,0,0,0,0,0,0,0,0,0,0,0,0,0
21,21,21,21,0,0,0,0,0,0,0,0,0,21,21,21,0,0,0
21,21,21,0,0,0,0,0,0,21,21,21,21,21,21,21,21,0,0
0,21,21,0,21,21,21,21,21,21,21,21,21,21,21,21,21,21,0
0,0,0,0,21,21,21,21,21,21,21,21,21,21,21,21,21,21,0
0,0,0,21,21,21,21,21,21,21,21,21,21,21,21,21,21,21,0
0,0,0,21,21,21,21,21,21,21,21,21,21,21,21,21,21,21,0
0,0,0,21,21,21,21,21,21,21,21,21,21,21,21,21,21,21,0
0,32,0,21,21,21,21,21,21,21,21,21,21,21,21,21,21,0,0
0,0,21,21,21,21,21,21,21,21,21,21,21,21,21,21,21,0,0
0,0,21,21,21,21,21,21,21,21,21,21,21,21,21,21,21,0,0
0,21,21,21,21,21,21,21,21,21,21,21,21,21,21,21,0,0,0
0,21,21,21,21,21,21,21,21,21,21,21,21,21,21,21,0,32,0
0,21,21,21,21,21,21,21,0,0,0,21,21,21,21,21,0,0,0
0,21,21,21,21,0,0,0,0,0,0,0,21,21,21,21,0,0,0
0,0,0,0,0,0,0,0,0,0,0,0,0,21,0,0,0,0,0
endlayer

layer
0,0,0,0,0,0,0,0,0,0,0,0,0,0,0,0,0,0,0
0,0,21,0,0,0,0,0,0,0,0,0,0,0,0,0,0,0,0
0,21,21,0,0,0,0,0,0,0,0,0,0,0,0,32,0,0,0
0,0,0,0,0,0,0,0,0,0,0,0,0,0,0,0,0,0,0
0,0,0,0,0,0,21,21,0,0,0,21,21,21,0,0,0,0,0
0,0,0,0,0,21,21,0,0,21,21,21,21,21,21,21,0,0,0
0,0,0,0,32,0,0,0,21,21,21,21,21,21,21,21,0,0,0
0,0,0,0,0,0,0,0,21,21,21,21,21,21,21,21,0,0,0
0,0,0,0,0,0,0,0,21,21,21,21,21,21,21,21,0,0,0
0,0,0,0,21,21,0,0,0,21,21,21,21,21,21,0,0,0,0
0,0,0,0,21,21,21,0,0,32,0,21,21,0,0,0,0,0,0
0,0,0,21,21,21,21,0,0,0,0,0,0,0,0,0,0,0,0
0,0,21,21,21,21,0,0,0,0,0,0,0,32,0,0,0,0,0
0,0,21,21,0,0,0,0,0,0,0,0,0,0,0,0,0,0,0
0,0,0,0,0,0,0,0,0,0,0,0,0,0,0,0,0,0,0
0,0,0,0,0,0,0,0,0,0,0,0,0,0,0,0,0,0,0
endlayer

layer
0,0,0,0,0,0,0,0,0,0,0,0,0,0,0,0,0,0,0
0,0,0,0,0,0,0,0,0,0,0,0,0,0,0,0,0,0,0
0,0,32,0,0,0,0,0,0,0,0,0,0,0,0,0,0,0,0
0,0,0,0,0,0,0,0,0,0,0,0,0,0,0,0,0,0,0
0,0,0,0,0,0,0,0,0,0,0,0,0,0,0,0,0,0,0
0,0,0,0,0,0,0,0,0,0,0,0,0,0,0,0,0,0,0
0,0,0,0,0,0,0,0,0,0,0,0,0,0,32,0,0,0,0
0,0,0,0,0,0,0,0,0,0,0,0,0,0,0,0,0,0,0
0,0,0,0,0,0,0,0,0,0,0,32,0,0,0,0,0,0,0
0,0,0,0,0,0,0,0,0,0,0,0,0,0,0,0,0,0,0
0,0,0,0,0,0,0,0,0,0,0,0,0,0,0,0,0,0,0
0,0,0,0,32,0,0,0,0,0,0,0,0,0,0,0,0,0,0
0,0,0,0,0,0,0,0,0,0,0,0,0,0,0,0,0,0,0
0,0,0,0,0,0,0,0,0,0,0,0,0,0,0,0,0,0,0
0,0,0,0,0,0,0,0,0,0,0,0,0,0,0,0,0,0,0
0,0,0,0,0,0,0,0,0,0,0,0,0,0,0,0,0,0,0
endlayer

