
# Created by Ruins mod version 15.3 Ingame Parser
# authoring Player: Mensrea

weight=2
embed_into_distance=7
acceptable_target_blocks=
unacceptable_target_blocks=flowing_water,water,flowing_lava,lava
dimensions=12,16,19
allowable_overhang=0
max_leveling=2
leveling_buffer=0
preserve_water=0
preserve_lava=0
preventRotation=1

rule1=0,100,PFAAGeologica:strongStone-7
rule2=0,100,PFAAGeologica:mediumStone-3
rule3=0,100,IInventory;minecraft:chest;IW:foods#32#15#0+IW:foods#16#15#1+IW:foods#32#15#3+IW:foods#32#15#5+IW:foods#8#15#7+IW:foods#16#15#16+IW:foods#16#15#20+IW:foods#16#15#23-5
rule4=0,100,IInventory;minecraft:chest;IW:foods#32#15#0+IW:foods#8#15#4+IW:foods#64#15#8+IW:foods#64#15#12+IW:foods#64#15#14+IW:foods#32#15#18+IW:foods#16#15#25-5
rule5=0,100,IW:steelsiding-0
rule6=0,100,ChestGenHook:mineshaftCorridor:5-2
rule7=0,100,minecraft:ladder-2
rule8=0,100,PFAAGeologica:weakStone-1
rule9=0,100,minecraft:planks-0
rule10=0,100,minecraft:stonebrick-0
rule11=0,100,minecraft:sand-1
rule12=0,100,IW:smalllightwhite-3
rule13=0,100,minecraft:gravel-0
rule14=0,100,IW:steelblock-0
rule15=0,100,ImmersiveEngineering:treatedWood-1
rule16=0,100,minecraft:jungle_stairs-1
rule17=0,100,PFAAGeologica:strongStoneBrickStairs.marble-1
rule18=0,100,minecraft:cauldron-0
rule19=0,100,minecraft:jungle_stairs-3
rule20=0,100,ImmersiveEngineering:metalDecoration-0
rule21=0,100,minecraft:jungle_stairs-2
rule22=0,100,IW:metaldoor-1
rule23=0,100,minecraft:jungle_stairs-0
rule24=0,100,minecraft:fence_gate-3
rule25=0,100,IW:computer1-0
rule26=0,100,minecraft:jukebox-0
rule27=0,100,minecraft:fence_gate-0
rule28=0,100,ChestGenHook:mineshaftCorridor:5-2
rule29=0,100,ChestGenHook:mineshaftCorridor:5-3
rule30=0,100,IW:metalhatch-2
rule31=0,100,minecraft:furnace-4
rule32=0,100,minecraft:cauldron-3
rule33=0,100,minecraft:oak_stairs-2
rule34=0,100,minecraft:glass_pane-0
rule35=0,100,minecraft:wooden_pressure_plate-0
rule36=0,100,IW:metaldoor-8
rule37=0,100,betterrecords:recordspeaker.sm-0
rule38=0,100,minecraft:stained_glass-15
rule39=0,100,IW:metaldoor-9
rule40=0,100,IW:smalllightwhite-1
rule41=2,100,WallSign:BEER#:MEATPIES#:JAMS#:null-2
rule42=0,100,IW:smalllightwhite-4
rule43=2,100,WallSign:#COLD:#HOT:#GOOD:null-2
rule44=2,100,WallSign:BEER: $3:SHOTS: $2:(mushroom vodka:$1)-2
rule45=0,100,IW:smalllightwhite-2
rule46=0,100,IW:scrapmetalsheet-0
rule47=0,100,IW:machinery1-0
rule48=0,100,IC2:blockGenerator-3

layer
1,1,1,1,1,1,1,1,1,1,1,1,1,1,1,1,1,1,1
1,1,1,1,1,1,1,1,1,1,1,1,1,1,1,1,1,1,1
1,1,1,1,1,1,1,1,1,1,1,1,1,1,1,1,1,1,1
1,1,1,1,1,1,1,1,1,1,1,1,1,1,1,1,1,1,1
1,1,1,1,1,1,1,1,1,1,1,1,1,1,1,1,1,1,1
1,1,1,1,1,1,1,1,1,1,1,1,1,1,1,1,1,1,1
1,1,1,1,1,1,1,1,1,1,1,1,1,1,1,1,1,1,1
1,1,1,1,1,1,1,1,1,1,1,1,1,1,1,1,1,1,1
1,1,1,1,1,1,1,1,1,1,1,1,1,1,1,1,1,1,1
1,1,1,1,1,1,1,1,1,1,1,1,1,1,1,1,1,1,1
1,1,1,1,1,1,1,1,1,1,1,1,1,1,1,1,1,1,1
1,1,1,1,1,1,1,1,1,1,1,1,1,1,1,1,1,1,1
1,1,1,1,1,1,1,1,1,1,1,1,1,1,1,1,1,1,1
1,1,1,1,1,1,1,1,1,1,1,1,1,1,1,1,1,1,1
1,1,1,1,1,1,1,1,1,1,1,1,1,1,1,1,1,1,1
1,1,1,1,1,1,1,1,1,1,1,1,1,1,1,1,1,1,1
endlayer

layer
1,1,1,1,1,1,1,1,1,1,1,1,1,1,1,1,1,1,1
1,1,1,1,1,1,1,1,1,1,1,1,1,1,1,1,1,1,1
1,1,1,1,1,1,1,1,1,1,1,1,1,1,1,1,1,1,1
1,1,1,1,1,1,1,1,1,1,1,1,1,1,1,1,1,1,1
1,1,1,1,1,1,1,1,1,1,1,1,1,1,1,1,1,1,1
1,1,1,1,1,1,1,1,1,1,1,1,1,1,1,1,1,1,1
1,1,1,1,1,1,1,1,1,1,1,1,1,1,1,1,1,1,1
1,1,1,1,1,1,1,1,1,1,1,1,1,1,1,1,1,1,1
1,1,1,1,1,1,1,1,1,1,1,1,1,1,1,1,1,1,1
1,1,1,1,1,1,1,1,1,1,1,1,1,1,1,1,1,1,1
1,1,1,1,1,1,1,1,1,1,1,1,1,1,1,1,1,1,1
1,1,1,1,1,1,1,1,1,1,1,1,1,1,1,1,1,1,1
1,1,1,1,1,1,1,1,1,1,1,1,1,1,1,1,1,1,1
1,1,1,1,1,1,1,1,1,1,1,1,1,1,1,1,1,1,1
1,1,1,1,1,1,1,1,1,1,1,1,1,1,1,1,1,1,1
1,1,1,1,1,1,1,1,1,1,1,1,1,1,1,1,1,1,1
endlayer

layer
2,2,2,2,2,2,2,2,2,2,2,2,2,2,2,2,2,2,2
2,2,2,2,2,2,2,2,2,2,2,2,2,2,2,2,2,2,2
2,2,2,2,2,2,2,2,2,2,2,2,2,2,2,2,2,2,2
2,2,2,2,2,2,2,2,2,2,2,2,2,2,2,2,2,2,2
2,2,2,2,2,2,2,2,2,2,2,2,2,2,2,2,2,2,2
2,2,2,2,2,2,2,2,2,2,2,2,2,2,2,2,2,2,2
2,2,2,2,2,2,2,2,2,2,2,2,2,2,2,2,2,2,2
2,2,2,2,2,2,2,2,2,2,2,2,2,2,2,2,2,2,2
2,2,2,2,2,2,2,2,2,2,2,2,2,2,2,2,2,2,2
2,2,2,2,2,2,2,2,2,2,2,2,2,2,2,2,2,2,2
2,2,2,2,2,2,2,2,2,2,2,2,2,2,2,2,2,2,2
2,2,2,2,2,2,2,2,2,2,2,2,2,2,2,2,2,2,2
2,2,2,2,2,2,2,2,2,2,2,2,2,2,2,2,2,2,2
2,2,2,2,2,2,2,2,2,2,2,2,2,2,2,2,2,2,2
2,2,2,2,2,2,2,2,2,2,2,2,2,2,2,2,2,2,2
2,2,2,2,2,2,2,2,2,2,2,2,2,2,2,2,2,2,2
endlayer

layer
2,2,2,2,2,2,2,2,2,2,2,2,2,2,2,2,2,2,2
2,2,2,2,2,2,2,2,2,2,2,2,2,2,2,2,2,2,2
2,2,2,2,2,2,2,2,2,2,2,2,2,2,2,2,2,2,2
2,2,2,2,2,2,2,2,2,2,2,2,2,2,2,2,2,2,2
2,2,2,2,2,2,2,2,2,2,2,2,2,2,2,2,2,2,2
2,2,2,2,2,2,2,2,2,2,2,2,2,2,2,2,2,2,2
2,2,2,2,2,2,2,2,2,2,2,2,2,2,2,2,2,2,2
2,2,2,2,2,2,2,2,2,2,2,2,2,2,2,2,2,2,2
2,2,2,2,2,2,2,2,2,2,2,2,2,2,2,2,2,2,2
2,2,2,2,2,2,2,2,2,2,2,2,2,2,2,2,2,2,2
2,2,2,2,2,2,2,2,2,2,2,2,2,2,2,2,2,2,2
2,2,2,2,2,2,5,5,6,5,5,4,3,2,2,2,2,2,2
2,2,2,2,2,2,7,0,0,0,0,0,0,2,2,2,2,2,2
2,2,2,2,2,2,2,2,2,2,2,2,2,2,2,2,2,2,2
2,2,2,2,2,2,2,2,2,2,2,2,2,2,2,2,2,2,2
2,2,2,2,2,2,2,2,2,2,2,2,2,2,2,2,2,2,2
endlayer

layer
8,8,8,8,8,8,8,8,8,8,8,8,8,8,8,8,8,8,8
8,8,8,8,8,8,8,8,8,8,8,8,8,8,8,8,8,8,8
8,8,8,8,8,8,8,8,8,8,8,8,8,8,8,8,8,8,8
8,8,8,8,8,8,8,8,8,8,8,8,8,8,8,8,8,8,8
8,8,8,8,8,8,8,8,8,8,8,8,8,8,8,8,8,8,8
8,8,8,8,8,8,8,8,8,8,8,8,8,8,8,8,8,8,8
8,8,8,8,8,8,8,8,8,8,8,8,8,8,8,8,8,8,8
8,8,8,8,8,8,8,8,8,8,8,8,8,8,8,8,8,8,8
8,8,8,8,8,8,8,8,8,8,8,8,8,8,8,8,8,8,8
8,8,8,8,8,8,8,8,8,8,8,8,8,8,8,8,8,8,8
8,8,8,8,8,8,9,8,8,8,8,8,8,8,8,8,8,8,8
8,8,8,8,8,8,5,5,0,5,5,0,0,8,8,8,8,8,8
8,8,8,8,8,8,7,0,0,0,0,0,0,8,8,8,8,8,8
8,8,8,8,8,8,8,8,8,8,8,8,8,8,8,8,8,8,8
8,10,8,8,8,8,8,8,8,8,8,8,8,8,8,8,8,8,8
8,8,8,8,8,8,8,8,8,8,8,8,8,8,8,8,8,8,8
endlayer

layer
11,11,11,11,11,11,11,11,11,11,11,11,11,11,11,11,11,11,11
11,11,11,11,11,11,11,11,11,11,11,11,11,11,11,11,11,11,11
11,11,11,11,11,11,11,11,11,11,11,11,11,11,11,11,11,11,11
11,11,11,11,11,11,11,11,11,11,11,11,11,11,11,11,11,11,11
11,11,11,11,11,11,11,11,11,11,11,11,11,11,11,11,11,11,11
11,11,11,11,11,11,11,11,11,11,11,11,11,11,11,11,11,11,11
11,11,11,11,11,11,11,11,11,11,11,11,11,11,11,11,11,11,11
11,11,11,11,11,11,11,11,11,11,11,11,11,11,11,11,11,11,11
11,11,11,11,11,11,11,11,11,11,11,11,11,11,11,11,11,11,11
11,11,11,11,11,11,11,11,11,11,11,11,11,11,11,11,11,11,11
11,11,11,11,11,9,9,9,9,9,9,9,9,9,11,11,11,11,11
11,11,11,11,11,9,0,0,0,0,0,0,0,9,11,11,11,11,11
11,11,11,11,11,9,7,0,0,0,0,0,12,9,11,11,11,11,11
11,11,11,11,11,9,9,9,9,9,9,9,9,9,11,11,11,11,11
11,10,11,11,11,11,11,11,11,11,11,11,11,11,11,11,11,11,11
11,11,11,11,11,11,11,11,11,11,11,11,11,11,11,11,11,11,11
endlayer

layer
11,11,11,11,11,11,11,11,11,11,11,11,11,11,11,11,11,11,11
11,10,10,10,10,10,10,10,10,10,10,10,10,10,10,10,10,10,11
11,10,10,10,10,10,10,10,10,10,10,10,10,10,10,10,10,10,11
11,10,10,10,10,10,10,10,10,10,10,10,10,10,10,10,10,10,11
11,10,10,10,10,10,10,10,10,10,10,10,10,10,10,10,10,10,11
11,10,10,10,10,10,10,10,10,10,10,10,10,10,10,10,10,10,11
11,10,10,10,10,10,10,10,10,10,10,10,10,10,10,10,10,10,13
11,10,10,10,10,10,10,10,10,10,10,10,10,10,10,10,10,10,13
11,10,10,10,10,10,10,10,10,10,10,10,10,10,10,10,10,10,13
11,10,10,10,10,10,10,10,10,10,10,10,10,10,10,10,10,10,13
11,10,10,10,10,10,10,10,10,10,10,10,10,10,10,10,10,10,11
11,10,10,10,10,10,10,10,10,10,10,10,10,10,10,10,10,10,11
11,10,10,10,10,10,7,10,10,10,10,10,10,10,10,10,10,10,11
11,10,10,10,10,10,10,10,10,10,10,10,10,10,10,10,10,10,11
11,10,10,10,10,10,10,10,10,10,10,10,10,10,10,10,10,10,11
11,11,11,11,11,11,11,11,11,11,11,11,11,11,11,11,11,11,11
endlayer

layer
0,0,0,0,0,0,0,0,0,0,0,0,0,0,0,0,0,0,0
0,0,0,0,0,0,0,0,0,0,0,0,0,0,0,0,0,0,0
0,0,14,15,15,15,15,15,15,15,15,15,15,15,15,15,14,0,0
0,0,15,18,17,9,0,0,0,0,0,16,0,0,16,0,15,0,0
0,0,15,0,0,22,0,0,16,0,21,20,0,16,20,19,15,0,0
0,0,15,5,5,9,5,24,5,0,0,23,0,0,23,0,15,0,0
0,0,15,9,9,15,26,0,25,0,0,0,0,0,0,0,14,0,0
0,0,15,28,0,27,0,0,5,19,0,0,0,0,0,0,22,0,0
0,0,15,29,0,9,0,0,5,0,0,0,0,0,0,0,22,0,0
0,0,15,5,0,9,0,0,5,19,0,0,0,0,0,0,14,0,0
0,0,15,5,0,9,0,0,5,0,0,16,0,0,16,0,15,0,0
0,0,15,0,0,9,0,0,5,19,0,20,19,0,20,0,15,0,0
0,0,15,32,31,9,30,0,5,0,0,0,0,0,23,0,15,0,0
0,0,14,15,15,15,15,15,15,15,15,15,15,15,15,15,14,0,0
0,0,0,0,0,0,0,0,14,33,0,0,0,0,0,0,0,0,0
0,0,0,0,0,0,0,0,0,0,0,0,0,0,0,0,0,0,0
endlayer

layer
0,0,0,0,0,0,0,0,0,0,0,0,0,0,0,0,0,0,0
0,0,0,0,0,0,0,0,0,0,0,0,0,0,0,0,0,0,0
0,0,14,15,15,15,15,15,34,15,15,34,15,15,34,15,14,0,0
0,0,15,0,0,9,0,0,0,0,0,0,0,0,0,0,15,0,0
0,0,15,0,0,36,0,0,0,0,0,35,0,0,35,0,34,0,0
0,0,15,0,0,9,37,0,0,0,0,0,0,0,0,0,15,0,0
0,0,15,9,9,15,0,0,38,0,0,0,0,0,0,0,14,0,0
0,0,15,0,0,0,0,0,0,0,0,0,0,0,0,0,39,0,0
0,0,15,0,0,9,0,0,0,0,0,0,0,0,0,0,36,0,0
0,0,15,5,0,9,0,0,0,0,0,0,0,0,0,0,14,0,0
0,0,15,5,0,0,0,0,0,0,0,0,0,0,0,0,15,0,0
0,0,15,0,0,0,0,0,0,0,0,35,0,0,35,0,34,0,0
0,0,15,0,0,9,0,0,0,0,0,0,0,0,0,0,15,0,0
0,0,14,15,15,15,15,15,34,15,15,34,15,15,34,15,14,0,0
0,0,0,0,0,0,0,14,33,0,0,0,0,0,0,0,0,0,0
0,0,0,0,0,0,0,0,0,0,0,0,0,0,0,0,0,0,0
endlayer

layer
0,0,0,0,0,0,0,0,0,0,0,0,0,0,0,0,0,0,0
0,0,0,0,0,0,0,0,0,0,0,0,0,0,0,0,0,0,0
0,0,14,15,15,15,15,15,34,15,15,34,15,15,34,15,14,0,0
0,0,15,0,12,9,40,0,0,0,0,0,0,0,0,40,15,0,0
0,0,15,0,0,9,0,0,0,0,0,0,0,0,0,0,34,0,0
0,0,15,0,12,9,0,0,0,0,0,0,0,0,0,0,15,0,0
0,0,15,9,9,15,0,0,0,0,0,0,0,0,0,12,14,0,0
0,0,15,42,0,9,42,0,0,0,0,0,0,0,0,0,5,41,0
0,0,15,0,0,9,0,0,0,0,0,0,0,0,0,0,5,43,0
0,0,15,0,0,9,0,0,0,0,0,0,0,0,0,12,14,0,0
0,0,15,0,0,9,0,0,0,0,0,0,0,0,0,0,15,0,0
0,0,15,0,0,9,44,0,0,0,0,0,0,0,0,0,34,0,0
0,0,15,42,0,9,45,0,0,0,0,0,0,0,0,45,15,0,0
0,0,14,15,15,15,15,15,34,15,15,34,15,15,34,15,14,0,0
0,0,0,0,0,0,14,33,0,0,0,0,0,0,0,0,0,0,0
0,0,0,0,0,0,0,0,0,0,0,0,0,0,0,0,0,0,0
endlayer

layer
0,0,0,0,0,0,0,0,0,0,0,0,0,0,0,0,0,0,0
0,0,0,0,0,0,0,0,0,0,0,0,0,0,0,0,0,0,0
0,0,14,14,14,14,14,14,14,14,14,14,14,14,14,14,14,0,0
0,0,14,46,46,46,46,46,46,46,46,46,46,46,46,46,14,0,0
0,0,14,46,46,46,46,46,46,46,46,46,46,46,46,46,14,0,0
0,0,14,46,46,46,46,46,46,46,46,46,47,46,46,46,14,0,0
0,0,14,46,46,46,46,46,46,46,46,46,46,46,46,46,14,0,0
0,0,14,46,46,46,46,46,46,46,46,46,46,46,46,46,14,0,0
0,0,14,46,46,46,46,46,46,46,46,46,46,46,46,46,14,0,0
0,0,14,46,46,46,46,46,46,46,46,46,46,46,46,46,14,0,0
0,0,14,46,46,46,46,46,46,46,46,46,47,46,46,46,14,0,0
0,0,14,47,46,46,46,46,46,46,46,46,46,46,46,46,14,0,0
0,0,14,46,46,46,46,46,46,46,46,46,46,46,46,46,14,0,0
0,0,14,14,14,14,14,14,14,14,14,14,14,14,14,14,14,0,0
0,0,0,0,0,14,33,0,0,0,0,0,0,0,0,0,0,0,0
0,0,0,0,0,0,0,0,0,0,0,0,0,0,0,0,0,0,0
endlayer

layer
0,0,0,0,0,0,0,0,0,0,0,0,0,0,0,0,0,0,0
0,0,0,0,0,0,0,0,0,0,0,0,0,0,0,0,0,0,0
0,0,14,46,46,46,46,46,46,46,46,46,46,46,46,46,14,0,0
0,0,46,0,0,0,0,0,0,0,0,0,0,0,0,0,46,0,0
0,0,46,0,0,0,0,0,0,0,0,0,0,0,0,0,46,0,0
0,0,46,0,0,0,0,0,0,0,0,0,0,0,0,0,46,0,0
0,0,46,0,0,0,0,0,0,0,0,0,0,0,0,0,46,0,0
0,0,46,0,48,0,0,0,0,0,0,0,0,0,0,0,46,0,0
0,0,46,0,48,0,0,0,0,0,0,0,0,0,0,0,46,0,0
0,0,46,0,0,0,0,0,0,0,0,0,0,0,0,0,46,0,0
0,0,46,0,0,0,0,0,0,0,0,0,0,0,0,0,46,0,0
0,0,46,0,0,0,0,0,0,0,0,0,0,0,0,0,46,0,0
0,0,46,0,0,0,0,0,0,0,0,0,0,0,0,0,46,0,0
0,0,14,46,14,0,14,46,46,46,46,46,46,46,46,46,14,0,0
0,0,0,0,0,0,0,0,0,0,0,0,0,0,0,0,0,0,0
0,0,0,0,0,0,0,0,0,0,0,0,0,0,0,0,0,0,0
endlayer

