
# Created by Ruins mod version 15.2 Ingame Parser
# authoring Player: Mensrea

weight=1
embed_into_distance=6
acceptable_target_blocks=
unacceptable_target_blocks=flowing_water,water,flowing_lava,lava
dimensions=7,13,16
allowable_overhang=0
max_leveling=2
leveling_buffer=0
preserve_water=0
preserve_lava=0
preventRotation=1

rule1=0,100,PFAAGeologica:mediumStone-0
rule2=0,100,minecraft:sand-1
rule3=0,100,IW:blood-0
rule4=0,100,minecraft:netherrack-0
rule5=0,100,minecraft:fire-15
rule6=0,100,Skull:1:6-1
rule7=0,100,Skull:1:5-1
rule8=0,100,Skull:1:12-1
rule9=0,100,Skull:1:13-1
rule10=0,100,Skull:0:5-1
rule11=0,100,Skull:0:10-1
rule12=0,100,Skull:0:14-1

layer
1,1,1,1,1,1,1,1,1,1,1,1,1,1,1,1
1,1,1,1,1,1,1,1,1,1,1,1,1,1,1,1
1,1,1,1,1,1,1,1,1,1,1,1,1,1,1,1
1,1,1,1,1,1,1,1,1,1,1,1,1,1,1,1
1,1,1,1,1,1,1,1,1,1,1,1,1,1,1,1
1,1,1,1,1,1,1,1,1,1,1,1,1,1,1,1
1,1,1,1,1,1,1,1,1,1,1,1,1,1,1,1
1,1,1,1,1,1,1,1,1,1,1,1,1,1,1,1
1,1,1,1,1,1,1,1,1,1,1,1,1,1,1,1
1,1,1,1,1,1,1,1,1,1,1,1,1,1,1,1
1,1,1,1,1,1,1,1,1,1,1,1,1,1,1,1
1,1,1,1,1,1,1,1,1,1,1,1,1,1,1,1
1,1,1,1,1,1,1,1,1,1,1,1,1,1,1,1
endlayer

layer
2,2,2,2,2,2,2,2,2,2,2,2,2,2,2,2
2,2,2,2,2,2,2,2,2,2,2,2,2,2,2,2
2,2,2,2,2,2,2,2,2,2,2,2,2,2,2,2
2,2,2,2,2,2,2,2,2,2,2,2,2,2,2,2
2,2,2,2,2,2,2,2,2,2,2,2,2,2,2,2
2,2,2,2,2,2,2,2,2,2,2,2,2,2,2,2
2,2,2,2,2,2,2,2,2,2,2,2,2,2,2,2
2,2,2,2,2,2,2,2,2,2,2,2,2,2,2,2
2,2,2,2,2,2,2,2,2,2,2,2,2,2,2,2
2,2,2,2,2,2,2,2,2,2,2,2,2,2,2,2
2,2,2,2,2,2,2,2,2,2,2,2,2,2,2,2
2,2,2,2,2,2,2,2,2,2,2,2,2,2,2,2
2,2,2,2,2,2,2,2,2,2,2,2,2,2,2,2
endlayer

layer
2,2,2,2,2,2,2,2,2,2,2,2,2,2,2,2
2,2,2,2,2,2,2,2,2,2,2,2,2,2,2,2
2,2,2,2,2,2,2,2,2,2,2,2,2,2,2,2
2,2,2,2,2,3,3,2,2,2,3,3,2,2,2,2
2,2,2,2,2,3,4,4,4,3,4,4,2,2,2,2
2,2,2,2,2,4,4,4,4,4,4,4,3,2,2,2
2,2,2,2,2,4,4,4,4,4,4,3,2,2,2,2
2,2,2,2,2,3,4,4,4,4,3,3,2,2,2,2
2,2,2,2,2,2,3,3,3,3,2,2,2,2,2,2
2,2,2,2,2,2,2,2,2,2,2,2,2,2,2,2
2,2,2,2,2,2,2,2,2,2,2,2,2,2,2,2
2,2,2,2,2,2,2,2,2,2,2,2,2,2,2,2
2,2,2,2,2,2,2,2,2,2,2,2,2,2,2,2
endlayer

layer
2,2,2,2,2,2,2,2,2,2,2,2,2,2,2,2
2,2,2,2,2,2,2,2,2,2,2,2,2,2,2,2
2,2,2,2,2,2,2,2,2,2,2,2,2,2,2,2
2,2,2,2,2,0,0,2,2,2,0,0,2,2,2,2
2,2,2,2,2,0,0,0,0,0,0,5,0,2,2,2
2,2,2,2,2,0,7,5,0,0,6,0,0,2,2,2
2,2,2,2,2,5,0,0,6,5,0,0,2,2,2,2
2,2,2,2,2,0,9,5,0,8,0,0,2,2,2,2
2,2,2,2,2,2,0,0,0,0,2,2,2,2,2,2
2,2,2,2,2,2,2,2,2,2,2,2,2,2,2,2
2,2,2,2,2,2,2,2,2,2,2,2,2,2,2,2
2,2,2,2,2,2,2,2,2,2,2,2,2,2,2,2
2,2,2,2,2,2,2,2,2,2,2,2,2,2,2,2
endlayer

layer
2,2,2,2,2,2,2,2,2,2,2,2,2,2,2,2
2,2,2,2,2,2,2,2,2,2,2,2,2,2,2,2
2,2,3,2,2,0,0,2,2,2,0,0,2,2,2,2
2,2,2,2,0,0,0,0,10,0,0,0,0,2,2,2
2,2,2,2,0,0,0,0,0,0,0,0,0,0,2,2
2,2,2,2,0,0,0,0,0,0,0,0,0,0,2,2
2,2,2,2,0,0,0,0,0,0,0,0,0,2,2,2
2,2,2,2,0,0,0,0,0,0,0,0,0,2,2,2
2,2,2,2,0,0,0,0,0,0,0,0,0,2,2,2
2,2,2,2,2,2,0,0,0,0,11,2,2,2,2,2
2,2,2,2,2,2,2,2,2,2,2,2,2,2,2,2
2,2,2,2,2,2,2,2,2,2,2,2,2,2,2,2
2,2,2,2,2,2,2,2,2,2,2,2,2,2,2,2
endlayer

layer
2,2,2,2,2,2,2,2,2,2,2,2,2,2,2,2
2,2,0,0,2,0,0,0,2,2,0,0,0,2,2,2
2,0,0,0,0,0,0,0,0,0,0,0,0,0,2,2
2,2,0,0,0,0,0,0,0,0,0,0,0,0,0,2
2,2,2,0,0,0,0,0,0,0,0,0,0,0,0,2
2,2,2,0,0,0,0,0,0,0,0,0,0,0,0,2
2,2,2,0,0,0,0,0,0,0,0,0,0,0,2,2
2,2,2,0,0,0,0,0,0,0,0,0,0,0,2,2
2,2,2,0,0,0,0,0,0,0,0,0,0,0,2,2
2,2,2,0,0,12,0,0,0,0,0,0,0,0,2,2
2,2,2,2,2,2,0,0,0,0,0,2,2,2,2,2
2,2,2,2,2,2,2,2,2,2,2,2,2,2,2,2
2,2,2,2,2,2,2,2,2,2,2,2,2,2,2,2
endlayer

layer
0,2,0,0,2,0,0,0,2,2,0,0,0,2,0,0
2,0,0,0,0,0,0,0,0,0,0,0,0,0,2,0
0,0,0,0,0,0,0,0,0,0,0,0,0,0,0,2
2,0,0,0,0,0,0,0,0,0,0,0,0,0,0,0
0,2,0,0,0,0,0,0,0,0,0,0,0,0,0,0
0,2,0,0,0,0,0,0,0,0,0,0,0,0,0,0
0,2,0,0,0,0,0,0,0,0,0,0,0,0,0,2
0,2,0,0,0,0,0,0,0,0,0,0,0,0,0,2
0,2,0,0,0,0,0,0,0,0,0,0,0,0,0,2
0,2,0,0,0,0,0,0,0,0,0,0,0,0,0,2
0,2,0,0,0,0,0,0,0,0,0,0,0,0,0,2
0,0,2,2,2,2,0,0,0,0,0,2,2,2,2,0
0,0,0,0,0,0,2,2,2,2,2,0,0,0,0,0
endlayer

