
# Created by Ruins mod version 15.3 Ingame Parser
# authoring Player: Mensrea

weight=8
embed_into_distance=7
acceptable_target_blocks=
unacceptable_target_blocks=flowing_water,water,flowing_lava,lava
dimensions=12,22,27
allowable_overhang=0
max_leveling=2
leveling_buffer=0
preserve_water=0
preserve_lava=0
preventRotation=1

rule1=0,100,PFAAGeologica:strongStone-7
rule2=0,100,IW:concrete-0
rule3=0,100,IW:steelsiding-0
rule4=0,100,minecraft:stonebrick-0
rule5=0,100,minecraft:mossy_cobblestone-0
rule6=0,100,IW:blood-0
rule7=0,100,PFAAGeologica:mediumStone-3
rule8=0,100,minecraft:furnace-5
rule9=0,100,minecraft:cauldron-3
rule10=0,100,IW:metalladder-5
rule11=0,100,IW:fiberboard-0
rule12=0,100,minecraft:spruce_stairs-1
rule13=0,100,ChestGenHook:strongholdCorridor:5-2
rule14=0,100,minecraft:spruce_stairs-3
rule15=0,100,minecraft:fence-0
rule16=0,100,IC2:blockGenerator-0
rule17=0,100,minecraft:spruce_stairs-2
rule18=0,100,ChestGenHook:mineshaftCorridor:5-2
rule19=0,100,IW:metaldoor-3
rule20=0,100,IW:metaldoor-1
rule21=0,100,ChestGenHook:mineshaftCorridor:5-2
rule22=0,100,PFAAGeologica:strongStoneBrickStairs.marble-0
rule23=0,100,ThermalExpansion:Workbench-1
rule24=0,100,minecraft:spruce_stairs-0
rule25=0,100,IW:metaldoor-0
rule26=0,100,minecraft:water-0
rule27=0,100,minecraft:bookshelf-0
rule28=0,100,IW:computer1-0
rule29=0,100,minecraft:bed-3
rule30=0,100,minecraft:bed-11
rule31=0,100,minecraft:stone_slab-0
rule32=0,100,minecraft:water-9
rule33=0,100,minecraft:wooden_pressure_plate-0
rule34=0,100,IW:metaldoor-8
rule35=0,100,minecraft:stained_glass-15
rule36=0,100,Skull:1:0-4
rule37=0,100,PFAAGeologica:weakStone-1
rule38=0,100,IW:smalllightwhite-1
rule39=0,100,minecraft:glass_pane-0
rule40=0,100,IW:smalllightwhite-3
rule41=0,100,IW:smalllightwhite-4
rule42=0,100,IW:smalllightwhite-2
rule43=0,100,minecraft:flower_pot-2
rule44=0,100,minecraft:water-1
rule45=0,100,minecraft:sand-1
rule46=0,100,minecraft:farmland-7
rule47=0,100,IW:lightwhite-0
rule48=0,100,PFAAGeologica:strongCobble-9
rule49=0,100,minecraft:flower_pot-1
rule50=0,100,AgriCraft:cropPotato-7
rule51=0,100,minecraft:flower_pot-0
rule52=0,100,minecraft:bed-9
rule53=2,100,WallSign:null:null:null:null-2
rule54=2,100,WallSign:null:null:null:null-3
rule55=0,100,minecraft:bed-1
rule56=0,100,minecraft:jukebox-0
rule57=0,100,minecraft:flower_pot-3
rule58=0,100,IInventory;minecraft:chest;AgriCraft:seedPotato#64#0#0+AgriCraft:seedCoffee#5#0#1+ThermalFoundation:tool.hoePlatinum#1#0#2+ThermalFoundation:tool.sicklePlatinum#1#0#3+minecraft:dye#45#15#4+AgriCraft:seedPotato#13#0#5+IC2:itemCellEmpty#64#12#6+minecraft:dirt#64#0#7+minecraft:dirt#6#0#8-2
rule59=0,100,minecraft:flower_pot-4
rule60=0,100,minecraft:flower_pot-6
rule61=0,100,minecraft:flower_pot-5
rule62=0,100,IW:metaldoor-2
rule63=0,100,IW:bush-0
rule64=0,100,IW:glassblack-0
rule65=0,100,minecraft:wooden_slab-0
rule66=0,100,IW:machinery1-0

layer
1,1,1,1,1,1,1,1,1,1,1,1,1,1,1,1,1,1,1,1,1,1,1,1,1,1,1
1,1,1,1,1,1,1,1,1,1,1,1,1,1,1,1,1,1,1,1,1,1,1,1,1,1,1
1,1,1,1,1,1,1,1,1,1,1,1,1,1,1,1,1,1,1,1,1,1,1,1,1,1,1
1,1,1,1,1,1,1,1,1,1,1,1,1,1,1,1,1,1,1,1,1,1,1,1,1,1,1
1,1,1,1,1,1,1,1,1,1,1,1,1,1,1,1,1,1,1,1,1,1,1,1,1,1,1
1,1,1,1,1,1,1,1,1,1,1,1,1,1,1,1,1,1,1,1,1,1,1,1,1,1,1
1,1,1,1,1,1,1,1,1,1,1,1,1,1,1,1,1,1,1,1,1,1,1,1,1,1,1
1,1,1,1,1,1,1,1,1,1,1,1,1,1,1,1,1,1,1,1,1,1,1,1,1,1,1
1,1,1,1,1,1,1,1,1,1,1,1,1,1,1,1,1,1,1,1,1,1,1,1,1,1,1
1,1,1,1,1,1,1,1,1,1,1,1,1,1,1,1,1,1,1,1,1,1,1,1,1,1,1
1,1,1,1,1,1,1,1,1,1,1,1,1,1,1,1,1,1,1,1,1,1,1,1,1,1,1
1,1,1,1,1,1,1,1,1,1,1,1,1,1,1,1,1,1,1,1,1,1,1,1,1,1,1
1,1,1,1,1,1,1,1,1,1,1,1,1,1,1,1,1,1,1,1,1,1,1,1,1,1,1
1,1,1,1,1,1,1,1,1,1,1,1,1,1,1,1,1,1,1,1,1,1,1,1,1,1,1
1,1,1,1,1,1,1,1,1,1,1,1,1,1,1,1,1,1,1,1,1,1,1,1,1,1,1
1,1,1,1,1,1,1,1,1,1,1,1,1,1,1,1,1,1,1,1,1,1,1,1,1,1,1
1,1,1,1,1,1,1,1,1,1,1,1,1,1,1,1,1,1,1,1,1,1,1,1,1,1,1
1,1,1,1,1,1,1,1,1,1,1,1,1,1,1,1,1,1,1,1,1,1,1,1,1,1,1
1,1,1,1,1,1,1,1,1,1,1,1,1,1,1,1,1,1,1,1,1,1,1,1,1,1,1
1,1,1,1,1,1,1,1,1,1,1,1,1,1,1,1,1,1,1,1,1,1,1,1,1,1,1
1,1,1,1,1,1,1,1,1,1,1,1,1,1,1,1,1,1,1,1,1,1,1,1,1,1,1
1,1,1,1,1,1,1,1,1,1,1,1,1,1,1,1,1,1,1,1,1,1,1,1,1,1,1
endlayer

layer
1,1,1,1,1,1,1,1,1,1,1,1,1,1,1,1,1,1,1,1,1,1,1,1,1,1,1
1,1,1,1,1,1,1,1,1,1,1,1,1,1,1,1,1,1,1,1,1,1,1,1,1,1,1
1,1,1,1,1,1,1,1,1,1,1,1,1,1,1,1,1,1,1,1,1,1,1,1,1,1,1
1,1,1,1,1,1,2,2,2,2,2,1,1,1,1,1,1,1,1,1,1,1,1,1,1,1,1
1,1,1,1,2,2,2,2,2,2,2,2,3,1,1,1,1,1,1,1,1,1,1,1,1,1,1
1,1,1,1,2,2,2,2,2,2,2,2,3,1,1,1,1,1,1,1,1,1,1,1,1,1,1
1,1,1,2,2,2,2,2,2,2,2,2,2,2,1,1,1,1,1,1,1,1,1,1,1,1,1
1,1,1,2,2,2,2,2,2,2,2,2,2,2,2,0,0,0,0,0,0,0,0,0,1,1,1
1,1,1,2,2,2,2,2,2,2,2,2,2,2,1,1,1,1,1,0,0,0,0,0,1,1,1
1,1,1,2,2,2,2,2,2,2,2,2,2,2,1,1,1,4,4,4,4,4,4,4,4,1,1
1,1,1,2,2,2,2,2,2,2,2,2,2,2,1,1,1,4,4,4,4,4,4,4,4,1,1
1,1,1,1,2,2,2,2,2,2,2,2,2,1,1,1,1,4,4,4,4,4,4,4,4,1,1
1,1,1,1,2,2,2,2,2,2,2,2,2,1,1,1,1,4,4,4,4,4,4,4,4,1,1
1,1,1,1,1,1,2,2,2,2,2,1,1,1,1,1,1,4,4,4,4,4,4,4,4,1,1
1,1,1,1,1,1,1,1,5,1,1,1,1,1,1,1,1,4,4,4,4,4,4,4,4,1,1
1,1,1,1,1,1,1,5,5,5,1,1,1,1,1,1,1,4,4,4,4,4,4,4,4,1,1
1,1,1,1,1,1,1,6,6,6,1,1,1,1,1,1,1,4,4,4,4,4,4,4,4,1,1
1,1,1,1,1,1,1,5,5,5,1,1,1,1,1,1,1,1,1,1,1,1,4,4,4,1,1
1,1,1,1,1,1,1,1,1,1,1,1,1,1,1,1,1,1,1,1,1,1,4,4,4,1,1
1,1,1,1,1,1,1,1,1,1,1,1,1,1,1,1,1,1,1,1,1,1,4,4,4,1,1
1,1,1,1,1,1,1,1,1,1,1,1,1,1,1,1,1,1,1,1,1,1,1,1,1,1,1
1,1,1,1,1,1,1,1,1,1,1,1,1,1,1,1,1,1,1,1,1,1,1,1,1,1,1
endlayer

layer
7,7,7,7,7,7,7,7,7,7,7,7,7,7,7,7,7,7,7,7,7,7,7,7,7,7,7
7,7,7,7,7,7,7,7,7,7,7,7,7,7,7,7,7,7,7,7,7,7,7,7,7,7,7
7,7,7,7,7,7,2,2,2,2,2,7,7,7,7,7,7,7,7,7,7,7,7,7,7,7,7
7,7,7,7,2,2,3,3,10,9,8,2,2,7,7,7,7,7,7,7,7,7,7,7,7,7,7
7,7,7,2,13,0,12,0,0,0,0,11,0,2,7,7,7,7,7,7,7,7,7,7,7,7,7
7,7,7,2,16,11,0,15,14,0,0,11,0,2,7,7,7,7,7,7,7,7,7,7,7,7,7
7,7,2,18,0,11,17,0,0,0,0,11,0,3,2,7,7,7,7,7,7,7,7,7,7,7,7
7,7,2,21,0,20,0,0,0,0,0,19,0,0,2,0,0,0,0,0,0,0,0,0,7,7,7
7,7,2,3,3,11,3,24,0,24,23,11,22,3,2,7,7,7,7,0,0,0,0,0,7,7,7
7,7,2,11,11,11,11,11,25,11,11,11,11,11,2,7,7,4,4,4,4,4,4,4,4,7,7
7,7,2,27,0,27,28,27,0,0,0,0,0,27,2,7,7,4,26,26,26,26,26,26,4,7,7
7,7,7,2,17,0,0,0,0,0,29,29,0,2,7,7,7,4,26,26,26,26,26,26,4,7,7
7,7,7,2,15,24,24,0,0,0,30,30,0,2,7,7,7,4,26,26,26,26,26,26,4,7,7
7,7,7,7,2,2,3,27,27,27,3,2,2,7,7,7,7,4,26,26,26,26,26,26,4,7,7
7,7,7,7,7,7,2,2,0,2,2,7,7,7,7,7,7,4,26,26,26,26,26,26,4,7,7
7,7,7,7,7,7,5,0,0,0,5,7,7,7,7,7,7,4,26,26,26,26,26,26,4,7,7
7,7,7,7,7,7,5,0,31,0,5,7,7,7,7,7,7,4,4,4,4,4,4,26,4,7,7
7,7,7,7,7,7,5,31,31,31,5,7,7,7,7,7,7,7,7,7,7,7,4,26,4,7,7
7,7,7,7,7,7,7,5,5,5,7,7,7,7,7,7,7,7,7,7,7,7,4,32,4,7,7
7,7,7,7,7,7,7,7,7,7,7,7,7,7,7,7,7,7,7,7,7,7,4,4,4,7,7
7,7,7,7,7,7,7,7,7,7,7,7,7,7,7,7,7,7,7,7,7,7,7,7,7,7,7
7,7,7,7,7,7,7,7,7,7,7,7,7,7,7,7,7,7,7,7,7,7,7,7,7,7,7
endlayer

layer
7,7,7,7,7,7,7,7,7,7,7,7,7,7,7,7,7,7,7,7,7,7,7,7,7,7,7
7,7,7,7,7,7,7,7,7,7,7,7,7,7,7,7,7,7,7,7,7,7,7,7,7,7,7
7,7,7,7,7,7,2,2,2,2,2,7,7,7,7,7,7,7,7,7,7,7,7,7,7,7,7
7,7,7,7,2,2,0,0,10,0,0,2,2,7,7,7,7,7,7,7,7,7,7,7,7,7,7
7,7,7,2,0,11,0,0,0,0,0,11,0,2,7,7,7,7,7,7,7,7,7,7,7,7,7
7,7,7,2,3,11,0,33,0,0,0,11,0,2,7,7,7,7,7,7,7,4,7,7,7,7,7
7,7,2,0,0,11,0,0,0,0,0,11,0,3,2,7,7,7,7,7,7,4,7,7,7,7,7
7,7,2,0,0,34,0,0,0,0,0,34,0,0,2,0,0,0,0,0,0,4,0,0,7,7,7
7,7,2,3,3,11,3,0,0,0,0,11,0,0,2,7,7,7,7,0,0,4,0,0,7,7,7
7,7,2,11,11,11,11,11,34,11,11,11,11,11,2,7,7,4,4,4,4,4,4,4,4,7,7
7,7,2,27,0,0,35,0,0,0,0,0,0,27,2,7,7,4,26,26,26,26,26,26,4,7,7
7,7,7,2,0,0,0,0,0,0,0,0,0,2,7,7,7,4,26,26,26,26,26,26,4,7,7
7,7,7,2,33,0,0,0,0,0,0,0,0,2,7,7,7,4,26,26,26,26,26,26,4,7,7
7,7,7,7,2,2,3,27,27,27,3,2,2,7,7,7,7,4,26,26,26,26,26,26,4,7,7
7,7,7,7,7,7,2,2,0,2,2,7,7,7,7,7,7,4,26,26,26,26,26,26,4,7,7
7,7,7,7,7,7,5,0,0,0,5,7,7,7,7,7,7,4,26,26,26,26,26,26,4,7,7
7,7,7,7,7,7,5,0,0,0,5,7,7,7,7,7,7,4,4,4,4,4,4,26,4,7,7
7,7,7,7,7,7,5,36,36,36,5,7,7,7,7,7,7,7,7,7,7,7,4,26,4,7,7
7,7,7,7,7,7,7,5,5,5,7,7,7,7,7,7,7,7,7,7,7,7,4,32,4,7,7
7,7,7,7,7,7,7,7,7,7,7,7,7,7,7,7,7,7,7,7,7,7,4,4,4,7,7
7,7,7,7,7,7,7,7,7,7,7,7,7,7,7,7,7,7,7,7,7,7,7,7,7,7,7
7,7,7,7,7,7,7,7,7,7,7,7,7,7,7,7,7,7,7,7,7,7,7,7,7,7,7
endlayer

layer
37,37,37,37,37,37,37,37,37,37,37,37,37,37,37,37,37,37,37,37,37,37,37,37,37,37,37
37,37,37,37,37,37,37,37,37,37,37,37,37,37,37,37,37,37,37,37,37,37,37,37,37,37,37
37,37,37,37,37,37,2,2,2,2,2,37,37,37,37,37,37,37,37,37,37,37,37,37,37,37,37
37,37,37,37,2,2,38,0,10,0,38,2,2,37,37,37,37,37,37,37,37,37,37,37,37,37,37
37,37,37,2,0,11,0,0,0,0,0,11,3,2,37,37,37,37,37,37,37,4,37,37,37,37,37
37,37,37,2,3,11,0,0,0,0,0,11,39,2,37,37,37,37,37,37,4,26,4,37,37,37,37
37,37,2,0,0,11,0,0,0,0,0,11,0,0,2,37,37,37,37,37,4,26,4,37,37,37,37
37,37,2,41,0,15,0,0,0,0,0,15,0,40,2,0,0,0,0,0,4,26,4,0,37,37,37
37,37,2,0,0,11,0,0,0,0,0,11,0,0,2,37,37,37,37,0,4,26,4,0,37,37,37
37,37,2,11,11,11,11,11,15,11,11,11,11,11,2,37,37,4,4,4,4,26,4,4,4,37,37
37,37,2,0,0,0,0,0,0,0,0,0,0,0,2,37,37,4,26,26,26,26,26,26,4,37,37
37,37,37,2,0,0,0,0,0,0,0,0,0,2,37,37,37,4,26,26,26,26,26,26,4,37,37
37,37,37,2,0,42,0,0,0,0,0,42,0,2,37,37,37,4,26,26,26,26,26,26,4,37,37
37,37,37,37,2,2,0,43,0,0,0,2,2,37,37,37,37,4,26,26,26,26,26,26,4,37,37
37,37,37,37,37,37,2,2,2,2,2,37,37,37,37,37,37,4,26,26,26,26,26,26,4,37,37
37,37,37,37,37,37,5,0,0,0,5,37,37,37,37,37,37,4,26,26,26,26,26,26,4,37,37
37,37,37,37,37,37,5,0,0,0,5,37,37,37,37,37,37,4,4,4,4,4,4,26,4,37,37
37,37,37,37,37,37,5,36,36,36,5,37,37,37,37,37,37,37,37,37,37,37,4,26,4,37,37
37,37,37,37,37,37,37,5,5,5,37,37,37,37,37,37,37,37,37,37,37,37,4,44,4,37,37
37,37,37,37,37,37,37,37,37,37,37,37,37,37,37,37,37,37,37,37,37,37,4,4,4,37,37
37,37,37,37,37,37,37,37,37,37,37,37,37,37,37,37,37,37,37,37,37,37,37,37,37,37,37
37,37,37,37,37,37,37,37,37,37,37,37,37,37,37,37,37,37,37,37,37,37,37,37,37,37,37
endlayer

layer
45,45,45,45,45,45,45,45,45,45,45,45,45,45,45,45,45,45,45,45,45,45,45,45,45,45,45
45,45,45,45,45,45,45,45,45,45,45,45,45,45,45,45,45,2,2,2,2,2,2,2,2,2,45
45,45,45,45,45,45,2,2,2,2,2,45,45,45,45,45,45,2,2,2,2,2,2,2,2,2,45
45,45,45,45,2,2,2,2,10,2,2,2,2,45,45,45,45,2,2,46,46,46,46,46,2,2,45
45,45,45,2,2,2,2,2,2,2,2,2,2,2,45,45,45,2,2,46,46,46,46,46,2,2,45
45,45,45,2,2,2,2,2,2,2,2,2,2,2,45,45,45,2,2,46,46,26,46,46,2,2,45
45,45,2,2,2,2,2,2,2,2,2,2,2,2,2,45,45,2,2,46,46,46,46,46,2,2,45
45,45,2,2,2,2,2,2,2,2,2,2,2,2,2,2,2,2,2,46,46,46,46,46,2,2,45
45,45,2,2,2,2,2,2,47,2,2,2,2,2,2,2,2,2,2,46,46,46,46,46,2,2,45
45,45,2,2,2,2,2,2,2,2,2,2,2,2,2,2,2,2,2,46,46,46,46,46,2,2,45
45,45,2,2,2,2,2,2,2,2,2,2,2,2,2,45,45,2,2,46,46,26,46,46,2,2,45
45,45,45,2,2,2,2,2,2,2,2,2,2,2,45,45,45,2,2,46,46,46,46,46,2,2,45
45,45,45,2,2,2,2,2,2,2,2,2,2,2,45,45,45,2,2,46,46,46,46,46,2,2,45
45,45,45,45,2,2,2,2,2,2,2,2,2,45,45,45,45,2,2,2,2,2,2,2,2,2,45
45,45,45,45,45,45,2,2,2,2,2,45,45,45,45,45,45,2,2,2,2,2,2,2,2,2,45
45,45,45,45,45,45,45,48,48,48,45,45,45,45,45,45,45,4,4,4,4,4,4,4,4,45,45
45,45,45,45,45,45,48,48,48,48,48,45,45,45,45,45,45,4,4,4,4,4,4,4,4,45,45
45,45,45,45,45,45,48,48,48,48,48,45,45,45,45,45,45,45,45,45,45,45,4,4,4,45,45
45,45,45,45,45,45,45,48,48,48,45,45,45,45,45,45,45,45,45,45,45,45,4,0,4,45,45
45,45,45,45,45,45,45,45,45,45,45,45,45,45,45,45,45,45,45,45,45,45,4,4,4,45,45
45,45,45,45,45,45,45,45,45,45,45,45,45,45,45,45,45,45,45,45,45,45,45,45,45,45,45
45,45,45,45,45,45,45,45,45,45,45,45,45,45,45,45,45,45,45,45,45,45,45,45,45,45,45
endlayer

layer
45,45,45,45,45,45,45,45,45,45,45,45,45,45,45,45,45,45,45,45,45,45,45,45,45,45,45
45,45,45,45,45,45,45,45,45,45,45,45,45,45,45,45,45,2,2,2,2,2,2,2,2,2,45
45,45,45,45,45,45,2,2,2,2,2,45,45,45,45,45,45,2,0,0,0,0,0,0,49,2,45
45,45,45,45,2,2,11,0,10,0,0,2,2,45,45,45,45,2,0,50,50,50,50,50,0,2,45
45,45,45,2,27,52,11,0,0,0,0,0,0,2,45,45,45,2,51,50,50,50,50,50,0,2,45
45,45,45,2,0,55,11,0,0,54,12,53,0,2,45,45,45,2,0,50,50,47,50,50,0,2,45
45,45,2,27,0,0,11,0,56,0,0,0,0,0,2,45,45,2,0,50,50,50,50,50,0,2,45
45,45,2,28,14,0,11,0,17,0,0,3,0,0,2,2,2,2,58,50,50,50,50,50,57,2,45
45,45,2,0,0,0,20,0,17,15,0,28,0,0,19,0,0,0,0,50,50,50,50,50,0,2,45
45,45,2,3,0,0,11,0,17,0,0,3,0,0,2,2,2,2,0,50,50,50,50,50,0,2,45
45,45,2,27,12,0,11,0,27,0,0,0,0,0,2,45,45,2,0,50,50,47,50,50,59,2,45
45,45,45,2,15,29,11,0,0,54,24,53,0,2,45,45,45,2,60,50,50,50,50,50,0,2,45
45,45,45,2,27,30,11,0,0,0,0,0,0,2,45,45,45,2,0,50,50,50,50,50,0,2,45
45,45,45,45,2,2,11,0,0,0,0,2,2,45,45,45,45,2,0,0,0,61,0,0,0,2,45
45,45,45,45,45,45,2,2,62,2,2,45,45,45,45,45,45,2,2,2,2,2,2,2,2,2,45
45,45,45,45,45,45,45,48,0,48,45,45,45,45,45,45,45,45,45,45,45,45,45,45,45,45,45
45,45,45,45,45,45,45,0,0,45,45,45,45,0,0,45,45,45,45,45,45,45,45,45,45,45,45
45,45,45,45,45,45,45,0,45,45,45,45,0,0,0,0,45,45,45,45,45,45,4,4,4,0,0
45,45,45,45,45,45,45,45,45,45,45,0,0,0,0,0,0,0,0,0,0,45,4,0,4,0,0
45,45,45,45,45,45,45,45,45,45,0,0,0,0,63,0,0,0,0,0,0,45,4,4,4,0,0
45,45,45,45,45,45,45,45,45,45,45,0,0,0,0,0,0,0,0,0,0,0,0,0,0,0,45
45,45,45,45,45,45,45,45,45,45,45,45,0,0,0,45,45,45,45,45,45,45,45,45,45,45,45
endlayer

layer
0,0,0,0,0,45,45,45,45,45,0,0,0,0,0,0,0,45,45,45,45,45,45,45,45,45,0
0,0,45,45,45,45,45,45,45,45,45,0,0,0,0,0,45,2,2,2,2,2,2,2,2,2,45
0,45,45,45,45,45,45,2,2,2,45,45,0,0,63,0,45,2,0,0,0,0,0,0,0,2,45
0,45,45,45,45,2,2,0,10,0,2,2,45,0,0,0,45,2,0,0,0,0,0,0,0,2,45
0,0,45,45,2,0,11,0,0,0,0,0,2,45,0,0,45,2,0,0,0,0,0,0,0,2,45
0,0,45,2,0,0,11,0,0,0,0,0,0,2,45,0,45,2,0,0,0,0,0,0,0,2,45
0,0,45,2,0,0,11,0,0,0,0,0,0,2,45,45,45,2,0,0,0,0,0,0,0,2,45
0,45,2,35,0,0,11,0,0,0,0,35,0,0,2,2,2,2,0,0,0,0,0,0,0,2,45
0,45,2,0,0,0,34,0,0,33,0,35,0,0,34,0,0,0,0,0,0,0,0,0,0,2,45
0,45,2,3,0,0,11,0,0,0,0,35,0,0,2,2,2,2,0,0,0,0,0,0,0,2,45
0,0,45,2,0,0,11,0,51,0,0,0,0,2,45,45,45,2,0,0,0,0,0,0,0,2,45
0,0,45,2,33,0,11,0,0,0,0,0,0,2,45,0,45,2,0,0,0,0,0,0,0,2,45
0,0,45,45,2,0,11,0,0,0,0,0,2,45,0,0,45,2,0,0,0,0,0,0,0,2,45
0,0,0,45,45,2,2,0,0,0,2,2,45,45,0,0,45,2,0,0,0,0,0,0,0,2,45
0,45,0,0,45,45,45,2,34,2,45,45,45,0,0,0,45,2,2,2,2,2,2,2,2,2,45
45,45,45,0,0,0,0,48,0,48,45,0,0,0,63,0,45,45,45,45,45,45,45,45,45,45,0
45,45,45,45,45,0,0,0,0,45,0,0,0,0,0,0,0,45,45,45,45,45,45,45,45,0,63
45,45,45,45,45,45,0,0,0,0,0,0,0,0,0,0,0,0,0,0,0,0,0,0,0,0,0
45,45,45,45,45,45,0,0,0,0,0,0,0,0,0,0,0,0,0,0,0,0,15,0,15,0,0
45,45,45,45,45,45,0,0,0,0,0,0,0,0,0,0,0,0,0,0,0,0,0,0,0,0,0
0,45,45,45,45,45,0,0,0,0,0,0,0,0,0,0,0,0,0,0,0,0,0,0,0,0,0
0,0,45,45,45,0,0,0,63,0,0,0,0,0,0,0,0,0,0,0,0,0,0,0,0,0,0
endlayer

layer
0,0,0,0,0,0,0,0,0,0,0,0,0,0,0,0,0,0,0,0,0,0,0,0,0,0,0
0,0,0,0,0,45,45,45,45,45,0,0,0,0,0,0,0,2,2,2,2,2,2,2,2,2,0
0,0,45,45,45,45,45,45,45,45,45,0,0,0,0,0,0,64,0,0,0,0,0,0,0,64,0
0,0,45,45,45,45,2,2,2,2,2,45,45,0,0,0,0,64,0,0,0,0,0,0,0,64,0
0,0,0,45,2,2,11,0,0,0,0,2,2,45,0,0,0,64,0,0,0,0,0,0,0,64,0
0,0,0,45,2,38,11,0,0,0,0,40,2,45,0,0,0,64,0,0,0,0,0,0,0,64,0
0,0,45,2,0,0,11,0,0,0,0,0,0,2,45,0,0,64,0,0,0,0,0,0,0,64,0
0,63,45,2,0,0,11,0,0,0,0,35,0,2,45,45,45,64,0,0,0,0,0,0,0,64,0
0,0,45,2,0,0,15,0,0,0,0,35,0,0,2,2,2,64,0,0,0,0,0,0,0,64,0
0,0,45,2,0,0,11,0,0,0,0,35,0,2,45,45,45,64,0,0,0,0,0,0,0,64,0
0,0,45,2,0,0,11,0,0,0,0,0,0,2,45,0,0,64,0,0,0,0,0,0,0,64,0
0,0,0,45,2,42,11,0,0,0,0,40,2,45,0,0,0,64,0,0,0,0,0,0,0,64,0
0,0,0,45,2,2,11,0,0,0,0,2,2,45,0,0,0,64,0,0,0,0,0,0,0,64,0
0,0,0,0,45,45,2,2,0,2,2,45,45,0,0,0,0,64,0,0,0,0,0,0,0,64,0
0,0,0,0,0,0,45,45,2,45,45,0,0,0,0,0,0,2,2,2,2,2,2,2,2,2,0
0,0,0,0,0,0,0,45,48,45,0,0,0,0,0,0,0,45,45,45,45,45,45,45,45,45,0
0,45,0,0,0,0,0,0,0,0,0,0,0,0,0,0,0,0,0,0,0,0,0,0,0,0,0
0,45,45,45,0,0,0,0,0,0,0,0,0,0,0,0,0,0,0,0,0,0,0,0,0,0,0
0,45,45,45,45,0,0,0,0,0,0,0,0,0,0,0,0,0,0,0,0,0,65,65,65,0,0
0,0,45,45,45,0,0,0,0,0,0,0,0,0,0,0,0,0,0,0,0,0,0,0,0,0,0
0,0,0,45,0,0,0,0,0,0,0,0,0,0,0,0,0,0,0,0,0,0,0,0,0,0,0
0,0,0,0,0,0,0,0,0,0,0,0,0,0,0,0,0,0,0,0,0,0,0,0,0,0,0
endlayer

layer
0,0,0,0,0,0,0,0,0,0,0,0,0,0,0,0,0,0,0,0,0,0,0,0,0,0,0
0,0,0,0,0,0,0,0,0,0,0,0,0,0,0,0,0,0,2,2,2,2,2,2,2,0,0
0,0,63,0,0,45,45,45,45,45,0,0,0,0,0,0,0,0,64,64,64,64,64,64,64,0,0
0,0,0,45,45,45,45,2,2,2,45,45,0,0,0,0,0,0,64,64,64,64,64,64,64,0,0
0,0,0,0,45,2,2,0,0,0,2,2,45,0,0,0,0,0,64,64,64,64,64,64,64,0,0
0,0,0,45,2,2,11,0,0,0,0,2,2,45,0,0,0,0,64,64,64,64,64,64,64,0,0
0,0,0,45,2,0,11,0,0,0,0,0,2,45,0,0,0,0,64,64,64,64,64,64,64,0,0
0,0,45,2,0,0,11,0,0,0,0,0,0,2,45,0,0,0,64,64,64,64,64,64,64,0,0
0,0,45,2,0,0,11,0,0,0,0,0,0,2,45,45,0,0,64,64,64,64,64,64,64,0,0
0,0,45,2,0,0,11,0,0,0,0,0,0,2,45,0,0,0,64,64,64,64,64,64,64,0,0
0,0,0,45,2,0,11,0,0,0,0,0,2,45,0,0,0,0,64,64,64,64,64,64,64,0,0
0,0,0,45,2,2,11,0,0,0,0,2,2,45,0,0,0,0,64,64,64,64,64,64,64,0,0
0,0,0,0,45,2,2,0,0,0,2,2,45,0,0,0,0,0,64,64,64,64,64,64,64,0,0
0,0,0,0,0,45,45,2,2,2,45,45,0,0,0,0,0,0,64,64,64,64,64,64,64,0,0
0,0,0,0,0,0,0,45,45,45,0,0,0,0,0,0,0,0,2,2,2,2,2,2,2,0,0
0,0,0,0,0,0,0,0,0,0,0,0,0,0,0,0,0,0,0,0,0,0,0,0,0,63,0
0,0,0,0,0,0,0,0,0,0,0,0,0,0,0,0,0,0,0,0,0,0,0,0,0,0,0
0,0,0,0,0,0,0,0,0,0,0,0,0,0,0,0,0,0,0,0,0,0,0,0,0,0,0
0,0,0,63,0,0,0,0,0,0,0,0,0,0,0,0,0,0,0,0,0,0,0,0,0,0,0
0,0,0,0,0,0,0,0,0,0,0,0,0,0,0,0,0,0,0,0,0,0,0,0,0,0,0
0,0,0,0,0,0,0,0,0,0,0,0,0,0,0,0,0,0,0,0,0,0,0,0,0,0,0
0,0,0,0,0,0,0,0,0,0,0,0,0,0,0,0,0,0,0,0,0,0,0,0,0,0,0
endlayer

layer
0,0,0,0,0,0,0,0,0,0,0,0,0,0,0,0,0,0,0,0,0,0,0,0,0,0,0
0,0,0,0,0,0,0,0,0,0,0,0,0,0,0,0,0,0,0,0,0,0,0,0,0,0,0
0,0,0,0,0,0,0,0,63,0,0,0,0,0,0,0,0,0,0,0,0,0,0,0,0,0,0
0,0,0,0,0,45,45,45,45,45,0,0,0,0,0,0,0,0,0,0,0,0,0,0,0,0,0
0,0,0,0,0,45,45,2,2,2,45,45,0,0,0,0,0,0,0,0,0,0,0,0,0,0,0
0,0,0,0,45,45,2,2,66,2,2,45,45,0,0,0,0,0,0,0,0,0,0,0,0,0,0
0,0,0,0,45,2,2,64,64,64,2,2,45,0,0,0,0,0,0,0,0,0,0,0,0,0,0
0,0,0,45,2,2,64,64,64,64,64,2,2,45,63,0,0,0,0,0,0,0,0,0,0,0,0
0,0,0,45,2,2,64,64,64,64,64,2,2,45,0,0,0,0,0,0,0,0,0,0,0,0,0
0,0,0,45,2,2,64,64,64,64,64,2,2,45,0,0,0,0,0,0,0,0,0,0,0,0,0
0,0,0,0,45,2,2,64,64,64,2,2,45,0,0,0,0,0,0,0,0,0,0,0,0,0,0
0,0,0,0,45,45,2,2,66,2,2,45,45,0,0,0,0,0,0,0,0,0,0,0,0,0,0
0,0,0,0,0,45,45,2,2,2,45,45,0,0,0,0,0,0,0,0,0,0,0,0,0,0,0
0,0,0,0,0,0,0,45,45,45,0,63,0,0,0,0,0,0,0,0,0,0,0,0,0,0,0
0,0,0,0,0,0,0,0,0,0,0,0,0,0,0,0,0,0,0,0,0,0,0,0,0,0,0
0,0,0,0,0,0,0,0,0,0,0,0,0,0,0,0,0,0,0,0,0,0,0,0,0,0,0
0,0,0,0,0,0,0,0,0,0,0,0,0,0,0,0,0,0,0,0,0,0,0,0,0,0,0
0,0,0,0,0,0,0,0,0,0,0,0,0,0,0,0,0,0,0,0,0,0,0,0,0,0,0
0,0,0,0,0,0,0,0,0,0,0,0,0,0,0,0,0,0,0,0,0,0,0,0,0,0,0
0,0,0,0,0,0,0,0,0,0,0,0,0,0,0,0,0,0,0,0,0,0,0,0,0,0,0
0,0,0,0,0,0,0,0,0,0,0,0,0,0,0,0,0,0,0,0,0,0,0,0,0,0,0
0,0,0,0,0,0,0,0,0,0,0,0,0,0,0,0,0,0,0,0,0,0,0,0,0,0,0
endlayer

layer
0,0,0,0,0,0,0,0,0,0,0,0,0,0,0,0,0,0,0,0,0,0,0,0,0,0,0
0,0,0,0,0,0,0,0,0,0,0,0,0,0,0,0,0,0,0,0,0,0,0,0,0,0,0
0,0,0,0,0,0,0,0,0,0,0,0,0,0,0,0,0,0,0,0,0,0,0,0,0,0,0
0,0,0,0,0,0,0,0,0,0,0,0,0,0,0,0,0,0,0,0,0,0,0,0,0,0,0
0,0,0,0,0,0,0,0,0,0,0,63,0,0,0,0,0,0,0,0,0,0,0,0,0,0,0
0,0,0,0,63,0,0,0,0,0,45,0,0,0,0,0,0,0,0,0,0,0,0,0,0,0,0
0,0,0,0,0,45,0,0,0,45,45,0,0,0,0,0,0,0,0,0,0,0,0,0,0,0,0
0,0,0,0,45,45,0,0,45,45,45,45,0,0,0,0,0,0,0,0,0,0,0,0,0,0,0
0,0,0,0,45,45,45,0,0,45,45,45,0,0,0,0,0,0,0,0,0,0,0,0,0,0,0
0,0,0,0,0,45,45,45,0,0,45,0,0,0,0,0,0,0,0,0,0,0,0,0,0,0,0
0,0,0,0,0,0,45,45,45,45,0,0,0,0,0,0,0,0,0,0,0,0,0,0,0,0,0
0,0,0,0,63,0,45,0,0,45,45,0,0,0,0,0,0,0,0,0,0,0,0,0,0,0,0
0,0,0,0,0,0,0,0,0,45,0,0,0,0,0,0,0,0,0,0,0,0,0,0,0,0,0
0,0,0,0,0,0,0,0,0,0,0,0,0,0,0,0,0,0,0,0,0,0,0,0,0,0,0
0,0,0,0,0,0,0,0,0,0,0,0,0,0,0,0,0,0,0,0,0,0,0,0,0,0,0
0,0,0,0,0,0,0,0,0,0,0,0,0,0,0,0,0,0,0,0,0,0,0,0,0,0,0
0,0,0,0,0,0,0,0,0,0,0,0,0,0,0,0,0,0,0,0,0,0,0,0,0,0,0
0,0,0,0,0,0,0,0,0,0,0,0,0,0,0,0,0,0,0,0,0,0,0,0,0,0,0
0,0,0,0,0,0,0,0,0,0,0,0,0,0,0,0,0,0,0,0,0,0,0,0,0,0,0
0,0,0,0,0,0,0,0,0,0,0,0,0,0,0,0,0,0,0,0,0,0,0,0,0,0,0
0,0,0,0,0,0,0,0,0,0,0,0,0,0,0,0,0,0,0,0,0,0,0,0,0,0,0
0,0,0,0,0,0,0,0,0,0,0,0,0,0,0,0,0,0,0,0,0,0,0,0,0,0,0
endlayer

