
# Created by Ruins mod version 15.2 Ingame Parser
# authoring Player: Mensrea

weight=4
embed_into_distance=28
acceptable_target_blocks=
unacceptable_target_blocks=flowing_water,water,flowing_lava,lava
dimensions=31,21,21
allowable_overhang=0
max_leveling=2
leveling_buffer=0
preserve_water=0
preserve_lava=0

rule1=0,100,preserveBlock
rule2=0,100,minecraft:stone-0
rule3=0,100,PFAAGeologica:heavyOil
rule4=0,100,minecraft:sand-1

layer
1,1,1,1,1,1,1,1,1,1,1,1,1,1,1,1,1,1,1,1,1
1,1,1,1,1,1,1,1,1,1,1,1,1,1,1,1,1,1,1,1,1
1,1,1,1,1,1,1,1,1,1,1,1,1,1,1,1,1,1,1,1,1
1,1,1,1,1,1,1,1,1,1,1,1,1,1,1,1,1,1,1,1,1
1,1,1,1,1,1,1,1,1,1,1,1,1,1,1,1,1,1,1,1,1
1,1,1,1,1,1,1,1,1,1,1,1,1,1,1,1,1,1,1,1,1
1,1,1,1,1,1,1,1,1,1,1,1,1,1,1,1,1,1,1,1,1
1,1,1,1,1,1,1,1,1,2,2,2,1,1,1,1,1,1,1,1,1
1,1,1,1,1,1,1,1,2,2,2,2,2,1,1,1,1,1,1,1,1
1,1,1,1,1,1,1,2,2,2,2,2,2,2,1,1,1,1,1,1,1
1,1,1,1,1,1,1,2,2,2,2,2,2,2,1,1,1,1,1,1,1
1,1,1,1,1,1,1,2,2,2,2,2,2,2,1,1,1,1,1,1,1
1,1,1,1,1,1,1,1,2,2,2,2,2,1,1,1,1,1,1,1,1
1,1,1,1,1,1,1,1,1,2,2,2,1,1,1,1,1,1,1,1,1
1,1,1,1,1,1,1,1,1,1,1,1,1,1,1,1,1,1,1,1,1
1,1,1,1,1,1,1,1,1,1,1,1,1,1,1,1,1,1,1,1,1
1,1,1,1,1,1,1,1,1,1,1,1,1,1,1,1,1,1,1,1,1
1,1,1,1,1,1,1,1,1,1,1,1,1,1,1,1,1,1,1,1,1
1,1,1,1,1,1,1,1,1,1,1,1,1,1,1,1,1,1,1,1,1
1,1,1,1,1,1,1,1,1,1,1,1,1,1,1,1,1,1,1,1,1
1,1,1,1,1,1,1,1,1,1,1,1,1,1,1,1,1,1,1,1,1
endlayer

layer
1,1,1,1,1,1,1,1,1,1,1,1,1,1,1,1,1,1,1,1,1
1,1,1,1,1,1,1,1,1,1,1,1,1,1,1,1,1,1,1,1,1
1,1,1,1,1,1,1,1,1,1,1,1,1,1,1,1,1,1,1,1,1
1,1,1,1,1,1,1,1,1,1,1,1,1,1,1,1,1,1,1,1,1
1,1,1,1,1,1,1,1,1,1,1,1,1,1,1,1,1,1,1,1,1
1,1,1,1,1,1,1,1,2,2,2,2,2,1,1,1,1,1,1,1,1
1,1,1,1,1,1,1,2,2,2,2,2,2,2,1,1,1,1,1,1,1
1,1,1,1,1,1,2,2,2,2,2,2,2,2,2,1,1,1,1,1,1
1,1,1,1,1,2,2,2,2,2,2,2,2,2,2,2,1,1,1,1,1
1,1,1,1,1,2,2,2,2,2,2,2,2,2,2,2,1,1,1,1,1
1,1,1,1,1,2,2,2,2,2,2,2,2,2,2,2,1,1,1,1,1
1,1,1,1,1,2,2,2,2,2,2,2,2,2,2,2,1,1,1,1,1
1,1,1,1,1,2,2,2,2,2,2,2,2,2,2,2,1,1,1,1,1
1,1,1,1,1,1,2,2,2,2,2,2,2,2,2,1,1,1,1,1,1
1,1,1,1,1,1,1,2,2,2,2,2,2,2,1,1,1,1,1,1,1
1,1,1,1,1,1,1,1,2,2,2,2,2,1,1,1,1,1,1,1,1
1,1,1,1,1,1,1,1,1,1,1,1,1,1,1,1,1,1,1,1,1
1,1,1,1,1,1,1,1,1,1,1,1,1,1,1,1,1,1,1,1,1
1,1,1,1,1,1,1,1,1,1,1,1,1,1,1,1,1,1,1,1,1
1,1,1,1,1,1,1,1,1,1,1,1,1,1,1,1,1,1,1,1,1
1,1,1,1,1,1,1,1,1,1,1,1,1,1,1,1,1,1,1,1,1
endlayer

layer
1,1,1,1,1,1,1,1,1,1,1,1,1,1,1,1,1,1,1,1,1
1,1,1,1,1,1,1,1,1,1,1,1,1,1,1,1,1,1,1,1,1
1,1,1,1,1,1,1,1,1,1,1,1,1,1,1,1,1,1,1,1,1
1,1,1,1,1,1,1,1,1,1,1,1,1,1,1,1,1,1,1,1,1
1,1,1,1,1,1,1,2,2,2,2,2,2,2,1,1,1,1,1,1,1
1,1,1,1,1,1,2,2,2,2,2,2,2,2,2,1,1,1,1,1,1
1,1,1,1,1,2,2,2,2,2,2,2,2,2,2,2,1,1,1,1,1
1,1,1,1,2,2,2,2,2,2,2,2,2,2,2,2,2,1,1,1,1
1,1,1,1,2,2,2,2,2,2,2,2,2,2,2,2,2,1,1,1,1
1,1,1,1,2,2,2,2,2,2,2,2,2,2,2,2,2,1,1,1,1
1,1,1,1,2,2,2,2,2,2,2,2,2,2,2,2,2,1,1,1,1
1,1,1,1,2,2,2,2,2,2,2,2,2,2,2,2,2,1,1,1,1
1,1,1,1,2,2,2,2,2,2,2,2,2,2,2,2,2,1,1,1,1
1,1,1,1,2,2,2,2,2,2,2,2,2,2,2,2,2,1,1,1,1
1,1,1,1,1,2,2,2,2,2,2,2,2,2,2,2,1,1,1,1,1
1,1,1,1,1,1,2,2,2,2,2,2,2,2,2,1,1,1,1,1,1
1,1,1,1,1,1,1,2,2,2,2,2,2,2,1,1,1,1,1,1,1
1,1,1,1,1,1,1,1,1,1,1,1,1,1,1,1,1,1,1,1,1
1,1,1,1,1,1,1,1,1,1,1,1,1,1,1,1,1,1,1,1,1
1,1,1,1,1,1,1,1,1,1,1,1,1,1,1,1,1,1,1,1,1
1,1,1,1,1,1,1,1,1,1,1,1,1,1,1,1,1,1,1,1,1
endlayer

layer
1,1,1,1,1,1,1,1,1,1,1,1,1,1,1,1,1,1,1,1,1
1,1,1,1,1,1,1,1,1,1,1,1,1,1,1,1,1,1,1,1,1
1,1,1,1,1,1,1,1,1,1,1,1,1,1,1,1,1,1,1,1,1
1,1,1,1,1,1,1,2,2,2,2,2,2,2,1,1,1,1,1,1,1
1,1,1,1,1,2,2,2,2,2,2,2,2,2,2,2,1,1,1,1,1
1,1,1,1,2,2,2,2,2,2,2,2,2,2,2,2,2,1,1,1,1
1,1,1,1,2,2,2,2,2,2,2,2,2,2,2,2,2,1,1,1,1
1,1,1,2,2,2,2,2,2,2,2,2,2,2,2,2,2,2,1,1,1
1,1,1,2,2,2,2,2,3,3,3,3,3,2,2,2,2,2,1,1,1
1,1,1,2,2,2,2,2,3,3,3,3,3,2,2,2,2,2,1,1,1
1,1,1,2,2,2,2,2,3,3,3,3,3,2,2,2,2,2,1,1,1
1,1,1,2,2,2,2,2,3,3,3,3,3,2,2,2,2,2,1,1,1
1,1,1,2,2,2,2,2,3,3,3,3,3,2,2,2,2,2,1,1,1
1,1,1,2,2,2,2,2,2,2,2,2,2,2,2,2,2,2,1,1,1
1,1,1,1,2,2,2,2,2,2,2,2,2,2,2,2,2,1,1,1,1
1,1,1,1,2,2,2,2,2,2,2,2,2,2,2,2,2,1,1,1,1
1,1,1,1,1,2,2,2,2,2,2,2,2,2,2,2,1,1,1,1,1
1,1,1,1,1,1,1,2,2,2,2,2,2,2,1,1,1,1,1,1,1
1,1,1,1,1,1,1,1,1,1,1,1,1,1,1,1,1,1,1,1,1
1,1,1,1,1,1,1,1,1,1,1,1,1,1,1,1,1,1,1,1,1
1,1,1,1,1,1,1,1,1,1,1,1,1,1,1,1,1,1,1,1,1
endlayer

layer
1,1,1,1,1,1,1,1,1,1,1,1,1,1,1,1,1,1,1,1,1
1,1,1,1,1,1,1,1,1,1,1,1,1,1,1,1,1,1,1,1,1
1,1,1,1,1,1,1,2,2,2,2,2,2,2,1,1,1,1,1,1,1
1,1,1,1,1,2,2,2,2,2,2,2,2,2,2,2,1,1,1,1,1
1,1,1,1,2,2,2,2,2,2,2,2,2,2,2,2,2,1,1,1,1
1,1,1,2,2,2,2,2,2,2,2,2,2,2,2,2,2,2,1,1,1
1,1,1,2,2,2,2,2,3,3,3,3,3,2,2,2,2,2,1,1,1
1,1,2,2,2,2,2,3,3,3,3,3,3,3,2,2,2,2,2,1,1
1,1,2,2,2,2,3,3,3,3,3,3,3,3,3,2,2,2,2,1,1
1,1,2,2,2,2,3,3,3,3,3,3,3,3,3,2,2,2,2,1,1
1,1,2,2,2,2,3,3,3,3,3,3,3,3,3,2,2,2,2,1,1
1,1,2,2,2,2,3,3,3,3,3,3,3,3,3,2,2,2,2,1,1
1,1,2,2,2,2,3,3,3,3,3,3,3,3,3,2,2,2,2,1,1
1,1,2,2,2,2,2,3,3,3,3,3,3,3,2,2,2,2,2,1,1
1,1,1,2,2,2,2,2,3,3,3,3,3,2,2,2,2,2,1,1,1
1,1,1,2,2,2,2,2,2,2,2,2,2,2,2,2,2,2,1,1,1
1,1,1,1,2,2,2,2,2,2,2,2,2,2,2,2,2,1,1,1,1
1,1,1,1,1,2,2,2,2,2,2,2,2,2,2,2,1,1,1,1,1
1,1,1,1,1,1,1,2,2,2,2,2,2,2,1,1,1,1,1,1,1
1,1,1,1,1,1,1,1,1,1,1,1,1,1,1,1,1,1,1,1,1
1,1,1,1,1,1,1,1,1,1,1,1,1,1,1,1,1,1,1,1,1
endlayer

layer
1,1,1,1,1,1,1,1,1,1,1,1,1,1,1,1,1,1,1,1,1
1,1,1,1,1,1,1,1,2,2,2,2,2,1,1,1,1,1,1,1,1
1,1,1,1,1,1,2,2,2,2,2,2,2,2,2,1,1,1,1,1,1
1,1,1,1,2,2,2,2,2,2,2,2,2,2,2,2,2,1,1,1,1
1,1,1,2,2,2,2,2,2,2,3,2,2,2,2,2,2,2,1,1,1
1,1,1,2,2,2,2,3,3,3,3,3,3,3,2,2,2,2,1,1,1
1,1,2,2,2,2,3,3,3,3,3,3,3,3,3,2,2,2,2,1,1
1,1,2,2,2,3,3,3,3,3,3,3,3,3,3,3,2,2,2,1,1
1,2,2,2,2,3,3,3,3,3,3,3,3,3,3,3,2,2,2,2,1
1,2,2,2,2,3,3,3,3,3,3,3,3,3,3,3,2,2,2,2,1
1,2,2,2,3,3,3,3,3,3,3,3,3,3,3,3,3,2,2,2,1
1,2,2,2,2,3,3,3,3,3,3,3,3,3,3,3,2,2,2,2,1
1,2,2,2,2,3,3,3,3,3,3,3,3,3,3,3,2,2,2,2,1
1,1,2,2,2,3,3,3,3,3,3,3,3,3,3,3,2,2,2,1,1
1,1,2,2,2,2,3,3,3,3,3,3,3,3,3,2,2,2,2,1,1
1,1,1,2,2,2,2,3,3,3,3,3,3,3,2,2,2,2,1,1,1
1,1,1,2,2,2,2,2,2,2,3,2,2,2,2,2,2,2,1,1,1
1,1,1,1,2,2,2,2,2,2,2,2,2,2,2,2,2,1,1,1,1
1,1,1,1,1,1,2,2,2,2,2,2,2,2,2,1,1,1,1,1,1
1,1,1,1,1,1,1,1,2,2,2,2,2,1,1,1,1,1,1,1,1
1,1,1,1,1,1,1,1,1,1,1,1,1,1,1,1,1,1,1,1,1
endlayer

layer
1,1,1,1,1,1,1,1,1,1,1,1,1,1,1,1,1,1,1,1,1
1,1,1,1,1,1,1,2,2,2,2,2,2,2,1,1,1,1,1,1,1
1,1,1,1,1,2,2,2,2,2,2,2,2,2,2,2,1,1,1,1,1
1,1,1,1,2,2,2,2,2,2,2,2,2,2,2,2,2,1,1,1,1
1,1,1,2,2,2,2,3,3,3,3,3,3,3,2,2,2,2,1,1,1
1,1,2,2,2,2,3,3,3,3,3,3,3,3,3,2,2,2,2,1,1
1,1,2,2,2,3,3,3,3,3,3,3,3,3,3,3,2,2,2,1,1
1,2,2,2,3,3,3,3,3,3,3,3,3,3,3,3,3,2,2,2,1
1,2,2,2,3,3,3,3,3,3,3,3,3,3,3,3,3,2,2,2,1
1,2,2,2,3,3,3,3,3,3,3,3,3,3,3,3,3,2,2,2,1
1,2,2,2,3,3,3,3,3,3,3,3,3,3,3,3,3,2,2,2,1
1,2,2,2,3,3,3,3,3,3,3,3,3,3,3,3,3,2,2,2,1
1,2,2,2,3,3,3,3,3,3,3,3,3,3,3,3,3,2,2,2,1
1,2,2,2,3,3,3,3,3,3,3,3,3,3,3,3,3,2,2,2,1
1,1,2,2,2,3,3,3,3,3,3,3,3,3,3,3,2,2,2,1,1
1,1,2,2,2,2,3,3,3,3,3,3,3,3,3,2,2,2,2,1,1
1,1,1,2,2,2,2,3,3,3,3,3,3,3,2,2,2,2,1,1,1
1,1,1,1,2,2,2,2,2,2,2,2,2,2,2,2,2,1,1,1,1
1,1,1,1,1,2,2,2,2,2,2,2,2,2,2,2,1,1,1,1,1
1,1,1,1,1,1,1,2,2,2,2,2,2,2,1,1,1,1,1,1,1
1,1,1,1,1,1,1,1,1,1,1,1,1,1,1,1,1,1,1,1,1
endlayer

layer
1,1,1,1,1,1,1,1,1,2,2,2,1,1,1,1,1,1,1,1,1
1,1,1,1,1,1,2,2,2,2,2,2,2,2,2,1,1,1,1,1,1
1,1,1,1,2,2,2,2,2,2,2,2,2,2,2,2,2,1,1,1,1
1,1,1,2,2,2,2,2,3,3,3,3,3,2,2,2,2,2,1,1,1
1,1,2,2,2,2,3,3,3,3,3,3,3,3,3,2,2,2,2,1,1
1,1,2,2,2,3,3,3,3,3,3,3,3,3,3,3,2,2,2,1,1
1,2,2,2,3,3,3,3,3,3,3,3,3,3,3,3,3,2,2,2,1
1,2,2,2,3,3,3,3,3,3,3,3,3,3,3,3,3,2,2,2,1
1,2,2,3,3,3,3,3,3,3,3,3,3,3,3,3,3,3,2,2,1
2,2,2,3,3,3,3,3,3,3,3,3,3,3,3,3,3,3,2,2,2
2,2,2,3,3,3,3,3,3,3,3,3,3,3,3,3,3,3,2,2,2
2,2,2,3,3,3,3,3,3,3,3,3,3,3,3,3,3,3,2,2,2
1,2,2,3,3,3,3,3,3,3,3,3,3,3,3,3,3,3,2,2,1
1,2,2,2,3,3,3,3,3,3,3,3,3,3,3,3,3,2,2,2,1
1,2,2,2,3,3,3,3,3,3,3,3,3,3,3,3,3,2,2,2,1
1,1,2,2,2,3,3,3,3,3,3,3,3,3,3,3,2,2,2,1,1
1,1,2,2,2,2,3,3,3,3,3,3,3,3,3,2,2,2,2,1,1
1,1,1,2,2,2,2,2,3,3,3,3,3,2,2,2,2,2,1,1,1
1,1,1,1,2,2,2,2,2,2,2,2,2,2,2,2,2,1,1,1,1
1,1,1,1,1,1,2,2,2,2,2,2,2,2,2,1,1,1,1,1,1
1,1,1,1,1,1,1,1,1,2,2,2,1,1,1,1,1,1,1,1,1
endlayer

layer
1,1,1,1,1,1,1,1,2,2,2,2,2,1,1,1,1,1,1,1,1
1,1,1,1,1,2,2,2,2,2,2,2,2,2,2,2,1,1,1,1,1
1,1,1,1,2,2,2,2,2,2,2,2,2,2,2,2,2,1,1,1,1
1,1,1,2,2,2,2,3,3,3,3,3,3,3,2,2,2,2,1,1,1
1,1,2,2,2,3,3,3,3,3,3,3,3,3,3,3,2,2,2,1,1
1,2,2,2,3,3,3,3,3,3,3,3,3,3,3,3,3,2,2,2,1
1,2,2,2,3,3,3,3,3,3,3,3,3,3,3,3,3,2,2,2,1
1,2,2,3,3,3,3,3,3,3,3,3,3,3,3,3,3,3,2,2,1
2,2,2,3,3,3,3,3,3,3,3,3,3,3,3,3,3,3,2,2,2
2,2,2,3,3,3,3,3,3,3,3,3,3,3,3,3,3,3,2,2,2
2,2,2,3,3,3,3,3,3,3,3,3,3,3,3,3,3,3,2,2,2
2,2,2,3,3,3,3,3,3,3,3,3,3,3,3,3,3,3,2,2,2
2,2,2,3,3,3,3,3,3,3,3,3,3,3,3,3,3,3,2,2,2
1,2,2,3,3,3,3,3,3,3,3,3,3,3,3,3,3,3,2,2,1
1,2,2,2,3,3,3,3,3,3,3,3,3,3,3,3,3,2,2,2,1
1,2,2,2,3,3,3,3,3,3,3,3,3,3,3,3,3,2,2,2,1
1,1,2,2,2,3,3,3,3,3,3,3,3,3,3,3,2,2,2,1,1
1,1,1,2,2,2,2,3,3,3,3,3,3,3,2,2,2,2,1,1,1
1,1,1,1,2,2,2,2,2,2,2,2,2,2,2,2,2,1,1,1,1
1,1,1,1,1,2,2,2,2,2,2,2,2,2,2,2,1,1,1,1,1
1,1,1,1,1,1,1,1,2,2,2,2,2,1,1,1,1,1,1,1,1
endlayer

layer
1,1,1,1,1,1,1,2,2,2,2,2,2,2,1,1,1,1,1,1,1
1,1,1,1,1,2,2,2,2,2,2,2,2,2,2,2,1,1,1,1,1
1,1,1,1,2,2,2,2,3,3,3,3,3,2,2,2,2,1,1,1,1
1,1,1,2,2,2,3,3,3,3,3,3,3,3,3,2,2,2,1,1,1
1,1,2,2,2,3,3,3,3,3,3,3,3,3,3,3,2,2,2,1,1
1,2,2,2,3,3,3,3,3,3,3,3,3,3,3,3,3,2,2,2,1
1,2,2,3,3,3,3,3,3,3,3,3,3,3,3,3,3,3,2,2,1
2,2,2,3,3,3,3,3,3,3,3,3,3,3,3,3,3,3,2,2,2
2,2,3,3,3,3,3,3,3,3,3,3,3,3,3,3,3,3,3,2,2
2,2,3,3,3,3,3,3,3,3,3,3,3,3,3,3,3,3,3,2,2
2,2,3,3,3,3,3,3,3,3,3,3,3,3,3,3,3,3,3,2,2
2,2,3,3,3,3,3,3,3,3,3,3,3,3,3,3,3,3,3,2,2
2,2,3,3,3,3,3,3,3,3,3,3,3,3,3,3,3,3,3,2,2
2,2,2,3,3,3,3,3,3,3,3,3,3,3,3,3,3,3,2,2,2
1,2,2,3,3,3,3,3,3,3,3,3,3,3,3,3,3,3,2,2,1
1,2,2,2,3,3,3,3,3,3,3,3,3,3,3,3,3,2,2,2,1
1,1,2,2,2,3,3,3,3,3,3,3,3,3,3,3,2,2,2,1,1
1,1,1,2,2,2,3,3,3,3,3,3,3,3,3,2,2,2,1,1,1
1,1,1,1,2,2,2,2,3,3,3,3,3,2,2,2,2,1,1,1,1
1,1,1,1,1,2,2,2,2,2,2,2,2,2,2,2,1,1,1,1,1
1,1,1,1,1,1,1,2,2,2,2,2,2,2,1,1,1,1,1,1,1
endlayer

layer
1,1,1,1,1,1,1,2,2,2,2,2,2,2,1,1,1,1,1,1,1
1,1,1,1,1,2,2,2,2,2,2,2,2,2,2,2,1,1,1,1,1
1,1,1,1,2,2,2,2,3,3,3,3,3,2,2,2,2,1,1,1,1
1,1,1,2,2,2,3,3,3,3,3,3,3,3,3,2,2,2,1,1,1
1,1,2,2,2,3,3,3,3,3,3,3,3,3,3,3,2,2,2,1,1
1,2,2,2,3,3,3,3,3,3,3,3,3,3,3,3,3,2,2,2,1
1,2,2,3,3,3,3,3,3,3,3,3,3,3,3,3,3,3,2,2,1
2,2,2,3,3,3,3,3,3,3,3,3,3,3,3,3,3,3,2,2,2
2,2,3,3,3,3,3,3,3,3,3,3,3,3,3,3,3,3,3,2,2
2,2,3,3,3,3,3,3,3,3,3,3,3,3,3,3,3,3,3,2,2
2,2,3,3,3,3,3,3,3,3,3,3,3,3,3,3,3,3,3,2,2
2,2,3,3,3,3,3,3,3,3,3,3,3,3,3,3,3,3,3,2,2
2,2,3,3,3,3,3,3,3,3,3,3,3,3,3,3,3,3,3,2,2
2,2,2,3,3,3,3,3,3,3,3,3,3,3,3,3,3,3,2,2,2
1,2,2,3,3,3,3,3,3,3,3,3,3,3,3,3,3,3,2,2,1
1,2,2,2,3,3,3,3,3,3,3,3,3,3,3,3,3,2,2,2,1
1,1,2,2,2,3,3,3,3,3,3,3,3,3,3,3,2,2,2,1,1
1,1,1,2,2,2,3,3,3,3,3,3,3,3,3,2,2,2,1,1,1
1,1,1,1,2,2,2,2,3,3,3,3,3,2,2,2,2,1,1,1,1
1,1,1,1,1,2,2,2,2,2,2,2,2,2,2,2,1,1,1,1,1
1,1,1,1,1,1,1,2,2,2,2,2,2,2,1,1,1,1,1,1,1
endlayer

layer
1,1,1,1,1,1,1,2,2,2,2,2,2,2,1,1,1,1,1,1,1
1,1,1,1,1,2,2,2,2,2,2,2,2,2,2,2,1,1,1,1,1
1,1,1,1,2,2,2,2,3,3,3,3,3,2,2,2,2,1,1,1,1
1,1,1,2,2,2,3,3,3,3,3,3,3,3,3,2,2,2,1,1,1
1,1,2,2,3,3,3,3,3,3,3,3,3,3,3,3,3,2,2,1,1
1,2,2,2,3,3,3,3,3,3,3,3,3,3,3,3,3,2,2,2,1
1,2,2,3,3,3,3,3,3,3,3,3,3,3,3,3,3,3,2,2,1
2,2,2,3,3,3,3,3,3,3,3,3,3,3,3,3,3,3,2,2,2
2,2,3,3,3,3,3,3,3,3,3,3,3,3,3,3,3,3,3,2,2
2,2,3,3,3,3,3,3,3,3,3,3,3,3,3,3,3,3,3,2,2
2,2,3,3,3,3,3,3,3,3,3,3,3,3,3,3,3,3,3,2,2
2,2,3,3,3,3,3,3,3,3,3,3,3,3,3,3,3,3,3,2,2
2,2,3,3,3,3,3,3,3,3,3,3,3,3,3,3,3,3,3,2,2
2,2,2,3,3,3,3,3,3,3,3,3,3,3,3,3,3,3,2,2,2
1,2,2,3,3,3,3,3,3,3,3,3,3,3,3,3,3,3,2,2,1
1,2,2,2,3,3,3,3,3,3,3,3,3,3,3,3,3,2,2,2,1
1,1,2,2,3,3,3,3,3,3,3,3,3,3,3,3,3,2,2,1,1
1,1,1,2,2,2,3,3,3,3,3,3,3,3,3,2,2,2,1,1,1
1,1,1,1,2,2,2,2,3,3,3,3,3,2,2,2,2,1,1,1,1
1,1,1,1,1,2,2,2,2,2,2,2,2,2,2,2,1,1,1,1,1
1,1,1,1,1,1,1,2,2,2,2,2,2,2,1,1,1,1,1,1,1
endlayer

layer
1,1,1,1,1,1,1,1,2,2,2,2,2,1,1,1,1,1,1,1,1
1,1,1,1,1,2,2,2,2,2,2,2,2,2,2,2,1,1,1,1,1
1,1,1,1,2,2,2,2,3,3,3,3,3,2,2,2,2,1,1,1,1
1,1,1,2,2,2,3,3,3,3,3,3,3,3,3,2,2,2,1,1,1
1,1,2,2,2,3,3,3,3,3,3,3,3,3,3,3,2,2,2,1,1
1,2,2,2,3,3,3,3,3,3,3,3,3,3,3,3,3,2,2,2,1
1,2,2,3,3,3,3,3,3,3,3,3,3,3,3,3,3,3,2,2,1
1,2,2,3,3,3,3,3,3,3,3,3,3,3,3,3,3,3,2,2,1
2,2,3,3,3,3,3,3,3,3,3,3,3,3,3,3,3,3,3,2,2
2,2,3,3,3,3,3,3,3,3,3,3,3,3,3,3,3,3,3,2,2
2,2,3,3,3,3,3,3,3,3,3,3,3,3,3,3,3,3,3,2,2
2,2,3,3,3,3,3,3,3,3,3,3,3,3,3,3,3,3,3,2,2
2,2,3,3,3,3,3,3,3,3,3,3,3,3,3,3,3,3,3,2,2
1,2,2,3,3,3,3,3,3,3,3,3,3,3,3,3,3,3,2,2,1
1,2,2,3,3,3,3,3,3,3,3,3,3,3,3,3,3,3,2,2,1
1,2,2,2,3,3,3,3,3,3,3,3,3,3,3,3,3,2,2,2,1
1,1,2,2,2,3,3,3,3,3,3,3,3,3,3,3,2,2,2,1,1
1,1,1,2,2,2,3,3,3,3,3,3,3,3,3,2,2,2,1,1,1
1,1,1,1,2,2,2,2,3,3,3,3,3,2,2,2,2,1,1,1,1
1,1,1,1,1,2,2,2,2,2,2,2,2,2,2,2,1,1,1,1,1
1,1,1,1,1,1,1,1,2,2,2,2,2,1,1,1,1,1,1,1,1
endlayer

layer
1,1,1,1,1,1,1,1,1,2,2,2,1,1,1,1,1,1,1,1,1
1,1,1,1,1,1,2,2,2,2,2,2,2,2,2,1,1,1,1,1,1
1,1,1,1,2,2,2,2,3,3,3,3,3,2,2,2,2,1,1,1,1
1,1,1,2,2,2,3,3,3,3,3,3,3,3,3,2,2,2,1,1,1
1,1,2,2,2,3,3,3,3,3,3,3,3,3,3,3,2,2,2,1,1
1,1,2,2,3,3,3,3,3,3,3,3,3,3,3,3,3,2,2,1,1
1,2,2,3,3,3,3,3,3,3,3,3,3,3,3,3,3,3,2,2,1
1,2,2,3,3,3,3,3,3,3,3,3,3,3,3,3,3,3,2,2,1
1,2,3,3,3,3,3,3,3,3,3,3,3,3,3,3,3,3,3,2,1
2,2,3,3,3,3,3,3,3,3,3,3,3,3,3,3,3,3,3,2,2
2,2,3,3,3,3,3,3,3,3,3,3,3,3,3,3,3,3,3,2,2
2,2,3,3,3,3,3,3,3,3,3,3,3,3,3,3,3,3,3,2,2
1,2,3,3,3,3,3,3,3,3,3,3,3,3,3,3,3,3,3,2,1
1,2,2,3,3,3,3,3,3,3,3,3,3,3,3,3,3,3,2,2,1
1,2,2,3,3,3,3,3,3,3,3,3,3,3,3,3,3,3,2,2,1
1,1,2,2,3,3,3,3,3,3,3,3,3,3,3,3,3,2,2,1,1
1,1,2,2,2,3,3,3,3,3,3,3,3,3,3,3,2,2,2,1,1
1,1,1,2,2,2,3,3,3,3,3,3,3,3,3,2,2,2,1,1,1
1,1,1,1,2,2,2,2,3,3,3,3,3,2,2,2,2,1,1,1,1
1,1,1,1,1,1,2,2,2,2,2,2,2,2,2,1,1,1,1,1,1
1,1,1,1,1,1,1,1,1,2,2,2,1,1,1,1,1,1,1,1,1
endlayer

layer
1,1,1,1,1,1,1,1,1,1,1,1,1,1,1,1,1,1,1,1,1
1,1,1,1,1,1,1,2,2,2,2,2,2,2,1,1,1,1,1,1,1
1,1,1,1,1,2,2,2,2,2,2,2,2,2,2,2,1,1,1,1,1
1,1,1,1,2,2,2,3,3,3,3,3,3,3,2,2,2,1,1,1,1
1,1,1,2,2,3,3,3,3,3,3,3,3,3,3,3,2,2,1,1,1
1,1,2,2,3,3,3,3,3,3,3,3,3,3,3,3,3,2,2,1,1
1,1,2,2,3,3,3,3,3,3,3,3,3,3,3,3,3,2,2,1,1
1,2,2,3,3,3,3,3,3,3,3,3,3,3,3,3,3,3,2,2,1
1,2,2,3,3,3,3,3,3,3,3,3,3,3,3,3,3,3,2,2,1
1,2,2,3,3,3,3,3,3,3,3,3,3,3,3,3,3,3,2,2,1
1,2,2,3,3,3,3,3,3,3,3,3,3,3,3,3,3,3,2,2,1
1,2,2,3,3,3,3,3,3,3,3,3,3,3,3,3,3,3,2,2,1
1,2,2,3,3,3,3,3,3,3,3,3,3,3,3,3,3,3,2,2,1
1,2,2,3,3,3,3,3,3,3,3,3,3,3,3,3,3,3,2,2,1
1,1,2,2,3,3,3,3,3,3,3,3,3,3,3,3,3,2,2,1,1
1,1,2,2,3,3,3,3,3,3,3,3,3,3,3,3,3,2,2,1,1
1,1,1,2,2,3,3,3,3,3,3,3,3,3,3,3,2,2,1,1,1
1,1,1,1,2,2,2,3,3,3,3,3,3,3,2,2,2,1,1,1,1
1,1,1,1,1,2,2,2,2,2,2,2,2,2,2,2,1,1,1,1,1
1,1,1,1,1,1,1,2,2,2,2,2,2,2,1,1,1,1,1,1,1
1,1,1,1,1,1,1,1,1,1,1,1,1,1,1,1,1,1,1,1,1
endlayer

layer
1,1,1,1,1,1,1,1,1,1,1,1,1,1,1,1,1,1,1,1,1
1,1,1,1,1,1,1,1,2,2,2,2,2,1,1,1,1,1,1,1,1
1,1,1,1,1,1,2,2,2,2,2,2,2,2,2,1,1,1,1,1,1
1,1,1,1,2,2,2,2,3,3,3,3,3,2,2,2,2,1,1,1,1
1,1,1,2,2,2,3,3,3,3,3,3,3,3,3,2,2,2,1,1,1
1,1,1,2,2,3,3,3,3,3,3,3,3,3,3,3,2,2,1,1,1
1,1,2,2,3,3,3,3,3,3,3,3,3,3,3,3,3,2,2,1,1
1,1,2,2,3,3,3,3,3,3,3,3,3,3,3,3,3,2,2,1,1
1,2,2,3,3,3,3,3,3,3,3,3,3,3,3,3,3,3,2,2,1
1,2,2,3,3,3,3,3,3,3,3,3,3,3,3,3,3,3,2,2,1
1,2,2,3,3,3,3,3,3,3,3,3,3,3,3,3,3,3,2,2,1
1,2,2,3,3,3,3,3,3,3,3,3,3,3,3,3,3,3,2,2,1
1,2,2,3,3,3,3,3,3,3,3,3,3,3,3,3,3,3,2,2,1
1,1,2,2,3,3,3,3,3,3,3,3,3,3,3,3,3,2,2,1,1
1,1,2,2,3,3,3,3,3,3,3,3,3,3,3,3,3,2,2,1,1
1,1,1,2,2,3,3,3,3,3,3,3,3,3,3,3,2,2,1,1,1
1,1,1,2,2,2,3,3,3,3,3,3,3,3,3,2,2,2,1,1,1
1,1,1,1,2,2,2,2,3,3,3,3,3,2,2,2,2,1,1,1,1
1,1,1,1,1,1,2,2,2,2,2,2,2,2,2,1,1,1,1,1,1
1,1,1,1,1,1,1,1,2,2,2,2,2,1,1,1,1,1,1,1,1
1,1,1,1,1,1,1,1,1,1,1,1,1,1,1,1,1,1,1,1,1
endlayer

layer
1,1,1,1,1,1,1,1,1,1,1,1,1,1,1,1,1,1,1,1,1
1,1,1,1,1,1,1,1,1,1,1,1,1,1,1,1,1,1,1,1,1
1,1,1,1,1,1,1,2,2,2,2,2,2,2,1,1,1,1,1,1,1
1,1,1,1,1,2,2,2,2,2,2,2,2,2,2,2,1,1,1,1,1
1,1,1,1,2,2,2,3,3,3,3,3,3,3,2,2,2,1,1,1,1
1,1,1,2,2,2,3,3,3,3,3,3,3,3,3,2,2,2,1,1,1
1,1,1,2,2,3,3,3,3,3,3,3,3,3,3,3,2,2,1,1,1
1,1,2,2,3,3,3,3,3,3,3,3,3,3,3,3,3,2,2,1,1
1,1,2,2,3,3,3,3,3,3,3,3,3,3,3,3,3,2,2,1,1
1,1,2,2,3,3,3,3,3,3,3,3,3,3,3,3,3,2,2,1,1
1,1,2,2,3,3,3,3,3,3,3,3,3,3,3,3,3,2,2,1,1
1,1,2,2,3,3,3,3,3,3,3,3,3,3,3,3,3,2,2,1,1
1,1,2,2,3,3,3,3,3,3,3,3,3,3,3,3,3,2,2,1,1
1,1,2,2,3,3,3,3,3,3,3,3,3,3,3,3,3,2,2,1,1
1,1,1,2,2,3,3,3,3,3,3,3,3,3,3,3,2,2,1,1,1
1,1,1,2,2,2,3,3,3,3,3,3,3,3,3,2,2,2,1,1,1
1,1,1,1,2,2,2,3,3,3,3,3,3,3,2,2,2,1,1,1,1
1,1,1,1,1,2,2,2,2,2,2,2,2,2,2,2,1,1,1,1,1
1,1,1,1,1,1,1,2,2,2,2,2,2,2,1,1,1,1,1,1,1
1,1,1,1,1,1,1,1,1,1,1,1,1,1,1,1,1,1,1,1,1
1,1,1,1,1,1,1,1,1,1,1,1,1,1,1,1,1,1,1,1,1
endlayer

layer
1,1,1,1,1,1,1,1,1,1,1,1,1,1,1,1,1,1,1,1,1
1,1,1,1,1,1,1,1,1,1,1,1,1,1,1,1,1,1,1,1,1
1,1,1,1,1,1,1,1,1,1,1,1,1,1,1,1,1,1,1,1,1
1,1,1,1,1,1,1,2,2,2,2,2,2,2,1,1,1,1,1,1,1
1,1,1,1,1,2,2,2,2,2,3,2,2,2,2,2,1,1,1,1,1
1,1,1,1,2,2,2,3,3,3,3,3,3,3,2,2,2,1,1,1,1
1,1,1,1,2,2,3,3,3,3,3,3,3,3,3,2,2,1,1,1,1
1,1,1,2,2,3,3,3,3,3,3,3,3,3,3,3,2,2,1,1,1
1,1,1,2,2,3,3,3,3,3,3,3,3,3,3,3,2,2,1,1,1
1,1,1,2,2,3,3,3,3,3,3,3,3,3,3,3,2,2,1,1,1
1,1,1,2,3,3,3,3,3,3,3,3,3,3,3,3,3,2,1,1,1
1,1,1,2,2,3,3,3,3,3,3,3,3,3,3,3,2,2,1,1,1
1,1,1,2,2,3,3,3,3,3,3,3,3,3,3,3,2,2,1,1,1
1,1,1,2,2,3,3,3,3,3,3,3,3,3,3,3,2,2,1,1,1
1,1,1,1,2,2,3,3,3,3,3,3,3,3,3,2,2,1,1,1,1
1,1,1,1,2,2,2,3,3,3,3,3,3,3,2,2,2,1,1,1,1
1,1,1,1,1,2,2,2,2,2,3,2,2,2,2,2,1,1,1,1,1
1,1,1,1,1,1,1,2,2,2,2,2,2,2,1,1,1,1,1,1,1
1,1,1,1,1,1,1,1,1,1,1,1,1,1,1,1,1,1,1,1,1
1,1,1,1,1,1,1,1,1,1,1,1,1,1,1,1,1,1,1,1,1
1,1,1,1,1,1,1,1,1,1,1,1,1,1,1,1,1,1,1,1,1
endlayer

layer
1,1,1,1,1,1,1,1,1,1,1,1,1,1,1,1,1,1,1,1,1
1,1,1,1,1,1,1,1,1,1,1,1,1,1,1,1,1,1,1,1,1
1,1,1,1,1,1,1,1,1,1,1,1,1,1,1,1,1,1,1,1,1
1,1,1,1,1,1,1,1,1,1,1,1,1,1,1,1,1,1,1,1,1
1,1,1,1,1,1,1,2,2,2,2,2,2,2,1,1,1,1,1,1,1
1,1,1,1,1,1,2,2,2,2,2,2,2,2,2,1,1,1,1,1,1
1,1,1,1,1,2,2,2,3,3,3,3,3,2,2,2,1,1,1,1,1
1,1,1,1,2,2,2,3,3,3,3,3,3,3,2,2,2,1,1,1,1
1,1,1,1,2,2,3,3,3,3,3,3,3,3,3,2,2,1,1,1,1
1,1,1,1,2,2,3,3,3,3,3,3,3,3,3,2,2,1,1,1,1
1,1,1,1,2,2,3,3,3,3,3,3,3,3,3,2,2,1,1,1,1
1,1,1,1,2,2,3,3,3,3,3,3,3,3,3,2,2,1,1,1,1
1,1,1,1,2,2,3,3,3,3,3,3,3,3,3,2,2,1,1,1,1
1,1,1,1,2,2,2,3,3,3,3,3,3,3,2,2,2,1,1,1,1
1,1,1,1,1,2,2,2,3,3,3,3,3,2,2,2,1,1,1,1,1
1,1,1,1,1,1,2,2,2,2,2,2,2,2,2,1,1,1,1,1,1
1,1,1,1,1,1,1,2,2,2,2,2,2,2,1,1,1,1,1,1,1
1,1,1,1,1,1,1,1,1,1,1,1,1,1,1,1,1,1,1,1,1
1,1,1,1,1,1,1,1,1,1,1,1,1,1,1,1,1,1,1,1,1
1,1,1,1,1,1,1,1,1,1,1,1,1,1,1,1,1,1,1,1,1
1,1,1,1,1,1,1,1,1,1,1,1,1,1,1,1,1,1,1,1,1
endlayer

layer
1,1,1,1,1,1,1,1,1,1,1,1,1,1,1,1,1,1,1,1,1
1,1,1,1,1,1,1,1,1,1,1,1,1,1,1,1,1,1,1,1,1
1,1,1,1,1,1,1,1,1,1,1,1,1,1,1,1,1,1,1,1,1
1,1,1,1,1,1,1,1,1,1,1,1,1,1,1,1,1,1,1,1,1
1,1,1,1,1,1,1,1,1,1,1,1,1,1,1,1,1,1,1,1,1
1,1,1,1,1,1,1,1,2,2,2,2,2,1,1,1,1,1,1,1,1
1,1,1,1,1,1,1,2,2,2,2,2,2,2,1,1,1,1,1,1,1
1,1,1,1,1,1,2,2,2,2,2,2,2,2,2,1,1,1,1,1,1
1,1,1,1,1,2,2,2,3,3,3,3,3,2,2,2,1,1,1,1,1
1,1,1,1,1,2,2,2,3,3,3,3,3,2,2,2,1,1,1,1,1
1,1,1,1,1,2,2,2,3,3,3,3,3,2,2,2,1,1,1,1,1
1,1,1,1,1,2,2,2,3,3,3,3,3,2,2,2,1,1,1,1,1
1,1,1,1,1,2,2,2,3,3,3,3,3,2,2,2,1,1,1,1,1
1,1,1,1,1,1,2,2,2,2,2,2,2,2,2,1,1,1,1,1,1
1,1,1,1,1,1,1,2,2,2,2,2,2,2,1,1,1,1,1,1,1
1,1,1,1,1,1,1,1,2,2,2,2,2,1,1,1,1,1,1,1,1
1,1,1,1,1,1,1,1,1,1,1,1,1,1,1,1,1,1,1,1,1
1,1,1,1,1,1,1,1,1,1,1,1,1,1,1,1,1,1,1,1,1
1,1,1,1,1,1,1,1,1,1,1,1,1,1,1,1,1,1,1,1,1
1,1,1,1,1,1,1,1,1,1,1,1,1,1,1,1,1,1,1,1,1
1,1,1,1,1,1,1,1,1,1,1,1,1,1,1,1,1,1,1,1,1
endlayer

layer
1,1,1,1,1,1,1,1,1,1,1,1,1,1,1,1,1,1,1,1,1
1,1,1,1,1,1,1,1,1,1,1,1,1,1,1,1,1,1,1,1,1
1,1,1,1,1,1,1,1,1,1,1,1,1,1,1,1,1,1,1,1,1
1,1,1,1,1,1,1,1,1,1,1,1,1,1,1,1,1,1,1,1,1
1,1,1,1,1,1,1,1,1,1,1,1,1,1,1,1,1,1,1,1,1
1,1,1,1,1,1,1,1,1,1,1,1,1,1,1,1,1,1,1,1,1
1,1,1,1,1,1,1,1,1,1,1,1,1,1,1,1,1,1,1,1,1
1,1,1,1,1,1,1,1,1,1,1,1,1,1,1,1,1,1,1,1,1
1,1,1,1,1,1,1,1,2,2,2,2,2,1,1,1,1,1,1,1,1
1,1,1,1,1,1,1,1,2,2,2,2,2,1,1,1,1,1,1,1,1
1,1,1,1,1,1,1,1,2,2,3,2,2,1,1,1,1,1,1,1,1
1,1,1,1,1,1,1,1,2,2,2,2,2,1,1,1,1,1,1,1,1
1,1,1,1,1,1,1,1,2,2,2,2,2,1,1,1,1,1,1,1,1
1,1,1,1,1,1,1,1,1,1,1,1,1,1,1,1,1,1,1,1,1
1,1,1,1,1,1,1,1,1,1,1,1,1,1,1,1,1,1,1,1,1
1,1,1,1,1,1,1,1,1,1,1,1,1,1,1,1,1,1,1,1,1
1,1,1,1,1,1,1,1,1,1,1,1,1,1,1,1,1,1,1,1,1
1,1,1,1,1,1,1,1,1,1,1,1,1,1,1,1,1,1,1,1,1
1,1,1,1,1,1,1,1,1,1,1,1,1,1,1,1,1,1,1,1,1
1,1,1,1,1,1,1,1,1,1,1,1,1,1,1,1,1,1,1,1,1
1,1,1,1,1,1,1,1,1,1,1,1,1,1,1,1,1,1,1,1,1
endlayer

layer
1,1,1,1,1,1,1,1,1,1,1,1,1,1,1,1,1,1,1,1,1
1,1,1,1,1,1,1,1,1,1,1,1,1,1,1,1,1,1,1,1,1
1,1,1,1,1,1,1,1,1,1,1,1,1,1,1,1,1,1,1,1,1
1,1,1,1,1,1,1,1,1,1,1,1,1,1,1,1,1,1,1,1,1
1,1,1,1,1,1,1,1,1,1,1,1,1,1,1,1,1,1,1,1,1
1,1,1,1,1,1,1,1,1,1,1,1,1,1,1,1,1,1,1,1,1
1,1,1,1,1,1,1,1,1,1,1,1,1,1,1,1,1,1,1,1,1
1,1,1,1,1,1,1,1,1,1,1,1,1,1,1,1,1,1,1,1,1
1,1,1,1,1,1,1,1,1,1,1,1,1,1,1,1,1,1,1,1,1
1,1,1,1,1,1,1,1,1,2,2,2,1,1,1,1,1,1,1,1,1
1,1,1,1,1,1,1,1,1,2,3,2,1,1,1,1,1,1,1,1,1
1,1,1,1,1,1,1,1,1,2,2,2,1,1,1,1,1,1,1,1,1
1,1,1,1,1,1,1,1,1,1,1,1,1,1,1,1,1,1,1,1,1
1,1,1,1,1,1,1,1,1,1,1,1,1,1,1,1,1,1,1,1,1
1,1,1,1,1,1,1,1,1,1,1,1,1,1,1,1,1,1,1,1,1
1,1,1,1,1,1,1,1,1,1,1,1,1,1,1,1,1,1,1,1,1
1,1,1,1,1,1,1,1,1,1,1,1,1,1,1,1,1,1,1,1,1
1,1,1,1,1,1,1,1,1,1,1,1,1,1,1,1,1,1,1,1,1
1,1,1,1,1,1,1,1,1,1,1,1,1,1,1,1,1,1,1,1,1
1,1,1,1,1,1,1,1,1,1,1,1,1,1,1,1,1,1,1,1,1
1,1,1,1,1,1,1,1,1,1,1,1,1,1,1,1,1,1,1,1,1
endlayer

layer
1,1,1,1,1,1,1,1,1,1,1,1,1,1,1,1,1,1,1,1,1
1,1,1,1,1,1,1,1,1,1,1,1,1,1,1,1,1,1,1,1,1
1,1,1,1,1,1,1,1,1,1,1,1,1,1,1,1,1,1,1,1,1
1,1,1,1,1,1,1,1,1,1,1,1,1,1,1,1,1,1,1,1,1
1,1,1,1,1,1,1,1,1,1,1,1,1,1,1,1,1,1,1,1,1
1,1,1,1,1,1,1,1,1,1,1,1,1,1,1,1,1,1,1,1,1
1,1,1,1,1,1,1,1,1,1,1,1,1,1,1,1,1,1,1,1,1
1,1,1,1,1,1,1,1,1,1,1,1,1,1,1,1,1,1,1,1,1
1,1,1,1,1,1,1,1,1,2,2,2,1,1,1,1,1,1,1,1,1
1,1,1,1,1,1,1,1,2,2,2,2,2,1,1,1,1,1,1,1,1
1,1,1,1,1,1,1,1,2,2,3,2,2,1,1,1,1,1,1,1,1
1,1,1,1,1,1,1,1,2,2,2,2,2,1,1,1,1,1,1,1,1
1,1,1,1,1,1,1,1,1,2,2,2,1,1,1,1,1,1,1,1,1
1,1,1,1,1,1,1,1,1,1,1,1,1,1,1,1,1,1,1,1,1
1,1,1,1,1,1,1,1,1,1,1,1,1,1,1,1,1,1,1,1,1
1,1,1,1,1,1,1,1,1,1,1,1,1,1,1,1,1,1,1,1,1
1,1,1,1,1,1,1,1,1,1,1,1,1,1,1,1,1,1,1,1,1
1,1,1,1,1,1,1,1,1,1,1,1,1,1,1,1,1,1,1,1,1
1,1,1,1,1,1,1,1,1,1,1,1,1,1,1,1,1,1,1,1,1
1,1,1,1,1,1,1,1,1,1,1,1,1,1,1,1,1,1,1,1,1
1,1,1,1,1,1,1,1,1,1,1,1,1,1,1,1,1,1,1,1,1
endlayer

layer
1,1,1,1,1,1,1,1,1,1,1,1,1,1,1,1,1,1,1,1,1
1,1,1,1,1,1,1,1,1,1,1,1,1,1,1,1,1,1,1,1,1
1,1,1,1,1,1,1,1,1,1,1,1,1,1,1,1,1,1,1,1,1
1,1,1,1,1,1,1,1,1,1,1,1,1,1,1,1,1,1,1,1,1
1,1,1,1,1,1,1,1,1,1,1,1,1,1,1,1,1,1,1,1,1
1,1,1,1,1,1,1,1,1,1,1,1,1,1,1,1,1,1,1,1,1
1,1,1,1,1,1,1,1,1,1,1,1,1,1,1,1,1,1,1,1,1
1,1,1,1,1,1,1,1,1,2,2,2,1,1,1,1,1,1,1,1,1
1,1,1,1,1,1,1,1,2,2,2,2,2,1,1,1,1,1,1,1,1
1,1,1,1,1,1,1,2,2,3,3,3,2,2,2,1,1,1,1,1,1
1,1,1,1,1,1,1,1,2,3,3,3,2,2,2,1,1,1,1,1,1
1,1,1,1,1,1,1,1,2,3,3,3,2,2,2,1,1,1,1,1,1
1,1,1,1,1,1,1,1,1,2,2,2,1,1,1,1,1,1,1,1,1
1,1,1,1,1,1,1,1,1,1,1,1,1,1,1,1,1,1,1,1,1
1,1,1,1,1,1,1,1,1,1,1,1,1,1,1,1,1,1,1,1,1
1,1,1,1,1,1,1,1,1,1,1,1,1,1,1,1,1,1,1,1,1
1,1,1,1,1,1,1,1,1,1,1,1,1,1,1,1,1,1,1,1,1
1,1,1,1,1,1,1,1,1,1,1,1,1,1,1,1,1,1,1,1,1
1,1,1,1,1,1,1,1,1,1,1,1,1,1,1,1,1,1,1,1,1
1,1,1,1,1,1,1,1,1,1,1,1,1,1,1,1,1,1,1,1,1
1,1,1,1,1,1,1,1,1,1,1,1,1,1,1,1,1,1,1,1,1
endlayer

layer
1,1,1,1,1,1,1,1,1,1,1,1,1,1,1,1,1,1,1,1,1
1,1,1,1,1,1,1,1,1,1,1,1,1,1,1,1,1,1,1,1,1
1,1,1,1,1,1,1,1,1,1,1,1,1,1,1,1,1,1,1,1,1
1,1,1,1,1,1,1,1,1,1,1,1,1,1,1,1,1,1,1,1,1
1,1,1,1,1,1,1,1,1,1,1,1,1,1,1,1,1,1,1,1,1
1,1,1,1,1,1,1,1,1,1,1,1,1,1,1,1,1,1,1,1,1
1,1,1,1,1,1,1,1,1,2,2,2,1,1,1,1,1,1,1,1,1
1,1,1,1,1,1,1,1,2,2,2,2,2,2,2,1,1,1,1,1,1
1,1,1,1,1,1,1,2,2,3,3,3,2,2,2,2,1,1,1,1,1
1,1,1,1,1,1,2,2,3,3,3,3,3,3,3,2,2,1,1,1,1
1,1,1,1,1,1,1,2,2,3,3,3,3,3,3,2,2,1,1,1,1
1,1,1,1,1,1,1,2,2,3,3,3,3,3,3,2,2,1,1,1,1
1,1,1,1,1,1,1,1,2,2,2,2,2,2,2,2,1,1,1,1,1
1,1,1,1,1,1,1,1,1,2,2,2,2,2,2,1,1,1,1,1,1
1,1,1,1,1,1,1,1,1,1,1,1,1,1,1,1,1,1,1,1,1
1,1,1,1,1,1,1,1,1,1,1,1,1,1,1,1,1,1,1,1,1
1,1,1,1,1,1,1,1,1,1,1,1,1,1,1,1,1,1,1,1,1
1,1,1,1,1,1,1,1,1,1,1,1,1,1,1,1,1,1,1,1,1
1,1,1,1,1,1,1,1,1,1,1,1,1,1,1,1,1,1,1,1,1
1,1,1,1,1,1,1,1,1,1,1,1,1,1,1,1,1,1,1,1,1
1,1,1,1,1,1,1,1,1,1,1,1,1,1,1,1,1,1,1,1,1
endlayer

layer
1,1,1,1,1,1,1,1,1,1,1,1,1,1,1,1,1,1,1,1,1
1,1,1,1,1,1,1,1,1,1,1,1,1,1,1,1,1,1,1,1,1
1,1,1,1,1,1,1,1,1,1,1,1,1,1,1,1,1,1,1,1,1
1,1,1,1,1,1,1,1,1,1,1,1,1,1,1,1,1,1,1,1,1
1,1,1,1,1,1,1,1,1,1,1,1,1,1,1,1,1,1,1,1,1
1,1,1,1,1,1,1,1,1,2,2,2,1,1,1,1,1,1,1,1,1
1,1,1,1,1,1,1,1,2,2,2,2,2,2,2,1,1,1,1,1,1
1,1,1,1,1,1,1,2,2,3,3,3,2,2,2,2,1,1,1,1,1
1,1,1,1,1,1,2,2,3,3,3,3,3,3,3,2,2,1,1,1,1
1,1,1,1,1,2,2,3,3,3,3,3,3,3,3,3,2,2,1,1,1
1,1,1,1,1,1,2,2,3,3,3,3,3,3,3,3,2,2,1,1,1
1,1,1,1,1,1,2,2,3,3,3,3,3,3,3,3,2,2,1,1,1
1,1,1,1,1,1,1,2,2,3,3,3,3,3,3,2,2,1,1,1,1
1,1,1,1,1,1,1,1,2,2,2,2,2,2,2,2,1,1,1,1,1
1,1,1,1,1,1,1,1,1,2,2,2,2,2,2,1,1,1,1,1,1
1,1,1,1,1,1,1,1,1,1,1,1,1,1,1,1,1,1,1,1,1
1,1,1,1,1,1,1,1,1,1,1,1,1,1,1,1,1,1,1,1,1
1,1,1,1,1,1,1,1,1,1,1,1,1,1,1,1,1,1,1,1,1
1,1,1,1,1,1,1,1,1,1,1,1,1,1,1,1,1,1,1,1,1
1,1,1,1,1,1,1,1,1,1,1,1,1,1,1,1,1,1,1,1,1
1,1,1,1,1,1,1,1,1,1,1,1,1,1,1,1,1,1,1,1,1
endlayer

layer
1,1,1,1,1,1,1,1,1,1,1,1,1,1,1,1,1,1,1,1,1
1,1,1,1,1,1,1,1,1,1,1,1,1,1,1,1,1,1,1,1,1
1,1,1,1,1,1,1,1,1,1,1,1,1,1,1,1,1,1,1,1,1
1,1,1,1,1,1,1,1,1,1,1,1,1,1,1,1,1,1,1,1,1
1,1,1,1,1,1,1,1,1,2,2,2,1,1,1,1,1,1,1,1,1
1,1,1,1,1,1,1,1,2,2,2,2,2,2,2,1,1,1,1,1,1
1,1,1,1,1,1,1,2,2,3,3,3,2,2,2,2,1,1,1,1,1
1,1,1,1,1,1,2,2,3,3,3,3,3,3,3,2,2,1,1,1,1
1,1,1,1,1,2,2,3,3,3,3,3,3,3,3,3,2,2,1,1,1
1,1,1,1,1,2,3,3,3,3,3,3,3,3,3,3,3,2,2,1,1
1,1,1,1,1,2,2,3,3,3,3,3,3,3,3,3,3,2,2,1,1
1,1,1,1,1,2,2,3,3,3,3,3,3,3,3,3,3,2,2,1,1
1,1,1,1,1,1,2,2,3,3,3,3,3,3,3,3,2,2,1,1,1
1,1,1,1,1,1,1,2,2,3,3,3,3,3,3,2,2,1,1,1,1
1,1,1,1,1,1,1,2,2,2,2,2,2,2,2,2,1,1,1,1,1
1,1,1,1,1,1,1,1,2,2,2,2,2,2,2,1,1,1,1,1,1
1,1,1,1,1,1,1,1,1,1,1,1,1,1,1,1,1,1,1,1,1
1,1,1,1,1,1,1,1,1,1,1,1,1,1,1,1,1,1,1,1,1
1,1,1,1,1,1,1,1,1,1,1,1,1,1,1,1,1,1,1,1,1
1,1,1,1,1,1,1,1,1,1,1,1,1,1,1,1,1,1,1,1,1
1,1,1,1,1,1,1,1,1,1,1,1,1,1,1,1,1,1,1,1,1
endlayer

layer
4,4,4,4,4,4,4,4,4,4,4,4,4,4,4,4,4,4,4,4,4
4,4,4,4,4,4,4,4,4,4,4,4,4,4,4,4,4,4,4,4,4
4,4,4,4,4,4,4,4,4,4,4,4,4,4,4,4,4,4,4,4,4
4,4,4,4,4,4,4,4,4,4,4,4,4,4,4,4,4,4,4,4,4
4,4,4,4,4,4,4,4,4,2,2,2,4,4,4,4,4,4,4,4,4
4,4,4,4,4,4,4,4,2,3,3,3,2,2,2,4,4,4,4,4,4
4,4,4,4,4,4,4,2,3,3,3,3,3,3,3,2,4,4,4,4,4
4,4,4,4,4,4,2,3,3,3,3,3,3,3,3,3,2,4,4,4,4
4,4,4,4,4,2,3,3,3,3,3,3,3,3,3,3,3,2,4,4,4
4,4,4,4,4,2,3,3,3,3,3,3,3,3,3,3,3,3,2,4,4
4,4,4,4,4,2,3,3,3,3,3,3,3,3,3,3,3,3,2,4,4
4,4,4,4,4,2,3,3,3,3,3,3,3,3,3,3,3,3,2,4,4
4,4,4,4,4,4,2,3,3,3,3,3,3,3,3,3,3,2,4,4,4
4,4,4,4,4,4,4,2,3,3,3,3,3,3,3,3,2,4,4,4,4
4,4,4,4,4,4,4,2,3,3,3,3,3,3,3,2,4,4,4,4,4
4,4,4,4,4,4,4,4,2,2,2,2,2,2,2,4,4,4,4,4,4
4,4,4,4,4,4,4,4,4,4,4,4,4,4,4,4,4,4,4,4,4
4,4,4,4,4,4,4,4,4,4,4,4,4,4,4,4,4,4,4,4,4
4,4,4,4,4,4,4,4,4,4,4,4,4,4,4,4,4,4,4,4,4
4,4,4,4,4,4,4,4,4,4,4,4,4,4,4,4,4,4,4,4,4
4,4,4,4,4,4,4,4,4,4,4,4,4,4,4,4,4,4,4,4,4
endlayer

layer
0,0,0,0,0,0,0,0,0,0,0,0,0,0,0,0,0,0,0,0,0
0,0,0,0,0,0,0,0,0,0,0,0,0,0,0,0,0,0,0,0,0
0,0,0,0,0,0,0,0,0,0,0,0,0,0,0,0,0,0,0,0,0
0,0,0,0,0,0,0,0,0,0,0,0,0,0,0,0,0,0,0,0,0
0,0,0,0,0,0,0,0,0,0,0,0,0,0,0,0,0,0,0,0,0
0,0,0,0,0,0,0,0,0,0,0,0,0,0,0,0,0,0,0,0,0
0,0,0,0,0,0,0,0,0,0,0,0,0,0,0,0,0,0,0,0,0
0,0,0,0,0,0,0,0,0,0,0,0,0,0,0,0,0,0,0,0,0
0,0,0,0,0,0,0,0,0,0,0,0,0,0,0,0,0,0,0,0,0
0,0,0,0,0,0,0,0,0,0,3,0,0,0,0,0,0,0,0,0,0
0,0,0,0,0,0,0,0,0,3,3,3,0,0,0,0,0,0,0,0,0
0,0,0,0,0,0,0,0,0,0,3,0,0,0,0,0,0,0,0,0,0
0,0,0,0,0,0,0,0,0,0,0,0,0,0,0,0,0,0,0,0,0
0,0,0,0,0,0,0,0,0,0,0,0,0,0,0,0,0,0,0,0,0
0,0,0,0,0,0,0,0,0,0,0,0,0,0,0,0,0,0,0,0,0
0,0,0,0,0,0,0,0,0,0,0,0,0,0,0,0,0,0,0,0,0
0,0,0,0,0,0,0,0,0,0,0,0,0,0,0,0,0,0,0,0,0
0,0,0,0,0,0,0,0,0,0,0,0,0,0,0,0,0,0,0,0,0
0,0,0,0,0,0,0,0,0,0,0,0,0,0,0,0,0,0,0,0,0
0,0,0,0,0,0,0,0,0,0,0,0,0,0,0,0,0,0,0,0,0
0,0,0,0,0,0,0,0,0,0,0,0,0,0,0,0,0,0,0,0,0
endlayer

layer
0,0,0,0,0,0,0,0,0,0,0,0,0,0,0,0,0,0,0,0,0
0,0,0,0,0,0,0,0,0,0,0,0,0,0,0,0,0,0,0,0,0
0,0,0,0,0,0,0,0,0,0,0,0,0,0,0,0,0,0,0,0,0
0,0,0,0,0,0,0,0,0,0,0,0,0,0,0,0,0,0,0,0,0
0,0,0,0,0,0,0,0,0,0,0,0,0,0,0,0,0,0,0,0,0
0,0,0,0,0,0,0,0,0,0,0,0,0,0,0,0,0,0,0,0,0
0,0,0,0,0,0,0,0,0,0,0,0,0,0,0,0,0,0,0,0,0
0,0,0,0,0,0,0,0,0,0,0,0,0,0,0,0,0,0,0,0,0
0,0,0,0,0,0,0,0,0,0,0,0,0,0,0,0,0,0,0,0,0
0,0,0,0,0,0,0,0,0,0,0,0,0,0,0,0,0,0,0,0,0
0,0,0,0,0,0,0,0,0,0,3,0,0,0,0,0,0,0,0,0,0
0,0,0,0,0,0,0,0,0,0,0,0,0,0,0,0,0,0,0,0,0
0,0,0,0,0,0,0,0,0,0,0,0,0,0,0,0,0,0,0,0,0
0,0,0,0,0,0,0,0,0,0,0,0,0,0,0,0,0,0,0,0,0
0,0,0,0,0,0,0,0,0,0,0,0,0,0,0,0,0,0,0,0,0
0,0,0,0,0,0,0,0,0,0,0,0,0,0,0,0,0,0,0,0,0
0,0,0,0,0,0,0,0,0,0,0,0,0,0,0,0,0,0,0,0,0
0,0,0,0,0,0,0,0,0,0,0,0,0,0,0,0,0,0,0,0,0
0,0,0,0,0,0,0,0,0,0,0,0,0,0,0,0,0,0,0,0,0
0,0,0,0,0,0,0,0,0,0,0,0,0,0,0,0,0,0,0,0,0
0,0,0,0,0,0,0,0,0,0,0,0,0,0,0,0,0,0,0,0,0
endlayer

layer
0,0,0,0,0,0,0,0,0,0,0,0,0,0,0,0,0,0,0,0,0
0,0,0,0,0,0,0,0,0,0,0,0,0,0,0,0,0,0,0,0,0
0,0,0,0,0,0,0,0,0,0,0,0,0,0,0,0,0,0,0,0,0
0,0,0,0,0,0,0,0,0,0,0,0,0,0,0,0,0,0,0,0,0
0,0,0,0,0,0,0,0,0,0,0,0,0,0,0,0,0,0,0,0,0
0,0,0,0,0,0,0,0,0,0,0,0,0,0,0,0,0,0,0,0,0
0,0,0,0,0,0,0,0,0,0,0,0,0,0,0,0,0,0,0,0,0
0,0,0,0,0,0,0,0,0,0,0,0,0,0,0,0,0,0,0,0,0
0,0,0,0,0,0,0,0,0,0,0,0,0,0,0,0,0,0,0,0,0
0,0,0,0,0,0,0,0,0,0,0,0,0,0,0,0,0,0,0,0,0
0,0,0,0,0,0,0,0,0,0,3,0,0,0,0,0,0,0,0,0,0
0,0,0,0,0,0,0,0,0,0,0,0,0,0,0,0,0,0,0,0,0
0,0,0,0,0,0,0,0,0,0,0,0,0,0,0,0,0,0,0,0,0
0,0,0,0,0,0,0,0,0,0,0,0,0,0,0,0,0,0,0,0,0
0,0,0,0,0,0,0,0,0,0,0,0,0,0,0,0,0,0,0,0,0
0,0,0,0,0,0,0,0,0,0,0,0,0,0,0,0,0,0,0,0,0
0,0,0,0,0,0,0,0,0,0,0,0,0,0,0,0,0,0,0,0,0
0,0,0,0,0,0,0,0,0,0,0,0,0,0,0,0,0,0,0,0,0
0,0,0,0,0,0,0,0,0,0,0,0,0,0,0,0,0,0,0,0,0
0,0,0,0,0,0,0,0,0,0,0,0,0,0,0,0,0,0,0,0,0
0,0,0,0,0,0,0,0,0,0,0,0,0,0,0,0,0,0,0,0,0
endlayer

