
# Created by Ruins mod version 15.3 Ingame Parser
# authoring Player: Mensrea

weight=5
embed_into_distance=17
acceptable_target_blocks=
unacceptable_target_blocks=flowing_water,water,flowing_lava,lava
dimensions=21,25,25
allowable_overhang=0
max_leveling=2
leveling_buffer=0
preserve_water=0
preserve_lava=0
preventRotation=1

rule1=0,100,PFAAGeologica:strongStone-3
rule2=0,100,minecraft:stone-0
rule3=0,100,minecraft:stonebrick-0
rule4=0,100,MobSpawner:desertmobs.cryptzombie
rule5=0,100,minecraft:nether_brick-0
rule6=0,100,minecraft:dirt-0
rule7=0,100,minecraft:obsidian-0
rule8=0,100,minecraft:gold_block-0
rule9=0,100,ImmersiveEngineering:stoneSlab-2
rule10=0,100,ChestGenHook:pyramidDesertyChest:5-2
rule11=0,100,ChestGenHook:pyramidDesertyChest:5-3
rule12=0,100,minecraft:stonebrick-2
rule13=0,100,minecraft:stone_brick_stairs-3
rule14=0,100,ChestGenHook:pyramidDesertyChest:5-2
rule15=0,100,ChestGenHook:pyramidJungleChest:5-2
rule16=0,100,ChestGenHook:pyramidJungleChest:5-3
rule17=0,100,ChestGenHook:pyramidJungleChest:5-2
rule18=0,100,ChestGenHook:pyramidJungleChest:5-3
rule19=0,100,ChestGenHook:pyramidJungleChest:5-2
rule20=0,100,ChestGenHook:pyramidJungleChest:5-3
rule21=0,100,ImmersiveEngineering:storageSlab-7
rule22=0,100,minecraft:stone_brick_stairs-1
rule23=0,100,PFAAGeologica:strongStone-7
rule24=0,100,minecraft:stone_brick_stairs-2
rule25=0,100,minecraft:stone_brick_stairs-0
rule26=0,100,PFAAGeologica:mediumStone-3
rule27=0,100,PFAAGeologica:weakStone-1
rule28=0,100,minecraft:sand-1
rule29=0,100,minecraft:planks-3
rule30=0,100,IW:bush-0

layer
1,1,1,1,1,1,1,1,1,2,2,2,2,2,2,2,1,1,1,1,1,1,1,1,1
1,1,1,1,1,1,1,1,1,2,3,3,3,3,3,2,1,1,1,1,1,1,1,1,1
1,1,1,1,1,1,1,1,1,2,3,3,3,3,3,2,1,1,1,1,1,1,1,1,1
1,1,1,1,1,1,1,1,1,2,6,3,5,3,4,2,1,1,1,1,1,1,1,1,1
1,1,1,1,1,1,1,1,1,2,6,5,7,5,6,2,1,1,1,1,1,1,1,1,1
1,1,1,1,1,1,1,1,1,2,5,7,7,7,5,2,1,1,1,1,1,1,1,1,1
1,1,1,1,1,1,1,1,1,2,4,3,7,3,6,2,1,1,1,1,1,1,1,1,1
1,1,1,1,1,1,1,1,1,2,6,3,5,3,6,2,1,1,1,1,1,1,1,1,1
1,1,1,1,1,1,1,1,1,2,3,5,5,5,3,2,1,1,1,1,1,1,1,1,1
2,2,2,2,2,2,2,2,2,2,5,5,5,5,5,2,2,2,2,2,2,2,2,2,2
2,3,3,4,6,5,6,6,3,5,5,3,5,3,5,5,3,6,6,5,6,6,3,3,2
2,3,3,3,5,7,3,3,5,5,3,5,5,5,3,5,5,3,3,7,5,3,3,3,2
2,3,3,5,7,7,7,5,5,5,5,5,5,5,5,5,5,5,7,7,7,5,3,3,2
2,3,3,3,5,7,3,3,5,5,3,5,5,5,3,5,5,3,3,7,5,3,3,3,2
2,3,3,4,6,5,6,6,3,5,3,3,5,3,5,5,3,6,4,5,6,4,3,3,2
2,2,2,2,2,2,2,2,2,2,5,5,5,5,5,2,2,2,2,2,2,2,2,2,2
1,1,1,1,1,1,1,1,1,2,3,5,5,5,3,2,1,1,1,1,1,1,1,1,1
1,1,1,1,1,1,1,1,1,2,6,3,5,3,6,2,1,1,1,1,1,1,1,1,1
1,1,1,1,1,1,1,1,1,2,4,3,7,3,4,2,1,1,1,1,1,1,1,1,1
1,1,1,1,1,1,1,1,1,2,5,7,7,7,5,2,1,1,1,1,1,1,1,1,1
1,1,1,1,1,1,1,1,1,2,6,5,7,5,6,2,1,1,1,1,1,1,1,1,1
1,1,1,1,1,1,1,1,1,2,6,3,5,3,6,2,1,1,1,1,1,1,1,1,1
1,1,1,1,1,1,1,1,1,2,3,3,3,3,3,2,1,1,1,1,1,1,1,1,1
1,1,1,1,1,1,1,1,1,2,3,3,3,3,3,2,1,1,1,1,1,1,1,1,1
1,1,1,1,1,1,1,1,1,2,2,2,2,2,2,2,1,1,1,1,1,1,1,1,1
endlayer

layer
1,1,1,1,1,1,1,1,1,2,3,3,3,3,3,2,1,1,1,1,1,1,1,1,1
1,1,1,1,1,1,1,1,1,3,8,0,0,0,8,3,1,1,1,1,1,1,1,1,1
1,1,1,1,1,1,1,1,1,3,0,0,0,0,0,3,1,1,1,1,1,1,1,1,1
1,1,1,1,1,1,1,1,1,3,9,0,0,0,9,3,1,1,1,1,1,1,1,1,1
1,1,1,1,1,1,1,1,1,3,9,0,7,0,9,3,1,1,1,1,1,1,1,1,1
1,1,1,1,1,1,1,1,1,3,0,7,7,7,0,3,1,1,1,1,1,1,1,1,1
1,1,1,1,1,1,1,1,1,3,9,0,0,0,9,3,1,1,1,1,1,1,1,1,1
1,1,1,1,1,1,1,1,1,3,9,0,0,0,9,3,1,1,1,1,1,1,1,1,1
1,1,1,1,1,1,1,1,1,3,8,0,0,0,8,3,1,1,1,1,1,1,1,1,1
2,3,3,3,3,3,3,3,3,2,10,0,0,0,0,2,3,3,3,3,3,3,3,3,2
3,8,0,9,9,0,9,9,8,0,0,0,0,0,0,11,8,9,9,0,9,9,0,8,3
3,0,0,0,0,7,0,0,0,0,0,0,0,0,0,0,0,0,0,7,0,0,0,0,3
3,0,0,0,7,7,0,0,0,0,0,0,0,0,0,0,0,0,0,7,7,0,0,0,3
3,0,0,0,0,7,0,0,0,0,0,0,0,0,0,0,0,0,0,7,0,0,0,0,3
3,8,0,9,9,0,9,9,8,0,13,12,0,0,0,0,8,9,9,0,9,9,0,8,3
2,3,3,3,3,3,3,3,3,2,0,0,0,0,14,2,3,3,3,3,3,3,3,3,2
1,1,1,1,1,1,1,1,1,3,8,0,0,0,8,3,1,1,1,1,1,1,1,1,1
1,1,1,1,1,1,1,1,1,3,9,0,0,0,9,3,1,1,1,1,1,1,1,1,1
1,1,1,1,1,1,1,1,1,3,9,0,0,0,9,3,1,1,1,1,1,1,1,1,1
1,1,1,1,1,1,1,1,1,3,0,7,7,7,0,3,1,1,1,1,1,1,1,1,1
1,1,1,1,1,1,1,1,1,3,9,0,7,0,9,3,1,1,1,1,1,1,1,1,1
1,1,1,1,1,1,1,1,1,3,9,0,0,0,9,3,1,1,1,1,1,1,1,1,1
1,1,1,1,1,1,1,1,1,3,0,0,0,0,0,3,1,1,1,1,1,1,1,1,1
1,1,1,1,1,1,1,1,1,3,8,0,0,0,8,3,1,1,1,1,1,1,1,1,1
1,1,1,1,1,1,1,1,1,2,3,3,3,3,3,2,1,1,1,1,1,1,1,1,1
endlayer

layer
1,1,1,1,1,1,1,1,1,2,3,3,3,3,3,2,1,1,1,1,1,1,1,1,1
1,1,1,1,1,1,1,1,1,3,8,0,0,0,8,3,1,1,1,1,1,1,1,1,1
1,1,1,1,1,1,1,1,1,3,0,0,0,0,0,3,1,1,1,1,1,1,1,1,1
1,1,1,1,1,1,1,1,1,3,0,0,0,0,0,3,1,1,1,1,1,1,1,1,1
1,1,1,1,1,1,1,1,1,3,0,0,15,0,0,3,1,1,1,1,1,1,1,1,1
1,1,1,1,1,1,1,1,1,3,0,7,16,7,0,3,1,1,1,1,1,1,1,1,1
1,1,1,1,1,1,1,1,1,3,0,0,0,0,0,3,1,1,1,1,1,1,1,1,1
1,1,1,1,1,1,1,1,1,3,0,0,0,0,0,3,1,1,1,1,1,1,1,1,1
1,1,1,1,1,1,1,1,1,3,8,0,0,0,8,3,1,1,1,1,1,1,1,1,1
2,3,3,3,3,3,3,3,3,2,0,0,0,0,0,2,3,3,3,3,3,3,3,3,2
3,8,0,0,0,0,0,0,8,0,0,0,0,0,0,0,8,0,0,0,0,0,0,8,3
3,0,0,0,0,7,0,0,0,0,0,0,0,0,0,0,0,0,0,7,0,0,0,0,3
3,0,0,0,18,17,0,0,0,0,0,0,0,0,0,0,0,0,0,18,17,0,0,0,3
3,0,0,0,0,7,0,0,0,0,0,0,0,0,0,0,0,0,0,7,0,0,0,0,3
3,8,0,0,0,0,0,0,8,0,0,13,12,0,0,0,8,0,0,0,0,0,0,8,3
2,3,3,3,3,3,3,3,3,2,0,0,0,0,0,2,3,3,3,3,3,3,3,3,2
1,1,1,1,1,1,1,1,1,3,8,0,0,0,8,3,1,1,1,1,1,1,1,1,1
1,1,1,1,1,1,1,1,1,3,0,0,0,0,0,3,1,1,1,1,1,1,1,1,1
1,1,1,1,1,1,1,1,1,3,0,0,0,0,0,3,1,1,1,1,1,1,1,1,1
1,1,1,1,1,1,1,1,1,3,0,7,19,7,0,3,1,1,1,1,1,1,1,1,1
1,1,1,1,1,1,1,1,1,3,0,0,20,0,0,3,1,1,1,1,1,1,1,1,1
1,1,1,1,1,1,1,1,1,3,0,0,0,0,0,3,1,1,1,1,1,1,1,1,1
1,1,1,1,1,1,1,1,1,3,0,0,0,0,0,3,1,1,1,1,1,1,1,1,1
1,1,1,1,1,1,1,1,1,3,8,0,0,0,8,3,1,1,1,1,1,1,1,1,1
1,1,1,1,1,1,1,1,1,2,3,3,3,3,3,2,1,1,1,1,1,1,1,1,1
endlayer

layer
1,1,1,1,1,1,1,1,1,2,3,3,3,3,3,2,1,1,1,1,1,1,1,1,1
1,1,1,1,1,1,1,1,1,3,8,0,0,0,8,3,1,1,1,1,1,1,1,1,1
1,1,1,1,1,1,1,1,1,3,0,0,0,0,0,3,1,1,1,1,1,1,1,1,1
1,1,1,1,1,1,1,1,1,3,0,0,0,0,0,3,1,1,1,1,1,1,1,1,1
1,1,1,1,1,1,1,1,1,3,0,0,21,0,0,3,1,1,1,1,1,1,1,1,1
1,1,1,1,1,1,1,1,1,3,0,0,21,0,0,3,1,1,1,1,1,1,1,1,1
1,1,1,1,1,1,1,1,1,3,0,0,0,0,0,3,1,1,1,1,1,1,1,1,1
1,1,1,1,1,1,1,1,1,3,0,0,0,0,0,3,1,1,1,1,1,1,1,1,1
1,1,1,1,1,1,1,1,1,3,8,0,0,0,8,3,1,1,1,1,1,1,1,1,1
2,3,3,3,3,3,3,3,3,2,0,0,0,0,0,2,3,3,3,3,3,3,3,3,2
3,8,0,0,0,0,0,0,8,0,0,0,0,0,0,0,8,0,0,0,0,0,0,8,3
3,0,0,0,0,0,0,0,0,0,0,0,0,0,0,0,0,0,0,0,0,0,0,0,3
3,0,0,0,21,21,0,0,0,0,0,0,0,0,0,0,0,0,0,21,21,0,0,0,3
3,0,0,0,0,0,0,0,0,0,0,0,0,0,0,0,0,0,0,0,0,0,0,0,3
3,8,0,0,0,0,0,0,8,0,0,0,13,12,0,0,8,0,0,0,0,0,0,8,3
2,3,3,3,3,3,3,3,3,2,0,0,0,0,0,2,3,3,3,3,3,3,3,3,2
1,1,1,1,1,1,1,1,1,3,8,0,0,0,8,3,1,1,1,1,1,1,1,1,1
1,1,1,1,1,1,1,1,1,3,0,0,0,0,0,3,1,1,1,1,1,1,1,1,1
1,1,1,1,1,1,1,1,1,3,0,0,0,0,0,3,1,1,1,1,1,1,1,1,1
1,1,1,1,1,1,1,1,1,3,0,0,21,0,0,3,1,1,1,1,1,1,1,1,1
1,1,1,1,1,1,1,1,1,3,0,0,21,0,0,3,1,1,1,1,1,1,1,1,1
1,1,1,1,1,1,1,1,1,3,0,0,0,0,0,3,1,1,1,1,1,1,1,1,1
1,1,1,1,1,1,1,1,1,3,0,0,0,0,0,3,1,1,1,1,1,1,1,1,1
1,1,1,1,1,1,1,1,1,3,8,0,0,0,8,3,1,1,1,1,1,1,1,1,1
1,1,1,1,1,1,1,1,1,2,3,3,3,3,3,2,1,1,1,1,1,1,1,1,1
endlayer

layer
1,1,1,1,1,1,1,1,1,2,2,2,2,2,2,2,1,1,1,1,1,1,1,1,1
1,1,1,1,1,1,1,1,1,2,7,7,7,7,7,2,1,1,1,1,1,1,1,1,1
1,1,1,1,1,1,1,1,1,2,7,7,0,7,7,2,1,1,1,1,1,1,1,1,1
1,1,1,1,1,1,1,1,1,2,7,0,0,0,7,2,1,1,1,1,1,1,1,1,1
1,1,1,1,1,1,1,1,1,2,7,0,0,0,7,2,1,1,1,1,1,1,1,1,1
1,1,1,1,1,1,1,1,1,2,7,0,0,0,7,2,1,1,1,1,1,1,1,1,1
1,1,1,1,1,1,1,1,1,2,7,0,0,0,7,2,1,1,1,1,1,1,1,1,1
1,1,1,1,1,1,1,1,1,2,7,7,0,7,7,2,1,1,1,1,1,1,1,1,1
1,1,1,1,1,1,1,1,1,2,7,7,7,7,7,2,1,1,1,1,1,1,1,1,1
2,2,2,2,2,2,2,2,2,2,2,2,2,2,2,2,2,2,2,2,2,2,2,2,2
2,7,7,7,7,7,7,7,7,2,0,0,0,0,0,2,7,7,7,7,7,7,7,7,2
2,7,7,0,0,0,0,7,7,2,0,0,0,0,0,2,7,7,0,0,0,0,7,7,2
2,7,0,0,0,0,0,0,7,2,0,0,0,0,0,2,7,0,0,0,0,0,0,7,2
2,7,7,0,0,0,0,7,7,2,0,0,0,0,12,2,7,7,0,0,0,0,7,7,2
2,7,7,7,7,7,7,7,7,2,0,0,0,13,12,2,7,7,7,7,7,7,7,7,2
2,2,2,2,2,2,2,2,2,2,2,2,2,2,2,2,2,2,2,2,2,2,2,2,2
1,1,1,1,1,1,1,1,1,2,7,7,7,7,7,2,1,1,1,1,1,1,1,1,1
1,1,1,1,1,1,1,1,1,2,7,7,0,7,7,2,1,1,1,1,1,1,1,1,1
1,1,1,1,1,1,1,1,1,2,7,0,0,0,7,2,1,1,1,1,1,1,1,1,1
1,1,1,1,1,1,1,1,1,2,7,0,0,0,7,2,1,1,1,1,1,1,1,1,1
1,1,1,1,1,1,1,1,1,2,7,0,0,0,7,2,1,1,1,1,1,1,1,1,1
1,1,1,1,1,1,1,1,1,2,7,0,0,0,7,2,1,1,1,1,1,1,1,1,1
1,1,1,1,1,1,1,1,1,2,7,7,0,7,7,2,1,1,1,1,1,1,1,1,1
1,1,1,1,1,1,1,1,1,2,7,7,7,7,7,2,1,1,1,1,1,1,1,1,1
1,1,1,1,1,1,1,1,1,2,2,2,2,2,2,2,1,1,1,1,1,1,1,1,1
endlayer

layer
1,1,1,1,1,1,1,1,1,1,1,1,1,1,1,1,1,1,1,1,1,1,1,1,1
1,1,1,1,1,1,1,1,1,1,1,1,1,1,1,1,1,1,1,1,1,1,1,1,1
1,1,1,1,1,1,1,1,1,1,1,7,7,7,1,1,1,1,1,1,1,1,1,1,1
1,1,1,1,1,1,1,1,1,1,1,7,7,7,1,1,1,1,1,1,1,1,1,1,1
1,1,1,1,1,1,1,1,1,1,1,7,7,7,1,1,1,1,1,1,1,1,1,1,1
1,1,1,1,1,1,1,1,1,1,1,7,7,7,1,1,1,1,1,1,1,1,1,1,1
1,1,1,1,1,1,1,1,1,1,1,7,7,7,1,1,1,1,1,1,1,1,1,1,1
1,1,1,1,1,1,1,1,1,1,1,7,7,7,1,1,1,1,1,1,1,1,1,1,1
1,1,1,1,1,1,1,1,1,1,1,1,1,1,1,1,1,1,1,1,1,1,1,1,1
1,1,1,1,1,1,1,1,1,2,3,3,3,3,3,2,1,1,1,1,1,1,1,1,1
1,1,1,1,1,1,1,1,1,3,0,0,0,0,0,3,1,1,1,1,1,1,1,1,1
1,1,7,7,7,7,7,7,1,3,0,0,0,0,0,3,1,7,7,7,7,7,7,1,1
1,1,7,7,7,7,7,7,1,3,0,0,0,0,12,3,1,7,7,7,7,7,7,1,1
1,1,7,7,7,7,7,7,1,3,0,0,0,0,22,3,1,7,7,7,7,7,7,1,1
1,1,1,1,1,1,1,1,1,3,0,0,0,0,0,3,1,1,1,1,1,1,1,1,1
1,1,1,1,1,1,1,1,1,2,3,3,3,3,3,2,1,1,1,1,1,1,1,1,1
1,1,1,1,1,1,1,1,1,1,1,1,1,1,1,1,1,1,1,1,1,1,1,1,1
1,1,1,1,1,1,1,1,1,1,1,7,7,7,1,1,1,1,1,1,1,1,1,1,1
1,1,1,1,1,1,1,1,1,1,1,7,7,7,1,1,1,1,1,1,1,1,1,1,1
1,1,1,1,1,1,1,1,1,1,1,7,7,7,1,1,1,1,1,1,1,1,1,1,1
1,1,1,1,1,1,1,1,1,1,1,7,7,7,1,1,1,1,1,1,1,1,1,1,1
1,1,1,1,1,1,1,1,1,1,1,7,7,7,1,1,1,1,1,1,1,1,1,1,1
1,1,1,1,1,1,1,1,1,1,1,7,7,7,1,1,1,1,1,1,1,1,1,1,1
1,1,1,1,1,1,1,1,1,1,1,1,1,1,1,1,1,1,1,1,1,1,1,1,1
1,1,1,1,1,1,1,1,1,1,1,1,1,1,1,1,1,1,1,1,1,1,1,1,1
endlayer

layer
1,1,1,1,1,1,1,1,1,1,1,1,1,1,1,1,1,1,1,1,1,1,1,1,1
1,1,1,1,1,1,1,1,1,1,1,1,1,1,1,1,1,1,1,1,1,1,1,1,1
1,1,1,1,1,1,1,1,1,1,1,1,1,1,1,1,1,1,1,1,1,1,1,1,1
1,1,1,1,1,1,1,1,1,1,1,1,1,1,1,1,1,1,1,1,1,1,1,1,1
1,1,1,1,1,1,1,1,1,1,1,1,1,1,1,1,1,1,1,1,1,1,1,1,1
1,1,1,1,1,1,1,1,1,1,1,1,1,1,1,1,1,1,1,1,1,1,1,1,1
1,1,1,1,1,1,1,1,1,1,1,1,1,1,1,1,1,1,1,1,1,1,1,1,1
1,1,1,1,1,1,1,1,1,1,1,1,1,1,1,1,1,1,1,1,1,1,1,1,1
1,1,1,1,1,1,1,1,1,1,1,1,1,1,1,1,1,1,1,1,1,1,1,1,1
1,1,1,1,1,1,1,1,1,2,3,3,3,3,3,2,1,1,1,1,1,1,1,1,1
1,1,1,1,1,1,1,1,1,3,0,0,0,0,0,3,1,1,1,1,1,1,1,1,1
1,1,1,1,1,1,1,1,1,3,0,0,0,0,12,3,1,1,1,1,1,1,1,1,1
1,1,1,1,1,1,1,1,1,3,0,0,0,0,22,3,1,1,1,1,1,1,1,1,1
1,1,1,1,1,1,1,1,1,3,0,0,0,0,0,3,1,1,1,1,1,1,1,1,1
1,1,1,1,1,1,1,1,1,3,0,0,0,0,0,3,1,1,1,1,1,1,1,1,1
1,1,1,1,1,1,1,1,1,2,3,3,3,3,3,2,1,1,1,1,1,1,1,1,1
1,1,1,1,1,1,1,1,1,1,1,1,1,1,1,1,1,1,1,1,1,1,1,1,1
1,1,1,1,1,1,1,1,1,1,1,1,1,1,1,1,1,1,1,1,1,1,1,1,1
1,1,1,1,1,1,1,1,1,1,1,1,1,1,1,1,1,1,1,1,1,1,1,1,1
1,1,1,1,1,1,1,1,1,1,1,1,1,1,1,1,1,1,1,1,1,1,1,1,1
1,1,1,1,1,1,1,1,1,1,1,1,1,1,1,1,1,1,1,1,1,1,1,1,1
1,1,1,1,1,1,1,1,1,1,1,1,1,1,1,1,1,1,1,1,1,1,1,1,1
1,1,1,1,1,1,1,1,1,1,1,1,1,1,1,1,1,1,1,1,1,1,1,1,1
1,1,1,1,1,1,1,1,1,1,1,1,1,1,1,1,1,1,1,1,1,1,1,1,1
1,1,1,1,1,1,1,1,1,1,1,1,1,1,1,1,1,1,1,1,1,1,1,1,1
endlayer

layer
1,1,1,1,1,1,1,1,1,1,1,1,1,1,1,1,1,1,1,1,1,1,1,1,1
1,1,1,1,1,1,1,1,1,1,1,1,1,1,1,1,1,1,1,1,1,1,1,1,1
1,1,1,1,1,1,1,1,1,1,1,1,1,1,1,1,1,1,1,1,1,1,1,1,1
1,1,1,1,1,1,1,1,1,1,1,1,1,1,1,1,1,1,1,1,1,1,1,1,1
1,1,1,1,1,1,1,1,1,1,1,1,1,1,1,1,1,1,1,1,1,1,1,1,1
1,1,1,1,1,1,1,1,1,1,1,1,1,1,1,1,1,1,1,1,1,1,1,1,1
1,1,1,1,1,1,1,1,1,1,1,1,1,1,1,1,1,1,1,1,1,1,1,1,1
1,1,1,1,1,1,1,1,1,1,1,1,1,1,1,1,1,1,1,1,1,1,1,1,1
1,1,1,1,1,1,1,1,1,1,1,1,1,1,1,1,1,1,1,1,1,1,1,1,1
1,1,1,1,1,1,1,1,1,2,3,3,3,3,3,2,1,1,1,1,1,1,1,1,1
1,1,1,1,1,1,1,1,1,3,0,0,0,12,12,3,1,1,1,1,1,1,1,1,1
1,1,1,1,1,1,1,1,1,3,0,0,0,0,22,3,1,1,1,1,1,1,1,1,1
1,1,1,1,1,1,1,1,1,3,0,0,0,0,0,3,1,1,1,1,1,1,1,1,1
1,1,1,1,1,1,1,1,1,3,0,0,0,0,0,3,1,1,1,1,1,1,1,1,1
1,1,1,1,1,1,1,1,1,3,0,0,0,0,0,3,1,1,1,1,1,1,1,1,1
1,1,1,1,1,1,1,1,1,2,3,3,3,3,3,2,1,1,1,1,1,1,1,1,1
1,1,1,1,1,1,1,1,1,1,1,1,1,1,1,1,1,1,1,1,1,1,1,1,1
1,1,1,1,1,1,1,1,1,1,1,1,1,1,1,1,1,1,1,1,1,1,1,1,1
1,1,1,1,1,1,1,1,1,1,1,1,1,1,1,1,1,1,1,1,1,1,1,1,1
1,1,1,1,1,1,1,1,1,1,1,1,1,1,1,1,1,1,1,1,1,1,1,1,1
1,1,1,1,1,1,1,1,1,1,1,1,1,1,1,1,1,1,1,1,1,1,1,1,1
1,1,1,1,1,1,1,1,1,1,1,1,1,1,1,1,1,1,1,1,1,1,1,1,1
1,1,1,1,1,1,1,1,1,1,1,1,1,1,1,1,1,1,1,1,1,1,1,1,1
1,1,1,1,1,1,1,1,1,1,1,1,1,1,1,1,1,1,1,1,1,1,1,1,1
1,1,1,1,1,1,1,1,1,1,1,1,1,1,1,1,1,1,1,1,1,1,1,1,1
endlayer

layer
23,23,23,23,23,23,23,23,23,23,23,23,23,23,23,23,23,23,23,23,23,23,23,23,23
23,23,23,23,23,23,23,23,23,23,23,23,23,23,23,23,23,23,23,23,23,23,23,23,23
23,23,23,23,23,23,23,23,23,23,23,23,23,23,23,23,23,23,23,23,23,23,23,23,23
23,23,23,23,23,23,23,23,23,23,23,23,23,23,23,23,23,23,23,23,23,23,23,23,23
23,23,23,23,23,23,23,23,23,23,23,23,23,23,23,23,23,23,23,23,23,23,23,23,23
23,23,23,23,23,23,23,23,23,23,23,23,23,23,23,23,23,23,23,23,23,23,23,23,23
23,23,23,23,23,23,23,23,23,23,23,23,23,23,23,23,23,23,23,23,23,23,23,23,23
23,23,23,23,23,23,23,23,23,23,23,23,23,23,23,23,23,23,23,23,23,23,23,23,23
23,23,23,23,23,23,23,23,23,23,23,23,23,23,23,23,23,23,23,23,23,23,23,23,23
23,23,23,23,23,23,23,23,23,2,3,3,3,3,3,2,23,23,23,23,23,23,23,23,23
23,23,23,23,23,23,23,23,23,3,0,0,12,24,0,3,23,23,23,23,23,23,23,23,23
23,23,23,23,23,23,23,23,23,3,0,0,0,0,0,3,23,23,23,23,23,23,23,23,23
23,23,23,23,23,23,23,23,23,3,0,0,0,0,0,3,23,23,23,23,23,23,23,23,23
23,23,23,23,23,23,23,23,23,3,0,0,0,0,0,3,23,23,23,23,23,23,23,23,23
23,23,23,23,23,23,23,23,23,3,0,0,0,0,0,3,23,23,23,23,23,23,23,23,23
23,23,23,23,23,23,23,23,23,2,3,3,3,3,3,2,23,23,23,23,23,23,23,23,23
23,23,23,23,23,23,23,23,23,23,23,23,23,23,23,23,23,23,23,23,23,23,23,23,23
23,23,23,23,23,23,23,23,23,23,23,23,23,23,23,23,23,23,23,23,23,23,23,23,23
23,23,23,23,23,23,23,23,23,23,23,23,23,23,23,23,23,23,23,23,23,23,23,23,23
23,23,23,23,23,23,23,23,23,23,23,23,23,23,23,23,23,23,23,23,23,23,23,23,23
23,23,23,23,23,23,23,23,23,23,23,23,23,23,23,23,23,23,23,23,23,23,23,23,23
23,23,23,23,23,23,23,23,23,23,23,23,23,23,23,23,23,23,23,23,23,23,23,23,23
23,23,23,23,23,23,23,23,23,23,23,23,23,23,23,23,23,23,23,23,23,23,23,23,23
23,23,23,23,23,23,23,23,23,23,23,23,23,23,23,23,23,23,23,23,23,23,23,23,23
23,23,23,23,23,23,23,23,23,23,23,23,23,23,23,23,23,23,23,23,23,23,23,23,23
endlayer

layer
23,23,23,23,23,23,23,23,23,23,23,23,23,23,23,23,23,23,23,23,23,23,23,23,23
23,23,23,23,23,23,23,23,23,23,23,23,23,23,23,23,23,23,23,23,23,23,23,23,23
23,23,23,23,23,23,23,23,23,23,23,23,23,23,23,23,23,23,23,23,23,23,23,23,23
23,23,23,23,23,23,23,23,23,23,23,23,23,23,23,23,23,23,23,23,23,23,23,23,23
23,23,23,23,23,23,23,23,23,23,23,23,23,23,23,23,23,23,23,23,23,23,23,23,23
23,23,23,23,23,23,23,23,23,23,23,23,23,23,23,23,23,23,23,23,23,23,23,23,23
23,23,23,23,23,23,23,23,23,23,23,23,23,23,23,23,23,23,23,23,23,23,23,23,23
23,23,23,23,23,23,23,23,23,23,23,23,23,23,23,23,23,23,23,23,23,23,23,23,23
23,23,23,23,23,23,23,23,23,23,23,23,23,23,23,23,23,23,23,23,23,23,23,23,23
23,23,23,23,23,23,23,23,23,2,3,3,3,3,3,2,23,23,23,23,23,23,23,23,23
23,23,23,23,23,23,23,23,23,3,0,12,24,0,0,3,23,23,23,23,23,23,23,23,23
23,23,23,23,23,23,23,23,23,3,0,0,0,0,0,3,23,23,23,23,23,23,23,23,23
23,23,23,23,23,23,23,23,23,3,0,0,0,0,0,3,23,23,23,23,23,23,23,23,23
23,23,23,23,23,23,23,23,23,3,0,0,0,0,0,3,23,23,23,23,23,23,23,23,23
23,23,23,23,23,23,23,23,23,3,0,0,0,0,0,3,23,23,23,23,23,23,23,23,23
23,23,23,23,23,23,23,23,23,2,3,3,3,3,3,2,23,23,23,23,23,23,23,23,23
23,23,23,23,23,23,23,23,23,23,23,23,23,23,23,23,23,23,23,23,23,23,23,23,23
23,23,23,23,23,23,23,23,23,23,23,23,23,23,23,23,23,23,23,23,23,23,23,23,23
23,23,23,23,23,23,23,23,23,23,23,23,23,23,23,23,23,23,23,23,23,23,23,23,23
23,23,23,23,23,23,23,23,23,23,23,23,23,23,23,23,23,23,23,23,23,23,23,23,23
23,23,23,23,23,23,23,23,23,23,23,23,23,23,23,23,23,23,23,23,23,23,23,23,23
23,23,23,23,23,23,23,23,23,23,23,23,23,23,23,23,23,23,23,23,23,23,23,23,23
23,23,23,23,23,23,23,23,23,23,23,23,23,23,23,23,23,23,23,23,23,23,23,23,23
23,23,23,23,23,23,23,23,23,23,23,23,23,23,23,23,23,23,23,23,23,23,23,23,23
23,23,23,23,23,23,23,23,23,23,23,23,23,23,23,23,23,23,23,23,23,23,23,23,23
endlayer

layer
23,23,23,23,23,23,23,23,23,23,23,23,23,23,23,23,23,23,23,23,23,23,23,23,23
23,23,23,23,23,23,23,23,23,23,23,23,23,23,23,23,23,23,23,23,23,23,23,23,23
23,23,23,23,23,23,23,23,23,23,23,23,23,23,23,23,23,23,23,23,23,23,23,23,23
23,23,23,23,23,23,23,23,23,23,23,23,23,23,23,23,23,23,23,23,23,23,23,23,23
23,23,23,23,23,23,23,23,23,23,23,23,23,23,23,23,23,23,23,23,23,23,23,23,23
23,23,23,23,23,23,23,23,23,23,23,23,23,23,23,23,23,23,23,23,23,23,23,23,23
23,23,23,23,23,23,23,23,23,23,23,23,23,23,23,23,23,23,23,23,23,23,23,23,23
23,23,23,23,23,23,23,23,23,23,23,23,23,23,23,23,23,23,23,23,23,23,23,23,23
23,23,23,23,23,23,23,23,23,23,23,23,23,23,23,23,23,23,23,23,23,23,23,23,23
23,23,23,23,23,23,23,23,23,2,3,3,3,3,3,2,23,23,23,23,23,23,23,23,23
23,23,23,23,23,23,23,23,23,3,12,24,0,0,0,3,23,23,23,23,23,23,23,23,23
23,23,23,23,23,23,23,23,23,3,12,0,0,0,0,3,23,23,23,23,23,23,23,23,23
23,23,23,23,23,23,23,23,23,3,0,0,0,0,0,3,23,23,23,23,23,23,23,23,23
23,23,23,23,23,23,23,23,23,3,0,0,0,0,0,3,23,23,23,23,23,23,23,23,23
23,23,23,23,23,23,23,23,23,3,0,0,0,0,0,3,23,23,23,23,23,23,23,23,23
23,23,23,23,23,23,23,23,23,2,3,3,3,3,3,2,23,23,23,23,23,23,23,23,23
23,23,23,23,23,23,23,23,23,23,23,23,23,23,23,23,23,23,23,23,23,23,23,23,23
23,23,23,23,23,23,23,23,23,23,23,23,23,23,23,23,23,23,23,23,23,23,23,23,23
23,23,23,23,23,23,23,23,23,23,23,23,23,23,23,23,23,23,23,23,23,23,23,23,23
23,23,23,23,23,23,23,23,23,23,23,23,23,23,23,23,23,23,23,23,23,23,23,23,23
23,23,23,23,23,23,23,23,23,23,23,23,23,23,23,23,23,23,23,23,23,23,23,23,23
23,23,23,23,23,23,23,23,23,23,23,23,23,23,23,23,23,23,23,23,23,23,23,23,23
23,23,23,23,23,23,23,23,23,23,23,23,23,23,23,23,23,23,23,23,23,23,23,23,23
23,23,23,23,23,23,23,23,23,23,23,23,23,23,23,23,23,23,23,23,23,23,23,23,23
23,23,23,23,23,23,23,23,23,23,23,23,23,23,23,23,23,23,23,23,23,23,23,23,23
endlayer

layer
23,23,23,23,23,23,23,23,23,23,23,23,23,23,23,23,23,23,23,23,23,23,23,23,23
23,23,23,23,23,23,23,23,23,23,23,23,23,23,23,23,23,23,23,23,23,23,23,23,23
23,23,23,23,23,23,23,23,23,23,23,23,23,23,23,23,23,23,23,23,23,23,23,23,23
23,23,23,23,23,23,23,23,23,23,23,23,23,23,23,23,23,23,23,23,23,23,23,23,23
23,23,23,23,23,23,23,23,23,23,23,23,23,23,23,23,23,23,23,23,23,23,23,23,23
23,23,23,23,23,23,23,23,23,23,23,23,23,23,23,23,23,23,23,23,23,23,23,23,23
23,23,23,23,23,23,23,23,23,23,23,23,23,23,23,23,23,23,23,23,23,23,23,23,23
23,23,23,23,23,23,23,23,23,23,23,23,23,23,23,23,23,23,23,23,23,23,23,23,23
23,23,23,23,23,23,23,23,23,23,23,23,23,23,23,23,23,23,23,23,23,23,23,23,23
23,23,23,23,23,23,23,23,23,2,3,3,3,3,3,2,23,23,23,23,23,23,23,23,23
23,23,23,23,23,23,23,23,23,3,0,0,0,0,0,3,23,23,23,23,23,23,23,23,23
23,23,23,23,23,23,23,23,23,3,25,0,0,0,0,3,23,23,23,23,23,23,23,23,23
23,23,23,23,23,23,23,23,23,3,12,0,0,0,0,3,23,23,23,23,23,23,23,23,23
23,23,23,23,23,23,23,23,23,3,0,0,0,0,0,3,23,23,23,23,23,23,23,23,23
23,23,23,23,23,23,23,23,23,3,0,0,0,0,0,3,23,23,23,23,23,23,23,23,23
23,23,23,23,23,23,23,23,23,2,3,3,3,3,3,2,23,23,23,23,23,23,23,23,23
23,23,23,23,23,23,23,23,23,23,23,23,23,23,23,23,23,23,23,23,23,23,23,23,23
23,23,23,23,23,23,23,23,23,23,23,23,23,23,23,23,23,23,23,23,23,23,23,23,23
23,23,23,23,23,23,23,23,23,23,23,23,23,23,23,23,23,23,23,23,23,23,23,23,23
23,23,23,23,23,23,23,23,23,23,23,23,23,23,23,23,23,23,23,23,23,23,23,23,23
23,23,23,23,23,23,23,23,23,23,23,23,23,23,23,23,23,23,23,23,23,23,23,23,23
23,23,23,23,23,23,23,23,23,23,23,23,23,23,23,23,23,23,23,23,23,23,23,23,23
23,23,23,23,23,23,23,23,23,23,23,23,23,23,23,23,23,23,23,23,23,23,23,23,23
23,23,23,23,23,23,23,23,23,23,23,23,23,23,23,23,23,23,23,23,23,23,23,23,23
23,23,23,23,23,23,23,23,23,23,23,23,23,23,23,23,23,23,23,23,23,23,23,23,23
endlayer

layer
26,26,26,26,26,26,26,26,26,26,26,26,26,26,26,26,26,26,26,26,26,26,26,26,26
26,26,26,26,26,26,26,26,26,26,26,26,26,26,26,26,26,26,26,26,26,26,26,26,26
26,26,26,26,26,26,26,26,26,26,26,26,26,26,26,26,26,26,26,26,26,26,26,26,26
26,26,26,26,26,26,26,26,26,26,26,26,26,26,26,26,26,26,26,26,26,26,26,26,26
26,26,26,26,26,26,26,26,26,26,26,26,26,26,26,26,26,26,26,26,26,26,26,26,26
26,26,26,26,26,26,26,26,26,26,26,26,26,26,26,26,26,26,26,26,26,26,26,26,26
26,26,26,26,26,26,26,26,26,26,26,26,26,26,26,26,26,26,26,26,26,26,26,26,26
26,26,26,26,26,26,26,26,26,26,26,26,26,26,26,26,26,26,26,26,26,26,26,26,26
26,26,26,26,26,26,26,26,26,26,26,26,26,26,26,26,26,26,26,26,26,26,26,26,26
26,26,26,26,26,26,26,26,26,2,3,3,3,3,3,2,26,26,26,26,26,26,26,26,26
26,26,26,26,26,26,26,26,26,3,0,0,0,0,0,3,26,26,26,26,26,26,26,26,26
26,26,26,26,26,26,26,26,26,3,0,0,0,0,0,3,26,26,26,26,26,26,26,26,26
26,26,26,26,26,26,26,26,26,3,25,0,0,0,0,3,26,26,26,26,26,26,26,26,26
26,26,26,26,26,26,26,26,26,3,12,0,0,0,0,3,26,26,26,26,26,26,26,26,26
26,26,26,26,26,26,26,26,26,3,0,0,0,0,0,3,26,26,26,26,26,26,26,26,26
26,26,26,26,26,26,26,26,26,2,3,3,3,3,3,2,26,26,26,26,26,26,26,26,26
26,26,26,26,26,26,26,26,26,26,26,26,26,26,26,26,26,26,26,26,26,26,26,26,26
26,26,26,26,26,26,26,26,26,26,26,26,26,26,26,26,26,26,26,26,26,26,26,26,26
26,26,26,26,26,26,26,26,26,26,26,26,26,26,26,26,26,26,26,26,26,26,26,26,26
26,26,26,26,26,26,26,26,26,26,26,26,26,26,26,26,26,26,26,26,26,26,26,26,26
26,26,26,26,26,26,26,26,26,26,26,26,26,26,26,26,26,26,26,26,26,26,26,26,26
26,26,26,26,26,26,26,26,26,26,26,26,26,26,26,26,26,26,26,26,26,26,26,26,26
26,26,26,26,26,26,26,26,26,26,26,26,26,26,26,26,26,26,26,26,26,26,26,26,26
26,26,26,26,26,26,26,26,26,26,26,26,26,26,26,26,26,26,26,26,26,26,26,26,26
26,26,26,26,26,26,26,26,26,26,26,26,26,26,26,26,26,26,26,26,26,26,26,26,26
endlayer

layer
26,26,26,26,26,26,26,26,26,26,26,26,26,26,26,26,26,26,26,26,26,26,26,26,26
26,26,26,26,26,26,26,26,26,26,26,26,26,26,26,26,26,26,26,26,26,26,26,26,26
26,26,26,26,26,26,26,26,26,26,26,26,26,26,26,26,26,26,26,26,26,26,26,26,26
26,26,26,26,26,26,26,26,26,26,26,26,26,26,26,26,26,26,26,26,26,26,26,26,26
26,26,26,26,26,26,26,26,26,26,26,26,26,26,26,26,26,26,26,26,26,26,26,26,26
26,26,26,26,26,26,26,26,26,26,26,26,26,26,26,26,26,26,26,26,26,26,26,26,26
26,26,26,26,26,26,26,26,26,26,26,26,26,26,26,26,26,26,26,26,26,26,26,26,26
26,26,26,26,26,26,26,26,26,26,26,26,26,26,26,26,26,26,26,26,26,26,26,26,26
26,26,26,26,26,26,26,26,26,26,26,26,26,26,26,26,26,26,26,26,26,26,26,26,26
26,26,26,26,26,26,26,26,26,2,2,2,2,2,2,2,26,26,26,26,26,26,26,26,26
26,26,26,26,26,26,26,26,26,2,0,0,0,0,0,2,26,26,26,26,26,26,26,26,26
26,26,26,26,26,26,26,26,26,2,0,0,0,0,0,2,26,26,26,26,26,26,26,26,26
26,26,26,26,26,26,26,26,26,2,0,0,0,0,0,2,26,26,26,26,26,26,26,26,26
26,26,26,26,26,26,26,26,26,2,25,0,0,0,0,2,26,26,26,26,26,26,26,26,26
26,26,26,26,26,26,26,26,26,2,12,12,0,0,0,2,26,26,26,26,26,26,26,26,26
26,26,26,26,26,26,26,26,26,2,2,2,2,2,2,2,26,26,26,26,26,26,26,26,26
26,26,26,26,26,26,26,26,26,26,26,26,26,26,26,26,26,26,26,26,26,26,26,26,26
26,26,26,26,26,26,26,26,26,26,26,26,26,26,26,26,26,26,26,26,26,26,26,26,26
26,26,26,26,26,26,26,26,26,26,26,26,26,26,26,26,26,26,26,26,26,26,26,26,26
26,26,26,26,26,26,26,26,26,26,26,26,26,26,26,26,26,26,26,26,26,26,26,26,26
26,26,26,26,26,26,26,26,26,26,26,26,26,26,26,26,26,26,26,26,26,26,26,26,26
26,26,26,26,26,26,26,26,26,26,26,26,26,26,26,26,26,26,26,26,26,26,26,26,26
26,26,26,26,26,26,26,26,26,26,26,26,26,26,26,26,26,26,26,26,26,26,26,26,26
26,26,26,26,26,26,26,26,26,26,26,26,26,26,26,26,26,26,26,26,26,26,26,26,26
26,26,26,26,26,26,26,26,26,26,26,26,26,26,26,26,26,26,26,26,26,26,26,26,26
endlayer

layer
27,27,27,27,27,27,27,27,27,27,27,27,27,27,27,27,27,27,27,27,27,27,27,27,27
27,27,27,27,27,27,27,27,27,27,27,27,27,27,27,27,27,27,27,27,27,27,27,27,27
27,27,27,27,27,27,27,27,27,27,27,27,27,27,27,27,27,27,27,27,27,27,27,27,27
27,27,27,27,27,27,27,27,27,27,27,27,27,27,27,27,27,27,27,27,27,27,27,27,27
27,27,27,27,27,27,27,27,27,27,27,27,27,27,27,27,27,27,27,27,27,27,27,27,27
27,27,27,27,27,27,27,27,27,27,27,27,27,27,27,27,27,27,27,27,27,27,27,27,27
27,27,27,27,27,27,27,27,27,27,27,27,27,27,27,27,27,27,27,27,27,27,27,27,27
27,27,27,27,27,27,27,27,27,27,27,27,27,27,27,27,27,27,27,27,27,27,27,27,27
27,27,27,27,27,27,27,27,27,27,27,27,27,27,27,27,27,27,27,27,27,27,27,27,27
27,27,27,27,27,27,27,27,27,12,3,12,3,12,12,12,27,27,27,27,27,27,27,27,27
27,27,27,27,27,27,27,27,27,12,0,0,0,0,0,12,27,27,27,27,27,27,27,27,27
27,27,27,27,27,27,27,27,27,12,0,0,0,0,0,3,27,27,27,27,27,27,27,27,27
27,27,27,27,27,27,27,27,27,3,0,0,0,0,0,12,27,27,27,27,27,27,27,27,27
27,27,27,27,27,27,27,27,27,3,0,0,0,0,0,12,27,27,27,27,27,27,27,27,27
27,27,27,27,27,27,27,27,27,12,0,13,12,0,0,12,27,27,27,27,27,27,27,27,27
27,27,27,27,27,27,27,27,27,12,12,12,3,3,12,3,27,27,27,27,27,27,27,27,27
27,27,27,27,27,27,27,27,27,27,27,27,27,27,27,27,27,27,27,27,27,27,27,27,27
27,27,27,27,27,27,27,27,27,27,27,27,27,27,27,27,27,27,27,27,27,27,27,27,27
27,27,27,27,27,27,27,27,27,27,27,27,27,27,27,27,27,27,27,27,27,27,27,27,27
27,27,27,27,27,27,27,27,27,27,27,27,27,27,27,27,27,27,27,27,27,27,27,27,27
27,27,27,27,27,27,27,27,27,27,27,27,27,27,27,27,27,27,27,27,27,27,27,27,27
27,27,27,27,27,27,27,27,27,27,27,27,27,27,27,27,27,27,27,27,27,27,27,27,27
27,27,27,27,27,27,27,27,27,27,27,27,27,27,27,27,27,27,27,27,27,27,27,27,27
27,27,27,27,27,27,27,27,27,27,27,27,27,27,27,27,27,27,27,27,27,27,27,27,27
27,27,27,27,27,27,27,27,27,27,27,27,27,27,27,27,27,27,27,27,27,27,27,27,27
endlayer

layer
28,28,28,28,28,28,28,28,28,28,28,28,28,28,28,28,28,28,28,28,28,28,28,28,28
28,28,28,28,28,28,28,28,28,28,28,28,28,28,28,28,28,28,28,28,28,28,28,28,28
28,28,28,28,28,28,28,28,28,28,28,28,28,28,28,28,28,28,28,28,28,28,28,28,28
28,28,28,28,28,28,28,28,28,28,28,28,28,28,28,28,28,28,28,28,28,28,28,28,28
28,28,28,28,28,28,28,28,28,28,28,28,28,28,28,28,28,28,28,28,28,28,28,28,28
28,28,28,28,28,28,28,28,28,28,28,28,28,28,28,28,28,28,28,28,28,28,28,28,28
28,28,28,28,28,28,28,28,28,28,28,28,28,28,28,28,28,28,28,28,28,28,28,28,28
28,28,28,28,28,28,28,28,28,28,28,28,28,28,28,28,28,28,28,28,28,28,28,28,28
28,28,28,28,28,28,28,28,28,28,28,28,28,28,28,28,28,28,28,28,28,28,28,28,28
28,28,28,28,28,28,28,28,28,12,12,3,12,3,3,3,28,28,28,28,28,28,28,28,28
28,28,28,28,28,28,28,28,28,3,0,0,0,0,0,3,28,28,28,28,28,28,28,28,28
28,28,28,28,28,28,28,28,28,3,0,0,0,0,0,12,28,28,28,28,28,28,28,28,28
28,28,28,28,28,28,28,28,28,12,0,0,0,0,0,12,28,28,28,28,28,28,28,28,28
28,28,28,28,28,28,28,28,28,12,0,0,0,0,0,3,28,28,28,28,28,28,28,28,28
28,28,28,28,28,28,28,28,28,12,0,28,28,0,0,3,28,28,28,28,28,28,28,28,28
28,28,28,28,28,28,28,28,28,12,3,12,28,12,12,12,28,28,28,28,28,28,28,28,28
28,28,28,28,28,28,28,28,28,28,28,28,28,28,28,28,28,28,28,28,28,28,28,28,28
28,28,28,28,28,28,28,28,28,28,28,28,28,28,28,28,28,28,28,28,28,28,28,28,28
28,28,28,28,28,28,28,28,28,28,28,28,28,28,28,28,28,28,28,28,28,28,28,28,28
28,28,28,28,28,28,28,28,28,28,28,28,28,28,28,28,28,28,28,28,28,28,28,28,28
28,28,28,28,28,28,28,28,28,28,28,28,28,28,28,28,28,28,28,28,28,28,28,28,28
28,28,28,28,28,28,28,28,28,28,28,28,28,28,28,28,28,28,28,28,28,28,28,28,28
28,28,28,28,28,28,28,28,28,28,28,28,28,28,28,28,28,28,28,28,28,28,28,28,28
28,28,28,28,28,28,28,28,28,28,28,28,28,28,28,28,28,28,28,28,28,28,28,28,28
28,28,28,28,28,28,28,28,28,28,28,28,28,28,28,28,28,28,28,28,28,28,28,28,28
endlayer

layer
28,28,28,28,28,28,28,28,28,28,0,0,0,0,0,0,0,0,28,28,28,28,28,28,28
28,0,0,28,28,28,28,28,28,28,28,28,0,0,0,0,0,28,28,28,28,28,28,28,28
28,0,28,28,28,28,28,28,28,28,28,28,28,0,0,28,28,28,28,28,28,28,28,28,28
28,28,28,28,28,28,28,28,28,28,28,28,28,0,28,28,28,28,28,28,28,28,28,28,28
28,28,28,28,28,28,28,28,28,28,28,28,28,28,28,28,28,28,28,28,28,28,28,28,0
28,28,28,28,28,28,28,28,28,28,28,28,28,28,28,28,28,28,28,28,28,28,28,0,0
28,28,28,28,28,28,28,28,28,28,28,28,28,28,28,28,28,28,28,28,28,28,28,0,0
28,28,28,28,28,28,28,28,28,28,28,28,28,28,28,28,28,28,28,28,28,28,28,28,0
28,28,28,28,28,28,28,28,28,28,28,28,28,28,28,28,28,28,28,28,28,28,28,28,0
28,28,28,28,28,28,28,28,28,3,3,3,3,3,3,3,28,28,28,28,28,28,28,28,28
28,28,28,28,28,28,28,28,28,3,0,0,29,0,0,3,28,28,28,28,28,28,28,28,28
28,28,28,28,28,28,28,28,28,3,0,0,0,0,0,3,28,28,28,28,28,28,28,28,28
28,28,28,28,28,28,28,28,28,3,29,0,0,0,29,3,28,28,28,28,28,28,28,28,28
28,28,28,28,28,28,28,0,28,3,0,0,0,0,0,3,28,28,28,28,28,28,28,28,28
28,28,28,28,28,0,0,0,28,3,0,0,0,0,0,3,28,28,28,28,28,28,28,28,28
28,28,28,28,28,0,0,28,28,3,3,3,28,3,3,3,28,28,28,28,28,28,28,28,28
28,28,28,28,0,28,28,28,28,28,28,28,28,28,28,28,28,28,28,28,28,28,28,28,0
28,28,28,0,28,28,28,28,28,28,28,28,28,28,28,28,28,28,28,28,28,28,28,28,0
0,0,0,28,28,28,28,28,28,28,28,28,28,28,28,28,28,28,28,28,28,28,28,28,0
0,0,0,28,28,28,28,28,28,28,28,28,28,28,28,28,28,28,28,28,28,28,28,28,0
28,28,28,28,28,28,28,28,28,28,28,28,28,28,28,28,28,28,28,28,28,28,28,0,0
28,28,28,28,28,28,28,28,28,28,28,28,28,28,28,28,28,28,28,28,28,28,28,0,0
28,28,28,28,28,28,28,28,28,28,28,28,28,28,28,28,28,28,28,28,28,28,28,0,0
28,28,28,28,28,28,28,28,28,28,28,28,28,28,28,28,28,28,28,28,28,28,28,28,0
28,28,28,0,0,0,0,28,28,28,28,28,0,0,0,28,28,28,28,28,28,28,0,0,0
endlayer

layer
0,0,0,0,0,0,0,0,0,0,0,0,0,0,0,0,0,0,0,0,0,28,28,0,0
0,0,0,0,0,28,28,28,0,0,0,0,0,0,0,0,0,0,0,0,28,28,28,28,0
0,0,30,0,28,28,28,28,28,0,0,0,0,0,0,0,0,0,0,0,28,28,28,28,0
0,0,0,28,28,28,28,28,28,0,0,0,30,0,0,0,0,0,0,0,0,28,28,0,0
0,0,28,28,28,28,28,28,28,28,0,0,0,0,0,0,28,28,0,0,0,0,0,0,0
0,0,28,28,28,28,28,28,28,28,0,0,0,0,0,28,28,28,28,28,0,0,0,0,0
0,0,28,28,28,28,28,28,28,28,0,0,0,0,28,28,28,28,28,28,28,0,0,0,0
0,28,28,28,28,28,28,28,28,28,0,0,28,28,28,28,28,28,28,28,28,0,0,30,0
0,28,28,28,28,28,28,28,28,0,0,28,28,28,28,28,28,28,28,28,28,28,0,0,0
0,0,28,28,28,28,28,28,28,0,28,28,28,28,28,28,28,28,28,28,28,28,28,0,0
0,28,28,28,28,28,28,28,0,0,7,7,7,7,7,28,28,28,28,28,28,28,28,0,0
0,28,28,28,28,28,28,28,0,0,7,0,29,0,7,28,28,28,28,28,28,28,28,0,0
28,28,28,28,28,28,28,0,0,0,7,29,0,29,7,28,28,28,28,28,28,28,28,28,0
28,28,28,28,28,0,0,0,0,0,7,0,29,0,7,28,28,28,28,28,28,28,28,28,0
28,28,28,28,0,0,0,0,0,0,7,7,7,7,7,28,28,28,28,28,28,28,28,28,0
28,28,28,28,0,0,0,0,0,0,0,28,28,28,28,28,28,28,28,28,28,28,28,0,0
0,28,28,0,0,0,0,28,28,28,28,28,28,28,28,28,28,28,28,28,28,28,28,0,0
0,0,0,0,0,28,28,28,28,28,28,28,28,28,28,28,28,28,28,28,28,28,28,0,0
0,0,0,0,28,28,28,28,28,28,28,28,28,28,28,28,28,28,28,28,28,28,28,0,0
0,0,0,0,28,28,28,28,28,28,28,28,28,28,28,28,28,28,28,28,28,28,0,0,0
0,30,0,0,28,28,28,28,28,28,28,28,28,28,28,28,28,28,28,28,28,28,0,0,0
0,0,0,28,28,28,28,28,28,28,28,28,28,28,28,28,28,28,28,28,28,28,0,0,0
0,0,0,0,28,28,28,28,28,28,28,28,28,28,28,28,28,28,28,28,28,0,0,0,0
0,0,0,0,0,0,0,0,28,28,28,28,0,0,0,28,28,28,28,0,0,0,30,0,0
0,0,0,0,0,0,0,0,0,0,0,0,0,0,0,0,0,0,0,0,0,0,0,0,0
endlayer

layer
0,0,0,0,0,0,0,0,0,0,0,0,0,0,0,0,0,0,0,0,0,0,0,0,0
0,0,0,0,0,0,0,0,0,0,0,0,0,0,0,0,0,0,0,0,0,28,0,0,0
0,0,0,0,0,28,28,28,0,0,0,0,0,0,0,0,0,0,0,0,0,0,0,0,0
0,0,0,0,28,28,28,28,0,0,0,0,0,0,0,0,0,0,0,0,0,30,0,0,0
0,0,0,28,28,28,28,28,28,0,0,0,0,0,0,0,0,0,0,0,0,0,0,0,0
0,0,0,28,28,28,28,28,28,0,0,0,0,0,0,0,0,0,0,0,0,0,0,0,0
0,0,0,28,28,28,28,28,28,0,0,0,0,0,0,0,28,28,0,0,0,0,0,0,0
0,0,28,28,28,28,28,28,28,0,0,0,0,0,0,28,28,28,28,0,0,0,0,0,0
0,0,28,28,28,28,28,28,0,0,0,0,0,0,28,28,28,28,28,28,0,0,0,0,0
0,0,0,28,28,28,28,28,0,0,0,0,0,28,28,28,28,28,28,28,0,0,0,0,0
0,0,28,28,28,28,28,0,0,0,0,0,28,28,28,28,28,28,28,28,28,0,0,0,0
0,0,28,28,28,28,28,0,0,0,0,7,7,7,28,28,28,28,28,28,28,0,0,0,0
0,28,28,28,28,0,0,0,0,0,0,7,7,7,28,28,28,28,28,28,28,28,0,0,0
0,28,28,28,0,0,0,0,0,0,0,7,7,7,28,28,28,28,28,28,28,28,0,0,0
0,28,28,0,0,0,0,0,0,0,0,0,28,28,28,28,28,28,28,28,28,28,0,0,0
0,28,28,0,0,0,0,0,0,0,0,0,0,28,28,28,28,28,28,28,28,0,0,0,0
0,0,0,0,0,0,0,0,0,0,0,0,28,28,28,28,28,28,28,28,28,0,0,0,0
0,0,0,0,0,0,0,0,28,28,28,28,28,28,28,28,28,28,28,28,28,0,30,0,0
0,0,0,0,0,0,28,28,28,28,28,28,28,28,28,28,28,28,28,28,28,0,0,0,0
0,0,0,0,0,28,28,28,28,28,28,28,28,28,28,28,28,28,28,28,0,0,0,0,0
0,0,0,0,0,28,28,28,28,28,28,28,28,28,28,28,28,28,28,28,0,0,0,0,0
0,0,0,0,28,0,0,0,28,28,28,28,0,0,0,28,28,28,28,0,0,0,0,0,0
0,0,0,0,0,0,0,0,0,0,0,0,0,0,0,0,0,0,0,0,0,0,0,0,0
0,0,0,0,0,0,0,0,0,0,0,0,0,0,0,0,0,0,0,0,0,0,0,0,0
0,0,0,0,0,0,0,0,0,0,0,0,0,0,0,0,0,0,0,0,0,0,0,0,0
endlayer

layer
0,0,0,0,0,0,0,0,0,0,0,0,0,0,0,0,0,0,0,0,0,0,0,0,0
0,0,0,0,0,0,0,0,0,0,0,0,0,0,0,0,0,0,0,0,0,0,0,0,0
0,0,0,0,0,0,0,0,0,0,0,0,0,0,0,0,0,0,0,0,0,0,0,0,0
0,0,0,0,0,0,0,0,0,0,0,0,0,0,0,0,0,0,0,0,0,0,0,0,0
0,0,0,0,0,0,0,0,0,0,0,0,0,0,0,0,0,0,0,0,0,0,0,0,0
0,0,0,0,0,28,28,30,0,0,0,0,0,0,0,0,0,0,0,0,0,0,0,0,0
0,0,0,0,28,28,28,28,0,0,0,0,0,0,0,0,0,0,0,0,0,0,0,0,0
0,0,0,30,0,28,28,0,0,0,0,0,0,0,0,0,0,0,0,0,0,0,0,0,0
0,0,0,0,0,0,0,0,0,0,0,0,0,0,0,0,0,0,0,0,0,0,0,0,0
0,0,0,0,0,0,0,0,0,0,0,0,0,0,0,28,28,0,30,0,0,0,0,0,0
0,0,0,0,0,30,0,0,0,0,0,0,0,0,28,28,28,28,0,0,0,0,0,0,0
0,0,0,0,0,0,0,0,0,0,0,0,0,0,28,28,28,28,0,0,0,0,0,0,0
0,0,0,0,0,0,0,0,0,0,0,0,7,28,28,28,28,28,28,0,0,0,0,0,0
0,0,30,0,0,0,0,0,0,0,0,0,0,28,28,28,28,28,28,0,0,0,0,0,0
0,0,0,0,0,0,0,0,0,0,0,0,0,0,28,28,28,28,28,0,0,0,0,0,0
0,0,0,0,0,0,0,0,0,0,0,0,0,0,28,28,28,28,28,28,0,0,0,0,0
0,0,0,0,0,0,0,0,0,0,0,0,30,0,0,28,28,28,28,28,0,0,0,0,0
0,0,0,0,0,0,0,0,0,0,0,0,0,0,0,28,28,28,28,28,0,0,0,0,0
0,0,0,0,0,0,0,0,30,0,0,0,0,0,28,28,28,28,28,0,0,0,0,0,0
0,0,0,0,0,0,0,0,0,0,0,0,0,0,28,28,28,28,28,0,0,0,0,0,0
0,0,0,0,0,0,0,0,0,0,0,30,0,0,0,28,28,28,0,0,0,0,0,0,0
0,0,0,0,0,0,0,0,0,0,0,0,0,0,0,0,0,0,0,0,0,0,0,0,0
0,0,0,0,0,0,0,0,0,0,0,0,0,0,0,0,0,0,0,0,0,0,0,0,0
0,0,0,0,0,0,0,0,0,0,0,0,0,0,0,0,0,0,0,0,0,0,0,0,0
0,0,0,0,0,0,0,0,0,0,0,0,0,0,0,0,0,0,0,0,0,0,0,0,0
endlayer

layer
0,0,0,0,0,0,0,0,0,0,0,0,0,0,0,0,0,0,0,0,0,0,0,0,0
0,0,0,0,0,0,0,0,0,0,0,0,0,0,0,0,0,0,0,0,0,0,0,0,0
0,0,0,0,0,0,0,0,0,0,0,0,0,0,0,0,0,0,0,0,0,0,0,0,0
0,0,0,0,0,0,0,0,0,0,0,0,0,0,0,0,0,0,0,0,0,0,0,0,0
0,0,0,0,0,0,0,0,0,0,0,0,0,0,0,0,0,0,0,0,0,0,0,0,0
0,0,0,0,0,0,0,0,0,0,0,0,0,0,0,0,0,0,0,0,0,0,0,0,0
0,0,0,0,0,0,0,0,0,0,0,0,0,0,0,0,0,0,0,0,0,0,0,0,0
0,0,0,0,0,0,0,0,0,0,0,0,0,0,0,0,0,0,0,0,0,0,0,0,0
0,0,0,0,0,0,0,0,0,0,0,0,0,0,0,0,0,0,0,0,0,0,0,0,0
0,0,0,0,0,0,0,0,0,0,0,0,0,0,0,0,0,0,0,0,0,0,0,0,0
0,0,0,0,0,0,0,0,0,0,0,0,0,0,0,0,0,0,0,0,0,0,0,0,0
0,0,0,0,0,0,0,0,0,0,0,0,0,0,0,0,28,0,0,0,0,0,0,0,0
0,0,0,0,0,0,0,0,0,0,0,0,0,0,0,30,28,28,0,0,0,0,0,0,0
0,0,0,0,0,0,0,0,0,0,0,0,0,0,0,28,28,28,0,0,0,0,0,0,0
0,0,0,0,0,0,0,0,0,0,0,0,0,0,0,28,28,28,0,0,0,0,0,0,0
0,0,0,0,0,0,0,0,0,0,0,0,0,0,0,0,28,28,0,0,0,0,0,0,0
0,0,0,0,0,0,0,0,0,0,0,0,0,0,0,0,28,28,0,0,0,0,0,0,0
0,0,0,0,0,0,0,0,0,0,0,0,0,0,0,0,28,30,0,0,0,0,0,0,0
0,0,0,0,0,0,0,0,0,0,0,0,0,0,0,0,0,0,0,0,0,0,0,0,0
0,0,0,0,0,0,0,0,0,0,0,0,0,0,0,0,0,0,0,0,0,0,0,0,0
0,0,0,0,0,0,0,0,0,0,0,0,0,0,0,0,0,0,0,0,0,0,0,0,0
0,0,0,0,0,0,0,0,0,0,0,0,0,0,0,0,0,0,0,0,0,0,0,0,0
0,0,0,0,0,0,0,0,0,0,0,0,0,0,0,0,0,0,0,0,0,0,0,0,0
0,0,0,0,0,0,0,0,0,0,0,0,0,0,0,0,0,0,0,0,0,0,0,0,0
0,0,0,0,0,0,0,0,0,0,0,0,0,0,0,0,0,0,0,0,0,0,0,0,0
endlayer

