
# Created by Ruins mod version 15.3 Ingame Parser
# authoring Player: Mensrea

weight=1
embed_into_distance=25
acceptable_target_blocks=
unacceptable_target_blocks=flowing_water,water,flowing_lava,lava
dimensions=32,25,25
allowable_overhang=0
max_leveling=2
leveling_buffer=0
preserve_water=0
preserve_lava=0
preventRotation=1

rule1=0,100,IW:concreteA-0
rule2=0,100,IW:concrete-0
rule3=0,100,ChestGenHook:mineshaftCorridor:5-2
rule4=0,100,ChestGenHook:strongholdLibrary:5-2
rule5=0,100,minecraft:stonebrick-0
rule6=0,100,minecraft:farmland-7
rule7=0,100,minecraft:planks-0
rule8=0,100,ChestGenHook:mineshaftCorridor:5-2
rule9=0,100,ChestGenHook:strongholdLibrary:5-2
rule10=0,100,IW:steelsiding-0
rule11=0,100,minecraft:water-0
rule12=0,100,minecraft:oak_stairs-1
rule13=0,100,minecraft:wooden_slab-0
rule14=0,100,MobSpawner:demonmobs.behemoth
rule15=0,100,IC2:blockDoorAlloy-2
rule16=0,100,ChestGenHook:strongholdLibrary:5-2
rule17=0,100,MobSpawner:demonmobs.trite
rule18=0,100,ChestGenHook:strongholdLibrary:5-2
rule19=0,100,minecraft:glass_pane-0
rule20=0,100,IW:concretestairs-1
rule21=0,100,MobSpawner:demonmobs.belph
rule22=0,100,IInventory;minecraft:chest;flansmod:boltmag#1#0#8+flansmod:ec#4#0#14+flansmod:20mmbox#1#0#17+flansmod:longlas#1#0#20+flansmod:8mmmag#5#0#23-4
rule23=0,100,IW:glassblackA-0
rule24=0,100,minecraft:wheat-7
rule25=0,100,IW:lightwhite-0
rule26=0,100,IW:glassblack-0
rule27=0,100,IC2:blockDoorAlloy-8
rule28=0,100,minecraft:wooden_slab-3
rule29=0,100,ChestGenHook:strongholdCorridor:5-2
rule30=0,100,ChestGenHook:strongholdCorridor:5-2
rule31=0,100,ChestGenHook:strongholdCorridor:5-2
rule32=0,100,ChestGenHook:strongholdCorridor:5-2
rule33=0,100,minecraft:lever-2
rule34=0,100,IW:steelblock-0
rule35=0,100,minecraft:oak_stairs-2
rule36=0,100,minecraft:oak_stairs-3
rule37=0,100,ChestGenHook:mineshaftCorridor:5-2
rule38=0,100,MobSpawner:demonmobs.pinky
rule39=0,100,minecraft:stained_glass_pane-15
rule40=0,100,IW:concretestairs-0
rule41=0,100,IW:metaldoor-5
rule42=0,100,minecraft:ladder-4
rule43=0,100,minecraft:bed-10
rule44=0,100,minecraft:bed-2
rule45=0,100,minecraft:bed-0
rule46=0,100,minecraft:bed-8
rule47=0,100,minecraft:tnt-0
rule48=0,100,minecraft:redstone_wire-0
rule49=0,100,minecraft:stone_pressure_plate-0
rule50=0,100,minecraft:tripwire-0
rule51=0,100,minecraft:oak_stairs-0
rule52=0,100,minecraft:stained_glass-15
rule53=0,100,IW:metaldoor-8
rule54=0,100,IW:concretestairs-3
rule55=0,100,PFAAGeologica:strongStone-7
rule56=0,100,PFAAGeologica:mediumStone-3
rule57=0,100,IW:concretestairs-2
rule58=0,100,PFAAGeologica:weakStone-1
rule59=0,100,minecraft:sand-1
rule60=0,100,IW:concretereinforcedA-0
rule61=0,100,IC2:blockDoorAlloy-0
rule62=0,100,IW:bush-0
rule63=0,100,AdvancedRepulsionSystems:DeFenceBW-0
rule64=0,100,IC2:blockDoorAlloy-9
rule65=0,100,minecraft:lever-1
rule66=0,100,MobSpawner:demonmobs.cacodemon

layer
1,1,1,1,1,1,1,1,1,1,1,1,1,1,1,1,1,1,1,1,1,1,1,1,1
1,1,1,1,1,1,1,1,1,1,1,1,1,1,1,1,1,1,1,1,1,1,1,1,1
1,1,1,1,1,1,1,1,1,1,1,1,1,1,1,1,1,1,1,1,1,1,1,1,1
1,1,1,1,1,1,1,1,1,1,1,1,1,1,1,1,1,1,1,1,1,1,1,1,1
1,1,1,1,1,1,1,1,1,1,1,1,1,1,1,1,1,1,1,1,1,1,1,1,1
1,1,1,1,1,1,1,1,1,1,1,1,1,1,1,1,1,1,1,1,1,1,1,1,1
1,1,1,1,1,1,1,1,1,1,1,1,1,1,1,1,1,1,1,1,1,1,1,1,1
1,1,1,1,1,1,1,1,1,1,1,1,1,1,1,1,1,1,1,1,1,1,1,1,1
1,1,1,1,1,1,1,1,1,1,1,1,1,1,1,1,1,1,1,1,1,1,1,1,1
1,1,1,1,1,1,1,1,1,1,1,1,1,1,1,1,1,1,1,1,1,1,1,1,1
1,1,1,1,1,1,1,1,1,1,1,1,1,1,1,1,1,1,1,1,1,1,1,1,1
1,1,1,1,1,1,1,1,1,1,1,1,1,1,1,1,1,1,1,1,1,1,1,1,1
1,1,1,1,1,1,1,1,1,1,1,1,1,1,1,1,1,1,1,1,1,1,1,1,1
1,1,1,1,1,1,1,1,1,1,1,1,1,1,1,1,1,1,1,1,1,1,1,1,1
1,1,1,1,1,1,1,1,1,1,1,1,1,1,1,1,1,1,1,1,1,1,1,1,1
1,1,1,1,1,1,1,1,1,1,1,1,1,1,1,1,1,1,1,1,1,1,1,1,1
1,1,1,1,1,1,1,1,1,1,1,1,1,1,1,1,1,1,1,1,1,1,1,1,1
1,1,1,1,1,1,1,1,1,1,1,1,1,1,1,1,1,1,1,1,1,1,1,1,1
1,1,1,1,1,1,1,1,1,1,1,1,1,1,1,1,1,1,1,1,1,1,1,1,1
1,1,1,1,1,1,1,1,1,1,1,1,1,1,1,1,1,1,1,1,1,1,1,1,1
1,1,1,1,1,1,1,1,1,1,1,1,1,1,1,1,1,1,1,1,1,1,1,1,1
1,1,1,1,1,1,1,1,1,1,1,1,1,1,1,1,1,1,1,1,1,1,1,1,1
1,1,1,1,1,1,1,1,1,1,1,1,1,1,1,1,1,1,1,1,1,1,1,1,1
1,1,1,1,1,1,1,1,1,1,1,1,1,1,1,1,1,1,1,1,1,1,1,1,1
1,1,1,1,1,1,1,1,1,1,1,1,1,1,1,1,1,1,1,1,1,1,1,1,1
endlayer

layer
1,1,1,1,1,1,1,1,1,1,1,1,1,1,1,1,1,1,1,1,1,1,1,1,1
1,1,1,1,1,1,1,1,1,1,1,1,1,1,1,1,1,1,1,1,1,1,1,1,1
1,1,1,1,1,1,1,1,1,1,1,1,1,1,1,1,1,1,1,1,1,1,1,1,1
1,1,1,1,1,1,1,1,1,1,1,1,1,1,1,1,1,1,1,1,1,1,1,1,1
1,1,1,1,1,1,1,1,1,1,1,1,1,1,1,1,1,1,1,1,1,1,1,1,1
1,1,1,1,1,1,1,1,1,1,1,1,1,1,1,1,1,1,1,1,1,1,1,1,1
1,1,1,1,1,1,1,1,1,1,1,1,1,1,1,1,1,1,1,1,1,1,1,1,1
1,1,1,1,1,1,1,1,1,1,1,1,1,1,1,1,1,1,1,1,1,1,1,1,1
1,1,1,1,1,1,1,1,1,1,1,1,1,1,1,1,1,1,1,1,1,1,1,1,1
1,1,1,1,1,1,1,1,1,1,1,1,1,1,1,1,1,1,1,1,1,1,1,1,1
1,1,1,1,1,1,1,1,1,1,1,1,1,1,1,1,1,1,1,1,1,1,1,1,1
1,1,1,1,1,1,1,1,1,1,1,1,1,1,1,1,1,1,1,1,1,1,1,1,1
1,1,1,1,1,1,1,1,1,1,1,1,1,1,1,1,1,1,1,1,1,1,1,1,1
1,1,1,1,1,1,1,1,1,1,1,1,1,1,1,1,1,1,1,1,1,1,1,1,1
1,1,1,1,1,1,1,1,1,1,1,1,1,1,1,1,1,1,1,1,1,1,1,1,1
1,1,1,1,1,1,1,1,1,1,1,1,1,1,1,1,1,1,1,1,1,1,1,1,1
1,1,1,1,1,1,1,1,1,1,1,1,1,1,1,1,1,1,1,1,1,1,1,1,1
1,1,1,1,1,1,1,1,1,1,1,1,1,1,1,1,1,1,1,1,1,1,1,1,1
1,1,1,1,1,1,1,1,1,1,1,1,1,1,1,1,1,1,1,1,1,1,1,1,1
1,1,1,1,1,1,1,1,1,1,1,1,1,1,1,1,1,1,1,1,1,1,1,1,1
1,1,1,1,1,1,1,1,1,1,1,1,1,1,1,1,1,1,1,1,1,1,1,1,1
1,1,1,1,1,1,1,1,1,1,1,1,1,1,1,1,1,1,1,1,1,1,1,1,1
1,1,1,1,1,1,1,1,1,1,1,1,1,1,1,1,1,1,1,1,1,1,1,1,1
1,1,1,1,1,1,1,1,1,1,1,1,1,1,1,1,1,1,1,1,1,1,1,1,1
1,1,1,1,1,1,1,1,1,1,1,1,1,1,1,1,1,1,1,1,1,1,1,1,1
endlayer

layer
1,1,1,1,1,1,1,1,1,1,1,1,1,1,1,1,1,1,1,1,1,1,1,1,1
1,6,6,6,6,6,5,0,0,2,0,4,0,3,0,2,0,0,0,0,0,0,0,0,1
1,6,6,6,6,6,5,0,0,2,0,9,0,8,0,2,0,7,7,0,0,7,7,0,1
1,6,6,11,6,6,5,0,0,2,0,10,0,10,0,2,0,7,0,0,0,7,7,0,1
1,6,6,6,6,6,5,0,0,2,0,0,12,0,0,2,0,0,0,0,0,0,0,0,1
1,6,6,6,6,6,5,0,0,2,0,0,0,0,0,2,0,0,13,7,13,0,0,0,1
1,6,6,11,6,6,5,0,0,2,15,10,10,10,10,2,0,0,7,14,7,0,0,0,1
1,6,6,6,6,6,5,0,0,2,0,0,0,0,0,2,0,0,13,7,13,0,0,0,1
1,6,6,6,6,6,5,0,0,2,0,0,0,0,0,2,7,7,0,0,0,0,0,7,1
1,6,6,11,6,6,5,0,0,2,5,5,0,5,5,2,7,7,0,0,0,0,0,7,1
1,6,6,6,6,6,5,0,0,0,0,0,0,0,0,0,0,0,0,0,0,0,0,0,1
1,6,6,6,6,6,5,0,0,0,0,0,0,0,0,0,0,0,0,0,0,0,0,0,1
1,6,6,11,6,6,5,0,0,0,0,0,0,0,0,0,0,0,7,0,0,16,7,7,1
1,6,6,6,6,6,5,0,0,0,0,0,0,0,2,0,0,0,7,0,0,18,7,17,1
1,6,6,6,6,6,5,0,0,0,0,0,0,19,20,19,0,0,0,0,0,0,0,7,1
1,6,6,11,6,6,5,0,0,2,0,0,0,0,0,2,0,0,0,0,0,0,0,0,1
1,6,6,6,6,6,5,0,0,0,0,0,0,0,0,0,0,0,0,0,0,0,7,7,1
1,6,6,6,6,6,5,0,0,0,0,0,0,0,0,0,0,0,0,0,0,0,7,7,1
1,6,6,11,6,6,5,0,0,0,0,0,0,0,0,0,0,0,0,0,0,0,0,0,1
1,6,6,6,6,6,5,0,0,0,0,0,0,0,0,0,0,0,0,13,7,13,0,0,1
1,6,6,6,6,6,5,0,0,0,0,0,0,0,0,0,0,0,0,7,21,7,0,0,1
1,6,6,11,6,6,5,0,0,0,2,0,0,0,2,0,7,7,0,13,7,13,0,0,1
1,6,6,6,6,6,5,0,0,0,2,0,0,0,2,0,7,7,0,0,0,0,0,7,1
1,6,6,6,6,6,5,0,0,0,2,0,0,0,2,0,0,0,0,0,0,0,7,22,1
1,1,1,1,1,1,1,1,1,1,1,23,15,23,1,1,1,1,1,1,1,1,1,1,1
endlayer

layer
1,1,1,1,1,1,1,1,1,1,1,1,1,1,1,1,1,1,1,1,1,1,1,1,1
1,24,24,24,24,24,0,0,0,2,0,10,0,10,0,2,0,0,0,0,0,0,0,0,1
1,24,24,24,24,24,0,0,0,2,0,10,0,10,0,2,0,7,0,0,0,7,7,0,1
1,24,24,25,24,24,0,0,0,2,0,10,0,10,0,2,0,0,0,0,0,7,7,0,1
1,24,24,24,24,24,0,0,0,2,0,0,0,0,0,2,0,0,0,0,0,0,0,0,1
1,24,24,24,24,24,0,0,0,2,0,0,0,0,0,2,0,0,0,0,0,0,0,0,1
1,24,24,25,24,24,0,0,0,2,27,26,0,26,26,2,0,0,0,13,0,0,0,0,1
1,24,24,24,24,24,0,0,0,2,0,0,0,0,0,2,0,0,0,0,0,0,0,0,1
1,24,24,24,24,24,0,0,0,2,0,0,0,0,0,2,7,7,0,0,0,0,0,7,1
1,24,24,25,24,24,0,0,0,2,5,5,0,5,5,2,7,7,0,0,0,0,0,7,1
1,24,24,24,24,24,0,0,0,0,0,0,0,0,0,0,0,0,0,0,0,0,0,0,1
1,24,24,24,24,24,0,0,0,0,0,0,0,0,0,0,0,0,0,0,0,0,0,0,1
1,24,24,25,24,24,0,0,0,0,0,0,0,0,2,0,0,0,0,0,0,7,7,0,1
1,24,24,24,24,24,0,0,0,0,0,0,0,19,20,19,0,0,0,0,0,7,7,28,1
1,24,24,24,24,24,0,0,0,0,0,0,0,19,0,19,0,0,0,0,0,0,0,0,1
1,24,24,25,24,24,0,0,0,2,0,0,0,0,0,2,0,0,0,0,0,0,0,0,1
1,24,24,24,24,24,0,0,0,0,0,0,0,0,0,0,0,0,0,0,0,0,7,7,1
1,24,24,24,24,24,0,0,0,0,0,0,0,0,0,0,0,0,0,0,0,0,7,7,1
1,24,24,25,24,24,0,0,0,0,0,0,0,0,0,0,0,0,0,0,0,0,0,0,1
1,24,24,24,24,24,0,0,0,0,0,0,0,0,0,0,0,0,0,0,0,0,0,0,1
1,24,24,24,24,24,0,0,0,0,0,0,0,0,0,0,0,0,0,0,13,0,0,0,1
1,24,24,25,24,24,0,0,0,0,2,0,0,0,2,0,7,7,0,0,0,0,0,0,1
1,24,24,24,24,24,0,0,0,0,26,0,0,0,26,0,7,7,0,0,0,0,0,7,1
1,24,24,24,24,24,0,0,0,0,26,0,0,0,26,0,0,0,0,0,0,0,7,7,1
1,1,1,1,1,1,1,1,1,1,1,23,27,23,1,1,1,1,1,1,1,1,1,1,1
endlayer

layer
1,1,1,1,1,1,1,1,1,1,1,1,1,1,1,1,1,1,1,1,1,1,1,1,1
1,0,0,0,0,0,0,0,0,2,0,30,0,29,0,2,0,0,0,0,0,0,0,0,1
1,0,0,0,0,0,0,0,0,2,0,32,0,31,0,2,0,0,0,0,0,0,0,0,1
1,0,0,0,0,0,0,0,0,2,0,10,0,10,0,2,0,0,0,0,0,0,0,0,1
1,0,0,0,0,0,0,0,0,2,0,0,0,0,0,2,0,0,0,0,0,0,0,0,1
1,0,0,0,0,0,0,0,0,2,33,0,0,0,0,2,0,0,0,0,0,0,0,0,1
1,0,0,0,0,0,0,0,0,2,10,26,26,26,26,2,0,0,0,0,0,0,0,0,1
1,0,0,0,0,0,0,0,0,2,0,0,0,0,0,2,0,0,0,0,0,0,0,0,1
1,0,0,0,0,0,0,0,0,2,0,0,0,0,0,2,0,0,0,0,0,0,0,0,1
1,0,0,0,0,0,0,0,0,2,5,5,5,5,5,2,0,0,0,0,0,0,0,0,1
1,0,0,0,0,0,0,0,0,0,0,0,0,0,0,0,0,0,0,0,0,0,0,0,1
1,0,0,0,0,0,0,0,0,0,0,0,0,0,2,0,0,0,0,0,0,0,0,0,1
1,0,0,0,0,0,0,0,0,0,0,0,0,19,20,19,0,0,0,0,0,0,0,0,1
1,0,0,0,0,0,0,0,0,0,0,0,0,19,0,0,0,0,0,0,0,0,0,0,1
1,0,0,0,0,0,0,0,0,0,0,0,0,0,0,0,0,0,0,0,0,0,0,0,1
1,0,0,0,0,0,0,0,0,2,0,0,0,0,0,2,0,0,0,0,0,0,0,0,1
1,0,0,0,0,0,0,0,0,0,0,0,0,0,0,0,0,0,0,0,0,0,0,0,1
1,0,0,0,0,0,0,0,0,0,0,0,0,0,0,0,0,0,0,0,0,0,0,0,1
1,0,0,0,0,0,0,0,0,0,0,0,0,0,0,0,0,0,0,0,0,0,0,0,1
1,0,0,0,0,0,0,0,0,0,0,0,0,0,0,0,0,0,0,0,0,0,0,0,1
1,0,0,0,0,0,0,0,0,0,0,0,0,0,0,0,0,0,0,0,0,0,0,0,1
1,0,0,0,0,0,0,0,0,0,2,0,0,0,2,0,0,0,0,0,0,0,0,0,1
1,0,0,0,0,0,0,0,0,0,26,0,0,0,26,0,0,0,0,0,0,0,0,0,1
1,0,0,0,0,0,0,0,0,0,26,0,33,0,26,0,0,0,0,0,0,0,0,0,1
1,1,1,1,1,1,1,1,1,1,1,23,1,23,1,1,1,1,1,1,1,1,1,1,1
endlayer

layer
1,1,1,1,1,1,1,1,1,1,1,1,1,1,1,1,1,1,1,1,1,1,1,1,1
1,0,0,0,0,0,0,0,0,2,25,0,0,0,25,2,0,0,0,0,0,0,0,0,1
1,0,0,0,0,0,0,0,0,2,0,0,0,0,0,2,0,0,0,0,0,0,0,0,1
1,0,0,0,0,0,0,0,0,2,0,0,0,0,0,2,0,0,0,0,0,0,0,0,1
1,0,0,0,0,0,0,0,0,2,0,0,0,0,0,2,0,0,0,0,0,0,0,0,1
1,0,0,0,0,0,0,0,0,2,0,0,0,0,0,2,0,0,0,0,0,0,0,0,1
1,0,0,0,0,0,0,0,0,2,26,26,26,26,26,2,0,0,0,0,0,0,0,0,1
1,0,0,0,0,0,0,0,0,2,0,0,0,0,0,2,0,0,0,0,0,0,0,0,1
1,0,0,0,0,0,0,0,0,2,0,0,0,0,0,2,0,0,0,0,0,0,0,0,1
1,0,0,0,0,0,0,0,0,2,5,5,5,5,5,2,0,0,0,0,0,0,0,0,1
1,0,0,0,0,0,0,0,0,0,0,0,0,0,2,0,0,0,0,0,0,0,0,0,1
1,0,0,0,0,0,0,0,0,0,0,0,0,19,20,19,0,0,0,0,0,0,0,0,1
1,0,0,0,0,0,0,0,0,0,0,0,0,19,0,19,0,0,0,0,0,0,0,0,1
1,0,0,0,0,0,0,0,0,0,0,0,0,0,0,0,0,0,0,0,0,0,0,0,1
1,0,0,0,0,0,0,0,0,0,0,0,0,0,0,0,0,0,0,0,0,0,0,0,1
1,0,0,0,0,0,0,0,0,2,0,0,0,0,0,2,0,0,0,0,0,0,0,0,1
1,0,0,0,0,0,0,0,0,0,0,0,0,0,0,0,0,0,0,0,0,0,0,0,1
1,0,0,0,0,0,0,0,0,0,0,0,0,0,0,0,0,0,0,0,0,0,0,0,1
1,0,0,0,0,0,0,0,0,0,0,0,0,0,0,0,0,0,0,0,0,0,0,0,1
1,0,0,0,0,0,0,0,0,0,0,0,0,0,0,0,0,0,0,0,0,0,0,0,1
1,0,0,0,0,0,0,0,0,0,0,0,0,0,0,0,0,0,0,0,0,0,0,0,1
1,0,0,0,0,0,0,0,0,0,2,2,2,2,2,0,0,0,0,0,0,0,0,0,1
1,0,0,0,0,0,0,0,0,0,2,0,0,0,2,0,0,0,0,0,0,0,0,0,1
1,0,0,0,0,0,0,0,0,0,2,0,0,0,2,0,0,0,0,0,0,0,0,0,1
1,1,1,1,1,1,1,1,1,1,1,1,1,1,1,1,1,1,1,1,1,1,1,1,1
endlayer

layer
1,1,1,1,1,1,1,1,1,1,1,1,1,1,1,1,1,1,1,1,1,1,1,1,1
1,2,2,2,2,2,2,2,2,2,2,2,2,2,2,2,2,2,2,2,2,2,2,2,1
1,2,2,2,2,2,2,2,2,2,2,2,2,2,2,2,2,2,2,2,2,2,2,2,1
1,2,2,2,2,2,2,2,2,2,2,2,2,2,2,2,2,2,2,2,2,2,2,2,1
1,2,2,2,2,2,2,2,2,2,2,2,2,2,2,2,2,2,2,2,2,2,2,2,1
1,2,2,2,2,2,2,2,2,2,2,2,2,2,2,2,2,2,2,2,2,2,2,2,1
1,2,2,2,2,2,2,2,2,2,2,2,2,2,2,2,2,2,2,2,2,2,2,2,1
1,2,2,2,2,2,2,2,2,2,2,2,2,2,2,2,2,2,2,2,2,2,2,2,1
1,2,2,2,2,2,2,2,2,2,2,2,2,2,2,2,2,2,2,2,2,2,2,2,1
1,2,2,2,2,2,2,2,2,2,2,2,2,2,2,2,2,2,2,2,2,2,2,2,1
1,2,2,2,2,2,2,2,2,2,2,0,0,19,20,2,2,2,2,2,2,2,2,2,1
1,2,2,2,2,2,2,2,2,2,2,0,0,19,0,2,2,2,2,2,2,2,2,2,1
1,2,2,2,2,2,2,2,2,2,0,0,0,0,0,2,2,2,2,2,2,2,2,2,1
1,2,2,2,2,2,2,2,2,2,0,0,0,0,0,2,2,2,2,2,2,2,2,2,1
1,2,2,2,2,2,2,2,2,2,0,0,0,0,0,2,2,2,2,2,2,2,2,2,1
1,2,2,2,2,2,2,2,2,2,2,2,2,2,2,2,2,2,2,2,2,2,2,2,1
1,2,2,2,2,2,2,2,2,2,2,2,2,2,2,2,2,2,2,2,2,2,2,2,1
1,2,2,2,2,2,2,2,2,2,2,2,2,2,2,2,2,2,2,2,2,2,2,2,1
1,2,2,2,2,2,2,2,2,2,2,2,2,2,2,2,2,2,2,2,2,2,2,2,1
1,2,2,2,2,2,2,2,2,2,2,2,2,2,2,2,2,2,2,2,2,2,2,2,1
1,2,2,2,2,2,2,2,2,2,2,2,2,2,2,2,2,2,2,2,2,2,2,2,1
1,2,2,2,2,2,2,2,2,2,2,2,2,2,2,2,2,2,2,2,2,2,2,2,1
1,2,2,2,2,2,2,2,2,2,2,2,2,2,2,2,2,2,2,2,2,2,2,2,1
1,2,2,2,2,2,2,2,2,2,2,2,2,2,2,2,2,2,2,2,2,2,2,2,1
1,1,1,1,1,1,1,1,1,1,1,1,1,1,1,1,1,1,1,1,1,1,1,1,1
endlayer

layer
1,1,1,1,1,1,1,1,1,1,1,1,1,1,1,1,1,1,1,1,1,1,1,1,1
1,0,0,0,0,0,5,0,0,0,0,0,7,21,7,0,0,0,0,0,0,0,0,0,1
1,0,34,0,34,3,5,0,10,0,0,0,13,7,13,0,0,10,0,0,0,0,10,0,1
1,0,10,0,10,36,5,0,10,37,12,10,0,13,10,36,0,10,0,10,35,0,10,0,1
1,0,10,0,10,0,5,0,10,10,10,10,0,0,10,10,10,10,0,10,10,10,10,0,1
1,0,0,0,0,0,5,0,0,0,0,0,0,0,0,0,0,0,0,0,0,0,0,0,1
1,35,34,0,34,0,5,5,5,5,5,0,0,5,5,5,5,5,5,5,5,5,5,5,1
1,0,10,0,10,36,5,0,0,0,0,0,0,0,0,0,0,0,5,38,7,0,0,10,1
1,0,10,0,10,0,5,0,0,0,0,0,0,0,0,0,0,0,5,34,0,0,0,10,1
1,0,0,0,0,0,5,0,0,2,0,19,19,19,0,2,0,0,5,39,39,39,0,0,1
1,35,0,0,0,0,5,0,0,19,40,19,0,19,0,19,0,0,5,0,0,0,0,0,1
1,35,0,0,0,0,5,0,0,19,2,0,0,0,0,19,0,0,5,39,39,39,0,0,1
1,0,0,0,0,0,41,0,0,19,0,0,0,0,0,19,0,0,0,0,0,0,0,0,1
1,0,0,0,0,0,5,0,0,19,0,0,0,0,0,19,0,0,0,0,0,0,0,0,1
1,0,10,0,10,0,5,0,0,19,0,0,0,0,0,19,0,0,0,0,42,0,42,0,1
1,35,10,0,10,0,5,13,0,2,19,19,19,19,19,2,0,0,5,10,10,0,10,10,1
1,0,34,0,34,36,5,7,13,0,0,0,0,0,0,0,0,0,5,46,45,0,44,43,1
1,0,0,0,0,0,5,38,7,13,0,0,0,0,0,0,0,0,5,0,42,0,42,0,1
1,5,5,5,5,5,5,5,5,5,0,0,0,5,5,5,5,5,5,10,10,7,10,10,1
1,21,10,10,0,10,10,0,10,10,0,0,0,0,12,0,12,0,5,47,48,49,48,47,1
1,7,0,0,0,0,0,0,0,0,0,0,0,35,10,10,10,36,5,0,42,0,42,50,1
1,0,0,10,10,10,10,10,10,0,0,0,0,0,51,0,12,0,5,10,10,0,10,10,1
1,0,0,10,10,10,10,10,10,0,0,0,0,35,10,10,10,36,5,46,45,0,49,47,1
1,0,0,0,0,0,0,0,0,0,0,0,0,0,51,0,51,0,5,30,0,0,0,29,1
1,1,1,1,1,1,1,1,1,1,1,1,1,1,1,1,1,1,1,1,1,1,1,1,1
endlayer

layer
1,1,1,1,1,1,1,1,1,1,1,1,1,1,1,1,1,1,1,1,1,1,1,1,1
1,0,0,0,0,0,5,0,0,0,0,0,0,13,0,0,0,0,0,0,0,0,0,0,1
1,0,52,0,52,0,5,0,39,0,0,0,0,0,0,0,0,39,0,0,0,0,39,0,1
1,0,0,0,0,0,5,0,0,0,0,0,0,0,0,0,0,39,0,0,0,0,39,0,1
1,0,0,0,0,0,5,0,0,0,0,0,0,0,0,39,39,39,0,0,39,39,39,0,1
1,0,0,0,0,0,5,0,0,0,0,0,0,0,0,0,0,0,0,0,0,0,0,0,1
1,0,52,0,52,0,5,5,5,5,5,0,0,0,5,5,5,5,5,5,5,5,5,5,1
1,0,0,0,0,0,5,0,0,0,0,0,0,0,0,0,0,0,5,28,0,0,0,0,1
1,0,0,0,0,0,5,0,0,0,0,0,0,0,0,0,0,0,5,0,0,0,0,0,1
1,0,0,0,0,0,5,0,0,2,0,0,0,0,0,2,0,0,5,0,39,39,0,0,1
1,0,0,0,0,0,5,0,0,0,0,19,0,0,0,0,0,0,5,0,0,0,0,0,1
1,0,0,0,0,0,5,0,0,19,40,19,0,0,0,0,0,0,5,39,39,39,0,0,1
1,0,0,0,0,0,53,0,0,0,2,0,0,0,0,0,0,0,0,0,0,0,0,0,1
1,0,0,0,0,0,5,0,0,0,0,0,0,0,0,0,0,0,0,0,0,0,0,0,1
1,0,0,0,0,0,5,0,0,0,0,0,0,0,0,0,0,0,5,0,42,0,42,0,1
1,0,0,0,0,0,5,0,0,2,0,0,0,0,0,2,0,0,5,10,10,0,10,10,1
1,0,52,0,52,0,5,0,0,0,0,0,0,0,0,0,0,0,5,0,0,0,0,0,1
1,0,0,0,0,0,5,13,0,0,0,0,0,0,0,0,0,0,5,0,42,0,42,0,1
1,5,5,5,5,5,5,5,5,5,5,0,0,0,5,5,5,5,5,10,10,0,10,10,1
1,28,10,10,0,10,10,0,10,10,0,0,0,0,0,0,0,0,5,47,0,0,0,47,1
1,0,0,0,0,0,0,0,0,0,0,0,0,0,0,0,0,0,5,0,42,0,42,0,1
1,0,0,0,0,0,0,0,0,0,0,0,0,0,0,0,0,0,5,10,10,0,10,10,1
1,0,0,0,0,0,0,0,0,0,0,0,0,0,0,0,0,0,5,0,0,0,0,47,1
1,0,0,0,0,0,0,0,0,0,0,0,0,0,0,0,0,0,5,0,0,0,0,0,1
1,1,1,1,1,1,1,1,1,1,1,1,1,1,1,1,1,1,1,1,1,1,1,1,1
endlayer

layer
1,1,1,1,1,1,1,1,1,1,1,1,1,1,1,1,1,1,1,1,1,1,1,1,1
1,0,39,39,39,0,5,0,0,0,0,0,0,0,0,0,0,0,0,0,0,0,0,0,1
1,0,0,0,0,0,5,0,0,0,0,0,0,0,0,0,0,0,0,0,0,0,0,0,1
1,0,0,0,0,0,5,0,0,0,0,0,0,0,0,0,0,0,0,0,0,0,0,0,1
1,0,0,0,0,0,5,0,0,0,0,0,0,0,0,0,0,0,0,0,0,0,0,0,1
1,0,0,0,0,0,5,0,0,0,0,0,0,0,0,0,0,0,0,0,0,0,0,0,1
1,0,0,0,0,0,5,5,5,5,5,5,0,5,5,5,5,5,5,5,5,5,5,5,1
1,0,0,0,0,0,5,0,0,0,0,0,0,0,0,0,0,0,5,0,0,0,0,0,1
1,39,0,0,0,0,5,0,0,0,0,0,0,0,0,0,0,0,5,0,0,0,0,0,1
1,39,0,0,0,0,5,0,0,2,0,0,0,0,0,2,0,0,5,0,39,39,0,0,1
1,39,0,0,0,0,5,0,0,0,0,0,0,0,0,0,0,0,5,0,0,39,0,0,1
1,0,0,0,0,0,5,0,0,19,0,19,0,0,0,0,0,0,5,0,39,39,0,0,1
1,0,0,0,0,0,5,0,0,19,40,19,0,0,0,0,0,0,0,0,0,0,0,0,1
1,0,0,0,0,0,5,0,0,0,2,0,0,0,0,0,0,0,5,0,0,0,0,0,1
1,0,0,0,0,0,5,0,0,0,0,0,0,0,0,0,0,0,5,0,0,0,0,0,1
1,0,0,0,0,0,5,0,0,2,0,0,0,0,0,2,0,0,5,46,45,0,44,43,1
1,0,0,0,0,0,5,0,0,0,0,0,0,0,0,0,0,0,5,0,0,0,0,0,1
1,0,39,39,39,0,5,0,0,0,0,0,0,0,0,0,0,0,5,0,0,0,0,0,1
1,5,5,5,5,5,5,5,5,5,0,0,0,5,5,5,5,5,5,46,45,0,44,43,1
1,0,0,0,0,0,0,0,0,0,0,0,0,0,0,0,0,0,5,0,0,0,0,0,1
1,0,0,0,0,0,0,0,0,0,0,0,0,0,0,0,0,0,5,0,0,0,0,0,1
1,0,0,0,0,0,0,0,0,0,0,0,0,0,0,0,0,0,5,46,45,0,44,43,1
1,0,0,0,0,0,0,0,0,0,0,0,0,0,0,0,0,0,5,0,0,0,0,0,1
1,0,0,0,0,0,0,0,0,0,0,0,0,0,0,0,0,0,5,0,0,0,0,0,1
1,1,1,1,1,1,1,1,1,1,1,1,1,1,1,1,1,1,1,1,1,1,1,1,1
endlayer

layer
1,1,1,1,1,1,1,1,1,1,1,1,1,1,1,1,1,1,1,1,1,1,1,1,1
1,0,0,0,0,0,5,0,0,0,0,0,0,0,0,0,0,0,0,0,0,0,0,0,1
1,0,0,0,0,0,5,0,0,0,0,0,0,0,0,0,0,0,0,0,0,0,0,0,1
1,0,0,0,0,0,5,0,0,0,0,0,0,0,0,0,0,0,0,0,0,0,0,0,1
1,0,0,0,0,0,5,0,0,0,0,0,0,0,0,0,0,0,0,0,0,0,0,0,1
1,0,0,0,0,0,5,0,0,0,0,0,0,0,0,0,0,0,0,0,0,0,0,0,1
1,0,0,0,0,0,5,5,5,5,5,5,5,5,5,5,5,5,5,5,5,5,5,5,1
1,0,0,0,0,0,5,0,0,0,0,0,0,0,0,0,0,0,5,0,0,0,0,0,1
1,0,0,0,0,0,5,0,0,0,0,0,0,0,0,0,0,0,5,0,0,0,0,0,1
1,0,0,0,0,0,5,0,0,2,0,0,0,0,0,2,0,0,5,0,0,0,0,0,1
1,0,0,0,0,0,5,0,0,0,0,0,0,0,0,0,0,0,5,34,0,0,0,0,1
1,0,0,0,0,0,5,0,0,0,0,0,0,0,0,0,0,0,5,0,0,0,0,0,1
1,0,0,0,0,0,5,0,0,19,0,19,0,0,0,0,0,0,5,0,0,0,0,0,1
1,0,0,0,0,0,5,0,0,19,40,19,0,0,0,0,0,0,5,0,0,0,0,0,1
1,0,0,0,0,0,5,0,0,0,2,2,0,0,0,0,0,0,5,0,0,0,0,0,1
1,0,0,0,0,0,5,0,0,2,0,0,0,0,0,2,0,0,5,0,0,0,0,0,1
1,0,0,0,0,0,5,0,0,0,0,0,0,0,0,0,0,0,5,0,0,0,0,0,1
1,0,0,0,0,0,5,0,0,0,0,0,0,0,0,0,0,0,5,0,0,0,0,0,1
1,5,5,5,5,5,5,5,5,5,5,5,0,5,5,5,5,5,5,0,0,0,0,0,1
1,0,0,0,0,0,0,0,0,0,0,0,0,0,0,0,0,0,5,0,0,0,0,0,1
1,0,0,0,0,0,0,0,0,0,0,0,0,0,0,0,0,0,5,0,0,0,0,0,1
1,0,0,0,0,0,0,0,0,0,0,0,0,0,0,0,0,0,5,0,0,0,0,0,1
1,0,0,0,0,0,0,0,0,0,0,0,0,0,0,0,0,0,5,0,0,0,0,0,1
1,0,0,0,0,0,0,0,0,0,0,0,0,0,0,0,0,0,5,0,0,0,0,0,1
1,1,1,1,1,1,1,1,1,1,1,1,1,1,1,1,1,1,1,1,1,1,1,1,1
endlayer

layer
1,1,1,1,1,1,1,1,1,1,1,1,1,1,1,1,1,1,1,1,1,1,1,1,1
1,1,1,1,1,1,1,1,1,1,1,1,1,1,1,1,1,1,1,1,1,1,1,1,1
1,1,1,1,1,1,1,1,1,1,1,1,1,1,1,1,1,1,1,1,1,1,1,1,1
1,1,1,1,1,1,1,1,1,1,1,1,1,1,1,1,1,1,1,1,1,1,1,1,1
1,1,1,1,1,1,1,1,1,1,1,1,1,1,1,1,1,1,1,1,1,1,1,1,1
1,1,1,1,1,1,1,1,1,1,1,1,1,1,1,1,1,1,1,1,1,1,1,1,1
1,1,1,1,1,1,1,1,1,1,1,1,1,1,1,1,1,1,1,1,1,1,1,1,1
1,1,1,1,1,1,1,1,1,1,1,1,1,1,1,1,1,1,1,1,1,1,1,1,1
1,1,1,1,1,1,1,1,1,1,1,1,1,1,1,1,1,1,1,1,1,1,1,1,1
1,1,1,1,1,1,1,1,1,1,1,1,1,1,1,1,1,1,1,1,1,1,1,1,1
1,1,1,1,1,1,1,1,1,1,0,0,0,0,0,1,1,1,1,1,1,1,1,1,1
1,1,1,1,1,1,1,1,1,1,0,0,0,0,0,1,1,1,1,1,1,1,1,1,1
1,1,1,1,1,1,1,1,1,1,0,0,0,0,0,1,1,1,1,1,1,1,1,1,1
1,1,1,1,1,1,1,1,1,1,0,19,0,0,0,1,1,1,1,1,1,1,1,1,1
1,1,1,1,1,1,1,1,1,1,0,54,2,0,0,1,1,1,1,1,1,1,1,1,1
1,1,1,1,1,1,1,1,1,1,1,1,1,1,1,1,1,1,1,1,1,1,1,1,1
1,1,1,1,1,1,1,1,1,1,1,1,1,1,1,1,1,1,1,1,1,1,1,1,1
1,1,1,1,1,1,1,1,1,1,1,1,1,1,1,1,1,1,1,1,1,1,1,1,1
1,1,1,1,1,1,1,1,1,1,1,1,1,1,1,1,1,1,1,1,1,1,1,1,1
1,1,1,1,1,1,1,1,1,1,1,1,1,1,1,1,1,1,1,1,1,1,1,1,1
1,1,1,1,1,1,1,1,1,1,1,1,1,1,1,1,1,1,1,1,1,1,1,1,1
1,1,1,1,1,1,1,1,1,1,1,1,1,1,1,1,1,1,1,1,1,1,1,1,1
1,1,1,1,1,1,1,1,1,1,1,1,1,1,1,1,1,1,1,1,1,1,1,1,1
1,1,1,1,1,1,1,1,1,1,1,1,1,1,1,1,1,1,1,1,1,1,1,1,1
1,1,1,1,1,1,1,1,1,1,1,1,1,1,1,1,1,1,1,1,1,1,1,1,1
endlayer

layer
55,55,55,55,55,55,55,55,55,55,55,55,55,55,55,55,55,55,55,55,55,55,55,55,55
55,55,55,55,55,55,55,55,55,55,55,55,55,55,55,55,55,55,55,55,55,55,55,55,55
55,55,55,55,55,55,55,55,55,55,55,55,55,55,55,55,55,55,55,55,55,55,55,55,55
55,55,55,55,55,55,55,55,55,55,55,55,55,55,55,55,55,55,55,55,55,55,55,55,55
55,55,55,55,55,55,55,55,55,55,55,55,55,55,55,55,55,55,55,55,55,55,55,55,55
55,55,55,55,55,55,55,55,55,55,55,55,55,55,55,55,55,55,55,55,55,55,55,55,55
55,55,55,55,55,55,55,55,55,55,55,55,55,55,55,55,55,55,55,55,55,55,55,55,55
55,55,55,55,55,55,55,55,55,55,55,55,55,55,55,55,55,55,55,55,55,55,55,55,55
55,55,55,55,55,55,55,55,55,55,55,55,55,55,55,55,55,55,55,55,55,55,55,55,55
55,55,55,55,55,55,55,55,55,1,1,1,1,1,1,1,55,55,55,55,55,55,55,55,55
55,55,55,55,55,55,55,55,55,1,0,0,0,0,0,1,55,55,55,55,55,55,55,55,55
55,55,55,55,55,55,55,55,55,1,0,0,0,0,0,1,55,55,55,55,55,55,55,55,55
55,55,55,55,55,55,55,55,55,1,0,0,0,0,0,1,55,55,55,55,55,55,55,55,55
55,55,55,55,55,55,55,55,55,1,0,19,19,0,0,1,55,55,55,55,55,55,55,55,55
55,55,55,55,55,55,55,55,55,1,0,0,54,2,0,1,55,55,55,55,55,55,55,55,55
55,55,55,55,55,55,55,55,55,1,1,1,1,1,1,1,55,55,55,55,55,55,55,55,55
55,55,55,55,55,55,55,55,55,55,55,55,55,55,55,55,55,55,55,55,55,55,55,55,55
55,55,55,55,55,55,55,55,55,55,55,55,55,55,55,55,55,55,55,55,55,55,55,55,55
55,55,55,55,55,55,55,55,55,55,55,55,55,55,55,55,55,55,55,55,55,55,55,55,55
55,55,55,55,55,55,55,55,55,55,55,55,55,55,55,55,55,55,55,55,55,55,55,55,55
55,55,55,55,55,55,55,55,55,55,55,55,55,55,55,55,55,55,55,55,55,55,55,55,55
55,55,55,55,55,55,55,55,55,55,55,55,55,55,55,55,55,55,55,55,55,55,55,55,55
55,55,55,55,55,55,55,55,55,55,55,55,55,55,55,55,55,55,55,55,55,55,55,55,55
55,55,55,55,55,55,55,55,55,55,55,55,55,55,55,55,55,55,55,55,55,55,55,55,55
55,55,55,55,55,55,55,55,55,55,55,55,55,55,55,55,55,55,55,55,55,55,55,55,55
endlayer

layer
55,55,55,55,55,55,55,55,55,55,55,55,55,55,55,55,55,55,55,55,55,55,55,55,55
55,55,55,55,55,55,55,55,55,55,55,55,55,55,55,55,55,55,55,55,55,55,55,55,55
55,55,55,55,55,55,55,55,55,55,55,55,55,55,55,55,55,55,55,55,55,55,55,55,55
55,55,55,55,55,55,55,55,55,55,55,55,55,55,55,55,55,55,55,55,55,55,55,55,55
55,55,55,55,55,55,55,55,55,55,55,55,55,55,55,55,55,55,55,55,55,55,55,55,55
55,55,55,55,55,55,55,55,55,55,55,55,55,55,55,55,55,55,55,55,55,55,55,55,55
55,55,55,55,55,55,55,55,55,55,55,55,55,55,55,55,55,55,55,55,55,55,55,55,55
55,55,55,55,55,55,55,55,55,55,55,55,55,55,55,55,55,55,55,55,55,55,55,55,55
55,55,55,55,55,55,55,55,55,55,55,55,55,55,55,55,55,55,55,55,55,55,55,55,55
55,55,55,55,55,55,55,55,55,1,1,1,1,1,1,1,55,55,55,55,55,55,55,55,55
55,55,55,55,55,55,55,55,55,1,0,0,0,0,0,1,55,55,55,55,55,55,55,55,55
55,55,55,55,55,55,55,55,55,1,0,0,0,0,0,1,55,55,55,55,55,55,55,55,55
55,55,55,55,55,55,55,55,55,1,0,0,0,0,0,1,55,55,55,55,55,55,55,55,55
55,55,55,55,55,55,55,55,55,1,0,0,19,19,2,1,55,55,55,55,55,55,55,55,55
55,55,55,55,55,55,55,55,55,1,0,0,0,54,2,1,55,55,55,55,55,55,55,55,55
55,55,55,55,55,55,55,55,55,1,1,1,1,1,1,1,55,55,55,55,55,55,55,55,55
55,55,55,55,55,55,55,55,55,55,55,55,55,55,55,55,55,55,55,55,55,55,55,55,55
55,55,55,55,55,55,55,55,55,55,55,55,55,55,55,55,55,55,55,55,55,55,55,55,55
55,55,55,55,55,55,55,55,55,55,55,55,55,55,55,55,55,55,55,55,55,55,55,55,55
55,55,55,55,55,55,55,55,55,55,55,55,55,55,55,55,55,55,55,55,55,55,55,55,55
55,55,55,55,55,55,55,55,55,55,55,55,55,55,55,55,55,55,55,55,55,55,55,55,55
55,55,55,55,55,55,55,55,55,55,55,55,55,55,55,55,55,55,55,55,55,55,55,55,55
55,55,55,55,55,55,55,55,55,55,55,55,55,55,55,55,55,55,55,55,55,55,55,55,55
55,55,55,55,55,55,55,55,55,55,55,55,55,55,55,55,55,55,55,55,55,55,55,55,55
55,55,55,55,55,55,55,55,55,55,55,55,55,55,55,55,55,55,55,55,55,55,55,55,55
endlayer

layer
55,55,55,55,55,55,55,55,55,55,55,55,55,55,55,55,55,55,55,55,55,55,55,55,55
55,55,55,55,55,55,55,55,55,55,55,55,55,55,55,55,55,55,55,55,55,55,55,55,55
55,55,55,55,55,55,55,55,55,55,55,55,55,55,55,55,55,55,55,55,55,55,55,55,55
55,55,55,55,55,55,55,55,55,55,55,55,55,55,55,55,55,55,55,55,55,55,55,55,55
55,55,55,55,55,55,55,55,55,55,55,55,55,55,55,55,55,55,55,55,55,55,55,55,55
55,55,55,55,55,55,55,55,55,55,55,55,55,55,55,55,55,55,55,55,55,55,55,55,55
55,55,55,55,55,55,55,55,55,55,55,55,55,55,55,55,55,55,55,55,55,55,55,55,55
55,55,55,55,55,55,55,55,55,55,55,55,55,55,55,55,55,55,55,55,55,55,55,55,55
55,55,55,55,55,55,55,55,55,55,55,55,55,55,55,55,55,55,55,55,55,55,55,55,55
55,55,55,55,55,55,55,55,55,1,1,1,1,1,1,1,55,55,55,55,55,55,55,55,55
55,55,55,55,55,55,55,55,55,1,0,0,0,0,0,1,55,55,55,55,55,55,55,55,55
55,55,55,55,55,55,55,55,55,1,0,0,0,0,0,1,55,55,55,55,55,55,55,55,55
55,55,55,55,55,55,55,55,55,1,0,0,0,0,2,1,55,55,55,55,55,55,55,55,55
55,55,55,55,55,55,55,55,55,1,0,0,0,19,20,1,55,55,55,55,55,55,55,55,55
55,55,55,55,55,55,55,55,55,1,0,0,0,0,0,1,55,55,55,55,55,55,55,55,55
55,55,55,55,55,55,55,55,55,1,1,1,1,1,1,1,55,55,55,55,55,55,55,55,55
55,55,55,55,55,55,55,55,55,55,55,55,55,55,55,55,55,55,55,55,55,55,55,55,55
55,55,55,55,55,55,55,55,55,55,55,55,55,55,55,55,55,55,55,55,55,55,55,55,55
55,55,55,55,55,55,55,55,55,55,55,55,55,55,55,55,55,55,55,55,55,55,55,55,55
55,55,55,55,55,55,55,55,55,55,55,55,55,55,55,55,55,55,55,55,55,55,55,55,55
55,55,55,55,55,55,55,55,55,55,55,55,55,55,55,55,55,55,55,55,55,55,55,55,55
55,55,55,55,55,55,55,55,55,55,55,55,55,55,55,55,55,55,55,55,55,55,55,55,55
55,55,55,55,55,55,55,55,55,55,55,55,55,55,55,55,55,55,55,55,55,55,55,55,55
55,55,55,55,55,55,55,55,55,55,55,55,55,55,55,55,55,55,55,55,55,55,55,55,55
55,55,55,55,55,55,55,55,55,55,55,55,55,55,55,55,55,55,55,55,55,55,55,55,55
endlayer

layer
55,55,55,55,55,55,55,55,55,55,55,55,55,55,55,55,55,55,55,55,55,55,55,55,55
55,55,55,55,55,55,55,55,55,55,55,55,55,55,55,55,55,55,55,55,55,55,55,55,55
55,55,55,55,55,55,55,55,55,55,55,55,55,55,55,55,55,55,55,55,55,55,55,55,55
55,55,55,55,55,55,55,55,55,55,55,55,55,55,55,55,55,55,55,55,55,55,55,55,55
55,55,55,55,55,55,55,55,55,55,55,55,55,55,55,55,55,55,55,55,55,55,55,55,55
55,55,55,55,55,55,55,55,55,55,55,55,55,55,55,55,55,55,55,55,55,55,55,55,55
55,55,55,55,55,55,55,55,55,55,55,55,55,55,55,55,55,55,55,55,55,55,55,55,55
55,55,55,55,55,55,55,55,55,55,55,55,55,55,55,55,55,55,55,55,55,55,55,55,55
55,55,55,55,55,55,55,55,55,55,55,55,55,55,55,55,55,55,55,55,55,55,55,55,55
55,55,55,55,55,55,55,55,55,1,1,1,1,1,1,1,55,55,55,55,55,55,55,55,55
55,55,55,55,55,55,55,55,55,1,0,0,0,0,0,1,55,55,55,55,55,55,55,55,55
55,55,55,55,55,55,55,55,55,1,0,0,0,0,2,1,55,55,55,55,55,55,55,55,55
55,55,55,55,55,55,55,55,55,1,0,0,0,19,20,1,55,55,55,55,55,55,55,55,55
55,55,55,55,55,55,55,55,55,1,0,0,0,19,0,1,55,55,55,55,55,55,55,55,55
55,55,55,55,55,55,55,55,55,1,0,0,0,0,0,1,55,55,55,55,55,55,55,55,55
55,55,55,55,55,55,55,55,55,1,1,1,1,1,1,1,55,55,55,55,55,55,55,55,55
55,55,55,55,55,55,55,55,55,55,55,55,55,55,55,55,55,55,55,55,55,55,55,55,55
55,55,55,55,55,55,55,55,55,55,55,55,55,55,55,55,55,55,55,55,55,55,55,55,55
55,55,55,55,55,55,55,55,55,55,55,55,55,55,55,55,55,55,55,55,55,55,55,55,55
55,55,55,55,55,55,55,55,55,55,55,55,55,55,55,55,55,55,55,55,55,55,55,55,55
55,55,55,55,55,55,55,55,55,55,55,55,55,55,55,55,55,55,55,55,55,55,55,55,55
55,55,55,55,55,55,55,55,55,55,55,55,55,55,55,55,55,55,55,55,55,55,55,55,55
55,55,55,55,55,55,55,55,55,55,55,55,55,55,55,55,55,55,55,55,55,55,55,55,55
55,55,55,55,55,55,55,55,55,55,55,55,55,55,55,55,55,55,55,55,55,55,55,55,55
55,55,55,55,55,55,55,55,55,55,55,55,55,55,55,55,55,55,55,55,55,55,55,55,55
endlayer

layer
55,55,55,55,55,55,55,55,55,55,55,55,55,55,55,55,55,55,55,55,55,55,55,55,55
55,55,55,55,55,55,55,55,55,55,55,55,55,55,55,55,55,55,55,55,55,55,55,55,55
55,55,55,55,55,55,55,55,55,55,55,55,55,55,55,55,55,55,55,55,55,55,55,55,55
55,55,55,55,55,55,55,55,55,55,55,55,55,55,55,55,55,55,55,55,55,55,55,55,55
55,55,55,55,55,55,55,55,55,55,55,55,55,55,55,55,55,55,55,55,55,55,55,55,55
55,55,55,55,55,55,55,55,55,55,55,55,55,55,55,55,55,55,55,55,55,55,55,55,55
55,55,55,55,55,55,55,55,55,55,55,55,55,55,55,55,55,55,55,55,55,55,55,55,55
55,55,55,55,55,55,55,55,55,55,55,55,55,55,55,55,55,55,55,55,55,55,55,55,55
55,55,55,55,55,55,55,55,55,55,55,55,55,55,55,55,55,55,55,55,55,55,55,55,55
55,55,55,55,55,55,55,55,55,1,1,1,1,1,1,1,55,55,55,55,55,55,55,55,55
55,55,55,55,55,55,55,55,55,1,0,0,0,2,2,1,55,55,55,55,55,55,55,55,55
55,55,55,55,55,55,55,55,55,1,0,0,0,19,20,1,55,55,55,55,55,55,55,55,55
55,55,55,55,55,55,55,55,55,1,0,0,0,19,0,1,55,55,55,55,55,55,55,55,55
55,55,55,55,55,55,55,55,55,1,0,0,0,0,0,1,55,55,55,55,55,55,55,55,55
55,55,55,55,55,55,55,55,55,1,0,0,0,0,0,1,55,55,55,55,55,55,55,55,55
55,55,55,55,55,55,55,55,55,1,1,1,1,1,1,1,55,55,55,55,55,55,55,55,55
55,55,55,55,55,55,55,55,55,55,55,55,55,55,55,55,55,55,55,55,55,55,55,55,55
55,55,55,55,55,55,55,55,55,55,55,55,55,55,55,55,55,55,55,55,55,55,55,55,55
55,55,55,55,55,55,55,55,55,55,55,55,55,55,55,55,55,55,55,55,55,55,55,55,55
55,55,55,55,55,55,55,55,55,55,55,55,55,55,55,55,55,55,55,55,55,55,55,55,55
55,55,55,55,55,55,55,55,55,55,55,55,55,55,55,55,55,55,55,55,55,55,55,55,55
55,55,55,55,55,55,55,55,55,55,55,55,55,55,55,55,55,55,55,55,55,55,55,55,55
55,55,55,55,55,55,55,55,55,55,55,55,55,55,55,55,55,55,55,55,55,55,55,55,55
55,55,55,55,55,55,55,55,55,55,55,55,55,55,55,55,55,55,55,55,55,55,55,55,55
55,55,55,55,55,55,55,55,55,55,55,55,55,55,55,55,55,55,55,55,55,55,55,55,55
endlayer

layer
56,56,56,56,56,56,56,56,56,56,56,56,56,56,56,56,56,56,56,56,56,56,56,56,56
56,56,56,56,56,56,56,56,56,56,56,56,56,56,56,56,56,56,56,56,56,56,56,56,56
56,56,56,56,56,56,56,56,56,56,56,56,56,56,56,56,56,56,56,56,56,56,56,56,56
56,56,56,56,56,56,56,56,56,56,56,56,56,56,56,56,56,56,56,56,56,56,56,56,56
56,56,56,56,56,56,56,56,56,56,56,56,56,56,56,56,56,56,56,56,56,56,56,56,56
56,56,56,56,56,56,56,56,56,56,56,56,56,56,56,56,56,56,56,56,56,56,56,56,56
56,56,56,56,56,56,56,56,56,56,56,56,56,56,56,56,56,56,56,56,56,56,56,56,56
56,56,56,56,56,56,56,56,56,56,56,56,56,56,56,56,56,56,56,56,56,56,56,56,56
56,56,56,56,56,56,56,56,56,56,56,56,56,56,56,56,56,56,56,56,56,56,56,56,56
56,56,56,56,56,56,56,56,56,1,1,1,1,1,1,1,56,56,56,56,56,56,56,56,56
56,56,56,56,56,56,56,56,56,1,0,0,2,57,0,1,56,56,56,56,56,56,56,56,56
56,56,56,56,56,56,56,56,56,1,0,0,0,19,0,1,56,56,56,56,56,56,56,56,56
56,56,56,56,56,56,56,56,56,1,0,0,0,0,0,1,56,56,56,56,56,56,56,56,56
56,56,56,56,56,56,56,56,56,1,0,0,0,0,0,1,56,56,56,56,56,56,56,56,56
56,56,56,56,56,56,56,56,56,1,0,0,0,0,0,1,56,56,56,56,56,56,56,56,56
56,56,56,56,56,56,56,56,56,1,1,1,1,1,1,1,56,56,56,56,56,56,56,56,56
56,56,56,56,56,56,56,56,56,56,56,56,56,56,56,56,56,56,56,56,56,56,56,56,56
56,56,56,56,56,56,56,56,56,56,56,56,56,56,56,56,56,56,56,56,56,56,56,56,56
56,56,56,56,56,56,56,56,56,56,56,56,56,56,56,56,56,56,56,56,56,56,56,56,56
56,56,56,56,56,56,56,56,56,56,56,56,56,56,56,56,56,56,56,56,56,56,56,56,56
56,56,56,56,56,56,56,56,56,56,56,56,56,56,56,56,56,56,56,56,56,56,56,56,56
56,56,56,56,56,56,56,56,56,56,56,56,56,56,56,56,56,56,56,56,56,56,56,56,56
56,56,56,56,56,56,56,56,56,56,56,56,56,56,56,56,56,56,56,56,56,56,56,56,56
56,56,56,56,56,56,56,56,56,56,56,56,56,56,56,56,56,56,56,56,56,56,56,56,56
56,56,56,56,56,56,56,56,56,56,56,56,56,56,56,56,56,56,56,56,56,56,56,56,56
endlayer

layer
56,56,56,56,56,56,56,56,56,56,56,56,56,56,56,56,56,56,56,56,56,56,56,56,56
56,56,56,56,56,56,56,56,56,56,56,56,56,56,56,56,56,56,56,56,56,56,56,56,56
56,56,56,56,56,56,56,56,56,56,56,56,56,56,56,56,56,56,56,56,56,56,56,56,56
56,56,56,56,56,56,56,56,56,56,56,56,56,56,56,56,56,56,56,56,56,56,56,56,56
56,56,56,56,56,56,56,56,56,56,56,56,56,56,56,56,56,56,56,56,56,56,56,56,56
56,56,56,56,56,56,56,56,56,56,56,56,56,56,56,56,56,56,56,56,56,56,56,56,56
56,56,56,56,56,56,56,56,56,56,56,56,56,56,56,56,56,56,56,56,56,56,56,56,56
56,56,56,56,56,56,56,56,56,56,56,56,56,56,56,56,56,56,56,56,56,56,56,56,56
56,56,56,56,56,56,56,56,56,56,56,56,56,56,56,56,56,56,56,56,56,56,56,56,56
56,56,56,56,56,56,56,56,56,1,1,1,1,1,1,1,56,56,56,56,56,56,56,56,56
56,56,56,56,56,56,56,56,56,1,0,2,57,0,0,1,56,56,56,56,56,56,56,56,56
56,56,56,56,56,56,56,56,56,1,0,0,19,19,0,1,56,56,56,56,56,56,56,56,56
56,56,56,56,56,56,56,56,56,1,0,0,0,0,0,1,56,56,56,56,56,56,56,56,56
56,56,56,56,56,56,56,56,56,1,0,0,0,0,0,1,56,56,56,56,56,56,56,56,56
56,56,56,56,56,56,56,56,56,1,0,0,0,0,0,1,56,56,56,56,56,56,56,56,56
56,56,56,56,56,56,56,56,56,1,1,1,1,1,1,1,56,56,56,56,56,56,56,56,56
56,56,56,56,56,56,56,56,56,56,56,56,56,56,56,56,56,56,56,56,56,56,56,56,56
56,56,56,56,56,56,56,56,56,56,56,56,56,56,56,56,56,56,56,56,56,56,56,56,56
56,56,56,56,56,56,56,56,56,56,56,56,56,56,56,56,56,56,56,56,56,56,56,56,56
56,56,56,56,56,56,56,56,56,56,56,56,56,56,56,56,56,56,56,56,56,56,56,56,56
56,56,56,56,56,56,56,56,56,56,56,56,56,56,56,56,56,56,56,56,56,56,56,56,56
56,56,56,56,56,56,56,56,56,56,56,56,56,56,56,56,56,56,56,56,56,56,56,56,56
56,56,56,56,56,56,56,56,56,56,56,56,56,56,56,56,56,56,56,56,56,56,56,56,56
56,56,56,56,56,56,56,56,56,56,56,56,56,56,56,56,56,56,56,56,56,56,56,56,56
56,56,56,56,56,56,56,56,56,56,56,56,56,56,56,56,56,56,56,56,56,56,56,56,56
endlayer

layer
56,56,56,56,56,56,56,56,56,56,56,56,56,56,56,56,56,56,56,56,56,56,56,56,56
56,56,56,56,56,56,56,56,56,56,56,56,56,56,56,56,56,56,56,56,56,56,56,56,56
56,56,56,56,56,56,56,56,56,56,56,56,56,56,56,56,56,56,56,56,56,56,56,56,56
56,56,56,56,56,56,56,56,56,56,56,56,56,56,56,56,56,56,56,56,56,56,56,56,56
56,56,56,56,56,56,56,56,56,56,56,56,56,56,56,56,56,56,56,56,56,56,56,56,56
56,56,56,56,56,56,56,56,56,56,56,56,56,56,56,56,56,56,56,56,56,56,56,56,56
56,56,56,56,56,56,56,56,56,56,56,56,56,56,56,56,56,56,56,56,56,56,56,56,56
56,56,56,56,56,56,56,56,56,56,56,56,56,56,56,56,56,56,56,56,56,56,56,56,56
56,56,56,56,56,56,56,56,56,56,56,56,56,56,56,56,56,56,56,56,56,56,56,56,56
56,56,56,56,56,56,56,56,56,1,1,1,1,1,1,1,56,56,56,56,56,56,56,56,56
56,56,56,56,56,56,56,56,56,1,2,57,0,0,0,1,56,56,56,56,56,56,56,56,56
56,56,56,56,56,56,56,56,56,1,2,19,19,0,0,1,56,56,56,56,56,56,56,56,56
56,56,56,56,56,56,56,56,56,1,0,0,0,0,0,1,56,56,56,56,56,56,56,56,56
56,56,56,56,56,56,56,56,56,1,0,0,0,0,0,1,56,56,56,56,56,56,56,56,56
56,56,56,56,56,56,56,56,56,1,0,0,0,0,0,1,56,56,56,56,56,56,56,56,56
56,56,56,56,56,56,56,56,56,1,1,1,1,1,1,1,56,56,56,56,56,56,56,56,56
56,56,56,56,56,56,56,56,56,56,56,56,56,56,56,56,56,56,56,56,56,56,56,56,56
56,56,56,56,56,56,56,56,56,56,56,56,56,56,56,56,56,56,56,56,56,56,56,56,56
56,56,56,56,56,56,56,56,56,56,56,56,56,56,56,56,56,56,56,56,56,56,56,56,56
56,56,56,56,56,56,56,56,56,56,56,56,56,56,56,56,56,56,56,56,56,56,56,56,56
56,56,56,56,56,56,56,56,56,56,56,56,56,56,56,56,56,56,56,56,56,56,56,56,56
56,56,56,56,56,56,56,56,56,56,56,56,56,56,56,56,56,56,56,56,56,56,56,56,56
56,56,56,56,56,56,56,56,56,56,56,56,56,56,56,56,56,56,56,56,56,56,56,56,56
56,56,56,56,56,56,56,56,56,56,56,56,56,56,56,56,56,56,56,56,56,56,56,56,56
56,56,56,56,56,56,56,56,56,56,56,56,56,56,56,56,56,56,56,56,56,56,56,56,56
endlayer

layer
58,58,58,58,58,58,58,58,58,58,58,58,58,58,58,58,58,58,58,58,58,58,58,58,58
58,58,58,58,58,58,58,58,58,58,58,58,58,58,58,58,58,58,58,58,58,58,58,58,58
58,58,58,58,58,58,58,58,58,58,58,58,58,58,58,58,58,58,58,58,58,58,58,58,58
58,58,58,58,58,58,58,58,58,58,58,58,58,58,58,58,58,58,58,58,58,58,58,58,58
58,58,58,58,58,58,58,58,58,58,58,58,58,58,58,58,58,58,58,58,58,58,58,58,58
58,58,58,58,58,58,58,58,58,58,58,58,58,58,58,58,58,58,58,58,58,58,58,58,58
58,58,58,58,58,58,58,58,58,58,58,58,58,58,58,58,58,58,58,58,58,58,58,58,58
58,58,58,58,58,58,58,58,58,58,58,58,58,58,58,58,58,58,58,58,58,58,58,58,58
58,58,58,58,58,58,58,58,58,58,58,58,58,58,58,58,58,58,58,58,58,58,58,58,58
58,58,58,58,58,58,58,58,58,1,1,1,1,1,1,1,58,58,58,58,58,58,58,58,58
58,58,58,58,58,58,58,58,58,1,0,0,0,0,0,1,58,58,58,58,58,58,58,58,58
58,58,58,58,58,58,58,58,58,1,40,19,0,0,0,1,58,58,58,58,58,58,58,58,58
58,58,58,58,58,58,58,58,58,1,2,0,0,0,0,1,58,58,58,58,58,58,58,58,58
58,58,58,58,58,58,58,58,58,1,0,0,0,0,0,1,58,58,58,58,58,58,58,58,58
58,58,58,58,58,58,58,58,58,1,0,0,0,0,0,1,58,58,58,58,58,58,58,58,58
58,58,58,58,58,58,58,58,58,1,1,1,1,1,1,1,58,58,58,58,58,58,58,58,58
58,58,58,58,58,58,58,58,58,58,58,58,58,58,58,58,58,58,58,58,58,58,58,58,58
58,58,58,58,58,58,58,58,58,58,58,58,58,58,58,58,58,58,58,58,58,58,58,58,58
58,58,58,58,58,58,58,58,58,58,58,58,58,58,58,58,58,58,58,58,58,58,58,58,58
58,58,58,58,58,58,58,58,58,58,58,58,58,58,58,58,58,58,58,58,58,58,58,58,58
58,58,58,58,58,58,58,58,58,58,58,58,58,58,58,58,58,58,58,58,58,58,58,58,58
58,58,58,58,58,58,58,58,58,58,58,58,58,58,58,58,58,58,58,58,58,58,58,58,58
58,58,58,58,58,58,58,58,58,58,58,58,58,58,58,58,58,58,58,58,58,58,58,58,58
58,58,58,58,58,58,58,58,58,58,58,58,58,58,58,58,58,58,58,58,58,58,58,58,58
58,58,58,58,58,58,58,58,58,58,58,58,58,58,58,58,58,58,58,58,58,58,58,58,58
endlayer

layer
58,58,58,58,58,58,58,58,58,58,58,58,58,58,58,58,58,58,58,58,58,58,58,58,58
58,58,58,58,58,58,58,58,58,58,58,58,58,58,58,58,58,58,58,58,58,58,58,58,58
58,58,58,58,58,58,58,58,58,58,58,58,58,58,58,58,58,58,58,58,58,58,58,58,58
58,58,58,58,58,58,58,58,58,58,58,58,58,58,58,58,58,58,58,58,58,58,58,58,58
58,58,58,58,58,58,58,58,58,58,58,58,58,58,58,58,58,58,58,58,58,58,58,58,58
58,58,58,58,58,58,58,58,58,58,58,58,58,58,58,58,58,58,58,58,58,58,58,58,58
58,58,58,58,58,58,58,58,58,58,58,58,58,58,58,58,58,58,58,58,58,58,58,58,58
58,58,58,58,58,58,58,58,58,58,58,58,58,58,58,58,58,58,58,58,58,58,58,58,58
58,58,58,58,58,58,58,58,58,58,58,58,58,58,58,58,58,58,58,58,58,58,58,58,58
58,58,58,58,58,58,58,58,58,1,1,1,1,1,1,1,58,58,58,58,58,58,58,58,58
58,58,58,58,58,58,58,58,58,1,0,0,0,0,0,1,58,58,58,58,58,58,58,58,58
58,58,58,58,58,58,58,58,58,1,0,19,0,0,0,1,58,58,58,58,58,58,58,58,58
58,58,58,58,58,58,58,58,58,1,40,19,0,0,0,1,58,58,58,58,58,58,58,58,58
58,58,58,58,58,58,58,58,58,1,2,0,0,0,0,1,58,58,58,58,58,58,58,58,58
58,58,58,58,58,58,58,58,58,1,0,0,0,0,0,1,58,58,58,58,58,58,58,58,58
58,58,58,58,58,58,58,58,58,1,1,1,1,1,1,1,58,58,58,58,58,58,58,58,58
58,58,58,58,58,58,58,58,58,58,58,58,58,58,58,58,58,58,58,58,58,58,58,58,58
58,58,58,58,58,58,58,58,58,58,58,58,58,58,58,58,58,58,58,58,58,58,58,58,58
58,58,58,58,58,58,58,58,58,58,58,58,58,58,58,58,58,58,58,58,58,58,58,58,58
58,58,58,58,58,58,58,58,58,58,58,58,58,58,58,58,58,58,58,58,58,58,58,58,58
58,58,58,58,58,58,58,58,58,58,58,58,58,58,58,58,58,58,58,58,58,58,58,58,58
58,58,58,58,58,58,58,58,58,58,58,58,58,58,58,58,58,58,58,58,58,58,58,58,58
58,58,58,58,58,58,58,58,58,58,58,58,58,58,58,58,58,58,58,58,58,58,58,58,58
58,58,58,58,58,58,58,58,58,58,58,58,58,58,58,58,58,58,58,58,58,58,58,58,58
58,58,58,58,58,58,58,58,58,58,58,58,58,58,58,58,58,58,58,58,58,58,58,58,58
endlayer

layer
58,58,58,58,58,58,58,58,58,58,58,58,58,58,58,58,58,58,58,58,58,58,58,58,58
58,58,58,58,58,58,58,58,58,58,58,58,58,58,58,58,58,58,58,58,58,58,58,58,58
58,58,58,58,58,58,58,58,58,58,58,58,58,58,58,58,58,58,58,58,58,58,58,58,58
58,58,58,58,58,58,58,58,58,58,58,58,58,58,58,58,58,58,58,58,58,58,58,58,58
58,58,58,58,58,58,58,58,58,58,58,58,58,58,58,58,58,58,58,58,58,58,58,58,58
58,58,58,58,58,58,58,58,58,58,58,58,58,58,58,58,58,58,58,58,58,58,58,58,58
58,58,58,58,58,58,58,58,58,58,58,58,58,58,58,58,58,58,58,58,58,58,58,58,58
58,58,58,58,58,58,58,58,58,58,58,58,58,58,58,58,58,58,58,58,58,58,58,58,58
58,58,58,58,58,58,58,58,58,58,58,58,58,58,58,58,58,58,58,58,58,58,58,58,58
58,58,58,58,58,58,58,58,58,1,1,1,1,1,1,1,58,58,58,58,58,58,58,58,58
58,58,58,58,58,58,58,58,58,1,0,0,0,0,0,1,58,58,58,58,58,58,58,58,58
58,58,58,58,58,58,58,58,58,1,0,0,0,0,0,1,58,58,58,58,58,58,58,58,58
58,58,58,58,58,58,58,58,58,1,0,19,0,0,0,1,58,58,58,58,58,58,58,58,58
58,58,58,58,58,58,58,58,58,1,40,19,0,0,0,1,58,58,58,58,58,58,58,58,58
58,58,58,58,58,58,58,58,58,1,2,0,0,0,0,1,58,58,58,58,58,58,58,58,58
58,58,58,58,58,58,58,58,58,1,1,1,1,1,1,1,58,58,58,58,58,58,58,58,58
58,58,58,58,58,58,58,58,58,58,58,58,58,58,58,58,58,58,58,58,58,58,58,58,58
58,58,58,58,58,58,58,58,58,58,58,58,58,58,58,58,58,58,58,58,58,58,58,58,58
58,58,58,58,58,58,58,58,58,58,58,58,58,58,58,58,58,58,58,58,58,58,58,58,58
58,58,58,58,58,58,58,58,58,58,58,58,58,58,58,58,58,58,58,58,58,58,58,58,58
58,58,58,58,58,58,58,58,58,58,58,58,58,58,58,58,58,58,58,58,58,58,58,58,58
58,58,58,58,58,58,58,58,58,58,58,58,58,58,58,58,58,58,58,58,58,58,58,58,58
58,58,58,58,58,58,58,58,58,58,58,58,58,58,58,58,58,58,58,58,58,58,58,58,58
58,58,58,58,58,58,58,58,58,58,58,58,58,58,58,58,58,58,58,58,58,58,58,58,58
58,58,58,58,58,58,58,58,58,58,58,58,58,58,58,58,58,58,58,58,58,58,58,58,58
endlayer

layer
59,59,59,59,59,59,59,59,59,59,59,59,59,59,59,59,59,59,59,59,59,59,59,59,59
59,59,59,59,59,59,59,59,59,59,59,59,59,59,59,59,59,59,59,59,59,59,59,59,59
59,59,59,59,59,59,59,59,59,59,59,59,59,59,59,59,59,59,59,59,59,0,0,59,59
59,59,59,59,59,59,59,59,59,59,59,59,59,59,59,59,59,59,59,59,59,59,0,59,59
59,59,59,59,59,59,59,60,60,60,60,60,60,60,60,60,60,60,59,59,59,59,59,59,59
59,59,59,59,59,59,60,60,60,60,60,60,60,60,60,60,60,60,60,59,59,59,59,59,59
59,59,59,59,59,60,60,60,60,60,60,60,60,60,60,60,60,60,60,60,59,59,59,59,59
59,59,59,59,60,60,60,60,60,60,60,60,60,60,60,60,60,60,60,60,60,59,59,59,59
59,59,59,59,60,60,60,60,60,60,60,60,60,60,60,60,60,60,60,60,60,59,59,59,59
59,59,59,59,60,60,60,60,60,60,60,60,60,60,60,60,60,60,60,60,60,59,59,59,59
59,59,59,59,60,60,60,60,60,60,0,2,26,26,26,60,60,60,60,60,60,59,59,59,59
59,59,59,59,60,60,60,60,60,60,0,2,26,26,26,60,60,60,60,60,60,59,59,59,59
59,59,59,59,60,60,60,60,60,60,0,2,26,26,26,60,60,60,60,60,60,59,59,59,59
59,59,59,59,60,60,60,60,60,60,0,2,26,26,26,60,60,60,60,60,60,59,59,59,59
59,59,59,59,60,60,60,60,60,60,40,2,26,26,26,60,60,60,60,60,60,59,59,59,59
59,59,59,59,60,60,60,60,60,60,60,60,60,60,60,60,60,60,60,60,60,59,59,59,59
59,59,59,59,60,60,60,60,60,60,60,60,60,60,60,60,60,60,60,60,60,59,59,59,59
59,59,59,59,60,60,60,60,60,60,60,60,60,60,60,60,60,60,60,60,60,59,59,59,59
59,59,59,59,59,60,60,60,60,60,60,60,60,60,60,60,60,60,60,60,59,59,59,59,59
59,59,59,59,59,59,60,60,60,60,60,60,60,60,60,60,60,60,60,59,59,59,59,59,59
59,59,59,59,59,59,59,60,60,60,60,60,60,60,60,60,60,60,59,59,59,59,59,59,59
59,59,59,59,59,59,59,59,59,59,59,59,59,59,59,59,59,59,59,59,59,59,59,59,59
59,59,59,59,59,59,59,59,59,59,59,59,59,59,59,59,59,59,59,59,59,59,59,59,59
59,59,59,59,59,59,59,59,59,59,59,59,59,59,59,59,59,59,59,59,59,59,59,59,59
59,59,59,59,59,59,59,59,59,59,59,59,59,59,59,59,59,59,59,59,59,59,59,59,59
endlayer

layer
59,59,59,59,59,59,59,59,59,0,0,0,0,59,59,59,59,59,59,59,59,59,59,59,59
59,59,59,59,59,59,59,59,59,59,59,59,59,59,59,59,59,59,59,0,0,0,0,59,59
59,59,59,59,59,59,59,59,59,59,59,59,59,59,59,59,59,59,59,59,0,0,0,0,59
59,59,59,59,59,59,59,60,60,60,60,60,60,60,60,60,60,60,60,59,59,0,0,0,59
59,59,59,59,59,59,60,60,60,60,60,60,60,60,60,60,60,60,60,60,59,59,0,59,59
59,59,59,59,59,60,60,60,60,60,60,60,60,60,60,60,60,60,60,60,60,59,59,59,59
59,59,59,59,60,60,60,60,60,60,60,60,60,60,60,60,60,60,60,60,60,60,59,59,59
59,59,59,60,60,60,60,60,0,0,0,0,0,0,0,0,0,60,60,60,60,60,59,59,59
59,59,59,60,60,60,60,0,0,23,0,0,0,0,0,23,0,0,60,60,60,60,59,0,0
59,59,59,60,60,60,60,0,23,60,23,23,23,23,23,60,23,0,60,60,60,60,59,59,0
59,59,59,60,60,60,60,0,0,23,0,0,0,0,0,23,0,0,60,60,60,60,59,59,0
59,59,59,60,60,60,60,0,0,23,0,0,0,0,0,23,0,0,60,60,60,60,59,59,0
59,59,59,60,60,60,60,0,0,23,0,0,0,0,0,23,0,0,60,60,60,60,59,59,59
59,59,59,60,60,60,60,0,0,23,0,0,0,0,0,23,0,0,60,60,60,60,59,59,59
59,59,59,60,60,60,60,0,0,23,0,0,0,0,0,23,0,0,60,60,60,60,59,59,59
59,59,59,60,60,60,60,0,23,60,61,23,23,23,23,60,23,0,60,60,60,60,59,59,59
59,59,59,60,60,60,60,0,0,23,0,0,0,0,0,23,0,0,60,60,60,60,59,59,59
59,59,59,60,60,60,60,60,0,0,0,0,0,0,0,0,0,60,60,60,60,60,59,59,59
59,59,0,60,60,60,60,60,60,60,60,60,60,60,60,60,60,60,60,60,60,60,59,59,59
59,59,0,0,60,60,60,60,60,60,60,60,60,60,60,60,60,60,60,60,60,59,59,59,59
59,59,59,59,59,60,60,60,60,60,60,60,60,60,60,60,60,60,60,60,59,59,59,59,59
59,59,59,59,59,59,60,60,60,60,60,60,60,60,60,60,60,60,60,59,59,59,59,59,59
0,59,0,59,59,59,59,59,59,59,59,59,59,59,59,59,59,59,59,59,59,59,59,59,59
0,0,0,0,59,59,59,0,0,59,59,59,59,59,59,59,59,59,59,59,59,59,59,59,59
0,0,0,59,59,59,59,59,59,59,59,59,0,0,0,59,59,59,59,59,59,59,59,59,59
endlayer

layer
0,0,0,62,0,0,0,0,0,0,0,0,0,0,0,0,0,0,0,0,0,0,0,0,0
0,59,0,0,0,0,0,0,0,0,0,62,0,0,0,59,59,59,0,0,0,0,0,0,0
59,59,59,59,59,0,0,0,0,0,0,0,0,0,0,0,0,0,0,0,0,0,0,0,0
59,59,59,59,0,0,0,0,0,0,0,0,0,0,0,0,0,0,0,0,0,0,0,0,0
0,59,59,0,0,0,0,63,63,63,63,60,0,60,63,63,63,63,0,0,0,0,0,62,0
0,0,0,0,0,0,63,60,60,60,60,60,61,60,60,60,60,60,63,0,0,0,0,0,0
0,0,0,0,0,63,60,0,23,0,23,0,0,0,23,0,23,0,60,63,0,0,0,0,0
0,0,0,0,63,60,0,0,0,0,0,0,0,0,0,0,0,0,0,60,63,0,0,0,0
0,59,0,0,63,60,23,0,0,23,0,0,0,0,0,23,0,0,23,60,63,0,0,0,0
0,59,0,0,63,60,0,0,23,60,23,23,23,23,23,60,23,0,0,60,63,0,0,0,0
0,59,0,0,63,60,0,0,0,23,0,0,0,0,0,23,0,0,0,60,63,0,0,0,0
0,59,59,0,63,60,23,0,0,23,0,0,0,0,0,23,0,0,23,60,63,0,0,0,0
0,59,59,0,63,60,0,0,0,23,0,0,0,0,0,23,0,0,0,60,63,0,0,0,0
0,0,59,0,63,60,23,0,0,23,0,0,0,0,0,23,0,0,23,60,63,0,0,0,0
0,0,59,0,63,60,0,0,0,23,0,0,0,0,0,23,0,0,0,60,63,0,0,62,0
0,0,0,0,63,60,0,0,23,60,64,23,23,23,23,60,23,0,0,60,63,0,0,0,0
0,0,0,0,63,60,23,0,0,23,0,0,0,0,0,23,0,0,23,60,63,0,0,0,0
0,0,0,0,63,60,0,0,0,0,0,0,0,0,0,0,0,0,0,60,63,0,0,0,0
0,0,0,0,0,63,60,0,23,0,0,23,0,23,0,0,23,0,60,63,0,0,0,59,0
0,0,0,0,0,0,63,60,60,60,60,60,60,60,60,60,60,60,63,0,0,0,0,59,0
0,0,0,0,0,0,0,63,63,63,63,63,63,63,63,63,63,63,0,0,0,0,59,59,0
0,0,0,0,0,0,0,0,0,0,0,0,0,0,0,0,0,0,0,0,0,59,59,59,0
0,0,0,0,62,0,0,0,0,0,0,0,0,0,0,0,0,0,0,0,59,59,59,59,0
0,0,0,0,0,0,0,0,0,0,0,0,62,0,0,0,0,0,0,59,59,59,59,0,0
0,0,0,0,0,0,0,0,0,0,0,0,0,0,0,0,0,0,0,0,0,0,0,0,0
endlayer

layer
0,0,0,0,0,0,0,0,0,0,0,0,0,0,0,0,0,0,0,0,0,0,0,0,0
0,0,0,0,0,0,0,0,0,0,0,0,0,0,0,0,0,0,0,0,0,0,0,0,0
0,59,59,0,0,0,0,0,0,0,0,0,0,0,0,0,0,0,0,0,0,0,0,0,0
0,59,0,0,0,0,0,0,0,0,0,0,0,0,0,0,0,0,0,0,0,0,0,0,0
0,0,0,0,0,0,0,0,0,0,0,0,0,0,0,0,0,0,0,0,0,0,0,0,0
0,0,0,0,0,0,0,60,0,0,0,60,27,60,0,0,0,60,0,0,0,0,0,0,0
0,0,0,0,0,0,0,0,23,0,23,0,0,65,23,0,23,0,0,0,0,0,0,0,0
0,0,0,0,0,60,0,0,0,0,0,0,0,0,0,0,0,0,0,60,0,0,0,0,0
0,0,0,0,0,0,23,0,0,23,0,0,0,0,0,23,0,0,23,0,0,0,0,0,0
0,0,0,0,0,0,0,0,23,60,23,23,23,23,23,60,23,0,0,0,0,0,0,0,0
0,0,0,0,0,0,0,0,0,23,0,0,0,0,0,23,0,0,0,0,0,0,0,0,0
0,62,0,0,0,0,23,0,0,23,0,0,0,0,0,23,0,0,23,0,0,0,0,0,0
0,0,0,0,0,60,0,0,0,23,0,0,0,0,0,23,0,0,0,60,0,0,0,0,0
0,0,0,0,0,0,23,0,0,23,0,0,0,0,0,23,0,0,23,0,0,0,0,0,0
0,0,0,0,0,0,0,0,0,23,33,0,0,0,0,23,0,0,0,0,0,0,0,0,0
0,0,0,0,0,0,0,0,23,60,60,23,23,23,23,60,23,0,0,0,0,0,0,0,0
0,0,0,0,0,0,23,0,0,23,0,0,0,0,0,23,0,0,23,0,0,0,0,0,0
0,0,0,0,0,60,0,0,0,0,0,0,0,0,0,0,0,0,0,60,0,0,0,0,0
0,0,0,0,0,0,0,0,23,0,0,23,0,23,0,0,23,0,0,0,0,0,0,0,0
0,0,0,0,0,0,0,60,0,0,0,0,60,0,0,0,0,60,0,0,0,0,0,0,0
0,0,0,0,0,0,0,0,0,0,0,0,0,0,0,0,0,0,0,0,0,0,0,0,0
0,0,0,0,0,0,0,0,0,0,0,0,0,0,0,0,0,0,0,0,0,0,59,0,0
0,0,0,0,0,0,0,0,0,0,0,0,0,0,0,0,0,0,0,0,0,59,59,0,0
0,0,0,0,0,0,0,0,0,0,0,0,0,0,0,0,0,0,0,0,0,0,0,0,0
0,0,0,0,0,0,0,0,0,0,0,0,0,0,0,0,0,0,0,0,0,0,0,0,0
endlayer

layer
0,0,0,0,0,0,0,0,0,0,0,0,0,0,0,0,0,0,0,0,0,0,0,0,0
0,0,0,0,0,0,0,0,0,0,0,0,0,0,0,0,0,0,0,0,0,0,0,0,0
0,0,0,0,0,0,0,0,0,0,0,0,0,0,0,0,0,0,0,0,0,0,0,0,0
0,0,0,0,0,0,0,0,0,0,0,0,0,0,0,0,0,0,0,0,0,0,0,0,0
0,0,0,0,0,0,0,0,0,0,0,0,0,0,0,0,0,0,0,0,0,0,0,0,0
0,0,0,0,0,0,0,0,0,0,0,60,60,60,0,0,0,0,0,0,0,0,0,0,0
0,0,0,0,0,0,0,60,60,60,60,60,60,60,60,60,60,60,0,0,0,0,0,0,0
0,0,0,0,0,0,60,60,60,60,60,60,60,60,60,60,60,60,60,0,0,0,0,0,0
0,0,0,0,0,0,60,60,60,60,60,60,60,60,60,60,60,60,60,0,0,0,0,0,0
0,0,0,0,0,0,60,60,60,60,60,60,60,60,60,60,60,60,60,0,0,0,0,0,0
0,0,0,0,0,0,60,60,60,60,60,0,0,0,60,60,60,60,60,0,0,0,0,0,0
0,0,0,0,0,0,60,60,60,60,0,0,0,0,0,60,60,60,60,0,0,0,0,0,0
0,0,0,0,0,0,60,60,60,60,0,0,0,0,0,60,60,60,60,0,0,0,0,0,0
0,0,0,0,0,0,60,60,60,60,0,0,0,0,0,60,60,60,60,0,0,0,0,0,0
0,0,0,0,0,0,60,60,60,60,60,0,0,0,60,60,60,60,60,0,0,0,0,0,0
0,0,0,0,0,0,60,60,60,60,60,60,60,60,60,60,60,60,60,0,0,0,0,0,0
0,0,0,0,0,0,60,60,60,60,60,60,60,60,60,60,60,60,60,0,0,0,0,0,0
0,0,0,0,0,0,60,60,60,60,60,60,60,60,60,60,60,60,60,0,0,0,0,0,0
0,0,0,0,0,0,0,60,60,60,60,60,60,60,60,60,60,60,0,0,0,0,0,0,0
0,0,0,0,0,0,0,0,0,0,0,0,0,0,0,0,0,0,0,0,0,0,0,0,0
0,0,0,0,0,0,0,0,0,0,0,0,0,0,0,0,0,0,0,0,0,0,0,0,0
0,0,0,0,0,0,0,0,0,0,0,0,0,0,0,0,0,0,0,0,0,0,0,0,0
0,0,0,0,0,0,0,0,0,0,0,0,0,0,0,0,0,0,0,0,0,0,62,0,0
0,0,0,0,0,0,0,0,0,0,0,0,0,0,0,0,0,0,0,0,0,0,0,0,0
0,0,0,0,0,0,0,0,0,0,0,0,0,0,0,0,0,0,0,0,0,0,0,0,0
endlayer

layer
0,0,0,0,0,0,0,0,0,0,0,0,0,0,0,0,0,0,0,0,0,0,0,0,0
0,0,0,0,0,0,0,0,0,0,0,0,0,0,0,0,0,0,0,0,0,0,0,0,0
0,0,0,0,0,0,0,0,0,0,0,0,0,0,0,0,0,0,0,0,0,0,0,0,0
0,0,0,0,0,0,0,0,0,0,0,0,0,0,0,0,0,0,0,0,0,0,0,0,0
0,0,0,0,0,0,0,0,0,0,0,0,0,0,0,0,0,0,0,0,0,0,0,0,0
0,0,0,0,0,0,0,0,0,0,0,63,63,63,0,0,0,0,0,0,0,0,0,0,0
0,0,0,0,0,0,0,63,63,63,63,63,63,63,63,63,63,63,0,0,0,0,0,0,0
0,0,0,0,0,0,63,63,60,60,60,60,60,60,60,60,60,63,63,0,0,0,0,0,0
0,0,0,0,0,0,63,60,60,60,60,60,60,60,60,60,60,60,63,0,0,0,0,0,0
0,0,0,0,0,0,63,60,60,60,60,60,60,60,60,60,60,60,63,0,0,0,0,0,0
0,0,0,0,0,0,63,60,60,60,60,7,7,7,60,60,60,60,63,0,0,0,0,0,0
0,0,0,0,0,0,63,60,60,60,7,7,7,7,7,60,60,60,63,0,0,0,0,0,0
0,0,0,0,0,0,63,60,60,60,7,7,7,7,7,60,60,60,63,0,0,0,0,0,0
0,0,0,0,0,0,63,60,60,60,7,7,7,7,7,60,60,60,63,0,0,0,0,0,0
0,0,0,0,0,0,63,60,60,60,60,7,7,7,60,60,60,60,63,0,0,0,0,0,0
0,0,0,0,0,0,63,60,60,60,60,60,60,60,60,60,60,60,63,0,0,0,0,0,0
0,0,0,0,0,0,63,60,60,60,60,60,60,60,60,60,60,60,63,0,0,0,0,0,0
0,0,0,0,0,0,63,63,60,60,60,60,60,60,60,60,60,63,63,0,0,0,0,0,0
0,0,0,0,0,0,0,63,63,63,63,63,63,63,63,63,63,63,0,0,0,0,0,0,0
0,0,0,0,0,0,0,0,0,0,0,0,0,0,0,0,0,0,0,0,0,0,0,0,0
0,0,0,0,0,0,0,0,0,0,0,0,0,0,0,0,0,0,0,0,0,0,0,0,0
0,0,0,0,0,0,0,0,0,0,0,0,0,0,0,0,0,0,0,0,0,0,0,0,0
0,0,0,0,0,0,0,0,0,0,0,0,0,0,0,0,0,0,0,0,0,0,0,0,0
0,0,0,0,0,0,0,0,0,0,0,0,0,0,0,0,0,0,0,0,0,0,0,0,0
0,0,0,0,0,0,0,0,0,0,0,0,0,0,0,0,0,0,0,0,0,0,0,0,0
endlayer

layer
0,0,0,0,0,0,0,0,0,0,0,0,0,0,0,0,0,0,0,0,0,0,0,0,0
0,0,0,0,0,0,0,0,0,0,0,0,0,0,0,0,0,0,0,0,0,0,0,0,0
0,0,0,0,0,0,0,0,0,0,0,0,0,0,0,0,0,0,0,0,0,0,0,0,0
0,0,0,0,0,0,0,0,0,0,0,0,0,0,0,0,0,0,0,0,0,0,0,0,0
0,0,0,0,0,0,0,0,0,0,0,0,0,0,0,0,0,0,0,0,0,0,0,0,0
0,0,0,0,0,0,0,0,0,0,0,0,0,0,0,0,0,0,0,0,0,0,0,0,0
0,0,0,0,0,0,0,0,0,0,0,0,0,0,0,0,0,0,0,0,0,0,0,0,0
0,0,0,0,0,0,0,0,0,0,0,0,0,0,0,0,0,0,0,0,0,0,0,0,0
0,0,0,0,0,0,0,0,0,60,60,60,60,60,60,60,0,0,0,0,0,0,0,0,0
0,0,0,0,0,0,0,0,60,60,60,60,60,60,60,60,60,0,0,0,0,0,0,0,0
0,0,0,0,0,0,0,0,60,60,60,23,23,23,60,60,60,0,0,0,0,0,0,0,0
0,0,0,0,0,0,0,0,60,60,23,23,23,23,23,60,60,0,0,0,0,0,0,0,0
0,0,0,0,0,0,0,0,60,60,23,23,23,23,23,60,60,0,0,0,0,0,0,0,0
0,0,0,0,0,0,0,0,60,60,23,23,23,23,23,60,60,0,0,0,0,0,0,0,0
0,0,0,0,0,0,0,0,60,60,60,23,23,23,60,60,60,0,0,0,0,0,0,0,0
0,0,0,0,0,0,0,0,60,60,60,60,60,60,60,60,60,0,0,0,0,0,0,0,0
0,0,0,0,0,0,0,0,0,60,60,60,60,60,60,60,0,0,0,0,0,0,0,0,0
0,0,0,0,0,0,0,0,0,0,0,0,0,0,0,0,0,0,0,0,0,0,0,0,0
0,0,0,0,0,0,0,0,0,0,0,0,0,0,0,0,0,0,0,0,0,0,0,0,0
0,0,0,0,0,0,0,0,0,0,0,0,0,0,0,0,0,0,0,0,0,0,0,0,0
0,0,0,0,0,0,0,0,0,0,0,0,0,0,0,0,0,0,0,0,0,0,0,0,0
0,0,0,0,0,0,0,0,0,0,0,0,0,0,0,0,0,0,0,0,0,0,0,0,0
0,0,0,0,0,0,0,0,0,0,0,0,0,0,0,0,0,0,0,0,0,0,0,0,0
0,0,0,0,0,0,0,0,0,0,0,0,0,0,0,0,0,0,0,0,0,0,0,0,0
0,0,0,0,0,0,0,0,0,0,0,0,0,0,0,0,0,0,0,0,0,0,0,0,0
endlayer

layer
0,0,0,0,0,0,0,0,0,0,0,0,0,0,0,0,0,0,0,0,0,0,0,0,0
0,0,0,0,0,0,0,0,0,0,0,0,0,0,0,0,0,0,0,0,0,0,0,0,0
0,0,0,0,0,0,0,0,0,0,0,0,0,0,0,0,0,0,0,0,0,0,0,0,0
0,0,0,0,0,0,0,0,0,0,0,0,0,0,0,0,0,0,0,0,0,0,0,0,0
0,0,0,0,0,0,0,0,0,0,0,0,0,0,0,0,0,0,0,0,0,0,0,0,0
0,0,0,0,0,0,0,0,0,0,0,0,0,0,0,0,0,0,0,0,0,0,0,0,0
0,0,0,0,0,0,0,0,0,0,0,0,0,0,0,0,0,0,0,0,0,0,0,0,0
0,0,0,0,0,0,0,0,0,0,0,0,0,0,0,0,0,0,0,0,0,0,0,0,0
0,0,0,0,0,0,0,0,0,0,0,0,0,0,0,0,0,0,0,0,0,0,0,0,0
0,0,0,0,0,0,0,0,0,0,0,0,0,0,0,0,0,0,0,0,0,0,0,0,0
0,0,0,0,0,0,0,0,0,0,0,0,13,7,13,0,0,0,0,0,0,0,0,0,0
0,0,0,0,0,0,0,0,0,0,0,0,7,66,7,0,0,0,0,0,0,0,0,0,0
0,0,0,0,0,0,0,0,0,0,0,0,13,7,13,0,0,0,0,0,0,0,0,0,0
0,0,0,0,0,0,0,0,0,0,0,0,0,0,0,0,0,0,0,0,0,0,0,0,0
0,0,0,0,0,0,0,0,0,0,0,0,0,0,0,0,0,0,0,0,0,0,0,0,0
0,0,0,0,0,0,0,0,0,0,0,0,0,0,0,0,0,0,0,0,0,0,0,0,0
0,0,0,0,0,0,0,0,0,0,0,0,0,0,0,0,0,0,0,0,0,0,0,0,0
0,0,0,0,0,0,0,0,0,0,0,0,0,0,0,0,0,0,0,0,0,0,0,0,0
0,0,0,0,0,0,0,0,0,0,0,0,0,0,0,0,0,0,0,0,0,0,0,0,0
0,0,0,0,0,0,0,0,0,0,0,0,0,0,0,0,0,0,0,0,0,0,0,0,0
0,0,0,0,0,0,0,0,0,0,0,0,0,0,0,0,0,0,0,0,0,0,0,0,0
0,0,0,0,0,0,0,0,0,0,0,0,0,0,0,0,0,0,0,0,0,0,0,0,0
0,0,0,0,0,0,0,0,0,0,0,0,0,0,0,0,0,0,0,0,0,0,0,0,0
0,0,0,0,0,0,0,0,0,0,0,0,0,0,0,0,0,0,0,0,0,0,0,0,0
0,0,0,0,0,0,0,0,0,0,0,0,0,0,0,0,0,0,0,0,0,0,0,0,0
endlayer

layer
0,0,0,0,0,0,0,0,0,0,0,0,0,0,0,0,0,0,0,0,0,0,0,0,0
0,0,0,0,0,0,0,0,0,0,0,0,0,0,0,0,0,0,0,0,0,0,0,0,0
0,0,0,0,0,0,0,0,0,0,0,0,0,0,0,0,0,0,0,0,0,0,0,0,0
0,0,0,0,0,0,0,0,0,0,0,0,0,0,0,0,0,0,0,0,0,0,0,0,0
0,0,0,0,0,0,0,0,0,0,0,0,0,0,0,0,0,0,0,0,0,0,0,0,0
0,0,0,0,0,0,0,0,0,0,0,0,0,0,0,0,0,0,0,0,0,0,0,0,0
0,0,0,0,0,0,0,0,0,0,0,0,0,0,0,0,0,0,0,0,0,0,0,0,0
0,0,0,0,0,0,0,0,0,0,0,0,0,0,0,0,0,0,0,0,0,0,0,0,0
0,0,0,0,0,0,0,0,0,0,0,0,0,0,0,0,0,0,0,0,0,0,0,0,0
0,0,0,0,0,0,0,0,0,0,0,0,0,0,0,0,0,0,0,0,0,0,0,0,0
0,0,0,0,0,0,0,0,0,0,0,0,0,0,0,0,0,0,0,0,0,0,0,0,0
0,0,0,0,0,0,0,0,0,0,0,0,0,13,0,0,0,0,0,0,0,0,0,0,0
0,0,0,0,0,0,0,0,0,0,0,0,0,0,0,0,0,0,0,0,0,0,0,0,0
0,0,0,0,0,0,0,0,0,0,0,0,0,0,0,0,0,0,0,0,0,0,0,0,0
0,0,0,0,0,0,0,0,0,0,0,0,0,0,0,0,0,0,0,0,0,0,0,0,0
0,0,0,0,0,0,0,0,0,0,0,0,0,0,0,0,0,0,0,0,0,0,0,0,0
0,0,0,0,0,0,0,0,0,0,0,0,0,0,0,0,0,0,0,0,0,0,0,0,0
0,0,0,0,0,0,0,0,0,0,0,0,0,0,0,0,0,0,0,0,0,0,0,0,0
0,0,0,0,0,0,0,0,0,0,0,0,0,0,0,0,0,0,0,0,0,0,0,0,0
0,0,0,0,0,0,0,0,0,0,0,0,0,0,0,0,0,0,0,0,0,0,0,0,0
0,0,0,0,0,0,0,0,0,0,0,0,0,0,0,0,0,0,0,0,0,0,0,0,0
0,0,0,0,0,0,0,0,0,0,0,0,0,0,0,0,0,0,0,0,0,0,0,0,0
0,0,0,0,0,0,0,0,0,0,0,0,0,0,0,0,0,0,0,0,0,0,0,0,0
0,0,0,0,0,0,0,0,0,0,0,0,0,0,0,0,0,0,0,0,0,0,0,0,0
0,0,0,0,0,0,0,0,0,0,0,0,0,0,0,0,0,0,0,0,0,0,0,0,0
endlayer

