
# Created by Ruins mod version 15.3 Ingame Parser
# authoring Player: Mensrea

weight=3
embed_into_distance=6
acceptable_target_blocks=
unacceptable_target_blocks=flowing_water,water,flowing_lava,lava
dimensions=68,15,16
allowable_overhang=0
max_leveling=2
leveling_buffer=0
preserve_water=0
preserve_lava=0
preventRotation=1

rule1=0,100,IW:concrete-0
rule2=0,100,minecraft:gravel-0
rule3=0,100,PFAAGeologica:strongStoneBrick-1
rule4=0,100,IW:concretetile-0
rule5=0,100,IW:metalladder-3
rule6=0,100,IC2:blockDoorAlloy-2
rule7=0,100,minecraft:lever-2
rule8=0,100,IC2:blockDoorAlloy-8
rule9=0,100,IW:metalbutton-1
rule10=0,100,IW:glassblack-0
rule11=0,100,IW:steelsiding-0
rule12=0,100,minecraft:wool-7
rule13=0,100,minecraft:jungle_stairs-3
rule14=0,100,minecraft:fence-0
rule15=0,100,minecraft:jungle_stairs-2
rule16=0,100,IW:computer1-0
rule17=0,100,IW:metalladder-2
rule18=0,100,minecraft:bed-0
rule19=0,100,minecraft:bed-8
rule20=0,100,minecraft:jungle_stairs-0
rule21=0,100,minecraft:wooden_pressure_plate-0
rule22=0,100,minecraft:stained_glass-15
rule23=0,100,ImmersiveEngineering:metalDecoration-13
rule24=0,100,MobSpawner:demonmobs.trite
rule25=0,100,minecraft:planks-0
rule26=0,100,ChestGenHook:strongholdCorridor:5-2
rule27=0,100,ChestGenHook:strongholdCorridor:5-3
rule28=0,100,minecraft:wooden_slab-0
rule29=0,100,ChestGenHook:strongholdCorridor:5-2
rule30=0,100,ChestGenHook:strongholdCorridor:5-3
rule31=0,100,ChestGenHook:strongholdCorridor:5-2
rule32=0,100,PFAAGeologica:strongStone-1
rule33=0,100,MobSpawner:demonmobs.pinky
rule34=0,100,IW:steelblock-0
rule35=0,100,MobSpawner:demonmobs.cacodemon
rule36=0,100,MobSpawner:demonmobs.nethersoul
rule37=0,100,minecraft:wool-0
rule38=0,100,minecraft:wool-8
rule39=0,100,IW:computer2-0
rule40=0,100,minecraft:wool-15
rule41=0,100,ChestGenHook:strongholdCorridor:5-2
rule42=0,100,ChestGenHook:strongholdCorridor:5-3
rule43=0,100,IW:machinery2-0
rule44=0,100,IC2:blockGenerator-3
rule45=0,100,IW:metalhatch-0
rule46=0,100,IW:tower1-0
rule47=0,100,IW:tower2-0
rule48=0,100,IW:tower3-0

layer
1,1,1,1,1,1,1,1,1,1,1,1,1,1,1,1
1,1,1,1,1,1,1,1,1,1,1,1,1,1,1,1
1,1,1,1,1,1,1,1,1,1,1,1,1,1,1,1
1,1,1,1,1,1,1,1,1,1,1,1,1,1,1,1
1,1,1,1,1,1,1,1,1,1,1,1,1,1,1,1
1,1,1,1,1,1,1,1,1,1,1,1,1,1,1,1
1,1,1,1,1,1,1,1,1,1,1,1,1,1,1,1
1,1,1,1,1,1,1,1,1,1,1,1,1,1,1,1
1,1,1,1,1,1,1,1,1,1,1,1,1,1,1,1
1,1,1,1,1,1,1,1,1,1,1,1,1,1,1,1
1,1,1,1,1,1,1,1,1,1,1,1,1,1,1,1
1,1,1,1,1,1,1,1,1,1,1,1,1,1,1,1
1,1,1,1,1,1,1,1,1,1,1,1,1,1,1,1
1,1,1,1,1,1,1,1,1,1,1,1,1,1,1,1
1,1,1,1,1,1,1,1,1,1,1,1,1,1,1,1
endlayer

layer
1,1,1,1,1,1,1,1,1,1,1,1,1,1,1,1
1,1,1,1,1,1,1,1,1,1,1,1,1,1,1,1
1,1,1,1,1,1,1,1,1,1,1,1,1,1,1,1
1,1,1,1,1,1,1,1,1,1,1,1,1,1,1,1
1,1,1,1,1,1,1,1,1,1,1,1,1,1,1,1
1,1,1,1,1,1,1,1,1,1,1,1,1,1,1,1
1,1,1,1,1,1,1,1,1,1,1,1,1,1,1,1
1,1,1,1,1,1,1,1,1,1,1,1,1,1,1,1
1,1,1,1,1,1,1,1,1,1,1,1,1,1,1,1
1,1,1,1,1,1,1,1,1,1,1,1,1,1,1,1
1,1,1,1,1,1,1,1,1,1,1,1,1,1,1,1
1,1,1,1,1,1,1,1,1,1,1,1,1,1,1,1
1,1,1,1,1,1,1,1,1,1,1,1,1,1,1,1
1,1,1,1,1,1,1,1,1,1,1,1,1,1,1,1
1,1,1,1,1,1,1,1,1,1,1,1,1,1,1,1
endlayer

layer
1,1,1,1,1,1,1,1,1,1,1,1,1,1,1,1
1,1,1,1,1,1,1,1,1,1,1,1,1,1,1,1
1,1,1,1,1,1,1,1,1,1,1,1,1,1,1,1
1,1,1,1,1,1,1,1,1,1,1,1,1,1,1,1
1,1,1,1,1,1,1,1,1,1,1,1,1,1,1,1
1,1,1,1,1,1,1,1,1,1,1,1,1,1,1,1
1,1,1,1,1,1,1,1,1,1,1,1,1,1,1,1
1,1,1,1,1,1,1,1,1,1,1,1,1,1,1,1
1,1,1,1,1,1,1,1,1,1,1,1,1,1,1,1
1,1,1,1,1,1,1,1,1,1,1,1,1,1,1,1
1,1,1,1,1,1,1,1,1,1,1,1,1,1,1,1
1,1,1,1,1,1,1,1,1,1,1,1,1,1,1,1
1,1,1,1,1,1,1,1,1,1,1,1,1,1,1,1
1,1,1,1,1,1,1,1,1,1,1,1,1,1,1,1
1,1,1,1,1,1,1,1,1,1,1,1,1,1,1,1
endlayer

layer
1,1,1,1,1,1,1,1,1,1,1,1,1,1,1,1
1,1,1,1,1,1,1,1,1,1,1,1,1,1,1,1
1,1,1,1,1,1,1,1,1,1,1,1,1,1,1,1
1,1,1,1,1,1,1,1,1,1,1,1,1,1,1,1
1,1,1,1,1,1,1,1,1,1,1,1,1,1,1,1
1,1,1,1,1,1,1,1,1,1,1,1,1,1,1,1
1,1,1,1,1,1,1,1,1,1,1,1,1,1,1,1
1,1,1,1,1,1,1,1,1,1,1,1,1,1,1,1
1,1,1,1,1,1,1,1,1,1,1,1,1,1,1,1
1,1,1,1,1,1,1,1,1,1,1,1,1,1,1,1
1,1,1,1,1,1,1,1,1,1,1,1,1,1,1,1
1,1,1,1,1,1,1,1,1,1,1,1,1,1,1,1
1,1,1,1,1,1,1,1,1,1,1,1,1,1,1,1
1,1,1,1,1,1,1,1,1,1,1,1,1,1,1,1
1,1,1,1,1,1,1,1,1,1,1,1,1,1,1,1
endlayer

layer
1,1,1,1,1,1,1,1,1,1,1,1,1,1,1,1
1,1,1,1,1,1,1,1,1,1,1,1,1,1,1,1
1,1,1,1,1,1,1,1,1,1,1,1,1,1,1,1
1,1,1,1,1,1,1,1,1,1,1,1,1,1,1,1
1,1,1,1,1,1,1,1,1,1,1,1,1,1,1,1
1,1,1,1,1,1,1,0,1,1,1,1,1,1,1,1
1,1,1,1,1,1,0,0,0,1,1,1,1,1,1,1
1,1,1,1,1,1,1,0,1,1,1,1,1,1,1,1
1,1,1,1,1,1,1,1,1,1,1,1,1,1,1,1
1,1,1,1,1,1,1,1,1,1,1,1,1,1,1,1
1,1,1,1,1,1,1,1,1,1,1,1,1,1,1,1
1,1,1,1,1,1,1,1,1,1,1,1,1,1,1,1
1,1,1,1,1,1,1,1,1,1,1,1,1,1,1,1
1,1,1,1,1,1,1,1,1,1,1,1,1,1,1,1
1,1,1,1,1,1,1,1,1,1,1,1,1,1,1,1
endlayer

layer
1,1,1,1,1,1,1,1,1,1,1,1,1,1,1,1
1,1,1,1,1,1,1,1,1,1,1,1,1,1,1,1
1,1,1,1,1,1,1,1,1,1,1,1,1,1,1,1
1,1,1,1,1,1,1,0,1,1,1,1,1,1,1,1
1,1,1,1,1,1,1,0,0,1,1,1,1,1,1,1
1,1,1,1,1,1,0,0,0,0,1,1,1,1,1,1
1,1,1,1,1,0,0,0,0,1,1,1,1,1,1,1
1,1,1,1,1,1,0,0,0,1,1,1,1,1,1,1
1,1,1,1,1,1,1,0,1,1,1,1,1,1,1,1
1,1,1,1,1,1,1,1,1,1,1,1,1,1,1,1
1,1,1,1,1,1,1,1,1,1,1,1,1,1,1,1
1,1,1,1,1,1,1,1,1,1,1,1,1,1,1,1
1,1,1,1,1,1,1,1,1,1,1,1,1,1,1,1
1,1,1,1,1,1,1,2,2,1,1,1,1,1,1,1
1,1,1,1,1,1,1,2,2,1,1,1,1,1,1,1
endlayer

layer
0,0,3,3,0,0,0,0,0,0,0,0,3,3,0,0
0,0,0,0,0,0,0,0,0,0,0,0,0,0,0,0
3,0,3,3,0,0,0,0,0,0,0,0,3,3,0,3
3,0,3,4,4,4,4,4,4,4,0,4,4,3,0,3
0,0,0,4,0,0,0,0,0,0,0,0,4,0,0,0
0,0,0,4,0,0,0,0,0,0,0,0,4,0,0,0
0,0,0,4,0,0,0,0,0,0,0,0,4,0,0,0
0,0,0,4,0,4,0,0,0,5,4,0,4,0,0,0
0,0,0,4,0,0,0,0,0,4,0,0,4,0,0,0
0,0,0,4,0,0,0,4,0,0,0,0,4,0,0,0
0,0,0,4,0,0,0,0,0,0,0,0,4,0,0,0
3,0,3,4,4,4,4,6,0,4,4,4,4,3,0,3
3,0,3,3,0,0,0,0,0,0,0,0,3,3,0,3
0,0,0,0,0,0,0,0,0,0,0,0,0,0,0,0
0,0,3,3,0,0,0,0,0,0,0,0,3,3,0,0
endlayer

layer
0,0,3,3,0,0,0,0,0,0,0,0,3,3,0,0
0,0,0,0,0,0,0,0,0,0,0,0,0,0,0,0
3,0,3,3,0,0,0,0,0,0,0,0,3,3,0,3
3,0,3,4,4,4,4,4,0,0,0,4,4,3,0,3
0,0,0,4,0,0,0,0,0,0,0,0,4,0,0,0
0,0,0,4,0,0,0,0,0,0,0,0,4,0,0,0
0,0,0,4,0,0,0,0,0,0,0,0,4,0,0,0
0,0,0,4,0,4,0,0,0,5,4,0,4,0,0,0
0,0,0,4,0,0,0,0,0,0,0,0,4,0,0,0
0,0,0,4,0,0,0,0,0,0,0,0,4,0,0,0
0,0,0,4,0,0,7,0,0,0,0,0,4,0,0,0
3,0,3,4,4,4,4,8,0,0,4,4,4,3,0,3
3,0,3,3,0,0,9,0,0,0,0,0,3,3,0,3
0,0,0,0,0,0,0,0,0,0,0,0,0,0,0,0
0,0,3,3,0,0,0,0,0,0,0,0,3,3,0,0
endlayer

layer
0,0,3,3,0,0,0,0,0,0,0,0,3,3,0,0
0,0,0,0,0,0,0,0,0,0,0,0,0,0,0,0
3,0,3,3,0,0,0,0,0,0,0,0,3,3,0,3
3,0,3,4,4,4,4,0,0,0,4,4,4,3,0,3
0,0,0,4,0,0,0,0,0,0,0,0,4,0,0,0
0,0,0,4,0,0,0,0,0,0,0,0,4,0,0,0
0,0,0,4,0,0,0,0,0,0,0,0,4,0,0,0
0,0,0,4,0,4,0,0,0,5,4,0,4,0,0,0
0,0,0,4,0,0,0,0,0,10,0,0,4,0,0,0
0,0,0,4,0,0,0,0,0,0,0,0,4,0,0,0
0,0,0,4,0,0,0,0,0,0,0,0,4,0,0,0
3,0,3,4,4,4,4,11,0,4,4,4,4,3,0,3
3,0,3,3,0,0,0,0,0,0,0,0,3,3,0,3
0,0,0,0,0,0,0,0,0,0,0,0,0,0,0,0
0,0,3,3,0,0,0,0,0,0,0,0,3,3,0,0
endlayer

layer
0,0,3,3,0,0,0,0,0,0,0,0,3,3,0,0
0,0,0,0,0,0,0,0,0,0,0,0,0,0,0,0
3,0,3,3,0,0,0,0,0,0,0,0,3,3,0,3
3,0,3,4,4,4,4,4,0,4,4,4,4,3,0,3
0,0,0,4,0,0,0,0,0,0,0,0,4,0,0,0
0,0,0,4,0,0,0,0,0,0,0,0,4,0,0,0
0,0,0,4,0,0,0,0,0,0,0,0,4,0,0,0
0,0,0,4,0,4,0,0,0,5,4,0,4,0,0,0
0,0,0,4,0,0,0,0,0,0,0,0,4,0,0,0
0,0,0,4,0,0,0,0,0,0,0,0,4,0,0,0
0,0,0,4,0,0,0,0,0,0,0,0,4,0,0,0
3,0,3,4,4,4,1,1,1,1,4,4,4,3,0,3
3,0,3,3,0,0,0,0,0,0,0,0,3,3,0,3
0,0,0,0,0,0,0,0,0,0,0,0,0,0,0,0
0,0,3,3,0,0,0,0,0,0,0,0,3,3,0,0
endlayer

layer
0,0,3,3,0,0,0,0,0,0,0,0,3,3,0,0
0,0,0,0,0,0,0,0,0,0,0,0,0,0,0,0
3,0,3,3,0,0,0,0,0,0,0,0,3,3,0,3
3,0,3,4,4,4,1,1,0,1,4,4,4,3,0,3
0,0,0,4,1,0,1,1,1,1,1,1,4,0,0,0
0,0,0,4,0,0,0,1,1,1,1,1,4,0,0,0
0,0,0,4,1,0,1,1,1,1,1,1,4,0,0,0
0,0,0,4,1,4,1,1,1,5,4,1,4,0,0,0
0,0,0,4,1,1,1,1,1,1,1,1,4,0,0,0
0,0,0,4,1,1,1,1,1,1,1,1,4,0,0,0
0,0,0,4,1,1,1,1,1,1,1,1,4,0,0,0
3,0,3,4,4,4,1,1,1,1,4,4,4,3,0,3
3,0,3,3,0,0,0,0,0,0,0,0,3,3,0,3
0,0,0,0,0,0,0,0,0,0,0,0,0,0,0,0
0,0,3,3,0,0,0,0,0,0,0,0,3,3,0,0
endlayer

layer
0,0,3,3,0,0,0,0,0,0,0,0,3,3,0,0
0,0,0,0,0,0,0,0,0,0,0,0,0,0,0,0
3,0,3,3,0,0,0,12,12,0,0,0,3,3,0,3
3,0,3,4,4,4,4,10,10,4,4,4,4,3,0,3
0,0,0,4,0,0,0,0,0,0,0,11,4,0,0,0
0,0,0,4,0,0,0,0,15,14,13,11,4,0,0,0
0,0,0,4,0,0,0,0,0,0,0,0,4,0,0,0
0,0,0,4,0,4,17,0,0,0,4,16,4,0,0,0
0,0,0,4,19,18,11,0,0,0,0,0,4,0,0,0
0,0,0,4,0,0,0,0,0,14,13,11,4,0,0,0
0,0,0,4,19,18,11,0,0,20,0,11,4,0,0,0
3,0,3,4,4,4,4,10,10,4,4,4,4,3,0,3
3,0,3,3,0,0,0,12,12,0,0,0,3,3,0,3
0,0,0,0,0,0,0,0,0,0,0,0,0,0,0,0
0,0,3,3,0,0,0,0,0,0,0,0,3,3,0,0
endlayer

layer
0,0,3,3,0,0,0,0,0,0,0,0,3,3,0,0
0,0,0,0,0,0,0,0,0,0,0,0,0,0,0,0
3,0,3,3,0,0,0,12,12,0,0,0,3,3,0,3
3,0,3,4,4,4,4,10,10,4,4,4,4,3,0,3
0,0,0,4,0,0,0,0,0,0,0,11,4,0,0,0
0,0,0,4,0,0,0,0,0,21,0,11,4,0,0,0
0,0,0,4,0,0,0,0,0,0,0,0,4,0,0,0
0,0,0,4,0,4,17,0,0,0,4,22,4,0,0,0
0,0,0,4,0,0,0,0,0,0,0,0,4,0,0,0
0,0,0,4,0,0,0,0,0,21,0,11,4,0,0,0
0,0,0,4,0,0,0,0,0,0,0,11,4,0,0,0
3,0,3,4,4,4,4,10,10,4,4,4,4,3,0,3
3,0,3,3,0,0,0,12,12,0,0,0,3,3,0,3
0,0,0,0,0,0,0,0,0,0,0,0,0,0,0,0
0,0,3,3,0,0,0,0,0,0,0,0,3,3,0,0
endlayer

layer
0,0,3,3,0,0,0,0,0,0,0,0,3,3,0,0
0,0,0,0,0,0,0,0,0,0,0,0,0,0,0,0
3,0,3,3,0,0,0,12,12,0,0,0,3,3,0,3
3,0,3,4,4,4,4,10,10,4,4,4,4,3,0,3
0,0,0,4,0,0,0,0,0,0,0,0,4,0,0,0
0,0,0,4,0,0,0,0,0,0,0,0,4,0,0,0
0,0,0,4,0,0,0,0,0,0,0,0,4,0,0,0
0,0,0,4,0,4,17,0,0,0,4,0,4,0,0,0
0,0,0,4,0,0,0,0,0,0,0,0,4,0,0,0
0,0,0,4,0,0,0,0,0,0,0,0,4,0,0,0
0,0,0,4,0,0,0,0,0,0,0,0,4,0,0,0
3,0,3,4,4,4,4,10,10,4,4,4,4,3,0,3
3,0,3,3,0,0,0,12,12,0,0,0,3,3,0,3
0,0,0,0,0,0,0,0,0,0,0,0,0,0,0,0
0,0,3,3,0,0,0,0,0,0,0,0,3,3,0,0
endlayer

layer
0,0,3,3,0,0,0,0,0,0,0,0,3,3,0,0
0,0,0,0,0,0,0,0,0,0,0,0,0,0,0,0
3,0,3,3,0,0,0,12,12,0,0,0,3,3,0,3
3,0,3,4,4,4,4,10,10,4,4,4,4,3,0,3
0,0,0,4,0,0,0,0,0,0,0,0,4,0,0,0
0,0,0,4,0,0,0,0,0,0,0,0,4,0,0,0
0,0,0,4,0,0,0,0,0,0,0,0,4,0,0,0
0,0,0,4,0,4,17,0,0,0,4,0,4,0,0,0
0,0,0,4,0,0,0,0,0,0,0,0,4,0,0,0
0,0,0,4,0,0,0,0,0,0,0,0,4,0,0,0
0,0,0,4,0,0,0,0,0,0,0,0,4,0,0,0
3,0,3,4,4,4,4,10,10,4,4,4,4,3,0,3
3,0,3,3,0,0,0,12,12,0,0,0,3,3,0,3
0,0,0,0,0,0,0,0,0,0,0,0,0,0,0,0
0,0,3,3,0,0,0,0,0,0,0,0,3,3,0,0
endlayer

layer
0,0,3,3,0,0,0,0,0,0,0,0,3,3,0,0
0,0,0,0,0,0,0,0,0,0,0,0,0,0,0,0
3,0,3,3,0,0,0,23,23,0,0,0,3,3,0,3
3,0,3,4,4,4,1,1,1,1,4,4,4,3,0,3
0,0,0,4,1,1,1,1,1,1,1,1,4,0,0,0
0,0,0,4,1,1,1,1,1,1,1,1,4,0,0,0
0,0,0,4,1,1,0,0,0,1,1,1,4,0,0,0
0,0,0,4,1,4,17,0,0,0,4,1,4,0,0,0
0,0,0,4,1,1,1,0,0,0,1,1,4,0,0,0
0,0,0,4,1,1,1,0,0,1,1,1,4,0,0,0
0,0,0,4,1,1,1,0,0,1,1,1,4,0,0,0
3,0,3,4,4,4,1,1,1,1,4,4,4,3,0,3
3,0,3,3,0,0,0,23,23,0,0,0,3,3,0,3
0,0,0,0,0,0,0,0,0,0,0,0,0,0,0,0
0,0,3,3,0,0,0,0,0,0,0,0,3,3,0,0
endlayer

layer
0,0,3,3,0,0,0,0,0,0,0,0,3,3,0,0
0,0,0,0,0,0,0,0,0,0,0,0,0,0,0,0
3,0,3,3,0,0,0,12,12,0,0,0,3,3,0,3
3,0,3,4,4,4,4,10,10,4,4,4,4,3,0,3
0,0,0,4,0,11,0,0,0,0,25,24,4,0,0,0
0,0,0,4,0,0,0,0,0,25,26,25,4,0,0,0
0,0,0,4,0,0,0,0,0,0,27,0,4,0,0,0
0,0,0,4,0,4,0,0,0,5,4,0,4,0,0,0
0,0,0,4,0,0,0,0,0,0,28,28,4,0,0,0
0,0,0,4,11,0,0,0,0,28,25,25,4,0,0,0
0,0,0,4,25,29,25,0,0,28,25,24,4,0,0,0
3,0,3,4,4,4,4,10,10,4,4,4,4,3,0,3
3,0,3,3,0,0,0,12,12,0,0,0,3,3,0,3
0,0,0,0,0,0,0,0,0,0,0,0,0,0,0,0
0,0,3,3,0,0,0,0,0,0,0,0,3,3,0,0
endlayer

layer
0,0,3,3,0,0,0,0,0,0,0,0,3,3,0,0
0,0,0,0,0,0,0,0,0,0,0,0,0,0,0,0
3,0,3,3,0,0,0,12,12,0,0,0,3,3,0,3
3,0,3,4,4,4,4,10,10,4,4,4,4,3,0,3
0,0,0,4,0,11,0,0,0,0,0,28,4,0,0,0
0,0,0,4,0,0,0,0,0,25,25,0,4,0,0,0
0,0,0,4,0,0,0,0,0,0,25,0,4,0,0,0
0,0,0,4,0,4,0,0,0,5,4,0,4,0,0,0
0,0,0,4,0,0,0,0,0,0,0,0,4,0,0,0
0,0,0,4,0,0,0,0,0,0,0,0,4,0,0,0
0,0,0,4,25,25,0,0,0,0,0,28,4,0,0,0
3,0,3,4,4,4,4,10,10,4,4,4,4,3,0,3
3,0,3,3,0,0,0,12,12,0,0,0,3,3,0,3
0,0,0,0,0,0,0,0,0,0,0,0,0,0,0,0
0,0,3,3,0,0,0,0,0,0,0,0,3,3,0,0
endlayer

layer
0,0,3,3,0,0,0,0,0,0,0,0,3,3,0,0
0,0,0,0,0,0,0,0,0,0,0,0,0,0,0,0
3,0,3,3,0,0,0,12,12,0,0,0,3,3,0,3
3,0,3,4,4,4,4,10,10,4,4,4,4,3,0,3
0,0,0,4,0,0,0,0,0,0,0,0,4,0,0,0
0,0,0,4,0,0,0,0,0,0,0,0,4,0,0,0
0,0,0,4,0,0,0,0,0,0,0,0,4,0,0,0
0,0,0,4,0,4,0,0,0,5,4,0,4,0,0,0
0,0,0,4,0,0,0,0,0,0,0,0,4,0,0,0
0,0,0,4,0,0,0,0,0,0,0,0,4,0,0,0
0,0,0,4,0,0,0,0,0,0,0,0,4,0,0,0
3,0,3,4,4,4,4,10,10,4,4,4,4,3,0,3
3,0,3,3,0,0,0,12,12,0,0,0,3,3,0,3
0,0,0,0,0,0,0,0,0,0,0,0,0,0,0,0
0,0,3,3,0,0,0,0,0,0,0,0,3,3,0,0
endlayer

layer
0,0,3,3,0,0,0,0,0,0,0,0,3,3,0,0
0,0,0,0,0,0,0,0,0,0,0,0,0,0,0,0
3,0,3,3,0,0,0,12,12,0,0,0,3,3,0,3
3,0,3,4,4,4,4,10,10,4,4,4,4,3,0,3
0,0,0,4,0,0,0,0,0,0,0,0,4,0,0,0
0,0,0,4,0,0,0,0,0,0,0,0,4,0,0,0
0,0,0,4,0,0,0,0,0,0,0,0,4,0,0,0
0,0,0,4,0,4,0,0,0,5,4,0,4,0,0,0
0,0,0,4,0,0,0,0,0,0,0,0,4,0,0,0
0,0,0,4,0,0,0,0,0,0,0,0,4,0,0,0
0,0,0,4,0,0,0,0,0,0,0,0,4,0,0,0
3,0,3,4,4,4,4,10,10,4,4,4,4,3,0,3
3,0,3,3,0,0,0,12,12,0,0,0,3,3,0,3
0,0,0,0,0,0,0,0,0,0,0,0,0,0,0,0
0,0,3,3,0,0,0,0,0,0,0,0,3,3,0,0
endlayer

layer
0,0,3,3,0,0,0,0,0,0,0,0,3,3,0,0
0,0,0,0,0,0,0,0,0,0,0,0,0,0,0,0
3,0,3,3,0,0,0,23,23,0,0,0,3,3,0,3
3,0,3,4,4,4,1,1,1,1,4,4,4,3,0,3
0,0,0,4,1,1,1,1,1,1,1,1,4,0,0,0
0,0,0,4,1,1,1,1,0,0,1,1,4,0,0,0
0,0,0,4,1,1,1,0,0,0,1,1,4,0,0,0
0,0,0,4,1,4,0,0,1,5,4,1,4,0,0,0
0,0,0,4,1,0,0,0,1,0,1,1,4,0,0,0
0,0,0,4,1,1,0,1,1,1,1,1,4,0,0,0
0,0,0,4,1,1,1,1,1,1,1,1,4,0,0,0
3,0,3,4,4,4,1,1,1,1,4,4,4,3,0,3
3,0,3,3,0,0,0,23,23,0,0,0,3,3,0,3
0,0,0,0,0,0,0,0,0,0,0,0,0,0,0,0
0,0,3,3,0,0,0,0,0,0,0,0,3,3,0,0
endlayer

layer
0,0,3,3,0,0,0,0,0,0,0,0,3,3,0,0
0,0,0,0,0,0,0,0,0,0,0,0,0,0,0,0
3,0,3,3,0,0,0,12,12,0,0,0,3,3,0,3
3,0,3,4,4,4,4,10,10,4,4,4,4,3,0,3
0,0,0,4,0,0,0,0,0,0,0,25,4,0,0,0
0,0,0,4,0,25,25,0,0,0,0,0,4,0,0,0
0,0,0,4,0,0,0,0,0,0,0,0,4,0,0,0
0,0,0,4,0,4,17,0,0,0,4,0,4,0,0,0
0,0,0,4,0,0,0,0,0,0,0,0,4,0,0,0
0,0,0,4,0,0,0,25,25,0,25,25,4,0,0,0
0,0,0,4,16,0,0,0,0,0,31,30,4,0,0,0
3,0,3,4,4,4,4,10,10,4,4,4,4,3,0,3
3,0,3,3,0,0,0,12,12,0,0,0,3,3,0,3
0,0,0,0,0,0,0,0,0,0,0,0,0,0,0,0
0,0,3,3,0,0,0,0,0,0,0,0,3,3,0,0
endlayer

layer
0,0,3,3,0,0,0,0,0,0,0,0,3,3,0,0
0,0,0,0,0,0,0,0,0,0,0,0,0,0,0,0
3,0,3,3,0,0,0,12,12,0,0,0,3,3,0,3
3,0,3,4,4,4,4,10,10,4,4,4,4,3,0,3
0,0,0,4,0,0,0,0,0,0,0,0,4,0,0,0
0,0,0,4,0,25,25,0,0,0,0,0,4,0,0,0
0,0,0,4,0,0,0,0,0,0,0,0,4,0,0,0
0,0,0,4,0,4,17,0,0,0,4,0,4,0,0,0
0,0,0,4,0,0,0,0,0,0,0,0,4,0,0,0
0,0,0,4,0,0,0,0,0,0,25,25,4,0,0,0
0,0,0,4,22,0,0,0,0,0,25,25,4,0,0,0
3,0,3,4,4,4,4,10,10,4,4,4,4,3,0,3
3,0,3,3,0,0,0,12,12,0,0,0,3,3,0,3
0,0,0,0,0,0,0,0,0,0,0,0,0,0,0,0
0,0,3,3,0,0,0,0,0,0,0,0,3,3,0,0
endlayer

layer
0,0,3,3,0,0,0,0,0,0,0,0,3,3,0,0
0,0,0,0,0,0,0,0,0,0,0,0,0,0,0,0
3,0,3,3,0,0,0,12,12,0,0,0,3,3,0,3
3,0,3,4,4,4,4,10,10,4,4,4,4,3,0,3
0,0,0,4,0,0,0,0,0,0,0,0,4,0,0,0
0,0,0,4,0,0,0,0,0,0,0,0,4,0,0,0
0,0,0,4,0,0,0,0,0,0,0,0,4,0,0,0
0,0,0,4,0,4,17,0,0,0,4,0,4,0,0,0
0,0,0,4,0,0,0,0,0,0,0,0,4,0,0,0
0,0,0,4,0,0,0,0,0,0,0,0,4,0,0,0
0,0,0,4,0,0,0,0,0,0,0,0,4,0,0,0
3,0,3,4,4,4,4,10,10,4,4,4,4,3,0,3
3,0,3,3,0,0,0,12,12,0,0,0,3,3,0,3
0,0,0,0,0,0,0,0,0,0,0,0,0,0,0,0
0,0,3,3,0,0,0,0,0,0,0,0,3,3,0,0
endlayer

layer
0,0,3,3,0,0,0,0,0,0,0,0,3,3,0,0
0,0,0,0,0,0,0,0,0,0,0,0,0,0,0,0
3,0,3,3,0,0,0,12,12,0,0,0,3,3,0,3
3,0,3,4,4,4,4,10,10,4,4,4,4,3,0,3
0,0,0,4,0,0,0,0,0,0,0,0,4,0,0,0
0,0,0,4,0,0,0,0,0,0,0,0,4,0,0,0
0,0,0,4,0,0,0,0,0,0,0,0,4,0,0,0
0,0,0,4,0,4,17,0,0,0,4,0,4,0,0,0
0,0,0,4,0,0,0,0,0,0,0,0,4,0,0,0
0,0,0,4,0,0,0,0,0,0,0,0,4,0,0,0
0,0,0,4,0,0,0,0,0,0,0,0,4,0,0,0
3,0,3,4,4,4,4,10,10,4,4,4,4,3,0,3
3,0,3,3,0,0,0,12,12,0,0,0,3,3,0,3
0,0,0,0,0,0,0,0,0,0,0,0,0,0,0,0
0,0,3,3,0,0,0,0,0,0,0,0,3,3,0,0
endlayer

layer
0,0,3,3,0,0,0,0,0,0,0,0,3,3,0,0
0,0,0,0,0,0,0,0,0,0,0,0,0,0,0,0
3,0,3,3,0,0,0,23,23,0,0,0,3,3,0,3
3,0,3,4,4,4,4,4,4,4,4,4,4,3,0,3
0,0,0,4,1,1,1,0,1,1,1,1,4,0,0,0
0,0,0,4,1,0,0,0,0,1,0,1,4,0,0,0
0,0,0,4,1,1,0,0,0,0,1,1,4,0,0,0
0,0,0,4,1,4,17,0,1,1,4,1,4,0,0,0
0,0,0,4,1,1,1,1,1,1,1,1,4,0,0,0
0,0,0,4,1,1,1,1,1,1,1,0,4,0,0,0
0,0,0,4,1,1,1,1,1,1,1,1,4,0,0,0
3,0,3,4,4,4,1,1,1,1,4,4,4,3,0,3
3,0,3,3,0,0,0,23,23,0,0,0,3,3,0,3
0,0,0,0,0,0,0,0,0,0,0,0,0,0,0,0
0,0,3,3,0,0,0,0,0,0,0,0,3,3,0,0
endlayer

layer
0,0,32,32,0,0,0,0,0,0,0,0,32,32,0,0
0,0,0,0,0,0,0,0,0,0,0,0,0,0,0,0
32,0,3,3,0,0,0,12,12,0,0,0,3,3,0,32
32,0,3,4,4,4,4,10,10,4,4,4,4,3,0,32
0,0,0,4,0,0,0,0,0,0,0,0,4,0,0,0
0,0,0,4,0,0,0,0,0,0,0,0,4,0,0,0
0,0,0,4,0,0,0,0,0,0,0,0,4,0,0,0
0,0,0,4,0,4,0,0,0,5,4,0,4,0,0,0
0,0,0,4,0,0,0,0,25,0,0,0,4,0,0,0
0,0,0,4,0,0,0,25,33,25,0,0,4,0,0,0
0,0,0,4,0,0,0,0,25,0,0,0,4,0,0,0
32,0,3,4,4,4,4,10,10,4,4,4,4,3,0,32
32,0,3,3,0,0,0,12,12,0,0,0,3,3,0,32
0,0,0,0,0,0,0,0,0,0,0,0,0,0,0,0
0,0,32,32,0,0,0,0,0,0,0,0,32,32,0,0
endlayer

layer
0,0,32,32,0,0,0,0,0,0,0,0,32,32,0,0
0,0,32,32,0,0,0,0,0,0,0,0,32,32,0,0
32,32,3,3,0,0,0,12,12,0,0,0,3,3,32,32
32,32,3,4,4,4,4,10,10,4,4,4,4,3,32,32
0,0,0,4,0,0,0,0,0,0,0,0,4,0,0,0
0,0,0,4,0,0,0,0,0,0,0,0,4,0,0,0
0,0,0,4,0,0,0,0,0,0,0,0,4,0,0,0
0,0,0,4,0,4,0,0,0,5,4,0,4,0,0,0
0,0,0,4,0,0,0,0,0,0,0,0,4,0,0,0
0,0,0,4,0,0,0,0,28,0,0,0,4,0,0,0
0,0,0,4,0,0,0,0,0,0,0,0,4,0,0,0
32,32,3,4,4,4,4,10,10,4,4,4,4,3,32,32
32,32,3,3,0,0,0,12,12,0,0,0,3,3,32,32
0,0,32,32,0,0,0,0,0,0,0,0,32,32,0,0
0,0,32,32,0,0,0,0,0,0,0,0,32,32,0,0
endlayer

layer
0,0,0,0,0,0,0,0,0,0,0,0,0,0,0,0
0,0,32,32,0,0,0,0,0,0,0,0,32,32,0,0
0,32,32,32,0,0,0,12,12,0,0,0,32,32,32,0
0,32,32,4,4,4,4,10,10,4,4,4,4,32,32,0
0,0,0,4,0,0,0,0,0,0,0,0,4,0,0,0
0,0,0,4,0,0,0,0,0,0,0,0,4,0,0,0
0,0,0,4,0,0,0,0,0,0,0,0,4,0,0,0
0,0,0,4,0,4,0,0,0,5,4,0,4,0,0,0
0,0,0,4,0,0,0,0,0,0,0,0,4,0,0,0
0,0,0,4,0,0,0,0,0,0,0,0,4,0,0,0
0,0,0,4,0,0,0,0,0,0,0,0,4,0,0,0
0,32,32,4,4,4,4,10,10,4,4,4,4,32,32,0
0,32,32,32,0,0,0,12,12,0,0,0,32,32,32,0
0,0,32,32,0,0,0,0,0,0,0,0,32,32,0,0
0,0,0,0,0,0,0,0,0,0,0,0,0,0,0,0
endlayer

layer
0,0,0,0,0,0,0,0,0,0,0,0,0,0,0,0
0,0,0,0,0,0,0,0,0,0,0,0,0,0,0,0
0,0,3,32,32,0,0,12,12,0,0,32,32,3,0,0
0,0,32,4,4,4,4,10,10,4,4,4,4,32,0,0
0,0,32,4,0,0,0,0,0,0,0,0,4,32,0,0
0,0,0,4,0,0,0,0,0,0,0,0,4,0,0,0
0,0,0,4,0,0,0,0,0,0,0,0,4,0,0,0
0,0,0,4,0,4,0,0,0,5,4,0,4,0,0,0
0,0,0,4,0,0,0,0,0,0,0,0,4,0,0,0
0,0,0,4,0,0,0,0,0,0,0,0,4,0,0,0
0,0,32,4,0,0,0,0,0,0,0,0,4,32,0,0
0,0,32,4,4,4,4,10,10,4,4,4,4,32,0,0
0,0,3,32,32,0,0,12,12,0,0,32,32,3,0,0
0,0,0,0,0,0,0,0,0,0,0,0,0,0,0,0
0,0,0,0,0,0,0,0,0,0,0,0,0,0,0,0
endlayer

layer
0,0,0,0,0,0,0,0,0,0,0,0,0,0,0,0
0,0,0,0,0,0,0,0,0,0,0,0,0,0,0,0
0,0,3,3,32,32,0,23,23,0,32,32,3,3,0,0
0,0,3,4,4,4,1,1,1,1,4,4,4,3,0,0
0,0,32,4,1,1,1,1,1,1,1,1,4,32,0,0
0,0,32,4,1,1,1,1,1,1,1,1,4,32,0,0
0,0,0,4,1,1,1,1,1,1,1,1,4,0,0,0
0,0,0,4,1,1,1,1,1,5,1,1,4,0,0,0
0,0,0,4,1,1,1,1,1,1,1,1,4,0,0,0
0,0,32,4,1,1,1,1,1,1,1,1,4,32,0,0
0,0,32,4,1,1,1,1,1,1,1,1,4,32,0,0
0,0,3,4,4,4,1,1,1,1,4,4,4,3,0,0
0,0,3,3,32,32,0,23,23,0,32,32,3,3,0,0
0,0,0,0,0,0,0,0,0,0,0,0,0,0,0,0
0,0,0,0,0,0,0,0,0,0,0,0,0,0,0,0
endlayer

layer
0,0,0,0,0,0,0,0,0,0,0,0,0,0,0,0
0,0,0,0,0,0,0,0,0,0,0,0,0,0,0,0
0,0,34,34,0,32,32,32,32,32,32,0,3,3,0,0
0,0,34,34,0,0,0,0,4,4,4,4,4,3,0,0
0,0,0,0,0,0,0,0,4,0,0,0,4,0,0,0
0,0,32,28,25,28,0,0,4,0,0,5,4,32,0,0
0,0,32,25,35,25,0,0,0,0,0,0,4,32,0,0
0,0,32,28,25,28,0,0,0,0,0,0,4,32,0,0
0,0,32,0,0,0,0,0,0,0,25,0,4,32,0,0
0,0,32,0,0,0,0,0,4,25,36,25,4,32,0,0
0,0,0,0,0,0,0,0,4,0,25,0,4,0,0,0
0,0,34,34,0,0,0,0,4,4,4,4,4,3,0,0
0,0,34,34,0,32,32,32,32,32,32,0,3,3,0,0
0,0,0,0,0,0,0,0,0,0,0,0,0,0,0,0
0,0,0,0,0,0,0,0,0,0,0,0,0,0,0,0
endlayer

layer
0,0,0,0,0,0,0,0,0,0,0,0,0,0,0,0
0,0,0,0,0,0,0,0,0,0,0,0,0,0,0,0
0,0,0,0,0,0,32,32,32,32,0,0,3,3,0,0
0,0,0,0,0,0,0,0,4,4,4,4,4,3,0,0
0,0,0,0,0,0,0,0,4,0,0,0,4,0,0,0
0,0,0,0,0,0,0,0,4,0,0,5,4,0,0,0
0,0,32,0,28,0,0,0,0,0,0,0,4,32,0,0
0,0,32,0,0,0,0,0,0,0,0,0,4,32,0,0
0,0,32,0,0,0,0,0,0,0,0,0,4,32,0,0
0,0,0,0,0,0,0,0,4,0,28,0,4,0,0,0
0,0,0,0,0,0,0,0,4,0,0,0,4,0,0,0
0,0,0,0,0,0,0,0,4,4,4,4,4,3,0,0
0,0,0,0,0,0,32,32,32,32,0,0,3,3,0,0
0,0,0,0,0,0,0,0,0,0,0,0,0,0,0,0
0,0,0,0,0,0,0,0,0,0,0,0,0,0,0,0
endlayer

layer
0,0,0,0,0,0,0,0,0,0,0,0,0,0,0,0
0,0,0,0,0,0,0,0,0,0,0,0,0,0,0,0
0,0,0,0,0,0,0,0,0,0,0,0,3,3,0,0
0,0,0,0,0,0,0,0,4,4,4,4,4,3,0,0
0,0,0,0,0,0,0,0,4,0,0,0,4,0,0,0
0,0,0,0,0,0,37,0,4,0,0,5,4,0,0,0
0,0,0,0,0,0,37,0,1,0,0,0,4,0,0,0
0,0,0,0,0,0,37,0,1,0,0,0,4,0,0,0
0,0,0,0,0,0,37,0,1,0,0,0,4,0,0,0
0,0,0,0,0,0,37,0,4,0,0,0,4,0,0,0
0,0,0,0,0,0,0,0,4,0,0,0,4,0,0,0
0,0,0,0,0,0,0,0,4,4,4,4,4,3,0,0
0,0,0,0,0,0,0,0,0,0,0,0,3,3,0,0
0,0,0,0,0,0,0,0,0,0,0,0,0,0,0,0
0,0,0,0,0,0,0,0,0,0,0,0,0,0,0,0
endlayer

layer
0,0,0,0,0,0,0,0,0,0,0,0,0,0,0,0
0,0,0,0,0,0,0,0,0,0,0,0,0,0,0,0
0,0,0,0,0,0,0,0,0,0,0,0,3,3,0,0
0,0,0,0,0,0,0,0,4,4,4,4,4,3,0,0
0,0,0,0,0,0,37,0,4,0,0,0,4,0,0,0
0,0,0,0,0,0,37,0,4,0,0,5,4,0,0,0
0,0,0,0,0,0,37,0,4,0,0,0,4,0,0,0
0,0,0,0,0,0,38,0,4,0,0,0,4,0,0,0
0,0,0,0,0,0,37,0,4,0,0,0,4,0,0,0
0,0,0,0,0,0,37,0,4,0,0,0,4,0,0,0
0,0,0,0,0,0,37,0,4,0,0,0,4,0,0,0
0,0,0,0,0,0,0,0,4,4,4,4,4,3,0,0
0,0,0,0,0,0,0,0,0,0,0,0,3,3,0,0
0,0,0,0,0,0,0,0,0,0,0,0,0,0,0,0
0,0,0,0,0,0,0,0,0,0,0,0,0,0,0,0
endlayer

layer
0,0,0,0,0,0,0,0,0,0,0,0,0,0,0,0
0,0,0,0,0,0,0,0,0,0,0,0,0,0,0,0
0,0,0,0,0,0,0,0,0,0,0,0,3,3,0,0
0,0,0,0,0,0,37,0,4,4,4,4,4,3,0,0
0,0,0,0,0,0,37,0,4,11,11,11,4,0,0,0
0,0,0,0,0,0,37,0,4,11,11,5,4,0,0,0
0,0,0,0,0,0,38,0,4,11,11,11,4,0,0,0
0,0,0,0,0,0,12,0,1,1,1,1,1,0,0,0
0,0,0,0,0,0,38,0,4,1,1,1,4,0,0,0
0,0,0,0,0,0,37,0,4,1,1,1,4,0,0,0
0,0,0,0,0,0,37,0,4,1,1,1,4,0,0,0
0,0,0,0,0,0,37,0,4,4,4,4,4,3,0,0
0,0,0,0,0,0,0,0,0,0,0,0,3,3,0,0
0,0,0,0,0,0,0,0,0,0,0,0,0,0,0,0
0,0,0,0,0,0,0,0,0,0,0,0,0,0,0,0
endlayer

layer
0,0,0,0,0,0,0,0,0,0,0,0,0,0,0,0
0,0,0,0,0,0,0,0,0,0,0,0,0,0,0,0
0,0,0,0,0,0,0,0,0,0,0,0,3,3,0,0
0,0,0,0,0,0,37,0,4,4,4,4,4,3,0,0
0,0,0,0,0,0,37,0,4,0,0,0,4,0,0,0
0,0,0,0,0,0,38,0,4,0,0,5,4,0,0,0
0,0,0,0,0,0,12,0,4,0,0,0,4,0,0,0
0,0,0,0,0,0,40,0,4,39,0,39,4,0,0,0
0,0,0,0,0,0,12,0,4,34,0,34,4,0,0,0
0,0,0,0,0,0,38,0,4,41,0,26,4,0,0,0
0,0,0,0,0,0,37,0,4,42,0,27,4,0,0,0
0,0,0,0,0,0,37,0,4,4,4,4,4,3,0,0
0,0,0,0,0,0,0,0,0,0,0,0,3,3,0,0
0,0,0,0,0,0,0,0,0,0,0,0,0,0,0,0
0,0,0,0,0,0,0,0,0,0,0,0,0,0,0,0
endlayer

layer
0,0,0,0,0,0,0,0,0,0,0,0,0,0,0,0
0,0,0,0,0,0,0,0,0,0,0,0,0,0,0,0
0,0,0,0,0,0,0,0,0,0,0,0,3,3,0,0
0,0,0,0,0,0,37,0,4,4,4,4,4,3,0,0
0,0,0,0,0,0,38,0,4,0,0,0,4,0,0,0
0,0,0,0,0,0,12,0,4,0,0,5,4,0,0,0
0,0,0,0,0,0,40,0,4,0,0,0,4,0,0,0
0,0,0,0,0,0,40,0,4,22,0,22,4,0,0,0
0,0,0,0,0,0,40,0,4,0,0,0,4,0,0,0
0,0,0,0,0,0,12,0,4,0,0,0,4,0,0,0
0,0,0,0,0,0,38,0,4,0,0,0,4,0,0,0
0,0,0,0,0,0,37,0,4,4,4,4,4,3,0,0
0,0,0,0,0,0,0,0,0,0,0,0,3,3,0,0
0,0,0,0,0,0,0,0,0,0,0,0,0,0,0,0
0,0,0,0,0,0,0,0,0,0,0,0,0,0,0,0
endlayer

layer
0,0,0,0,0,0,0,0,0,0,0,0,0,0,0,0
0,0,0,0,0,0,0,0,0,0,0,0,0,0,0,0
0,0,0,0,0,0,0,0,0,0,0,0,3,3,0,0
0,0,0,0,0,0,38,0,4,4,4,4,4,32,0,0
0,0,0,0,0,0,12,0,4,0,0,0,4,0,0,0
0,0,0,0,0,0,40,0,4,0,0,5,4,0,0,0
0,0,0,0,0,0,37,0,4,0,0,0,4,0,0,0
0,0,0,0,0,0,40,0,4,0,0,0,4,0,0,0
0,0,0,0,0,0,37,0,4,0,0,0,4,0,0,0
0,0,0,0,0,0,40,0,4,0,0,0,4,0,0,0
0,0,0,0,0,0,12,0,4,0,0,0,4,0,0,0
0,0,0,0,0,0,38,0,4,4,4,4,4,32,0,0
0,0,0,0,0,0,0,0,0,0,0,0,3,3,0,0
0,0,0,0,0,0,0,0,0,0,0,0,0,0,0,0
0,0,0,0,0,0,0,0,0,0,0,0,0,0,0,0
endlayer

layer
0,0,0,0,0,0,0,0,0,0,0,0,0,0,0,0
0,0,0,0,0,0,0,0,0,0,0,0,0,0,0,0
0,0,0,0,0,0,0,0,0,0,0,0,3,3,0,0
0,0,0,0,0,0,37,0,4,4,4,4,4,32,0,0
0,0,0,0,0,0,37,0,4,0,0,0,4,32,0,0
0,0,0,0,0,0,37,0,4,0,0,5,4,0,0,0
0,0,0,0,0,0,37,0,4,0,0,0,4,0,0,0
0,0,0,0,0,0,37,0,4,0,0,0,4,0,0,0
0,0,0,0,0,0,37,0,4,0,0,0,4,0,0,0
0,0,0,0,0,0,37,0,4,0,0,0,4,0,0,0
0,0,0,0,0,0,37,0,4,0,0,0,4,32,0,0
0,0,0,0,0,0,37,0,4,4,4,4,4,32,0,0
0,0,0,0,0,0,0,0,0,0,0,0,3,3,0,0
0,0,0,0,0,0,0,0,0,0,0,0,0,0,0,0
0,0,0,0,0,0,0,0,0,0,0,0,0,0,0,0
endlayer

layer
0,0,0,0,0,0,0,0,0,0,0,0,0,0,0,0
0,0,0,0,0,0,0,0,0,0,0,0,0,0,0,0
0,0,0,0,0,0,0,0,0,0,0,0,3,3,0,0
0,0,0,0,0,0,23,0,4,4,4,4,4,3,0,0
0,0,0,0,0,0,23,23,4,0,0,0,4,32,0,0
0,0,0,0,0,0,23,0,4,0,0,5,4,32,0,0
0,0,0,0,0,0,23,0,4,0,0,0,4,0,0,0
0,0,0,0,0,0,23,0,4,1,1,1,4,0,0,0
0,0,0,0,0,0,23,0,4,1,1,1,4,0,0,0
0,0,0,0,0,0,23,0,4,1,1,1,4,32,0,0
0,0,0,0,0,0,23,23,4,1,1,1,4,32,0,0
0,0,0,0,0,0,23,0,4,4,4,4,4,3,0,0
0,0,0,0,0,0,0,0,0,0,0,0,3,3,0,0
0,0,0,0,0,0,0,0,0,0,0,0,0,0,0,0
0,0,0,0,0,0,0,0,0,0,0,0,0,0,0,0
endlayer

layer
0,0,0,0,0,0,0,0,0,0,0,0,0,0,0,0
0,0,0,0,0,0,0,0,0,0,0,0,0,0,0,0
0,0,0,0,0,0,0,0,0,0,0,0,34,34,0,0
0,0,0,0,0,0,0,0,34,4,4,4,34,34,0,0
0,0,0,0,0,0,0,0,4,0,0,0,4,0,0,0
0,0,0,0,0,0,0,0,4,0,0,5,4,32,0,0
0,0,0,0,0,0,0,0,4,0,0,0,4,32,0,0
0,0,0,0,0,0,0,0,34,4,4,4,34,32,0,0
0,0,0,0,0,0,0,0,0,25,25,25,0,32,0,0
0,0,0,0,0,0,0,0,0,25,36,25,0,32,0,0
0,0,0,0,0,0,0,0,0,28,25,28,0,0,0,0
0,0,0,0,0,0,0,0,23,0,0,0,34,34,0,0
0,0,0,0,0,0,0,0,0,0,0,0,34,34,0,0
0,0,0,0,0,0,0,0,0,0,0,0,0,0,0,0
0,0,0,0,0,0,0,0,0,0,0,0,0,0,0,0
endlayer

layer
0,0,0,0,0,0,0,0,0,0,0,0,0,0,0,0
0,0,0,0,0,0,0,0,0,0,0,0,0,0,0,0
0,0,0,0,0,0,0,0,0,0,0,0,0,0,0,0
0,0,0,0,0,0,0,0,34,4,4,4,34,0,0,0
0,0,0,0,0,0,0,0,4,0,0,0,4,0,0,0
0,0,0,0,0,0,0,0,4,0,0,5,4,0,0,0
0,0,0,0,0,0,0,0,4,0,0,0,4,32,0,0
0,0,0,0,0,0,0,0,34,4,4,4,34,32,0,0
0,0,0,0,0,0,0,0,0,0,0,0,0,32,0,0
0,0,0,0,0,0,0,0,0,0,28,0,0,0,0,0
0,0,0,0,0,0,0,0,0,0,0,0,0,0,0,0
0,0,0,0,0,0,0,0,23,0,0,0,23,0,0,0
0,0,0,0,0,0,0,0,0,0,0,0,0,0,0,0
0,0,0,0,0,0,0,0,0,0,0,0,0,0,0,0
0,0,0,0,0,0,0,0,0,0,0,0,0,0,0,0
endlayer

layer
0,0,0,0,0,0,0,0,0,0,0,0,0,0,0,0
0,0,0,0,0,0,0,0,0,0,0,0,0,0,0,0
0,0,0,0,0,0,0,0,0,0,0,0,0,0,0,0
0,0,0,0,0,0,0,0,34,4,4,4,34,0,0,0
0,0,0,0,0,0,0,0,4,0,0,0,4,0,0,0
0,0,0,0,0,0,0,0,4,0,0,5,4,0,0,0
0,0,0,0,0,0,0,0,4,0,0,0,4,0,0,0
0,0,0,0,0,0,0,0,34,4,4,4,34,0,0,0
0,0,0,0,0,0,0,0,0,0,0,0,0,0,0,0
0,0,0,0,0,0,0,0,0,0,0,0,0,0,0,0
0,0,0,0,0,0,0,0,0,0,0,0,0,0,0,0
0,0,0,0,0,0,0,0,23,0,0,0,23,0,0,0
0,0,0,0,0,0,0,0,0,0,0,0,0,0,0,0
0,0,0,0,0,0,0,0,0,0,0,0,0,0,0,0
0,0,0,0,0,0,0,0,0,0,0,0,0,0,0,0
endlayer

layer
0,0,0,0,0,0,0,0,0,0,0,0,0,0,0,0
0,0,0,0,0,0,0,0,0,0,0,0,0,0,0,0
0,0,0,0,0,0,0,0,0,0,0,0,0,0,0,0
0,0,0,0,0,0,0,0,34,4,4,4,34,0,0,0
0,0,0,0,0,0,0,0,4,0,0,0,4,0,0,0
0,0,0,0,0,0,0,0,4,0,0,5,4,0,0,0
0,0,0,0,0,0,0,0,4,0,0,0,4,0,0,0
0,0,0,0,0,0,0,0,34,4,4,4,34,0,0,0
0,0,0,0,0,0,0,0,0,0,0,0,0,0,0,0
0,0,0,0,0,0,0,0,0,0,0,0,0,0,0,0
0,0,0,0,0,0,0,0,0,0,0,0,0,0,0,0
0,0,0,0,0,0,0,0,23,0,0,0,23,0,0,0
0,0,0,0,0,0,0,0,0,0,0,0,0,0,0,0
0,0,0,0,0,0,0,0,0,0,0,0,0,0,0,0
0,0,0,0,0,0,0,0,0,0,0,0,0,0,0,0
endlayer

layer
0,0,0,0,0,0,0,0,0,0,0,0,0,0,0,0
0,0,0,0,0,0,0,0,0,0,0,0,0,0,0,0
0,0,0,0,0,0,0,0,0,0,0,0,0,0,0,0
0,0,0,0,0,0,0,0,34,4,4,4,34,0,0,0
0,0,0,0,0,0,0,0,4,0,0,0,4,0,0,0
0,0,0,0,0,0,0,0,4,0,0,5,4,0,0,0
0,0,0,0,0,0,0,0,4,0,0,0,4,0,0,0
0,0,0,0,0,0,0,0,34,4,4,4,34,0,0,0
0,0,0,0,0,0,0,0,0,0,0,0,0,0,0,0
0,0,0,0,0,0,0,0,0,0,0,0,0,0,0,0
0,0,0,0,0,0,0,0,0,0,0,0,0,0,0,0
0,0,0,0,0,0,0,0,23,0,0,0,23,0,0,0
0,0,0,0,0,0,0,0,0,0,0,0,0,0,0,0
0,0,0,0,0,0,0,0,0,0,0,0,0,0,0,0
0,0,0,0,0,0,0,0,0,0,0,0,0,0,0,0
endlayer

layer
0,0,0,0,0,0,0,0,0,0,0,0,0,0,0,0
0,0,0,0,0,0,0,0,0,0,0,0,0,0,0,0
0,0,0,0,0,0,0,0,0,0,0,0,0,0,0,0
0,0,0,0,0,0,0,0,34,4,4,4,34,0,0,0
0,0,0,0,0,0,0,0,4,0,0,0,4,0,0,0
0,0,0,0,0,0,0,0,4,0,0,5,4,0,0,0
0,0,0,0,0,0,0,0,4,0,0,0,4,0,0,0
0,0,0,0,0,0,0,0,34,4,4,4,34,0,0,0
0,0,0,0,0,0,0,0,0,0,0,0,0,0,0,0
0,0,0,0,0,0,0,0,0,0,0,0,0,0,0,0
0,0,0,0,0,0,0,0,0,0,0,0,0,0,0,0
0,0,0,0,0,0,0,0,23,0,0,0,23,0,0,0
0,0,0,0,0,0,0,0,0,0,0,0,0,0,0,0
0,0,0,0,0,0,0,0,0,0,0,0,0,0,0,0
0,0,0,0,0,0,0,0,0,0,0,0,0,0,0,0
endlayer

layer
0,0,0,0,0,0,0,0,0,0,0,0,0,0,0,0
0,0,0,0,0,0,0,0,0,0,0,0,0,0,0,0
0,0,0,0,0,0,0,0,0,0,0,0,0,0,0,0
0,0,0,0,0,0,0,0,34,4,4,4,34,0,0,0
0,0,0,0,0,0,0,0,4,0,0,0,4,0,0,0
0,0,0,0,0,0,0,0,4,0,0,5,4,0,0,0
0,0,0,0,0,0,0,0,4,0,0,0,4,0,0,0
0,0,0,0,0,0,0,0,34,4,4,4,34,0,0,0
0,0,0,0,0,0,0,0,0,0,0,0,0,0,0,0
0,0,0,0,0,0,0,0,0,0,0,0,0,0,0,0
0,0,0,0,0,0,0,0,0,0,0,0,0,0,0,0
0,0,0,0,0,0,0,0,23,0,0,0,23,0,0,0
0,0,0,0,0,0,0,0,0,0,0,0,0,0,0,0
0,0,0,0,0,0,0,0,0,0,0,0,0,0,0,0
0,0,0,0,0,0,0,0,0,0,0,0,0,0,0,0
endlayer

layer
0,0,0,0,0,0,0,0,0,0,0,0,0,0,0,0
0,0,0,0,0,0,0,0,0,0,0,0,0,0,0,0
0,0,0,0,0,0,0,0,0,0,0,0,0,0,0,0
0,0,0,0,0,0,0,0,34,4,4,4,34,0,0,0
0,0,0,0,0,0,0,0,4,0,0,0,4,0,0,0
0,0,0,0,0,0,0,0,4,0,0,5,4,0,0,0
0,0,0,0,0,0,0,0,4,0,0,0,4,0,0,0
0,0,0,0,0,0,0,0,34,4,4,4,34,0,0,0
0,0,0,0,0,0,0,0,0,0,0,0,0,0,0,0
0,0,0,0,0,0,0,0,0,0,0,0,0,0,0,0
0,0,0,0,0,0,0,0,0,0,0,0,0,0,0,0
0,0,0,0,0,0,0,0,23,0,0,0,23,0,0,0
0,0,0,0,0,0,0,0,0,0,0,0,0,0,0,0
0,0,0,0,0,0,0,0,0,0,0,0,0,0,0,0
0,0,0,0,0,0,0,0,0,0,0,0,0,0,0,0
endlayer

layer
0,0,0,0,0,0,0,0,0,0,0,0,0,0,0,0
0,0,0,0,0,0,0,0,0,0,0,0,0,0,0,0
0,0,0,0,0,0,0,0,0,0,0,0,0,0,0,0
0,0,0,0,0,0,0,0,34,4,4,4,34,0,0,0
0,0,0,0,0,0,0,0,4,0,0,0,4,0,0,0
0,0,0,0,0,0,0,0,4,0,0,5,4,0,0,0
0,0,0,0,0,0,0,0,4,0,0,0,4,0,0,0
0,0,0,0,0,0,0,0,34,4,4,4,34,0,0,0
0,0,0,0,0,0,0,0,0,0,0,0,0,0,0,0
0,0,0,0,0,0,0,0,0,0,0,0,0,0,0,0
0,0,0,0,0,0,0,0,0,0,0,0,0,0,0,0
0,0,0,0,0,0,0,0,23,0,0,0,23,0,0,0
0,0,0,0,0,0,0,0,0,0,0,0,0,0,0,0
0,0,0,0,0,0,0,0,0,0,0,0,0,0,0,0
0,0,0,0,0,0,0,0,0,0,0,0,0,0,0,0
endlayer

layer
0,0,0,0,0,0,0,0,0,0,0,0,0,0,0,0
0,0,0,0,0,0,0,0,0,0,0,0,0,0,0,0
0,0,0,0,0,0,0,0,0,0,0,0,0,0,0,0
0,0,0,0,0,0,0,0,34,34,34,34,34,0,0,0
0,0,0,0,0,0,0,0,34,44,43,34,34,0,0,0
0,0,0,0,0,0,0,0,34,34,34,0,34,0,0,0
0,0,0,0,0,0,0,0,34,44,43,34,34,0,0,0
0,0,0,0,0,0,0,0,34,34,34,34,34,0,0,0
0,0,0,0,0,0,0,0,34,0,0,0,34,0,0,0
0,0,0,0,0,0,0,0,34,0,0,0,34,0,0,0
0,0,0,0,0,0,0,0,34,0,0,0,34,0,0,0
0,0,0,0,0,0,0,0,34,34,34,34,34,0,0,0
0,0,0,0,0,0,0,0,0,0,0,0,0,0,0,0
0,0,0,0,0,0,0,0,0,0,0,0,0,0,0,0
0,0,0,0,0,0,0,0,0,0,0,0,0,0,0,0
endlayer

layer
0,0,0,0,0,0,0,0,0,0,0,0,0,0,0,0
0,0,0,0,0,0,0,0,0,0,0,0,0,0,0,0
0,0,0,0,0,0,0,0,0,0,0,0,0,0,0,0
0,0,0,0,0,0,0,0,0,0,0,0,0,0,0,0
0,0,0,0,0,0,0,0,0,0,0,0,0,0,0,0
0,0,0,0,0,0,0,0,0,0,23,45,0,0,0,0
0,0,0,0,0,0,0,0,0,0,0,0,0,0,0,0
0,0,0,0,0,0,0,0,0,0,0,0,0,0,0,0
0,0,0,0,0,0,0,0,0,0,0,0,0,0,0,0
0,0,0,0,0,0,0,0,0,0,0,0,0,0,0,0
0,0,0,0,0,0,0,0,0,0,0,0,0,0,0,0
0,0,0,0,0,0,0,0,23,0,0,0,23,0,0,0
0,0,0,0,0,0,0,0,0,0,0,0,0,0,0,0
0,0,0,0,0,0,0,0,0,0,0,0,0,0,0,0
0,0,0,0,0,0,0,0,0,0,0,0,0,0,0,0
endlayer

layer
0,0,0,0,0,0,0,0,0,0,0,0,0,0,0,0
0,0,0,0,0,0,0,0,0,0,0,0,0,0,0,0
0,0,0,0,0,0,0,0,0,0,0,0,0,0,0,0
0,0,0,0,0,0,0,0,0,0,0,0,0,0,0,0
0,0,0,0,0,0,0,0,0,0,0,0,0,0,0,0
0,0,0,0,0,0,0,0,0,0,23,0,0,0,0,0
0,0,0,0,0,0,0,0,0,0,0,0,0,0,0,0
0,0,0,0,0,0,0,0,0,0,0,0,0,0,0,0
0,0,0,0,0,0,0,0,0,0,0,0,0,0,0,0
0,0,0,0,0,0,0,0,0,0,0,0,0,0,0,0
0,0,0,0,0,0,0,0,0,0,0,0,0,0,0,0
0,0,0,0,0,0,0,0,23,0,0,0,23,0,0,0
0,0,0,0,0,0,0,0,0,0,0,0,0,0,0,0
0,0,0,0,0,0,0,0,0,0,0,0,0,0,0,0
0,0,0,0,0,0,0,0,0,0,0,0,0,0,0,0
endlayer

layer
0,0,0,0,0,0,0,0,0,0,0,0,0,0,0,0
0,0,0,0,0,0,0,0,0,0,0,0,0,0,0,0
0,0,0,0,0,0,0,0,0,0,0,0,0,0,0,0
0,0,0,0,0,0,0,0,0,0,0,0,0,0,0,0
0,0,0,0,0,0,0,0,0,0,0,0,0,0,0,0
0,0,0,0,0,0,0,0,0,0,23,0,0,0,0,0
0,0,0,0,0,0,0,0,0,0,0,0,0,0,0,0
0,0,0,0,0,0,0,0,0,0,0,0,0,0,0,0
0,0,0,0,0,0,0,0,0,0,0,0,0,0,0,0
0,0,0,0,0,0,0,0,0,0,0,0,0,0,0,0
0,0,0,0,0,0,0,0,0,0,0,0,0,0,0,0
0,0,0,0,0,0,0,0,23,0,0,0,23,0,0,0
0,0,0,0,0,0,0,0,0,0,0,0,0,0,0,0
0,0,0,0,0,0,0,0,0,0,0,0,0,0,0,0
0,0,0,0,0,0,0,0,0,0,0,0,0,0,0,0
endlayer

layer
0,0,0,0,0,0,0,0,0,0,0,0,0,0,0,0
0,0,0,0,0,0,0,0,0,0,0,0,0,0,0,0
0,0,0,0,0,0,0,0,0,0,0,0,0,0,0,0
0,0,0,0,0,0,0,0,0,0,0,0,0,0,0,0
0,0,0,0,0,0,0,0,0,0,0,0,0,0,0,0
0,0,0,0,0,0,0,0,0,0,23,0,0,0,0,0
0,0,0,0,0,0,0,0,0,0,0,0,0,0,0,0
0,0,0,0,0,0,0,0,0,0,0,0,0,0,0,0
0,0,0,0,0,0,0,0,0,0,0,0,0,0,0,0
0,0,0,0,0,0,0,0,0,0,0,0,0,0,0,0
0,0,0,0,0,0,0,0,0,0,0,0,0,0,0,0
0,0,0,0,0,0,0,0,23,0,0,0,23,0,0,0
0,0,0,0,0,0,0,0,0,0,0,0,0,0,0,0
0,0,0,0,0,0,0,0,0,0,0,0,0,0,0,0
0,0,0,0,0,0,0,0,0,0,0,0,0,0,0,0
endlayer

layer
0,0,0,0,0,0,0,0,0,0,0,0,0,0,0,0
0,0,0,0,0,0,0,0,0,0,0,0,0,0,0,0
0,0,0,0,0,0,0,0,0,0,0,0,0,0,0,0
0,0,0,0,0,0,0,0,0,0,0,0,0,0,0,0
0,0,0,0,0,0,0,0,0,0,0,0,0,0,0,0
0,0,0,0,0,0,0,0,0,0,23,0,0,0,0,0
0,0,0,0,0,0,0,0,0,0,0,0,0,0,0,0
0,0,0,0,0,0,0,0,0,0,0,0,0,0,0,0
0,0,0,0,0,0,0,0,0,0,0,0,0,0,0,0
0,0,0,0,0,0,0,0,0,0,0,0,0,0,0,0
0,0,0,0,0,0,0,0,0,0,0,0,0,0,0,0
0,0,0,0,0,0,0,0,23,0,0,0,23,0,0,0
0,0,0,0,0,0,0,0,0,0,0,0,0,0,0,0
0,0,0,0,0,0,0,0,0,0,0,0,0,0,0,0
0,0,0,0,0,0,0,0,0,0,0,0,0,0,0,0
endlayer

layer
0,0,0,0,0,0,0,0,0,0,0,0,0,0,0,0
0,0,0,0,0,0,0,0,0,0,0,0,0,0,0,0
0,0,0,0,0,0,0,0,0,0,0,0,0,0,0,0
0,0,0,0,0,0,0,0,0,0,0,0,0,0,0,0
0,0,0,0,0,0,0,0,0,0,0,0,0,0,0,0
0,0,0,0,0,0,0,0,0,0,23,0,0,0,0,0
0,0,0,0,0,0,0,0,0,0,0,0,0,0,0,0
0,0,0,0,0,0,0,0,0,0,0,0,0,0,0,0
0,0,0,0,0,0,0,0,0,0,0,0,0,0,0,0
0,0,0,0,0,0,0,0,0,0,0,0,0,0,0,0
0,0,0,0,0,0,0,0,0,0,0,0,0,0,0,0
0,0,0,0,0,0,0,0,23,0,0,0,23,0,0,0
0,0,0,0,0,0,0,0,0,0,0,0,0,0,0,0
0,0,0,0,0,0,0,0,0,0,0,0,0,0,0,0
0,0,0,0,0,0,0,0,0,0,0,0,0,0,0,0
endlayer

layer
0,0,0,0,0,0,0,0,0,0,0,0,0,0,0,0
0,0,0,0,0,0,0,0,0,0,0,0,0,0,0,0
0,0,0,0,0,0,0,0,0,0,0,0,0,0,0,0
0,0,0,0,0,0,0,0,0,0,0,0,0,0,0,0
0,0,0,0,0,0,0,0,0,0,0,0,0,0,0,0
0,0,0,0,0,0,0,0,0,0,23,0,0,0,0,0
0,0,0,0,0,0,0,0,0,0,0,0,0,0,0,0
0,0,0,0,0,0,0,0,0,0,0,0,0,0,0,0
0,0,0,0,0,0,0,0,0,0,0,0,0,0,0,0
0,0,0,0,0,0,0,0,0,0,0,0,0,0,0,0
0,0,0,0,0,0,0,0,0,0,0,0,0,0,0,0
0,0,0,0,0,0,0,0,23,0,0,0,46,0,0,0
0,0,0,0,0,0,0,0,0,0,0,0,0,0,0,0
0,0,0,0,0,0,0,0,0,0,0,0,0,0,0,0
0,0,0,0,0,0,0,0,0,0,0,0,0,0,0,0
endlayer

layer
0,0,0,0,0,0,0,0,0,0,0,0,0,0,0,0
0,0,0,0,0,0,0,0,0,0,0,0,0,0,0,0
0,0,0,0,0,0,0,0,0,0,0,0,0,0,0,0
0,0,0,0,0,0,0,0,0,0,0,0,0,0,0,0
0,0,0,0,0,0,0,0,0,0,0,0,0,0,0,0
0,0,0,0,0,0,0,0,0,0,23,0,0,0,0,0
0,0,0,0,0,0,0,0,0,0,0,0,0,0,0,0
0,0,0,0,0,0,0,0,0,0,0,0,0,0,0,0
0,0,0,0,0,0,0,0,0,0,0,0,0,0,0,0
0,0,0,0,0,0,0,0,0,0,0,0,0,0,0,0
0,0,0,0,0,0,0,0,0,0,0,0,0,0,0,0
0,0,0,0,0,0,0,0,23,0,0,0,0,0,0,0
0,0,0,0,0,0,0,0,0,0,0,0,0,0,0,0
0,0,0,0,0,0,0,0,0,0,0,0,0,0,0,0
0,0,0,0,0,0,0,0,0,0,0,0,0,0,0,0
endlayer

layer
0,0,0,0,0,0,0,0,0,0,0,0,0,0,0,0
0,0,0,0,0,0,0,0,0,0,0,0,0,0,0,0
0,0,0,0,0,0,0,0,0,0,0,0,0,0,0,0
0,0,0,0,0,0,0,0,0,0,0,0,0,0,0,0
0,0,0,0,0,0,0,0,0,0,0,0,0,0,0,0
0,0,0,0,0,0,0,0,0,0,23,0,0,0,0,0
0,0,0,0,0,0,0,0,0,0,0,0,0,0,0,0
0,0,0,0,0,0,0,0,0,0,0,0,0,0,0,0
0,0,0,0,0,0,0,0,0,0,0,0,0,0,0,0
0,0,0,0,0,0,0,0,0,0,0,0,0,0,0,0
0,0,0,0,0,0,0,0,0,0,0,0,0,0,0,0
0,0,0,0,0,0,0,0,23,0,0,0,0,0,0,0
0,0,0,0,0,0,0,0,0,0,0,0,0,0,0,0
0,0,0,0,0,0,0,0,0,0,0,0,0,0,0,0
0,0,0,0,0,0,0,0,0,0,0,0,0,0,0,0
endlayer

layer
0,0,0,0,0,0,0,0,0,0,0,0,0,0,0,0
0,0,0,0,0,0,0,0,0,0,0,0,0,0,0,0
0,0,0,0,0,0,0,0,0,0,0,0,0,0,0,0
0,0,0,0,0,0,0,0,0,0,0,0,0,0,0,0
0,0,0,0,0,0,0,0,0,0,0,0,0,0,0,0
0,0,0,0,0,0,0,0,0,0,23,0,0,0,0,0
0,0,0,0,0,0,0,0,0,0,0,0,0,0,0,0
0,0,0,0,0,0,0,0,0,0,0,0,0,0,0,0
0,0,0,0,0,0,0,0,0,0,0,0,0,0,0,0
0,0,0,0,0,0,0,0,0,0,0,0,0,0,0,0
0,0,0,0,0,0,0,0,0,0,0,0,0,0,0,0
0,0,0,0,0,0,0,0,23,0,0,0,0,0,0,0
0,0,0,0,0,0,0,0,0,0,0,0,0,0,0,0
0,0,0,0,0,0,0,0,0,0,0,0,0,0,0,0
0,0,0,0,0,0,0,0,0,0,0,0,0,0,0,0
endlayer

layer
0,0,0,0,0,0,0,0,0,0,0,0,0,0,0,0
0,0,0,0,0,0,0,0,0,0,0,0,0,0,0,0
0,0,0,0,0,0,0,0,0,0,0,0,0,0,0,0
0,0,0,0,0,0,0,0,0,0,0,0,0,0,0,0
0,0,0,0,0,0,0,0,0,0,0,0,0,0,0,0
0,0,0,0,0,0,0,0,0,0,23,0,0,0,0,0
0,0,0,0,0,0,0,0,0,0,0,0,0,0,0,0
0,0,0,0,0,0,0,0,0,0,0,0,0,0,0,0
0,0,0,0,0,0,0,0,0,0,0,0,0,0,0,0
0,0,0,0,0,0,0,0,0,0,0,0,0,0,0,0
0,0,0,0,0,0,0,0,0,0,0,0,0,0,0,0
0,0,0,0,0,0,0,0,47,0,0,0,0,0,0,0
0,0,0,0,0,0,0,0,0,0,0,0,0,0,0,0
0,0,0,0,0,0,0,0,0,0,0,0,0,0,0,0
0,0,0,0,0,0,0,0,0,0,0,0,0,0,0,0
endlayer

layer
0,0,0,0,0,0,0,0,0,0,0,0,0,0,0,0
0,0,0,0,0,0,0,0,0,0,0,0,0,0,0,0
0,0,0,0,0,0,0,0,0,0,0,0,0,0,0,0
0,0,0,0,0,0,0,0,0,0,0,0,0,0,0,0
0,0,0,0,0,0,0,0,0,0,0,0,0,0,0,0
0,0,0,0,0,0,0,0,0,0,23,0,0,0,0,0
0,0,0,0,0,0,0,0,0,0,0,0,0,0,0,0
0,0,0,0,0,0,0,0,0,0,0,0,0,0,0,0
0,0,0,0,0,0,0,0,0,0,0,0,0,0,0,0
0,0,0,0,0,0,0,0,0,0,0,0,0,0,0,0
0,0,0,0,0,0,0,0,0,0,0,0,0,0,0,0
0,0,0,0,0,0,0,0,0,0,0,0,0,0,0,0
0,0,0,0,0,0,0,0,0,0,0,0,0,0,0,0
0,0,0,0,0,0,0,0,0,0,0,0,0,0,0,0
0,0,0,0,0,0,0,0,0,0,0,0,0,0,0,0
endlayer

layer
0,0,0,0,0,0,0,0,0,0,0,0,0,0,0,0
0,0,0,0,0,0,0,0,0,0,0,0,0,0,0,0
0,0,0,0,0,0,0,0,0,0,0,0,0,0,0,0
0,0,0,0,0,0,0,0,0,0,0,0,0,0,0,0
0,0,0,0,0,0,0,0,0,0,0,0,0,0,0,0
0,0,0,0,0,0,0,0,0,0,23,0,0,0,0,0
0,0,0,0,0,0,0,0,0,0,0,0,0,0,0,0
0,0,0,0,0,0,0,0,0,0,0,0,0,0,0,0
0,0,0,0,0,0,0,0,0,0,0,0,0,0,0,0
0,0,0,0,0,0,0,0,0,0,0,0,0,0,0,0
0,0,0,0,0,0,0,0,0,0,0,0,0,0,0,0
0,0,0,0,0,0,0,0,0,0,0,0,0,0,0,0
0,0,0,0,0,0,0,0,0,0,0,0,0,0,0,0
0,0,0,0,0,0,0,0,0,0,0,0,0,0,0,0
0,0,0,0,0,0,0,0,0,0,0,0,0,0,0,0
endlayer

layer
0,0,0,0,0,0,0,0,0,0,0,0,0,0,0,0
0,0,0,0,0,0,0,0,0,0,0,0,0,0,0,0
0,0,0,0,0,0,0,0,0,0,0,0,0,0,0,0
0,0,0,0,0,0,0,0,0,0,0,0,0,0,0,0
0,0,0,0,0,0,0,0,0,0,0,0,0,0,0,0
0,0,0,0,0,0,0,0,0,0,23,0,0,0,0,0
0,0,0,0,0,0,0,0,0,0,0,0,0,0,0,0
0,0,0,0,0,0,0,0,0,0,0,0,0,0,0,0
0,0,0,0,0,0,0,0,0,0,0,0,0,0,0,0
0,0,0,0,0,0,0,0,0,0,0,0,0,0,0,0
0,0,0,0,0,0,0,0,0,0,0,0,0,0,0,0
0,0,0,0,0,0,0,0,0,0,0,0,0,0,0,0
0,0,0,0,0,0,0,0,0,0,0,0,0,0,0,0
0,0,0,0,0,0,0,0,0,0,0,0,0,0,0,0
0,0,0,0,0,0,0,0,0,0,0,0,0,0,0,0
endlayer

layer
0,0,0,0,0,0,0,0,0,0,0,0,0,0,0,0
0,0,0,0,0,0,0,0,0,0,0,0,0,0,0,0
0,0,0,0,0,0,0,0,0,0,0,0,0,0,0,0
0,0,0,0,0,0,0,0,0,0,0,0,0,0,0,0
0,0,0,0,0,0,0,0,0,0,0,0,0,0,0,0
0,0,0,0,0,0,0,0,0,0,23,0,0,0,0,0
0,0,0,0,0,0,0,0,0,0,0,0,0,0,0,0
0,0,0,0,0,0,0,0,0,0,0,0,0,0,0,0
0,0,0,0,0,0,0,0,0,0,0,0,0,0,0,0
0,0,0,0,0,0,0,0,0,0,0,0,0,0,0,0
0,0,0,0,0,0,0,0,0,0,0,0,0,0,0,0
0,0,0,0,0,0,0,0,0,0,0,0,0,0,0,0
0,0,0,0,0,0,0,0,0,0,0,0,0,0,0,0
0,0,0,0,0,0,0,0,0,0,0,0,0,0,0,0
0,0,0,0,0,0,0,0,0,0,0,0,0,0,0,0
endlayer

layer
0,0,0,0,0,0,0,0,0,0,0,0,0,0,0,0
0,0,0,0,0,0,0,0,0,0,0,0,0,0,0,0
0,0,0,0,0,0,0,0,0,0,0,0,0,0,0,0
0,0,0,0,0,0,0,0,0,0,0,0,0,0,0,0
0,0,0,0,0,0,0,0,0,0,0,0,0,0,0,0
0,0,0,0,0,0,0,0,0,0,23,0,0,0,0,0
0,0,0,0,0,0,0,0,0,0,0,0,0,0,0,0
0,0,0,0,0,0,0,0,0,0,0,0,0,0,0,0
0,0,0,0,0,0,0,0,0,0,0,0,0,0,0,0
0,0,0,0,0,0,0,0,0,0,0,0,0,0,0,0
0,0,0,0,0,0,0,0,0,0,0,0,0,0,0,0
0,0,0,0,0,0,0,0,0,0,0,0,0,0,0,0
0,0,0,0,0,0,0,0,0,0,0,0,0,0,0,0
0,0,0,0,0,0,0,0,0,0,0,0,0,0,0,0
0,0,0,0,0,0,0,0,0,0,0,0,0,0,0,0
endlayer

layer
0,0,0,0,0,0,0,0,0,0,0,0,0,0,0,0
0,0,0,0,0,0,0,0,0,0,0,0,0,0,0,0
0,0,0,0,0,0,0,0,0,0,0,0,0,0,0,0
0,0,0,0,0,0,0,0,0,0,0,0,0,0,0,0
0,0,0,0,0,0,0,0,0,0,0,0,0,0,0,0
0,0,0,0,0,0,0,0,0,0,48,0,0,0,0,0
0,0,0,0,0,0,0,0,0,0,0,0,0,0,0,0
0,0,0,0,0,0,0,0,0,0,0,0,0,0,0,0
0,0,0,0,0,0,0,0,0,0,0,0,0,0,0,0
0,0,0,0,0,0,0,0,0,0,0,0,0,0,0,0
0,0,0,0,0,0,0,0,0,0,0,0,0,0,0,0
0,0,0,0,0,0,0,0,0,0,0,0,0,0,0,0
0,0,0,0,0,0,0,0,0,0,0,0,0,0,0,0
0,0,0,0,0,0,0,0,0,0,0,0,0,0,0,0
0,0,0,0,0,0,0,0,0,0,0,0,0,0,0,0
endlayer

