
# Created by Ruins mod version 15.3 Ingame Parser
# authoring Player: Mensrea

weight=2
embed_into_distance=9
acceptable_target_blocks=
unacceptable_target_blocks=flowing_water,water,flowing_lava,lava
dimensions=15,42,41
allowable_overhang=0
max_leveling=2
leveling_buffer=0
preserve_water=0
preserve_lava=0
preventRotation=1

rule1=0,100,PFAAGeologica:strongStone-7
rule2=0,100,IW:concrete-0
rule3=0,100,IW:steelsiding-0
rule4=0,100,minecraft:bed-9
rule5=0,100,MobSpawner:demonmobs.belph
rule6=0,100,ChestGenHook:strongholdCorridor:5-2
rule7=0,100,ChestGenHook:strongholdCorridor:5-2
rule8=0,100,minecraft:wooden_slab-0
rule9=0,100,minecraft:planks-0
rule10=0,100,IW:steelblock-0
rule11=0,100,minecraft:bed-1
rule12=0,100,minecraft:stone_pressure_plate-0
rule13=0,100,minecraft:tnt-0
rule14=0,100,IW:metaldoor-2
rule15=0,100,ChestGenHook:strongholdCorridor:5-2
rule16=0,100,IW:concretestairs-1
rule17=0,100,ChestGenHook:strongholdCorridor:5-2
rule18=0,100,MobSpawner:demonmobs.pinky
rule19=0,100,minecraft:bed-3
rule20=0,100,minecraft:bed-11
rule21=0,100,minecraft:oak_stairs-1
rule22=0,100,IC2:blockDoorAlloy-0
rule23=0,100,minecraft:oak_stairs-2
rule24=0,100,minecraft:oak_stairs-3
rule25=0,100,minecraft:oak_stairs-0
rule26=0,100,ChestGenHook:mineshaftCorridor:5-2
rule27=0,100,ChestGenHook:mineshaftCorridor:5-2
rule28=0,100,IW:concreteslab-0
rule29=0,100,IW:metaldoor-0
rule30=0,100,IW:metaldoor-7
rule31=0,100,minecraft:redstone_wire-0
rule32=0,100,minecraft:tripwire-0
rule33=0,100,MobSpawner:demonmobs.astaroth
rule34=0,100,IC2:blockDoorAlloy-1
rule35=0,100,ThermalExpansion:Workbench-1
rule36=0,100,ChestGenHook:strongholdCorridor:5-2
rule37=0,100,MobSpawner:demonmobs.trite
rule38=0,100,IW:metaldoor-8
rule39=0,100,IW:metalbutton-2
rule40=0,100,IC2:blockDoorAlloy-8
rule41=0,100,IC2:blockDoorAlloy-9
rule42=0,100,minecraft:stained_glass-15
rule43=0,100,minecraft:lever-1
rule44=0,100,IW:metalbutton-1
rule45=0,100,IW:metaldoor-9
rule46=0,100,IW:metalbutton-4
rule47=0,100,minecraft:lever-2
rule48=0,100,PFAAGeologica:mediumStone-3
rule49=0,100,IW:metalladder-5
rule50=0,100,PFAAGeologica:weakStone-1
rule51=0,100,minecraft:sand-1
rule52=0,100,minecraft:gravel-0
rule53=0,100,IW:bush-0

layer
1,1,1,1,1,1,1,1,1,1,1,1,1,1,1,1,1,1,1,1,1,1,1,1,1,1,1,1,1,1,1,1,1,1,1,1,1,1,1,1,1
1,1,1,1,1,1,1,1,1,1,1,1,1,1,1,1,1,1,1,1,1,1,1,1,1,1,1,1,1,1,1,1,1,1,1,1,1,1,1,1,1
1,1,1,1,1,1,1,1,1,1,1,1,1,1,1,1,1,1,1,1,1,1,1,1,1,1,1,1,1,1,1,1,1,1,1,1,1,1,1,1,1
1,1,1,1,1,1,1,1,1,1,1,1,1,1,1,1,1,1,1,1,1,1,1,1,1,1,1,1,1,1,1,1,1,1,1,1,1,1,1,1,1
1,1,1,1,1,1,1,1,1,1,1,1,1,1,1,1,1,1,1,1,1,1,1,1,1,1,1,1,1,1,1,1,1,1,1,1,1,1,1,1,1
1,1,1,1,1,1,1,1,1,1,1,1,1,1,1,1,1,1,1,1,1,1,1,1,1,1,1,1,1,1,1,1,1,1,1,1,1,1,1,1,1
1,1,1,1,1,1,1,1,1,1,1,1,1,1,1,1,1,1,1,1,1,1,1,1,1,1,1,1,1,1,1,1,1,1,1,1,1,1,1,1,1
1,1,1,1,1,1,1,1,1,1,1,1,1,1,1,1,1,1,1,1,1,1,1,1,1,1,1,1,1,1,1,1,1,1,1,1,1,1,1,1,1
1,1,1,1,1,1,1,1,1,1,1,1,1,1,1,1,1,1,1,1,1,1,1,1,1,1,1,1,1,1,1,1,1,1,1,1,1,1,1,1,1
1,1,1,1,1,1,1,1,1,1,1,1,1,1,1,1,1,1,1,1,1,1,1,1,1,1,1,1,1,1,1,1,1,1,1,1,1,1,1,1,1
1,1,1,1,1,1,1,1,1,1,1,1,1,1,1,1,1,1,1,1,1,1,1,1,1,1,1,1,1,1,1,1,1,1,1,1,1,1,1,1,1
1,1,1,1,1,1,1,1,1,1,1,1,1,1,1,1,1,1,1,1,1,1,1,1,1,1,1,1,1,1,1,1,1,1,1,1,1,1,1,1,1
1,1,1,1,1,1,1,1,1,1,1,1,1,1,1,1,1,1,1,1,1,1,1,1,1,1,1,1,1,1,1,1,1,1,1,1,1,1,1,1,1
1,1,1,1,1,1,1,1,1,1,1,1,1,1,1,1,1,1,1,1,1,1,1,1,1,1,1,1,1,1,1,1,1,1,1,1,1,1,1,1,1
1,1,1,1,1,1,1,1,1,1,1,1,1,1,1,1,1,1,1,1,1,1,1,1,1,1,1,1,1,1,1,1,1,1,1,1,1,1,1,1,1
1,1,1,1,1,1,1,1,1,1,1,1,1,1,1,1,1,1,1,1,1,1,1,1,1,1,1,1,1,1,1,1,1,1,1,1,1,1,1,1,1
1,1,1,1,1,1,1,1,1,1,1,1,1,1,1,1,1,1,1,1,1,1,1,1,1,1,1,1,1,1,1,1,1,1,1,1,1,1,1,1,1
1,1,1,1,1,1,1,1,1,1,1,1,1,1,1,1,1,1,1,1,1,1,1,1,1,1,1,1,1,1,1,1,1,1,1,1,1,1,1,1,1
1,1,1,1,1,1,1,1,1,1,1,1,1,1,1,1,1,1,1,1,1,1,1,1,1,1,1,1,1,1,1,1,1,1,1,1,1,1,1,1,1
1,1,1,1,1,1,1,1,1,1,1,1,1,1,1,1,1,1,1,1,1,1,1,1,1,1,1,1,1,1,1,1,1,1,1,1,1,1,1,1,1
1,1,1,1,1,1,1,1,1,1,1,1,1,1,1,1,1,1,1,1,1,1,1,1,1,1,1,1,1,1,1,1,1,1,1,1,1,1,1,1,1
1,1,1,1,1,1,1,1,1,1,1,1,1,1,1,1,1,1,1,1,1,1,1,1,1,1,1,1,1,1,1,1,1,1,1,1,1,1,1,1,1
1,1,1,1,1,1,1,1,1,1,1,1,1,1,1,1,1,1,1,1,1,1,1,1,1,1,1,1,1,1,1,1,1,1,1,1,1,1,1,1,1
1,1,1,1,1,1,1,1,1,1,1,1,1,1,1,1,1,1,1,1,1,1,1,1,1,1,1,1,1,1,1,1,1,1,1,1,1,1,1,1,1
1,1,1,1,1,1,1,1,1,1,1,1,1,1,1,1,1,1,1,1,1,1,1,1,1,1,1,1,1,1,1,1,1,1,1,1,1,1,1,1,1
1,1,1,1,1,1,1,1,1,1,1,1,1,1,1,1,1,1,1,1,1,1,1,1,1,1,1,1,1,1,1,1,1,1,1,1,1,1,1,1,1
1,1,1,1,1,1,1,1,1,1,1,1,1,1,1,1,1,1,1,1,1,1,1,1,1,1,1,1,1,1,1,1,1,1,1,1,1,1,1,1,1
1,1,1,1,1,1,1,1,1,1,1,1,1,1,1,1,1,1,1,1,1,1,1,1,1,1,1,1,1,1,1,1,1,1,1,1,1,1,1,1,1
1,1,1,1,1,1,1,1,1,1,1,1,1,1,1,1,1,1,1,1,1,1,1,1,1,1,1,1,1,1,1,1,1,1,1,1,1,1,1,1,1
1,1,1,1,1,1,1,1,1,1,1,1,1,1,1,1,1,1,1,1,1,1,1,1,1,1,1,1,1,1,1,1,1,1,1,1,1,1,1,1,1
1,1,1,1,1,1,1,1,1,1,1,1,1,1,1,1,1,1,1,1,1,1,1,1,1,1,1,1,1,1,1,1,1,1,1,1,1,1,1,1,1
1,1,1,1,1,1,1,1,1,1,1,1,1,1,1,1,1,1,1,1,1,1,1,1,1,1,1,1,1,1,1,1,1,1,1,1,1,1,1,1,1
1,1,1,1,1,1,1,1,1,1,1,1,1,1,1,1,1,1,1,1,1,1,1,1,1,1,1,1,1,1,1,1,1,1,1,1,1,1,1,1,1
1,1,1,1,1,1,1,1,1,1,1,1,1,1,1,1,1,1,1,1,1,1,1,1,1,1,1,1,1,1,1,1,1,1,1,1,1,1,1,1,1
1,1,1,1,1,1,1,1,1,1,1,1,1,1,1,1,1,1,1,1,1,1,1,1,1,1,1,1,1,1,1,1,1,1,1,1,1,1,1,1,1
1,1,1,1,1,1,1,1,1,1,1,1,1,1,1,1,1,1,1,1,1,1,1,1,1,1,1,1,1,1,1,1,1,1,1,1,1,1,1,1,1
1,1,1,1,1,1,1,1,1,1,1,1,1,1,1,1,1,1,1,1,1,1,1,1,1,1,1,1,1,1,1,1,1,1,1,1,1,1,1,1,1
1,1,1,1,1,1,1,1,1,1,1,1,1,1,1,1,1,1,1,1,1,1,1,1,1,1,1,1,1,1,1,1,1,1,1,1,1,1,1,1,1
1,1,1,1,1,1,1,1,1,1,1,1,1,1,1,1,1,1,1,1,1,1,1,1,1,1,1,1,1,1,1,1,1,1,1,1,1,1,1,1,1
1,1,1,1,1,1,1,1,1,1,1,1,1,1,1,1,1,1,1,1,1,1,1,1,1,1,1,1,1,1,1,1,1,1,1,1,1,1,1,1,1
1,1,1,1,1,1,1,1,1,1,1,1,1,1,1,1,1,1,1,1,1,1,1,1,1,1,1,1,1,1,1,1,1,1,1,1,1,1,1,1,1
1,1,1,1,1,1,1,1,1,1,1,1,1,1,1,1,1,1,1,1,1,1,1,1,1,1,1,1,1,1,1,1,1,1,1,1,1,1,1,1,1
endlayer

layer
1,1,1,1,1,1,1,1,1,1,1,1,1,1,1,1,1,1,1,1,1,1,1,1,1,1,1,1,1,1,1,1,1,1,1,1,1,1,1,1,1
1,1,1,1,1,1,1,1,1,1,1,1,1,1,1,1,1,1,1,1,1,1,1,1,1,1,1,1,1,1,1,1,1,1,1,1,1,1,1,1,1
1,1,1,1,1,1,1,1,1,1,1,1,1,1,1,1,1,1,1,1,1,1,1,1,1,1,1,1,1,1,1,1,1,1,1,1,1,1,1,1,1
1,1,1,1,1,1,1,1,1,1,1,1,1,1,1,1,1,1,1,1,1,1,1,1,1,1,1,1,1,1,1,1,1,1,1,1,1,1,1,1,1
1,1,1,1,2,2,2,2,2,2,2,2,2,2,2,2,2,2,2,2,2,2,2,2,2,2,2,2,2,1,1,1,1,1,1,1,1,1,1,1,1
1,1,1,0,2,2,2,2,2,2,2,2,2,2,2,2,2,2,2,2,2,2,2,2,2,2,2,2,2,1,1,1,1,1,1,1,1,1,1,1,1
1,1,1,1,2,2,2,2,2,2,2,2,2,2,2,2,2,2,2,2,2,2,2,2,2,2,2,2,2,1,1,1,1,1,1,1,1,1,1,1,1
1,1,1,1,2,2,2,2,2,2,2,2,2,2,2,2,2,2,2,2,2,2,2,2,2,2,2,2,2,1,1,1,1,1,1,1,1,1,1,1,1
1,1,1,1,2,2,2,2,2,2,2,2,2,2,2,2,2,2,2,2,2,2,2,2,2,2,2,2,2,1,1,1,1,1,1,1,1,1,1,1,1
1,1,1,1,2,2,2,2,2,2,2,2,2,2,2,2,2,2,2,2,2,2,2,2,2,2,2,2,2,1,1,1,1,1,1,1,1,1,1,1,1
1,1,1,1,2,2,2,2,2,2,2,2,2,2,2,2,2,2,2,2,2,2,2,2,2,2,2,2,2,1,1,1,1,1,1,1,1,1,1,1,1
1,1,1,1,2,2,2,2,2,2,2,2,2,2,2,2,2,2,2,2,2,2,2,2,2,2,2,2,2,1,1,1,1,1,1,1,1,1,1,1,1
1,1,1,1,2,2,2,2,2,2,2,2,2,2,2,2,2,2,2,2,2,2,2,2,2,2,2,2,2,1,1,1,1,1,1,1,1,1,1,1,1
1,1,1,1,2,2,2,2,2,2,2,2,2,2,2,2,2,2,2,2,2,2,2,2,2,2,2,2,2,1,1,1,1,1,1,1,1,1,1,1,1
1,1,1,1,2,2,2,2,2,2,2,2,2,2,2,2,2,2,2,2,2,2,2,2,2,2,2,2,2,1,1,1,1,1,1,1,1,1,1,1,1
1,1,1,1,2,2,2,2,2,2,2,2,2,2,2,2,2,2,2,2,2,2,2,2,2,2,2,2,2,1,1,1,1,1,1,1,1,1,1,1,1
1,1,1,1,2,2,2,2,2,2,2,2,2,2,2,2,2,2,2,2,2,2,2,2,2,2,2,2,2,1,1,1,1,1,1,1,1,1,1,1,1
1,1,1,1,2,2,2,2,2,2,2,2,2,2,2,2,2,2,2,2,2,2,2,2,2,2,2,2,2,1,1,1,1,1,1,1,1,1,1,1,1
1,1,1,1,2,2,2,2,2,2,2,2,2,2,2,2,2,2,2,2,2,2,2,2,2,2,2,2,2,1,1,1,1,1,1,1,1,1,1,1,1
1,1,1,1,2,2,2,2,2,2,2,2,2,2,2,2,2,2,2,2,2,2,2,2,2,2,2,2,2,1,1,1,1,1,1,1,1,1,1,1,1
1,1,1,1,2,2,2,2,2,2,2,2,2,2,2,2,2,2,2,2,2,2,2,2,2,2,2,2,2,1,1,1,1,1,1,1,1,1,1,1,1
1,1,1,1,2,2,2,2,2,2,2,2,2,2,2,2,2,2,2,2,2,2,2,2,2,2,2,2,2,1,1,1,2,2,2,2,2,2,2,2,1
1,1,1,1,2,2,2,2,2,2,2,2,2,2,2,2,2,2,2,2,2,2,2,2,2,2,2,2,2,1,1,1,2,2,2,2,2,2,2,2,1
1,1,1,1,2,2,2,2,2,2,2,2,2,2,2,2,2,2,2,2,2,2,2,2,2,2,2,2,2,1,1,1,2,2,2,2,2,2,2,2,1
1,1,1,1,2,2,2,2,2,2,2,2,2,2,2,2,2,2,2,2,2,2,2,2,2,2,2,2,2,1,1,1,2,2,2,2,2,2,2,2,1
1,1,1,1,2,2,2,2,2,2,2,2,2,2,2,2,2,2,2,2,2,2,2,2,2,2,2,2,2,1,1,1,2,2,2,2,2,2,2,2,1
1,1,1,1,2,2,2,2,2,2,2,2,2,2,2,2,2,2,2,2,2,2,2,2,2,2,2,2,2,1,1,1,2,2,2,2,2,2,2,2,1
1,1,1,1,2,2,2,2,2,2,2,2,2,2,2,2,2,2,2,2,2,2,2,2,2,2,2,2,2,1,1,1,2,2,2,2,2,2,2,2,1
1,1,1,1,2,2,2,2,2,2,2,2,2,2,2,2,2,2,2,2,2,2,2,2,2,2,2,2,2,1,1,1,2,2,2,2,2,2,2,2,1
1,1,1,1,2,2,2,2,2,2,2,2,2,2,2,2,2,2,2,2,2,2,2,2,2,2,2,2,2,1,1,1,2,2,2,2,2,2,2,2,1
1,1,1,1,2,2,2,2,2,2,2,2,2,2,2,2,2,2,2,2,2,2,2,2,2,2,2,2,2,1,1,1,2,2,2,2,2,2,2,2,1
1,1,1,1,2,2,2,2,2,2,2,2,2,2,2,2,2,2,2,2,2,2,2,2,2,2,2,2,2,1,1,1,2,2,2,2,2,2,2,2,1
1,1,1,1,2,2,2,2,2,2,2,2,2,2,2,2,2,2,2,2,2,2,2,2,2,2,2,2,2,1,1,1,2,2,2,2,2,2,2,2,1
1,1,1,1,2,2,2,2,2,2,2,2,2,2,2,2,2,2,2,2,2,2,2,2,2,2,2,2,2,1,1,1,2,2,2,2,2,2,2,2,1
1,1,1,1,2,2,2,2,2,2,2,2,2,2,2,2,2,2,2,2,2,2,2,2,2,2,2,2,2,2,2,2,2,2,2,2,2,2,2,2,1
1,1,1,1,2,2,2,2,2,2,2,2,2,2,2,2,2,2,2,2,2,2,2,2,2,2,2,2,2,2,2,2,2,2,2,2,2,2,2,2,1
1,1,1,1,2,2,2,2,2,2,2,2,2,2,2,2,2,2,2,2,2,2,2,2,2,2,2,2,2,2,2,2,2,2,2,2,2,2,2,2,1
1,1,1,1,1,1,1,1,1,1,1,1,1,1,1,1,1,1,1,1,1,1,1,1,1,1,1,1,1,1,1,0,0,2,2,2,2,2,2,2,1
1,1,1,1,1,1,1,1,1,1,1,1,1,1,1,1,1,1,1,1,1,1,1,1,1,1,1,1,1,1,1,1,1,1,1,1,1,1,1,1,1
1,1,1,1,1,1,1,1,1,1,1,1,1,1,1,1,1,1,1,1,1,1,1,1,1,1,1,1,1,1,1,1,1,1,1,1,1,1,1,1,1
1,1,1,1,1,1,1,1,1,1,1,1,1,1,1,1,1,1,1,1,1,1,1,1,1,1,1,1,1,1,1,1,1,1,1,1,1,1,1,1,1
1,1,1,1,1,1,1,1,1,1,1,1,1,1,1,1,1,1,1,1,1,1,1,1,1,1,1,1,1,1,1,1,1,1,1,1,1,1,1,1,1
endlayer

layer
1,1,1,1,1,1,1,1,1,1,1,1,1,1,1,1,1,1,1,1,1,1,1,1,1,1,1,1,1,1,1,1,1,1,1,1,1,1,1,1,1
1,1,1,1,1,1,1,1,1,1,1,1,1,1,1,1,1,1,1,1,1,1,1,1,1,1,1,1,1,1,1,1,1,1,1,1,1,1,1,1,1
1,1,1,1,1,1,1,1,1,1,1,1,1,1,1,1,1,1,1,1,1,1,1,1,1,1,1,1,1,1,1,1,1,1,1,1,1,1,1,1,1
1,1,1,2,2,2,2,2,2,2,2,2,2,2,2,2,2,2,2,2,2,2,2,2,2,2,2,2,2,2,2,1,1,1,1,1,1,1,1,1,1
1,1,1,2,2,2,2,2,2,2,2,2,2,2,2,2,2,2,2,2,2,2,2,2,2,2,2,2,2,2,2,1,1,1,1,1,1,1,1,1,1
1,0,0,2,2,10,0,10,5,9,8,2,0,7,6,0,2,0,4,3,0,4,3,0,4,3,5,4,3,2,2,1,1,1,1,1,1,1,1,1,1
1,0,0,2,2,0,0,0,9,8,0,2,3,0,0,3,2,0,11,0,0,11,0,0,11,0,9,11,0,2,2,1,1,1,1,1,1,1,1,1,1
1,1,0,2,2,10,0,10,8,0,0,2,13,12,0,3,2,0,9,0,0,9,0,0,9,0,8,0,0,2,2,1,1,1,1,1,1,1,1,1,1
1,1,1,2,2,0,0,0,0,0,0,2,2,14,2,2,2,0,0,0,0,0,0,0,0,0,0,0,0,2,2,1,1,1,1,1,1,1,1,1,1
1,1,1,2,2,16,16,0,0,0,0,2,0,0,0,0,0,0,0,0,0,0,0,0,0,0,0,15,3,2,2,1,1,1,1,1,1,1,1,1,1
1,1,1,2,2,0,0,0,0,0,0,2,0,0,0,0,0,0,0,0,0,0,0,0,0,0,0,17,3,2,2,1,1,1,1,1,1,1,1,1,1
1,1,1,2,2,0,0,0,0,0,0,2,0,0,0,9,2,0,0,0,0,0,0,0,0,0,0,0,0,2,2,1,1,1,1,1,1,1,1,1,1
1,1,1,2,2,0,0,0,0,0,0,2,0,0,9,18,2,0,0,0,0,0,0,0,0,0,0,9,0,2,2,1,1,1,1,1,1,1,1,1,1
1,1,1,2,2,0,3,3,3,3,0,2,0,0,9,9,2,0,19,0,0,19,0,0,19,0,0,19,0,2,2,1,1,1,1,1,1,1,1,1,1
1,1,1,2,2,0,3,0,0,3,0,2,0,0,9,9,2,0,20,3,0,20,3,0,20,3,0,20,3,2,2,1,1,1,1,1,1,1,1,1,1
1,1,1,2,2,0,0,0,0,0,0,2,0,0,0,0,2,2,2,2,2,2,2,2,2,2,2,2,2,2,2,1,1,1,1,1,1,1,1,1,1
1,1,1,2,2,0,0,0,0,0,0,2,9,9,0,0,2,9,8,0,0,0,0,0,0,0,0,0,0,2,2,1,1,1,1,1,1,1,1,1,1
1,1,1,2,2,2,2,22,22,2,2,2,9,9,0,0,2,5,9,0,21,0,21,0,21,0,0,0,0,2,2,1,1,1,1,1,1,1,1,1,1
1,1,1,2,2,23,21,0,0,0,0,0,0,0,0,0,2,3,8,0,3,3,3,3,3,3,0,0,3,2,2,1,1,1,1,1,1,1,1,1,1
1,1,1,2,2,23,0,0,0,0,0,0,0,0,0,0,2,3,0,23,3,3,3,3,3,3,24,0,3,2,2,1,2,2,2,2,2,2,2,2,1
1,1,1,2,2,23,0,0,0,0,0,0,0,0,0,0,2,26,0,0,25,0,25,0,25,0,0,0,0,2,2,1,2,2,2,2,2,2,2,2,1
1,1,1,2,2,23,25,0,0,0,0,0,0,0,0,0,2,27,0,0,0,0,0,0,0,0,0,0,0,2,2,1,2,2,2,2,2,2,2,2,1
1,1,1,2,2,2,2,29,29,2,2,2,0,9,9,0,2,0,0,0,0,0,0,0,0,0,0,0,0,2,2,1,2,28,28,28,28,28,28,2,1
1,1,1,2,2,13,31,12,12,31,13,2,0,9,9,0,30,0,0,0,0,0,0,0,0,0,0,0,0,2,2,1,2,0,0,0,0,0,0,2,1
1,1,1,2,2,0,0,0,3,3,3,2,0,0,0,0,30,0,0,0,21,3,21,3,21,3,21,3,0,2,2,1,2,0,0,0,0,0,0,2,1
1,1,1,2,2,0,0,0,3,25,0,2,0,9,0,0,2,23,0,0,0,0,0,0,0,0,0,0,0,2,2,1,2,0,0,0,0,0,0,2,1
1,1,1,2,2,23,0,0,0,0,0,2,0,0,0,0,2,0,0,0,21,3,21,3,21,3,21,3,0,2,2,1,2,0,0,0,0,0,0,2,1
1,1,1,2,2,0,0,0,0,0,0,2,0,0,0,32,2,0,0,0,0,0,0,0,0,0,0,0,0,2,2,1,2,8,0,0,0,0,0,2,1
1,1,1,2,2,0,0,0,3,3,3,2,0,0,0,0,2,3,0,0,0,0,0,0,0,0,0,0,0,2,2,1,2,9,8,0,0,0,0,2,1
1,1,1,2,2,0,0,0,3,0,24,2,9,9,0,9,2,3,0,0,3,3,3,3,3,3,3,0,0,2,2,1,2,33,9,8,0,0,8,2,1
1,1,1,2,2,0,0,0,0,0,0,2,0,0,0,0,2,0,0,0,0,0,0,0,0,0,0,0,0,2,2,1,2,9,8,0,0,8,9,2,1
1,1,1,2,2,0,0,0,0,0,0,2,0,0,9,9,2,0,0,0,0,0,0,0,0,0,0,0,0,2,2,1,2,8,0,0,8,9,5,2,1
1,1,1,2,2,0,0,0,3,3,3,2,0,0,9,9,2,2,2,2,2,2,2,2,2,2,2,2,2,2,2,1,2,0,0,0,0,8,3,2,1
1,1,1,2,2,3,0,0,3,24,0,2,0,0,0,0,0,3,3,0,3,3,0,3,3,0,3,3,0,2,2,2,2,0,0,0,0,0,3,2,1
1,1,1,2,2,3,0,0,0,0,0,2,8,0,0,0,0,0,0,0,0,0,0,0,0,0,0,0,0,0,0,0,34,0,0,0,0,0,3,2,1
1,1,1,2,2,0,0,0,0,21,3,2,9,8,0,0,0,0,0,0,0,0,0,0,0,0,0,0,0,0,0,0,34,0,0,0,0,0,3,2,1
1,1,1,2,2,0,0,0,3,3,3,2,37,9,8,0,0,3,3,36,3,3,36,3,3,36,3,3,0,2,2,2,2,3,35,3,3,35,3,2,1
1,1,1,2,2,2,2,2,2,2,2,2,2,2,2,2,2,2,2,2,2,2,2,2,2,2,2,2,2,2,2,2,2,2,2,2,2,2,2,2,1
1,1,1,2,2,2,2,2,2,2,2,2,2,2,2,2,2,2,2,2,2,2,2,2,2,2,2,2,2,2,2,1,1,1,1,1,1,1,1,1,1
1,1,1,1,1,1,1,1,1,1,1,1,1,1,1,1,1,1,1,1,1,1,1,1,1,1,1,1,1,1,1,1,1,1,1,1,1,1,1,1,1
1,1,1,1,1,1,1,1,1,1,1,1,1,1,1,1,1,1,1,1,1,1,1,1,1,1,1,1,1,1,1,1,1,1,1,1,1,1,1,1,1
1,1,1,1,1,1,1,1,1,1,1,1,1,1,1,1,1,1,1,1,1,1,1,1,1,1,1,1,1,1,1,1,1,1,1,1,1,1,1,1,1
endlayer

layer
1,1,1,1,1,1,1,1,1,1,1,1,1,1,1,1,1,1,1,1,1,1,1,1,1,1,1,1,1,1,1,1,1,1,1,1,1,1,1,1,1
1,1,1,1,1,1,1,1,1,1,1,1,1,1,1,1,1,1,1,1,1,1,1,1,1,1,1,1,1,1,1,1,1,1,1,1,1,1,1,1,1
1,1,1,1,1,1,1,1,1,1,1,1,1,1,1,1,1,1,1,1,1,1,1,1,1,1,1,1,1,1,1,1,1,1,1,1,1,1,1,1,1
1,1,1,2,2,2,2,2,2,2,2,2,2,2,2,2,2,2,2,2,2,2,2,2,2,2,2,2,2,2,2,1,1,1,1,1,1,1,1,1,1
1,1,1,2,2,2,2,2,2,2,2,2,2,2,2,2,2,2,2,2,2,2,2,2,2,2,2,2,2,2,2,1,1,1,1,1,1,1,1,1,1
1,2,2,2,2,3,3,3,8,0,0,2,0,0,0,0,2,0,0,3,0,0,3,0,0,3,8,0,3,2,2,1,1,1,1,1,1,1,1,1,1
1,2,2,2,2,3,3,3,0,0,0,2,3,0,0,3,2,0,0,0,0,0,0,0,0,0,0,0,0,2,2,1,1,1,1,1,1,1,1,1,1
1,2,2,2,2,3,3,3,0,0,0,2,13,0,0,3,2,0,0,0,0,0,0,0,0,0,0,0,0,2,2,1,1,1,1,1,1,1,1,1,1
1,1,1,2,2,16,16,0,0,0,0,2,2,38,2,2,0,0,0,0,0,0,0,0,0,0,0,0,0,2,2,1,1,1,1,1,1,1,1,1,1
1,1,1,2,2,0,0,0,0,0,0,2,0,0,0,0,0,0,0,0,0,0,0,0,0,0,0,0,3,2,2,1,1,1,1,1,1,1,1,1,1
1,1,1,2,2,0,0,0,0,0,0,2,0,0,0,0,0,0,0,0,0,0,0,0,0,0,0,0,3,2,2,1,1,1,1,1,1,1,1,1,1
1,1,1,2,2,0,0,0,0,0,0,2,0,0,0,0,0,0,0,0,0,0,0,0,0,0,0,0,0,2,2,1,1,1,1,1,1,1,1,1,1
1,1,1,2,2,0,0,0,0,0,0,2,0,0,0,8,2,0,0,0,0,0,0,0,0,0,0,0,0,2,2,1,1,1,1,1,1,1,1,1,1
1,1,1,2,2,0,0,0,0,0,0,2,0,0,9,9,2,0,0,0,0,0,0,0,0,0,0,0,0,2,2,1,1,1,1,1,1,1,1,1,1
1,1,1,2,2,0,0,0,0,0,0,2,0,0,9,9,2,0,0,3,0,0,3,0,0,3,0,0,3,2,2,1,1,1,1,1,1,1,1,1,1
1,1,1,2,2,0,0,0,0,0,0,2,0,0,0,0,2,2,2,2,2,2,2,2,2,2,2,2,2,2,2,1,1,1,1,1,1,1,1,1,1
1,1,1,2,2,0,39,0,0,0,0,2,9,9,0,0,2,0,0,0,0,0,0,0,0,0,0,0,0,2,2,1,1,1,1,1,1,1,1,1,1
1,1,1,2,2,2,2,41,40,2,2,2,9,9,0,0,2,8,0,0,0,0,0,0,0,0,0,0,0,2,2,1,2,2,2,2,2,2,2,2,1
1,1,1,2,2,0,44,0,0,43,0,0,0,0,0,0,2,3,0,0,0,0,0,0,0,0,0,0,42,2,2,1,2,2,2,2,2,2,2,2,1
1,1,1,2,2,0,0,0,0,0,0,0,0,0,0,0,2,3,0,0,0,0,0,0,0,0,0,0,42,2,2,1,2,2,2,2,2,2,2,2,1
1,1,1,2,2,0,0,0,0,0,0,0,0,0,0,0,2,0,0,0,0,0,0,0,0,0,0,0,0,2,2,1,2,28,28,28,28,28,28,2,1
1,1,1,2,2,0,0,0,0,0,0,0,0,0,0,0,2,0,0,0,0,0,0,0,0,0,0,0,0,2,2,1,2,0,0,0,0,0,0,2,1
1,1,1,2,2,2,2,45,38,2,2,2,0,9,9,0,2,0,0,0,0,0,0,0,0,0,0,0,0,2,2,1,2,0,0,0,0,0,0,2,1
1,1,1,2,2,13,0,0,0,0,13,2,0,9,9,0,38,0,0,0,0,0,0,0,0,0,0,0,0,2,2,1,2,0,0,0,0,0,0,2,1
1,1,1,2,2,0,0,0,0,42,0,2,0,0,0,0,45,0,0,0,0,0,0,0,0,0,0,0,0,2,2,1,2,0,0,0,0,0,0,2,1
1,1,1,2,2,0,0,0,0,0,0,2,0,0,0,0,2,0,0,0,0,0,0,0,0,0,0,0,0,2,2,1,2,0,0,0,0,0,0,2,1
1,1,1,2,2,0,0,0,0,0,0,2,0,0,0,0,2,0,0,0,0,0,0,0,0,0,0,0,0,2,2,1,2,0,0,0,0,0,0,2,1
1,1,1,2,2,0,0,0,0,0,0,2,0,0,0,0,2,0,0,0,0,0,0,0,0,0,0,0,0,2,2,1,2,0,0,0,0,0,0,2,1
1,1,1,2,2,0,0,0,0,42,0,2,0,0,0,0,2,3,0,0,0,0,0,0,0,0,0,0,0,2,2,1,2,0,0,0,0,0,0,2,1
1,1,1,2,2,0,0,0,0,0,0,2,9,9,0,9,2,3,0,0,42,42,42,42,42,42,42,0,0,2,2,1,2,8,0,0,0,0,0,2,1
1,1,1,2,2,0,0,0,0,0,0,2,0,0,0,0,2,0,0,0,0,0,0,0,0,0,0,0,0,2,2,1,2,0,0,0,0,0,0,2,1
1,1,1,2,2,0,0,0,0,0,0,2,0,0,9,9,2,0,0,0,0,0,0,0,0,0,0,0,0,2,2,1,2,0,0,0,0,0,8,2,1
1,1,1,2,2,0,0,0,0,42,0,2,0,0,9,9,2,2,2,2,2,2,2,2,2,2,2,2,2,2,2,1,2,0,0,0,0,0,0,2,1
1,1,1,2,2,3,0,0,0,0,0,2,0,0,0,0,0,0,0,0,0,0,0,0,0,0,0,0,0,2,2,2,2,46,0,0,0,0,0,2,1
1,1,1,2,2,3,0,0,0,0,0,2,0,0,0,0,0,0,0,0,0,0,0,0,0,0,0,0,0,0,0,43,41,0,0,0,0,0,0,2,1
1,1,1,2,2,0,0,0,0,0,0,2,0,0,0,0,0,0,0,0,0,0,0,0,0,0,0,0,0,0,0,47,40,0,0,0,0,0,0,2,1
1,1,1,2,2,0,0,0,0,42,0,2,8,0,0,0,0,3,3,0,3,3,0,3,3,0,3,3,0,2,2,2,2,0,0,3,3,0,0,2,1
1,1,1,2,2,2,2,2,2,2,2,2,2,2,2,2,2,2,2,2,2,2,2,2,2,2,2,2,2,2,2,2,2,2,2,2,2,2,2,2,1
1,1,1,2,2,2,2,2,2,2,2,2,2,2,2,2,2,2,2,2,2,2,2,2,2,2,2,2,2,2,2,1,1,1,1,1,1,1,1,1,1
1,1,1,1,1,1,1,1,1,1,1,1,1,1,1,1,1,1,1,1,1,1,1,1,1,1,1,1,1,1,1,1,1,1,1,1,1,1,1,1,1
1,1,1,1,1,1,1,1,1,1,1,1,1,1,1,1,1,1,1,1,1,1,1,1,1,1,1,1,1,1,1,1,1,1,1,1,1,1,1,1,1
1,1,1,1,1,1,1,1,1,1,1,1,1,1,1,1,1,1,1,1,1,1,1,1,1,1,1,1,1,1,1,1,1,1,1,1,1,1,1,1,1
endlayer

layer
48,48,48,48,48,48,48,48,48,48,48,48,48,48,48,48,48,48,48,48,48,48,48,48,48,48,48,48,48,48,48,48,48,48,48,48,48,48,48,48,48
48,48,48,48,48,48,48,48,48,48,48,48,48,48,48,48,48,48,48,48,48,48,48,48,48,48,48,48,48,48,48,48,48,48,48,48,48,48,48,48,48
48,48,48,48,48,48,48,48,48,48,48,48,48,48,48,48,48,48,48,48,48,48,48,48,48,48,48,48,48,48,48,48,48,48,48,48,48,48,48,48,48
48,48,48,2,2,2,2,2,2,2,2,2,2,2,2,2,2,2,2,2,2,2,2,2,2,2,2,2,2,2,2,48,48,48,48,48,48,48,48,48,48
48,48,48,2,2,2,2,2,2,2,2,2,2,2,2,2,2,2,2,2,2,2,2,2,2,2,2,2,2,2,2,48,48,48,48,48,48,48,48,48,48
48,2,2,2,2,0,0,0,0,0,0,2,0,0,0,0,2,0,0,0,0,0,0,0,0,0,0,0,0,2,2,48,48,48,48,48,48,48,48,48,48
48,2,49,0,0,0,0,0,0,0,0,2,3,0,0,3,2,0,0,0,0,0,0,0,0,0,0,0,0,2,2,48,48,48,48,48,48,48,48,48,48
48,2,2,2,2,0,0,0,0,0,0,2,13,0,0,3,2,0,0,0,0,0,0,0,0,0,0,0,0,2,2,48,48,48,48,48,48,48,48,48,48
48,48,48,2,2,0,0,0,0,0,0,2,2,3,3,2,0,0,0,0,0,0,0,0,0,0,0,0,0,2,2,48,48,48,48,48,48,48,48,48,48
48,48,48,2,2,0,0,0,0,0,0,2,0,0,0,0,0,0,0,0,0,0,0,0,0,0,0,0,3,2,2,48,48,48,48,48,48,48,48,48,48
48,48,48,2,2,0,0,0,0,0,0,2,0,0,0,0,0,0,0,0,0,0,0,0,0,0,0,0,3,2,2,48,48,48,48,48,48,48,48,48,48
48,48,48,2,2,0,0,0,0,0,0,2,0,0,0,0,0,0,0,0,0,0,0,0,0,0,0,0,0,2,2,48,48,48,48,48,48,48,48,48,48
48,48,48,2,2,0,0,0,0,0,0,2,0,0,0,0,0,0,0,0,0,0,0,0,0,0,0,0,0,2,2,48,48,48,48,48,48,48,48,48,48
48,48,48,2,2,0,0,0,0,0,0,2,0,0,0,0,2,0,0,0,0,0,0,0,0,0,0,0,0,2,2,48,48,48,48,48,48,48,48,48,48
48,48,48,2,2,0,0,0,0,0,0,2,0,0,0,0,2,0,0,0,0,0,0,0,0,0,0,0,0,2,2,48,48,48,48,48,48,48,48,48,48
48,48,48,2,2,0,0,0,0,0,0,2,0,0,0,0,2,2,2,2,2,2,2,2,2,2,2,2,2,2,2,48,2,2,2,2,2,2,2,2,48
48,48,48,2,2,0,0,0,0,0,0,2,0,0,0,0,2,0,0,0,0,0,0,0,0,0,0,0,0,2,2,48,2,2,2,2,2,2,2,2,48
48,48,48,2,2,2,2,3,3,2,2,2,0,0,0,0,2,0,0,0,0,0,0,0,0,0,0,0,0,2,2,48,2,2,2,2,2,2,2,2,48
48,48,48,2,2,0,0,0,0,0,0,0,0,0,0,0,2,3,0,0,0,0,0,0,0,0,0,0,42,2,2,48,2,28,28,28,28,28,28,2,48
48,48,48,2,2,0,0,0,0,0,0,0,0,0,0,0,2,3,0,0,0,0,0,0,0,0,0,0,42,2,2,48,2,0,0,0,0,0,0,2,48
48,48,48,2,2,0,0,0,0,0,0,0,0,0,0,0,2,0,0,0,0,0,0,0,0,0,0,0,0,2,2,48,2,0,0,0,0,0,0,2,48
48,48,48,2,2,0,0,0,0,0,0,0,0,0,0,0,2,0,0,0,0,0,0,0,0,0,0,0,0,2,2,48,2,0,0,0,0,0,0,2,48
48,48,48,2,2,2,2,3,3,2,2,2,0,0,0,0,2,0,0,0,0,0,0,0,0,0,0,0,0,2,2,48,2,0,0,0,0,0,0,2,48
48,48,48,2,2,13,0,0,0,0,13,2,0,0,0,0,3,0,0,0,0,0,0,0,0,0,0,0,0,2,2,48,2,0,0,0,0,0,0,2,48
48,48,48,2,2,0,0,0,0,0,0,2,0,0,0,0,3,0,0,0,0,0,0,0,0,0,0,0,0,2,2,48,2,0,0,0,0,0,0,2,48
48,48,48,2,2,0,0,0,0,0,0,2,0,0,0,0,2,0,0,0,0,0,0,0,0,0,0,0,0,2,2,48,2,0,0,0,0,0,0,2,48
48,48,48,2,2,0,0,0,0,0,0,2,0,0,0,0,2,0,0,0,0,0,0,0,0,0,0,0,0,2,2,48,2,0,0,0,0,0,0,2,48
48,48,48,2,2,0,0,0,0,0,0,2,0,0,0,0,2,0,0,0,0,0,0,0,0,0,0,0,0,2,2,48,2,0,0,0,0,0,0,2,48
48,48,48,2,2,0,0,0,0,0,0,2,0,0,0,0,2,3,0,0,0,0,0,0,0,0,0,0,0,2,2,48,2,0,0,0,0,0,0,2,48
48,48,48,2,2,0,0,0,0,0,0,2,0,0,0,0,2,3,0,0,42,42,42,42,42,42,42,0,0,2,2,48,2,0,0,0,0,0,0,2,48
48,48,48,2,2,0,0,0,0,0,0,2,0,0,0,0,2,0,0,0,0,0,0,0,0,0,0,0,0,2,2,48,2,0,0,0,0,0,0,2,48
48,48,48,2,2,0,0,0,0,0,0,2,0,0,0,0,2,0,0,0,0,0,0,0,0,0,0,0,0,2,2,48,2,0,0,0,0,0,0,2,48
48,48,48,2,2,0,0,0,0,0,0,2,0,0,0,0,2,2,2,2,2,2,2,2,2,2,2,2,2,2,2,48,2,0,0,0,0,0,0,2,48
48,48,48,2,2,3,0,0,0,0,0,2,0,0,0,0,0,0,0,0,0,0,0,0,0,0,0,0,0,2,2,2,2,0,0,0,0,0,0,2,48
48,48,48,2,2,3,0,0,0,0,0,2,0,0,0,0,0,0,0,0,0,0,0,0,0,0,0,0,0,2,2,2,2,0,0,0,0,0,0,2,48
48,48,48,2,2,0,0,0,0,0,0,2,0,0,0,0,0,0,0,0,0,0,0,0,0,0,0,0,0,2,2,2,2,0,0,0,0,0,0,2,48
48,48,48,2,2,0,0,0,0,0,0,2,0,0,0,0,0,3,3,0,3,3,0,3,3,0,3,3,0,2,2,2,2,0,0,3,3,0,0,2,48
48,48,48,2,2,2,2,2,2,2,2,2,2,2,2,2,2,2,2,2,2,2,2,2,2,2,2,2,2,2,2,2,2,2,2,2,2,2,2,2,48
48,48,48,2,2,2,2,2,2,2,2,2,2,2,2,2,2,2,2,2,2,2,2,2,2,2,2,2,2,2,2,48,48,48,48,48,48,48,48,48,48
48,48,48,48,48,48,48,48,48,48,48,48,48,48,48,48,48,48,48,48,48,48,48,48,48,48,48,48,48,48,48,48,48,48,48,48,48,48,48,48,48
48,48,48,48,48,48,48,48,48,48,48,48,48,48,48,48,48,48,48,48,48,48,48,48,48,48,48,48,48,48,48,48,48,48,48,48,48,48,48,48,48
48,48,48,48,48,48,48,48,48,48,48,48,48,48,48,48,48,48,48,48,48,48,48,48,48,48,48,48,48,48,48,48,48,48,48,48,48,48,48,48,48
endlayer

layer
48,48,48,48,48,48,48,48,48,48,48,48,48,48,48,48,48,48,48,48,48,48,48,48,48,48,48,48,48,48,48,48,48,48,48,48,48,48,48,48,48
48,48,48,48,48,48,48,48,48,48,48,48,48,48,48,48,48,48,48,48,48,48,48,48,48,48,48,48,48,48,48,48,48,48,48,48,48,48,48,48,48
48,48,48,48,48,48,48,48,48,48,48,48,48,48,48,48,48,48,48,48,48,48,48,48,48,48,48,48,48,48,48,48,48,48,48,48,48,48,48,48,48
48,48,48,2,2,2,2,2,2,2,2,2,2,2,2,2,2,2,2,2,2,2,2,2,2,2,2,2,2,2,2,48,48,48,48,48,48,48,48,48,48
48,48,48,2,2,2,2,2,2,2,2,2,2,2,2,2,2,2,2,2,2,2,2,2,2,2,2,2,2,2,2,48,48,48,48,48,48,48,48,48,48
48,2,2,2,2,0,0,0,0,0,0,2,0,0,0,0,2,0,0,0,0,0,0,0,0,0,0,0,0,2,2,48,48,48,48,48,48,48,48,48,48
48,2,49,0,0,0,0,0,0,0,0,2,0,0,0,0,2,0,0,0,0,0,0,0,0,0,0,0,0,2,2,48,48,48,48,48,48,48,48,48,48
48,2,2,2,2,0,0,0,0,0,0,2,0,0,0,0,2,0,0,0,0,0,0,0,0,0,0,0,0,2,2,48,48,48,48,48,48,48,48,48,48
48,48,48,2,2,0,0,0,0,0,0,2,2,2,2,2,2,0,0,0,0,0,0,0,0,0,0,0,0,2,2,48,48,48,48,48,48,48,48,48,48
48,48,48,2,2,0,0,0,0,0,0,2,0,0,0,0,0,0,0,0,0,0,0,0,0,0,0,0,0,2,2,48,48,48,48,48,48,48,48,48,48
48,48,48,2,2,0,0,0,0,0,0,2,0,0,0,0,0,0,0,0,0,0,0,0,0,0,0,0,0,2,2,48,48,48,48,48,48,48,48,48,48
48,48,48,2,2,0,0,0,0,0,0,2,0,0,0,0,2,0,0,0,0,0,0,0,0,0,0,0,0,2,2,48,48,48,48,48,48,48,48,48,48
48,48,48,2,2,0,0,0,0,0,0,2,0,0,0,0,2,0,0,0,0,0,0,0,0,0,0,0,0,2,2,48,48,48,48,48,48,48,48,48,48
48,48,48,2,2,0,0,0,0,0,0,2,0,0,0,0,2,0,0,0,0,0,0,0,0,0,0,0,0,2,2,48,2,2,2,2,2,2,2,2,48
48,48,48,2,2,0,0,0,0,0,0,2,0,0,0,0,2,0,0,0,0,0,0,0,0,0,0,0,0,2,2,48,2,2,2,2,2,2,2,2,48
48,48,48,2,2,0,0,0,0,0,0,2,0,0,0,0,2,2,2,2,2,2,2,2,2,2,2,2,2,2,2,48,2,2,2,2,2,2,2,2,48
48,48,48,2,2,0,0,0,0,0,0,2,0,0,0,0,2,0,0,0,0,0,0,0,0,0,0,0,0,2,2,48,2,28,28,28,28,28,28,2,48
48,48,48,2,2,2,2,2,2,2,2,2,0,0,0,0,2,0,0,0,0,0,0,0,0,0,0,0,0,2,2,48,2,0,0,0,0,0,0,2,48
48,48,48,2,2,0,0,0,0,0,0,0,0,0,0,0,2,0,0,0,0,0,0,0,0,0,0,0,0,2,2,48,2,0,0,0,0,0,0,2,48
48,48,48,2,2,0,0,0,0,0,0,0,0,0,0,0,2,0,0,0,0,0,0,0,0,0,0,0,0,2,2,48,2,0,0,0,0,0,0,2,48
48,48,48,2,2,0,0,0,0,0,0,0,0,0,0,0,2,0,0,0,0,0,0,0,0,0,0,0,0,2,2,48,2,0,0,0,0,0,0,2,48
48,48,48,2,2,0,0,0,0,0,0,0,0,0,0,0,2,0,0,0,0,0,0,0,0,0,0,0,0,2,2,48,2,0,0,0,0,0,0,2,48
48,48,48,2,2,2,2,2,2,2,2,2,0,0,0,0,2,0,0,0,0,0,0,0,0,0,0,0,0,2,2,48,2,0,0,0,0,0,0,2,48
48,48,48,2,2,13,0,0,0,0,13,2,0,0,0,0,2,0,0,0,0,0,0,0,0,0,0,0,0,2,2,48,2,0,0,0,0,0,0,2,48
48,48,48,2,2,0,0,0,0,0,0,2,0,0,0,0,2,0,0,0,0,0,0,0,0,0,0,0,0,2,2,48,2,0,0,0,0,0,0,2,48
48,48,48,2,2,0,0,0,0,0,0,2,0,0,0,0,2,0,0,0,0,0,0,0,0,0,0,0,0,2,2,48,2,0,0,0,0,0,0,2,48
48,48,48,2,2,0,0,0,0,0,0,2,0,0,0,0,2,0,0,0,0,0,0,0,0,0,0,0,0,2,2,48,2,0,0,0,0,0,0,2,48
48,48,48,2,2,0,0,0,0,0,0,2,0,0,0,0,2,0,0,0,0,0,0,0,0,0,0,0,0,2,2,48,2,0,0,0,0,0,0,2,48
48,48,48,2,2,0,0,0,0,0,0,2,0,0,0,0,2,0,0,0,0,0,0,0,0,0,0,0,0,2,2,48,2,0,0,0,0,0,0,2,48
48,48,48,2,2,0,0,0,0,0,0,2,0,0,0,0,2,0,0,0,0,0,0,0,0,0,0,0,0,2,2,48,2,0,0,0,0,0,0,2,48
48,48,48,2,2,0,0,0,0,0,0,2,0,0,0,0,2,0,0,0,0,0,0,0,0,0,0,0,0,2,2,48,2,0,0,0,0,0,0,2,48
48,48,48,2,2,0,0,0,0,0,0,2,0,0,0,0,2,0,0,0,0,0,0,0,0,0,0,0,0,2,2,48,2,0,0,0,0,0,0,2,48
48,48,48,2,2,0,0,0,0,0,0,2,0,0,0,0,2,2,2,2,2,2,2,2,2,2,2,2,2,2,2,48,2,0,0,0,0,0,0,2,48
48,48,48,2,2,0,0,0,0,0,0,2,0,0,0,0,0,0,0,0,0,0,0,0,0,0,0,0,0,2,2,48,2,0,0,0,0,0,0,2,48
48,48,48,2,2,0,0,0,0,0,0,2,0,0,0,0,0,0,0,0,0,0,0,0,0,0,0,0,0,2,2,2,2,0,0,0,0,0,0,2,48
48,48,48,2,2,0,0,0,0,0,0,2,0,0,0,0,0,0,0,0,0,0,0,0,0,0,0,0,0,2,2,2,2,0,0,0,0,0,0,2,48
48,48,48,2,2,0,0,0,0,0,0,2,0,0,0,0,0,0,0,0,0,0,0,0,0,0,0,0,0,2,2,2,2,0,0,0,0,0,0,2,48
48,48,48,2,2,2,2,2,2,2,2,2,2,2,2,2,2,2,2,2,2,2,2,2,2,2,2,2,2,2,2,2,2,2,2,2,2,2,2,2,48
48,48,48,2,2,2,2,2,2,2,2,2,2,2,2,2,2,2,2,2,2,2,2,2,2,2,2,2,2,2,2,48,48,48,48,48,48,48,48,48,48
48,48,48,48,48,48,48,48,48,48,48,48,48,48,48,48,48,48,48,48,48,48,48,48,48,48,48,48,48,48,48,48,48,48,48,48,48,48,48,48,48
48,48,48,48,48,48,48,48,48,48,48,48,48,48,48,48,48,48,48,48,48,48,48,48,48,48,48,48,48,48,48,48,48,48,48,48,48,48,48,48,48
48,48,48,48,48,48,48,48,48,48,48,48,48,48,48,48,48,48,48,48,48,48,48,48,48,48,48,48,48,48,48,48,48,48,48,48,48,48,48,48,48
endlayer

layer
50,50,50,50,50,50,50,50,50,50,50,50,50,50,50,50,50,50,50,50,50,50,50,50,50,50,50,50,50,50,50,50,50,50,50,50,50,50,50,50,50
50,50,50,50,50,50,50,50,50,50,50,50,50,50,50,50,50,50,50,50,50,50,50,50,50,50,50,50,50,50,50,50,50,50,50,50,50,50,50,50,50
50,50,50,50,50,50,50,50,50,50,50,50,50,50,50,50,50,50,50,50,50,50,50,50,50,50,50,50,50,50,50,50,50,50,50,50,50,50,50,50,50
50,50,50,2,2,2,2,2,2,2,2,2,2,2,2,2,2,2,2,2,2,2,2,2,2,2,2,2,2,2,2,50,50,50,50,50,50,50,50,50,50
50,50,50,2,2,2,2,2,2,2,2,2,2,2,2,2,2,2,2,2,2,2,2,2,2,2,2,2,2,2,2,50,50,50,50,50,50,50,50,50,50
50,2,2,2,2,2,2,2,2,2,2,2,2,2,2,2,2,2,2,2,2,2,2,2,2,2,2,2,2,2,2,50,50,50,50,50,50,50,50,50,50
50,2,49,2,2,2,2,2,2,2,2,2,2,2,2,2,2,2,2,2,2,2,2,2,2,2,2,2,2,2,2,50,50,50,50,50,50,50,50,50,50
50,2,2,2,2,2,2,2,2,2,2,2,2,2,2,2,2,2,2,2,2,2,2,2,2,2,2,2,2,2,2,50,50,50,50,50,50,50,50,50,50
50,50,50,2,2,2,2,2,2,2,2,2,2,2,2,2,2,2,2,2,2,2,2,2,2,2,2,2,2,2,2,50,50,50,50,50,50,50,50,50,50
50,50,50,2,2,2,2,2,2,2,2,2,2,2,2,2,2,2,2,2,2,2,2,2,2,2,2,2,2,2,2,50,50,50,50,50,50,50,50,50,50
50,50,50,2,2,2,2,2,2,2,2,2,2,2,2,2,2,2,2,2,2,2,2,2,2,2,2,2,2,2,2,50,50,50,50,50,50,50,50,50,50
50,50,50,2,2,2,2,2,2,2,2,2,2,2,2,2,2,2,2,2,2,2,2,2,2,2,2,2,2,2,2,50,2,2,2,2,2,2,2,2,50
50,50,50,2,2,2,2,2,2,2,2,2,2,2,2,2,2,2,2,2,2,2,2,2,2,2,2,2,2,2,2,50,2,2,2,2,2,2,2,2,50
50,50,50,2,2,2,2,2,2,2,2,2,2,2,2,2,2,2,2,2,2,2,2,2,2,2,2,2,2,2,2,50,2,2,2,2,2,2,2,2,50
50,50,50,2,2,2,2,2,2,2,2,2,2,2,2,2,2,2,2,2,2,2,2,2,2,2,2,2,2,2,2,50,2,28,28,28,28,28,28,2,50
50,50,50,2,2,2,2,2,2,2,2,2,2,2,2,2,2,2,2,2,2,2,2,2,2,2,2,2,2,2,2,50,2,0,0,0,0,0,0,2,50
50,50,50,2,2,2,2,2,2,2,2,2,2,2,2,2,2,2,2,2,2,2,2,2,2,2,2,2,2,2,2,50,2,0,0,0,0,0,0,2,50
50,50,50,2,2,2,2,2,2,2,2,2,2,2,2,2,2,2,2,2,2,2,2,2,2,2,2,2,2,2,2,50,2,0,0,0,0,0,0,2,50
50,50,50,2,2,2,2,2,2,2,2,2,2,2,2,2,2,2,2,2,2,2,2,2,2,2,2,2,2,2,2,50,2,0,0,0,0,0,0,2,50
50,50,50,2,2,2,2,2,2,2,2,2,2,2,2,2,2,2,2,2,2,2,2,2,2,2,2,2,2,2,2,50,2,0,0,0,0,0,0,2,50
50,50,50,2,2,2,2,2,2,2,2,2,2,2,2,2,2,2,2,2,2,2,2,2,2,2,2,2,2,2,2,50,2,0,0,0,0,0,0,2,50
50,50,50,2,2,2,2,2,2,2,2,2,2,2,2,2,2,2,2,2,2,2,2,2,2,2,2,2,2,2,2,50,2,0,0,0,0,0,0,2,50
50,50,50,2,2,2,2,2,2,2,2,2,2,2,2,2,2,2,2,2,2,2,2,2,2,2,2,2,2,2,2,50,2,0,0,0,0,0,0,2,50
50,50,50,2,2,2,2,2,2,2,2,2,2,2,2,2,2,2,2,2,2,2,2,2,2,2,2,2,2,2,2,50,2,2,2,2,2,2,2,2,50
50,50,50,2,2,2,2,2,2,2,2,2,2,2,2,2,2,2,2,2,2,2,2,2,2,2,2,2,2,2,2,50,2,2,2,2,2,2,2,2,50
50,50,50,2,2,2,2,2,2,2,2,2,2,2,2,2,2,2,2,2,2,2,2,2,2,2,2,2,2,2,2,50,2,2,2,2,2,2,2,2,50
50,50,50,2,2,2,2,2,2,2,2,2,2,2,2,2,2,2,2,2,2,2,2,2,2,2,2,2,2,2,2,50,2,2,2,2,2,2,2,2,50
50,50,50,2,2,2,2,2,2,2,2,2,2,2,2,2,2,2,2,2,2,2,2,2,2,2,2,2,2,2,2,50,2,2,2,2,2,2,2,2,50
50,50,50,2,2,2,2,2,2,2,2,2,2,2,2,2,2,2,2,2,2,2,2,2,2,2,2,2,2,2,2,50,2,2,2,2,2,2,2,2,50
50,50,50,2,2,2,2,2,2,2,2,2,2,2,2,2,2,2,2,2,2,2,2,2,2,2,2,2,2,2,2,50,2,2,2,2,2,2,2,2,50
50,50,50,2,2,2,2,2,2,2,2,2,2,2,2,2,2,2,2,2,2,2,2,2,2,2,2,2,2,2,2,50,2,2,2,2,2,2,2,2,50
50,50,50,2,2,2,2,2,2,2,2,2,2,2,2,2,2,2,2,2,2,2,2,2,2,2,2,2,2,2,2,50,2,2,2,2,2,2,2,2,50
50,50,50,2,2,2,2,2,2,2,2,2,2,2,2,2,2,2,2,2,2,2,2,2,2,2,2,2,2,2,2,50,2,2,2,2,2,2,2,2,50
50,50,50,2,2,2,2,2,2,2,2,2,2,2,2,2,2,2,2,2,2,2,2,2,2,2,2,2,2,2,2,50,2,2,2,2,2,2,2,2,50
50,50,50,2,2,2,2,2,2,2,2,2,2,2,2,2,2,2,2,2,2,2,2,2,2,2,2,2,2,2,2,2,2,2,2,2,2,2,2,2,50
50,50,50,2,2,2,2,2,2,2,2,2,2,2,2,2,2,2,2,2,2,2,2,2,2,2,2,2,2,2,2,2,2,2,2,2,2,2,2,2,50
50,50,50,2,2,2,2,2,2,2,2,2,2,2,2,2,2,2,2,2,2,2,2,2,2,2,2,2,2,2,2,2,2,2,2,2,2,2,2,2,50
50,50,50,2,2,2,2,2,2,2,2,2,2,2,2,2,2,2,2,2,2,2,2,2,2,2,2,2,2,2,2,2,2,2,2,2,2,2,2,2,50
50,50,50,2,2,2,2,2,2,2,2,2,2,2,2,2,2,2,2,2,2,2,2,2,2,2,2,2,2,2,2,50,50,50,50,50,50,50,50,50,50
50,50,50,50,50,50,50,50,50,50,50,50,50,50,50,50,50,50,50,50,50,50,50,50,50,50,50,50,50,50,50,50,50,50,50,50,50,50,50,50,50
50,50,50,50,50,50,50,50,50,50,50,50,50,50,50,50,50,50,50,50,50,50,50,50,50,50,50,50,50,50,50,50,50,50,50,50,50,50,50,50,50
50,50,50,50,50,50,50,50,50,50,50,50,50,50,50,50,50,50,50,50,50,50,50,50,50,50,50,50,50,50,50,50,50,50,50,50,50,50,50,50,50
endlayer

layer
51,51,50,50,50,50,51,51,51,51,51,50,50,50,51,51,51,50,50,50,50,50,50,51,51,51,51,51,51,51,50,50,50,50,50,50,50,50,50,51,51
51,50,50,50,50,50,50,50,50,50,50,50,50,50,50,50,50,50,50,50,50,50,50,50,50,50,50,50,50,50,50,50,50,50,50,50,50,50,50,50,51
50,50,50,50,50,50,50,50,50,50,50,50,50,50,50,50,50,50,50,50,50,50,50,50,50,50,50,50,50,50,50,50,50,50,50,50,50,50,50,50,51
50,50,50,2,2,2,2,2,2,2,2,2,2,2,2,2,2,2,2,2,2,2,2,2,2,2,2,2,2,2,2,50,50,50,50,50,50,50,50,50,51
50,50,50,2,2,2,2,2,2,2,2,2,2,2,2,2,2,2,2,2,2,2,2,2,2,2,2,2,2,2,2,50,50,50,50,50,50,50,50,50,50
50,2,2,2,2,2,2,2,2,2,2,2,2,2,2,2,2,2,2,2,2,2,2,2,2,2,2,2,2,2,2,50,50,50,50,50,50,50,50,50,50
50,2,49,2,2,2,2,2,2,2,2,2,2,2,2,2,2,2,2,2,2,2,2,2,2,2,2,2,2,2,2,50,50,50,50,50,50,50,50,50,50
50,2,2,2,2,2,2,2,2,2,2,2,2,2,2,2,2,2,2,2,2,2,2,2,2,2,2,2,2,2,2,50,50,50,50,50,50,50,50,50,50
50,50,50,2,2,2,2,2,2,2,2,2,2,2,2,2,2,2,2,2,2,2,2,2,2,2,2,2,2,2,2,50,50,50,50,50,50,50,50,50,50
50,50,50,2,2,2,2,2,2,2,2,2,2,2,2,2,2,2,2,2,2,2,2,2,2,2,2,2,2,2,2,50,2,2,2,2,2,2,2,2,50
50,50,50,2,2,2,2,2,2,2,2,2,2,2,2,2,2,2,2,2,2,2,2,2,2,2,2,2,2,2,2,50,2,2,2,2,2,2,2,2,50
50,50,50,2,2,2,2,2,2,2,2,2,2,2,2,2,2,2,2,2,2,2,2,2,2,2,2,2,2,2,2,50,2,2,2,2,2,2,2,2,50
50,50,50,2,2,2,2,2,2,2,2,2,2,2,2,2,2,2,2,2,2,2,2,2,2,2,2,2,2,2,2,50,2,28,28,28,28,28,28,2,50
51,50,50,2,2,2,2,2,2,2,2,2,2,2,2,2,2,2,2,2,2,2,2,2,2,2,2,2,2,2,2,50,2,0,0,0,0,0,0,2,50
51,50,50,2,2,2,2,2,2,2,2,2,2,2,2,2,2,2,2,2,2,2,2,2,2,2,2,2,2,2,2,50,2,0,0,0,0,0,0,2,50
51,50,50,2,2,2,2,2,2,2,2,2,2,2,2,2,2,2,2,2,2,2,2,2,2,2,2,2,2,2,2,50,2,0,0,0,0,0,0,2,50
51,50,50,2,2,2,2,2,2,2,2,2,2,2,2,2,2,2,2,2,2,2,2,2,2,2,2,2,2,2,2,50,2,0,0,0,0,0,0,2,50
51,50,50,2,2,2,2,2,2,2,2,2,2,2,2,2,2,2,2,2,2,2,2,2,2,2,2,2,2,2,2,50,2,0,0,0,0,0,0,2,50
51,50,50,2,2,2,2,2,2,2,2,2,2,2,2,2,2,2,2,2,2,2,2,2,2,2,2,2,2,2,2,50,2,0,0,0,0,0,0,2,50
50,50,50,2,2,2,2,2,2,2,2,2,2,2,2,2,2,2,2,2,2,2,2,2,2,2,2,2,2,2,2,50,2,0,0,0,0,0,0,2,50
50,50,50,2,2,2,2,2,2,2,2,2,2,2,2,2,2,2,2,2,2,2,2,2,2,2,2,2,2,2,2,50,2,0,0,0,0,0,0,2,50
50,50,50,2,2,2,2,2,2,2,2,2,2,2,2,2,2,2,2,2,2,2,2,2,2,2,2,2,2,2,2,50,2,2,2,2,2,2,2,2,50
50,50,50,2,2,2,2,2,2,2,2,2,2,2,2,2,2,2,2,2,2,2,2,2,2,2,2,2,2,2,2,50,2,2,2,2,2,2,2,2,50
50,50,50,2,2,2,2,2,2,2,2,2,2,2,2,2,2,2,2,2,2,2,2,2,2,2,2,2,2,2,2,50,2,2,2,2,2,2,2,2,50
50,50,50,2,2,2,2,2,2,2,2,2,2,2,2,2,2,2,2,2,2,2,2,2,2,2,2,2,2,2,2,50,50,50,50,50,50,50,50,50,50
50,50,50,2,2,2,2,2,2,2,2,2,2,2,2,2,2,2,2,2,2,2,2,2,2,2,2,2,2,2,2,50,50,50,50,50,50,50,50,50,50
50,50,50,2,2,2,2,2,2,2,2,2,2,2,2,2,2,2,2,2,2,2,2,2,2,2,2,2,2,2,2,50,50,50,50,50,50,50,50,50,50
51,50,50,2,2,2,2,2,2,2,2,2,2,2,2,2,2,2,2,2,2,2,2,2,2,2,2,2,2,2,2,50,50,50,50,50,50,50,50,50,50
51,50,50,2,2,2,2,2,2,2,2,2,2,2,2,2,2,2,2,2,2,2,2,2,2,2,2,2,2,2,2,50,50,50,50,50,50,50,50,50,50
51,50,50,2,2,2,2,2,2,2,2,2,2,2,2,2,2,2,2,2,2,2,2,2,2,2,2,2,2,2,2,50,50,50,50,50,50,50,50,50,50
51,50,50,2,2,2,2,2,2,2,2,2,2,2,2,2,2,2,2,2,2,2,2,2,2,2,2,2,2,2,2,50,50,50,50,50,50,50,50,50,50
50,50,50,2,2,2,2,2,2,2,2,2,2,2,2,2,2,2,2,2,2,2,2,2,2,2,2,2,2,2,2,50,50,50,50,50,50,50,50,50,50
50,50,50,2,2,2,2,2,2,2,2,2,2,2,2,2,2,2,2,2,2,2,2,2,2,2,2,2,2,2,2,50,50,50,50,50,50,50,50,50,50
50,50,50,2,2,2,2,2,2,2,2,2,2,2,2,2,2,2,2,2,2,2,2,2,2,2,2,2,2,2,2,50,50,50,50,50,50,50,50,51,51
50,50,50,2,2,2,2,2,2,2,2,2,2,2,2,2,2,2,2,2,2,2,2,2,2,2,2,2,2,2,2,50,50,50,50,50,50,50,50,50,51
50,50,50,2,2,2,2,2,2,2,2,2,2,2,2,2,2,2,2,2,2,2,2,2,2,2,2,2,2,2,2,50,50,50,50,50,50,50,50,50,51
50,50,50,2,2,2,2,2,2,2,2,2,2,2,2,2,2,2,2,2,2,2,2,2,2,2,2,2,2,2,2,50,50,50,50,50,50,50,50,50,51
51,50,50,2,2,2,2,2,2,2,2,2,2,2,2,2,2,2,2,2,2,2,2,2,2,2,2,2,2,2,2,50,50,50,50,50,50,50,50,50,50
51,50,50,2,2,2,2,2,2,2,2,2,2,2,2,2,2,2,2,2,2,2,2,2,2,2,2,2,2,2,2,50,50,50,50,50,50,50,50,50,50
51,50,50,50,50,50,50,50,50,50,50,50,50,50,50,50,50,50,50,50,50,50,50,50,50,50,50,50,50,50,51,51,50,50,50,50,50,50,50,50,50
51,51,50,50,50,50,50,50,50,51,51,51,50,50,50,50,50,50,50,50,50,50,50,50,50,50,50,50,50,51,51,51,51,50,50,50,50,50,50,50,50
51,51,51,50,50,50,50,51,51,51,51,51,51,51,50,50,50,50,51,51,51,51,51,51,51,50,50,50,50,50,51,51,51,51,51,51,51,50,50,50,50
endlayer

layer
0,0,51,51,51,51,0,0,0,0,0,51,51,51,0,0,0,51,51,51,51,51,51,0,0,0,0,0,0,0,51,51,51,51,51,52,52,52,51,0,0
0,51,51,51,51,51,51,51,51,51,51,51,51,51,51,51,51,51,51,51,51,51,51,51,51,51,51,51,51,51,51,51,51,51,52,52,52,52,51,51,0
51,51,51,51,51,51,51,51,51,51,51,51,51,51,51,51,51,51,51,51,51,51,51,51,51,51,51,51,51,51,51,51,51,51,52,52,52,52,52,51,0
51,51,51,51,51,51,51,51,51,51,51,51,51,51,51,51,51,51,51,51,51,51,51,51,51,51,51,51,51,51,51,51,51,52,52,52,52,52,51,51,0
51,51,51,51,51,51,51,51,51,51,51,51,51,51,51,51,51,51,51,51,51,51,51,51,51,51,51,51,51,51,51,51,51,52,52,52,52,51,51,51,51
51,2,2,2,51,51,51,51,51,51,51,51,51,51,51,51,51,51,51,51,51,51,51,51,51,51,51,51,51,51,51,51,51,52,52,52,52,52,51,51,51
51,2,49,2,51,51,51,51,51,51,51,51,51,51,51,51,51,51,51,51,51,51,51,51,51,51,51,51,51,51,51,51,51,52,52,52,52,52,52,51,51
51,2,2,2,51,51,51,51,51,51,51,51,51,51,51,51,51,51,51,51,51,51,51,51,51,51,51,51,51,51,51,51,2,52,52,52,52,52,52,2,51
51,51,2,51,51,51,51,51,51,51,51,51,51,51,51,51,51,51,51,51,51,51,51,51,51,51,51,51,51,51,51,51,2,52,52,52,52,52,52,2,51
51,51,51,51,51,51,51,51,51,51,51,51,51,51,51,51,51,51,51,51,51,51,51,51,51,51,51,51,51,51,51,51,2,2,2,2,2,2,2,2,51
51,51,51,51,51,51,51,51,51,51,51,51,51,51,51,51,51,51,51,51,51,51,51,51,51,51,51,51,51,51,51,51,2,28,28,28,28,28,28,2,51
51,51,51,51,51,51,51,51,51,51,51,51,51,51,51,51,51,51,51,51,51,51,51,51,51,51,51,51,51,51,51,51,2,0,0,0,0,0,0,2,51
51,51,51,51,51,51,51,51,51,51,51,51,51,51,51,51,51,51,51,51,51,51,51,51,51,51,51,51,51,51,51,51,2,0,0,0,0,0,0,2,51
0,51,51,51,51,51,51,51,51,51,51,51,51,51,51,51,51,51,51,51,51,51,51,51,51,51,51,51,51,51,51,51,2,0,0,0,0,0,0,2,51
0,51,51,51,51,51,51,51,51,51,51,51,51,51,51,51,51,51,51,51,51,51,51,51,51,51,51,51,51,51,51,51,2,0,0,0,0,0,0,2,51
0,51,51,51,51,51,51,51,51,51,51,51,51,51,51,51,51,51,51,51,51,51,51,51,51,51,51,51,51,51,51,51,2,0,0,0,0,0,0,2,51
0,51,51,51,51,51,51,51,51,51,51,51,51,51,51,51,51,51,51,51,51,51,51,51,51,51,51,51,51,51,51,51,2,0,0,0,0,0,0,2,51
0,51,51,51,51,51,51,51,51,51,51,51,51,51,51,51,51,51,51,51,51,51,51,51,51,51,51,51,51,51,51,51,2,0,0,0,0,0,0,2,51
0,51,51,51,51,51,51,51,51,51,51,51,51,51,51,51,51,51,51,51,51,51,51,51,51,51,51,51,51,51,51,51,2,0,0,0,0,0,0,2,51
51,51,51,51,51,51,51,51,51,51,51,51,51,51,51,51,51,51,51,51,51,51,51,51,51,51,51,51,51,51,51,51,2,2,2,2,2,2,2,2,51
51,51,51,51,51,51,51,51,51,51,51,51,51,51,51,51,51,51,51,51,51,51,51,51,51,51,51,51,51,51,51,51,2,2,2,2,2,2,2,2,51
51,51,51,51,51,51,51,51,51,51,51,51,51,51,51,51,51,51,51,51,51,51,51,51,51,51,51,51,51,51,51,51,2,2,2,2,2,2,2,2,51
51,51,51,51,51,51,51,51,51,51,51,51,51,51,51,51,51,51,51,51,51,51,51,51,51,51,51,51,51,51,51,51,51,51,51,51,51,51,51,51,51
51,51,51,51,51,51,51,51,51,51,51,51,51,51,51,51,51,51,51,51,51,51,51,51,51,51,51,51,51,51,51,51,51,51,51,51,51,51,51,51,51
51,51,51,51,51,51,51,51,51,51,51,51,51,51,51,51,51,51,51,51,51,51,51,51,51,51,51,51,51,51,51,51,51,51,51,0,0,0,51,51,51
51,51,51,51,51,51,51,51,51,51,51,51,51,51,51,51,51,51,51,51,51,51,51,51,51,51,51,51,51,51,51,51,51,51,0,0,0,0,0,51,51
51,51,51,51,51,51,51,51,51,51,51,51,51,51,51,51,51,51,51,51,51,51,51,51,51,51,51,51,51,51,51,51,51,0,0,0,0,0,0,0,51
0,51,51,51,51,51,51,51,51,51,51,51,51,51,51,51,51,51,51,51,51,51,51,51,51,51,51,51,51,51,51,51,0,0,0,51,0,0,0,0,51
0,51,51,51,51,51,51,51,51,51,51,51,51,51,51,51,51,51,51,51,51,51,51,51,51,51,51,51,51,51,51,0,0,0,51,51,51,0,0,0,51
0,51,51,51,51,51,51,51,51,51,51,51,51,51,51,51,51,51,51,51,51,51,51,51,51,51,51,51,51,51,51,0,0,51,51,51,0,0,0,0,51
0,51,51,51,51,51,51,51,51,51,51,51,51,51,51,51,51,51,51,51,51,51,51,51,51,51,51,51,51,51,51,0,0,0,51,0,0,0,0,51,51
51,51,51,51,51,51,51,51,51,51,51,51,51,51,51,51,51,51,51,51,51,51,51,51,51,51,51,51,51,51,51,0,0,0,0,0,0,0,51,51,51
51,51,51,51,51,51,51,51,51,51,51,51,51,51,51,51,51,51,51,51,51,51,51,51,51,51,51,51,51,51,51,51,0,0,0,0,0,0,51,51,51
51,51,51,51,51,51,51,51,51,51,51,51,51,51,51,51,51,51,51,51,51,51,51,51,51,51,51,51,51,51,51,51,51,0,0,0,0,51,51,51,0
51,51,51,51,51,51,51,51,51,51,51,51,51,51,51,51,51,51,51,51,51,51,51,51,51,51,51,51,51,51,51,51,51,51,0,0,51,51,51,51,0
51,51,51,51,51,51,51,51,51,51,51,51,51,51,51,51,51,51,51,51,51,51,51,51,51,51,51,51,51,51,51,51,51,51,51,51,51,51,51,51,0
51,51,51,51,51,51,51,51,51,51,51,51,51,51,51,51,51,51,51,51,51,51,51,51,51,51,51,51,51,51,51,51,51,51,51,51,51,51,51,51,0
0,51,51,51,51,51,51,51,51,51,51,51,51,51,51,51,51,51,51,51,51,51,51,51,51,51,51,51,51,51,51,51,51,51,51,51,51,51,51,51,51
0,51,51,51,51,51,51,51,51,51,51,51,51,51,51,51,51,51,51,51,51,51,51,51,51,51,51,51,51,51,51,51,51,51,51,51,51,51,51,51,51
0,51,51,51,51,51,51,51,51,51,51,51,51,51,51,51,51,51,51,51,51,51,51,51,51,51,51,51,51,51,0,0,51,51,51,51,51,51,51,51,51
0,0,51,51,51,51,51,51,51,0,0,0,51,51,51,51,51,51,51,51,51,51,51,51,51,51,51,51,51,0,0,0,0,51,51,51,51,51,51,51,51
0,0,0,51,51,51,51,0,0,0,0,0,0,0,51,51,51,51,0,0,0,0,0,0,0,51,51,51,51,51,0,0,0,0,0,0,0,51,51,51,51
endlayer

layer
0,0,0,0,0,0,0,0,0,0,0,0,0,0,0,0,0,0,0,0,0,0,0,0,0,0,0,0,0,0,0,0,0,0,0,0,0,0,0,0,0
0,0,0,53,0,0,0,0,0,0,0,0,0,0,0,0,0,51,51,51,51,51,51,0,0,53,0,0,0,0,0,51,51,0,0,0,0,0,0,0,0
0,0,51,51,51,0,53,0,51,51,51,51,51,51,51,51,0,51,51,51,51,51,51,51,51,51,51,51,51,51,51,51,51,0,0,0,0,0,0,0,0
0,51,51,51,51,51,51,51,51,51,51,51,51,51,51,51,51,51,51,51,51,51,51,51,51,51,51,51,51,51,51,51,51,0,0,0,0,0,0,0,0
51,51,51,51,51,51,51,51,51,51,51,51,51,51,51,51,51,51,51,51,51,51,51,51,51,51,51,51,51,51,51,51,51,0,0,0,0,0,0,0,0
51,2,2,2,51,51,51,51,51,51,51,51,51,51,51,51,51,51,51,51,51,51,51,51,51,51,51,51,51,51,51,51,51,0,0,0,0,0,0,0,0
51,2,49,2,51,51,51,51,51,51,51,51,51,51,51,51,51,51,51,51,51,51,51,51,51,51,51,51,51,51,51,51,51,0,0,0,0,0,0,0,51
51,2,14,2,51,51,51,51,51,51,51,51,51,51,51,51,51,51,51,51,51,51,51,51,51,51,51,51,51,51,51,51,51,0,0,0,0,0,0,51,51
51,51,0,51,51,51,51,51,51,51,51,51,51,51,51,51,51,51,51,51,51,51,51,51,51,51,51,51,51,51,51,51,51,0,0,0,0,0,0,51,51
0,51,0,51,51,51,51,51,51,51,51,51,51,51,51,51,51,51,51,51,51,51,51,51,51,51,51,51,51,51,51,51,2,0,0,0,0,0,0,2,51
0,0,0,51,51,51,51,51,51,51,51,51,51,51,51,51,51,51,51,51,51,51,51,51,51,51,51,51,51,51,51,51,2,0,0,0,0,0,0,2,51
0,0,0,51,51,51,51,51,51,51,51,51,51,51,51,51,51,51,51,51,51,51,51,51,51,51,51,51,51,51,51,51,2,0,0,0,0,0,0,2,51
0,0,0,51,51,51,51,51,51,51,51,51,51,51,51,51,51,51,51,51,51,51,51,51,51,51,51,51,51,51,51,51,2,0,0,0,0,0,0,2,51
0,0,0,51,51,51,51,51,51,51,51,51,51,51,51,51,51,51,51,51,51,51,51,51,51,51,51,51,51,51,51,51,2,0,0,0,0,0,0,2,51
0,0,0,51,51,51,51,51,51,51,51,51,51,51,51,51,51,51,51,51,51,51,51,51,51,51,51,51,51,51,51,51,2,0,0,0,0,0,0,2,51
0,0,0,51,51,51,51,51,51,51,51,51,51,51,51,51,51,51,51,51,51,51,51,51,51,51,51,51,51,51,51,51,2,0,0,0,0,0,0,2,51
0,0,53,51,51,51,51,51,51,51,51,51,51,51,51,51,51,51,51,51,51,51,51,51,51,51,51,51,51,51,51,51,2,0,0,0,0,0,0,2,51
0,0,0,51,51,51,51,51,51,51,51,51,51,51,51,51,51,51,51,51,51,51,51,51,51,51,51,51,51,51,51,51,2,2,2,2,2,2,2,2,51
0,0,0,51,51,51,51,51,51,51,51,51,51,51,51,51,51,51,51,51,51,51,51,51,51,51,51,51,51,51,51,51,2,2,2,2,2,2,2,2,51
0,0,0,51,51,51,51,51,51,51,51,51,51,51,51,51,51,51,51,51,51,51,51,51,51,51,51,51,51,51,51,51,2,2,2,2,2,2,2,2,51
0,0,0,51,51,51,51,51,51,51,51,51,51,51,51,51,51,51,51,51,51,51,51,51,51,51,51,51,51,51,51,51,51,51,51,51,51,51,51,51,51
0,0,0,51,51,51,51,51,51,51,51,51,51,51,51,51,51,51,51,51,51,51,51,51,51,51,51,51,51,51,51,51,51,51,51,51,51,51,51,51,51
0,0,0,51,51,51,51,51,51,51,51,51,51,51,51,51,51,51,51,51,51,51,51,51,51,51,51,51,51,51,51,51,51,51,51,51,51,51,51,51,51
0,0,0,51,51,51,51,51,51,51,51,51,51,51,51,51,51,51,51,51,51,51,51,51,51,51,51,51,51,51,51,51,51,51,0,0,0,0,0,0,0
0,0,0,51,51,51,51,51,51,51,51,51,51,51,51,51,51,51,51,51,51,51,51,51,51,51,51,51,51,51,51,51,51,0,0,0,0,0,0,0,0
0,53,0,0,51,51,51,51,51,51,51,51,51,51,51,51,51,51,51,51,51,51,51,51,51,51,51,51,51,51,51,51,0,0,0,0,0,0,0,0,0
0,0,0,0,51,51,51,51,51,51,51,51,51,51,51,51,51,51,51,51,51,51,51,51,51,51,51,51,51,51,51,0,0,0,0,0,0,0,0,0,0
0,0,0,0,51,51,51,51,51,51,51,51,51,51,51,51,51,51,51,51,51,51,51,51,51,51,51,51,51,51,0,0,0,0,0,0,0,0,0,0,0
0,0,0,0,51,51,51,51,51,51,51,51,51,51,51,51,51,51,51,51,51,51,51,51,51,51,51,51,51,51,0,0,0,0,0,53,0,0,0,0,0
0,0,0,0,51,51,51,51,51,51,51,51,51,51,51,51,51,51,51,51,51,51,51,51,51,51,51,51,51,51,0,0,0,0,0,0,0,0,0,0,0
0,0,0,0,51,51,51,51,51,51,51,51,51,51,51,51,51,51,51,51,51,51,51,51,51,51,51,51,51,51,0,0,0,0,0,0,0,0,0,0,0
0,53,0,0,51,51,51,51,51,51,51,51,51,51,51,51,51,51,51,51,51,51,51,51,51,51,51,51,51,51,0,0,0,0,0,0,0,0,0,0,0
0,0,0,0,51,51,51,51,51,51,51,51,51,51,51,51,51,51,51,51,51,51,51,51,51,51,51,51,51,51,0,0,0,0,0,0,0,0,0,0,0
0,0,0,0,51,51,51,51,51,51,51,51,51,51,51,51,51,51,51,51,51,51,51,51,51,51,51,51,51,51,0,0,0,0,0,0,0,0,0,0,0
0,0,0,0,51,51,51,51,51,51,51,51,51,51,51,51,51,51,51,51,51,51,51,51,51,51,51,51,51,51,0,0,0,0,0,0,0,0,0,0,0
0,0,0,51,51,51,51,51,51,51,51,51,51,51,51,51,51,51,51,51,51,51,51,51,51,51,51,51,51,51,0,0,0,0,0,0,0,0,0,0,0
0,0,0,51,51,51,51,51,51,51,51,51,51,51,51,51,51,51,51,51,51,51,51,51,51,51,51,51,51,0,0,0,0,0,53,0,51,51,0,53,0
0,0,0,51,51,51,51,51,51,51,51,51,51,51,51,51,51,51,51,51,51,51,51,51,51,51,51,51,0,0,0,0,0,0,0,51,51,51,51,0,0
0,0,0,51,51,51,51,0,0,0,0,0,0,0,0,0,0,51,51,51,51,51,51,51,51,0,0,0,0,0,0,0,0,0,0,0,51,51,0,0,0
0,0,0,0,0,0,0,0,0,0,0,0,0,53,0,0,0,0,0,0,0,0,0,0,0,0,0,0,0,53,0,0,0,0,0,0,0,0,0,0,0
0,0,0,0,53,0,0,0,0,0,0,0,0,0,0,0,0,0,0,0,0,0,0,0,0,0,0,0,0,0,0,0,0,0,0,0,0,53,0,0,0
0,0,0,0,0,0,0,0,0,0,0,0,0,0,0,0,0,0,0,0,0,0,0,0,0,0,0,0,0,0,0,0,0,0,0,0,0,0,0,0,0
endlayer

layer
0,0,0,0,0,0,0,0,0,0,0,0,0,0,0,0,0,0,0,0,0,0,0,0,0,0,0,0,0,0,0,0,0,0,0,0,0,0,0,0,0
0,0,0,0,0,0,0,0,0,0,0,0,0,0,0,0,0,0,0,0,0,0,0,0,0,0,0,0,0,0,0,0,0,0,0,0,0,0,0,0,0
0,0,0,0,0,0,0,0,0,0,0,0,0,0,0,0,0,51,51,51,51,51,0,0,0,0,0,0,0,0,0,0,51,0,0,0,0,0,0,0,0
0,0,51,51,51,0,0,0,0,0,51,51,51,51,51,51,51,51,51,51,51,51,51,51,51,51,51,51,51,51,51,51,51,0,0,0,0,0,0,0,0
0,51,51,51,51,51,51,0,51,51,51,51,51,51,51,51,51,51,51,51,51,51,51,51,51,51,51,51,51,51,51,51,51,0,0,0,0,0,0,0,0
51,2,2,2,51,51,51,51,51,51,51,51,51,51,51,51,51,51,51,51,51,51,51,51,51,51,51,51,51,51,51,51,51,0,0,0,0,0,0,0,0
51,2,49,2,51,51,51,51,51,51,51,51,51,51,51,51,51,51,51,51,51,51,51,51,51,51,51,51,51,51,51,51,51,0,0,0,0,0,0,0,0
51,2,38,2,51,51,51,51,51,51,51,51,51,51,51,51,51,51,51,51,51,51,51,51,51,51,51,51,51,51,51,51,0,0,0,0,0,0,0,0,51
0,51,0,51,51,51,51,51,51,51,51,51,51,51,51,51,51,51,51,51,51,51,51,51,51,51,51,51,51,51,51,51,0,0,0,0,0,0,0,51,51
0,0,0,0,51,51,51,51,51,51,51,51,51,51,51,51,51,51,51,51,51,51,51,51,51,51,51,51,51,51,51,51,51,0,0,0,0,0,0,51,51
0,0,0,0,51,51,51,51,51,51,51,51,51,51,51,51,51,51,51,51,51,51,51,51,51,51,51,51,51,51,51,51,51,0,0,0,0,0,0,51,51
0,0,0,0,51,51,51,51,51,51,51,51,51,51,51,51,51,51,51,51,51,51,51,51,51,51,51,51,51,51,51,51,2,0,0,0,0,0,0,2,51
0,0,0,0,0,51,51,51,51,51,51,51,51,51,51,51,51,51,51,51,51,51,51,51,51,51,51,51,51,51,51,51,2,0,0,0,0,0,0,2,51
0,0,0,0,0,51,51,51,51,51,51,51,51,51,51,51,51,51,51,51,51,51,51,51,51,51,51,51,51,51,51,51,2,0,0,0,0,0,0,2,51
0,0,0,0,51,51,51,51,51,51,51,51,51,51,51,51,51,51,51,51,51,51,51,51,51,51,51,51,51,51,51,51,2,0,0,0,0,0,0,2,51
0,0,0,0,51,51,51,51,51,51,51,51,51,51,51,51,51,51,51,51,51,51,51,51,51,51,51,51,51,51,51,51,2,2,2,2,2,2,2,2,51
0,0,0,0,51,51,51,51,51,51,51,51,51,51,51,51,51,51,51,51,51,51,51,51,51,51,51,51,51,51,51,51,2,2,2,2,2,2,2,2,51
0,0,0,0,51,51,51,51,51,51,51,51,51,51,51,51,51,51,51,51,51,51,51,51,51,51,51,51,51,51,51,51,2,2,2,2,2,2,2,2,51
0,0,0,0,51,51,51,51,51,51,51,51,51,51,51,51,51,51,51,51,51,51,51,51,51,51,51,51,51,51,51,51,51,51,51,51,51,51,51,51,51
0,0,0,0,51,51,51,51,51,51,51,51,51,51,51,51,51,51,51,51,51,51,51,51,51,51,51,51,51,51,51,51,51,51,51,51,51,51,51,51,51
0,0,0,0,51,51,51,51,51,51,51,51,51,51,51,51,51,51,51,51,51,51,51,51,51,51,51,51,51,51,51,51,51,0,0,0,0,53,0,0,0
0,0,0,0,51,51,51,51,51,51,51,51,51,51,51,51,51,51,51,51,51,51,51,51,51,51,51,51,51,51,51,51,0,0,0,0,0,0,0,0,0
0,0,0,0,51,51,51,51,51,51,51,51,51,51,51,51,51,51,51,51,51,51,51,51,51,51,51,51,51,51,0,0,0,0,0,0,0,0,0,0,0
0,0,0,0,51,51,51,51,51,51,51,51,51,51,51,51,51,51,51,51,51,51,51,51,51,51,51,51,51,51,0,0,0,0,0,0,0,0,0,0,0
0,0,0,0,0,51,51,51,51,51,51,51,51,51,51,51,51,51,51,51,51,51,51,51,51,51,51,51,51,0,0,0,0,0,0,0,0,0,0,0,0
0,0,0,0,0,51,51,51,51,51,51,51,51,51,51,51,51,51,51,51,51,51,51,51,51,51,51,51,51,0,0,0,0,0,0,0,0,0,0,0,0
0,0,0,0,0,51,51,51,51,51,51,51,51,51,51,51,51,51,51,51,51,51,51,51,51,51,51,51,51,0,0,0,0,0,0,0,0,0,0,0,0
0,0,0,0,0,0,0,51,51,51,51,51,51,51,51,51,51,51,51,51,51,51,51,51,51,51,51,51,51,0,0,0,0,0,0,0,0,0,0,0,0
0,0,0,0,0,0,0,51,51,51,51,51,51,51,51,51,51,51,51,51,51,51,51,51,51,51,51,51,51,0,0,0,0,0,0,0,0,0,0,0,0
0,0,0,0,0,51,51,51,51,51,51,51,51,51,51,51,51,51,51,51,51,51,51,51,51,51,51,51,51,0,0,0,0,0,0,0,0,0,0,0,0
0,0,0,0,0,51,51,51,51,51,51,51,51,51,51,51,51,51,51,51,51,51,51,51,51,51,51,51,51,0,0,0,0,0,0,0,0,0,0,0,0
0,0,0,0,0,51,51,51,51,51,51,51,51,51,51,51,51,51,51,51,51,51,51,51,51,51,51,51,51,0,0,0,0,0,0,0,0,0,0,0,0
0,0,0,0,0,51,51,51,51,51,51,51,51,51,51,51,51,51,51,51,51,51,51,51,51,51,51,51,51,0,0,0,0,0,0,0,0,0,0,0,0
0,0,0,0,0,51,51,51,51,51,51,51,51,51,51,51,51,51,51,51,51,51,51,51,51,51,51,51,51,0,0,0,0,0,0,0,0,0,0,0,0
0,0,0,0,0,51,51,51,51,51,51,51,51,51,51,51,51,51,51,51,51,51,51,51,51,51,51,51,51,0,0,0,0,0,0,0,0,0,0,0,0
0,0,0,0,0,51,51,51,51,51,51,51,51,51,51,51,51,51,51,51,51,51,51,51,51,51,51,51,0,0,0,0,0,0,0,0,0,0,0,0,0
0,0,0,0,51,51,51,51,51,51,51,51,51,51,51,51,51,51,51,51,51,51,51,51,51,51,51,0,0,0,0,0,0,0,0,0,0,0,0,0,0
0,0,0,0,51,51,0,0,0,0,0,0,0,0,0,0,0,0,51,51,51,51,51,51,0,0,0,53,0,0,0,0,0,0,0,0,51,51,0,0,0
0,0,0,0,0,0,0,0,0,0,0,0,0,0,0,0,0,0,0,0,0,0,0,0,0,0,0,0,0,0,0,0,0,0,0,0,0,0,0,0,0
0,0,0,0,0,0,0,0,0,0,0,0,0,0,0,0,0,0,0,0,0,0,0,0,0,0,0,0,0,0,0,0,0,0,0,0,0,0,0,0,0
0,0,0,0,0,0,0,0,0,0,0,0,0,0,0,0,0,0,0,0,0,0,0,0,0,0,0,0,0,0,0,0,0,0,0,0,0,0,0,0,0
0,0,0,0,0,0,0,0,0,0,0,0,0,0,0,0,0,0,0,0,0,0,0,0,0,0,0,0,0,0,0,0,0,0,0,0,0,0,0,0,0
endlayer

layer
0,0,0,0,0,0,0,0,0,0,0,0,0,0,0,0,0,0,0,0,0,0,0,0,0,0,0,0,0,0,0,0,0,0,0,0,0,0,0,0,0
0,0,0,0,0,0,0,0,0,0,0,0,0,0,0,0,0,0,0,0,0,0,0,0,0,0,0,0,0,0,0,0,0,0,0,0,0,0,0,0,0
0,0,0,0,0,0,0,0,0,0,0,0,0,0,0,0,0,0,0,0,0,0,0,0,0,0,0,0,0,0,0,0,0,0,0,0,0,0,0,0,0
0,0,0,0,0,0,0,0,0,0,53,0,0,0,0,0,0,0,51,51,51,0,0,0,0,0,0,0,0,0,0,0,0,0,0,0,0,0,0,0,0
0,0,0,0,51,0,0,0,0,0,0,0,0,0,0,51,51,51,51,51,51,51,51,51,0,0,0,53,0,0,0,0,0,0,0,0,0,0,0,0,0
51,2,2,2,51,0,0,0,0,0,0,0,0,0,0,0,51,51,51,51,51,51,51,51,51,51,0,0,0,0,0,0,0,0,0,0,0,0,0,0,0
51,2,2,2,51,0,0,51,51,51,0,0,0,0,0,0,0,51,51,51,51,51,51,51,51,0,0,0,0,0,0,0,0,0,0,0,0,0,0,0,0
51,2,2,2,51,0,51,51,51,51,51,0,0,0,53,0,0,0,51,51,51,51,51,51,0,0,0,0,0,53,0,0,0,0,0,0,0,0,0,0,0
0,51,2,51,0,0,51,51,51,51,51,0,0,0,0,0,0,0,0,51,51,51,51,0,0,0,0,0,0,0,0,0,0,0,0,0,0,0,0,0,0
0,0,0,0,0,0,51,51,51,51,51,0,0,0,0,0,0,0,0,0,0,0,0,0,0,51,0,0,0,0,51,51,0,0,0,0,0,0,0,0,0
0,0,0,0,0,0,51,51,51,51,51,0,0,0,0,0,0,53,0,0,0,0,0,0,51,51,51,53,0,51,51,51,0,0,0,0,0,0,0,0,0
0,0,0,0,0,0,0,51,51,51,0,0,0,0,0,0,0,0,0,0,0,0,0,0,51,51,0,0,0,51,51,51,51,0,0,0,0,0,0,51,0
0,0,0,0,0,0,0,0,0,0,0,0,0,51,51,51,51,51,51,51,51,0,0,0,51,0,0,0,0,51,51,51,51,0,0,0,0,0,0,51,0
0,0,0,0,0,53,0,0,0,0,0,51,51,51,51,51,51,51,51,51,51,51,51,0,0,0,0,0,0,51,51,51,51,0,0,0,0,0,0,51,51
0,0,0,0,0,0,0,0,0,51,51,51,51,51,51,51,51,51,51,51,51,51,51,51,0,0,0,0,0,0,51,51,51,0,0,0,0,0,0,51,51
0,0,0,0,0,0,0,0,51,51,51,51,51,51,51,51,51,51,51,51,51,51,51,51,0,0,0,53,0,0,0,51,51,51,51,51,51,51,51,51,51
0,0,0,0,0,0,0,51,51,51,51,51,51,51,51,51,51,51,51,51,51,51,51,51,0,0,0,0,0,0,0,51,51,51,51,51,51,51,51,51,51
0,0,0,0,0,0,0,51,51,51,51,51,51,51,51,51,51,51,51,51,51,51,51,51,51,0,0,0,0,0,0,51,51,51,51,51,51,51,51,51,0
0,0,0,0,0,0,51,51,51,51,51,51,51,51,51,51,51,51,51,51,51,51,51,51,51,0,0,0,0,0,0,0,51,51,51,51,51,51,51,51,0
0,0,0,0,0,51,51,51,51,51,51,51,51,51,51,51,51,51,51,51,51,51,51,51,51,0,0,0,53,0,0,53,0,0,0,0,0,0,0,0,0
0,0,0,0,0,51,51,51,51,51,51,51,51,51,51,51,51,51,51,51,51,51,51,51,51,51,0,0,0,0,0,0,0,0,0,0,0,0,0,0,0
0,0,0,0,0,51,51,51,51,51,51,51,51,51,51,51,51,51,51,51,51,51,51,51,51,51,0,0,0,0,0,0,0,0,0,0,0,0,0,0,0
0,0,0,0,0,51,51,51,51,51,51,51,51,51,51,51,51,51,51,51,51,51,51,51,51,51,0,0,0,0,0,0,0,0,0,0,0,0,0,0,0
0,0,0,0,0,0,51,51,51,51,51,51,51,51,51,51,51,51,51,51,51,51,51,51,51,51,0,0,0,0,0,0,0,0,0,0,0,0,0,0,0
0,0,0,0,0,0,51,51,51,51,51,51,51,51,51,51,51,51,51,51,51,51,51,51,51,51,51,0,0,0,0,0,0,0,0,0,0,0,0,0,0
0,0,0,0,0,0,51,51,51,51,51,51,51,51,51,51,51,51,51,51,51,51,51,51,51,51,51,0,0,0,0,0,0,0,0,0,0,0,0,0,0
0,0,0,0,0,0,0,51,51,51,51,51,51,51,51,51,51,51,51,51,51,51,51,51,51,51,51,0,0,0,0,0,0,0,0,0,0,0,0,0,0
0,0,0,0,0,0,0,0,51,51,51,51,51,51,51,51,51,51,51,51,51,51,51,51,51,51,51,0,0,0,0,0,0,0,0,0,0,0,0,0,0
0,0,0,0,0,0,0,0,51,51,51,51,51,51,51,51,51,51,51,51,51,51,51,51,51,51,51,0,0,0,0,0,0,0,0,0,0,0,0,0,0
0,0,0,0,0,0,0,0,51,51,51,51,51,51,51,51,51,51,51,51,51,51,51,51,51,51,51,0,0,0,0,0,0,0,0,0,0,0,0,0,0
0,0,0,0,0,0,0,0,51,51,51,51,51,51,51,51,51,51,51,51,51,51,51,51,51,51,51,0,0,0,0,0,0,0,0,0,0,0,0,0,0
0,0,0,0,0,0,0,0,51,51,51,51,51,51,51,51,51,51,51,51,51,51,51,51,51,51,51,0,0,0,0,0,0,0,0,0,0,0,0,0,0
0,0,0,0,0,0,0,0,0,51,51,51,51,51,51,51,51,51,51,51,51,51,51,51,51,51,51,0,0,0,0,0,0,0,0,0,0,0,0,0,0
0,0,0,0,0,0,0,0,0,0,51,51,51,51,51,51,51,51,51,51,51,51,51,51,51,51,51,0,0,0,0,0,0,0,0,0,0,0,0,0,0
0,0,0,0,0,0,0,0,0,0,0,51,51,51,51,51,51,51,51,51,51,51,51,51,51,51,0,0,0,0,0,0,0,0,0,0,0,0,0,0,0
0,0,0,0,0,0,0,53,0,0,0,0,0,53,0,51,51,51,51,51,51,51,51,51,51,51,0,0,0,0,0,0,0,0,0,0,0,0,0,0,0
0,0,0,0,0,0,0,0,0,0,0,0,0,0,0,0,0,0,0,51,51,51,51,0,0,0,0,0,0,0,0,0,0,0,0,0,0,0,0,0,0
0,0,0,0,0,0,0,0,0,0,0,0,0,0,0,0,0,0,0,0,0,0,0,0,0,0,0,0,0,0,0,0,0,0,0,0,0,0,0,0,0
0,0,0,0,0,0,0,0,0,0,0,0,0,0,0,0,0,0,0,0,0,0,0,0,0,0,0,0,0,0,0,0,0,0,0,0,0,0,0,0,0
0,0,0,0,0,0,0,0,0,0,0,0,0,0,0,0,0,0,0,0,0,0,0,0,0,0,0,0,0,0,0,0,0,0,0,0,0,0,0,0,0
0,0,0,0,0,0,0,0,0,0,0,0,0,0,0,0,0,0,0,0,0,0,0,0,0,0,0,0,0,0,0,0,0,0,0,0,0,0,0,0,0
0,0,0,0,0,0,0,0,0,0,0,0,0,0,0,0,0,0,0,0,0,0,0,0,0,0,0,0,0,0,0,0,0,0,0,0,0,0,0,0,0
endlayer

layer
0,0,0,0,0,0,0,0,0,0,0,0,0,0,0,0,0,0,0,0,0,0,0,0,0,0,0,0,0,0,0,0,0,0,0,0,0,0,0,0,0
0,0,0,0,0,0,0,0,0,0,0,0,0,0,0,0,0,0,0,0,0,0,0,0,0,0,0,0,0,0,0,0,0,0,0,0,0,0,0,0,0
0,0,0,0,0,0,0,0,0,0,0,0,0,0,0,0,0,0,0,0,0,0,0,0,0,0,0,0,0,0,0,0,0,0,0,0,0,0,0,0,0
0,0,0,0,0,0,0,0,0,0,0,0,0,0,0,0,0,0,0,0,0,0,0,0,0,0,0,0,0,0,0,0,0,0,0,0,0,0,0,0,0
0,0,0,0,0,0,0,0,0,0,0,0,0,0,0,0,53,0,0,51,0,0,0,0,0,0,0,0,0,0,0,0,0,0,0,0,0,0,0,0,0
0,51,51,51,0,0,0,0,0,0,0,0,0,0,0,0,0,0,51,51,51,51,0,0,0,0,0,0,0,0,0,0,0,0,0,0,0,0,0,0,0
0,51,51,51,0,0,0,0,0,0,0,0,0,0,0,0,0,0,0,51,51,51,51,0,0,0,0,0,0,0,0,0,0,0,0,0,0,0,0,0,0
0,51,51,51,0,0,0,0,51,0,0,0,0,0,0,0,0,0,0,0,51,51,0,0,0,0,0,0,0,0,0,0,0,0,0,0,0,0,0,0,0
0,0,51,0,0,0,0,51,51,51,0,0,0,0,0,0,0,0,0,0,0,0,0,0,0,0,0,0,0,0,0,0,0,0,0,0,0,0,0,0,0
0,0,0,0,0,0,0,51,51,51,0,0,0,0,0,0,0,0,0,0,0,0,0,0,0,0,0,0,0,0,0,0,0,0,0,0,0,0,0,0,0
0,0,0,0,0,0,0,0,51,0,0,0,0,0,0,0,0,0,0,0,0,0,0,0,0,0,0,0,0,0,0,51,0,0,0,0,0,0,0,0,0
0,0,0,0,0,0,0,0,0,0,0,0,0,0,0,0,0,0,0,0,0,0,0,0,0,0,0,0,0,0,51,51,0,0,0,0,0,0,0,0,0
0,0,0,0,0,0,0,0,0,0,0,0,0,0,0,0,0,0,0,0,0,0,0,0,0,0,0,0,0,0,51,51,0,0,0,0,0,0,0,0,0
0,0,0,0,0,0,0,0,0,0,0,0,0,0,0,0,0,0,0,0,0,0,0,0,0,0,0,0,0,0,0,51,0,0,0,0,0,0,0,0,0
0,0,0,0,0,0,0,0,0,0,0,0,0,0,51,51,51,51,51,51,0,0,0,0,0,0,0,0,0,0,0,0,0,0,0,0,0,0,0,0,0
0,0,0,0,0,0,0,0,0,0,0,0,51,51,51,51,51,51,51,51,51,51,0,0,0,0,0,0,0,0,0,0,51,51,51,51,51,51,51,51,0
0,0,0,0,0,0,0,0,0,51,51,51,51,51,51,51,51,51,51,51,51,51,0,0,0,0,0,0,0,0,0,0,51,51,51,51,51,51,51,51,0
0,0,0,0,0,0,0,0,51,51,51,51,51,51,51,51,51,51,51,51,51,51,51,0,0,0,0,0,0,0,0,0,0,51,51,51,51,51,51,0,0
0,0,0,0,0,0,0,0,51,51,51,51,51,51,51,51,51,51,51,51,51,51,51,0,0,0,0,0,0,0,0,0,0,0,0,0,0,0,0,0,0
0,0,0,0,0,0,0,51,51,51,51,51,51,51,51,51,51,51,51,51,51,51,51,0,0,0,0,0,0,0,0,0,0,0,0,0,0,0,0,0,0
0,0,0,0,0,0,0,51,51,51,51,51,51,51,51,51,51,51,51,51,51,51,51,0,0,0,0,0,0,0,0,0,0,0,0,0,0,0,0,0,0
0,0,0,0,0,0,0,51,51,51,51,51,51,51,51,51,51,51,51,51,51,51,51,51,0,0,0,0,0,0,0,0,0,0,0,0,0,0,0,0,0
0,0,0,0,0,0,0,51,51,51,51,51,51,51,51,51,51,51,51,51,51,51,51,51,0,0,0,0,0,0,0,0,0,0,0,0,0,0,0,0,0
0,0,0,0,0,0,0,0,51,51,51,51,51,51,51,51,51,51,51,51,51,51,51,51,0,0,0,0,0,0,0,0,0,0,0,0,0,0,0,0,0
0,0,0,0,0,0,0,0,51,51,51,51,51,51,51,51,51,51,51,51,51,51,51,51,51,0,0,0,0,0,0,0,0,0,0,0,0,0,0,0,0
0,0,0,0,0,0,0,0,51,51,51,51,51,51,51,51,51,51,51,51,51,51,51,51,51,0,0,0,0,0,0,0,0,0,0,0,0,0,0,0,0
0,0,0,0,0,0,0,0,0,51,51,51,51,51,51,51,51,51,51,51,51,51,51,51,51,0,0,0,0,0,0,0,0,0,0,0,0,0,0,0,0
0,0,0,0,0,0,0,0,0,51,51,51,51,51,51,51,51,51,51,51,51,51,51,51,51,0,0,0,0,0,0,0,0,0,0,0,0,0,0,0,0
0,0,0,0,0,0,0,0,0,51,51,51,51,51,51,51,51,51,51,51,51,51,51,51,51,0,0,0,0,0,0,0,0,0,0,0,0,0,0,0,0
0,0,0,0,0,0,0,0,0,51,51,51,51,51,51,51,51,51,51,51,51,51,51,51,51,0,0,0,0,0,0,0,0,0,0,0,0,0,0,0,0
0,0,0,0,0,0,0,0,0,51,51,51,51,51,51,51,51,51,51,51,51,51,51,51,51,0,0,0,0,0,0,0,0,0,0,0,0,0,0,0,0
0,0,0,0,0,0,0,0,0,0,51,51,51,51,51,51,51,51,51,51,51,51,51,51,51,0,0,0,0,0,0,0,0,0,0,0,0,0,0,0,0
0,0,0,0,0,0,0,0,0,0,0,51,51,51,51,51,51,51,51,51,51,51,51,51,51,0,0,0,0,0,0,0,0,0,0,0,0,0,0,0,0
0,0,0,0,0,0,0,0,0,0,0,0,51,51,51,51,51,51,51,51,51,51,51,51,51,0,0,0,0,0,0,0,0,0,0,0,0,0,0,0,0
0,0,0,0,0,0,0,0,0,0,0,0,0,0,0,0,51,51,51,51,51,51,51,51,0,0,0,0,0,0,0,0,0,0,0,0,0,0,0,0,0
0,0,0,0,0,0,0,0,0,0,0,0,0,0,0,0,0,0,0,0,51,51,0,0,0,0,0,0,0,0,0,0,0,0,0,0,0,0,0,0,0
0,0,0,0,0,0,0,0,0,0,0,0,0,0,0,0,0,0,0,0,0,0,0,0,0,0,0,0,0,0,0,0,0,0,0,0,0,0,0,0,0
0,0,0,0,0,0,0,0,0,0,0,0,0,0,0,0,0,0,0,0,0,0,0,0,0,0,0,0,0,0,0,0,0,0,0,0,0,0,0,0,0
0,0,0,0,0,0,0,0,0,0,0,0,0,0,0,0,0,0,0,0,0,0,0,0,0,0,0,0,0,0,0,0,0,0,0,0,0,0,0,0,0
0,0,0,0,0,0,0,0,0,0,0,0,0,0,0,0,0,0,0,0,0,0,0,0,0,0,0,0,0,0,0,0,0,0,0,0,0,0,0,0,0
0,0,0,0,0,0,0,0,0,0,0,0,0,0,0,0,0,0,0,0,0,0,0,0,0,0,0,0,0,0,0,0,0,0,0,0,0,0,0,0,0
0,0,0,0,0,0,0,0,0,0,0,0,0,0,0,0,0,0,0,0,0,0,0,0,0,0,0,0,0,0,0,0,0,0,0,0,0,0,0,0,0
endlayer

layer
0,0,0,0,0,0,0,0,0,0,0,0,0,0,0,0,0,0,0,0,0,0,0,0,0,0,0,0,0,0,0,0,0,0,0,0,0,0,0,0,0
0,0,0,0,0,0,0,0,0,0,0,0,0,0,0,0,0,0,0,0,0,0,0,0,0,0,0,0,0,0,0,0,0,0,0,0,0,0,0,0,0
0,0,0,0,0,0,0,0,0,0,0,0,0,0,0,0,0,0,0,0,0,0,0,0,0,0,0,0,0,0,0,0,0,0,0,0,0,0,0,0,0
0,0,0,0,0,0,0,0,0,0,0,0,0,0,0,0,0,0,0,0,0,0,0,0,0,0,0,0,0,0,0,0,0,0,0,0,0,0,0,0,0
0,0,0,0,0,0,0,0,0,0,0,0,0,0,0,0,0,0,0,0,0,0,0,0,0,0,0,0,0,0,0,0,0,0,0,0,0,0,0,0,0
0,0,0,0,0,0,0,0,0,0,0,0,0,0,0,0,0,0,0,0,0,0,0,0,0,0,0,0,0,0,0,0,0,0,0,0,0,0,0,0,0
0,0,0,0,0,0,0,0,0,0,0,0,0,0,0,0,0,0,0,0,53,0,0,0,0,0,0,0,0,0,0,0,0,0,0,0,0,0,0,0,0
0,0,0,0,0,0,0,0,0,0,0,0,0,0,0,0,0,0,0,0,0,0,0,0,0,0,0,0,0,0,0,0,0,0,0,0,0,0,0,0,0
0,0,0,0,0,0,0,0,0,0,0,0,0,0,0,0,0,0,0,0,0,0,0,0,0,0,0,0,0,0,0,0,0,0,0,0,0,0,0,0,0
0,0,0,0,0,0,0,0,0,53,0,0,0,0,0,0,0,0,0,0,0,0,0,0,0,0,0,0,0,0,0,0,0,0,0,0,0,0,0,0,0
0,0,0,0,0,0,0,0,0,0,0,0,0,0,0,0,0,0,0,0,0,0,0,0,0,0,0,0,0,0,0,0,0,0,0,0,0,0,0,0,0
0,0,0,0,0,0,0,0,0,0,0,0,0,0,0,0,0,0,0,0,0,0,0,0,0,0,0,0,0,0,0,0,0,0,0,0,0,0,0,0,0
0,0,0,0,0,0,0,0,0,0,0,0,0,0,0,0,0,0,0,0,0,0,0,0,0,0,0,0,0,0,0,53,0,0,0,0,0,0,0,0,0
0,0,0,0,0,0,0,0,0,0,0,0,0,0,0,0,0,0,0,0,0,0,0,0,0,0,0,0,0,0,0,0,0,0,0,0,0,0,0,0,0
0,0,0,0,0,0,0,0,0,0,0,0,0,0,0,0,0,0,0,0,0,0,0,0,0,0,0,0,0,0,0,0,0,0,0,0,0,0,0,0,0
0,0,0,0,0,0,0,0,0,0,0,0,0,0,0,0,0,0,0,0,0,0,0,0,0,0,0,0,0,0,0,0,0,0,0,0,0,0,0,0,0
0,0,0,0,0,0,0,0,0,0,0,0,0,0,0,0,0,0,0,0,0,0,0,0,0,0,0,0,0,0,0,0,0,0,0,0,0,0,0,0,0
0,0,0,0,0,0,0,0,0,0,0,0,0,0,0,53,0,0,0,0,0,0,0,0,0,0,0,0,0,0,0,0,0,0,0,0,0,0,0,0,0
0,0,0,0,0,0,0,0,0,0,53,0,0,0,0,0,0,0,0,0,0,0,0,0,0,0,0,0,0,0,0,0,0,0,0,0,0,0,0,0,0
0,0,0,0,0,0,0,0,0,0,0,0,0,0,0,0,0,0,0,53,0,0,0,0,0,0,0,0,0,0,0,0,0,0,0,0,0,0,0,0,0
0,0,0,0,0,0,0,0,0,0,0,0,0,0,0,51,51,51,51,0,0,0,0,0,0,0,0,0,0,0,0,0,0,0,0,0,0,0,0,0,0
0,0,0,0,0,0,0,0,0,0,0,0,0,0,51,51,51,51,51,51,0,0,0,0,0,0,0,0,0,0,0,0,0,0,0,0,0,0,0,0,0
0,0,0,0,0,0,0,0,0,0,0,53,0,51,51,51,51,51,51,51,51,0,0,0,0,0,0,0,0,0,0,0,0,0,0,0,0,0,0,0,0
0,0,0,0,0,0,0,0,0,0,0,0,0,51,51,51,51,51,51,51,51,0,0,0,0,0,0,0,0,0,0,0,0,0,0,0,0,0,0,0,0
0,0,0,0,0,0,0,0,0,0,0,0,0,0,51,51,51,51,51,51,51,0,0,0,0,0,0,0,0,0,0,0,0,0,0,0,0,0,0,0,0
0,0,0,0,0,0,0,0,0,0,0,0,0,0,51,51,51,51,51,51,0,0,0,0,0,0,0,0,0,0,0,0,0,0,0,0,0,0,0,0,0
0,0,0,0,0,0,0,0,0,0,0,0,0,0,0,51,51,51,51,51,0,0,53,0,0,0,0,0,0,0,0,0,0,0,0,0,0,0,0,0,0
0,0,0,0,0,0,0,0,0,0,0,0,0,53,0,0,51,51,51,51,51,0,0,0,0,0,0,0,0,0,0,0,0,0,0,0,0,0,0,0,0
0,0,0,0,0,0,0,0,0,0,0,0,0,0,0,0,0,51,51,51,51,0,0,0,0,0,0,0,0,0,0,0,0,0,0,0,0,0,0,0,0
0,0,0,0,0,0,0,0,0,0,0,0,0,0,0,0,0,51,51,51,51,0,0,0,0,0,0,0,0,0,0,0,0,0,0,0,0,0,0,0,0
0,0,0,0,0,0,0,0,0,0,0,0,0,0,0,0,0,0,51,51,0,0,0,0,0,0,0,0,0,0,0,0,0,0,0,0,0,0,0,0,0
0,0,0,0,0,0,0,0,0,0,0,0,0,0,0,0,0,0,0,0,0,0,0,53,0,0,0,0,0,0,0,0,0,0,0,0,0,0,0,0,0
0,0,0,0,0,0,0,0,0,0,0,0,0,0,53,0,0,0,0,0,0,0,0,0,0,0,0,0,0,0,0,0,0,0,0,0,0,0,0,0,0
0,0,0,0,0,0,0,0,0,0,0,0,0,0,0,0,0,0,0,0,0,0,0,0,0,0,0,0,0,0,0,0,0,0,0,0,0,0,0,0,0
0,0,0,0,0,0,0,0,0,0,0,0,0,0,0,0,0,0,0,0,0,0,0,0,0,0,0,0,0,0,0,0,0,0,0,0,0,0,0,0,0
0,0,0,0,0,0,0,0,0,0,0,0,0,0,0,0,0,0,0,0,0,0,0,0,0,0,0,0,0,0,0,0,0,0,0,0,0,0,0,0,0
0,0,0,0,0,0,0,0,0,0,0,0,0,0,0,0,0,0,0,0,0,0,0,0,0,0,0,0,0,0,0,0,0,0,0,0,0,0,0,0,0
0,0,0,0,0,0,0,0,0,0,0,0,0,0,0,0,0,0,0,0,0,0,0,0,0,0,0,0,0,0,0,0,0,0,0,0,0,0,0,0,0
0,0,0,0,0,0,0,0,0,0,0,0,0,0,0,0,0,0,0,0,0,0,0,0,0,0,0,0,0,0,0,0,0,0,0,0,0,0,0,0,0
0,0,0,0,0,0,0,0,0,0,0,0,0,0,0,0,0,0,0,0,0,0,0,0,0,0,0,0,0,0,0,0,0,0,0,0,0,0,0,0,0
0,0,0,0,0,0,0,0,0,0,0,0,0,0,0,0,0,0,0,0,0,0,0,0,0,0,0,0,0,0,0,0,0,0,0,0,0,0,0,0,0
0,0,0,0,0,0,0,0,0,0,0,0,0,0,0,0,0,0,0,0,0,0,0,0,0,0,0,0,0,0,0,0,0,0,0,0,0,0,0,0,0
endlayer

layer
0,0,0,0,0,0,0,0,0,0,0,0,0,0,0,0,0,0,0,0,0,0,0,0,0,0,0,0,0,0,0,0,0,0,0,0,0,0,0,0,0
0,0,0,0,0,0,0,0,0,0,0,0,0,0,0,0,0,0,0,0,0,0,0,0,0,0,0,0,0,0,0,0,0,0,0,0,0,0,0,0,0
0,0,0,0,0,0,0,0,0,0,0,0,0,0,0,0,0,0,0,0,0,0,0,0,0,0,0,0,0,0,0,0,0,0,0,0,0,0,0,0,0
0,0,0,0,0,0,0,0,0,0,0,0,0,0,0,0,0,0,0,0,0,0,0,0,0,0,0,0,0,0,0,0,0,0,0,0,0,0,0,0,0
0,0,0,0,0,0,0,0,0,0,0,0,0,0,0,0,0,0,0,0,0,0,0,0,0,0,0,0,0,0,0,0,0,0,0,0,0,0,0,0,0
0,0,0,0,0,0,0,0,0,0,0,0,0,0,0,0,0,0,0,0,0,0,0,0,0,0,0,0,0,0,0,0,0,0,0,0,0,0,0,0,0
0,0,0,0,0,0,0,0,0,0,0,0,0,0,0,0,0,0,0,0,0,0,0,0,0,0,0,0,0,0,0,0,0,0,0,0,0,0,0,0,0
0,0,0,0,0,0,0,0,0,0,0,0,0,0,0,0,0,0,0,0,0,0,0,0,0,0,0,0,0,0,0,0,0,0,0,0,0,0,0,0,0
0,0,0,0,0,0,0,0,0,0,0,0,0,0,0,0,0,0,0,0,0,0,0,0,0,0,0,0,0,0,0,0,0,0,0,0,0,0,0,0,0
0,0,0,0,0,0,0,0,0,0,0,0,0,0,0,0,0,0,0,0,0,0,0,0,0,0,0,0,0,0,0,0,0,0,0,0,0,0,0,0,0
0,0,0,0,0,0,0,0,0,0,0,0,0,0,0,0,0,0,0,0,0,0,0,0,0,0,0,0,0,0,0,0,0,0,0,0,0,0,0,0,0
0,0,0,0,0,0,0,0,0,0,0,0,0,0,0,0,0,0,0,0,0,0,0,0,0,0,0,0,0,0,0,0,0,0,0,0,0,0,0,0,0
0,0,0,0,0,0,0,0,0,0,0,0,0,0,0,0,0,0,0,0,0,0,0,0,0,0,0,0,0,0,0,0,0,0,0,0,0,0,0,0,0
0,0,0,0,0,0,0,0,0,0,0,0,0,0,0,0,0,0,0,0,0,0,0,0,0,0,0,0,0,0,0,0,0,0,0,0,0,0,0,0,0
0,0,0,0,0,0,0,0,0,0,0,0,0,0,0,0,0,0,0,0,0,0,0,0,0,0,0,0,0,0,0,0,0,0,0,0,0,0,0,0,0
0,0,0,0,0,0,0,0,0,0,0,0,0,0,0,0,0,0,0,0,0,0,0,0,0,0,0,0,0,0,0,0,0,0,0,0,0,0,0,0,0
0,0,0,0,0,0,0,0,0,0,0,0,0,0,0,0,0,0,0,0,0,0,0,0,0,0,0,0,0,0,0,0,0,0,0,0,0,0,0,0,0
0,0,0,0,0,0,0,0,0,0,0,0,0,0,0,0,0,0,0,0,0,0,0,0,0,0,0,0,0,0,0,0,0,0,0,0,0,0,0,0,0
0,0,0,0,0,0,0,0,0,0,0,0,0,0,0,0,0,0,0,0,0,0,0,0,0,0,0,0,0,0,0,0,0,0,0,0,0,0,0,0,0
0,0,0,0,0,0,0,0,0,0,0,0,0,0,0,0,0,0,0,0,0,0,0,0,0,0,0,0,0,0,0,0,0,0,0,0,0,0,0,0,0
0,0,0,0,0,0,0,0,0,0,0,0,0,0,0,0,0,0,0,0,0,0,0,0,0,0,0,0,0,0,0,0,0,0,0,0,0,0,0,0,0
0,0,0,0,0,0,0,0,0,0,0,0,0,0,0,0,0,0,0,0,0,0,0,0,0,0,0,0,0,0,0,0,0,0,0,0,0,0,0,0,0
0,0,0,0,0,0,0,0,0,0,0,0,0,0,0,0,0,53,0,0,0,0,0,0,0,0,0,0,0,0,0,0,0,0,0,0,0,0,0,0,0
0,0,0,0,0,0,0,0,0,0,0,0,0,0,0,0,0,0,0,0,0,0,0,0,0,0,0,0,0,0,0,0,0,0,0,0,0,0,0,0,0
0,0,0,0,0,0,0,0,0,0,0,0,0,0,0,0,0,0,0,0,0,0,0,0,0,0,0,0,0,0,0,0,0,0,0,0,0,0,0,0,0
0,0,0,0,0,0,0,0,0,0,0,0,0,0,0,0,0,0,0,0,0,0,0,0,0,0,0,0,0,0,0,0,0,0,0,0,0,0,0,0,0
0,0,0,0,0,0,0,0,0,0,0,0,0,0,0,0,0,0,0,0,0,0,0,0,0,0,0,0,0,0,0,0,0,0,0,0,0,0,0,0,0
0,0,0,0,0,0,0,0,0,0,0,0,0,0,0,0,0,0,0,0,0,0,0,0,0,0,0,0,0,0,0,0,0,0,0,0,0,0,0,0,0
0,0,0,0,0,0,0,0,0,0,0,0,0,0,0,0,0,0,0,0,0,0,0,0,0,0,0,0,0,0,0,0,0,0,0,0,0,0,0,0,0
0,0,0,0,0,0,0,0,0,0,0,0,0,0,0,0,0,0,0,0,0,0,0,0,0,0,0,0,0,0,0,0,0,0,0,0,0,0,0,0,0
0,0,0,0,0,0,0,0,0,0,0,0,0,0,0,0,0,0,0,0,0,0,0,0,0,0,0,0,0,0,0,0,0,0,0,0,0,0,0,0,0
0,0,0,0,0,0,0,0,0,0,0,0,0,0,0,0,0,0,0,0,0,0,0,0,0,0,0,0,0,0,0,0,0,0,0,0,0,0,0,0,0
0,0,0,0,0,0,0,0,0,0,0,0,0,0,0,0,0,0,0,0,0,0,0,0,0,0,0,0,0,0,0,0,0,0,0,0,0,0,0,0,0
0,0,0,0,0,0,0,0,0,0,0,0,0,0,0,0,0,0,0,0,0,0,0,0,0,0,0,0,0,0,0,0,0,0,0,0,0,0,0,0,0
0,0,0,0,0,0,0,0,0,0,0,0,0,0,0,0,0,0,0,0,0,0,0,0,0,0,0,0,0,0,0,0,0,0,0,0,0,0,0,0,0
0,0,0,0,0,0,0,0,0,0,0,0,0,0,0,0,0,0,0,0,0,0,0,0,0,0,0,0,0,0,0,0,0,0,0,0,0,0,0,0,0
0,0,0,0,0,0,0,0,0,0,0,0,0,0,0,0,0,0,0,0,0,0,0,0,0,0,0,0,0,0,0,0,0,0,0,0,0,0,0,0,0
0,0,0,0,0,0,0,0,0,0,0,0,0,0,0,0,0,0,0,0,0,0,0,0,0,0,0,0,0,0,0,0,0,0,0,0,0,0,0,0,0
0,0,0,0,0,0,0,0,0,0,0,0,0,0,0,0,0,0,0,0,0,0,0,0,0,0,0,0,0,0,0,0,0,0,0,0,0,0,0,0,0
0,0,0,0,0,0,0,0,0,0,0,0,0,0,0,0,0,0,0,0,0,0,0,0,0,0,0,0,0,0,0,0,0,0,0,0,0,0,0,0,0
0,0,0,0,0,0,0,0,0,0,0,0,0,0,0,0,0,0,0,0,0,0,0,0,0,0,0,0,0,0,0,0,0,0,0,0,0,0,0,0,0
0,0,0,0,0,0,0,0,0,0,0,0,0,0,0,0,0,0,0,0,0,0,0,0,0,0,0,0,0,0,0,0,0,0,0,0,0,0,0,0,0
endlayer

