
# Created by Ruins mod version 15.3 Ingame Parser
# authoring Player: Mensrea

weight=3
embed_into_distance=7
acceptable_target_blocks=
unacceptable_target_blocks=flowing_water,water,flowing_lava,lava
dimensions=17,12,12
allowable_overhang=0
max_leveling=2
leveling_buffer=0
preserve_water=0
preserve_lava=0
preventRotation=1

rule1=0,100,PFAAGeologica:strongStone-7
rule2=0,100,minecraft:stonebrick-0
rule3=0,100,minecraft:dirt-0
rule4=0,100,ChestGenHook:pyramidJungleChest:5-2
rule5=0,100,ChestGenHook:pyramidJungleChest:5-2
rule6=0,100,ChestGenHook:pyramidJungleChest:5-2
rule7=0,100,MobSpawner:desertmobs.cryptzombie
rule8=0,100,ChestGenHook:pyramidJungleChest:5-2
rule9=0,100,minecraft:stone-0
rule10=0,100,ImmersiveEngineering:storageSlab-7
rule11=0,100,PFAAGeologica:mediumStone-3
rule12=0,100,PFAAGeologica:weakStone-1
rule13=0,100,minecraft:stone_slab-8
rule14=0,100,minecraft:sand-1
rule15=0,100,minecraft:obsidian-0
rule16=0,100,IW:bush-0

layer
1,1,1,1,1,1,1,1,1,1,1,1
1,1,1,1,1,1,1,1,1,1,1,1
1,1,1,1,1,1,1,1,1,1,1,1
1,1,2,2,2,2,2,2,2,1,1,1
1,1,2,2,2,3,2,2,2,1,1,1
1,1,2,2,2,4,2,2,2,1,1,1
1,1,2,7,6,2,5,3,2,1,1,1
1,1,2,2,2,8,2,2,2,1,1,1
1,1,2,2,2,7,2,2,2,1,1,1
1,1,2,2,2,2,2,2,2,1,1,1
1,1,1,1,1,1,1,1,1,1,1,1
1,1,1,1,1,1,1,1,1,1,1,1
endlayer

layer
1,1,1,1,1,1,1,1,1,1,1,1
1,1,1,1,1,1,1,1,1,1,1,1
1,1,1,1,1,1,1,1,1,1,1,1
1,1,2,9,9,2,9,9,2,1,1,1
1,1,9,0,0,10,0,0,9,1,1,1
1,1,9,0,0,10,0,0,9,1,1,1
1,1,2,10,10,0,10,10,2,1,1,1
1,1,9,0,0,10,0,0,9,1,1,1
1,1,9,0,0,10,0,0,9,1,1,1
1,1,2,9,9,2,9,9,2,1,1,1
1,1,1,1,1,1,1,1,1,1,1,1
1,1,1,1,1,1,1,1,1,1,1,1
endlayer

layer
11,11,11,11,11,11,11,11,11,11,11,11
11,11,11,11,11,11,11,11,11,11,11,11
11,11,11,11,11,11,11,11,11,11,11,11
11,11,2,9,9,2,9,9,2,11,11,11
11,11,9,0,0,0,0,0,9,11,11,11
11,11,9,0,0,0,0,0,9,11,11,11
11,11,2,0,0,0,0,0,2,11,11,11
11,11,9,0,0,0,0,0,9,11,11,11
11,11,9,0,0,0,0,0,9,11,11,11
11,11,2,9,9,2,9,9,2,11,11,11
11,11,11,11,11,11,11,11,11,11,11,11
11,11,11,11,11,11,11,11,11,11,11,11
endlayer

layer
11,11,11,11,11,11,11,11,11,11,11,11
11,11,11,11,11,11,11,11,11,11,11,11
11,11,11,11,11,11,11,11,11,11,11,11
11,11,2,9,9,2,9,9,2,11,11,11
11,11,9,0,0,0,0,0,9,11,11,11
11,11,9,0,0,0,0,0,9,11,11,11
11,11,2,0,0,0,0,0,2,11,11,11
11,11,9,0,0,0,0,0,9,11,11,11
11,11,9,0,0,0,0,0,9,11,11,11
11,11,2,9,9,2,9,9,2,11,11,11
11,11,11,11,11,11,11,11,11,11,11,11
11,11,11,11,11,11,11,11,11,11,11,11
endlayer

layer
12,12,12,12,12,12,12,12,12,12,12,12
12,12,12,12,12,12,12,12,12,12,12,12
12,12,12,12,12,12,12,12,12,12,12,12
12,12,9,9,9,9,9,9,9,12,12,12
12,12,9,9,13,13,13,9,9,12,12,12
12,12,9,13,0,0,0,13,9,12,12,12
12,12,9,13,0,0,0,13,9,12,12,12
12,12,9,13,0,0,0,13,9,12,12,12
12,12,9,9,13,13,13,9,9,12,12,12
12,12,9,9,9,9,9,9,9,12,12,12
12,12,12,12,12,12,12,12,12,12,12,12
12,12,12,12,12,12,12,12,12,12,12,12
endlayer

layer
14,14,14,14,14,14,14,14,14,14,14,14
14,14,14,14,14,14,14,14,14,14,14,14
14,14,14,14,14,14,14,14,14,14,14,14
14,14,15,15,15,15,15,15,15,14,14,14
14,14,15,15,15,15,15,15,15,14,14,14
14,14,15,15,9,0,9,15,15,14,14,14
14,14,15,15,0,0,0,15,15,14,14,14
14,14,15,15,9,0,9,15,15,14,14,14
14,14,15,15,15,15,15,15,15,14,14,14
14,14,15,15,15,15,15,15,15,14,14,14
14,14,14,14,14,14,14,14,14,14,14,14
14,14,14,14,14,14,14,14,14,14,14,14
endlayer

layer
14,14,14,14,14,14,14,14,14,14,14,14
14,14,14,14,14,14,14,14,14,14,14,14
14,14,14,14,14,14,14,14,14,14,14,0
14,14,15,14,14,14,14,14,15,14,14,0
14,14,14,15,15,15,15,15,14,14,14,0
0,14,0,15,15,15,15,15,14,14,14,14
14,0,0,15,15,0,15,15,14,14,14,14
0,14,14,15,15,15,15,15,14,14,14,14
0,14,14,15,15,15,15,15,14,14,14,14
14,14,15,14,14,14,14,14,15,14,14,14
14,14,14,14,14,14,14,14,14,14,14,14
14,14,14,14,14,14,14,14,14,14,14,14
endlayer

layer
0,0,14,14,0,0,0,0,0,0,16,0
0,14,14,14,14,16,0,0,0,0,0,0
0,14,14,14,14,0,0,14,14,0,0,0
0,0,14,14,0,0,14,14,14,14,0,0
0,0,0,15,0,14,14,15,14,14,0,0
0,0,0,0,15,15,15,14,14,0,0,0
0,0,0,0,15,15,15,14,0,0,0,0
0,0,0,0,15,15,15,0,0,16,0,0
0,0,16,15,0,0,0,15,0,0,0,0
0,0,0,0,0,0,0,0,14,14,0,0
0,0,14,0,0,16,0,0,14,14,14,0
0,14,14,0,0,0,0,0,0,14,0,0
endlayer

layer
0,0,0,0,0,0,0,0,0,0,0,0
0,0,14,0,0,0,0,0,0,0,0,0
0,0,14,14,0,0,0,0,0,0,0,0
0,0,0,0,0,0,0,0,16,0,0,0
0,0,0,0,0,0,14,14,0,0,0,0
0,0,0,0,15,15,15,14,0,0,0,0
0,0,0,0,15,15,15,0,0,0,0,0
0,0,0,0,15,15,15,0,0,0,0,0
0,0,0,0,0,0,0,0,0,0,0,0
0,0,0,0,0,0,0,0,0,0,0,0
0,0,0,0,0,0,0,0,0,14,0,0
0,0,0,0,0,0,0,0,0,0,0,0
endlayer

layer
0,0,0,0,0,0,0,0,0,0,0,0
0,0,0,0,0,0,0,0,0,0,0,0
0,0,0,0,0,0,0,0,0,0,0,0
0,0,0,0,0,0,0,0,0,0,0,0
0,0,0,0,0,0,0,0,0,0,0,0
0,0,0,0,15,15,15,0,0,0,0,0
0,0,0,0,15,15,15,0,0,0,0,0
0,0,0,0,15,15,15,0,0,0,0,0
0,0,0,0,0,0,0,0,0,0,0,0
0,0,0,0,0,0,0,0,0,0,0,0
0,0,0,0,0,0,0,0,0,0,0,0
0,0,0,0,0,0,0,0,0,0,0,0
endlayer

layer
0,0,0,0,0,0,0,0,0,0,0,0
0,0,0,0,0,0,0,0,0,0,0,0
0,0,0,0,0,0,0,0,0,0,0,0
0,0,0,0,0,0,0,0,0,0,0,0
0,0,0,0,0,0,0,0,0,0,0,0
0,0,0,0,15,15,15,0,0,0,0,0
0,0,0,0,15,15,15,0,0,0,0,0
0,0,0,0,15,15,15,0,0,0,0,0
0,0,0,0,0,0,0,0,0,0,0,0
0,0,0,0,0,0,0,0,0,0,0,0
0,0,0,0,0,0,0,0,0,0,0,0
0,0,0,0,0,0,0,0,0,0,0,0
endlayer

layer
0,0,0,0,0,0,0,0,0,0,0,0
0,0,0,0,0,0,0,0,0,0,0,0
0,0,0,0,0,0,0,0,0,0,0,0
0,0,0,0,0,0,0,0,0,0,0,0
0,0,0,0,0,0,0,0,0,0,0,0
0,0,0,0,15,15,15,0,0,0,0,0
0,0,0,0,15,15,15,0,0,0,0,0
0,0,0,0,15,15,15,0,0,0,0,0
0,0,0,0,0,0,0,0,0,0,0,0
0,0,0,0,0,0,0,0,0,0,0,0
0,0,0,0,0,0,0,0,0,0,0,0
0,0,0,0,0,0,0,0,0,0,0,0
endlayer

layer
0,0,0,0,0,0,0,0,0,0,0,0
0,0,0,0,0,0,0,0,0,0,0,0
0,0,0,0,0,0,0,0,0,0,0,0
0,0,0,0,0,0,0,0,0,0,0,0
0,0,0,0,0,0,0,0,0,0,0,0
0,0,0,0,15,15,15,0,0,0,0,0
0,0,0,0,15,15,15,0,0,0,0,0
0,0,0,0,15,15,15,0,0,0,0,0
0,0,0,0,0,0,0,0,0,0,0,0
0,0,0,0,0,0,0,0,0,0,0,0
0,0,0,0,0,0,0,0,0,0,0,0
0,0,0,0,0,0,0,0,0,0,0,0
endlayer

layer
0,0,0,0,0,0,0,0,0,0,0,0
0,0,0,0,0,0,0,0,0,0,0,0
0,0,0,0,0,0,0,0,0,0,0,0
0,0,0,0,0,0,0,0,0,0,0,0
0,0,0,0,0,0,0,0,0,0,0,0
0,0,0,0,15,15,15,0,0,0,0,0
0,0,0,0,15,15,15,0,0,0,0,0
0,0,0,0,15,15,15,0,0,0,0,0
0,0,0,0,0,0,0,0,0,0,0,0
0,0,0,0,0,0,0,0,0,0,0,0
0,0,0,0,0,0,0,0,0,0,0,0
0,0,0,0,0,0,0,0,0,0,0,0
endlayer

layer
0,0,0,0,0,0,0,0,0,0,0,0
0,0,0,0,0,0,0,0,0,0,0,0
0,0,0,0,0,0,0,0,0,0,0,0
0,0,0,0,0,0,0,0,0,0,0,0
0,0,0,0,0,0,0,0,0,0,0,0
0,0,0,0,15,15,15,0,0,0,0,0
0,0,0,0,15,15,15,0,0,0,0,0
0,0,0,0,15,15,15,0,0,0,0,0
0,0,0,0,0,0,0,0,0,0,0,0
0,0,0,0,0,0,0,0,0,0,0,0
0,0,0,0,0,0,0,0,0,0,0,0
0,0,0,0,0,0,0,0,0,0,0,0
endlayer

layer
0,0,0,0,0,0,0,0,0,0,0,0
0,0,0,0,0,0,0,0,0,0,0,0
0,0,0,0,0,0,0,0,0,0,0,0
0,0,0,0,0,0,0,0,0,0,0,0
0,0,0,0,0,0,0,0,0,0,0,0
0,0,0,0,0,15,0,0,0,0,0,0
0,0,0,0,15,15,15,0,0,0,0,0
0,0,0,0,0,15,0,0,0,0,0,0
0,0,0,0,0,0,0,0,0,0,0,0
0,0,0,0,0,0,0,0,0,0,0,0
0,0,0,0,0,0,0,0,0,0,0,0
0,0,0,0,0,0,0,0,0,0,0,0
endlayer

layer
0,0,0,0,0,0,0,0,0,0,0,0
0,0,0,0,0,0,0,0,0,0,0,0
0,0,0,0,0,0,0,0,0,0,0,0
0,0,0,0,0,0,0,0,0,0,0,0
0,0,0,0,0,0,0,0,0,0,0,0
0,0,0,0,0,0,0,0,0,0,0,0
0,0,0,0,0,15,0,0,0,0,0,0
0,0,0,0,0,0,0,0,0,0,0,0
0,0,0,0,0,0,0,0,0,0,0,0
0,0,0,0,0,0,0,0,0,0,0,0
0,0,0,0,0,0,0,0,0,0,0,0
0,0,0,0,0,0,0,0,0,0,0,0
endlayer

