
# Created by Ruins mod version 15.3 Ingame Parser
# authoring Player: Mensrea

weight=15
embed_into_distance=1
acceptable_target_blocks=
unacceptable_target_blocks=flowing_water,water,flowing_lava,lava
dimensions=39,13,14
allowable_overhang=0
max_leveling=2
leveling_buffer=0
preserve_water=0
preserve_lava=0
preventRotation=1

rule1=0,100,PFAAGeologica:weakStone-1
rule2=0,100,IW:concrete-0
rule3=0,100,minecraft:gravel-0
rule4=0,100,MobSpawner:demonmobs.trite
rule5=0,100,PFAAGeologica:strongStoneBrick-1
rule6=0,100,IW:concretetile-0
rule7=0,100,minecraft:planks-0
rule8=0,100,IW:concreteslab-0
rule9=0,100,IW:metalladder-3
rule10=0,100,IW:steelblock-0
rule11=0,100,IW:glassblack-0
rule12=0,100,minecraft:bed-0
rule13=0,100,minecraft:bed-8
rule14=0,100,minecraft:jungle_stairs-3
rule15=0,100,minecraft:jungle_stairs-2
rule16=0,100,IW:metalladder-2
rule17=0,100,minecraft:jungle_stairs-0
rule18=0,100,minecraft:wooden_slab-8
rule19=0,100,PFAAGeologica:strongStone-1
rule20=0,100,ChestGenHook:strongholdCorridor:5-2
rule21=0,100,ChestGenHook:strongholdCorridor:5-2
rule22=0,100,minecraft:wooden_slab-0
rule23=0,100,MobSpawner:demonmobs.belph
rule24=0,100,ChestGenHook:strongholdCorridor:5-2
rule25=0,100,ImmersiveEngineering:metalDecoration-1
rule26=0,100,ImmersiveEngineering:metalDecoration-0
rule27=0,100,ThermalExpansion:Workbench-1
rule28=0,100,IW:computer1-0
rule29=0,100,minecraft:oak_stairs-0
rule30=0,100,IW:metalhatch-1
rule31=0,100,minecraft:stained_glass-15
rule32=0,100,IW:machinery1-0
rule33=0,100,IC2:blockGenerator-3
rule34=0,100,ImmersiveEngineering:metalDecoration-13
rule35=0,100,MobSpawner:demonmobs.nethersoul
rule36=0,100,IW:tower3-0

layer
1,1,1,2,2,1,1,1,1,2,2,1,1,1
1,2,2,2,2,2,2,2,2,2,2,2,2,1
2,2,2,2,2,2,2,2,2,2,2,2,2,2
2,2,2,2,2,2,2,2,2,2,2,2,2,2
1,2,2,2,2,2,2,2,2,2,2,2,2,1
1,2,2,2,2,2,2,2,2,2,2,2,2,1
1,2,2,2,2,2,2,2,2,2,2,2,2,1
1,2,2,2,2,2,2,2,2,2,2,2,2,1
1,2,2,2,2,2,2,2,2,2,2,2,2,1
2,2,2,2,2,2,2,2,2,2,2,2,2,2
2,2,2,2,2,2,2,2,2,2,2,2,2,2
1,2,2,2,2,2,2,2,2,2,2,2,2,1
1,1,1,2,2,1,1,1,1,2,2,1,1,1
endlayer

layer
3,3,3,2,2,3,3,3,3,2,2,3,3,3
3,2,2,2,2,2,2,2,2,2,2,2,2,3
2,2,2,2,2,2,2,2,2,2,2,2,2,2
2,2,2,2,2,2,2,2,2,2,2,2,2,2
3,2,2,2,2,2,4,2,2,2,2,2,2,3
3,2,2,2,2,2,2,2,2,2,2,2,2,3
3,2,2,2,2,2,2,2,2,2,2,2,2,3
3,2,2,2,2,2,2,2,2,2,2,2,2,3
3,2,2,2,2,2,2,2,2,2,2,2,2,3
2,2,2,2,2,2,2,2,2,2,2,2,2,2
2,2,2,2,2,2,2,2,2,2,2,2,2,2
3,2,2,2,2,2,2,2,2,2,2,2,2,3
3,3,3,2,2,3,3,3,3,2,2,3,3,3
endlayer

layer
0,0,0,5,5,0,0,0,0,5,5,0,0,0
0,0,0,0,0,0,0,0,0,0,0,0,0,0
5,0,2,2,6,6,0,0,6,6,2,2,0,5
5,0,2,0,0,0,0,0,0,7,7,2,0,5
0,0,6,0,0,0,8,0,0,0,0,0,0,0
0,0,0,0,0,0,0,0,0,0,0,0,0,0
0,0,0,0,6,0,0,0,9,6,0,6,0,0
0,0,6,0,0,0,0,0,0,0,0,6,0,0
0,0,6,7,0,0,0,0,0,7,7,6,0,0
5,0,2,7,7,0,0,0,0,7,7,2,0,5
5,0,2,2,6,6,0,0,0,6,2,2,0,5
0,0,0,0,0,0,0,0,0,0,0,0,0,0
0,0,0,5,5,0,0,0,0,5,5,0,0,0
endlayer

layer
0,0,0,5,5,0,0,0,0,5,5,0,0,0
0,0,0,0,0,0,0,0,0,0,0,0,0,0
5,0,2,2,6,6,6,6,6,6,2,2,0,5
5,0,2,0,0,0,0,0,0,0,0,2,0,5
0,0,6,0,0,0,0,0,0,0,0,6,0,0
0,0,6,0,0,0,0,0,0,0,0,6,0,0
0,0,6,0,6,0,0,0,9,6,0,6,0,0
0,0,6,0,0,0,0,0,0,0,0,6,0,0
0,0,6,0,0,0,0,0,0,7,7,6,0,0
5,0,2,7,0,0,0,0,0,7,7,2,0,5
5,0,2,2,6,0,0,0,0,6,2,2,0,5
0,0,0,0,0,0,0,0,0,0,0,0,0,0
0,0,0,5,5,0,0,0,0,5,5,0,0,0
endlayer

layer
0,0,0,5,5,0,0,0,0,5,5,0,0,0
0,0,0,0,0,0,0,0,0,0,0,0,0,0
5,0,2,2,6,6,6,6,6,6,2,2,0,5
5,0,2,0,0,0,0,0,0,0,0,2,0,5
0,0,6,0,0,0,0,0,0,0,0,6,0,0
0,0,6,0,0,0,0,0,0,0,0,6,0,0
0,0,6,0,6,0,0,0,9,6,0,6,0,0
0,0,6,0,0,0,0,0,0,0,0,6,0,0
0,0,6,0,0,0,0,0,0,0,0,6,0,0
5,0,2,0,0,0,0,0,0,0,0,2,0,5
5,0,2,2,6,6,0,0,6,6,2,2,0,5
0,0,0,0,0,0,0,0,0,0,0,0,0,0
0,0,0,5,5,0,0,0,0,5,5,0,0,0
endlayer

layer
0,0,0,5,5,0,0,0,0,5,5,0,0,0
0,0,0,0,0,0,0,0,0,0,0,0,0,0
5,0,2,2,6,6,6,6,6,6,2,2,0,5
5,0,2,0,0,0,0,0,0,0,0,2,0,5
0,0,6,0,0,0,0,0,0,0,0,6,0,0
0,0,6,0,0,0,0,0,0,0,0,6,0,0
0,0,6,0,6,0,0,0,9,6,0,6,0,0
0,0,6,0,0,0,0,0,0,0,0,6,0,0
0,0,6,0,0,0,0,0,0,0,0,6,0,0
5,0,2,0,0,0,0,0,0,0,0,2,0,5
5,0,2,2,6,10,10,10,10,6,2,2,0,5
0,0,0,0,0,0,0,0,0,0,0,0,0,0
0,0,0,5,5,0,0,0,0,5,5,0,0,0
endlayer

layer
0,0,0,5,5,0,0,0,0,5,5,0,0,0
0,0,0,0,0,0,0,0,0,0,0,0,0,0
5,0,2,2,6,2,2,2,2,6,2,2,0,5
5,0,2,2,2,2,2,2,2,2,2,2,0,5
0,0,6,2,2,2,2,2,2,2,2,6,0,0
0,0,6,2,2,2,2,2,2,2,2,6,0,0
0,0,6,2,6,0,0,0,9,6,2,6,0,0
0,0,6,0,0,0,0,0,2,2,2,6,0,0
0,0,6,2,2,0,0,2,2,2,2,6,0,0
5,0,2,2,2,2,2,2,2,2,2,2,0,5
5,0,2,2,6,2,2,2,2,6,2,2,0,5
0,0,0,0,0,0,0,0,0,0,0,0,0,0
0,0,0,5,5,0,0,0,0,5,5,0,0,0
endlayer

layer
0,0,0,5,5,0,0,0,0,5,5,0,0,0
0,0,0,0,0,0,0,0,0,0,0,0,0,0
5,0,2,2,6,6,11,11,6,6,2,2,0,5
5,0,2,13,12,7,0,0,0,0,7,2,0,5
0,0,6,0,0,0,0,15,7,14,7,6,0,0
0,0,6,13,12,7,0,0,0,0,0,6,0,0
0,0,6,0,6,16,0,0,0,6,0,6,0,0
0,0,6,0,0,0,0,0,0,0,0,6,0,0
0,0,6,0,0,0,0,0,7,14,7,6,0,0
5,0,2,13,12,7,0,0,17,0,7,2,0,5
5,0,2,2,6,6,11,11,6,6,2,2,0,5
0,0,0,0,0,0,0,0,0,0,0,0,0,0
0,0,0,5,5,0,0,0,0,5,5,0,0,0
endlayer

layer
0,0,0,5,5,0,0,0,0,5,5,0,0,0
0,0,0,0,0,0,0,0,0,0,0,0,0,0
5,0,2,2,6,6,11,11,6,6,2,2,0,5
5,0,2,0,0,0,0,0,0,0,7,2,0,5
0,0,6,0,0,0,0,0,0,0,7,6,0,0
0,0,6,0,0,0,0,0,0,0,0,6,0,0
0,0,6,0,6,16,0,0,0,6,0,6,0,0
0,0,6,0,0,0,0,0,0,0,0,6,0,0
0,0,6,0,0,0,0,0,0,0,7,6,0,0
5,0,2,0,0,0,0,0,0,0,7,2,0,5
5,0,2,2,6,6,11,11,6,6,2,2,0,5
0,0,0,0,0,0,0,0,0,0,0,0,0,0
0,0,0,5,5,0,0,0,0,5,5,0,0,0
endlayer

layer
0,0,0,5,5,0,0,0,0,5,5,0,0,0
0,0,0,0,0,0,0,0,0,0,0,0,0,0
5,0,2,2,6,6,11,11,6,6,2,2,0,5
5,0,2,0,0,0,0,0,0,0,0,2,0,5
0,0,6,0,0,0,0,0,0,0,0,6,0,0
0,0,6,0,0,0,0,0,0,0,0,6,0,0
0,0,6,0,6,16,0,0,0,6,0,6,0,0
0,0,6,0,0,0,0,0,0,0,0,6,0,0
0,0,6,0,0,0,0,0,0,0,0,6,0,0
5,0,2,0,0,0,0,0,0,0,0,2,0,5
5,0,2,2,6,6,11,11,6,6,2,2,0,5
0,0,0,0,0,0,0,0,0,0,0,0,0,0
0,0,0,5,5,0,0,0,0,5,5,0,0,0
endlayer

layer
0,0,0,5,5,0,0,0,0,5,5,0,0,0
0,0,0,0,0,0,0,0,0,0,0,0,0,0
5,0,2,2,6,6,11,11,6,6,2,2,0,5
5,0,2,0,0,0,0,0,0,0,0,2,0,5
0,0,6,0,0,0,0,0,0,0,0,6,0,0
0,0,6,0,0,0,0,0,0,0,0,6,0,0
0,0,6,0,6,16,0,0,0,6,0,6,0,0
0,0,6,0,0,0,0,0,0,0,0,6,0,0
0,0,6,0,0,0,0,0,0,0,0,6,0,0
5,0,2,0,0,0,0,0,0,0,0,2,0,5
5,0,2,2,6,6,11,11,6,6,2,2,0,5
0,0,0,0,0,0,0,0,0,0,0,0,0,0
0,0,0,5,5,0,0,0,0,5,5,0,0,0
endlayer

layer
0,0,0,5,5,0,0,0,0,5,5,0,0,0
0,0,0,0,0,0,0,0,0,0,0,0,0,0
5,0,2,2,6,10,10,10,10,6,2,2,0,5
5,0,2,2,2,2,0,2,2,0,0,2,0,5
0,0,6,2,2,18,0,0,2,2,0,6,0,0
0,0,6,2,2,18,0,0,2,2,2,6,0,0
0,0,6,2,6,16,0,0,2,6,2,6,0,0
0,0,6,2,2,0,0,0,2,2,2,6,0,0
0,0,6,2,2,2,0,2,2,2,2,6,0,0
5,0,2,2,2,2,2,2,2,2,2,2,0,5
5,0,2,2,6,10,10,10,10,6,2,2,0,5
0,0,0,0,0,0,0,0,0,0,0,0,0,0
0,0,0,5,5,0,0,0,0,5,5,0,0,0
endlayer

layer
0,0,0,5,19,0,0,0,0,19,5,0,0,0
0,0,0,0,0,0,0,0,0,0,0,0,0,0
5,0,2,2,6,6,11,11,6,6,2,2,0,5
5,0,2,0,7,0,0,0,0,0,0,2,0,5
0,0,6,0,0,0,0,0,7,20,0,6,0,0
0,0,6,0,0,0,0,0,7,21,0,6,0,0
0,0,6,0,6,0,0,0,9,6,0,6,0,0
0,0,6,0,0,0,0,0,0,22,22,6,0,0
0,0,6,0,0,0,0,0,22,7,7,6,0,0
5,0,2,7,24,0,0,0,22,7,23,2,0,5
5,0,2,2,6,6,11,11,6,6,2,2,0,5
0,0,0,0,0,0,0,0,0,0,0,0,0,0
0,0,0,5,19,0,0,0,0,19,5,0,0,0
endlayer

layer
0,0,0,5,19,19,0,0,19,19,5,0,0,0
0,0,0,0,0,0,0,0,0,0,0,0,0,0
5,0,2,2,6,6,11,11,6,6,2,2,0,5
5,0,2,0,7,0,0,0,0,0,0,2,0,5
0,0,6,0,0,0,0,0,7,7,0,6,0,0
0,0,6,0,0,0,0,0,7,7,0,6,0,0
0,0,6,0,6,0,0,0,9,6,0,6,0,0
0,0,6,0,0,0,0,0,0,0,0,6,0,0
0,0,6,0,0,0,0,0,0,0,0,6,0,0
5,0,2,7,7,0,0,0,0,0,22,2,0,5
5,0,2,2,6,6,11,11,6,6,2,2,0,5
0,0,0,0,0,0,0,0,0,0,0,0,0,0
0,0,0,5,19,19,0,0,19,19,5,0,0,0
endlayer

layer
0,0,0,5,5,19,19,19,19,5,5,0,0,0
0,0,0,0,0,0,0,0,0,0,0,0,0,0
5,0,2,2,6,6,11,11,6,6,2,2,0,5
5,0,2,0,0,0,0,0,0,0,0,2,0,5
0,0,6,0,0,0,0,0,0,0,0,6,0,0
0,0,6,0,0,0,0,0,0,0,0,6,0,0
0,0,6,0,6,0,0,0,9,6,0,6,0,0
0,0,6,0,0,0,0,0,0,0,0,6,0,0
0,0,6,0,0,0,0,0,0,0,0,6,0,0
5,0,2,0,0,0,0,0,0,0,0,2,0,5
5,0,2,2,6,6,11,11,6,6,2,2,0,5
0,0,0,0,0,0,0,0,0,0,0,0,0,0
0,0,0,5,5,19,19,19,19,5,5,0,0,0
endlayer

layer
0,0,0,5,5,0,19,19,0,5,5,0,0,0
0,0,0,0,0,0,0,0,0,0,0,0,0,0
5,0,2,2,6,6,11,11,6,6,2,2,0,5
5,0,2,0,0,0,0,0,0,0,0,2,0,5
0,0,6,0,0,0,0,0,0,0,0,6,0,0
0,0,6,0,0,0,0,0,0,0,0,6,0,0
0,0,6,0,6,0,0,0,9,6,0,6,0,0
0,0,6,0,0,0,0,0,0,0,0,6,0,0
0,0,6,0,0,0,0,0,0,0,0,6,0,0
5,0,2,0,0,0,0,0,0,0,0,2,0,5
5,0,2,2,6,6,11,11,6,6,2,2,0,5
0,0,0,0,0,0,0,0,0,0,0,0,0,0
0,0,0,5,5,0,19,19,0,5,5,0,0,0
endlayer

layer
0,0,0,10,10,10,10,10,10,10,10,0,0,0
0,0,0,10,25,25,25,25,25,25,10,0,0,0
5,0,2,2,10,10,10,10,10,10,2,2,0,5
5,0,2,2,2,2,2,2,2,2,2,2,0,5
0,0,6,2,2,2,2,2,2,2,2,6,0,0
0,0,6,2,2,2,2,2,2,2,2,6,0,0
0,0,6,2,6,2,2,2,9,6,2,6,0,0
0,0,6,2,2,2,2,2,2,2,2,6,0,0
0,0,6,2,2,2,2,2,2,2,2,6,0,0
5,0,2,2,2,2,2,2,2,2,2,2,0,5
5,0,2,2,10,10,10,10,10,10,2,2,0,5
0,0,0,10,25,25,25,25,25,25,10,0,0,0
0,0,0,10,10,10,10,10,10,10,10,0,0,0
endlayer

layer
0,0,0,0,0,0,0,0,0,0,0,0,0,0
0,0,0,0,0,0,0,0,0,0,0,0,0,0
5,0,2,2,0,0,0,0,0,0,2,2,0,5
5,0,2,0,0,0,0,0,0,0,0,2,0,5
0,0,26,0,0,0,28,27,0,0,0,26,0,0
0,0,26,0,0,0,29,0,0,0,0,26,0,0
0,0,26,0,6,16,0,0,30,6,0,26,0,0
0,0,26,0,0,0,0,0,0,0,0,26,0,0
0,0,26,0,0,0,0,0,0,0,0,26,0,0
5,0,2,0,0,0,0,0,0,0,0,2,0,5
5,0,2,2,0,0,0,0,0,0,2,2,0,5
0,0,0,0,0,0,0,0,0,0,0,0,0,0
0,0,0,0,0,0,0,0,0,0,0,0,0,0
endlayer

layer
0,0,0,0,0,0,0,0,0,0,0,0,0,0
0,0,0,0,0,0,0,0,0,0,0,0,0,0
5,0,2,2,0,0,0,0,0,0,2,2,0,5
5,0,2,0,0,0,0,0,0,0,0,2,0,5
0,0,0,0,0,0,31,0,0,0,0,0,0,0
0,0,0,0,0,0,0,0,0,0,0,0,0,0
0,0,0,0,6,16,0,0,0,6,0,0,0,0
0,0,0,0,0,0,0,0,0,0,0,0,0,0
0,0,0,0,0,0,0,0,0,0,0,0,0,0
5,0,2,0,0,0,0,0,0,0,0,2,0,5
5,0,2,2,0,0,0,0,0,0,2,2,0,5
0,0,0,0,0,0,0,0,0,0,0,0,0,0
0,0,0,0,0,0,0,0,0,0,0,0,0,0
endlayer

layer
0,0,0,0,0,0,0,0,0,0,0,0,0,0
0,0,0,0,0,0,0,0,0,0,0,0,0,0
5,0,10,10,10,10,10,10,10,10,10,10,0,5
5,0,10,0,0,0,0,0,0,0,0,10,0,5
0,0,10,0,0,0,0,0,0,0,0,10,0,0
0,0,10,0,0,0,0,0,0,0,0,10,0,0
0,0,10,0,6,16,0,0,0,6,0,10,0,0
0,0,10,0,0,0,0,0,0,0,0,10,0,0
0,0,10,0,0,0,0,0,0,0,0,10,0,0
5,0,10,0,0,0,0,0,0,0,0,10,0,5
5,0,6,10,10,10,10,10,10,10,10,10,0,5
0,0,0,0,0,0,0,0,0,0,0,0,0,0
0,0,0,0,0,0,0,0,0,0,0,0,0,0
endlayer

layer
0,0,0,0,0,0,0,0,0,0,0,0,0,0
0,0,0,0,0,0,0,0,0,0,0,0,0,0
19,0,6,6,6,6,6,6,6,6,6,6,0,19
19,0,6,0,0,0,0,0,0,0,0,6,0,19
0,0,6,0,0,0,0,0,0,0,0,6,0,0
0,0,6,0,0,0,0,0,0,0,0,6,0,0
0,0,6,0,6,16,0,0,0,6,0,6,0,0
0,0,6,0,0,0,0,0,0,0,0,6,0,0
0,0,6,0,0,0,0,0,0,0,0,6,0,0
19,0,6,0,0,0,0,0,0,0,0,6,0,19
19,0,6,6,6,6,6,6,6,6,6,6,0,19
0,0,0,0,0,0,0,0,0,0,0,0,0,0
0,0,0,0,0,0,0,0,0,0,0,0,0,0
endlayer

layer
0,0,0,0,0,0,0,0,0,0,0,0,0,0
0,0,0,0,0,0,0,0,0,0,0,0,0,0
19,19,6,6,6,6,6,6,6,6,6,6,19,19
19,19,6,2,2,2,2,2,2,2,2,6,19,19
0,0,6,2,2,2,2,32,2,2,2,6,0,0
0,0,6,2,2,2,2,2,2,2,2,6,0,0
0,0,6,2,6,16,2,2,2,6,2,6,0,0
0,0,6,2,2,2,2,2,2,2,2,6,0,0
0,0,6,2,2,2,2,2,2,2,2,6,0,0
19,19,6,2,2,2,2,2,2,2,2,6,19,19
19,19,6,6,6,6,6,6,6,6,6,6,19,19
0,0,0,0,0,0,0,0,0,0,0,0,0,0
0,0,0,0,0,0,0,0,0,0,0,0,0,0
endlayer

layer
0,0,0,0,0,0,0,0,0,0,0,0,0,0
0,0,0,0,0,0,0,0,0,0,0,0,0,0
0,19,19,0,0,0,0,0,0,0,0,19,19,0
0,19,19,0,0,0,0,0,0,0,0,19,19,0
0,0,0,0,0,0,0,33,0,0,0,0,0,0
0,0,0,0,0,0,0,0,0,0,0,0,0,0
0,0,0,0,0,0,0,0,0,34,0,0,0,0
0,0,0,0,0,0,22,7,22,0,0,0,0,0
0,0,0,0,0,0,7,35,7,0,0,0,0,0
0,19,19,0,0,0,22,7,22,0,0,19,19,0
0,19,19,0,0,0,0,0,0,0,0,19,19,0
0,0,0,0,0,0,0,0,0,0,0,0,0,0
0,0,0,0,0,0,0,0,0,0,0,0,0,0
endlayer

layer
0,0,0,0,0,0,0,0,0,0,0,0,0,0
0,0,0,0,0,0,0,0,0,0,0,0,0,0
0,0,19,0,0,0,0,0,0,0,0,19,0,0
0,0,19,0,0,0,0,0,0,0,0,19,0,0
0,0,0,0,0,0,0,0,0,0,0,0,0,0
0,0,0,0,0,0,0,0,0,0,0,0,0,0
0,0,0,0,0,0,0,0,0,34,0,0,0,0
0,0,0,0,0,0,0,0,0,0,0,0,0,0
0,0,0,0,0,0,0,22,0,0,0,0,0,0
0,0,19,0,0,0,0,0,0,0,0,19,0,0
0,0,19,0,0,0,0,0,0,0,0,19,0,0
0,0,0,0,0,0,0,0,0,0,0,0,0,0
0,0,0,0,0,0,0,0,0,0,0,0,0,0
endlayer

layer
0,0,0,0,0,0,0,0,0,0,0,0,0,0
0,0,0,0,0,0,0,0,0,0,0,0,0,0
0,0,19,0,0,0,0,0,0,0,0,19,0,0
0,0,19,0,0,0,0,0,0,0,0,19,0,0
0,0,0,0,0,0,0,0,0,0,0,0,0,0
0,0,0,0,0,0,0,0,0,0,0,0,0,0
0,0,0,0,0,0,0,0,0,34,0,0,0,0
0,0,0,0,0,0,0,0,0,0,0,0,0,0
0,0,0,0,0,0,0,0,0,0,0,0,0,0
0,0,19,0,0,0,0,0,0,0,0,19,0,0
0,0,19,0,0,0,0,0,0,0,0,19,0,0
0,0,0,0,0,0,0,0,0,0,0,0,0,0
0,0,0,0,0,0,0,0,0,0,0,0,0,0
endlayer

layer
0,0,0,0,0,0,0,0,0,0,0,0,0,0
0,0,0,0,0,0,0,0,0,0,0,0,0,0
0,0,0,0,0,0,0,0,0,0,0,0,0,0
0,0,0,0,0,0,0,0,0,0,0,0,0,0
0,0,0,0,0,0,0,0,0,0,0,0,0,0
0,0,0,0,0,0,0,0,0,0,0,0,0,0
0,0,0,0,0,0,0,0,0,34,0,0,0,0
0,0,0,0,0,0,0,0,0,0,0,0,0,0
0,0,0,0,0,0,0,0,0,0,0,0,0,0
0,0,0,0,0,0,0,0,0,0,0,0,0,0
0,0,0,0,0,0,0,0,0,0,0,0,0,0
0,0,0,0,0,0,0,0,0,0,0,0,0,0
0,0,0,0,0,0,0,0,0,0,0,0,0,0
endlayer

layer
0,0,0,0,0,0,0,0,0,0,0,0,0,0
0,0,0,0,0,0,0,0,0,0,0,0,0,0
0,0,0,0,0,0,0,0,0,0,0,0,0,0
0,0,0,0,0,0,0,0,0,0,0,0,0,0
0,0,0,0,0,0,0,0,0,0,0,0,0,0
0,0,0,0,0,0,0,0,0,0,0,0,0,0
0,0,0,0,0,0,0,0,0,34,0,0,0,0
0,0,0,0,0,0,0,0,0,0,0,0,0,0
0,0,0,0,0,0,0,0,0,0,0,0,0,0
0,0,0,0,0,0,0,0,0,0,0,0,0,0
0,0,0,0,0,0,0,0,0,0,0,0,0,0
0,0,0,0,0,0,0,0,0,0,0,0,0,0
0,0,0,0,0,0,0,0,0,0,0,0,0,0
endlayer

layer
0,0,0,0,0,0,0,0,0,0,0,0,0,0
0,0,0,0,0,0,0,0,0,0,0,0,0,0
0,0,0,0,0,0,0,0,0,0,0,0,0,0
0,0,0,0,0,0,0,0,0,0,0,0,0,0
0,0,0,0,0,0,0,0,0,0,0,0,0,0
0,0,0,0,0,0,0,0,0,0,0,0,0,0
0,0,0,0,0,0,0,0,0,34,0,0,0,0
0,0,0,0,0,0,0,0,0,0,0,0,0,0
0,0,0,0,0,0,0,0,0,0,0,0,0,0
0,0,0,0,0,0,0,0,0,0,0,0,0,0
0,0,0,0,0,0,0,0,0,0,0,0,0,0
0,0,0,0,0,0,0,0,0,0,0,0,0,0
0,0,0,0,0,0,0,0,0,0,0,0,0,0
endlayer

layer
0,0,0,0,0,0,0,0,0,0,0,0,0,0
0,0,0,0,0,0,0,0,0,0,0,0,0,0
0,0,0,0,0,0,0,0,0,0,0,0,0,0
0,0,0,0,0,0,0,0,0,0,0,0,0,0
0,0,0,0,0,0,0,0,0,0,0,0,0,0
0,0,0,0,0,0,0,0,0,0,0,0,0,0
0,0,0,0,0,0,0,0,0,34,0,0,0,0
0,0,0,0,0,0,0,0,0,0,0,0,0,0
0,0,0,0,0,0,0,0,0,0,0,0,0,0
0,0,0,0,0,0,0,0,0,0,0,0,0,0
0,0,0,0,0,0,0,0,0,0,0,0,0,0
0,0,0,0,0,0,0,0,0,0,0,0,0,0
0,0,0,0,0,0,0,0,0,0,0,0,0,0
endlayer

layer
0,0,0,0,0,0,0,0,0,0,0,0,0,0
0,0,0,0,0,0,0,0,0,0,0,0,0,0
0,0,0,0,0,0,0,0,0,0,0,0,0,0
0,0,0,0,0,0,0,0,0,0,0,0,0,0
0,0,0,0,0,0,0,0,0,0,0,0,0,0
0,0,0,0,0,0,0,0,0,0,0,0,0,0
0,0,0,0,0,0,0,0,0,34,0,0,0,0
0,0,0,0,0,0,0,0,0,0,0,0,0,0
0,0,0,0,0,0,0,0,0,0,0,0,0,0
0,0,0,0,0,0,0,0,0,0,0,0,0,0
0,0,0,0,0,0,0,0,0,0,0,0,0,0
0,0,0,0,0,0,0,0,0,0,0,0,0,0
0,0,0,0,0,0,0,0,0,0,0,0,0,0
endlayer

layer
0,0,0,0,0,0,0,0,0,0,0,0,0,0
0,0,0,0,0,0,0,0,0,0,0,0,0,0
0,0,0,0,0,0,0,0,0,0,0,0,0,0
0,0,0,0,0,0,0,0,0,0,0,0,0,0
0,0,0,0,0,0,0,0,0,0,0,0,0,0
0,0,0,0,0,0,0,0,0,0,0,0,0,0
0,0,0,0,0,0,0,0,0,34,0,0,0,0
0,0,0,0,0,0,0,0,0,0,0,0,0,0
0,0,0,0,0,0,0,0,0,0,0,0,0,0
0,0,0,0,0,0,0,0,0,0,0,0,0,0
0,0,0,0,0,0,0,0,0,0,0,0,0,0
0,0,0,0,0,0,0,0,0,0,0,0,0,0
0,0,0,0,0,0,0,0,0,0,0,0,0,0
endlayer

layer
0,0,0,0,0,0,0,0,0,0,0,0,0,0
0,0,0,0,0,0,0,0,0,0,0,0,0,0
0,0,0,0,0,0,0,0,0,0,0,0,0,0
0,0,0,0,0,0,0,0,0,0,0,0,0,0
0,0,0,0,0,0,0,0,0,0,0,0,0,0
0,0,0,0,0,0,0,0,0,0,0,0,0,0
0,0,0,0,0,0,0,0,0,34,0,0,0,0
0,0,0,0,0,0,0,0,0,0,0,0,0,0
0,0,0,0,0,0,0,0,0,0,0,0,0,0
0,0,0,0,0,0,0,0,0,0,0,0,0,0
0,0,0,0,0,0,0,0,0,0,0,0,0,0
0,0,0,0,0,0,0,0,0,0,0,0,0,0
0,0,0,0,0,0,0,0,0,0,0,0,0,0
endlayer

layer
0,0,0,0,0,0,0,0,0,0,0,0,0,0
0,0,0,0,0,0,0,0,0,0,0,0,0,0
0,0,0,0,0,0,0,0,0,0,0,0,0,0
0,0,0,0,0,0,0,0,0,0,0,0,0,0
0,0,0,0,0,0,0,0,0,0,0,0,0,0
0,0,0,0,0,0,0,0,0,0,0,0,0,0
0,0,0,0,0,0,0,0,0,34,0,0,0,0
0,0,0,0,0,0,0,0,0,0,0,0,0,0
0,0,0,0,0,0,0,0,0,0,0,0,0,0
0,0,0,0,0,0,0,0,0,0,0,0,0,0
0,0,0,0,0,0,0,0,0,0,0,0,0,0
0,0,0,0,0,0,0,0,0,0,0,0,0,0
0,0,0,0,0,0,0,0,0,0,0,0,0,0
endlayer

layer
0,0,0,0,0,0,0,0,0,0,0,0,0,0
0,0,0,0,0,0,0,0,0,0,0,0,0,0
0,0,0,0,0,0,0,0,0,0,0,0,0,0
0,0,0,0,0,0,0,0,0,0,0,0,0,0
0,0,0,0,0,0,0,0,0,0,0,0,0,0
0,0,0,0,0,0,0,0,0,0,0,0,0,0
0,0,0,0,0,0,0,0,0,34,0,0,0,0
0,0,0,0,0,0,0,0,0,0,0,0,0,0
0,0,0,0,0,0,0,0,0,0,0,0,0,0
0,0,0,0,0,0,0,0,0,0,0,0,0,0
0,0,0,0,0,0,0,0,0,0,0,0,0,0
0,0,0,0,0,0,0,0,0,0,0,0,0,0
0,0,0,0,0,0,0,0,0,0,0,0,0,0
endlayer

layer
0,0,0,0,0,0,0,0,0,0,0,0,0,0
0,0,0,0,0,0,0,0,0,0,0,0,0,0
0,0,0,0,0,0,0,0,0,0,0,0,0,0
0,0,0,0,0,0,0,0,0,0,0,0,0,0
0,0,0,0,0,0,0,0,0,0,0,0,0,0
0,0,0,0,0,0,0,0,0,0,0,0,0,0
0,0,0,0,0,0,0,0,0,34,0,0,0,0
0,0,0,0,0,0,0,0,0,0,0,0,0,0
0,0,0,0,0,0,0,0,0,0,0,0,0,0
0,0,0,0,0,0,0,0,0,0,0,0,0,0
0,0,0,0,0,0,0,0,0,0,0,0,0,0
0,0,0,0,0,0,0,0,0,0,0,0,0,0
0,0,0,0,0,0,0,0,0,0,0,0,0,0
endlayer

layer
0,0,0,0,0,0,0,0,0,0,0,0,0,0
0,0,0,0,0,0,0,0,0,0,0,0,0,0
0,0,0,0,0,0,0,0,0,0,0,0,0,0
0,0,0,0,0,0,0,0,0,0,0,0,0,0
0,0,0,0,0,0,0,0,0,0,0,0,0,0
0,0,0,0,0,0,0,0,0,0,0,0,0,0
0,0,0,0,0,0,0,0,0,34,0,0,0,0
0,0,0,0,0,0,0,0,0,0,0,0,0,0
0,0,0,0,0,0,0,0,0,0,0,0,0,0
0,0,0,0,0,0,0,0,0,0,0,0,0,0
0,0,0,0,0,0,0,0,0,0,0,0,0,0
0,0,0,0,0,0,0,0,0,0,0,0,0,0
0,0,0,0,0,0,0,0,0,0,0,0,0,0
endlayer

layer
0,0,0,0,0,0,0,0,0,0,0,0,0,0
0,0,0,0,0,0,0,0,0,0,0,0,0,0
0,0,0,0,0,0,0,0,0,0,0,0,0,0
0,0,0,0,0,0,0,0,0,0,0,0,0,0
0,0,0,0,0,0,0,0,0,0,0,0,0,0
0,0,0,0,0,0,0,0,0,0,0,0,0,0
0,0,0,0,0,0,0,0,0,34,0,0,0,0
0,0,0,0,0,0,0,0,0,0,0,0,0,0
0,0,0,0,0,0,0,0,0,0,0,0,0,0
0,0,0,0,0,0,0,0,0,0,0,0,0,0
0,0,0,0,0,0,0,0,0,0,0,0,0,0
0,0,0,0,0,0,0,0,0,0,0,0,0,0
0,0,0,0,0,0,0,0,0,0,0,0,0,0
endlayer

layer
0,0,0,0,0,0,0,0,0,0,0,0,0,0
0,0,0,0,0,0,0,0,0,0,0,0,0,0
0,0,0,0,0,0,0,0,0,0,0,0,0,0
0,0,0,0,0,0,0,0,0,0,0,0,0,0
0,0,0,0,0,0,0,0,0,0,0,0,0,0
0,0,0,0,0,0,0,0,0,0,0,0,0,0
0,0,0,0,0,0,0,0,0,34,0,0,0,0
0,0,0,0,0,0,0,0,0,0,0,0,0,0
0,0,0,0,0,0,0,0,0,0,0,0,0,0
0,0,0,0,0,0,0,0,0,0,0,0,0,0
0,0,0,0,0,0,0,0,0,0,0,0,0,0
0,0,0,0,0,0,0,0,0,0,0,0,0,0
0,0,0,0,0,0,0,0,0,0,0,0,0,0
endlayer

layer
0,0,0,0,0,0,0,0,0,0,0,0,0,0
0,0,0,0,0,0,0,0,0,0,0,0,0,0
0,0,0,0,0,0,0,0,0,0,0,0,0,0
0,0,0,0,0,0,0,0,0,0,0,0,0,0
0,0,0,0,0,0,0,0,0,0,0,0,0,0
0,0,0,0,0,0,0,0,0,0,0,0,0,0
0,0,0,0,0,0,0,0,0,36,0,0,0,0
0,0,0,0,0,0,0,0,0,0,0,0,0,0
0,0,0,0,0,0,0,0,0,0,0,0,0,0
0,0,0,0,0,0,0,0,0,0,0,0,0,0
0,0,0,0,0,0,0,0,0,0,0,0,0,0
0,0,0,0,0,0,0,0,0,0,0,0,0,0
0,0,0,0,0,0,0,0,0,0,0,0,0,0
endlayer

