
# Created by Ruins mod version 15.3 Ingame Parser
# authoring Player: Mensrea

weight=15
embed_into_distance=5
acceptable_target_blocks=
unacceptable_target_blocks=flowing_water,water,flowing_lava,lava
dimensions=9,10,10
allowable_overhang=0
max_leveling=2
leveling_buffer=0
preserve_water=0
preserve_lava=0
preventRotation=1

rule1=0,100,IW:concrete-0
rule2=0,100,minecraft:bed-9
rule3=0,100,ChestGenHook:strongholdCorridor:5-2
rule4=0,100,minecraft:planks-0
rule5=0,100,minecraft:bed-1
rule6=0,100,IW:steelsiding-0
rule7=0,100,IW:metalladder-5
rule8=0,100,minecraft:jungle_stairs-1
rule9=0,100,minecraft:jungle_stairs-0
rule10=0,100,IW:lightred-0
rule11=0,100,IW:glassblack-0
rule12=0,100,IW:concreteslab-0
rule13=0,100,AdvancedRepulsionSystems:DeFenceBW-0
rule14=0,100,IW:metalhatch-1

layer
1,1,1,1,1,1,1,1,1,1
1,1,1,1,1,1,1,1,1,1
1,1,1,1,1,1,1,1,1,1
1,1,1,1,1,1,1,1,1,1
1,1,1,1,1,1,1,1,1,1
1,1,1,1,1,1,1,1,1,1
1,1,1,1,1,1,1,1,1,1
1,1,1,1,1,1,1,1,1,1
1,1,1,1,1,1,1,1,1,1
1,1,1,1,1,1,1,1,1,1
endlayer

layer
1,1,1,1,1,1,1,1,1,1
1,4,4,3,0,0,0,0,2,1
1,0,0,0,0,0,0,0,5,1
1,0,0,0,0,4,0,0,4,1
1,0,0,0,0,6,0,0,0,1
1,8,4,0,0,7,0,0,0,1
1,0,0,9,0,0,0,0,0,1
1,0,0,0,0,0,0,0,4,1
1,0,0,0,0,0,0,0,4,1
1,1,1,1,1,1,1,1,1,1
endlayer

layer
1,1,1,1,1,1,1,1,1,1
1,4,4,0,0,0,0,0,0,1
1,0,0,0,0,0,0,0,0,1
1,0,0,0,0,0,0,0,0,1
1,0,0,0,0,6,0,0,0,1
1,0,0,0,0,7,0,0,0,1
1,0,0,0,0,0,0,0,0,1
1,0,0,0,0,0,0,0,4,1
1,0,0,0,0,0,0,0,4,1
1,1,1,1,1,1,1,1,1,1
endlayer

layer
1,1,1,1,1,1,1,1,1,1
1,1,1,1,1,1,1,1,1,1
1,1,10,1,1,1,1,10,1,1
1,1,1,1,1,1,1,1,1,1
1,1,1,1,1,1,1,1,1,1
1,1,1,1,1,7,1,1,1,1
1,1,1,1,1,1,1,1,1,1
1,1,10,1,1,1,1,10,1,1
1,1,1,1,1,1,1,1,1,1
1,1,1,1,1,1,1,1,1,1
endlayer

layer
1,1,1,1,1,1,1,1,1,1
1,1,1,1,1,1,1,1,1,1
1,1,0,11,11,11,0,0,1,1
1,1,0,0,0,0,0,11,1,1
1,1,11,0,0,1,0,11,1,1
1,1,11,0,0,7,0,11,1,1
1,1,11,0,0,0,0,0,1,1
1,1,0,0,11,11,11,0,1,1
1,1,1,1,1,1,1,1,1,1
1,1,1,1,1,1,1,1,1,1
endlayer

layer
1,1,1,1,1,1,1,1,1,1
1,1,1,0,0,0,0,1,1,1
1,1,0,11,11,11,0,0,1,1
1,0,0,0,0,0,0,11,0,1
1,0,11,0,0,1,0,11,0,1
1,0,11,0,0,7,0,11,0,1
1,0,11,0,0,0,0,0,0,1
1,1,0,0,11,11,11,0,1,1
1,1,1,0,0,0,0,1,1,1
1,1,1,1,1,1,1,1,1,1
endlayer

layer
12,12,0,0,0,0,0,0,12,12
12,1,1,0,0,0,0,1,1,12
0,1,0,11,11,11,0,0,1,0
0,0,0,0,0,0,0,11,0,0
0,0,11,0,0,1,0,11,0,0
0,0,11,0,0,7,0,11,0,0
0,0,11,0,0,0,0,0,0,0
0,1,0,0,11,11,11,0,1,0
12,1,1,0,0,0,0,1,1,12
12,12,0,0,0,0,0,0,12,12
endlayer

layer
0,0,0,12,12,12,12,0,0,0
0,13,12,1,1,1,1,12,13,0
0,12,1,1,1,1,1,1,12,0
12,1,1,1,1,1,1,1,1,12
12,1,1,1,1,1,1,1,1,12
12,1,1,1,1,7,1,1,1,12
12,1,1,1,1,1,1,1,1,12
0,12,1,1,1,1,1,1,12,0
0,13,12,1,1,1,1,12,13,0
0,0,0,12,12,12,12,0,0,0
endlayer

layer
0,0,0,0,0,0,0,0,0,0
0,0,0,13,13,13,13,0,0,0
0,0,0,12,12,12,12,0,0,0
0,13,12,12,1,1,12,12,13,0
0,13,12,1,0,0,1,12,13,0
0,13,12,1,0,14,1,12,13,0
0,13,12,12,1,1,12,12,13,0
0,0,0,12,12,12,12,0,0,0
0,0,0,13,13,13,13,0,0,0
0,0,0,0,0,0,0,0,0,0
endlayer

