
# Created by Ruins mod version 15.3 Ingame Parser
# authoring Player: Mensrea

weight=6
embed_into_distance=7
acceptable_target_blocks=
unacceptable_target_blocks=flowing_water,water,flowing_lava,lava
dimensions=13,22,27
allowable_overhang=0
max_leveling=2
leveling_buffer=0
preserve_water=0
preserve_lava=0
preventRotation=1

rule1=0,100,PFAAGeologica:strongStone-7
rule2=0,100,PFAAGeologica:mediumStone-3
rule3=0,100,minecraft:stonebrick-0
rule4=0,100,minecraft:water-0
rule5=0,100,PFAAGeologica:weakStone-1
rule6=0,100,minecraft:planks-0
rule7=0,100,minecraft:spruce_stairs-1
rule8=0,100,minecraft:carpet-8
rule9=0,100,flansmod:flansWorkbench-1
rule10=0,100,minecraft:ladder-4
rule11=0,100,ChestGenHook:strongholdCorridor:5-2
rule12=0,100,minecraft:spruce_stairs-3
rule13=0,100,minecraft:spruce_stairs-2
rule14=0,100,ChestGenHook:strongholdCorridor:5-2
rule15=0,100,ChestGenHook:strongholdCorridor:5-2
rule16=0,100,ChestGenHook:strongholdCorridor:5-2
rule17=0,100,IW:smalllightwhite-1
rule18=0,100,IW:smalllightwhite-2
rule19=0,100,minecraft:sand-1
rule20=0,100,IW:steelsiding-0
rule21=0,100,minecraft:oak_stairs-0
rule22=0,100,minecraft:gravel-0
rule23=0,100,PFAAGeologica:strongStoneBrick-3
rule24=0,100,minecraft:fence-0
rule25=0,100,minecraft:stone_brick_stairs-1
rule26=0,100,IInventory;minecraft:furnace;minecraft:coal#7#0#1-2
rule27=0,100,IW:concretestairs-1
rule28=0,100,IW:steelblock-0
rule29=0,100,minecraft:farmland-7
rule30=0,100,minecraft:stone_brick_stairs-3
rule31=0,100,minecraft:stone_brick_stairs-2
rule32=0,100,IW:glassblack-0
rule33=0,100,IW:fiberboard-0
rule34=0,100,minecraft:wheat-6
rule35=0,100,minecraft:wheat-7
rule36=0,100,minecraft:wheat-3
rule37=0,100,minecraft:wheat-4
rule38=0,100,minecraft:wheat-2
rule39=0,100,minecraft:planks-1
rule40=0,100,minecraft:cauldron-0
rule41=0,100,PFAAGeologica:strongStoneBrickStairs.marble-1
rule42=0,100,minecraft:glass-0
rule43=0,100,ImmersiveEngineering:metalDecoration-0
rule44=0,100,minecraft:bed-10
rule45=0,100,minecraft:bed-2
rule46=0,100,ChestGenHook:mineshaftCorridor:5-2
rule47=0,100,ChestGenHook:mineshaftCorridor:5-2
rule48=0,100,minecraft:wheat-5
rule49=0,100,IW:metaldoor-0
rule50=0,100,IW:metaldoor-1
rule51=0,100,minecraft:bed-0
rule52=0,100,minecraft:bed-8
rule53=0,100,IW:metaldoor-3
rule54=0,100,ChestGenHook:mineshaftCorridor:5-2
rule55=0,100,minecraft:bookshelf-0
rule56=0,100,minecraft:wheat-1
rule57=0,100,minecraft:spruce_stairs-0
rule58=0,100,IW:computer1-0
rule59=0,100,ThermalExpansion:Workbench-1
rule60=0,100,minecraft:cauldron-3
rule61=0,100,minecraft:furnace-4
rule62=0,100,minecraft:wooden_door-2
rule63=0,100,IInventory;minecraft:chest;ThermalFoundation:tool.sicklePlatinum#1#0#0+minecraft:wheat_seeds#64#0#1+minecraft:wheat_seeds#8#0#2+ThermalFoundation:tool.hoePlatinum#1#0#3+minecraft:dye#58#15#4+minecraft:sapling#5#0#5+IC2:itemCellEmpty#49#1#6-3
rule64=0,100,IW:smalllightwhite-3
rule65=0,100,IW:smalllightwhite-4
rule66=0,100,IW:metaldoor-8
rule67=0,100,minecraft:wooden_pressure_plate-0
rule68=0,100,minecraft:stained_glass-15
rule69=0,100,minecraft:wooden_door-8
rule70=0,100,IW:scrapmetalsheet-0
rule71=0,100,IW:machinery1-0
rule72=0,100,IC2:blockGenerator-3
rule73=0,100,PFAAGeologica:strongStone-3

layer
1,1,1,1,1,1,1,1,1,1,1,1,1,1,1,1,1,1,1,1,1,1,1,1,1,1,1
1,1,1,1,1,1,1,1,1,1,1,1,1,1,1,1,1,1,1,1,1,1,1,1,1,1,1
1,1,1,1,1,1,1,1,1,1,1,1,1,1,1,1,1,1,1,1,1,1,1,1,1,1,1
1,1,1,1,1,1,1,1,1,1,1,1,1,1,1,1,1,1,1,1,1,1,1,1,1,1,1
1,1,1,1,1,1,1,1,1,1,1,1,1,1,1,1,1,1,1,1,1,1,1,1,1,1,1
1,1,1,1,1,1,1,1,1,1,1,1,1,1,1,1,1,1,1,1,1,1,1,1,1,1,1
1,1,1,1,1,1,1,1,1,1,1,1,1,1,1,1,1,1,1,1,1,1,1,1,1,1,1
1,1,1,1,1,1,1,1,1,1,1,1,1,1,1,1,1,1,1,1,1,1,1,1,1,1,1
1,1,1,1,1,1,1,1,1,1,1,1,1,1,1,1,1,1,1,1,1,1,1,1,1,1,1
1,1,1,1,1,1,1,1,1,1,1,1,1,1,1,1,1,1,1,1,1,1,1,1,1,1,1
1,1,1,1,1,1,1,1,1,1,1,1,1,1,1,1,1,1,1,1,1,1,1,1,1,1,1
1,1,1,1,1,1,1,1,1,1,1,1,1,1,1,1,1,1,1,1,1,1,1,1,1,1,1
1,1,1,1,1,1,1,1,1,1,1,1,1,1,1,1,1,1,1,1,1,1,1,1,1,1,1
1,1,1,1,1,1,1,1,1,1,1,1,1,1,1,1,1,1,1,1,1,1,1,1,1,1,1
1,1,1,1,1,1,1,1,1,1,1,1,1,1,1,1,1,1,1,1,1,1,1,1,1,1,1
1,1,1,1,1,1,1,1,1,1,1,1,1,1,1,1,1,1,1,1,1,1,1,1,1,1,1
1,1,1,1,1,1,1,1,1,1,1,1,1,1,1,1,1,1,1,1,1,1,1,1,1,1,1
1,1,1,1,1,1,1,1,1,1,1,1,1,1,1,1,1,1,1,1,1,1,1,1,1,1,1
1,1,1,1,1,1,1,1,1,1,1,1,1,1,1,1,1,1,1,1,1,1,1,1,1,1,1
1,1,1,1,1,1,1,1,1,1,1,1,1,1,1,1,1,1,1,1,1,1,1,1,1,1,1
1,1,1,1,1,1,1,1,1,1,1,1,1,1,1,1,1,1,1,1,1,1,1,1,1,1,1
1,1,1,1,1,1,1,1,1,1,1,1,1,1,1,1,1,1,1,1,1,1,1,1,1,1,1
endlayer

layer
2,2,2,2,2,2,2,2,2,2,2,2,2,2,2,2,2,2,2,2,2,2,2,2,2,2,2
2,2,2,2,2,2,2,2,2,2,2,2,2,2,2,2,2,2,2,2,2,2,2,2,2,2,2
2,2,2,2,2,2,2,2,2,2,2,2,2,2,2,2,2,2,2,2,2,2,2,2,2,2,2
2,2,2,2,2,2,2,2,2,2,2,2,2,2,2,2,2,2,2,2,2,2,2,2,2,2,2
2,2,2,2,2,2,2,2,2,2,2,2,2,2,2,2,2,2,2,2,2,2,2,2,2,2,2
2,2,2,2,2,2,2,2,2,2,2,2,2,2,2,2,2,2,2,2,2,2,2,2,2,2,2
2,2,2,2,2,2,2,2,2,2,2,2,2,2,2,2,2,2,2,2,2,2,2,2,2,2,2
2,2,2,2,2,2,2,2,2,2,2,2,2,2,2,2,2,2,2,2,2,2,2,2,2,2,2
2,2,2,2,2,2,2,2,2,2,2,2,2,2,2,2,2,2,2,2,2,2,2,2,2,2,2
2,2,2,2,2,2,2,2,2,2,2,2,2,2,2,2,2,3,3,3,3,3,3,3,3,2,2
2,2,2,2,2,2,2,2,2,2,2,2,2,2,2,2,2,3,3,3,3,3,3,3,3,2,2
2,2,2,2,2,2,2,2,2,2,2,2,2,2,2,2,2,3,3,3,3,3,3,3,3,2,2
2,2,2,2,2,2,2,2,2,2,2,2,2,2,2,2,2,3,3,3,3,3,3,3,3,2,2
2,2,2,2,2,2,2,2,2,2,2,2,2,2,2,2,2,3,3,3,3,3,3,3,3,2,2
2,2,2,2,2,2,2,2,2,2,2,2,2,2,2,2,2,3,3,3,3,3,3,3,3,2,2
2,2,2,2,2,2,2,2,2,2,2,2,2,2,2,2,2,3,3,3,3,3,3,3,3,2,2
2,2,2,2,2,2,2,2,2,2,2,2,2,2,2,2,2,3,3,3,3,3,3,3,3,2,2
2,2,2,2,2,2,2,2,2,2,2,2,2,2,2,2,2,2,2,2,2,2,3,3,3,2,2
2,2,2,2,2,2,2,2,2,2,2,2,2,2,2,2,2,2,2,2,2,2,3,3,3,2,2
2,2,2,2,2,2,2,2,2,2,2,2,2,2,2,2,2,2,2,2,2,2,3,3,3,2,2
2,2,2,2,2,2,2,2,2,2,2,2,2,2,2,2,2,2,2,2,2,2,2,2,2,2,2
2,2,2,2,2,2,2,2,2,2,2,2,2,2,2,2,2,2,2,2,2,2,2,2,2,2,2
endlayer

layer
2,2,2,2,2,2,2,2,2,2,2,2,2,2,2,2,2,2,2,2,2,2,2,2,2,2,2
2,2,2,2,2,2,2,2,2,2,2,2,2,2,2,2,2,2,2,2,2,2,2,2,2,2,2
2,2,2,2,2,2,2,2,2,2,2,2,2,2,2,2,2,2,2,2,2,2,2,2,2,2,2
2,2,2,2,2,2,2,2,2,2,2,2,2,2,2,2,2,2,2,2,2,2,2,2,2,2,2
2,2,2,2,2,2,2,2,2,2,2,2,2,2,2,2,2,2,2,2,2,2,2,2,2,2,2
2,2,2,2,2,2,2,2,2,2,2,2,2,2,2,2,2,2,2,2,2,2,2,2,2,2,2
2,2,2,2,2,2,2,2,2,2,2,2,2,2,2,2,2,2,2,2,2,2,2,2,2,2,2
2,2,2,2,2,2,2,2,2,2,2,2,2,2,2,2,2,2,2,2,2,2,2,2,2,2,2
2,2,2,2,2,2,2,2,2,2,2,2,2,2,2,2,2,2,2,2,2,2,2,2,2,2,2
2,2,2,2,2,2,2,2,2,2,2,2,2,2,2,2,2,3,3,3,3,3,3,3,3,2,2
2,2,2,2,2,2,2,2,2,2,2,2,2,2,2,2,2,3,4,4,4,4,4,4,3,2,2
2,2,2,2,2,2,2,2,2,2,2,2,2,2,2,2,2,3,4,4,4,4,4,4,3,2,2
2,2,2,2,2,2,2,2,2,2,2,2,2,2,2,2,2,3,4,4,4,4,4,4,3,2,2
2,2,2,2,2,2,2,2,2,2,2,2,2,2,2,2,2,3,4,4,4,4,4,4,3,2,2
2,2,2,2,2,2,2,2,2,2,2,2,2,2,2,2,2,3,4,4,4,4,4,4,3,2,2
2,2,2,2,2,2,2,2,2,2,2,2,2,2,2,2,2,3,4,4,4,4,4,4,3,2,2
2,2,2,2,2,2,2,2,2,2,2,2,2,2,2,2,2,3,3,3,3,3,3,4,3,2,2
2,2,2,2,2,2,2,2,2,2,2,2,2,2,2,2,2,2,2,2,2,2,3,4,3,2,2
2,2,2,2,2,2,2,2,2,2,2,2,2,2,2,2,2,2,2,2,2,2,3,2,3,2,2
2,2,2,2,2,2,2,2,2,2,2,2,2,2,2,2,2,2,2,2,2,2,3,3,3,2,2
2,2,2,2,2,2,2,2,2,2,2,2,2,2,2,2,2,2,2,2,2,2,2,2,2,2,2
2,2,2,2,2,2,2,2,2,2,2,2,2,2,2,2,2,2,2,2,2,2,2,2,2,2,2
endlayer

layer
5,5,5,5,5,5,5,5,5,5,5,5,5,5,5,5,5,5,5,5,5,5,5,5,5,5,5
5,5,5,5,5,5,5,5,5,5,5,5,5,5,5,5,5,5,5,5,5,5,5,5,5,5,5
5,5,5,5,5,5,5,5,5,5,5,5,5,5,5,5,5,5,5,5,5,5,5,5,5,5,5
5,5,5,5,5,5,5,5,5,5,5,5,5,5,5,5,5,5,5,5,5,5,5,5,5,5,5
5,5,5,5,5,5,5,5,5,5,5,5,5,5,5,5,5,5,5,5,5,5,5,5,5,5,5
5,5,5,5,5,5,5,5,5,5,5,5,5,5,5,5,5,5,5,5,5,5,5,5,5,5,5
5,5,5,5,5,5,6,5,5,5,6,6,5,5,6,5,5,5,5,5,5,5,5,5,5,5,5
5,5,5,5,5,5,8,9,8,8,0,0,0,0,7,5,5,5,5,5,5,5,5,5,5,5,5
5,5,5,5,5,5,8,0,0,0,0,0,0,0,0,10,5,5,5,5,5,5,5,5,5,5,5
5,5,5,5,5,5,14,13,0,12,11,6,5,5,6,6,5,3,3,3,3,3,3,3,3,5,5
5,5,5,5,5,5,16,8,0,8,15,5,5,5,5,5,5,3,4,4,4,4,4,4,3,5,5
5,5,5,5,5,5,6,8,0,8,6,5,5,5,5,5,5,3,4,4,4,4,4,4,3,5,5
5,5,5,5,5,5,5,6,0,6,5,5,5,5,5,5,5,3,4,4,4,4,4,4,3,5,5
5,5,5,5,5,5,5,5,0,5,5,5,5,5,5,5,5,3,4,4,4,4,4,4,3,5,5
5,5,5,5,5,5,5,5,0,5,5,5,5,5,5,5,5,3,4,4,4,4,4,4,3,5,5
5,5,5,5,5,5,5,6,0,6,5,5,5,5,5,5,5,3,4,4,4,4,4,4,3,5,5
5,5,5,5,5,5,5,5,0,5,5,5,5,5,5,5,5,3,3,3,3,3,3,4,3,5,5
5,5,5,5,5,5,5,5,0,5,5,5,5,5,5,5,5,5,5,5,5,5,3,4,3,5,5
5,5,5,5,5,5,5,5,0,5,5,5,5,5,5,5,5,5,5,5,5,5,3,5,3,5,5
5,5,5,5,5,5,5,5,5,5,5,5,5,5,5,5,5,5,5,5,5,5,3,3,3,5,5
5,5,5,5,5,5,5,5,5,5,5,5,5,5,5,5,5,5,5,5,5,5,5,5,5,5,5
5,5,5,5,5,5,5,5,5,5,5,5,5,5,5,5,5,5,5,5,5,5,5,5,5,5,5
endlayer

layer
5,5,5,5,5,5,5,5,5,5,5,5,5,5,5,5,5,5,5,5,5,5,5,5,5,5,5
5,5,5,5,5,5,5,5,5,5,5,5,5,5,5,5,5,5,5,5,5,5,5,5,5,5,5
5,5,5,5,5,5,5,5,5,5,5,5,5,5,5,5,5,5,5,5,5,5,5,5,5,5,5
5,5,5,5,5,5,5,5,5,5,5,5,5,5,5,5,5,5,5,5,5,5,5,5,5,5,5
5,5,5,5,5,5,5,5,5,5,5,5,5,5,5,5,5,5,5,5,5,5,5,5,5,5,5
5,5,5,5,5,5,5,5,5,5,5,5,5,5,5,5,5,5,5,5,5,5,5,5,5,5,5
5,5,5,5,5,5,6,5,5,5,6,6,5,5,6,5,5,5,5,5,5,5,5,5,5,5,5
5,5,5,5,5,5,0,0,0,0,0,0,0,0,17,5,5,5,5,5,5,5,5,5,5,5,5
5,5,5,5,5,5,0,0,0,0,0,18,0,0,0,10,5,5,5,5,5,5,5,5,5,5,5
5,5,5,5,5,5,0,0,0,0,0,6,5,5,6,6,5,3,3,3,3,3,3,3,3,5,5
5,5,5,5,5,5,0,0,0,0,0,5,5,5,5,5,5,3,4,4,4,4,4,4,3,5,5
5,5,5,5,5,5,6,0,0,0,6,5,5,5,5,5,5,3,4,4,4,4,4,4,3,5,5
5,5,5,5,5,5,5,6,0,6,5,5,5,5,5,5,5,3,4,4,4,4,4,4,3,5,5
5,5,5,5,5,5,5,5,0,5,5,5,5,5,5,5,5,3,4,4,4,4,4,4,3,5,5
5,5,5,5,5,5,5,5,0,5,5,5,5,5,5,5,5,3,4,4,4,4,4,4,3,5,5
5,5,5,5,5,5,5,6,0,6,5,5,5,5,5,5,5,3,4,4,4,4,4,4,3,5,5
5,5,5,5,5,5,5,5,0,5,5,5,5,5,5,5,5,3,3,3,3,3,3,4,3,5,5
5,5,5,5,5,5,5,5,0,5,5,5,5,5,5,5,5,5,5,5,5,5,3,4,3,5,5
5,5,5,5,5,5,5,5,0,5,5,5,5,5,5,5,5,5,5,5,5,5,3,4,3,5,5
5,5,5,5,5,5,5,5,5,5,5,5,5,5,5,5,5,5,5,5,5,5,3,3,3,5,5
5,5,5,5,5,5,5,5,5,5,5,5,5,5,5,5,5,5,5,5,5,5,5,5,5,5,5
5,5,5,5,5,5,5,5,5,5,5,5,5,5,5,5,5,5,5,5,5,5,5,5,5,5,5
endlayer

layer
19,19,19,19,19,19,19,19,19,19,19,19,19,19,19,19,19,19,19,19,19,19,19,19,19,19,19
19,19,19,19,19,19,19,19,19,19,19,19,19,19,19,19,19,19,19,19,19,19,19,19,19,19,19
19,19,19,19,19,19,19,19,19,19,19,19,19,19,19,19,19,19,19,19,19,19,19,19,19,19,19
19,19,19,19,19,19,19,19,19,19,19,19,19,19,19,19,19,19,19,19,19,19,19,19,19,19,19
19,19,19,19,19,19,19,19,19,19,19,19,19,19,19,19,19,19,19,19,19,19,19,19,19,19,19
19,19,19,19,19,19,19,19,19,19,19,19,19,19,19,19,19,19,19,19,19,19,19,19,19,19,19
19,19,19,19,19,19,6,6,6,6,6,19,19,19,19,19,19,19,19,19,19,19,19,19,19,19,19
19,19,19,19,19,6,17,0,0,0,0,6,6,6,6,19,19,19,19,19,19,19,19,19,19,19,19
19,19,19,19,19,6,0,0,0,0,0,6,6,6,6,10,19,19,19,19,19,19,19,19,19,19,19
19,19,19,19,19,6,0,0,0,0,0,6,19,19,19,6,19,3,3,3,3,3,3,3,3,19,19
19,19,19,19,19,6,18,0,0,0,18,6,19,19,19,19,19,3,3,3,3,3,3,3,3,19,19
19,19,19,19,19,19,6,0,0,0,6,19,19,19,19,19,19,3,3,3,3,3,3,3,3,19,19
19,19,19,19,19,19,19,6,6,6,19,19,19,19,19,19,19,3,3,3,3,3,3,3,3,19,19
19,19,19,19,19,19,19,19,6,19,19,19,19,19,19,19,19,3,3,3,3,3,20,3,3,19,19
19,19,19,19,19,19,19,19,6,19,19,19,19,19,19,19,19,3,3,3,3,3,3,3,3,3,19
19,19,19,19,19,19,19,19,6,19,19,19,19,19,19,19,19,3,3,3,3,3,3,3,3,19,19
19,19,19,19,19,19,19,19,6,19,19,19,19,19,19,19,19,3,3,3,3,3,3,3,3,19,19
19,19,19,19,19,19,19,19,6,19,19,19,19,19,19,19,19,19,19,19,19,19,3,3,3,19,19
19,19,19,19,19,19,19,19,0,19,19,19,19,19,19,19,19,19,19,19,19,19,3,0,3,19,19
19,19,19,19,19,19,19,19,19,19,19,19,19,19,19,19,19,19,19,19,19,19,3,3,3,19,19
19,19,19,19,19,19,19,19,19,19,19,19,19,19,19,19,19,19,19,19,19,19,19,19,19,19,19
19,19,19,19,19,19,19,19,19,19,19,19,19,19,19,19,19,19,19,19,19,19,19,19,19,19,19
endlayer

layer
19,19,19,19,0,0,19,19,19,19,19,19,19,19,19,0,0,0,19,19,19,19,19,19,19,0,0
19,19,19,19,19,19,19,19,19,19,19,19,19,19,19,19,0,19,19,19,19,19,19,19,19,19,0
19,19,19,19,19,19,19,19,19,19,19,19,19,3,19,19,19,19,19,3,19,19,19,19,19,3,19
19,19,19,19,19,19,19,19,19,19,19,19,19,19,19,19,19,19,19,19,19,19,19,19,19,19,19
19,19,19,19,19,19,19,19,19,19,19,19,19,19,19,6,0,6,0,19,19,19,19,19,19,19,19
19,19,19,19,19,19,19,19,19,19,19,19,19,19,19,6,0,6,0,0,0,19,19,19,19,19,19
0,19,19,19,19,19,0,19,19,0,19,19,19,19,19,0,0,0,0,0,0,19,19,19,19,19,19
0,19,19,19,19,0,6,6,6,6,6,19,19,19,19,0,0,6,6,0,0,0,19,19,19,19,0
0,19,19,19,19,19,6,6,6,6,6,19,19,19,19,6,0,6,6,0,6,0,19,19,19,19,0
19,19,19,19,19,0,6,6,6,6,6,19,0,0,0,6,0,0,0,0,0,19,19,19,19,19,0
19,19,19,19,19,0,6,6,6,6,6,19,0,0,0,0,0,0,6,0,19,19,19,19,19,19,19
19,19,19,19,19,19,6,6,6,6,6,19,21,19,19,6,0,0,0,19,19,19,19,19,19,19,19
19,19,19,19,19,19,19,0,19,0,19,19,19,19,19,6,0,6,19,19,19,19,19,19,19,19,19
19,19,19,19,19,19,19,19,19,19,19,19,19,19,19,19,19,19,19,19,19,19,20,19,19,19,19
19,19,19,19,19,19,19,19,19,19,19,19,19,3,19,19,19,19,19,3,19,19,19,19,19,3,19
19,19,19,19,19,19,19,0,19,19,19,19,19,19,19,19,19,22,22,19,22,22,19,19,19,19,19
19,19,19,19,19,19,19,19,19,19,19,19,19,19,19,22,22,22,22,22,22,22,22,22,19,19,19
19,19,19,19,19,19,19,19,19,19,19,19,19,19,22,22,22,22,22,22,22,22,20,20,20,19,19
19,19,19,19,19,19,19,19,0,19,19,19,19,22,22,22,22,22,22,22,22,22,20,20,20,22,19
19,19,19,19,19,22,22,22,19,19,19,19,19,22,22,22,22,22,22,22,22,22,20,20,20,22,19
19,19,19,19,19,22,22,22,22,22,22,22,22,22,22,22,22,22,22,22,22,22,22,22,22,19,0
19,19,19,0,0,19,19,19,19,19,19,0,0,0,19,22,22,22,22,22,19,22,19,19,19,0,0
endlayer

layer
19,19,0,0,0,0,0,0,19,19,19,0,0,0,0,0,0,0,0,0,0,0,0,0,0,0,0
19,23,23,23,23,23,23,23,23,23,23,23,0,0,0,0,0,0,0,0,0,0,0,19,19,0,0
0,23,23,23,23,23,23,23,23,23,23,23,0,3,0,0,0,0,0,3,0,0,0,0,0,3,0
0,23,23,23,23,23,23,23,23,23,23,23,0,0,0,0,0,0,0,0,0,0,0,0,0,0,0
0,23,23,23,23,23,23,23,23,23,23,23,0,0,0,0,0,0,0,0,0,0,0,0,0,0,0
0,23,23,23,23,23,23,23,23,23,23,23,0,0,0,0,0,0,0,0,0,0,0,0,0,0,0
0,23,23,23,23,23,23,23,23,23,23,23,0,0,0,0,0,0,0,0,0,0,0,0,0,0,0
0,23,23,23,23,23,23,23,23,23,23,23,0,0,0,0,0,0,0,0,0,0,0,0,0,0,0
0,23,23,23,23,23,23,23,23,23,23,23,0,0,0,0,0,0,0,0,0,0,0,0,0,0,0
0,23,23,23,23,23,23,23,23,23,23,23,0,0,0,0,0,0,0,0,0,0,0,0,0,0,0
0,23,23,23,23,23,23,23,23,23,23,23,0,0,0,0,0,0,0,0,0,0,0,0,0,0,0
0,23,23,23,23,23,23,23,23,23,23,23,0,0,0,0,0,0,0,0,0,0,0,0,0,0,0
0,23,23,23,23,23,23,23,23,23,23,23,0,0,0,0,0,0,0,0,0,0,0,0,0,0,0
0,23,23,23,23,23,23,23,23,23,23,23,0,0,0,0,0,0,0,0,0,0,20,0,0,0,0
0,23,23,23,23,23,23,23,23,23,23,23,0,3,0,0,0,0,0,3,0,0,0,0,0,3,19
0,23,23,23,23,23,23,23,23,23,23,23,0,19,0,0,3,0,0,0,0,0,0,0,19,19,19
0,23,23,23,23,23,23,23,23,23,23,23,0,0,0,24,25,24,0,0,0,0,0,0,0,19,0
19,23,23,23,23,23,23,23,23,23,23,23,0,0,0,0,0,0,0,0,0,0,0,0,0,0,0
19,23,23,23,23,23,23,23,23,23,23,23,0,0,26,0,0,0,0,0,0,0,0,0,0,0,0
0,19,19,19,0,27,27,27,0,0,0,0,0,0,0,0,0,0,0,0,0,0,0,0,0,0,0
0,0,19,0,0,0,0,0,0,0,0,0,0,0,0,0,0,0,0,0,0,0,0,0,0,0,0
0,0,0,0,0,0,0,0,0,0,0,0,0,0,0,0,0,0,0,0,0,0,0,0,0,0,0
endlayer

layer
0,0,0,0,0,0,0,0,0,0,0,0,0,0,0,0,0,0,0,0,0,0,0,0,0,0,0
0,23,23,23,23,23,23,23,23,23,23,23,0,0,0,0,0,0,0,0,0,0,0,0,0,0,0
0,23,29,29,29,29,29,29,29,29,29,23,0,28,28,28,28,28,28,28,28,28,28,28,28,28,0
0,23,29,29,29,29,29,29,29,29,29,23,0,28,20,20,20,20,20,28,20,20,20,20,20,28,0
0,23,29,29,29,29,29,29,29,29,29,23,0,28,20,20,20,20,20,28,20,20,20,20,20,28,0
0,23,29,29,29,29,3,29,29,29,29,23,0,28,20,20,20,20,20,28,20,20,20,20,20,28,0
0,23,29,29,29,29,4,29,29,29,29,23,0,28,20,20,20,20,20,28,20,20,20,20,20,28,0
0,23,29,29,29,29,4,29,29,29,29,23,0,28,20,20,20,20,20,28,20,20,20,20,20,28,0
0,23,29,29,29,29,4,29,29,29,29,23,0,28,20,20,20,20,20,28,20,20,20,20,20,28,0
0,23,29,29,29,29,4,29,29,29,29,23,0,28,20,20,20,20,20,28,20,20,20,20,20,28,0
0,23,29,29,29,29,4,29,29,29,29,23,0,28,20,20,20,20,20,28,20,20,20,20,20,28,0
0,23,29,29,29,29,4,29,29,29,29,23,0,28,20,20,20,20,20,28,20,20,20,20,20,28,0
0,23,29,29,29,29,4,29,29,29,29,23,0,28,20,20,20,20,20,28,20,20,20,20,20,28,0
0,23,29,29,29,29,4,29,29,29,29,23,0,28,20,20,20,20,20,28,20,20,20,20,20,28,0
0,23,29,29,29,29,3,29,29,29,29,23,0,28,28,28,28,28,28,28,28,28,28,28,28,28,0
0,23,29,29,29,29,29,29,29,29,29,23,0,0,0,24,25,24,0,0,0,0,0,0,0,19,0
0,23,3,3,3,3,3,3,3,3,3,23,0,0,0,24,0,24,0,0,0,0,0,0,0,0,0
0,23,3,31,0,0,0,0,0,30,3,23,0,0,0,0,0,0,0,0,0,0,0,0,0,0,0
0,23,23,23,23,0,0,0,23,23,23,23,0,0,0,0,0,0,0,0,0,0,0,0,0,0,0
0,0,19,0,0,0,0,0,0,0,0,0,0,0,0,0,0,0,0,0,0,0,0,0,0,0,0
0,0,0,0,0,0,0,0,0,0,0,0,0,0,0,0,0,0,0,0,0,0,0,0,0,0,0
0,0,0,0,0,0,0,0,0,0,0,0,0,0,0,0,0,0,0,0,0,0,0,0,0,0,0
endlayer

layer
0,0,0,0,0,0,0,0,0,0,0,0,0,0,0,0,0,0,0,0,0,0,0,0,0,0,0
0,23,23,32,32,32,32,32,32,32,23,23,0,0,0,0,0,0,0,0,0,0,0,0,0,0,0
0,32,38,35,37,35,34,36,34,35,34,32,0,28,33,33,33,33,33,28,33,33,33,33,33,28,0
0,32,37,35,48,36,35,35,35,37,34,32,0,33,47,46,0,45,44,33,43,42,41,40,39,33,0
0,32,36,34,34,38,35,35,34,34,36,32,0,33,0,0,0,45,44,33,0,0,0,0,0,33,0
0,32,35,36,48,48,20,34,34,35,37,32,0,33,49,33,33,33,33,33,33,33,33,33,49,33,0
0,32,34,35,35,35,20,35,35,35,48,32,0,33,0,33,0,45,44,33,39,0,0,33,0,33,0
0,32,35,38,48,38,20,34,34,35,35,32,0,33,0,53,0,0,12,33,52,51,0,50,0,33,0
0,32,35,48,34,34,20,35,35,35,35,32,0,33,0,33,54,0,39,33,13,0,0,33,0,33,0
0,32,37,35,35,35,20,35,34,34,35,32,0,33,0,33,33,33,33,33,33,33,33,33,0,33,0
0,32,35,35,35,37,20,56,35,48,34,32,0,33,0,0,7,0,0,55,7,7,7,0,0,33,0
0,32,38,35,56,36,20,35,35,35,48,32,0,33,0,13,24,7,0,0,0,0,0,0,12,33,0
0,32,48,34,48,35,20,34,37,35,34,32,0,33,0,0,57,0,0,0,0,0,0,0,12,33,0
0,32,48,35,35,37,20,37,34,35,38,32,0,33,61,0,0,0,60,59,39,58,39,0,55,33,0
0,32,37,37,37,37,20,34,34,35,34,32,0,28,33,33,62,33,33,28,33,33,33,33,33,28,0
0,32,35,37,37,38,34,48,35,37,35,32,0,0,0,24,0,24,0,0,0,0,0,0,0,0,0
0,32,0,0,0,0,0,0,0,0,0,32,0,0,0,0,0,0,0,0,0,0,0,0,0,0,0
0,32,0,0,0,0,0,0,0,0,63,32,0,0,0,0,0,0,0,0,0,0,0,0,0,0,0
0,23,32,32,23,0,0,0,23,32,32,23,0,0,0,0,0,0,0,0,0,0,0,0,0,0,0
0,0,0,0,0,0,0,0,0,0,0,0,0,0,0,0,0,0,0,0,0,0,0,0,0,0,0
0,0,0,0,0,0,0,0,0,0,0,0,0,0,0,0,0,0,0,0,0,0,0,0,0,0,0
0,0,0,0,0,0,0,0,0,0,0,0,0,0,0,0,0,0,0,0,0,0,0,0,0,0,0
endlayer

layer
0,0,0,0,0,0,0,0,0,0,0,0,0,0,0,0,0,0,0,0,0,0,0,0,0,0,0
0,23,23,32,32,32,32,32,32,32,23,23,0,0,0,0,0,0,0,0,0,0,0,0,0,0,0
0,32,0,0,0,0,0,0,0,0,0,32,0,28,33,33,42,33,33,28,33,33,33,42,33,28,0
0,32,0,0,0,0,0,0,0,0,0,32,0,33,65,0,0,0,64,33,43,42,17,0,17,33,0
0,32,0,0,0,0,0,0,0,0,0,32,0,33,0,0,0,0,0,33,0,0,0,0,0,33,0
0,32,0,0,0,0,0,0,0,0,0,32,0,33,66,33,33,33,33,33,33,33,33,33,66,33,0
0,32,0,0,0,0,0,0,0,0,0,32,0,33,0,33,0,0,0,33,0,0,0,33,0,33,0
0,32,0,0,0,0,0,0,0,0,0,32,0,42,0,66,0,0,64,33,65,0,0,66,0,42,0
0,32,0,0,0,0,0,0,0,0,0,32,0,33,0,33,0,0,0,33,0,0,0,33,0,33,0
0,32,0,0,0,0,0,0,0,0,0,32,0,33,0,33,33,33,33,33,33,33,33,33,0,33,0
0,32,0,0,0,0,0,0,0,0,0,32,0,33,0,0,0,0,0,55,0,0,0,0,0,33,0
0,32,0,0,0,0,0,0,0,0,0,32,0,42,0,0,67,0,0,0,0,0,0,0,0,42,0
0,32,0,0,0,0,0,0,0,0,0,32,0,42,0,0,0,0,0,0,0,0,0,0,0,42,0
0,32,0,0,0,0,0,0,0,0,0,32,0,33,18,0,0,0,0,18,68,68,68,0,18,33,0
0,32,0,0,0,0,0,0,0,0,0,32,0,28,33,33,69,33,42,28,33,33,33,42,33,28,0
0,32,0,0,0,0,0,0,0,0,0,32,0,0,0,0,0,0,0,0,0,0,0,0,0,0,0
0,32,0,0,0,0,0,0,0,0,0,32,0,0,0,0,0,0,0,0,0,0,0,0,0,0,0
0,32,0,0,0,0,0,0,0,0,0,32,0,0,0,0,0,0,0,0,0,0,0,0,0,0,0
0,23,23,32,23,0,0,0,23,32,23,23,0,0,0,0,0,0,0,0,0,0,0,0,0,0,0
0,0,0,0,0,0,0,0,0,0,0,0,0,0,0,0,0,0,0,0,0,0,0,0,0,0,0
0,0,0,0,0,0,0,0,0,0,0,0,0,0,0,0,0,0,0,0,0,0,0,0,0,0,0
0,0,0,0,0,0,0,0,0,0,0,0,0,0,0,0,0,0,0,0,0,0,0,0,0,0,0
endlayer

layer
0,0,0,0,0,0,0,0,0,0,0,0,0,0,0,0,0,0,0,0,0,0,0,0,0,0,0
0,0,23,23,32,32,32,32,32,23,23,0,0,18,0,0,0,0,0,18,0,0,0,0,0,18,0
0,0,32,0,0,0,0,0,0,0,32,0,0,28,28,28,28,28,28,28,28,28,28,28,28,28,65
0,0,32,0,0,0,0,0,0,0,32,0,0,28,70,70,70,70,70,28,70,70,70,70,70,28,0
0,0,32,0,0,0,0,0,0,0,32,0,0,28,70,70,71,70,70,28,70,70,71,70,70,28,0
0,0,32,0,0,0,0,0,0,0,32,0,0,28,70,70,70,70,70,28,70,70,70,70,70,28,0
0,0,32,0,0,0,0,0,0,0,32,0,0,28,70,70,70,70,70,28,70,70,70,70,70,28,0
0,0,32,0,0,0,0,0,0,0,32,0,0,28,70,70,70,70,70,28,70,70,70,70,70,28,0
0,0,32,0,0,0,0,0,0,0,32,0,0,28,70,70,72,70,70,28,70,70,72,70,70,28,0
0,0,32,0,0,0,0,0,0,0,32,0,0,28,70,70,70,70,70,28,70,70,70,70,70,28,0
0,0,32,0,0,0,0,0,0,0,32,0,0,28,70,70,70,70,70,28,70,70,70,70,70,28,0
0,0,32,0,0,0,0,0,0,0,32,0,0,28,70,70,70,70,70,28,70,70,70,70,70,28,0
0,0,32,0,0,0,0,0,0,0,32,0,0,28,70,70,71,70,70,28,70,70,71,70,70,28,0
0,0,32,0,0,0,0,0,0,0,32,0,0,28,70,70,70,70,70,28,70,70,70,70,70,28,0
0,0,32,0,0,0,0,0,0,0,32,0,0,28,28,28,28,28,28,28,28,28,28,28,28,28,65
0,0,32,0,0,0,0,0,0,0,32,0,0,17,0,0,0,0,0,17,0,0,0,0,0,17,0
0,0,32,0,0,0,0,0,0,0,32,0,0,0,0,0,0,0,0,0,0,0,0,0,0,0,0
0,0,32,0,0,0,0,0,0,0,32,0,0,0,0,0,0,0,0,0,0,0,0,0,0,0,0
0,0,23,23,73,73,73,73,73,23,23,0,0,0,0,0,0,0,0,0,0,0,0,0,0,0,0
0,0,0,0,0,0,0,0,0,0,0,0,0,0,0,0,0,0,0,0,0,0,0,0,0,0,0
0,0,0,0,0,0,0,0,0,0,0,0,0,0,0,0,0,0,0,0,0,0,0,0,0,0,0
0,0,0,0,0,0,0,0,0,0,0,0,0,0,0,0,0,0,0,0,0,0,0,0,0,0,0
endlayer

layer
0,0,0,0,0,0,0,0,0,0,0,0,0,0,0,0,0,0,0,0,0,0,0,0,0,0,0
0,0,0,23,23,23,23,23,23,23,0,0,0,0,0,0,0,0,0,0,0,0,0,0,0,0,0
0,0,0,32,32,32,32,32,32,32,0,0,0,0,0,0,0,0,0,0,0,0,0,0,0,0,0
0,0,0,32,32,32,32,32,32,32,0,0,0,0,0,0,0,0,0,0,0,0,0,0,0,0,0
0,0,0,32,32,32,32,32,32,32,0,0,0,0,0,0,0,0,0,0,0,0,0,0,0,0,0
0,0,0,32,32,32,32,32,32,32,0,0,0,0,0,0,0,0,0,0,0,0,0,0,0,0,0
0,0,0,32,32,32,32,32,32,32,0,0,0,0,0,0,0,0,0,0,0,0,0,0,0,0,0
0,0,0,32,32,32,32,32,32,32,0,0,0,0,0,0,0,0,0,0,0,0,0,0,0,0,0
0,0,0,32,32,32,32,32,32,32,0,0,0,0,0,0,0,0,0,0,0,0,0,0,0,0,0
0,0,0,32,32,32,32,32,32,32,0,0,0,0,0,0,0,0,0,0,0,0,0,0,0,0,0
0,0,0,32,32,32,32,32,32,32,0,0,0,0,0,0,0,0,0,0,0,0,0,0,0,0,0
0,0,0,32,32,32,32,32,32,32,0,0,0,0,0,0,0,0,0,0,0,0,0,0,0,0,0
0,0,0,32,32,32,32,32,32,32,0,0,0,0,0,0,0,0,0,0,0,0,0,0,0,0,0
0,0,0,32,32,32,32,32,32,32,0,0,0,0,0,0,0,0,0,0,0,0,0,0,0,0,0
0,0,0,32,32,32,32,32,32,32,0,0,0,0,0,0,0,0,0,0,0,0,0,0,0,0,0
0,0,0,32,32,32,32,32,32,32,0,0,0,0,0,0,0,0,0,0,0,0,0,0,0,0,0
0,0,0,32,32,32,32,32,32,32,0,0,0,0,0,0,0,0,0,0,0,0,0,0,0,0,0
0,0,0,32,32,32,32,32,32,32,0,0,0,0,0,0,0,0,0,0,0,0,0,0,0,0,0
0,0,0,23,23,23,23,23,23,23,0,0,0,0,0,0,0,0,0,0,0,0,0,0,0,0,0
0,0,0,0,0,0,0,0,0,0,0,0,0,0,0,0,0,0,0,0,0,0,0,0,0,0,0
0,0,0,0,0,0,0,0,0,0,0,0,0,0,0,0,0,0,0,0,0,0,0,0,0,0,0
0,0,0,0,0,0,0,0,0,0,0,0,0,0,0,0,0,0,0,0,0,0,0,0,0,0,0
endlayer

