
# Created by Ruins mod version 15.3 Ingame Parser
# authoring Player: Mensrea

weight=6
embed_into_distance=6
acceptable_target_blocks=
unacceptable_target_blocks=flowing_water,water,flowing_lava,lava
dimensions=12,22,27
allowable_overhang=0
max_leveling=2
leveling_buffer=0
preserve_water=0
preserve_lava=0
preventRotation=1

rule1=0,100,PFAAGeologica:mediumStone-3
rule2=0,100,minecraft:stonebrick-0
rule3=0,100,minecraft:water-0
rule4=0,100,PFAAGeologica:weakStone-1
rule5=0,100,minecraft:sand-1
rule6=0,100,minecraft:wooden_slab-0
rule7=0,100,ChestGenHook:strongholdLibrary:5-2
rule8=0,100,minecraft:planks-0
rule9=0,100,minecraft:oak_stairs-2
rule10=0,100,minecraft:gravel-0
rule11=0,100,PFAAGeologica:strongStoneBrick-1
rule12=0,100,minecraft:stone_brick_stairs-1
rule13=0,100,minecraft:fence-0
rule14=0,100,IW:concretestairs-1
rule15=0,100,IW:steelblock-0
rule16=0,100,IW:steelsiding-0
rule17=0,100,minecraft:farmland-7
rule18=0,100,minecraft:dirt-0
rule19=0,100,minecraft:stone_brick_stairs-3
rule20=0,100,minecraft:stone_brick_stairs-2
rule21=0,100,minecraft:glass-0
rule22=0,100,IW:fiberboard-0
rule23=0,100,minecraft:stone_slab-0
rule24=0,100,minecraft:jungle_stairs-1
rule25=0,100,minecraft:bed-10
rule26=0,100,minecraft:bed-2
rule27=0,100,minecraft:planks-3
rule28=0,100,minecraft:pumpkin_stem-7
rule29=0,100,minecraft:reeds-0
rule30=0,100,minecraft:melon_stem-6
rule31=0,100,minecraft:melon_block-0
rule32=0,100,minecraft:melon_stem-7
rule33=0,100,minecraft:jungle_stairs-3
rule34=0,100,minecraft:jungle_stairs-2
rule35=0,100,IW:metaldoor-2
rule36=0,100,minecraft:pumpkin-0
rule37=0,100,minecraft:melon_stem-5
rule38=0,100,minecraft:bookshelf-0
rule39=0,100,IW:metaldoor-3
rule40=0,100,minecraft:furnace-2
rule41=0,100,ChestGenHook:mineshaftCorridor:5-2
rule42=0,100,minecraft:melon_stem-4
rule43=0,100,minecraft:pumpkin_stem-6
rule44=0,100,minecraft:jukebox-0
rule45=0,100,minecraft:pumpkin_stem-4
rule46=0,100,minecraft:wooden_door-1
rule47=0,100,IW:computer1-0
rule48=0,100,minecraft:cauldron-3
rule49=0,100,ThermalExpansion:Workbench-1
rule50=0,100,minecraft:wooden_door-2
rule51=0,100,IInventory;minecraft:chest;minecraft:iron_hoe#1#0#0+minecraft:sapling#5#0#1+minecraft:reeds#64#0#2+ProjRed|Exploration:projectred.exploration.sickleiron#1#0#3+minecraft:dye#58#15#4+minecraft:pumpkin_seeds#6#0#5+IC2:itemCellEmpty#49#1#6+minecraft:melon_seeds#12#0#7-3
rule52=0,100,IW:smalllightwhite-4
rule53=0,100,IW:smalllightwhite-3
rule54=0,100,minecraft:wooden_pressure_plate-0
rule55=0,100,IW:metaldoor-8
rule56=0,100,IW:smalllightwhite-1
rule57=0,100,minecraft:wooden_door-8
rule58=0,100,minecraft:stained_glass-15
rule59=0,100,IW:smalllightwhite-2
rule60=0,100,minecraft:wool-0
rule61=0,100,IW:scrapmetalsheet-0
rule62=0,100,IW:machinery1-0
rule63=0,100,IC2:blockGenerator-3
rule64=0,100,PFAAGeologica:strongStone-1

layer
1,1,1,1,1,1,1,1,1,1,1,1,1,1,1,1,1,1,1,1,1,1,1,1,1,1,1
1,1,1,1,1,1,1,1,1,1,1,1,1,1,1,1,1,1,1,1,1,1,1,1,1,1,1
1,1,1,1,1,1,1,1,1,1,1,1,1,1,1,1,1,1,1,1,1,1,1,1,1,1,1
1,1,1,1,1,1,1,1,1,1,1,1,1,1,1,1,1,1,1,1,1,1,1,1,1,1,1
1,1,1,1,1,1,1,1,1,1,1,1,1,1,1,1,1,1,1,1,1,1,1,1,1,1,1
1,1,1,1,1,1,1,1,1,1,1,1,1,1,1,1,1,1,1,1,1,1,1,1,1,1,1
1,1,1,1,1,1,1,1,1,1,1,1,1,1,1,1,1,1,1,1,1,1,1,1,1,1,1
1,1,1,1,1,1,1,1,1,1,1,1,1,1,1,1,1,1,1,1,1,1,1,1,1,1,1
1,1,1,1,1,1,1,1,1,1,1,1,1,1,1,1,1,1,1,1,1,1,1,1,1,1,1
1,1,1,1,1,1,1,1,1,1,1,1,1,1,1,1,1,1,1,1,1,1,1,1,1,1,1
1,1,1,1,1,1,1,1,1,1,1,1,1,1,1,1,1,1,1,1,1,1,1,1,1,1,1
1,1,1,1,1,1,1,1,1,1,1,1,1,1,1,1,1,1,1,1,1,1,1,1,1,1,1
1,1,1,1,1,1,1,1,1,1,1,1,1,1,1,1,1,1,1,1,1,1,1,1,1,1,1
1,1,1,1,1,1,1,1,1,1,1,1,1,1,1,1,1,1,1,1,1,1,1,1,1,1,1
1,1,1,1,1,1,1,1,1,1,1,1,1,1,1,1,1,1,1,1,1,1,1,1,1,1,1
1,1,1,1,1,1,1,1,1,1,1,1,1,1,1,1,1,1,1,1,1,1,1,1,1,1,1
1,1,1,1,1,1,1,1,1,1,1,1,1,1,1,1,1,1,1,1,1,1,1,1,1,1,1
1,1,1,1,1,1,1,1,1,1,1,1,1,1,1,1,1,1,1,1,1,1,1,1,1,1,1
1,1,1,1,1,1,1,1,1,1,1,1,1,1,1,1,1,1,1,1,1,1,1,1,1,1,1
1,1,1,1,1,1,1,1,1,1,1,1,1,1,1,1,1,1,1,1,1,1,1,1,1,1,1
1,1,1,1,1,1,1,1,1,1,1,1,1,1,1,1,1,1,1,1,1,1,1,1,1,1,1
1,1,1,1,1,1,1,1,1,1,1,1,1,1,1,1,1,1,1,1,1,1,1,1,1,1,1
endlayer

layer
1,1,1,1,1,1,1,1,1,1,1,1,1,1,1,1,1,1,1,1,1,1,1,1,1,1,1
1,1,1,1,1,1,1,1,1,1,1,1,1,1,1,1,1,1,1,1,1,1,1,1,1,1,1
1,1,1,1,1,1,1,1,1,1,1,1,1,1,1,1,1,1,1,1,1,1,1,1,1,1,1
1,1,1,1,1,1,1,1,1,1,1,1,1,1,1,1,1,1,1,1,1,1,1,1,1,1,1
1,1,1,1,1,1,1,1,1,1,1,1,1,1,1,1,1,1,1,1,1,1,1,1,1,1,1
1,1,1,1,1,1,1,1,1,1,1,1,1,1,1,1,1,1,1,1,1,1,1,1,1,1,1
1,1,1,1,1,1,1,1,1,1,1,1,1,1,1,1,1,1,1,1,1,1,1,1,1,1,1
1,1,1,1,1,1,1,1,1,1,1,1,1,1,1,1,1,1,1,1,1,1,1,1,1,1,1
1,1,1,1,1,1,1,1,1,1,1,1,1,1,1,1,1,1,1,1,1,1,1,1,1,1,1
1,1,1,1,1,1,1,1,1,1,1,1,1,1,1,1,1,2,2,2,2,2,2,2,2,1,1
1,1,1,1,1,1,1,1,1,1,1,1,1,1,1,1,1,2,3,3,3,3,3,3,2,1,1
1,1,1,1,1,1,1,1,1,1,1,1,1,1,1,1,1,2,3,3,3,3,3,3,2,1,1
1,1,1,1,1,1,1,1,1,1,1,1,1,1,1,1,1,2,3,3,3,3,3,3,2,1,1
1,1,1,1,1,1,1,1,1,1,1,1,1,1,1,1,1,2,3,3,3,3,3,3,2,1,1
1,1,1,1,1,1,1,1,1,1,1,1,1,1,1,1,1,2,3,3,3,3,3,3,2,1,1
1,1,1,1,1,1,1,1,1,1,1,1,1,1,1,1,1,2,3,3,3,3,3,3,2,1,1
1,1,1,1,1,1,1,1,1,1,1,1,1,1,1,1,1,2,2,2,2,2,2,3,2,1,1
1,1,1,1,1,1,1,1,1,1,1,1,1,1,1,1,1,1,1,1,1,1,2,3,2,1,1
1,1,1,1,1,1,1,1,1,1,1,1,1,1,1,1,1,1,1,1,1,1,2,1,2,1,1
1,1,1,1,1,1,1,1,1,1,1,1,1,1,1,1,1,1,1,1,1,1,2,2,2,1,1
1,1,1,1,1,1,1,1,1,1,1,1,1,1,1,1,1,1,1,1,1,1,1,1,1,1,1
1,1,1,1,1,1,1,1,1,1,1,1,1,1,1,1,1,1,1,1,1,1,1,1,1,1,1
endlayer

layer
4,4,4,4,4,4,4,4,4,4,4,4,4,4,4,4,4,4,4,4,4,4,4,4,4,4,4
4,4,4,4,4,4,4,4,4,4,4,4,4,4,4,4,4,4,4,4,4,4,4,4,4,4,4
4,4,4,4,4,4,4,4,4,4,4,4,4,4,4,4,4,4,4,4,4,4,4,4,4,4,4
4,4,4,4,4,4,4,4,4,4,4,4,4,4,4,4,4,4,4,4,4,4,4,4,4,4,4
4,4,4,4,4,4,4,4,4,4,4,4,4,4,4,4,4,4,4,4,4,4,4,4,4,4,4
4,4,4,4,4,4,4,4,4,4,4,4,4,4,4,4,4,4,4,4,4,4,4,4,4,4,4
4,4,4,4,4,4,4,4,4,4,4,4,4,4,4,4,4,4,4,4,4,4,4,4,4,4,4
4,4,4,4,4,4,4,4,4,4,4,4,4,4,4,4,4,4,4,4,4,4,4,4,4,4,4
4,4,4,4,4,4,4,4,4,4,4,4,4,4,4,4,4,4,4,4,4,4,4,4,4,4,4
4,4,4,4,4,4,4,4,4,4,4,4,4,4,4,4,4,2,2,2,2,2,2,2,2,4,4
4,4,4,4,4,4,4,4,4,4,4,4,4,4,4,4,4,2,3,3,3,3,3,3,2,4,4
4,4,4,4,4,4,4,4,4,4,4,4,4,4,4,4,4,2,3,3,3,3,3,3,2,4,4
4,4,4,4,4,4,4,4,4,4,4,4,4,4,4,4,4,2,3,3,3,3,3,3,2,4,4
4,4,4,4,4,4,4,4,4,4,4,4,4,4,4,4,4,2,3,3,3,3,3,3,2,4,4
4,4,4,4,4,4,4,4,4,4,4,4,4,4,4,4,4,2,3,3,3,3,3,3,2,4,4
4,4,4,4,4,4,4,4,4,4,4,4,4,4,4,4,4,2,3,3,3,3,3,3,2,4,4
4,4,4,4,4,4,4,4,4,4,4,4,4,4,4,4,4,2,2,2,2,2,2,3,2,4,4
4,4,4,4,4,4,4,4,4,4,4,4,4,4,4,4,4,4,4,4,4,4,2,3,2,4,4
4,4,4,4,4,4,4,4,4,4,4,4,4,4,4,4,4,4,4,4,4,4,2,4,2,4,4
4,4,4,4,4,4,4,4,4,4,4,4,4,4,4,4,4,4,4,4,4,4,2,2,2,4,4
4,4,4,4,4,4,4,4,4,4,4,4,4,4,4,4,4,4,4,4,4,4,4,4,4,4,4
4,4,4,4,4,4,4,4,4,4,4,4,4,4,4,4,4,4,4,4,4,4,4,4,4,4,4
endlayer

layer
4,4,4,4,4,4,4,4,4,4,4,4,4,4,4,4,4,4,4,4,4,4,4,4,4,4,4
4,4,4,4,4,4,4,4,4,4,4,4,4,4,4,4,4,4,4,4,4,4,4,4,4,4,4
4,4,4,4,4,4,4,4,4,4,4,4,4,4,4,4,4,4,4,4,4,4,4,4,4,4,4
4,4,4,4,4,4,4,4,4,4,4,4,4,4,4,4,4,4,4,4,4,4,4,4,4,4,4
4,4,4,4,4,4,4,4,4,4,4,4,4,4,4,4,4,4,4,4,4,4,4,4,4,4,4
4,4,4,4,4,4,4,4,4,4,4,4,4,4,4,4,4,4,4,4,4,4,4,4,4,4,4
4,4,4,4,4,4,4,4,4,4,4,4,4,4,4,4,4,4,4,4,4,4,4,4,4,4,4
4,4,4,4,4,4,4,4,4,4,4,4,4,4,4,4,4,4,4,4,4,4,4,4,4,4,4
4,4,4,4,4,4,4,4,4,4,4,4,4,4,4,4,4,4,4,4,4,4,4,4,4,4,4
4,4,4,4,4,4,4,4,4,4,4,4,4,4,4,4,4,2,2,2,2,2,2,2,2,4,4
4,4,4,4,4,4,4,4,4,4,4,4,4,4,4,4,4,2,3,3,3,3,3,3,2,4,4
4,4,4,4,4,4,4,4,4,4,4,4,4,4,4,4,4,2,3,3,3,3,3,3,2,4,4
4,4,4,4,4,4,4,4,4,4,4,4,4,4,4,4,4,2,3,3,3,3,3,3,2,4,4
4,4,4,4,4,4,4,4,4,4,4,4,4,4,4,4,4,2,3,3,3,3,3,3,2,4,4
4,4,4,4,4,4,4,4,4,4,4,4,4,4,4,4,4,2,3,3,3,3,3,3,2,4,4
4,4,4,4,4,4,4,4,4,4,4,4,4,4,4,4,4,2,3,3,3,3,3,3,2,4,4
4,4,4,4,4,4,4,4,4,4,4,4,4,4,4,4,4,2,2,2,2,2,2,3,2,4,4
4,4,4,4,4,4,4,4,4,4,4,4,4,4,4,4,4,4,4,4,4,4,2,3,2,4,4
4,4,4,4,4,4,4,4,4,4,4,4,4,4,4,4,4,4,4,4,4,4,2,3,2,4,4
4,4,4,4,4,4,4,4,4,4,4,4,4,4,4,4,4,4,4,4,4,4,2,2,2,4,4
4,4,4,4,4,4,4,4,4,4,4,4,4,4,4,4,4,4,4,4,4,4,4,4,4,4,4
4,4,4,4,4,4,4,4,4,4,4,4,4,4,4,4,4,4,4,4,4,4,4,4,4,4,4
endlayer

layer
5,5,5,5,5,5,5,5,5,5,5,5,5,5,5,5,5,5,5,5,5,5,5,5,5,5,5
5,5,5,5,5,5,5,5,5,5,5,5,5,5,5,5,5,5,5,5,5,5,5,5,5,5,5
5,5,5,5,5,5,5,5,5,5,5,5,5,5,5,5,5,5,5,5,5,5,5,5,5,5,5
5,5,5,5,5,5,5,5,5,5,5,5,5,5,5,5,5,5,5,5,5,5,5,5,5,5,5
5,5,5,5,5,5,5,5,5,5,5,5,5,5,5,7,6,5,5,5,5,5,5,5,5,5,5
5,5,5,5,5,5,5,5,5,5,5,5,5,5,5,5,5,5,5,5,5,5,5,5,5,5,5
5,5,5,5,5,5,5,5,5,5,5,5,5,5,5,5,5,5,5,5,5,5,5,5,5,5,5
5,5,5,5,5,5,5,5,5,5,5,5,5,5,5,5,5,5,5,5,5,5,5,5,5,5,5
5,5,5,5,5,5,5,5,5,5,5,5,5,5,5,5,5,5,5,5,5,5,5,5,5,5,5
5,5,5,5,5,5,5,5,5,5,5,5,5,5,5,5,5,2,2,2,2,2,2,2,2,5,5
5,5,5,5,5,5,5,5,5,5,5,5,5,5,5,5,5,2,2,2,2,2,2,2,2,5,5
5,5,5,5,5,5,5,5,5,5,5,5,5,5,5,5,5,2,2,2,2,2,2,2,2,5,5
5,5,5,5,5,5,5,5,5,5,5,5,5,5,5,5,5,2,2,2,2,2,2,2,2,5,5
5,5,5,5,5,5,5,5,5,5,5,5,5,5,5,5,5,2,2,2,2,2,2,2,2,5,5
5,5,5,5,5,5,5,5,5,5,5,5,5,5,5,5,5,2,2,2,2,2,2,2,2,5,5
5,5,5,5,5,5,5,5,5,5,5,5,5,5,5,5,5,2,2,2,2,2,2,2,2,5,5
5,5,5,5,5,5,5,5,5,5,5,5,5,5,5,5,5,2,2,2,2,2,2,2,2,5,5
5,5,5,5,5,5,5,5,5,5,5,5,5,5,5,5,5,5,5,5,5,5,2,2,2,5,5
5,5,5,5,5,5,5,5,5,5,5,5,5,5,5,5,5,5,5,5,5,5,2,0,2,5,5
5,5,5,5,5,5,5,5,5,5,5,5,5,5,5,5,5,5,5,5,5,5,2,2,2,5,5
5,5,5,5,5,5,5,5,5,5,5,5,5,5,5,5,5,5,5,5,5,5,5,5,5,5,5
5,5,5,5,5,5,5,5,5,5,5,5,5,5,5,5,5,5,5,5,5,5,5,5,5,5,5
endlayer

layer
5,5,5,5,5,5,5,5,5,0,0,0,5,5,5,5,5,5,5,5,5,5,5,5,5,5,5
5,5,5,5,5,5,5,5,5,5,5,5,5,5,5,5,5,5,5,5,5,5,5,5,5,5,5
5,5,5,5,5,5,5,5,5,5,5,5,5,2,5,5,5,5,5,2,5,5,5,2,5,5,5
5,5,5,5,5,5,5,5,5,5,5,5,5,5,5,5,5,5,5,5,5,5,5,5,5,5,5
5,5,5,5,5,5,5,5,5,5,5,5,5,5,5,8,0,8,5,5,5,5,5,5,5,5,0
5,5,5,5,5,5,5,5,5,5,5,5,5,5,5,8,0,8,5,5,5,5,5,5,5,5,0
5,5,5,5,5,5,5,5,5,5,5,5,5,5,5,0,0,0,0,0,5,5,5,5,5,5,0
5,5,5,5,5,5,5,5,5,5,5,5,5,5,5,0,0,0,0,8,0,5,5,5,5,5,5
5,5,5,5,5,5,5,5,5,5,5,5,5,5,5,8,0,0,0,0,0,5,5,5,5,5,5
5,5,5,5,5,5,5,5,5,5,5,5,5,5,5,8,0,8,8,0,8,8,5,5,5,5,5
5,5,5,5,5,5,5,5,5,5,5,5,5,5,5,0,0,8,8,0,0,0,0,5,5,5,5
0,5,5,5,5,5,5,5,5,5,5,5,5,5,5,8,0,0,0,0,0,0,5,5,5,5,5
0,5,5,5,5,5,5,5,5,5,5,5,5,5,5,8,0,8,0,0,0,0,5,5,5,5,5
0,5,5,5,5,5,5,5,5,5,5,5,5,5,5,5,5,5,5,5,8,0,5,5,5,5,5
5,5,5,5,5,5,5,5,5,5,5,5,5,2,5,5,5,5,5,2,8,0,5,2,5,5,5
5,5,5,5,5,5,5,5,5,5,5,5,5,5,5,10,5,10,5,5,9,0,5,5,5,5,0
5,5,5,5,5,5,5,5,5,5,5,5,5,5,5,10,10,10,5,5,5,5,5,5,5,5,0
5,5,5,5,5,5,5,5,5,5,5,5,5,5,10,10,10,10,10,5,5,5,2,2,2,5,5
5,5,5,5,5,5,5,5,5,5,5,5,5,10,10,10,10,10,10,10,10,10,2,0,2,5,5
5,5,5,5,5,10,10,10,5,5,5,5,10,10,10,10,10,10,10,10,10,5,2,2,2,5,5
5,5,5,5,5,10,10,10,10,10,10,10,10,10,10,10,10,10,10,10,5,5,5,5,5,5,0
5,5,5,5,5,5,5,5,5,5,5,5,5,10,10,10,10,10,10,5,0,0,5,5,0,0,0
endlayer

layer
5,5,5,5,5,0,0,0,0,0,0,0,0,5,0,0,0,0,0,0,0,0,0,0,0,0,0
5,11,11,11,11,11,11,11,11,11,11,11,5,5,5,0,0,0,0,5,0,0,0,0,0,0,0
5,11,11,11,11,11,11,11,11,11,11,11,5,2,5,0,0,0,5,2,0,0,0,2,0,0,0
0,11,11,11,11,11,11,11,11,11,11,11,0,0,0,0,0,0,0,0,0,0,0,0,0,0,0
0,11,11,11,11,11,11,11,11,11,11,11,0,0,0,0,0,0,0,0,0,0,0,0,0,0,0
0,11,11,11,11,11,11,11,11,11,11,11,0,0,0,0,0,0,0,0,0,0,0,0,0,0,0
0,11,11,11,11,11,11,11,11,11,11,11,0,0,0,0,0,0,0,0,0,0,0,0,0,0,0
0,11,11,11,11,11,11,11,11,11,11,11,0,0,0,0,0,0,0,0,0,0,0,0,0,0,0
0,11,11,11,11,11,11,11,11,11,11,11,0,0,0,0,0,0,0,0,0,0,0,0,0,0,0
0,11,11,11,11,11,11,11,11,11,11,11,0,0,0,0,0,0,0,0,0,0,0,0,0,5,0
0,11,11,11,11,11,11,11,11,11,11,11,0,0,0,0,0,0,0,0,0,0,0,0,0,5,0
0,11,11,11,11,11,11,11,11,11,11,11,0,0,0,0,0,0,0,0,0,0,0,0,0,5,0
0,11,11,11,11,11,11,11,11,11,11,11,0,0,0,0,0,0,0,0,0,0,0,0,0,0,0
0,11,11,11,11,11,11,11,11,11,11,11,0,0,0,0,0,0,0,0,0,0,0,0,0,0,0
0,11,11,11,11,11,11,11,11,11,11,11,0,2,0,0,0,0,0,2,0,0,0,2,5,0,0
0,11,11,11,11,11,11,11,11,11,11,11,0,0,0,0,2,0,0,0,0,0,0,5,0,0,0
0,11,11,11,11,11,11,11,11,11,11,11,0,0,0,0,12,0,0,0,0,0,0,0,0,0,0
5,11,11,11,11,11,11,11,11,11,11,11,0,0,0,0,0,0,0,0,0,0,13,13,13,0,0
5,11,11,11,11,11,11,11,11,11,11,11,0,0,0,0,0,0,0,0,0,0,13,0,13,0,0
0,5,5,5,0,14,14,14,5,5,5,0,0,0,0,0,0,0,0,0,0,0,13,13,13,0,0
0,0,5,0,0,0,0,0,0,0,0,0,0,0,0,0,0,0,0,0,0,0,0,0,0,0,0
0,0,0,0,0,0,0,0,0,0,0,0,0,0,0,0,0,0,0,0,0,0,0,0,0,0,0
endlayer

layer
0,5,0,0,0,0,0,0,0,0,0,0,0,0,0,0,0,0,0,0,0,0,0,0,0,0,0
5,11,11,11,11,11,11,11,11,11,11,11,0,5,0,0,0,0,0,0,0,0,0,0,0,0,0
0,11,2,2,2,2,2,2,2,2,2,11,0,15,15,15,15,15,15,15,8,8,8,8,0,0,0
0,11,17,18,3,18,17,18,3,17,17,11,0,15,16,16,16,16,16,15,8,8,8,8,0,0,0
0,11,17,17,3,18,17,18,3,17,17,11,0,15,16,16,16,16,16,15,8,8,8,8,0,0,0
0,11,17,17,3,18,17,18,3,18,17,11,0,15,16,16,16,16,16,15,8,8,8,8,0,0,0
0,11,17,18,3,18,17,18,3,17,17,11,0,15,16,16,16,16,16,15,8,8,8,8,0,0,0
0,11,17,17,3,18,17,18,3,18,17,11,0,15,16,16,16,16,16,15,8,8,8,8,0,0,0
0,11,17,17,3,18,17,18,3,17,17,11,0,15,16,16,16,16,16,15,8,8,8,8,0,0,0
0,11,17,17,3,18,17,18,3,17,17,11,0,15,16,16,16,16,16,15,8,8,8,8,0,0,0
0,11,17,17,3,18,18,18,3,18,17,11,0,15,16,16,16,16,16,15,8,8,8,8,0,0,0
0,11,17,17,3,18,17,18,3,17,17,11,0,15,16,16,16,16,16,15,8,8,8,8,0,0,0
0,11,17,17,3,18,18,18,3,18,17,11,0,15,16,16,16,16,16,15,8,8,8,8,0,0,0
0,11,17,18,3,18,17,18,3,18,17,11,0,15,16,16,16,16,16,15,8,8,8,8,0,0,0
0,11,17,18,3,18,18,18,3,17,17,11,0,15,15,15,15,15,15,15,8,8,8,8,0,0,0
0,11,17,18,3,18,17,18,3,17,17,11,0,0,0,0,12,0,0,0,0,0,0,0,0,0,0
0,11,2,2,2,2,2,2,2,2,2,11,0,0,0,0,0,0,0,0,0,0,0,0,0,0,0
0,11,2,20,0,0,0,0,0,19,2,11,0,0,0,0,0,0,0,0,0,0,0,13,0,0,0
0,11,11,11,11,0,0,0,11,11,11,11,0,0,0,0,0,0,0,0,0,0,0,0,0,0,0
0,0,5,0,0,0,0,0,0,0,0,0,0,0,0,0,0,0,0,0,0,0,0,13,0,0,0
0,0,0,0,0,0,0,0,0,0,0,0,0,0,0,0,0,0,0,0,0,0,0,0,0,0,0
0,0,0,0,0,0,0,0,0,0,0,0,0,0,0,0,0,0,0,0,0,0,0,0,0,0,0
endlayer

layer
0,0,0,0,0,0,0,0,0,0,0,0,0,0,0,0,0,0,0,0,0,0,0,0,0,0,0
0,11,11,21,21,21,21,21,21,21,11,11,0,0,0,0,0,0,0,0,0,0,0,0,0,0,0
0,21,0,0,23,0,0,0,23,0,0,21,0,15,22,22,22,22,22,15,13,13,13,13,0,0,0
0,21,32,31,23,29,30,29,23,0,28,21,0,22,24,27,0,26,25,22,0,24,0,13,0,0,0
0,21,32,0,23,29,0,29,23,0,32,21,0,22,0,0,0,26,25,22,34,13,33,13,0,0,0
0,21,37,0,23,29,32,29,23,36,28,21,0,22,35,22,22,22,22,22,0,34,0,13,0,0,0
0,21,32,31,23,29,0,29,23,0,32,21,0,22,0,39,0,24,38,22,0,0,0,13,0,0,0
0,21,32,0,23,29,32,29,23,36,28,21,0,22,0,22,0,0,0,22,40,0,0,13,0,0,0
0,21,37,0,23,29,0,29,23,0,42,21,0,22,0,22,41,26,25,22,34,0,0,13,0,0,0
0,21,32,0,23,29,32,29,23,0,43,21,0,22,0,22,22,22,22,22,34,0,0,13,0,0,0
0,21,32,0,23,29,31,29,23,31,32,21,0,22,0,44,24,24,33,21,0,0,0,13,0,0,0
0,21,32,0,23,29,32,29,23,0,45,21,0,22,0,0,0,0,33,21,0,0,0,13,0,0,0
0,21,32,0,23,29,31,29,23,31,32,21,0,22,48,0,47,0,0,46,0,0,0,13,0,0,0
0,21,32,31,23,29,32,29,23,36,28,21,0,22,49,0,0,0,0,21,0,0,0,13,0,0,0
0,21,32,31,23,29,31,29,23,0,32,21,0,15,22,22,50,22,22,15,13,13,13,13,0,0,0
0,21,32,31,23,29,32,29,23,0,28,21,0,0,0,0,0,0,0,0,0,0,0,0,0,0,0
0,21,0,0,0,0,0,0,0,0,0,21,0,0,0,0,0,0,0,0,0,0,0,0,0,0,0
0,21,0,0,0,0,0,0,0,0,51,21,0,0,0,0,0,0,0,0,0,0,0,6,0,0,0
0,11,21,21,11,0,0,0,11,21,21,11,0,0,0,0,0,0,0,0,0,0,0,6,0,0,0
0,0,0,0,0,0,0,0,0,0,0,0,0,0,0,0,0,0,0,0,0,0,0,6,0,0,0
0,0,0,0,0,0,0,0,0,0,0,0,0,0,0,0,0,0,0,0,0,0,0,0,0,0,0
0,0,0,0,0,0,0,0,0,0,0,0,0,0,0,0,0,0,0,0,0,0,0,0,0,0,0
endlayer

layer
0,0,0,0,0,0,0,0,0,0,0,0,0,0,0,0,0,0,0,0,0,0,0,0,0,0,0
0,11,11,21,21,21,21,21,21,21,11,11,0,0,0,0,0,0,0,0,0,0,0,0,0,0,0
0,21,0,0,0,0,0,0,0,0,0,21,0,15,22,22,21,22,22,15,52,0,0,13,0,0,0
0,21,0,0,0,29,0,29,0,0,0,21,0,22,52,0,0,0,53,22,0,0,0,0,0,0,0
0,21,0,0,0,29,0,29,0,0,0,21,0,22,0,0,0,0,0,21,0,54,0,0,0,0,0
0,21,0,0,0,29,0,29,0,0,0,21,0,22,55,22,22,22,22,22,0,0,0,0,0,0,0
0,21,0,0,0,29,0,29,0,0,0,21,0,22,0,55,0,0,0,22,0,0,0,0,0,0,0
0,21,0,0,0,29,0,29,0,0,0,21,0,21,0,22,52,0,0,21,0,0,0,0,0,0,0
0,21,0,0,0,29,0,29,0,0,0,21,0,22,0,22,0,0,0,22,0,0,0,0,0,0,0
0,21,0,0,0,29,0,29,0,0,0,21,0,22,0,22,22,22,22,22,0,0,0,0,0,0,0
0,21,0,0,0,29,0,29,0,0,0,21,0,22,0,0,0,0,56,21,0,0,0,0,0,0,0
0,21,0,0,0,29,0,29,0,0,0,21,0,22,0,0,0,0,0,21,0,0,0,0,0,0,0
0,21,0,0,0,29,0,29,0,0,0,21,0,21,0,0,58,0,0,57,0,0,0,0,0,0,0
0,21,0,0,0,29,0,29,0,0,0,21,0,22,52,0,0,0,0,21,0,0,0,0,0,0,0
0,21,0,0,0,29,0,29,0,0,0,21,0,15,21,22,57,22,21,15,52,0,0,13,0,0,0
0,21,0,0,0,29,0,29,0,0,0,21,0,0,0,0,0,0,0,0,0,0,0,0,0,0,0
0,21,0,0,0,0,0,0,0,0,0,21,0,0,0,0,0,0,0,0,0,0,0,0,0,0,0
0,21,0,0,0,0,0,0,0,0,0,21,0,0,0,0,0,0,0,0,0,0,0,0,0,0,0
0,11,11,21,11,0,0,0,11,21,11,11,0,0,0,0,0,0,0,0,0,0,0,0,0,0,0
0,0,0,0,0,0,0,0,0,0,0,0,0,0,0,0,0,0,0,0,0,0,0,0,0,0,0
0,0,0,0,0,0,0,0,0,0,0,0,0,0,0,0,0,0,0,0,0,0,0,0,0,0,0
0,0,0,0,0,0,0,0,0,0,0,0,0,0,0,0,0,0,0,0,0,0,0,0,0,0,0
endlayer

layer
0,0,0,0,0,0,0,0,0,0,0,0,0,0,0,0,0,0,0,0,0,0,0,0,0,0,0
0,0,11,11,21,21,21,21,21,11,11,0,0,59,0,0,0,0,0,59,0,0,0,59,0,0,0
0,0,21,0,0,0,0,0,0,0,21,0,0,15,15,15,15,15,15,15,8,8,8,8,52,0,0
0,0,21,0,0,29,0,29,0,0,21,0,0,15,61,61,61,61,61,15,60,60,60,8,0,0,0
0,0,21,0,0,29,0,29,0,0,21,0,0,15,61,61,62,61,61,15,60,60,60,8,0,0,0
0,0,21,0,0,29,0,29,0,0,21,0,0,15,61,61,61,61,61,15,60,60,60,8,0,0,0
0,0,21,0,0,29,0,29,0,0,21,0,0,15,61,61,61,61,61,15,60,60,60,8,0,0,0
0,0,21,0,0,29,0,29,0,0,21,0,0,15,61,61,61,61,61,15,60,60,60,8,0,0,0
0,0,21,0,0,29,0,29,0,0,21,0,0,15,61,61,63,61,61,15,60,60,60,8,52,0,0
0,0,21,0,0,29,0,29,0,0,21,0,0,15,61,61,61,61,61,15,60,60,60,8,0,0,0
0,0,21,0,0,29,0,29,0,0,21,0,0,15,61,61,61,61,61,15,60,60,60,8,0,0,0
0,0,21,0,0,29,0,29,0,0,21,0,0,15,61,61,61,61,61,15,60,60,60,8,0,0,0
0,0,21,0,0,29,0,29,0,0,21,0,0,15,61,61,62,61,61,15,60,60,60,8,0,0,0
0,0,21,0,0,29,0,29,0,0,21,0,0,15,61,61,61,61,61,15,60,60,60,8,0,0,0
0,0,21,0,0,29,0,29,0,0,21,0,0,15,15,15,15,15,15,15,8,8,8,8,52,0,0
0,0,21,0,0,29,0,29,0,0,21,0,0,56,0,0,0,0,0,56,0,0,0,56,0,0,0
0,0,21,0,0,0,0,0,0,0,21,0,0,0,0,0,0,0,0,0,0,0,0,0,0,0,0
0,0,21,0,0,0,0,0,0,0,21,0,0,0,0,0,0,0,0,0,0,0,0,0,0,0,0
0,0,11,11,64,64,64,64,64,11,11,0,0,0,0,0,0,0,0,0,0,0,0,0,0,0,0
0,0,0,0,0,0,0,0,0,0,0,0,0,0,0,0,0,0,0,0,0,0,0,0,0,0,0
0,0,0,0,0,0,0,0,0,0,0,0,0,0,0,0,0,0,0,0,0,0,0,0,0,0,0
0,0,0,0,0,0,0,0,0,0,0,0,0,0,0,0,0,0,0,0,0,0,0,0,0,0,0
endlayer

layer
0,0,0,0,0,0,0,0,0,0,0,0,0,0,0,0,0,0,0,0,0,0,0,0,0,0,0
0,0,0,11,11,11,11,11,11,11,0,0,0,0,0,0,0,0,0,0,0,0,0,0,0,0,0
0,0,0,21,21,21,21,21,21,21,0,0,0,0,0,0,0,0,0,0,0,0,0,0,0,0,0
0,0,0,21,21,21,21,21,21,21,0,0,0,0,0,0,0,0,0,0,0,0,0,0,0,0,0
0,0,0,21,21,21,21,21,21,21,0,0,0,0,0,0,0,0,0,0,0,0,0,0,0,0,0
0,0,0,21,21,21,21,21,21,21,0,0,0,0,0,0,0,0,0,0,0,0,0,0,0,0,0
0,0,0,21,21,21,21,21,21,21,0,0,0,0,0,0,0,0,0,0,0,0,0,0,0,0,0
0,0,0,21,21,21,21,21,21,21,0,0,0,0,0,0,0,0,0,0,0,0,0,0,0,0,0
0,0,0,21,21,21,21,21,21,21,0,0,0,0,0,0,0,0,0,0,0,0,0,0,0,0,0
0,0,0,21,21,21,21,21,21,21,0,0,0,0,0,0,0,0,0,0,0,0,0,0,0,0,0
0,0,0,21,21,21,21,21,21,21,0,0,0,0,0,0,0,0,0,0,0,0,0,0,0,0,0
0,0,0,21,21,21,21,21,21,21,0,0,0,0,0,0,0,0,0,0,0,0,0,0,0,0,0
0,0,0,21,21,21,21,21,21,21,0,0,0,0,0,0,0,0,0,0,0,0,0,0,0,0,0
0,0,0,21,21,21,21,21,21,21,0,0,0,0,0,0,0,0,0,0,0,0,0,0,0,0,0
0,0,0,21,21,21,21,21,21,21,0,0,0,0,0,0,0,0,0,0,0,0,0,0,0,0,0
0,0,0,21,21,21,21,21,21,21,0,0,0,0,0,0,0,0,0,0,0,0,0,0,0,0,0
0,0,0,21,21,21,21,21,21,21,0,0,0,0,0,0,0,0,0,0,0,0,0,0,0,0,0
0,0,0,21,21,21,21,21,21,21,0,0,0,0,0,0,0,0,0,0,0,0,0,0,0,0,0
0,0,0,11,11,11,11,11,11,11,0,0,0,0,0,0,0,0,0,0,0,0,0,0,0,0,0
0,0,0,0,0,0,0,0,0,0,0,0,0,0,0,0,0,0,0,0,0,0,0,0,0,0,0
0,0,0,0,0,0,0,0,0,0,0,0,0,0,0,0,0,0,0,0,0,0,0,0,0,0,0
0,0,0,0,0,0,0,0,0,0,0,0,0,0,0,0,0,0,0,0,0,0,0,0,0,0,0
endlayer

