
# Created by Ruins mod version 15.3 Ingame Parser
# authoring Player: Mensrea

weight=1
embed_into_distance=5
acceptable_target_blocks=
unacceptable_target_blocks=flowing_water,water,flowing_lava,lava
dimensions=9,10,10
allowable_overhang=0
max_leveling=2
leveling_buffer=0
preserve_water=0
preserve_lava=0
preventRotation=1

rule1=0,100,IW:concrete-0
rule2=0,100,ChestGenHook:strongholdCorridor:5-2
rule3=0,100,ChestGenHook:dungeonChest:5-5
rule4=0,100,minecraft:planks-0
rule5=0,100,MobSpawner:demonmobs.belph
rule6=0,100,IW:concreteslab-0
rule7=0,100,IW:metalladder-5
rule8=0,100,AdvancedRepulsionSystems:DeFenceBW-0

layer
1,1,1,1,1,1,1,1,1,1
1,1,1,1,1,1,1,1,1,1
1,1,1,1,1,1,1,1,1,1
1,1,1,1,1,1,1,1,1,1
0,1,1,1,1,1,1,1,1,1
1,1,1,1,1,1,1,1,1,1
1,1,1,1,1,1,1,1,1,1
1,1,1,1,1,1,1,1,1,1
1,1,1,1,1,1,1,1,1,1
1,1,1,1,1,1,1,1,1,1
endlayer

layer
1,1,1,1,1,1,1,1,1,1
1,0,0,0,0,0,0,3,2,1
1,4,0,0,0,0,0,4,4,1
0,4,4,0,0,0,0,0,0,1
0,4,0,0,0,0,0,0,0,1
0,4,4,0,0,0,0,0,0,1
1,4,0,0,0,0,0,0,0,1
1,4,0,0,0,0,0,0,0,1
1,0,0,0,0,0,0,0,0,1
1,1,1,1,1,1,1,1,1,1
endlayer

layer
1,1,1,1,1,1,1,1,1,1
1,0,0,0,0,0,0,4,4,1
1,0,0,0,0,0,0,4,4,1
1,0,0,0,0,0,0,0,0,1
0,4,0,0,0,0,0,0,0,0
0,0,0,0,0,0,0,0,0,1
1,4,0,0,0,0,0,0,0,1
1,0,0,0,0,0,0,0,0,1
1,0,0,0,0,0,0,0,0,1
1,1,1,1,1,1,1,1,1,1
endlayer

layer
1,1,1,1,1,1,1,1,1,1
1,1,1,1,1,1,1,1,1,1
1,1,1,1,1,1,1,5,1,1
1,1,1,1,1,1,1,1,1,0
0,1,1,1,1,1,1,1,1,0
1,1,1,1,0,0,0,1,1,0
1,1,1,1,1,0,0,1,1,1
1,1,1,1,1,0,1,1,1,1
1,1,1,1,1,1,1,1,1,1
1,1,1,1,1,1,1,1,1,1
endlayer

layer
1,1,1,1,1,1,1,1,1,1
1,1,1,1,1,1,1,1,1,1
1,1,0,0,0,0,0,6,1,0
1,1,0,0,0,0,0,0,1,0
0,1,0,0,0,1,0,0,1,0
1,1,0,0,0,7,0,0,1,0
1,1,0,0,0,0,0,0,1,0
1,0,0,0,0,0,0,0,1,1
1,0,1,1,1,1,1,1,1,1
1,1,1,1,1,1,1,1,1,1
endlayer

layer
1,1,0,0,1,1,1,1,1,1
1,1,0,0,0,0,0,1,1,1
1,1,0,0,0,0,0,0,1,1
1,0,0,0,0,0,0,0,0,0
0,0,0,0,0,1,0,0,0,0
0,0,0,0,0,0,0,0,0,0
1,0,0,0,0,0,0,0,0,0
1,0,0,0,0,0,0,0,1,1
0,0,1,0,0,0,0,1,1,1
0,0,1,1,1,1,1,1,1,1
endlayer

layer
6,0,0,0,0,0,0,0,6,6
6,1,0,0,0,0,0,1,1,6
0,1,0,0,0,0,0,0,1,0
0,0,0,0,0,0,0,0,0,0
0,0,0,0,0,0,0,0,0,0
0,0,0,0,0,0,0,0,0,0
0,0,0,0,0,0,0,0,0,0
0,0,0,0,0,0,0,0,1,0
0,0,1,0,0,0,0,1,1,6
0,0,0,0,0,0,0,0,6,6
endlayer

layer
0,0,0,6,6,6,6,0,0,0
0,0,6,1,1,1,1,6,0,0
0,6,1,1,1,1,1,0,6,0
6,1,1,1,1,0,1,1,1,6
6,0,1,1,0,0,1,1,0,6
0,1,1,1,1,0,1,1,1,6
6,1,1,1,0,0,0,1,1,0
0,0,1,1,0,0,0,1,6,0
0,0,6,1,0,0,1,6,0,0
0,0,0,0,0,6,6,0,0,0
endlayer

layer
0,0,0,0,0,0,0,0,0,0
0,0,0,0,8,8,0,0,0,0
0,0,0,6,6,0,6,0,0,0
0,0,6,6,1,0,6,0,0,0
0,0,6,0,0,0,0,6,0,0
0,8,6,1,0,0,1,6,0,0
0,0,0,6,0,0,0,6,0,0
0,0,0,6,0,0,0,0,0,0
0,0,0,0,0,0,8,0,0,0
0,0,0,0,0,0,0,0,0,0
endlayer

