
# Created by Ruins mod version 15.3 Ingame Parser
# authoring Player: Mensrea

weight=3
embed_into_distance=9
acceptable_target_blocks=
unacceptable_target_blocks=flowing_water,water,flowing_lava,lava
dimensions=13,12,9
allowable_overhang=0
max_leveling=2
leveling_buffer=0
preserve_water=0
preserve_lava=0
preventRotation=1

rule1=0,100,minecraft:stonebrick-0
rule2=0,100,minecraft:stone-0
rule3=0,100,minecraft:tripwire_hook-7
rule4=0,100,minecraft:tripwire-4
rule5=0,100,minecraft:stone_brick_stairs-3
rule6=0,100,minecraft:stone_brick_stairs-1
rule7=0,100,ChestGenHook:dungeonChest:5-2
rule8=0,100,ChestGenHook:dungeonChest:5-2
rule9=0,100,minecraft:stone_brick_stairs-0
rule10=0,100,minecraft:tripwire_hook-5
rule11=0,100,minecraft:obsidian-0
rule12=0,100,minecraft:stonebrick-2
rule13=0,100,minecraft:iron_bars-0
rule14=0,100,Skull:0:0-5
rule15=0,100,Skull:0:0-3
rule16=0,100,Skull:0:0-4
rule17=0,100,IInventory;minecraft:dispenser;minecraft:tnt#1#0#4-4
rule18=0,100,IInventory;minecraft:dispenser;demonmobs:devilstarcharge#5#0#4-4
rule19=0,100,minecraft:stonebrick-1
rule20=0,100,minecraft:stone_brick_stairs-7
rule21=0,100,minecraft:stone_brick_stairs-5
rule22=0,100,minecraft:stone_brick_stairs-4
rule23=0,100,minecraft:stone_brick_stairs-2
rule24=0,100,minecraft:sand-1
rule25=0,100,IW:bush-0

layer
1,1,1,1,1,1,1,1,1
1,1,1,1,1,1,1,1,1
1,1,1,1,1,1,1,1,1
1,1,1,1,1,1,1,1,1
1,1,1,1,1,1,1,1,1
1,1,1,2,1,1,1,1,1
1,1,1,1,1,1,1,1,1
1,1,1,1,1,1,1,1,1
1,1,1,1,1,1,1,1,1
1,1,1,1,1,1,1,1,1
1,1,1,1,1,1,1,1,1
1,1,1,1,1,1,1,1,1
endlayer

layer
1,1,1,1,1,1,1,1,1
1,3,3,1,1,1,1,1,1
1,4,4,1,1,1,1,1,1
1,4,4,5,1,1,1,1,1
1,4,4,5,1,1,1,1,1
1,4,4,1,1,1,1,1,1
1,4,4,0,6,6,1,1,1
1,4,4,0,7,5,1,1,1
1,4,4,0,8,5,1,1,1
1,10,10,0,9,5,1,1,1
1,11,11,1,1,1,1,1,1
1,1,1,1,1,1,1,1,1
endlayer

layer
1,1,1,1,1,1,1,1,1
1,1,1,1,1,1,1,1,1
1,1,1,1,12,1,1,1,1
1,0,0,0,5,1,1,1,1
1,0,0,0,5,1,1,1,1
1,0,0,1,12,12,1,1,1
1,0,0,0,14,13,1,1,1
1,0,0,0,0,15,1,1,1
1,0,0,0,0,13,1,1,1
1,0,0,0,16,13,1,1,1
11,18,17,11,1,1,1,1,1
1,11,11,1,1,1,1,1,1
endlayer

layer
1,1,1,1,1,1,1,1,1
1,1,1,1,1,1,1,1,1
1,1,1,1,12,12,1,19,1
1,0,0,0,0,5,12,19,12
1,0,0,0,0,5,19,12,12
1,0,0,0,12,12,12,12,12
1,0,0,0,21,20,12,12,1
1,0,0,0,0,20,12,12,1
1,0,0,0,0,20,12,12,1
1,0,0,0,22,20,1,1,1
1,11,11,1,1,1,1,1,1
1,1,1,1,1,1,1,1,1
endlayer

layer
1,1,1,1,1,1,1,1,1
1,1,1,1,1,1,1,1,1
1,1,1,1,12,19,12,12,12
1,1,0,0,0,0,0,0,12
1,1,0,0,0,0,0,0,12
1,1,1,1,19,12,0,0,12
1,1,1,1,1,12,9,9,12
1,1,1,1,1,12,13,12,1
1,1,1,1,1,12,13,12,1
1,1,1,1,1,0,12,1,1
1,1,1,1,1,1,1,1,1
1,1,1,1,1,1,1,1,1
endlayer

layer
1,1,1,1,1,1,1,1,1
1,1,1,1,1,1,1,1,1
1,1,1,1,12,12,19,12,12
1,1,1,0,0,0,0,0,12
1,1,1,0,0,0,0,0,19
1,1,1,1,12,12,0,0,12
1,1,1,1,1,19,0,0,12
1,1,1,1,1,23,0,0,19
1,1,1,1,1,23,0,0,12
1,1,1,19,19,19,19,19,1
1,1,1,1,1,1,1,1,1
1,1,1,1,1,1,1,1,1
endlayer

layer
24,24,24,24,24,24,24,24,24
24,24,24,24,24,24,24,24,24
24,24,24,24,12,12,12,12,12
24,24,24,19,0,0,0,0,12
24,24,24,12,0,0,0,0,12
24,24,24,12,12,12,0,0,12
1,1,1,19,19,12,0,0,12
1,1,1,1,23,0,0,0,19
1,1,1,1,23,0,0,0,12
1,1,1,19,19,19,19,19,24
24,24,24,24,24,24,24,24,24
24,24,24,24,24,24,24,24,24
endlayer

layer
24,24,24,24,24,24,24,24,24
24,24,24,24,24,24,24,24,24
24,24,24,24,24,24,24,24,24
24,24,24,24,12,12,12,12,12
24,24,24,24,12,12,19,12,12
24,24,24,24,12,12,0,0,12
24,1,1,19,19,19,0,0,12
19,19,19,23,0,0,0,0,12
19,19,19,23,0,0,0,0,19
24,1,1,19,12,19,19,19,24
24,24,24,24,24,24,24,24,24
24,24,24,24,24,24,24,24,24
endlayer

layer
24,24,24,0,0,0,24,24,24
0,24,24,24,24,24,24,24,24
0,24,24,24,24,24,24,24,0
24,24,24,24,24,24,24,24,0
24,24,24,24,24,24,24,24,24
24,24,24,24,24,12,12,12,24
24,19,19,12,12,19,19,19,24
24,24,24,24,0,0,0,19,24
24,24,24,0,0,0,0,19,24
24,19,19,19,12,19,19,19,24
24,24,24,24,24,24,24,24,24
24,24,24,24,24,24,24,24,0
endlayer

layer
0,0,0,0,0,0,0,0,0
0,0,25,0,0,0,0,0,25
0,0,0,0,0,0,0,0,0
0,0,0,24,24,0,0,0,0
0,0,24,24,24,24,24,0,0
0,24,24,24,24,24,24,24,0
24,24,19,19,19,19,19,24,0
24,24,24,0,0,0,12,24,0
24,0,0,0,0,0,19,24,0
24,24,19,12,19,12,19,24,0
0,24,24,24,24,24,24,0,0
0,0,24,24,24,24,0,0,0
endlayer

layer
0,0,0,0,0,0,0,0,0
0,0,0,0,0,0,0,0,0
0,0,0,0,0,0,0,0,0
0,0,0,0,25,0,0,0,0
0,0,0,0,0,0,0,0,0
0,0,24,0,0,24,0,0,0
0,24,19,19,19,19,24,0,0
0,24,19,19,19,19,24,0,0
0,0,19,19,19,19,24,0,0
0,24,19,19,19,19,24,0,0
0,0,24,24,24,24,0,0,0
0,0,0,0,0,0,0,0,0
endlayer

layer
0,0,0,0,0,0,0,0,0
0,0,0,0,0,0,0,0,0
0,0,0,0,0,0,0,0,0
0,0,0,0,0,0,0,0,0
0,0,0,0,0,0,0,0,0
0,0,0,0,0,0,0,0,0
0,0,24,24,24,24,0,0,0
0,0,24,24,24,0,0,0,0
0,0,24,24,0,0,0,0,0
0,0,24,24,24,0,0,0,0
0,0,0,0,0,0,0,0,0
0,0,0,0,0,0,0,0,0
endlayer

layer
0,0,0,0,0,0,0,0,0
0,0,0,0,0,0,0,0,0
0,0,0,0,0,0,0,0,0
0,0,0,0,0,0,0,0,0
0,0,0,0,0,0,0,0,0
0,0,0,0,0,0,0,0,0
0,0,0,0,0,0,0,0,0
0,0,0,0,0,0,0,0,0
0,0,0,25,0,0,0,0,0
0,0,0,0,0,0,0,0,0
0,0,0,0,0,0,0,0,0
0,0,0,0,0,0,0,0,0
endlayer

