
# Created by Ruins mod version 15.3 Ingame Parser
# authoring Player: Mensrea

weight=3
embed_into_distance=17
acceptable_target_blocks=
unacceptable_target_blocks=flowing_water,water,flowing_lava,lava
dimensions=21,15,13
allowable_overhang=0
max_leveling=2
leveling_buffer=0
preserve_water=0
preserve_lava=0
preventRotation=1

rule1=0,100,PFAAGeologica:strongStone-3
rule2=0,100,IW:concrete-0
rule3=0,100,IW:steelsiding-0
rule4=0,100,IW:toxicsludge-0
rule5=0,100,ChestGenHook:dungeonChest:5-2
rule6=0,100,ChestGenHook:pyramidDesertyChest:5-2
rule7=0,100,MobSpawner:customnpcs.CustomNpc
rule8=0,100,ChestGenHook:dungeonChest:5-2
rule9=0,100,ChestGenHook:pyramidDesertyChest:5-2
rule10=0,100,minecraft:obsidian-0
rule11=0,100,ImmersiveEngineering:storageSlab-7
rule12=0,100,IW:steelblock-0
rule13=0,100,PFAAGeologica:strongStone-7
rule14=0,100,PFAAGeologica:mediumStone-3
rule15=0,100,PFAAGeologica:weakStone-1
rule16=0,100,minecraft:sand-1
rule17=0,100,IC2:blockDoorAlloy-2
rule18=0,100,IC2:blockDoorAlloy-8
rule19=0,100,IW:metalbutton-1
rule20=0,100,IW:bush-0

layer
1,1,1,1,1,1,1,1,1,1,1,1,1
1,2,2,2,2,2,2,2,2,2,2,2,1
1,2,2,2,2,2,2,2,2,2,2,2,1
1,2,2,2,2,2,2,2,2,2,2,2,1
1,2,2,2,2,2,2,2,2,2,2,2,1
1,2,2,2,2,2,2,2,2,2,2,2,1
1,2,2,2,2,2,2,2,2,2,2,2,1
1,2,2,2,2,2,2,2,2,2,2,2,1
1,2,2,2,2,2,2,2,2,2,2,2,1
1,2,2,2,2,2,2,2,2,2,2,2,1
1,2,2,2,2,2,2,2,2,2,2,2,1
1,2,2,2,2,2,2,2,2,2,2,2,1
1,2,2,2,2,2,2,2,2,2,2,2,1
1,2,2,2,2,2,2,2,2,2,2,2,1
1,1,1,1,1,1,1,1,1,1,1,1,1
endlayer

layer
1,1,1,1,1,1,1,1,1,1,1,1,1
1,2,2,2,2,2,2,2,2,2,2,2,1
1,2,2,2,3,2,3,2,2,3,2,2,1
1,2,2,2,3,2,2,2,2,3,2,2,1
1,2,2,2,3,2,2,2,3,3,2,2,1
1,2,2,2,2,2,2,2,2,2,2,2,1
1,2,2,2,3,2,2,2,2,2,2,2,1
1,2,3,3,3,2,2,2,2,2,2,2,1
1,2,2,2,2,2,3,3,3,2,2,2,1
1,2,2,2,2,2,3,2,3,2,2,2,1
1,2,2,2,2,2,3,2,3,3,3,2,1
1,2,2,2,2,2,3,2,2,2,2,2,1
1,2,2,2,2,2,3,2,2,2,2,2,1
1,2,2,2,2,2,2,2,2,2,2,2,1
1,1,1,1,1,1,1,1,1,1,1,1,1
endlayer

layer
1,1,1,1,1,1,1,1,1,1,1,1,1
1,2,2,2,2,2,2,2,2,2,2,2,1
1,2,2,2,3,2,3,2,2,3,2,2,1
1,2,2,4,4,4,4,4,4,4,2,2,1
1,2,2,4,4,2,5,2,4,4,2,2,1
1,2,2,4,4,8,7,6,4,4,2,2,1
1,2,2,4,4,2,9,2,4,4,2,2,1
1,2,3,4,4,4,4,4,4,4,2,2,1
1,2,2,4,4,4,4,4,4,4,2,2,1
1,2,2,4,4,4,4,4,4,4,2,2,1
1,2,2,4,4,4,4,4,4,4,3,2,1
1,2,2,4,4,4,4,4,4,4,2,2,1
1,2,2,2,2,2,3,2,2,2,2,2,1
1,2,2,2,2,2,2,2,2,2,2,2,1
1,1,1,1,1,1,1,1,1,1,1,1,1
endlayer

layer
1,1,1,1,1,1,1,1,1,1,1,1,1
1,2,2,2,2,2,2,2,2,2,2,2,1
1,2,2,2,3,2,3,2,2,3,2,2,1
1,2,2,0,0,0,0,0,0,0,2,2,1
1,2,2,0,0,10,11,10,0,0,2,2,1
1,2,2,0,0,11,11,11,0,0,2,2,1
1,2,2,0,0,10,11,10,0,0,2,2,1
1,2,3,0,0,0,0,0,0,0,2,2,1
1,2,3,0,0,0,0,0,0,0,2,2,1
1,2,3,0,0,0,0,0,0,0,2,2,1
1,2,2,0,0,0,0,0,0,0,3,2,1
1,2,2,0,0,0,0,0,0,0,2,2,1
1,2,2,2,2,2,3,3,3,3,2,2,1
1,2,2,2,2,2,2,2,2,2,2,2,1
1,1,1,1,1,1,1,1,1,1,1,1,1
endlayer

layer
1,1,1,1,1,1,1,1,1,1,1,1,1
1,2,2,2,2,2,2,2,2,2,2,2,1
1,2,3,3,3,2,3,2,2,3,3,2,1
1,2,3,0,0,0,0,0,0,0,3,2,1
1,2,3,0,0,0,0,0,0,0,3,2,1
1,2,3,0,0,0,0,0,0,0,2,2,1
1,2,3,0,0,0,0,0,0,0,2,2,1
1,2,3,0,0,0,0,0,0,0,2,2,1
1,2,2,0,0,0,0,0,0,0,2,2,1
1,2,3,0,0,0,0,0,0,0,3,2,1
1,2,3,0,0,0,0,0,0,0,3,2,1
1,2,3,0,0,0,0,0,0,0,2,2,1
1,2,3,3,3,3,3,2,2,3,2,2,1
1,2,2,2,2,2,2,2,2,2,2,2,1
1,1,1,1,1,1,1,1,1,1,1,1,1
endlayer

layer
1,1,1,1,1,1,1,1,1,1,1,1,1
1,2,2,2,2,2,2,2,2,2,2,2,1
1,2,2,3,2,2,3,2,2,3,2,2,1
1,2,2,0,0,0,0,0,0,0,2,2,1
1,2,2,0,0,0,0,0,0,0,3,2,1
1,2,2,0,0,0,0,0,0,0,3,2,1
1,2,2,0,0,0,0,0,0,0,3,2,1
1,2,3,0,0,0,0,0,0,0,3,2,1
1,2,2,0,0,0,0,0,0,0,3,2,1
1,2,2,0,0,0,0,0,0,0,3,2,1
1,2,2,0,0,0,0,0,0,0,2,2,1
1,2,2,0,0,0,0,0,0,0,2,2,1
1,2,2,3,2,2,3,2,2,3,2,2,1
1,2,2,2,2,2,2,2,2,2,2,2,1
1,1,1,1,1,1,1,1,1,1,1,1,1
endlayer

layer
1,1,1,1,1,1,1,1,1,1,1,1,1
1,2,2,2,2,2,2,2,2,2,2,2,1
1,2,2,3,2,2,3,2,3,3,2,2,1
1,2,2,0,0,0,0,0,0,0,2,2,1
1,2,2,0,0,0,0,0,0,0,2,2,1
1,2,2,0,0,0,0,0,0,0,2,2,1
1,2,2,0,0,0,0,0,0,0,2,2,1
1,2,3,0,0,0,0,0,0,0,2,2,1
1,2,2,0,0,0,0,0,0,0,2,2,1
1,2,2,0,0,0,0,0,0,0,3,2,1
1,2,2,0,0,0,0,0,0,0,3,2,1
1,2,2,0,0,0,0,0,0,0,3,2,1
1,2,2,3,2,2,3,2,2,3,3,2,1
1,2,2,2,2,2,2,2,2,2,2,2,1
1,1,1,1,1,1,1,1,1,1,1,1,1
endlayer

layer
1,1,1,1,1,1,1,1,1,1,1,1,1
1,2,2,2,2,2,2,2,2,2,2,2,1
1,2,2,3,2,2,3,2,3,2,2,2,1
1,2,2,3,3,2,3,2,3,3,2,2,1
1,2,2,2,3,3,3,2,2,3,2,2,1
1,2,2,2,2,2,3,2,2,3,2,2,1
1,2,2,2,2,2,3,3,3,3,2,2,1
1,2,3,3,3,3,3,2,3,2,2,2,1
1,2,2,3,2,2,2,2,3,2,2,2,1
1,2,2,3,12,2,2,2,3,2,2,2,1
1,2,3,3,2,2,0,2,3,3,3,2,1
1,2,3,2,2,2,3,2,2,2,2,2,1
1,2,3,3,2,2,3,2,2,2,2,2,1
1,2,2,2,2,2,2,2,2,2,2,2,1
1,1,1,1,1,1,1,1,1,1,1,1,1
endlayer

layer
1,1,1,1,1,1,1,1,1,1,1,1,1
1,2,2,2,2,2,2,2,2,2,2,2,1
1,2,2,2,2,2,2,2,2,2,2,2,1
1,2,2,2,2,2,2,2,2,2,2,2,1
1,2,2,2,2,2,2,2,2,2,2,2,1
1,2,2,2,2,2,2,2,2,2,2,2,1
1,2,2,2,2,2,2,2,2,2,2,2,1
1,2,2,2,2,2,2,2,2,2,2,2,1
1,2,2,2,2,2,2,2,2,2,2,2,1
1,2,2,2,12,2,2,2,2,2,2,2,1
1,2,2,2,2,2,0,2,2,2,2,2,1
1,2,2,2,2,2,3,2,2,2,2,2,1
1,2,2,2,2,2,2,2,2,2,2,2,1
1,2,2,2,2,2,2,2,2,2,2,2,1
1,1,1,1,1,1,1,1,1,1,1,1,1
endlayer

layer
13,13,13,13,13,13,13,13,13,13,13,13,13
13,13,13,13,13,13,13,13,13,13,13,13,13
13,13,13,13,13,13,13,13,13,13,13,13,13
13,13,13,13,13,13,13,13,13,13,13,13,13
13,13,13,13,13,13,13,13,13,13,13,13,13
13,13,13,13,13,13,13,13,13,13,13,13,13
13,13,13,13,13,13,13,13,13,13,13,13,13
13,13,13,13,13,13,13,13,13,13,13,13,13
13,13,13,13,13,13,13,13,13,13,13,13,13
13,13,13,13,12,2,2,2,13,13,13,13,13
13,13,13,13,13,2,0,2,13,13,13,13,13
13,13,13,13,13,2,2,2,13,13,13,13,13
13,13,13,13,13,13,13,13,13,13,13,13,13
13,13,13,13,13,13,13,13,13,13,13,13,13
13,13,13,13,13,13,13,13,13,13,13,13,13
endlayer

layer
13,13,13,13,13,13,13,13,13,13,13,13,13
13,13,13,13,13,13,13,13,13,13,13,13,13
13,13,13,13,13,13,13,13,13,13,13,13,13
13,13,13,13,13,13,13,13,13,13,13,13,13
13,13,13,13,13,13,13,13,13,13,13,13,13
13,13,13,13,13,13,13,13,13,13,13,13,13
13,13,13,13,13,13,13,13,13,13,13,13,13
13,13,13,13,13,13,13,13,13,13,13,13,13
13,13,13,13,13,13,13,13,13,13,13,13,13
13,13,13,13,12,2,2,2,13,13,13,13,13
13,13,13,13,13,2,0,2,13,13,13,13,13
13,13,13,13,13,2,2,2,13,13,13,13,13
13,13,13,13,13,13,13,13,13,13,13,13,13
13,13,13,13,13,13,13,13,13,13,13,13,13
13,13,13,13,13,13,13,13,13,13,13,13,13
endlayer

layer
13,13,13,13,13,13,13,13,13,13,13,13,13
13,13,13,13,13,13,13,13,13,13,13,13,13
13,13,13,13,13,13,13,13,13,13,13,13,13
13,13,13,13,13,13,13,13,13,13,13,13,13
13,13,13,13,13,13,13,13,13,13,13,13,13
13,13,13,13,13,13,13,13,13,13,13,13,13
13,13,13,13,13,13,13,13,13,13,13,13,13
13,13,13,13,13,13,13,13,13,13,13,13,13
13,13,13,13,13,13,13,13,13,13,13,13,13
13,13,13,13,12,2,2,2,13,13,13,13,13
13,13,13,13,13,2,0,2,13,13,13,13,13
13,13,13,13,13,2,2,2,13,13,13,13,13
13,13,13,13,13,13,13,13,13,13,13,13,13
13,13,13,13,13,13,13,13,13,13,13,13,13
13,13,13,13,13,13,13,13,13,13,13,13,13
endlayer

layer
13,13,13,13,13,13,13,13,13,13,13,13,13
13,13,13,13,13,13,13,13,13,13,13,13,13
13,13,13,13,13,13,13,13,13,13,13,13,13
13,13,13,13,13,13,13,13,13,13,13,13,13
13,13,13,13,13,13,13,13,13,13,13,13,13
13,13,13,13,13,13,13,13,13,13,13,13,13
13,13,13,13,13,13,13,13,13,13,13,13,13
13,13,13,13,13,13,13,13,13,13,13,13,13
13,13,13,13,13,13,13,13,13,13,13,13,13
13,13,13,13,12,2,2,2,13,13,13,13,13
13,13,13,13,13,2,0,2,13,13,13,13,13
13,13,13,13,13,2,2,2,13,13,13,13,13
13,13,13,13,13,13,13,13,13,13,13,13,13
13,13,13,13,13,13,13,13,13,13,13,13,13
13,13,13,13,13,13,13,13,13,13,13,13,13
endlayer

layer
14,14,14,14,14,14,14,14,14,14,14,14,14
14,14,14,14,14,14,14,14,14,14,14,14,14
14,14,14,14,14,14,14,14,14,14,14,14,14
14,14,14,14,14,14,14,14,14,14,14,14,14
14,14,14,14,14,14,14,14,14,14,14,14,14
14,14,14,14,14,14,14,14,14,14,14,14,14
14,14,14,14,14,14,14,14,14,14,14,14,14
14,14,14,14,14,14,14,14,14,14,14,14,14
14,14,14,14,14,14,14,14,14,14,14,14,14
14,14,14,14,12,2,2,2,14,14,14,14,14
14,14,14,14,14,2,0,2,14,14,14,14,14
14,14,14,14,14,2,2,2,14,14,14,14,14
14,14,14,14,14,14,14,14,14,14,14,14,14
14,14,14,14,14,14,14,14,14,14,14,14,14
14,14,14,14,14,14,14,14,14,14,14,14,14
endlayer

layer
14,14,14,14,14,14,14,14,14,14,14,14,14
14,14,14,14,14,14,14,14,14,14,14,14,14
14,14,14,14,14,14,14,14,14,14,14,14,14
14,14,14,14,14,14,14,14,14,14,14,14,14
14,14,14,14,14,14,14,14,14,14,14,14,14
14,14,14,14,14,14,14,14,14,14,14,14,14
14,14,14,14,14,14,14,14,14,14,14,14,14
14,14,14,14,14,14,14,14,14,14,14,14,14
14,14,14,14,14,14,14,14,14,14,14,14,14
14,14,14,14,12,2,2,2,14,14,14,14,14
14,14,14,14,14,2,0,2,14,14,14,14,14
14,14,14,14,14,2,2,2,14,14,14,14,14
14,14,14,14,14,14,14,14,14,14,14,14,14
14,14,14,14,14,14,14,14,14,14,14,14,14
14,14,14,14,14,14,14,14,14,14,14,14,14
endlayer

layer
15,15,15,15,15,15,15,15,15,15,15,15,15
15,15,15,15,15,15,15,15,15,15,15,15,15
15,15,15,15,15,15,15,15,15,15,15,15,15
15,15,15,15,15,15,15,15,15,15,15,15,15
15,15,15,15,15,15,15,15,15,15,15,15,15
15,15,15,15,15,15,15,15,15,15,15,15,15
15,15,15,15,15,15,15,15,15,15,15,15,15
15,15,15,15,15,15,15,15,15,15,15,15,15
15,15,15,15,15,15,15,15,15,15,15,15,15
15,15,15,15,12,2,2,2,15,15,15,15,15
15,15,15,15,15,2,0,2,15,15,15,15,15
15,15,15,15,15,2,2,2,15,15,15,15,15
15,15,15,15,15,15,15,15,15,15,15,15,15
15,15,15,15,15,15,15,15,15,15,15,15,15
15,15,15,15,15,15,15,15,15,15,15,15,15
endlayer

layer
16,16,16,16,16,16,16,16,16,16,16,16,16
16,16,16,16,16,16,16,16,16,16,16,16,16
16,16,16,16,16,16,16,16,16,16,16,16,16
16,16,16,16,16,16,16,16,16,16,16,16,16
16,16,16,16,16,16,16,16,16,16,16,16,16
16,16,16,16,16,16,16,16,16,16,16,16,16
16,16,16,16,16,16,16,16,16,16,16,16,16
16,16,16,16,16,16,16,16,16,16,16,16,16
16,16,16,16,16,16,16,16,16,16,16,16,16
16,16,16,16,12,2,2,2,16,16,16,16,16
16,16,16,16,16,2,0,2,16,16,16,16,16
16,16,16,16,16,2,17,2,16,16,16,16,16
16,16,16,16,16,16,0,16,16,16,16,16,16
16,16,16,16,16,16,16,16,16,16,16,16,16
16,16,16,16,16,16,16,16,16,16,16,16,16
endlayer

layer
0,0,16,16,16,16,16,16,16,16,16,0,0
0,16,16,16,16,16,16,16,16,16,16,16,0
16,16,16,16,16,16,16,16,16,16,16,16,0
16,16,16,16,16,16,16,16,16,16,16,16,16
16,16,16,16,16,16,16,16,16,16,16,16,16
16,16,16,16,16,16,16,16,16,16,16,16,16
16,16,16,16,16,16,16,16,16,16,16,16,16
0,16,16,16,16,16,16,16,16,16,16,16,16
0,16,16,16,16,16,16,16,16,16,16,16,0
16,16,16,16,12,2,2,2,16,16,0,0,0
16,16,16,16,16,2,0,2,16,0,0,16,16
16,16,16,16,16,2,18,2,0,0,16,16,16
0,16,16,16,16,16,0,19,0,16,16,16,16
0,0,16,16,16,16,16,16,16,16,16,16,16
0,0,0,0,16,16,0,0,16,16,16,16,16
endlayer

layer
0,0,0,0,0,0,0,0,0,0,20,0,0
0,0,0,16,16,16,16,16,16,0,0,0,0
0,0,16,16,16,16,16,16,16,16,0,0,0
0,16,16,16,16,16,16,16,16,16,16,0,0
0,16,16,16,16,16,16,16,16,16,16,16,0
0,16,16,16,16,16,16,16,16,16,16,16,0
0,16,16,16,16,16,16,16,16,16,16,16,0
0,0,16,16,16,16,16,16,16,16,16,0,0
0,20,16,16,16,16,16,16,16,16,0,0,0
0,0,0,16,12,12,2,12,16,0,0,0,0
0,0,0,0,16,2,2,2,0,0,0,0,0
0,0,20,0,0,12,2,12,0,0,0,16,0
0,0,0,0,0,0,0,0,0,0,16,16,16
0,0,0,0,0,0,0,0,0,16,16,16,16
0,0,0,0,0,0,0,0,0,0,16,16,0
endlayer

layer
0,0,0,0,0,0,0,0,0,0,0,0,0
0,0,0,0,0,0,0,0,0,0,0,0,0
0,0,0,0,16,16,16,16,0,0,0,0,0
0,20,0,16,16,16,16,16,16,0,0,0,0
0,0,16,16,16,16,16,16,16,16,0,0,0
0,0,16,16,16,16,16,16,16,16,16,0,0
0,0,0,16,16,16,16,16,16,16,0,0,0
0,0,0,16,16,16,16,16,16,0,0,0,0
0,0,0,0,16,16,16,16,0,0,0,0,0
0,0,0,0,0,16,16,0,0,0,0,0,0
0,0,0,0,0,16,16,0,0,0,0,0,0
0,0,0,0,0,16,0,0,0,0,0,0,0
0,0,0,0,0,0,0,0,0,0,0,20,0
0,0,0,0,0,0,0,0,0,0,0,0,0
0,0,0,0,0,0,0,0,0,0,0,0,0
endlayer

layer
0,0,0,0,0,0,0,0,0,0,0,0,0
0,0,0,0,0,0,0,0,0,0,0,0,0
0,0,0,0,0,0,0,0,0,0,0,0,0
0,0,0,0,0,0,0,0,0,0,0,0,0
0,0,0,0,20,0,0,0,0,0,0,0,0
0,0,0,0,0,0,0,0,0,0,0,0,0
0,0,0,0,0,0,0,0,20,0,0,0,0
0,0,0,0,0,0,0,0,0,0,0,0,0
0,0,0,0,0,0,0,0,0,0,0,0,0
0,0,0,0,0,0,0,0,0,0,0,0,0
0,0,0,0,0,0,0,0,0,0,0,0,0
0,0,0,0,0,0,0,0,0,0,0,0,0
0,0,0,0,0,0,0,0,0,0,0,0,0
0,0,0,0,0,0,0,0,0,0,0,0,0
0,0,0,0,0,0,0,0,0,0,0,0,0
endlayer

