
# Created by Ruins mod version 15.3 Ingame Parser
# authoring Player: Mensrea

weight=4
embed_into_distance=6
acceptable_target_blocks=
unacceptable_target_blocks=flowing_water,water,flowing_lava,lava
dimensions=9,22,17
allowable_overhang=0
max_leveling=2
leveling_buffer=0
preserve_water=0
preserve_lava=0
preventRotation=1

rule1=0,100,PFAAGeologica:mediumStone-3
rule2=0,100,minecraft:water-0
rule3=0,100,PFAAGeologica:mediumStone-0
rule4=0,100,IW:fiberboard-0
rule5=0,100,minecraft:ladder-5
rule6=0,100,ChestGenHook:mineshaftCorridor:5-2
rule7=0,100,ChestGenHook:strongholdLibrary:5-2
rule8=0,100,minecraft:sand-1
rule9=0,100,minecraft:dirt-0
rule10=0,100,minecraft:gravel-0
rule11=0,100,PFAAGeologica:strongStoneBrick-9
rule12=0,100,minecraft:farmland-7
rule13=0,100,minecraft:stonebrick-0
rule14=0,100,minecraft:wooden_door-1
rule15=0,100,minecraft:furnace-4
rule16=0,100,minecraft:fence-0
rule17=0,100,minecraft:bed-3
rule18=0,100,ImmersiveEngineering:hemp-4
rule19=0,100,ImmersiveEngineering:hemp-0
rule20=0,100,ImmersiveEngineering:hemp-1
rule21=0,100,ImmersiveEngineering:hemp-2
rule22=0,100,minecraft:bed-11
rule23=0,100,ImmersiveEngineering:hemp-3
rule24=0,100,minecraft:glass-0
rule25=0,100,minecraft:wooden_door-8
rule26=0,100,ImmersiveEngineering:hemp-5
rule27=0,100,IW:smalllightwhite-2
rule28=0,100,minecraft:wooden_slab-4
rule29=0,100,minecraft:wooden_slab-0

layer
1,1,1,1,1,1,1,1,1,1,1,1,1,1,1,1,1
1,1,1,1,1,1,1,1,1,1,1,1,1,1,1,1,1
1,1,1,1,1,1,1,1,1,1,1,1,1,1,1,1,1
1,1,1,1,1,1,1,1,1,1,1,1,1,1,1,1,1
1,1,1,1,1,1,1,1,1,1,1,1,1,1,1,1,1
1,1,1,1,1,1,1,1,1,1,1,1,1,1,1,1,1
1,1,1,1,1,1,1,1,1,1,1,1,1,1,1,1,1
1,1,1,1,1,1,1,1,1,1,1,1,1,1,1,1,1
1,1,1,1,1,1,1,1,1,1,1,1,1,1,1,1,1
1,1,1,1,1,1,1,1,1,1,1,1,1,1,1,1,1
1,1,1,1,1,1,1,1,1,1,1,1,1,1,1,1,1
1,1,1,1,1,1,1,1,1,1,1,1,1,1,1,1,1
1,1,1,1,1,1,1,1,1,1,1,1,1,1,1,1,1
1,1,1,1,1,1,1,1,1,1,1,1,1,1,1,1,1
1,1,1,1,1,1,1,1,1,1,1,1,1,1,1,1,1
1,1,1,1,1,1,1,1,1,1,1,1,1,1,1,1,1
1,1,1,1,1,1,1,1,1,1,1,1,1,1,1,1,1
1,1,1,1,1,1,1,1,1,1,1,1,1,1,1,1,1
1,1,1,1,1,1,1,1,1,1,1,1,1,1,1,1,1
1,1,1,1,1,1,1,1,1,1,1,1,1,1,1,1,1
1,1,1,1,1,1,1,1,1,1,1,1,1,1,1,1,1
1,1,1,1,1,1,1,1,1,1,1,1,1,1,1,1,1
endlayer

layer
1,1,1,1,1,1,1,1,1,1,1,1,1,1,1,1,1
1,1,1,1,1,1,1,1,1,1,1,1,1,1,1,1,1
1,1,1,1,1,1,1,1,1,1,1,1,1,1,1,1,1
1,1,1,1,1,1,1,1,1,1,1,1,1,1,1,1,1
1,1,1,1,1,1,1,1,1,1,1,1,1,1,1,1,1
1,1,1,1,1,1,1,1,1,1,1,1,1,1,1,1,1
1,1,1,1,1,1,1,1,1,1,1,1,1,1,1,1,1
1,1,1,1,1,1,1,1,1,1,1,1,1,1,1,1,1
1,1,1,1,1,1,1,1,1,1,1,1,1,1,1,1,1
1,1,1,1,1,1,1,1,1,1,1,1,1,1,1,1,1
1,1,1,1,1,1,1,1,1,1,1,1,1,1,1,1,1
1,1,1,1,1,1,1,1,1,1,1,1,1,1,1,1,1
1,1,1,1,1,1,1,1,1,1,1,1,1,1,1,1,1
1,1,1,1,1,1,1,1,1,1,1,1,1,1,1,1,1
1,1,1,1,1,1,1,1,1,1,1,1,1,1,1,1,1
1,2,2,2,1,1,1,1,1,1,1,1,1,1,1,1,1
1,2,2,2,1,1,1,1,1,1,1,1,1,1,1,1,1
1,2,2,2,1,1,1,1,1,1,1,1,1,1,1,1,1
1,1,1,1,1,1,1,1,1,1,1,1,1,1,1,1,1
1,1,1,1,1,1,1,1,1,1,1,1,1,1,1,1,1
1,1,1,1,1,1,1,1,1,1,1,1,1,1,1,1,1
1,1,1,1,1,1,1,1,1,1,1,1,1,1,1,1,1
endlayer

layer
3,3,3,3,3,3,3,3,3,3,3,3,3,3,3,3,3
3,3,3,3,3,3,3,3,3,3,3,3,3,3,3,3,3
3,3,3,3,3,3,3,3,3,3,3,3,3,3,3,3,3
3,3,3,3,3,3,3,3,3,3,3,3,3,3,3,3,3
3,3,3,3,3,3,3,3,3,3,3,3,3,3,3,3,3
3,3,3,3,3,3,3,3,3,3,3,3,3,3,3,3,3
3,3,3,3,3,3,3,3,3,3,3,3,3,3,3,3,3
3,3,3,3,3,3,3,3,3,3,3,3,3,3,3,3,3
3,3,3,3,3,3,3,3,3,3,3,3,3,3,3,3,3
3,3,3,3,3,3,3,3,3,3,3,3,3,3,3,3,3
3,3,3,3,3,3,3,3,3,3,3,3,3,3,3,3,3
3,3,3,3,3,3,3,3,3,3,3,3,3,3,3,3,3
3,3,3,3,3,3,3,3,3,3,3,3,3,3,3,3,3
3,3,3,3,3,3,3,3,3,3,3,3,3,3,3,3,3
3,3,3,3,3,3,3,3,3,3,3,3,3,3,3,3,3
3,2,2,2,3,3,3,3,3,3,3,3,3,3,3,3,3
3,2,2,2,3,3,3,3,3,3,3,3,3,3,3,3,3
3,2,2,2,3,3,3,3,3,3,3,3,3,3,3,3,3
3,3,3,3,3,3,3,3,3,3,3,3,3,3,3,3,3
3,3,3,3,3,3,3,3,3,3,3,3,3,3,3,3,3
3,3,3,3,3,3,3,3,3,3,3,3,3,3,3,3,3
3,3,3,3,3,3,3,3,3,3,3,3,3,3,3,3,3
endlayer

layer
3,3,3,3,3,3,3,3,3,3,3,3,3,3,3,3,3
3,3,3,3,3,3,3,3,3,3,3,4,4,0,0,4,3
3,3,3,3,3,3,3,3,3,3,3,5,0,0,0,0,3
3,3,3,3,3,3,3,3,3,3,3,3,4,7,6,4,3
3,3,3,3,3,3,3,3,3,3,3,3,3,3,3,3,3
3,3,3,3,3,3,3,3,3,3,3,3,3,3,3,3,3
3,3,3,3,3,3,3,3,3,3,3,3,3,3,3,3,3
3,3,3,3,3,3,3,3,3,3,3,3,3,3,3,3,3
3,3,3,3,3,3,3,3,3,3,3,3,3,3,3,3,3
3,3,3,3,3,3,3,3,3,3,3,3,3,3,3,3,3
3,3,3,3,3,3,3,3,3,3,3,3,3,3,3,3,3
3,3,3,3,3,3,3,3,3,3,3,3,3,3,3,3,3
3,3,3,3,3,3,3,3,3,3,3,3,3,3,3,3,3
3,3,3,3,3,3,3,3,3,3,3,3,3,3,3,3,3
3,3,3,3,3,3,3,3,3,3,3,3,3,3,3,3,3
3,2,2,2,3,3,3,3,3,3,3,3,3,3,3,3,3
3,2,2,2,3,3,3,3,3,3,3,3,3,3,3,3,3
3,2,2,2,3,3,3,3,3,3,3,3,3,3,3,3,3
3,3,3,3,3,3,3,3,3,3,3,3,3,3,3,3,3
3,3,3,3,3,3,3,3,3,3,3,3,3,3,3,3,3
3,3,3,3,3,3,3,3,3,3,3,3,3,3,3,3,3
3,3,3,3,3,3,3,3,3,3,3,3,3,3,3,3,3
endlayer

layer
8,8,8,8,8,8,8,8,8,8,8,8,8,8,8,8,8
8,8,8,8,8,8,8,8,8,8,8,4,4,0,0,4,8
8,8,8,8,8,8,8,8,8,8,8,5,0,0,0,0,8
8,8,8,8,8,8,8,8,8,8,8,8,4,0,0,4,8
8,8,8,8,8,8,8,8,8,8,8,8,8,8,8,8,8
8,8,8,8,8,8,8,8,8,8,8,8,8,8,8,8,8
8,8,8,8,8,8,8,8,8,8,8,8,8,8,8,8,8
8,8,8,8,8,8,8,8,8,8,8,8,8,8,8,8,8
8,8,8,8,8,8,8,8,8,8,8,8,8,8,8,8,8
8,8,8,8,8,8,8,8,8,8,8,8,8,8,8,8,8
8,8,8,8,8,8,8,8,8,8,8,8,8,8,8,8,8
8,8,8,8,8,8,8,8,8,8,8,8,8,8,8,8,8
8,8,8,8,8,8,8,8,8,8,8,8,8,8,8,8,8
8,8,8,8,8,8,8,8,8,8,8,8,8,8,8,8,8
8,8,8,8,8,8,8,8,8,8,8,8,8,8,8,8,8
8,2,2,2,8,8,8,8,8,8,8,8,8,8,8,8,8
8,2,2,2,8,8,8,8,8,8,8,8,8,8,8,8,8
8,2,2,2,8,8,8,8,8,8,8,8,9,8,8,8,8
8,8,8,8,8,8,8,8,8,8,8,8,8,8,8,8,8
8,8,8,8,8,8,8,8,8,8,8,8,8,8,8,8,8
8,8,8,8,8,8,8,8,8,8,8,8,8,8,8,8,8
8,8,8,8,8,8,8,8,8,8,8,8,8,8,8,8,8
endlayer

layer
8,8,8,8,8,8,8,8,8,8,8,8,8,8,8,8,8
8,11,11,11,11,11,10,10,8,8,8,4,4,4,4,4,8
8,11,11,11,11,11,10,10,8,8,8,5,4,4,4,4,8
8,11,11,11,11,11,10,10,8,8,8,8,4,4,4,4,8
8,11,11,11,8,8,8,8,8,8,8,8,8,8,8,8,8
8,11,11,11,8,12,12,12,12,12,12,12,12,12,12,8,8
8,11,11,11,8,12,12,12,12,12,12,12,12,12,12,8,8
8,8,8,8,8,12,12,2,12,12,12,12,2,12,12,8,8
8,8,8,8,8,12,12,12,12,12,12,12,12,12,12,8,8
8,8,8,8,8,12,12,12,12,12,12,12,12,12,12,8,8
8,8,8,8,8,12,12,12,12,12,12,12,12,12,12,8,8
8,8,8,8,8,12,12,12,12,12,12,12,12,12,12,8,8
8,8,8,8,8,12,12,2,12,12,12,12,2,12,12,8,8
8,8,8,8,8,12,12,12,12,12,12,12,12,12,12,8,8
8,8,8,8,8,12,12,12,12,12,12,12,12,12,12,8,8
8,13,13,13,8,12,12,12,12,12,12,12,12,12,12,8,8
8,13,0,13,8,12,12,12,12,12,12,12,12,12,12,8,8
8,13,13,13,8,12,12,2,12,12,12,12,2,12,12,8,8
8,8,8,8,8,12,12,12,12,12,12,12,12,12,12,8,8
8,8,8,8,8,12,12,12,12,12,12,12,12,12,12,8,8
8,8,8,8,8,8,8,8,8,8,8,8,8,8,8,8,8
8,8,8,8,8,8,8,8,8,8,8,8,8,8,8,8,8
endlayer

layer
0,0,0,0,0,0,0,0,0,0,0,0,0,0,0,0,0
0,11,11,11,11,11,0,0,0,0,8,8,8,8,8,8,0
0,11,0,0,0,14,0,0,0,0,0,8,8,8,8,8,0
0,11,0,15,11,11,0,0,0,0,0,0,8,8,8,8,0
0,11,17,11,0,0,0,0,0,0,0,0,0,0,0,0,16
0,11,22,11,0,19,20,21,21,20,20,19,19,19,18,0,16
0,11,11,11,0,23,19,20,20,19,21,19,19,21,19,0,16
0,8,8,8,0,23,20,0,19,19,21,21,0,19,19,0,16
0,8,8,8,0,21,21,20,20,21,21,20,19,19,18,0,16
0,8,8,8,0,19,19,18,20,21,21,21,19,19,20,0,16
0,8,8,8,0,21,20,19,19,21,19,23,19,20,21,0,16
0,8,8,8,0,19,20,20,19,19,20,19,21,19,21,0,16
0,8,8,8,0,20,19,0,18,19,20,21,0,20,20,0,16
0,8,8,0,0,21,19,20,19,20,21,20,21,19,23,0,16
0,0,0,0,0,19,19,20,19,21,21,19,19,21,20,0,16
0,16,16,16,0,21,21,20,20,20,19,19,21,21,23,0,16
0,16,0,16,0,20,21,20,20,19,21,19,20,19,20,0,16
0,16,16,16,0,19,19,0,20,19,20,19,0,21,23,0,16
0,0,0,0,0,20,19,19,19,20,19,19,23,19,21,0,16
0,8,8,8,0,19,20,19,19,19,18,20,20,19,19,0,16
0,0,8,0,0,0,0,0,0,0,0,0,0,0,0,0,16
0,0,0,0,16,16,16,16,16,16,16,16,16,16,16,16,16
endlayer

layer
0,0,0,0,0,0,0,0,0,0,0,0,0,0,0,0,0
0,11,11,11,24,11,0,0,0,0,0,0,0,0,0,0,0
0,24,0,0,0,25,0,0,0,0,0,0,8,8,8,0,0
0,11,0,13,24,11,0,0,0,0,0,0,0,0,0,0,0
0,24,0,24,0,0,0,0,0,0,0,0,0,0,0,0,0
0,11,27,11,0,0,0,0,0,0,0,0,0,0,26,0,0
0,11,11,11,0,0,0,0,0,0,0,0,0,0,0,0,0
0,0,8,0,0,0,0,0,0,0,0,0,0,0,0,0,0
0,0,8,0,0,0,0,0,0,0,0,0,0,0,26,0,0
0,0,8,0,0,0,0,26,0,0,0,0,0,0,0,0,0
0,0,8,0,0,0,0,0,0,0,0,0,0,0,0,0,0
0,0,8,0,0,0,0,0,0,0,0,0,0,0,0,0,0
0,0,8,0,0,0,0,0,26,0,0,0,0,0,0,0,0
0,0,0,0,0,0,0,0,0,0,0,0,0,0,0,0,0
0,0,0,0,0,0,0,0,0,0,0,0,0,0,0,0,0
0,0,16,0,0,0,0,0,0,0,0,0,0,0,0,0,0
0,0,0,0,0,0,0,0,0,0,0,0,0,0,0,0,0
0,0,16,0,0,0,0,0,0,0,0,0,0,0,0,0,0
0,0,0,0,0,0,0,0,0,0,0,0,0,0,0,0,0
0,0,8,0,0,0,0,0,0,0,26,0,0,0,0,0,0
0,0,0,0,0,0,0,0,0,0,0,0,0,0,0,0,0
0,0,0,0,0,0,0,0,0,0,0,0,0,0,0,0,0
endlayer

layer
0,0,0,0,0,0,0,0,0,0,0,0,0,0,0,0,0
0,0,0,0,28,0,0,0,0,0,0,0,0,0,0,0,0
0,28,28,28,28,28,0,0,0,0,0,0,0,0,0,0,0
0,0,28,13,28,0,0,0,0,0,0,0,0,0,0,0,0
0,28,28,28,0,0,0,0,0,0,0,0,0,0,0,0,0
0,0,28,0,0,0,0,0,0,0,0,0,0,0,0,0,0
0,0,0,0,0,0,0,0,0,0,0,0,0,0,0,0,0
0,0,0,0,0,0,0,0,0,0,0,0,0,0,0,0,0
0,0,0,0,0,0,0,0,0,0,0,0,0,0,0,0,0
0,0,0,0,0,0,0,0,0,0,0,0,0,0,0,0,0
0,0,0,0,0,0,0,0,0,0,0,0,0,0,0,0,0
0,0,0,0,0,0,0,0,0,0,0,0,0,0,0,0,0
0,0,0,0,0,0,0,0,0,0,0,0,0,0,0,0,0
0,0,0,0,0,0,0,0,0,0,0,0,0,0,0,0,0
0,0,0,0,0,0,0,0,0,0,0,0,0,0,0,0,0
0,0,29,0,0,0,0,0,0,0,0,0,0,0,0,0,0
0,0,29,0,0,0,0,0,0,0,0,0,0,0,0,0,0
0,0,29,0,0,0,0,0,0,0,0,0,0,0,0,0,0
0,0,0,0,0,0,0,0,0,0,0,0,0,0,0,0,0
0,0,0,0,0,0,0,0,0,0,0,0,0,0,0,0,0
0,0,0,0,0,0,0,0,0,0,0,0,0,0,0,0,0
0,0,0,0,0,0,0,0,0,0,0,0,0,0,0,0,0
endlayer

