
# Created by Ruins mod version 15.2 Ingame Parser
# authoring Player: Mensrea

weight=4
embed_into_distance=7
acceptable_target_blocks=
unacceptable_target_blocks=flowing_water,water,flowing_lava,lava
dimensions=10,22,17
allowable_overhang=0
max_leveling=2
leveling_buffer=0
preserve_water=0
preserve_lava=0
preventRotation=1

rule1=0,100,PFAAGeologica:mediumStone-0
rule2=0,100,minecraft:sand-1
rule3=0,100,minecraft:water-0
rule4=0,100,minecraft:planks-0
rule5=0,100,minecraft:ladder-5
rule6=0,100,ChestGenHook:mineshaftCorridor:5-4
rule7=0,100,minecraft:dirt-0
rule8=0,100,minecraft:gravel-0
rule9=0,100,PFAAGeologica:strongStoneBrick-9
rule10=0,100,IW:lightwhite-0
rule11=0,100,minecraft:stonebrick-0
rule12=0,100,minecraft:wooden_door-1
rule13=0,100,minecraft:furnace-4
rule14=0,100,minecraft:fence-0
rule15=0,100,minecraft:bed-3
rule16=0,100,ProjRed|Exploration:projectred.exploration.lily-0
rule17=0,100,minecraft:bed-11
rule18=0,100,minecraft:glass-0
rule19=0,100,minecraft:wooden_door-8
rule20=0,100,minecraft:wooden_slab-4

layer
1,1,1,1,1,1,1,1,1,1,1,1,1,1,1,1,1
1,1,1,1,1,1,1,1,1,1,1,1,1,1,1,1,1
1,1,1,1,1,1,1,1,1,1,1,1,1,1,1,1,1
1,1,1,1,1,1,1,1,1,1,1,1,1,1,1,1,1
1,1,1,1,1,1,1,1,1,1,1,1,1,1,1,1,1
1,1,1,1,1,1,1,1,1,1,1,1,1,1,1,1,1
1,1,1,1,1,1,1,1,1,1,1,1,1,1,1,1,1
1,1,1,1,1,1,1,1,1,1,1,1,1,1,1,1,1
1,1,1,1,1,1,1,1,1,1,1,1,1,1,1,1,1
1,1,1,1,1,1,1,1,1,1,1,1,1,1,1,1,1
1,1,1,1,1,1,1,1,1,1,1,1,1,1,1,1,1
1,1,1,1,1,1,1,1,1,1,1,1,1,1,1,1,1
1,1,1,1,1,1,1,1,1,1,1,1,1,1,1,1,1
1,1,1,1,1,1,1,1,1,1,1,1,1,1,1,1,1
1,1,1,1,1,1,1,1,1,1,1,1,1,1,1,1,1
1,1,1,1,1,1,1,1,1,1,1,1,1,1,1,1,1
1,1,1,1,1,1,1,1,1,1,1,1,1,1,1,1,1
1,1,1,1,1,1,1,1,1,1,1,1,1,1,1,1,1
1,1,1,1,1,1,1,1,1,1,1,1,1,1,1,1,1
1,1,1,1,1,1,1,1,1,1,1,1,1,1,1,1,1
1,1,1,1,1,1,1,1,1,1,1,1,1,1,1,1,1
1,1,1,1,1,1,1,1,1,1,1,1,1,1,1,1,1
endlayer

layer
2,2,2,2,2,2,2,2,2,2,2,2,2,2,2,2,2
2,2,2,2,2,2,2,2,2,2,2,2,2,2,2,2,2
2,2,2,2,2,2,2,2,2,2,2,2,2,2,2,2,2
2,2,2,2,2,2,2,2,2,2,2,2,2,2,2,2,2
2,2,2,2,2,2,2,2,2,2,2,2,2,2,2,2,2
2,2,2,2,2,2,2,2,2,2,2,2,2,2,2,2,2
2,2,2,2,2,2,2,2,2,2,2,2,2,2,2,2,2
2,2,2,2,2,2,2,2,2,2,2,2,2,2,2,2,2
2,2,2,2,2,2,2,2,2,2,2,2,2,2,2,2,2
2,2,2,2,2,2,2,2,2,2,2,2,2,2,2,2,2
2,2,2,2,2,2,2,2,2,2,2,2,2,2,2,2,2
2,2,2,2,2,2,2,2,2,2,2,2,2,2,2,2,2
2,2,2,2,2,2,2,2,2,2,2,2,2,2,2,2,2
2,2,2,2,2,2,2,2,2,2,2,2,2,2,2,2,2
2,2,2,2,2,2,2,2,2,2,2,2,2,2,2,2,2
2,2,2,2,2,2,2,2,2,2,2,2,2,2,2,2,2
2,2,2,2,2,2,2,2,2,2,2,2,2,2,2,2,2
2,2,2,2,2,2,2,2,2,2,2,2,2,2,2,2,2
2,2,2,2,2,2,2,2,2,2,2,2,2,2,2,2,2
2,2,2,2,2,2,2,2,2,2,2,2,2,2,2,2,2
2,2,2,2,2,2,2,2,2,2,2,2,2,2,2,2,2
2,2,2,2,2,2,2,2,2,2,2,2,2,2,2,2,2
endlayer

layer
2,2,2,2,2,2,2,2,2,2,2,2,2,2,2,2,2
2,2,2,2,2,2,2,2,2,2,2,2,2,2,2,2,2
2,2,2,2,2,2,2,2,2,2,2,2,2,2,2,2,2
2,2,2,2,2,2,2,2,2,2,2,2,2,2,2,2,2
2,2,2,2,2,2,2,2,2,2,2,2,2,2,2,2,2
2,2,2,2,2,2,2,2,2,2,2,2,2,2,2,2,2
2,2,2,2,2,2,2,2,2,2,2,2,2,2,2,2,2
2,2,2,2,2,2,2,2,2,2,2,2,2,2,2,2,2
2,2,2,2,2,2,2,2,2,2,2,2,2,2,2,2,2
2,2,2,2,2,2,2,2,2,2,2,2,2,2,2,2,2
2,2,2,2,2,2,2,2,2,2,2,2,2,2,2,2,2
2,2,2,2,2,2,2,2,2,2,2,2,2,2,2,2,2
2,2,2,2,2,2,2,2,2,2,2,2,2,2,2,2,2
2,2,2,2,2,2,2,2,2,2,2,2,2,2,2,2,2
2,2,2,2,2,2,2,2,2,2,2,2,2,2,2,2,2
2,3,3,3,2,2,2,2,2,2,2,2,2,2,2,2,2
2,3,3,3,2,2,2,2,2,2,2,2,2,2,2,2,2
2,3,3,3,2,2,2,2,2,2,2,2,2,2,2,2,2
2,2,2,2,2,2,2,2,2,2,2,2,2,2,2,2,2
2,2,2,2,2,2,2,2,2,2,2,2,2,2,2,2,2
2,2,2,2,2,2,2,2,2,2,2,2,2,2,2,2,2
2,2,2,2,2,2,2,2,2,2,2,2,2,2,2,2,2
endlayer

layer
2,2,2,2,2,2,2,2,2,2,2,2,2,2,2,2,2
2,2,2,2,2,2,2,2,2,2,2,2,2,2,2,2,2
2,2,2,2,2,2,2,2,2,2,2,2,2,2,2,2,2
2,2,2,2,2,2,2,2,2,2,2,2,2,2,2,2,2
2,2,2,2,2,2,2,2,2,2,2,2,2,2,2,2,2
2,2,2,2,2,2,2,2,2,2,2,2,2,2,2,2,2
2,2,2,2,2,2,2,2,2,2,2,2,2,2,2,2,2
2,2,2,2,2,2,2,2,2,2,2,2,2,2,2,2,2
2,2,2,2,2,2,2,2,2,2,2,2,2,2,2,2,2
2,2,2,2,2,2,2,2,2,2,2,2,2,2,2,2,2
2,2,2,2,2,2,2,2,2,2,2,2,2,2,2,2,2
2,2,2,2,2,2,2,2,2,2,2,2,2,2,2,2,2
2,2,2,2,2,2,2,2,2,2,2,2,2,2,2,2,2
2,2,2,2,2,2,2,2,2,2,2,2,2,2,2,2,2
2,2,2,2,2,2,2,2,2,2,2,2,2,2,2,2,2
2,3,3,3,2,2,2,2,2,2,2,2,2,2,2,2,2
2,3,3,3,2,2,2,2,2,2,2,2,2,2,2,2,2
2,3,3,3,2,2,2,2,2,2,2,2,2,2,2,2,2
2,2,2,2,2,2,2,2,2,2,2,2,2,2,2,2,2
2,2,2,2,2,2,2,2,2,2,2,2,2,2,2,2,2
2,2,2,2,2,2,2,2,2,2,2,2,2,2,2,2,2
2,2,2,2,2,2,2,2,2,2,2,2,2,2,2,2,2
endlayer

layer
2,2,2,2,2,2,2,2,2,2,2,2,2,2,2,2,2
2,2,2,2,2,2,2,2,2,2,2,4,4,0,0,4,2
2,2,2,2,2,2,2,2,2,2,2,5,0,0,0,0,2
2,2,2,2,2,2,2,2,2,2,2,2,4,6,6,4,2
2,2,2,2,2,2,2,2,2,2,2,2,2,2,2,2,2
2,2,2,2,2,2,2,2,2,2,2,2,2,2,2,2,2
2,2,2,2,2,2,2,2,2,2,2,2,2,2,2,2,2
2,2,2,2,2,2,2,2,2,2,2,2,2,2,2,2,2
2,2,2,2,2,2,2,2,2,2,2,2,2,2,2,2,2
2,2,2,2,2,2,2,2,2,2,2,2,2,2,2,2,2
2,2,2,2,2,2,2,2,2,2,2,2,2,2,2,2,2
2,2,2,2,2,2,2,2,2,2,2,2,2,2,2,2,2
2,2,2,2,2,2,2,2,2,2,2,2,2,2,2,2,2
2,2,2,2,2,2,2,2,2,2,2,2,2,2,2,2,2
2,2,2,2,2,2,2,2,2,2,2,2,2,2,2,2,2
2,3,3,3,2,2,2,2,2,2,2,2,2,2,2,2,2
2,3,3,3,2,2,2,2,2,2,2,2,2,2,2,2,2
2,3,3,3,2,2,2,2,2,2,2,2,2,2,2,2,2
2,2,2,2,2,2,2,2,2,2,2,2,2,2,2,2,2
2,2,2,2,2,2,2,2,2,2,2,2,2,2,2,2,2
2,2,2,2,2,2,2,2,2,2,2,2,2,2,2,2,2
2,2,2,2,2,2,2,2,2,2,2,2,2,2,2,2,2
endlayer

layer
2,2,2,2,2,2,2,2,2,2,2,2,2,2,2,2,2
2,2,2,2,2,2,2,2,2,2,2,4,4,0,0,4,2
2,2,2,2,2,2,2,2,2,2,2,5,0,0,0,0,2
2,2,2,2,2,2,2,2,2,2,2,2,4,0,0,4,2
2,2,2,2,2,2,2,2,2,2,2,2,2,2,2,2,2
2,2,2,2,2,2,2,2,2,2,2,2,2,2,2,2,2
2,2,2,2,2,2,2,2,2,2,2,2,2,2,2,2,2
2,2,2,2,2,2,2,2,2,2,2,2,2,2,2,2,2
2,2,2,2,2,2,2,2,2,2,2,2,2,2,2,2,2
2,2,2,2,2,2,2,2,2,2,2,2,2,2,2,2,2
2,2,2,2,2,2,2,2,2,2,2,2,2,2,2,2,2
2,2,2,2,2,2,2,2,2,2,2,2,2,2,2,2,2
2,2,2,2,2,2,2,2,2,2,2,2,2,2,2,2,2
2,2,2,2,2,2,2,2,2,2,2,2,2,2,2,2,2
2,2,2,2,2,2,2,2,2,2,2,2,2,2,2,2,2
2,3,3,3,2,2,2,2,2,2,2,2,2,2,2,2,2
2,3,3,3,2,2,2,2,2,2,2,2,2,2,2,2,2
2,3,3,3,2,2,2,2,2,2,2,2,7,2,2,2,2
2,2,2,2,2,2,2,2,2,2,2,2,2,2,2,2,2
2,2,2,2,2,2,2,2,2,2,2,2,2,2,2,2,2
2,2,2,2,2,2,2,2,2,2,2,2,2,2,2,2,2
2,2,2,2,2,2,2,2,2,2,2,2,2,2,2,2,2
endlayer

layer
2,2,2,2,2,2,2,2,2,2,2,2,2,2,2,2,2
2,9,9,9,9,9,8,8,2,2,2,4,4,4,4,4,2
2,9,10,9,9,9,8,8,2,2,2,5,4,4,4,4,2
2,9,9,9,9,9,8,8,2,2,2,2,4,4,4,4,2
2,9,9,9,2,2,2,2,2,2,2,2,2,2,2,2,2
2,9,9,9,2,7,7,7,7,7,7,7,7,7,7,2,2
2,9,9,9,2,7,7,7,7,7,7,7,7,7,7,2,2
2,2,2,2,2,7,7,7,7,7,7,7,7,7,7,2,2
2,2,2,2,2,7,7,7,7,7,7,7,7,7,7,2,2
2,2,2,2,2,7,7,7,7,7,7,7,7,7,7,2,2
2,2,2,2,2,7,7,7,7,7,7,7,7,7,7,2,2
2,2,2,2,2,7,7,7,7,7,7,7,7,7,7,2,2
2,2,2,2,2,7,7,7,7,7,7,7,7,7,7,2,2
2,2,2,2,2,7,7,7,7,7,7,7,7,7,7,2,2
2,2,2,2,2,7,7,7,7,7,7,7,7,7,7,2,2
2,11,11,11,2,7,7,7,7,7,7,7,7,7,7,2,2
2,11,0,11,2,7,7,7,7,7,7,7,7,7,7,2,2
2,11,11,11,2,7,7,7,7,7,7,7,7,7,7,2,2
2,2,2,2,2,7,7,7,7,7,7,7,7,7,7,2,2
2,2,2,2,2,7,7,7,7,7,7,7,7,7,7,2,2
2,2,2,2,2,7,7,7,7,7,7,7,7,7,7,2,2
2,2,2,2,2,2,2,2,2,2,2,2,2,2,2,2,2
endlayer

layer
0,0,0,0,0,0,0,0,0,0,0,0,0,0,0,0,0
0,9,9,9,9,9,0,0,0,2,2,2,2,2,2,2,0
0,9,0,0,0,12,0,0,0,0,2,2,2,2,2,2,0
0,9,0,13,9,9,0,0,0,0,0,2,2,2,2,2,0
0,9,15,9,0,0,0,0,0,0,0,0,0,0,0,0,14
0,9,17,9,0,16,16,16,16,16,16,16,16,16,16,0,14
0,9,9,9,0,16,16,16,16,16,16,16,16,16,16,0,14
0,2,2,2,0,16,16,16,16,16,16,16,16,16,16,0,14
0,2,2,2,0,16,16,16,16,16,16,16,16,16,16,0,14
0,2,2,2,0,16,16,16,16,16,16,16,16,16,16,0,14
0,2,2,2,0,16,16,16,16,16,16,16,16,16,16,0,14
0,2,2,2,0,16,16,16,16,16,16,16,16,16,16,0,14
0,2,2,2,0,16,16,16,16,16,16,16,16,16,16,0,14
0,2,2,2,0,16,16,16,16,16,16,16,16,16,16,0,14
0,2,2,2,0,16,16,16,16,16,16,16,16,16,16,0,14
2,0,4,0,0,16,16,16,16,16,16,16,16,16,16,0,14
2,0,0,0,0,16,16,16,16,16,16,16,16,16,16,0,14
2,0,4,0,0,16,16,16,16,16,16,16,16,16,16,0,14
2,0,0,0,0,16,16,16,16,16,16,16,16,16,16,0,14
0,2,2,2,0,16,16,16,16,16,16,16,16,16,16,0,14
0,0,2,0,0,16,16,16,16,16,16,16,16,16,16,0,14
0,0,0,0,14,14,14,14,14,14,14,14,14,14,14,14,14
endlayer

layer
0,0,0,0,0,0,0,0,0,0,0,0,0,0,0,0,0
0,9,9,9,18,9,0,0,0,0,0,0,0,0,0,0,0
0,18,0,0,0,19,0,0,0,0,0,2,2,2,2,0,0
0,9,0,11,18,9,0,0,0,0,0,0,0,0,0,0,0
0,18,0,18,0,0,0,0,0,0,0,0,0,0,0,0,0
0,9,0,9,0,0,0,0,0,0,0,0,0,0,0,0,0
0,9,9,9,0,0,0,0,0,0,0,0,0,0,0,0,0
0,0,2,0,0,0,0,0,0,0,0,0,0,0,0,0,0
0,0,2,0,0,0,0,0,0,0,0,0,0,0,0,0,0
0,0,2,0,0,0,0,0,0,0,0,0,0,0,0,0,0
0,0,2,0,0,0,0,0,0,0,0,0,0,0,0,0,0
0,0,2,0,0,0,0,0,0,0,0,0,0,0,0,0,0
0,0,2,0,0,0,0,0,0,0,0,0,0,0,0,0,0
0,0,2,0,0,0,0,0,0,0,0,0,0,0,0,0,0
0,0,0,0,0,0,0,0,0,0,0,0,0,0,0,0,0
0,0,4,0,0,0,0,0,0,0,0,0,0,0,0,0,0
0,0,4,0,0,0,0,0,0,0,0,0,0,0,0,0,0
0,0,4,0,0,0,0,0,0,0,0,0,0,0,0,0,0
0,0,0,0,0,0,0,0,0,0,0,0,0,0,0,0,0
0,0,2,0,0,0,0,0,0,0,0,0,0,0,0,0,0
0,0,0,0,0,0,0,0,0,0,0,0,0,0,0,0,0
0,0,0,0,0,0,0,0,0,0,0,0,0,0,0,0,0
endlayer

layer
0,0,0,0,0,0,0,0,0,0,0,0,0,0,0,0,0
0,0,0,0,20,0,0,0,0,0,0,0,0,0,0,0,0
0,20,20,20,20,20,0,0,0,0,0,0,0,0,0,0,0
0,0,20,11,20,0,0,0,0,0,0,0,0,0,0,0,0
0,20,20,20,0,0,0,0,0,0,0,0,0,0,0,0,0
0,0,20,0,0,0,0,0,0,0,0,0,0,0,0,0,0
0,0,0,0,0,0,0,0,0,0,0,0,0,0,0,0,0
0,0,0,0,0,0,0,0,0,0,0,0,0,0,0,0,0
0,0,0,0,0,0,0,0,0,0,0,0,0,0,0,0,0
0,0,0,0,0,0,0,0,0,0,0,0,0,0,0,0,0
0,0,0,0,0,0,0,0,0,0,0,0,0,0,0,0,0
0,0,0,0,0,0,0,0,0,0,0,0,0,0,0,0,0
0,0,0,0,0,0,0,0,0,0,0,0,0,0,0,0,0
0,0,0,0,0,0,0,0,0,0,0,0,0,0,0,0,0
0,0,0,0,0,0,0,0,0,0,0,0,0,0,0,0,0
0,0,0,0,0,0,0,0,0,0,0,0,0,0,0,0,0
0,0,0,0,0,0,0,0,0,0,0,0,0,0,0,0,0
0,0,0,0,0,0,0,0,0,0,0,0,0,0,0,0,0
0,0,0,0,0,0,0,0,0,0,0,0,0,0,0,0,0
0,0,0,0,0,0,0,0,0,0,0,0,0,0,0,0,0
0,0,0,0,0,0,0,0,0,0,0,0,0,0,0,0,0
0,0,0,0,0,0,0,0,0,0,0,0,0,0,0,0,0
endlayer

