
# Created by Ruins mod version 15.3 Ingame Parser
# authoring Player: Mensrea

weight=6
embed_into_distance=7
acceptable_target_blocks=
unacceptable_target_blocks=flowing_water,water,flowing_lava,lava
dimensions=13,22,27
allowable_overhang=0
max_leveling=2
leveling_buffer=0
preserve_water=0
preserve_lava=0
preventRotation=1

rule1=0,100,PFAAGeologica:strongStone-7
rule2=0,100,PFAAGeologica:mediumStone-3
rule3=0,100,minecraft:stonebrick-0
rule4=0,100,minecraft:water-0
rule5=0,100,PFAAGeologica:weakStone-1
rule6=0,100,minecraft:sand-1
rule7=0,100,ChestGenHook:strongholdLibrary:5-2
rule8=0,100,minecraft:dirt-0
rule9=0,100,PFAAChemica:pollutedSoil-0
rule10=0,100,minecraft:planks-0
rule11=0,100,minecraft:oak_stairs-0
rule12=0,100,minecraft:gravel-0
rule13=0,100,ImmersiveEngineering:stoneDecoration-0
rule14=0,100,minecraft:stone_brick_stairs-3
rule15=0,100,minecraft:fence-0
rule16=0,100,minecraft:stone_brick_stairs-1
rule17=0,100,IW:steelblock-0
rule18=0,100,ImmersiveEngineering:treatedWood-1
rule19=0,100,IW:steelsiding-0
rule20=0,100,minecraft:farmland-7
rule21=0,100,minecraft:stone_brick_stairs-2
rule22=0,100,IW:fiberboard-0
rule23=0,100,ImmersiveEngineering:woodenDecoration-1
rule24=0,100,minecraft:glass-0
rule25=0,100,minecraft:bookshelf-0
rule26=2,100,WallSign:null:null:null:null-2
rule27=0,100,minecraft:birch_stairs-1
rule28=2,100,WallSign:null:null:null:null-3
rule29=0,100,minecraft:wheat-4
rule30=0,100,minecraft:wheat-7
rule31=0,100,minecraft:wheat-5
rule32=0,100,ImmersiveEngineering:hemp-4
rule33=0,100,minecraft:bed-10
rule34=0,100,minecraft:bed-2
rule35=0,100,minecraft:furnace-3
rule36=0,100,IW:metaldoor-2
rule37=0,100,IW:metaldoor-3
rule38=0,100,minecraft:wheat-6
rule39=0,100,minecraft:birch_stairs-3
rule40=0,100,ChestGenHook:mineshaftCorridor:5-2
rule41=0,100,minecraft:wheat-3
rule42=0,100,minecraft:cauldron-3
rule43=0,100,ThermalExpansion:Workbench-1
rule44=0,100,IW:computer1-0
rule45=0,100,minecraft:birch_stairs-0
rule46=0,100,minecraft:wooden_door-2
rule47=0,100,IInventory;minecraft:chest;minecraft:wheat_seeds#64#0#0+minecraft:wheat_seeds#8#0#1+minecraft:dye#58#15#2+minecraft:sapling#5#0#3+IC2:itemCellEmpty#49#1#4+ThermalFoundation:tool.hoePlatinum#1#0#5+ThermalFoundation:tool.sicklePlatinum#1#0#6-3
rule48=0,100,IW:smalllightwhite-3
rule49=0,100,IW:smalllightwhite-1
rule50=0,100,ImmersiveEngineering:hemp-5
rule51=0,100,IW:smalllightwhite-2
rule52=0,100,IW:metaldoor-8
rule53=0,100,minecraft:wooden_pressure_plate-0
rule54=0,100,IW:smalllightwhite-4
rule55=0,100,minecraft:stained_glass-15
rule56=0,100,minecraft:wooden_door-8
rule57=0,100,IW:scrapmetalsheet-0
rule58=0,100,IW:machinery1-0
rule59=0,100,IC2:blockGenerator-3

layer
1,1,1,1,1,1,1,1,1,1,1,1,1,1,1,1,1,1,1,1,1,1,1,1,1,1,1
1,1,1,1,1,1,1,1,1,1,1,1,1,1,1,1,1,1,1,1,1,1,1,1,1,1,1
1,1,1,1,1,1,1,1,1,1,1,1,1,1,1,1,1,1,1,1,1,1,1,1,1,1,1
1,1,1,1,1,1,1,1,1,1,1,1,1,1,1,1,1,1,1,1,1,1,1,1,1,1,1
1,1,1,1,1,1,1,1,1,1,1,1,1,1,1,1,1,1,1,1,1,1,1,1,1,1,1
1,1,1,1,1,1,1,1,1,1,1,1,1,1,1,1,1,1,1,1,1,1,1,1,1,1,1
1,1,1,1,1,1,1,1,1,1,1,1,1,1,1,1,1,1,1,1,1,1,1,1,1,1,1
1,1,1,1,1,1,1,1,1,1,1,1,1,1,1,1,1,1,1,1,1,1,1,1,1,1,1
1,1,1,1,1,1,1,1,1,1,1,1,1,1,1,1,1,1,1,1,1,1,1,1,1,1,1
1,1,1,1,1,1,1,1,1,1,1,1,1,1,1,1,1,1,1,1,1,1,1,1,1,1,1
1,1,1,1,1,1,1,1,1,1,1,1,1,1,1,1,1,1,1,1,1,1,1,1,1,1,1
1,1,1,1,1,1,1,1,1,1,1,1,1,1,1,1,1,1,1,1,1,1,1,1,1,1,1
1,1,1,1,1,1,1,1,1,1,1,1,1,1,1,1,1,1,1,1,1,1,1,1,1,1,1
1,1,1,1,1,1,1,1,1,1,1,1,1,1,1,1,1,1,1,1,1,1,1,1,1,1,1
1,1,1,1,1,1,1,1,1,1,1,1,1,1,1,1,1,1,1,1,1,1,1,1,1,1,1
1,1,1,1,1,1,1,1,1,1,1,1,1,1,1,1,1,1,1,1,1,1,1,1,1,1,1
1,1,1,1,1,1,1,1,1,1,1,1,1,1,1,1,1,1,1,1,1,1,1,1,1,1,1
1,1,1,1,1,1,1,1,1,1,1,1,1,1,1,1,1,1,1,1,1,1,1,1,1,1,1
1,1,1,1,1,1,1,1,1,1,1,1,1,1,1,1,1,1,1,1,1,1,1,1,1,1,1
1,1,1,1,1,1,1,1,1,1,1,1,1,1,1,1,1,1,1,1,1,1,1,1,1,1,1
1,1,1,1,1,1,1,1,1,1,1,1,1,1,1,1,1,1,1,1,1,1,1,1,1,1,1
1,1,1,1,1,1,1,1,1,1,1,1,1,1,1,1,1,1,1,1,1,1,1,1,1,1,1
endlayer

layer
2,2,2,2,2,2,2,2,2,2,2,2,2,2,2,2,2,2,2,2,2,2,2,2,2,2,2
2,2,2,2,2,2,2,2,2,2,2,2,2,2,2,2,2,2,2,2,2,2,2,2,2,2,2
2,2,2,2,2,2,2,2,2,2,2,2,2,2,2,2,2,2,2,2,2,2,2,2,2,2,2
2,2,2,2,2,2,2,2,2,2,2,2,2,2,2,2,2,2,2,2,2,2,2,2,2,2,2
2,2,2,2,2,2,2,2,2,2,2,2,2,2,2,2,2,2,2,2,2,2,2,2,2,2,2
2,2,2,2,2,2,2,2,2,2,2,2,2,2,2,2,2,2,2,2,2,2,2,2,2,2,2
2,2,2,2,2,2,2,2,2,2,2,2,2,2,2,2,2,2,2,2,2,2,2,2,2,2,2
2,2,2,2,2,2,2,2,2,2,2,2,2,2,2,2,2,2,2,2,2,2,2,2,2,2,2
2,2,2,2,2,2,2,2,2,2,2,2,2,2,2,2,2,2,2,2,2,2,2,2,2,2,2
2,2,2,2,2,2,2,2,2,2,2,2,2,2,2,2,2,3,3,3,3,3,3,3,3,2,2
2,2,2,2,2,2,2,2,2,2,2,2,2,2,2,2,2,3,3,3,3,3,3,3,3,2,2
2,2,2,2,2,2,2,2,2,2,2,2,2,2,2,2,2,3,3,3,3,3,3,3,3,2,2
2,2,2,2,2,2,2,2,2,2,2,2,2,2,2,2,2,3,3,3,3,3,3,3,3,2,2
2,2,2,2,2,2,2,2,2,2,2,2,2,2,2,2,2,3,3,3,3,3,3,3,3,2,2
2,2,2,2,2,2,2,2,2,2,2,2,2,2,2,2,2,3,3,3,3,3,3,3,3,2,2
2,2,2,2,2,2,2,2,2,2,2,2,2,2,2,2,2,3,3,3,3,3,3,3,3,2,2
2,2,2,2,2,2,2,2,2,2,2,2,2,2,2,2,2,3,3,3,3,3,3,3,3,2,2
2,2,2,2,2,2,2,2,2,2,2,2,2,2,2,2,2,2,2,2,2,2,3,3,3,2,2
2,2,2,2,2,2,2,2,2,2,2,2,2,2,2,2,2,2,2,2,2,2,3,3,3,2,2
2,2,2,2,2,2,2,2,2,2,2,2,2,2,2,2,2,2,2,2,2,2,3,3,3,2,2
2,2,2,2,2,2,2,2,2,2,2,2,2,2,2,2,2,2,2,2,2,2,2,2,2,2,2
2,2,2,2,2,2,2,2,2,2,2,2,2,2,2,2,2,2,2,2,2,2,2,2,2,2,2
endlayer

layer
2,2,2,2,2,2,2,2,2,2,2,2,2,2,2,2,2,2,2,2,2,2,2,2,2,2,2
2,2,2,2,2,2,2,2,2,2,2,2,2,2,2,2,2,2,2,2,2,2,2,2,2,2,2
2,2,2,2,2,2,2,2,2,2,2,2,2,2,2,2,2,2,2,2,2,2,2,2,2,2,2
2,2,2,2,2,2,2,2,2,2,2,2,2,2,2,2,2,2,2,2,2,2,2,2,2,2,2
2,2,2,2,2,2,2,2,2,2,2,2,2,2,2,2,2,2,2,2,2,2,2,2,2,2,2
2,2,2,2,2,2,2,2,2,2,2,2,2,2,2,2,2,2,2,2,2,2,2,2,2,2,2
2,2,2,2,2,2,2,2,2,2,2,2,2,2,2,2,2,2,2,2,2,2,2,2,2,2,2
2,2,2,2,2,2,2,2,2,2,2,2,2,2,2,2,2,2,2,2,2,2,2,2,2,2,2
2,2,2,2,2,2,2,2,2,2,2,2,2,2,2,2,2,2,2,2,2,2,2,2,2,2,2
2,2,2,2,2,2,2,2,2,2,2,2,2,2,2,2,2,3,3,3,3,3,3,3,3,2,2
2,2,2,2,2,2,2,2,2,2,2,2,2,2,2,2,2,3,4,4,4,4,4,4,3,2,2
2,2,2,2,2,2,2,2,2,2,2,2,2,2,2,2,2,3,4,4,4,4,4,4,3,2,2
2,2,2,2,2,2,2,2,2,2,2,2,2,2,2,2,2,3,4,4,4,4,4,4,3,2,2
2,2,2,2,2,2,2,2,2,2,2,2,2,2,2,2,2,3,4,4,4,4,4,4,3,2,2
2,2,2,2,2,2,2,2,2,2,2,2,2,2,2,2,2,3,4,4,4,4,4,4,3,2,2
2,2,2,2,2,2,2,2,2,2,2,2,2,2,2,2,2,3,4,4,4,4,4,4,3,2,2
2,2,2,2,2,2,2,2,2,2,2,2,2,2,2,2,2,3,3,3,3,3,3,4,3,2,2
2,2,2,2,2,2,2,2,2,2,2,2,2,2,2,2,2,2,2,2,2,2,3,4,3,2,2
2,2,2,2,2,2,2,2,2,2,2,2,2,2,2,2,2,2,2,2,2,2,3,2,3,2,2
2,2,2,2,2,2,2,2,2,2,2,2,2,2,2,2,2,2,2,2,2,2,3,3,3,2,2
2,2,2,2,2,2,2,2,2,2,2,2,2,2,2,2,2,2,2,2,2,2,2,2,2,2,2
2,2,2,2,2,2,2,2,2,2,2,2,2,2,2,2,2,2,2,2,2,2,2,2,2,2,2
endlayer

layer
5,5,5,5,5,5,5,5,5,5,5,5,5,5,5,5,5,5,5,5,5,5,5,5,5,5,5
5,5,5,5,5,5,5,5,5,5,5,5,5,5,5,5,5,5,5,5,5,5,5,5,5,5,5
5,5,5,5,5,5,5,5,5,5,5,5,5,5,5,5,5,5,5,5,5,5,5,5,5,5,5
5,5,5,5,5,5,5,5,5,5,5,5,5,5,5,5,5,5,5,5,5,5,5,5,5,5,5
5,5,5,5,5,5,5,5,5,5,5,5,5,5,5,5,5,5,5,5,5,5,5,5,5,5,5
5,5,5,5,5,5,5,5,5,5,5,5,5,5,5,5,5,5,5,5,5,5,5,5,5,5,5
5,5,5,5,5,5,5,5,5,5,5,5,5,5,5,5,5,5,5,5,5,5,5,5,5,5,5
5,5,5,5,5,5,5,5,5,5,5,5,5,5,5,5,5,5,5,5,5,5,5,5,5,5,5
5,5,5,5,5,5,5,5,5,5,5,5,5,5,5,5,5,5,5,5,5,5,5,5,5,5,5
5,5,5,5,5,5,5,5,5,5,5,5,5,5,5,5,5,3,3,3,3,3,3,3,3,5,5
5,5,5,5,5,5,5,5,5,5,5,5,5,5,5,5,5,3,4,4,4,4,4,4,3,5,5
5,5,5,5,5,5,5,5,5,5,5,5,5,5,5,5,5,3,4,4,4,4,4,4,3,5,5
5,5,5,5,5,5,5,5,5,5,5,5,5,5,5,5,5,3,4,4,4,4,4,4,3,5,5
5,5,5,5,5,5,5,5,5,5,5,5,5,5,5,5,5,3,4,4,4,4,4,4,3,5,5
5,5,5,5,5,5,5,5,5,5,5,5,5,5,5,5,5,3,4,4,4,4,4,4,3,5,5
5,5,5,5,5,5,5,5,5,5,5,5,5,5,5,5,5,3,4,4,4,4,4,4,3,5,5
5,5,5,5,5,5,5,5,5,5,5,5,5,5,5,5,5,3,3,3,3,3,3,4,3,5,5
5,5,5,5,5,5,5,5,5,5,5,5,5,5,5,5,5,5,5,5,5,5,3,4,3,5,5
5,5,5,5,5,5,5,5,5,5,5,5,5,5,5,5,5,5,5,5,5,5,3,5,3,5,5
5,5,5,5,5,5,5,5,5,5,5,5,5,5,5,5,5,5,5,5,5,5,3,3,3,5,5
5,5,5,5,5,5,5,5,5,5,5,5,5,5,5,5,5,5,5,5,5,5,5,5,5,5,5
5,5,5,5,5,5,5,5,5,5,5,5,5,5,5,5,5,5,5,5,5,5,5,5,5,5,5
endlayer

layer
5,5,5,5,5,5,5,5,5,5,5,5,5,5,5,5,5,5,5,5,5,5,5,5,5,5,5
5,5,5,5,5,5,5,5,5,5,5,5,5,5,5,5,5,5,5,5,5,5,5,5,5,5,5
5,5,5,5,5,5,5,5,5,5,5,5,5,5,5,5,5,5,5,5,5,5,5,5,5,5,5
5,5,5,5,5,5,5,5,5,5,5,5,5,5,5,5,5,5,5,5,5,5,5,5,5,5,5
5,5,5,5,5,5,5,5,5,5,5,5,5,5,5,5,5,5,5,5,5,5,5,5,5,5,5
5,5,5,5,5,5,5,5,5,5,5,5,5,5,5,5,5,5,5,5,5,5,5,5,5,5,5
5,5,5,5,5,5,5,5,5,5,5,5,5,5,5,5,5,5,5,5,5,5,5,5,5,5,5
5,5,5,5,5,5,5,5,5,5,5,5,5,5,5,5,5,5,5,5,5,5,5,5,5,5,5
5,5,5,5,5,5,5,5,5,5,5,5,5,5,5,5,5,5,5,5,5,5,5,5,5,5,5
5,5,5,5,5,5,5,5,5,5,5,5,5,5,5,5,5,3,3,3,3,3,3,3,3,5,5
5,5,5,5,5,5,5,5,5,5,5,5,5,5,5,5,5,3,4,4,4,4,4,4,3,5,5
5,5,5,5,5,5,5,5,5,5,5,5,5,5,5,5,5,3,4,4,4,4,4,4,3,5,5
5,5,5,5,5,5,5,5,5,5,5,5,5,5,5,5,5,3,4,4,4,4,4,4,3,5,5
5,5,5,5,5,5,5,5,5,5,5,5,5,5,5,5,5,3,4,4,4,4,4,4,3,5,5
5,5,5,5,5,5,5,5,5,5,5,5,5,5,5,5,5,3,4,4,4,4,4,4,3,5,5
5,5,5,5,5,5,5,5,5,5,5,5,5,5,5,5,5,3,4,4,4,4,4,4,3,5,5
5,5,5,5,5,5,5,5,5,5,5,5,5,5,5,5,5,3,3,3,3,3,3,4,3,5,5
5,5,5,5,5,5,5,5,5,5,5,5,5,5,5,5,5,5,5,5,5,5,3,4,3,5,5
5,5,5,5,5,5,5,5,5,5,5,5,5,5,5,5,5,5,5,5,5,5,3,4,3,5,5
5,5,5,5,5,5,5,5,5,5,5,5,5,5,5,5,5,5,5,5,5,5,3,3,3,5,5
5,5,5,5,5,5,5,5,5,5,5,5,5,5,5,5,5,5,5,5,5,5,5,5,5,5,5
5,5,5,5,5,5,5,5,5,5,5,5,5,5,5,5,5,5,5,5,5,5,5,5,5,5,5
endlayer

layer
6,6,6,6,6,6,6,6,6,6,6,6,6,6,6,6,6,6,6,6,6,6,6,6,6,6,6
6,6,6,6,6,6,6,6,6,6,6,6,6,6,6,6,6,6,6,6,6,6,6,6,6,6,6
6,6,6,6,6,6,6,6,6,6,6,6,6,6,6,6,6,6,6,6,6,6,6,6,6,6,6
6,6,6,6,6,6,6,6,6,6,6,6,6,6,6,6,6,6,6,6,6,6,6,6,6,6,6
6,6,6,6,6,6,6,6,6,6,6,6,6,6,6,6,6,6,6,6,6,6,6,6,6,6,6
6,6,6,6,6,6,6,6,6,6,6,6,6,6,6,6,6,6,6,6,7,6,6,6,6,6,6
6,6,6,6,6,6,6,6,6,6,6,6,6,6,6,6,6,6,6,6,6,6,6,6,6,6,6
6,6,6,6,6,6,6,6,6,6,6,6,6,6,6,6,6,6,6,6,6,6,6,6,6,6,6
6,6,6,6,6,6,6,6,6,6,6,6,6,6,6,6,6,6,6,6,6,6,6,6,6,6,6
6,6,6,6,6,6,6,6,6,6,6,6,6,6,6,6,6,3,3,3,3,3,3,3,3,6,6
6,6,6,6,6,6,6,6,6,6,6,6,6,6,6,6,6,3,3,3,3,3,3,3,3,6,6
6,6,6,6,6,6,6,6,6,6,6,6,6,6,6,6,6,3,3,3,3,3,3,3,3,6,6
6,6,6,6,6,6,6,6,6,6,6,6,6,6,6,6,6,3,3,3,3,3,3,3,3,6,6
6,6,6,6,6,6,6,6,6,6,6,6,6,6,6,6,6,3,3,3,3,3,3,3,3,6,6
6,6,6,6,6,6,6,6,6,6,6,6,6,6,6,6,6,3,3,3,3,3,3,3,3,6,6
6,6,6,6,6,6,6,6,6,6,6,6,6,6,6,6,6,3,3,3,3,3,3,3,3,6,6
6,6,6,6,6,6,6,6,6,6,6,6,6,6,6,6,6,3,3,3,3,3,3,3,3,6,6
6,6,6,6,6,6,6,6,6,6,6,6,6,6,6,6,6,6,6,6,6,6,3,3,3,6,6
6,6,6,6,6,6,6,6,6,6,6,6,6,6,6,6,6,6,6,6,6,6,3,0,3,6,6
6,6,6,6,6,6,6,6,6,6,6,6,6,6,6,6,6,6,6,6,6,6,3,3,3,6,6
6,6,6,6,6,6,6,6,6,6,6,6,6,6,6,6,6,6,6,6,6,6,6,6,6,6,6
6,6,6,6,6,6,6,6,6,6,6,6,6,6,6,6,6,6,6,6,6,6,6,6,6,6,6
endlayer

layer
6,6,6,6,6,6,6,6,6,6,6,6,6,6,0,0,0,0,0,6,6,6,6,6,6,6,6
6,6,6,6,6,6,6,6,6,6,6,6,6,6,6,0,3,6,6,3,6,6,6,6,6,3,6
6,6,6,6,6,6,6,6,6,6,6,6,6,8,6,6,6,6,6,6,6,6,6,6,6,6,6
6,6,6,6,6,6,6,6,6,6,6,6,8,8,8,6,6,6,6,6,6,6,6,6,6,6,6
6,6,6,6,6,6,6,6,6,6,6,6,8,9,9,8,6,6,6,6,0,0,0,6,6,6,6
6,6,6,6,6,6,6,6,6,6,6,6,8,8,9,8,8,6,6,0,10,10,0,10,6,6,6
6,6,6,6,6,6,6,6,6,6,6,6,6,8,8,8,6,10,10,0,0,0,0,0,0,6,6
6,6,6,6,6,6,6,6,6,6,6,6,6,8,8,0,0,0,0,0,0,0,0,10,10,6,6
6,6,6,6,6,6,6,6,6,6,6,6,6,8,8,11,3,6,6,6,10,0,0,0,6,6,6
6,6,6,6,6,6,6,6,6,6,6,6,6,8,8,6,6,6,6,6,10,0,0,10,6,6,6
0,6,6,6,6,6,6,6,6,6,6,6,8,8,8,8,6,6,6,6,6,0,6,6,6,6,6
0,6,6,6,6,6,6,6,6,6,6,6,8,9,8,8,6,6,6,6,6,6,6,6,6,6,6
0,6,6,6,6,6,6,6,6,6,6,6,8,8,8,6,6,6,6,6,6,6,6,6,6,6,6
6,6,6,6,6,6,6,6,6,6,6,6,6,8,8,8,6,6,6,3,6,6,6,6,6,3,6
6,6,6,6,6,6,6,6,6,6,6,6,6,8,9,8,8,6,6,6,6,6,6,6,6,6,6
6,6,6,6,6,6,6,6,6,6,6,6,6,8,8,12,3,6,6,6,6,3,6,6,6,3,6
6,6,6,6,6,6,6,6,6,6,6,6,8,8,12,12,12,12,3,3,3,6,6,6,6,6,6
6,6,6,6,6,6,6,6,6,6,6,6,8,8,12,12,12,12,12,6,6,6,3,3,3,6,6
6,6,6,6,6,6,6,6,6,6,6,6,8,12,12,12,12,12,12,12,12,12,3,0,3,6,0
6,6,6,6,6,12,12,12,6,6,6,6,6,12,12,12,12,12,12,12,6,6,3,3,3,6,0
0,6,6,6,6,12,12,12,12,12,12,12,12,12,12,12,12,12,12,6,0,6,6,6,6,6,0
0,0,6,6,6,6,6,6,6,6,6,6,6,6,12,12,12,12,6,6,0,0,0,6,6,0,0
endlayer

layer
0,0,0,0,6,6,6,0,0,0,0,0,0,0,0,0,0,0,0,0,0,0,0,0,0,6,6
0,13,13,13,13,13,13,13,13,13,13,13,0,0,0,0,3,0,0,3,0,0,0,0,6,3,6
6,13,13,13,13,13,13,13,13,13,13,13,0,0,0,0,0,0,0,0,0,0,0,0,0,0,0
6,13,13,13,13,13,13,13,13,13,13,13,0,0,0,0,0,0,0,0,0,0,0,0,0,0,0
6,13,13,13,13,13,13,13,13,13,13,13,0,0,0,0,0,0,0,0,0,0,0,0,0,0,0
0,13,13,13,13,13,13,13,13,13,13,13,0,0,0,0,0,0,0,0,0,0,0,0,0,0,0
0,13,13,13,13,13,13,13,13,13,13,13,0,0,0,0,0,0,0,0,0,0,0,0,0,0,0
0,13,13,13,13,13,13,13,13,13,13,13,0,0,0,0,0,0,0,0,0,0,0,0,0,0,0
0,13,13,13,13,13,13,13,13,13,13,13,0,0,0,0,3,0,0,0,0,0,0,0,0,6,6
0,13,13,13,13,13,13,13,13,13,13,13,0,0,0,0,0,0,0,0,0,0,0,0,0,6,0
0,13,13,13,13,13,13,13,13,13,13,13,0,0,0,0,0,0,0,0,0,0,0,0,0,0,0
0,13,13,13,13,13,13,13,13,13,13,13,0,0,0,0,0,0,0,0,0,0,0,0,0,0,0
0,13,13,13,13,13,13,13,13,13,13,13,0,0,0,0,0,0,0,0,0,0,0,0,0,0,0
0,13,13,13,13,13,13,13,13,13,13,13,0,0,0,0,0,0,0,3,0,0,0,0,0,3,6
0,13,13,13,13,13,13,13,13,13,13,13,0,0,0,0,0,0,0,0,0,0,0,0,0,0,0
0,13,13,13,13,13,13,13,13,13,13,13,0,0,0,0,3,0,0,0,0,3,0,0,0,3,0
0,13,13,13,13,13,13,13,13,13,13,13,0,0,0,0,0,0,14,3,3,0,0,0,0,0,0
0,13,13,13,13,13,13,13,13,13,13,13,0,0,0,0,0,0,0,0,0,0,15,3,15,0,0
0,13,13,13,13,13,13,13,13,13,13,13,0,0,0,0,0,0,0,0,0,0,15,0,15,0,0
0,0,6,6,6,16,16,16,0,0,0,0,0,0,0,0,0,0,0,0,0,0,15,3,15,0,0
0,0,0,6,0,0,0,0,0,0,0,0,0,0,0,0,0,0,0,0,0,0,0,0,0,0,0
0,0,0,0,0,0,0,0,0,0,0,0,0,0,0,0,0,0,0,0,0,0,0,0,0,0,0
endlayer

layer
0,0,0,0,0,0,0,0,0,0,0,0,0,0,0,0,0,0,0,0,0,0,0,0,0,0,0
0,13,13,13,13,13,13,13,13,13,13,13,0,0,0,0,18,18,18,17,17,17,17,17,17,17,0
0,13,20,20,20,20,20,20,20,20,20,13,0,0,0,0,18,18,18,17,19,19,19,19,19,17,0
0,13,20,20,20,20,20,20,20,20,20,13,0,0,0,0,18,18,18,17,19,19,19,19,19,17,0
0,13,20,20,20,20,20,20,20,20,20,13,0,0,0,0,18,18,18,17,19,19,19,19,19,17,0
0,13,20,20,20,20,3,20,20,20,20,13,0,0,0,0,18,18,18,17,19,19,19,19,19,17,0
0,13,20,20,20,20,4,20,20,20,20,13,0,0,0,0,18,18,18,17,19,19,19,19,19,17,0
0,13,20,20,20,20,4,20,20,20,20,13,0,0,0,0,18,18,18,17,19,19,19,19,19,17,0
0,13,20,20,20,20,4,20,20,20,20,13,0,0,0,0,18,18,18,17,19,19,19,19,19,17,0
0,13,20,20,20,20,4,20,20,20,20,13,0,0,0,0,18,18,18,17,19,19,19,19,19,17,0
0,13,20,20,20,20,4,20,20,20,20,13,0,0,0,0,18,18,18,17,19,19,19,19,19,17,0
0,13,20,20,20,20,4,20,20,20,20,13,0,0,0,0,18,18,18,17,19,19,19,19,19,17,0
0,13,20,20,20,20,4,20,20,20,20,13,0,0,0,0,18,18,18,17,19,19,19,19,19,17,0
0,13,20,20,20,20,4,20,20,20,20,13,0,0,0,0,18,18,18,17,17,17,17,17,17,17,0
0,13,20,20,20,20,3,20,20,20,20,13,0,0,0,0,18,18,18,18,18,18,18,18,18,18,0
0,13,20,20,20,20,20,20,20,20,20,13,0,0,0,0,18,18,18,18,18,18,18,18,18,18,0
0,13,3,3,3,3,3,3,3,3,3,13,0,0,0,0,0,0,0,14,3,0,0,0,0,0,0
0,13,3,21,0,0,0,0,0,14,3,13,0,0,0,0,0,0,0,0,0,0,0,17,0,0,0
0,13,13,13,13,0,0,0,13,13,13,13,0,0,0,0,0,0,0,0,0,0,0,0,0,0,0
0,0,0,6,0,0,0,0,0,0,0,0,0,0,0,0,0,0,0,0,0,0,0,17,0,0,0
0,0,0,0,0,0,0,0,0,0,0,0,0,0,0,0,0,0,0,0,0,0,0,0,0,0,0
0,0,0,0,0,0,0,0,0,0,0,0,0,0,0,0,0,0,0,0,0,0,0,0,0,0,0
endlayer

layer
0,0,0,0,0,0,0,0,0,0,0,0,0,0,0,0,0,0,0,0,0,0,0,0,0,0,0
0,13,13,24,24,24,24,24,24,24,13,13,0,0,0,0,23,0,0,17,22,22,22,22,22,17,0
0,24,32,32,32,32,31,30,30,30,29,24,0,0,0,0,0,0,0,22,28,27,26,0,25,22,0
0,24,32,32,32,32,30,30,30,31,30,24,0,0,0,0,0,0,35,22,0,0,0,34,33,22,0
0,24,32,32,32,32,30,30,30,30,30,24,0,0,0,0,0,0,15,22,36,19,22,22,22,22,0
0,24,32,32,32,32,19,30,31,38,30,24,0,0,0,0,0,0,0,22,0,37,28,27,25,22,0
0,24,32,32,32,32,19,30,30,30,30,24,0,0,0,0,0,0,39,22,0,22,0,0,0,22,0
0,24,32,32,32,32,19,41,30,30,30,24,0,0,0,0,0,0,0,22,0,22,40,34,33,22,0
0,24,32,32,32,32,19,29,29,31,30,24,0,0,0,0,23,0,39,22,0,19,22,22,22,22,0
0,24,32,32,32,32,19,30,30,30,38,24,0,0,0,0,0,0,0,22,0,43,42,27,25,22,0
0,24,32,32,32,32,19,30,30,30,30,24,0,0,0,0,0,0,39,22,0,0,0,0,39,22,0
0,24,32,32,32,32,19,29,30,30,30,24,0,0,0,0,0,0,0,22,44,0,0,15,39,22,0
0,24,32,32,32,32,19,30,30,41,30,24,0,0,0,0,0,0,0,22,25,0,28,45,25,22,0
0,24,32,32,32,32,19,38,30,30,30,24,0,0,0,0,0,0,0,17,22,22,46,22,22,17,0
0,24,32,32,32,32,19,30,30,30,30,24,0,0,0,0,0,0,0,0,0,0,0,0,0,0,0
0,24,32,32,32,32,30,30,30,41,30,24,0,0,0,0,23,0,0,0,0,23,0,0,0,23,0
0,24,0,0,0,0,0,0,0,0,0,24,0,0,0,0,0,0,0,0,0,0,0,0,0,0,0
0,24,0,0,0,0,0,0,0,0,47,24,0,0,0,0,0,0,0,0,0,0,0,17,0,0,0
0,13,24,24,13,0,0,0,13,24,24,13,0,0,0,0,0,0,0,0,0,0,48,19,0,0,0
0,0,0,0,0,0,0,0,0,0,0,0,0,0,0,0,0,0,0,0,0,0,0,17,0,0,0
0,0,0,0,0,0,0,0,0,0,0,0,0,0,0,0,0,0,0,0,0,0,0,0,0,0,0
0,0,0,0,0,0,0,0,0,0,0,0,0,0,0,0,0,0,0,0,0,0,0,0,0,0,0
endlayer

layer
0,0,0,0,0,0,0,0,0,0,0,0,0,0,0,0,0,0,0,0,0,0,0,0,0,0,0
0,13,13,24,24,24,24,24,24,24,13,13,0,0,0,0,23,0,0,17,22,22,24,22,22,17,0
0,24,50,50,50,50,0,0,0,0,0,24,0,0,0,0,0,0,0,22,49,0,0,0,0,22,0
0,24,50,50,50,50,0,0,0,0,0,24,0,0,0,0,0,0,0,24,0,0,0,0,51,22,0
0,24,50,50,50,50,0,0,0,0,0,24,0,0,0,0,0,0,53,22,52,19,22,22,22,22,0
0,24,50,50,50,50,0,0,0,0,0,24,0,0,0,0,0,0,0,22,0,52,0,0,48,22,0
0,24,50,50,50,50,0,0,0,0,0,24,0,0,0,0,0,0,0,22,0,22,0,0,0,24,0
0,24,50,50,50,50,0,0,0,0,0,24,0,0,0,0,0,0,0,22,0,22,54,0,0,22,0
0,24,50,50,50,50,0,0,0,0,0,24,0,0,0,0,23,0,0,24,0,19,22,22,22,22,0
0,24,50,50,50,50,0,0,0,0,0,24,0,0,0,0,0,0,0,22,0,0,0,0,48,22,0
0,24,50,50,50,50,0,0,0,0,0,24,0,0,0,0,0,0,0,22,54,0,0,0,0,24,0
0,24,50,50,50,50,0,0,0,0,0,24,0,0,0,0,0,0,0,22,55,0,0,53,0,24,0
0,24,50,50,50,50,0,0,0,0,0,24,0,0,0,0,0,0,0,22,54,0,0,0,48,22,0
0,24,50,50,50,50,0,0,0,0,0,24,0,0,0,0,0,0,0,17,24,22,56,22,24,17,0
0,24,50,50,50,50,0,0,0,0,0,24,0,0,0,0,0,0,0,0,0,0,0,0,0,0,0
0,24,50,50,50,50,0,0,0,0,0,24,0,0,0,0,23,0,0,0,0,23,0,0,0,23,0
0,24,0,0,0,0,0,0,0,0,0,24,0,0,0,0,0,0,0,0,0,0,0,0,0,0,0
0,24,0,0,0,0,0,0,0,0,0,24,0,0,0,0,0,0,0,0,0,0,0,0,0,0,0
0,13,13,24,13,0,0,0,13,24,13,13,0,0,0,0,0,0,0,0,0,0,0,0,0,0,0
0,0,0,0,0,0,0,0,0,0,0,0,0,0,0,0,0,0,0,0,0,0,0,0,0,0,0
0,0,0,0,0,0,0,0,0,0,0,0,0,0,0,0,0,0,0,0,0,0,0,0,0,0,0
0,0,0,0,0,0,0,0,0,0,0,0,0,0,0,0,0,0,0,0,0,0,0,0,0,0,0
endlayer

layer
0,0,0,0,0,0,0,0,0,0,0,0,0,0,0,0,0,0,0,0,0,0,0,0,0,0,0
0,13,13,13,24,24,24,24,24,13,13,0,0,0,0,48,57,57,57,17,17,17,17,17,17,17,0
0,0,24,0,0,0,0,0,0,0,24,0,0,0,0,0,57,57,57,17,57,57,57,57,57,17,0
0,0,24,0,0,0,0,0,0,0,24,0,0,0,0,0,57,57,57,17,57,57,58,57,57,17,0
0,0,24,0,0,0,0,0,0,0,24,0,0,0,0,0,57,57,57,17,57,57,57,57,57,17,0
0,0,24,0,0,0,0,0,0,0,24,0,0,0,0,0,57,57,57,17,57,57,57,57,57,17,0
0,0,24,0,0,0,0,0,0,0,24,0,0,0,0,0,57,57,57,17,57,57,57,57,57,17,0
0,0,24,0,0,0,0,0,0,0,24,0,0,0,0,0,57,57,57,17,57,57,59,57,57,17,0
0,0,24,0,0,0,0,0,0,0,24,0,0,0,0,48,57,57,57,17,57,57,57,57,57,17,0
0,0,24,0,0,0,0,0,0,0,24,0,0,0,0,0,57,57,57,17,57,57,57,57,57,17,0
0,0,24,0,0,0,0,0,0,0,24,0,0,0,0,0,57,57,57,17,57,57,57,57,57,17,0
0,0,24,0,0,0,0,0,0,0,24,0,0,0,0,0,57,57,57,17,57,57,58,57,57,17,0
0,0,24,0,0,0,0,0,0,0,24,0,0,0,0,0,57,57,57,17,57,57,57,57,57,17,0
0,0,24,0,0,0,0,0,0,0,24,0,0,0,0,0,57,57,57,17,17,17,17,17,17,17,0
0,0,24,0,0,0,0,0,0,0,24,0,0,0,0,0,57,57,57,57,57,57,57,57,57,57,0
0,0,24,0,0,0,0,0,0,0,24,0,0,0,0,48,57,57,57,57,57,57,57,57,57,57,0
0,0,24,0,0,0,0,0,0,0,24,0,0,0,0,0,49,0,0,0,0,0,0,0,0,49,0
0,0,24,0,0,0,0,0,0,0,24,0,0,0,0,0,0,0,0,0,0,0,0,0,0,0,0
0,0,13,13,13,13,13,13,13,13,13,0,0,0,0,0,0,0,0,0,0,0,0,0,0,0,0
0,0,0,0,0,0,0,0,0,0,0,0,0,0,0,0,0,0,0,0,0,0,0,0,0,0,0
0,0,0,0,0,0,0,0,0,0,0,0,0,0,0,0,0,0,0,0,0,0,0,0,0,0,0
0,0,0,0,0,0,0,0,0,0,0,0,0,0,0,0,0,0,0,0,0,0,0,0,0,0,0
endlayer

layer
0,0,0,0,0,0,0,0,0,0,0,0,0,0,0,0,0,0,0,0,0,0,0,0,0,0,0
0,0,0,13,13,13,13,13,13,13,0,0,0,0,0,0,0,0,0,0,0,0,0,0,0,0,0
0,0,0,24,24,24,24,24,24,24,0,0,0,0,0,0,0,0,0,0,0,0,0,0,0,0,0
0,0,0,24,24,24,24,24,24,24,0,0,0,0,0,0,0,0,0,0,0,0,0,0,0,0,0
0,0,0,24,24,24,24,24,24,24,0,0,0,0,0,0,0,0,0,0,0,0,0,0,0,0,0
0,0,0,24,24,24,24,24,24,24,0,0,0,0,0,0,0,0,0,0,0,0,0,0,0,0,0
0,0,0,24,24,24,24,24,24,24,0,0,0,0,0,0,0,0,0,0,0,0,0,0,0,0,0
0,0,0,24,24,24,24,24,24,24,0,0,0,0,0,0,0,0,0,0,0,0,0,0,0,0,0
0,0,0,24,24,24,24,24,24,24,0,0,0,0,0,0,0,0,0,0,0,0,0,0,0,0,0
0,0,0,24,24,24,24,24,24,24,0,0,0,0,0,0,0,0,0,0,0,0,0,0,0,0,0
0,0,0,24,24,24,24,24,24,24,0,0,0,0,0,0,0,0,0,0,0,0,0,0,0,0,0
0,0,0,24,24,24,24,24,24,24,0,0,0,0,0,0,0,0,0,0,0,0,0,0,0,0,0
0,0,0,24,24,24,24,24,24,24,0,0,0,0,0,0,0,0,0,0,0,0,0,0,0,0,0
0,0,0,24,24,24,24,24,24,24,0,0,0,0,0,0,0,0,0,0,0,0,0,0,0,0,0
0,0,0,24,24,24,24,24,24,24,0,0,0,0,0,0,0,0,0,0,0,0,0,0,0,0,0
0,0,0,24,24,24,24,24,24,24,0,0,0,0,0,0,0,0,0,0,0,0,0,0,0,0,0
0,0,0,24,24,24,24,24,24,24,0,0,0,0,0,0,0,0,0,0,0,0,0,0,0,0,0
0,0,0,24,24,24,24,24,24,24,0,0,0,0,0,0,0,0,0,0,0,0,0,0,0,0,0
0,0,0,13,13,13,13,13,13,13,0,0,0,0,0,0,0,0,0,0,0,0,0,0,0,0,0
0,0,0,0,0,0,0,0,0,0,0,0,0,0,0,0,0,0,0,0,0,0,0,0,0,0,0
0,0,0,0,0,0,0,0,0,0,0,0,0,0,0,0,0,0,0,0,0,0,0,0,0,0,0
0,0,0,0,0,0,0,0,0,0,0,0,0,0,0,0,0,0,0,0,0,0,0,0,0,0,0
endlayer

