
# Created by Ruins mod version 15.3 Ingame Parser
# authoring Player: Mensrea

weight=50
embed_into_distance=4
acceptable_target_blocks=
unacceptable_target_blocks=flowing_water,water,flowing_lava,lava
dimensions=19,16,16
allowable_overhang=2
max_leveling=4
leveling_buffer=0
preserve_water=0
preserve_lava=0
preventRotation=1

rule1=0,100,minecraft:obsidian-0
rule2=0,100,minecraft:netherrack-0
rule3=0,100,MobSpawner:demonmobs.trite
rule4=0,100,ImmersiveEngineering:storageSlab-7
rule5=0,100,MobSpawner:demonmobs.belph
rule6=0,100,MobSpawner:demonmobs.pinky
rule7=0,100,minecraft:nether_brick_stairs-2
rule8=0,100,minecraft:nether_brick_stairs-3
rule9=0,100,ImmersiveEngineering:storage-7
rule10=0,100,minecraft:nether_brick-0
rule11=0,100,ChestGenHook:dungeonChest:5-2
rule12=0,100,ChestGenHook:dungeonChest:5-3
rule13=0,100,ChestGenHook:dungeonChest:5-2
rule14=0,100,ChestGenHook:dungeonChest:5-3
rule15=0,100,ChestGenHook:strongholdLibrary:5-2
rule16=0,100,ChestGenHook:strongholdLibrary:5-3
rule17=0,100,ChestGenHook:pyramidDesertyChest:5-2
rule18=0,100,ChestGenHook:pyramidDesertyChest:5-3
rule19=0,100,minecraft:nether_brick_stairs-0
rule20=0,100,minecraft:nether_brick_fence-0
rule21=0,100,MobSpawner:demonmobs.behemoth
rule22=0,100,demonmobs:demoncrystal-0
rule23=0,100,MobSpawner:demonmobs.nethersoul

layer
1,1,1,1,1,1,1,1,1,1,1,1,1,1,1,1
1,1,1,1,1,1,1,1,1,1,1,1,1,1,1,1
1,1,1,1,1,1,1,1,1,1,1,1,1,1,1,1
1,1,1,1,1,1,1,1,1,1,1,1,1,1,1,1
1,1,1,1,1,1,1,1,1,1,1,1,1,1,1,1
1,1,1,1,1,1,1,1,1,1,1,1,1,1,1,1
1,1,1,1,1,1,1,1,1,1,1,1,1,1,1,1
1,1,1,1,1,1,1,1,1,1,1,1,1,1,1,1
1,1,1,1,1,1,1,1,1,1,1,1,1,1,1,1
1,1,1,1,1,1,1,1,1,1,1,1,1,1,1,1
1,1,1,1,1,1,1,1,1,1,1,1,1,1,1,1
1,1,1,1,1,1,1,1,1,1,1,1,1,1,1,1
1,1,1,1,1,1,1,1,1,1,1,1,1,1,1,1
1,1,1,1,1,1,1,1,1,1,1,1,1,1,1,1
1,1,1,1,1,1,1,1,1,1,1,1,1,1,1,1
1,1,1,1,1,1,1,1,1,1,1,1,1,1,1,1
endlayer

layer
1,1,1,1,1,1,1,1,1,1,1,1,1,1,1,1
1,1,1,1,1,1,1,1,1,1,1,1,1,1,1,1
1,1,1,1,1,1,1,1,1,1,1,1,1,1,1,1
1,1,1,1,1,1,1,1,1,1,1,1,1,1,1,1
1,1,1,1,1,1,1,1,1,1,1,1,1,1,1,1
1,1,1,1,1,1,1,1,1,1,1,1,1,1,1,1
1,1,1,1,1,1,1,1,1,1,1,1,1,1,1,1
1,1,1,1,1,1,1,1,1,1,1,1,1,1,1,1
1,1,1,1,1,1,1,1,1,1,1,1,1,1,1,1
1,1,1,1,1,1,1,1,1,1,1,1,1,1,1,1
1,1,1,1,1,1,1,1,1,1,1,1,1,1,1,1
1,1,1,1,1,1,1,1,1,1,1,1,1,1,1,1
1,1,1,1,1,1,1,1,1,1,1,1,1,1,1,1
1,1,1,1,1,1,1,1,1,1,1,1,1,1,1,1
1,1,1,1,1,1,1,1,1,1,1,1,1,1,1,1
1,1,1,1,1,1,1,1,1,1,1,1,1,1,1,1
endlayer

layer
1,1,1,1,1,1,1,1,1,1,1,1,1,1,1,1
1,1,1,1,1,1,1,1,1,1,1,1,1,1,1,1
1,1,1,1,1,1,1,1,1,1,1,1,1,1,1,1
1,1,1,1,1,1,1,1,1,1,1,1,1,1,1,1
1,1,1,1,1,1,1,1,1,1,1,1,1,1,1,1
1,1,1,1,1,1,1,1,1,1,1,1,1,1,1,1
1,1,1,1,1,1,1,1,1,1,1,1,1,1,1,1
1,1,1,1,1,1,1,1,1,1,1,1,1,1,1,1
1,1,1,1,1,1,1,1,1,1,1,1,1,1,1,1
1,1,1,1,1,1,1,1,1,1,1,1,1,1,1,1
1,1,1,1,1,1,1,1,1,1,1,1,1,1,1,1
1,1,1,1,1,1,1,1,1,1,1,1,1,1,1,1
1,1,1,1,1,1,1,1,1,1,1,1,1,1,1,1
1,1,1,1,1,1,1,1,1,1,1,1,1,1,1,1
1,1,1,1,1,1,1,1,1,1,1,1,1,1,1,1
1,1,1,1,1,1,1,1,1,1,1,1,1,1,1,1
endlayer

layer
1,1,1,1,1,1,1,1,1,1,1,1,1,1,1,1
1,1,2,2,2,2,2,2,2,2,2,2,2,2,1,1
2,2,2,2,2,2,2,2,2,2,2,2,2,2,2,2
2,2,2,1,2,2,2,2,2,2,2,2,2,2,2,2
2,2,2,3,2,2,2,2,2,2,2,2,3,2,2,2
2,2,2,2,2,2,1,2,2,1,2,2,2,2,2,2
2,2,2,2,2,2,2,2,2,2,2,2,2,2,2,2
2,2,2,2,2,2,2,2,2,2,2,2,2,2,2,2
2,2,2,2,2,2,1,2,2,1,2,2,2,2,2,2
2,2,2,2,2,2,2,2,2,2,2,2,2,2,2,2
2,2,2,2,2,2,1,2,2,1,2,2,2,2,2,2
2,2,2,2,2,2,2,2,2,2,2,2,2,2,2,2
2,2,2,2,2,2,2,2,2,2,2,2,2,2,2,2
2,2,2,2,2,2,2,2,2,2,2,2,2,2,2,2
1,1,2,2,2,2,2,2,2,2,2,2,2,2,1,1
1,1,2,2,2,2,2,2,2,2,2,2,2,2,1,1
endlayer

layer
1,1,1,1,1,1,1,1,1,1,1,1,1,1,1,1
1,1,1,1,1,2,2,1,1,2,2,1,1,1,1,1
2,1,1,1,1,1,1,1,1,1,1,1,1,1,1,2
2,1,1,1,1,1,1,1,1,1,1,1,1,1,1,2
2,1,1,4,1,1,1,1,1,1,1,1,4,1,1,2
2,1,1,1,1,1,1,1,1,1,1,1,1,1,1,2
2,1,1,1,1,1,1,1,1,1,1,1,1,1,1,2
2,1,1,1,1,1,1,1,1,1,1,1,1,1,1,2
2,1,1,1,1,1,1,1,1,1,1,1,1,1,1,2
2,1,1,1,1,1,1,1,1,1,1,1,1,1,1,2
2,1,1,1,1,1,6,1,1,5,1,1,1,1,1,2
2,1,1,1,1,1,1,1,1,1,1,1,1,1,1,2
2,1,1,1,1,1,1,1,1,1,1,1,1,1,1,2
2,1,1,1,1,1,1,1,1,1,1,1,1,1,1,2
1,1,2,2,2,2,2,2,2,2,2,2,2,2,1,1
1,1,2,2,2,2,2,2,2,2,2,2,2,2,1,1
endlayer

layer
1,1,0,0,8,1,1,0,0,1,1,7,0,0,1,1
1,9,1,0,1,10,1,0,0,1,10,1,0,1,9,1
0,10,1,0,1,1,1,0,0,1,1,1,0,1,10,0
0,10,1,0,0,0,0,0,0,0,0,0,0,1,10,0
0,10,1,0,0,0,0,0,0,0,0,0,0,1,10,0
0,10,1,0,0,0,0,0,0,0,0,0,0,1,10,0
0,10,1,0,0,0,0,0,0,0,0,0,0,1,10,0
0,10,1,0,0,0,0,0,0,0,0,0,0,1,10,0
0,10,1,0,0,0,0,0,0,0,0,0,0,1,10,0
0,10,1,10,0,0,0,0,0,0,0,0,10,1,10,0
0,10,1,12,0,0,4,0,0,4,0,0,11,1,10,0
0,10,1,14,0,0,0,0,0,0,0,0,13,1,10,0
0,10,1,10,16,15,10,18,17,10,16,15,10,1,10,0
0,10,1,1,1,1,1,1,1,1,1,1,1,1,10,0
1,9,10,10,10,10,10,10,10,10,10,10,10,10,9,1
1,1,0,0,0,0,0,0,0,0,0,0,0,0,1,1
endlayer

layer
1,1,0,0,0,8,1,0,0,1,7,0,0,0,1,1
1,9,1,1,1,10,1,0,0,1,10,1,1,1,9,1
0,10,1,1,1,1,1,0,0,1,1,1,1,1,10,0
0,10,1,0,0,0,0,0,0,0,0,0,0,1,10,0
0,10,1,0,0,0,0,0,0,0,0,0,0,1,10,0
0,10,1,0,0,0,0,0,0,0,0,0,0,1,10,0
0,10,1,0,0,0,0,0,0,0,0,0,0,1,10,0
0,10,1,0,0,0,0,0,0,0,0,0,0,1,10,0
0,10,1,0,0,0,0,0,0,0,0,0,0,1,10,0
0,10,1,10,0,0,0,0,0,0,0,0,10,1,10,0
0,10,1,1,0,0,0,0,0,0,0,0,1,1,10,0
0,10,1,1,0,0,0,0,0,0,0,0,1,1,10,0
0,10,1,10,1,1,10,1,1,10,1,1,10,1,10,0
0,10,1,1,1,1,1,1,1,1,1,1,1,1,10,0
1,9,10,10,10,10,10,10,10,10,10,10,10,10,9,1
1,1,0,0,0,0,0,0,0,0,0,0,0,0,1,1
endlayer

layer
1,1,0,0,0,0,8,9,9,7,0,0,0,0,1,1
1,9,9,9,9,9,9,9,9,9,9,9,9,9,9,1
0,9,1,1,1,1,1,1,1,1,1,1,1,1,9,0
0,9,1,1,1,1,1,1,1,1,1,1,1,1,9,0
0,9,1,1,0,0,0,0,0,0,0,0,1,1,9,0
0,9,1,1,0,0,0,0,0,0,0,0,1,1,9,0
0,9,1,1,0,0,0,0,0,0,0,0,1,1,9,0
0,9,1,1,0,0,0,0,0,0,0,0,1,1,9,0
0,9,1,1,0,0,0,0,0,0,0,0,1,1,9,0
0,9,1,1,0,0,0,0,0,0,0,0,1,1,9,0
0,9,1,1,0,0,0,0,0,0,0,0,1,1,9,0
0,9,1,1,0,0,0,0,0,0,0,0,1,1,9,0
0,9,1,1,1,1,1,1,1,1,1,1,1,1,9,0
0,9,1,1,1,1,1,1,1,1,1,1,1,1,9,0
1,9,9,9,9,9,9,9,9,9,9,9,9,9,9,1
1,1,0,0,0,0,0,0,0,0,0,0,0,0,1,1
endlayer

layer
1,1,0,0,0,0,0,0,0,0,0,0,0,0,1,1
1,0,0,0,0,0,0,19,19,0,0,0,0,0,0,1
0,0,0,0,10,10,0,1,1,0,10,10,0,0,0,0
0,0,0,9,1,1,10,10,10,10,1,1,9,0,0,0
0,0,0,10,1,1,1,1,1,1,1,1,10,0,0,0
0,0,0,10,1,0,0,0,0,0,0,1,10,0,0,0
0,0,0,10,1,0,0,0,0,0,0,1,10,0,0,0
0,0,0,10,1,0,0,0,0,0,0,1,10,0,0,0
0,0,0,10,1,0,0,0,0,0,0,1,10,0,0,0
0,0,0,10,1,0,0,0,0,0,0,1,10,0,0,0
0,0,0,10,1,0,0,0,0,0,0,1,10,0,0,0
0,0,0,10,1,1,1,1,1,1,1,0,10,0,0,0
0,0,0,9,10,10,10,10,10,10,10,10,9,0,0,0
0,0,0,0,0,0,0,0,0,0,0,0,0,0,0,0
1,0,0,0,0,0,0,0,0,0,0,0,0,0,0,1
1,1,0,0,0,0,0,0,0,0,0,0,0,0,1,1
endlayer

layer
1,1,0,0,0,0,0,0,0,0,0,0,0,0,1,1
1,0,0,0,0,0,0,0,0,0,0,0,0,0,0,1
0,0,0,0,10,10,0,19,19,0,10,10,0,0,0,0
0,0,0,9,1,1,10,1,1,10,1,1,9,0,0,0
0,0,0,10,1,1,1,1,1,1,1,1,10,0,0,0
0,0,0,10,1,0,0,0,0,0,0,1,10,0,0,0
0,0,0,10,1,0,0,0,0,0,0,1,10,0,0,0
0,0,0,10,1,0,0,0,0,0,0,1,10,0,0,0
0,0,0,10,1,0,0,0,0,0,0,1,10,0,0,0
0,0,0,10,1,0,0,0,0,0,0,1,10,0,0,0
0,0,0,10,1,0,0,0,0,0,0,1,10,0,0,0
0,0,0,10,1,1,1,1,1,1,1,1,10,0,0,0
0,0,0,9,10,10,10,10,10,10,10,10,9,0,0,0
0,0,0,0,0,0,0,0,0,0,0,0,0,0,0,0
1,0,0,0,0,0,0,0,0,0,0,0,0,0,0,1
1,1,0,0,0,0,0,0,0,0,0,0,0,0,1,1
endlayer

layer
1,20,0,0,0,0,0,0,0,0,0,0,0,0,20,1
20,0,0,0,0,0,0,0,0,0,0,0,0,0,0,20
0,0,0,0,9,9,0,0,0,0,9,9,0,0,0,0
0,0,0,9,6,1,9,19,19,9,1,5,9,0,0,0
0,0,0,9,1,1,1,1,1,1,1,1,9,0,0,0
0,0,0,9,1,1,1,1,1,1,1,1,9,0,0,0
0,0,0,9,1,1,0,0,0,0,1,1,9,0,0,0
0,0,0,9,1,1,0,0,0,0,1,1,9,0,0,0
0,0,0,9,1,1,0,0,0,0,1,1,9,0,0,0
0,0,0,9,1,1,0,0,0,0,1,1,9,0,0,0
0,0,0,9,1,1,1,1,1,1,1,1,9,0,0,0
0,0,0,9,1,1,1,1,1,1,1,1,9,0,0,0
0,0,0,9,9,9,9,9,9,9,9,9,9,0,0,0
0,0,0,0,0,0,0,0,0,0,0,0,0,0,0,0
20,0,0,0,0,0,0,0,0,0,0,0,0,0,0,20
1,20,0,0,0,0,0,0,0,0,0,0,0,0,20,1
endlayer

layer
1,20,0,0,0,0,0,0,0,0,0,0,0,0,20,1
20,0,0,0,0,0,0,0,0,0,0,0,0,0,0,20
0,0,0,0,0,0,0,0,0,0,0,0,0,0,0,0
0,0,0,0,4,4,0,0,0,0,4,4,0,0,0,0
0,0,0,0,0,0,0,19,19,0,0,0,0,0,0,0
0,0,0,0,0,9,10,1,1,10,9,0,0,0,0,0
0,0,0,0,0,10,1,1,1,1,10,0,0,0,0,0
0,0,0,0,0,10,1,0,0,1,10,0,0,0,0,0
0,0,0,0,0,10,1,0,0,1,10,0,0,0,0,0
0,0,0,0,0,10,1,1,1,1,10,0,0,0,0,0
0,0,0,0,0,9,10,10,10,10,9,0,0,0,0,0
0,0,0,0,0,0,0,0,0,0,0,0,0,0,0,0
0,0,0,0,0,0,0,0,0,0,0,0,0,0,0,0
0,0,0,0,0,0,0,0,0,0,0,0,0,0,0,0
20,0,0,0,0,0,0,0,0,0,0,0,0,0,0,20
1,20,0,0,0,0,0,0,0,0,0,0,0,0,20,1
endlayer

layer
1,1,0,0,0,0,0,0,0,0,0,0,0,0,1,1
1,0,0,0,0,0,0,0,0,0,0,0,0,0,0,1
0,0,0,0,0,0,0,0,0,0,0,0,0,0,0,0
0,0,0,0,0,0,0,0,0,0,0,0,0,0,0,0
0,0,0,0,0,0,0,0,0,0,0,0,0,0,0,0
0,0,0,0,0,9,10,19,19,10,9,0,0,0,0,0
0,0,0,0,0,10,1,1,1,0,10,0,0,0,0,0
0,0,0,0,0,10,1,1,1,1,10,0,0,0,0,0
0,0,0,0,0,10,1,1,1,1,10,0,0,0,0,0
0,0,0,0,0,10,1,1,1,1,10,0,0,0,0,0
0,0,0,0,0,9,10,10,10,10,9,0,0,0,0,0
0,0,0,0,0,0,0,0,0,0,0,0,0,0,0,0
0,0,0,0,0,0,0,0,0,0,0,0,0,0,0,0
0,0,0,0,0,0,0,0,0,0,0,0,0,0,0,0
1,0,0,0,0,0,0,0,0,0,0,0,0,0,0,1
1,1,0,0,0,0,0,0,0,0,0,0,0,0,1,1
endlayer

layer
0,1,0,0,0,0,0,0,0,0,0,0,0,0,1,0
1,0,0,0,0,0,0,0,0,0,0,0,0,0,0,1
0,0,0,0,0,0,0,0,0,0,0,0,0,0,0,0
0,0,0,0,0,0,0,0,0,0,0,0,0,0,0,0
0,0,0,0,0,0,0,0,0,0,0,0,0,0,0,0
0,0,0,0,0,9,1,0,0,1,9,0,0,0,0,0
0,0,0,0,0,1,1,19,19,1,1,0,0,0,0,0
0,0,0,0,0,1,1,1,1,1,1,0,0,0,0,0
0,0,0,0,0,1,21,1,1,21,1,0,0,0,0,0
0,0,0,0,0,1,1,1,1,1,1,0,0,0,0,0
0,0,0,0,0,9,1,1,1,1,9,0,0,0,0,0
0,0,0,0,0,0,0,0,0,0,0,0,0,0,0,0
0,0,0,0,0,0,0,0,0,0,0,0,0,0,0,0
0,0,0,0,0,0,0,0,0,0,0,0,0,0,0,0
1,0,0,0,0,0,0,0,0,0,0,0,0,0,0,1
0,1,0,0,0,0,0,0,0,0,0,0,0,0,1,0
endlayer

layer
0,1,0,0,0,0,0,0,0,0,0,0,0,0,1,0
1,1,0,0,0,0,0,0,0,0,0,0,0,0,1,1
0,0,0,0,0,0,0,0,0,0,0,0,0,0,0,0
0,0,0,0,0,0,0,0,0,0,0,0,0,0,0,0
0,0,0,0,0,0,0,0,0,0,0,0,0,0,0,0
0,0,0,0,0,22,4,0,0,4,22,0,0,0,0,0
0,0,0,0,0,4,4,0,0,4,4,0,0,0,0,0
0,0,0,0,0,4,4,4,4,4,4,0,0,0,0,0
0,0,0,0,0,4,4,4,4,4,4,0,0,0,0,0
0,0,0,0,0,4,4,4,4,4,4,0,0,0,0,0
0,0,0,0,0,22,4,4,4,4,22,0,0,0,0,0
0,0,0,0,0,0,0,0,0,0,0,0,0,0,0,0
0,0,0,0,0,0,0,0,0,0,0,0,0,0,0,0
0,0,0,0,0,0,0,0,0,0,0,0,0,0,0,0
1,1,0,0,0,0,0,0,0,0,0,0,0,0,1,1
0,1,0,0,0,0,0,0,0,0,0,0,0,0,1,0
endlayer

layer
0,0,0,0,0,0,0,0,0,0,0,0,0,0,0,0
0,1,0,0,0,0,0,0,0,0,0,0,0,0,1,0
0,0,0,0,0,0,0,0,0,0,0,0,0,0,0,0
0,0,0,0,0,0,0,0,0,0,0,0,0,0,0,0
0,0,0,0,0,0,0,0,0,0,0,0,0,0,0,0
0,0,0,0,0,0,0,0,0,0,0,0,0,0,0,0
0,0,0,0,0,0,0,0,0,0,0,0,0,0,0,0
0,0,0,0,0,0,0,0,0,0,0,0,0,0,0,0
0,0,0,0,0,0,0,0,0,0,0,0,0,0,0,0
0,0,0,0,0,0,0,0,0,0,0,0,0,0,0,0
0,0,0,0,0,0,0,0,0,0,0,0,0,0,0,0
0,0,0,0,0,0,0,0,0,0,0,0,0,0,0,0
0,0,0,0,0,0,0,0,0,0,0,0,0,0,0,0
0,0,0,0,0,0,0,0,0,0,0,0,0,0,0,0
0,1,0,0,0,0,0,0,0,0,0,0,0,0,1,0
0,0,0,0,0,0,0,0,0,0,0,0,0,0,0,0
endlayer

layer
0,20,0,0,0,0,0,0,0,0,0,0,0,0,20,0
20,1,20,0,0,0,0,0,0,0,0,0,0,20,1,20
0,20,0,0,0,0,0,0,0,0,0,0,0,0,20,0
0,0,0,0,0,0,0,0,0,0,0,0,0,0,0,0
0,0,0,0,0,0,0,0,0,0,0,0,0,0,0,0
0,0,0,0,0,0,0,0,0,0,0,0,0,0,0,0
0,0,0,0,0,0,0,0,0,0,0,0,0,0,0,0
0,0,0,0,0,0,0,0,0,0,0,0,0,0,0,0
0,0,0,0,0,0,0,0,0,0,0,0,0,0,0,0
0,0,0,0,0,0,0,0,0,0,0,0,0,0,0,0
0,0,0,0,0,0,0,0,0,0,0,0,0,0,0,0
0,0,0,0,0,0,0,0,0,0,0,0,0,0,0,0
0,0,0,0,0,0,0,0,0,0,0,0,0,0,0,0
0,20,0,0,0,0,0,0,0,0,0,0,0,0,20,0
20,1,20,0,0,0,0,0,0,0,0,0,0,20,1,20
0,20,0,0,0,0,0,0,0,0,0,0,0,0,20,0
endlayer

layer
0,1,0,0,0,0,0,0,0,0,0,0,0,0,1,0
1,23,1,0,0,0,0,0,0,0,0,0,0,1,23,1
0,1,0,0,0,0,0,0,0,0,0,0,0,0,1,0
0,0,0,0,0,0,0,0,0,0,0,0,0,0,0,0
0,0,0,0,0,0,0,0,0,0,0,0,0,0,0,0
0,0,0,0,0,0,0,0,0,0,0,0,0,0,0,0
0,0,0,0,0,0,0,0,0,0,0,0,0,0,0,0
0,0,0,0,0,0,0,0,0,0,0,0,0,0,0,0
0,0,0,0,0,0,0,0,0,0,0,0,0,0,0,0
0,0,0,0,0,0,0,0,0,0,0,0,0,0,0,0
0,0,0,0,0,0,0,0,0,0,0,0,0,0,0,0
0,0,0,0,0,0,0,0,0,0,0,0,0,0,0,0
0,0,0,0,0,0,0,0,0,0,0,0,0,0,0,0
0,1,0,0,0,0,0,0,0,0,0,0,0,0,1,0
1,23,1,0,0,0,0,0,0,0,0,0,0,1,23,1
0,1,0,0,0,0,0,0,0,0,0,0,0,0,1,0
endlayer

layer
0,0,0,0,0,0,0,0,0,0,0,0,0,0,0,0
0,4,0,0,0,0,0,0,0,0,0,0,0,0,4,0
0,0,0,0,0,0,0,0,0,0,0,0,0,0,0,0
0,0,0,0,0,0,0,0,0,0,0,0,0,0,0,0
0,0,0,0,0,0,0,0,0,0,0,0,0,0,0,0
0,0,0,0,0,0,0,0,0,0,0,0,0,0,0,0
0,0,0,0,0,0,0,0,0,0,0,0,0,0,0,0
0,0,0,0,0,0,0,0,0,0,0,0,0,0,0,0
0,0,0,0,0,0,0,0,0,0,0,0,0,0,0,0
0,0,0,0,0,0,0,0,0,0,0,0,0,0,0,0
0,0,0,0,0,0,0,0,0,0,0,0,0,0,0,0
0,0,0,0,0,0,0,0,0,0,0,0,0,0,0,0
0,0,0,0,0,0,0,0,0,0,0,0,0,0,0,0
0,0,0,0,0,0,0,0,0,0,0,0,0,0,0,0
0,4,0,0,0,0,0,0,0,0,0,0,0,0,4,0
0,0,0,0,0,0,0,0,0,0,0,0,0,0,0,0
endlayer

